Workbook

Sheet RESUMEN ACU
A1: ANALISIS DE COSTOS UNITARIOS - PARTIDAS RESALTADAS DEL METRADO DE DRENAJE PLUVIAL
A4: ENTIDAD | C4: GERENCIA TERRITORIAL BAJO MAYO - TARAPOTO
A5: PROYECTO | C5: “CREACIÓN DEL SERVICIO DE PROTECCIÓN A MUJERES VÍCTIMAS DE VIOLENCIA EN SITUACIÓN DE RIESGO DE FEMINICIDIO O PELIGRE SU INTEGRIDAD Y/O SALUD FÍSICA Y/O MENTAL EN HOGAR DE REFUGIO TEMPORAL DISTRITO DE MORALES DE LA PROVINCIA DE SAN MARTÍN DEL DEPARTAMENTO DE SAN MARTÍN”, con CUI N.° 2675514
A6: UBICACIÓN | C6: SAN MARTIN - SAN MARTIN - MORALES
A7: FECHA | C7: 01/09/2026
A9: Item | B9: Descripción | C9: Und | D9: Metrado | E9: C.U. S/ | F9: Parcial S/ | G9: Hoja ACU
A10: 01.04.03.04.03.04 | B10: LLORADERO DE TUBERIA PVC Ø3" C/FILTRO DE GRAVA Y GEOTEXTIL @1.50 m (CUNETA COLINDANTE CON AREA VERDE) | C10: und | D10: 157 | E10: ='ACU LLORADEROS'!G47 | F10: =D10*E10 | G10: ACU LLORADEROS
A11: 01.04.03.05.01.05 | B11: TAPA LATERAL DE PLANCHA GALVANIZADA P/CANALETA SECCIÓN 0.25m x 0.20m | C11: und | D11: 40 | E11: ='ACU TAPA LATERAL CANALETA'!G42 | F11: =D11*E11 | G11: ACU TAPA LATERAL CANALETA
A12: 01.04.03.05.04.01 | B12: CANALETA DE PLANCHA DE ACERO GALVANIZADO e=0.50mm, SECCIÓN 0.18m x 0.21m | C12: m | D12: 35.37 | E12: ='ACU CANALETA BANCAS OC-01'!G38 | F12: =D12*E12 | G12: ACU CANALETA BANCAS OC-01
A13: 01.04.03.05.04.03 | B13: TAPA LATERAL DE PLANCHA GALVANIZADA P/CANALETA SECCIÓN 0.18m x 0.21m | C13: und | D13: 18 | E13: ='ACU CANALETA BANCAS OC-01'!G58 | F13: =D13*E13 | G13: ACU CANALETA BANCAS OC-01
A14: 01.04.04.05.01 | B14: TAPA DE REGISTRO CIEGA DE CONCRETO ARMADO 0.68x0.68x0.08 | C14: und | D14: 10 | E14: ='ACU TAPA REGISTRO'!G54 | F14: =D14*E14 | G14: ACU TAPA REGISTRO
A15: 01.04.04.06.01 | B15: JUNTA DE DILATACION E=1" CON TECNOPOR Y SELLADOR ASFALTICO EN COLECTOR | C15: m | D15: 100.64 | E15: ='ACU JUNTA DILATACION'!G45 | F15: =D15*E15 | G15: ACU JUNTA DILATACION
A16: 01.04.04.06.02 | B16: JUNTA E=1" CON TECNOPOR Y SELLADOR ASFALTICO ENTRE COLECTOR Y CERCO PERIMETRICO | C16: m | D16: 58.805 | E16: ='ACU JUNTA CERCO'!G45 | F16: =D16*E16 | G16: ACU JUNTA CERCO
B17: COSTO DIRECTO TOTAL DE LAS PARTIDAS RESALTADAS | F17: =SUM(F10:F16)
A19: Notas:
A20: Metrados tomados de la hoja RESUMEN del metrado de drenaje pluvial (partidas con el nombre resaltado en amarillo).
A21: Mano de obra: tabla oficial CAPECO-FTCCP 2026 (operario 28.95, oficial 22.68, peon 20.54 S/ hh). Precios sin IGV, con su fuente en cada ACU.
A22: Costo directo; no incluye gastos generales, utilidad ni IGV.

Sheet PRECIOS DE INSUMOS
A1: PRECIOS DE INSUMOS PARA LAS ACU DE LAS BANCAS OC-01 (sin IGV)
A4: N° | B4: INSUMO | C4: UND | D4: PRECIO S/ | E4: FUENTE
A5: 1 | B5: Plancha de acero galvanizado e=0.50 mm | C5: m2 | D5: =26.95*(0.5*7.85+0.3)/(0.9*7.85+0.3) | E5: Referencial: precio por kg de la plancha de 0.9 mm de la ACU CANALETAS (S/ 26.95 por m2, Mercado Tarapoto 2026) aplicado al peso de la de 0.50 mm (4.225 frente a 7.365 kg/m2). Por cotizar en Tarapoto.
A6: 2 | B6: Remache pop 1/8" | C6: und | D6: 0.1 | E6: mismo precio de la ACU CANALETAS de la planilla (Mercado Tarapoto 2026, sin IGV)
A7: 3 | B7: Sellador de poliuretano (cartucho 300 ml) | C7: und | D7: 21.19 | E7: mismo precio de la ACU CANALETAS de la planilla (sin IGV)

Sheet ACU LLORADEROS
A1: ANALISIS DE COSTO UNITARIO - LLORADERO DE TUBERIA PVC Ø3" C/FILTRO DE GRAVA Y GEOTEXTIL @1.50 m
A2: ENTIDAD | C2: =+'RESUMEN ACU'!C4
A3: PROYECTO | C3: =+'RESUMEN ACU'!C5
A4: UBICACIÓN | C4: =+'RESUMEN ACU'!C6
A5: FECHA | C5: =+'RESUMEN ACU'!C7
A7: Partida de Delphin 01.04.03.04.03.04 LLORADERO DE TUBERIA PVC Ø3" C/FILTRO DE GRAVA Y GEOTEXTIL @1.50 m (CUNETA COLINDANTE CON AREA VERDE) (metrado: hojas METRADO LLORADEROS y DESAGREGADO LLORADEROS). Cantidades por lloradero de las laminas DL-01 y DL-02: tubo PVC-U Ø 3" de 0.30 m con 8 perforaciones Ø 3/8", filtro de grava de 0.30 x 0.30 x 0.30 m forrado con geotextil no tejido y mortero 1:3 de sellado. Mano de obra de la hoja COSTO HORA HOMBRE 2026. Celda amarilla = dato; verde = formula. Precios sin IGV.
A9: 1. CANTIDADES POR LLORADERO (hoja DESAGREGADO LLORADEROS)
A10: N° | B10: CONCEPTO | C10: UND | D10: VALOR | H10: SUSTENTO
A11: 1 | B11: Numero de lloraderos de la partida | C11: und | D11: =157 | H11: DESAGREGADO LLORADEROS fila 23
A12: 2 | B12: Tubo PVC-U Ø 3" por lloradero | C12: m | D12: =0.3 | H12: DESAGREGADO LLORADEROS fila 37 (DL-02 B)
A13: 3 | B13: Desperdicio del tubo (corte de 10 piezas por tubo de 3 m) | C13: - | D13: 0.05 | H13: criterio de obra
A14: 4 | B14: Grava filtrante por lloradero (incluye 10 % de desperdicio) | C14: m3 | D14: =0.0297 | H14: DESAGREGADO LLORADEROS fila 40 (DL-02 A)
A15: 5 | B15: Geotextil por lloradero (6 caras + 10 % de traslapes) | C15: m2 | D15: =0.594 | H15: DESAGREGADO LLORADEROS fila 41 (DL-01 etapa 3)
A16: 6 | B16: Desperdicio del geotextil (corte del rollo) | C16: - | D16: 0.05 | H16: criterio de obra
A17: 7 | B17: Mortero 1:3 de sellado alrededor del tubo | C17: m3 | D17: =0.0005 | H17: DESAGREGADO LLORADEROS fila 42 (DL-02)
A18: 8 | B18: Cemento por m3 de mortero 1:3 | C18: bol/m3 | D18: 10.5 | H18: dosificacion usual del mortero 1:3
A19: 9 | B19: Arena gruesa por m3 de mortero 1:3 | C19: m3/m3 | D19: 1.05 | H19: arena suelta con 5 % de desperdicio
A20: 10 | B20: Agua por m3 de mortero 1:3 | C20: m3/m3 | D20: 0.27 | H20: dosificacion usual del mortero 1:3
A21: 11 | B21: Rendimiento de la cuadrilla | C21: und/dia | D21: 24 | H21: excavacion local de 0.027 m3, forrado, grava y cierre; el tubo se deja al vaciar el muro
A22: 12 | B22: Operarios en la cuadrilla | C22: - | D22: 0.5 | H22: colocacion del tubo, sellado y control
A23: 13 | B23: Peones en la cuadrilla | C23: - | D23: 1 | H23: excavacion, grava y relleno
A25: 2. ANALISIS DE COSTO UNITARIO (formato Delphin)
A26: Partida | C26: 01.04.03.04.03.04 LLORADERO DE TUBERIA PVC Ø3" C/FILTRO DE GRAVA Y GEOTEXTIL @1.50 m (CUNETA COLINDANTE CON AREA VERDE)
A27: Partida del metrado | C27: 01.04.03.04.03.04 (hojas METRADO LLORADEROS y DESAGREGADO LLORADEROS)
A28: Unidad | C28: und
A29: Metrado | C29: ='RESUMEN ACU'!D10
A30: Rendimiento (und/dia, cuadrilla 0.5 operario + 1 peon) | C30: =$D$21
A31: N° | B31: RECURSO | C31: UND | D31: CUADRILLA | E31: CANTIDAD POR UND | F31: PRECIO S/ | G31: PARCIAL S/ | H31: FUENTE DEL PRECIO
B32: MANO DE OBRA
A33: 1 | B33: Operario | C33: hh | D33: =E33*$C$30/8 | E33: =$D$22*8/$D$21 | F33: ='COSTO HORA HOMBRE 2026'!$G$11 | G33: =E33*F33 | H33: hoja COSTO HORA HOMBRE 2026 (tabla oficial CAPECO - FTCCP 2026)
A34: 2 | B34: Peon | C34: hh | D34: =E34*$C$30/8 | E34: =$D$23*8/$D$21 | F34: ='COSTO HORA HOMBRE 2026'!$G$13 | G34: =E34*F34 | H34: hoja COSTO HORA HOMBRE 2026 (tabla oficial CAPECO - FTCCP 2026)
B35: Subtotal mano de obra | G35: =SUM(G33:G34)
B36: MATERIALES
A37: 3 | B37: Tubo PVC-U Ø 3" desague (NTP 399.003) | C37: m | E37: =$D$12*(1+$D$13) | F37: =39.9/1.18/3 | G37: =E37*F37 | H37: Sodimac Peru y Promart: tubo desague PVC 3" x 3 m liviano Pavco S/ 39.90 con IGV (S/ 11.27 el m sin IGV)
A38: 4 | B38: Grava filtrante 20 a 40 mm | C38: m3 | E38: =$D$14 | F38: =70.0/1.18 | G38: =E38*F38 | H38: Agregados Tarapoto (Morales): piedra chancada 3/4" S/ 70.00 el m3 puesto en obra (precio publicado mas cercano a la grava 20 a 40 mm)
A39: 5 | B39: Geotextil no tejido 200 g/m2 | C39: m2 | E39: =$D$15*(1+$D$16) | F39: =2300.0/400/1.18 | G39: =E39*F39 | H39: Ferropolis Peru: geotextil no tejido 200 g/m2, rollo de 4 x 100 m S/ 2,300.00 (S/ 5.75 el m2 con IGV)
A40: 6 | B40: Cemento Portland tipo I | C40: bol | E40: =$D$17*$D$18 | F40: ='ACU TAPA REGISTRO'!F42 | G40: =E40*F40 | H40: precio de la ACU TAPA REGISTRO (Cemento Pacasmayo tipo I S/ 36.50 con IGV)
A41: 7 | B41: Arena gruesa | C41: m3 | E41: =$D$17*$D$19 | F41: ='ACU TAPA REGISTRO'!F43 | G41: =E41*F41 | H41: precio de la ACU TAPA REGISTRO (Agregados Tarapoto, Morales)
A42: 8 | B42: Agua | C42: m3 | E42: =$D$17*$D$20 | F42: ='ACU TAPA REGISTRO'!F45 | G42: =E42*F42 | H42: precio de la ACU TAPA REGISTRO (EMAPA San Martin)
B43: Subtotal materiales | G43: =SUM(G37:G42)
...

Sheet ACU TAPA REGISTRO
A1: ANALISIS DE COSTO UNITARIO - TAPA DE REGISTRO CIEGA DE CONCRETO ARMADO 0.68x0.68x0.08
A2: ENTIDAD | C2: =+'RESUMEN ACU'!C4
A3: PROYECTO | C3: =+'RESUMEN ACU'!C5
A4: UBICACIÓN | C4: =+'RESUMEN ACU'!C6
A5: FECHA | C5: =+'RESUMEN ACU'!C7
A7: Partida de Delphin 01.04.04.06.05.01 TAPA DE REGISTRO CIEGA DE CONCRETO ARMADO 0.68x0.68x0.08 (metrado 01.04.04.05.01, hojas COLECTOR REGISTROS Y TAPAS y COLECTOR ACERO). Tapa ciega de concreto armado vaciada aparte en obra sobre tablero, con parrilla 3/8" @0.10, 2 asas de fierro liso 1/2" en cajuelas y cantos biselados; se coloca en el rebaje de concreto de 0.70 x 0.70 x 0.08 de la losa (el rebaje y el borde engrosado se metran con el concreto del colector). Incluye el refuerzo de borde de la abertura (2 barras de 1/2" por lado). Sin marco ni contramarco metalico. Celda amarilla = dato; verde = formula. Precios sin IGV.
A9: 1. CANTIDADES POR TAPA (hojas COLECTOR PARAMETROS, COLECTOR REGISTROS Y TAPAS y COLECTOR ACERO)
A10: N° | B10: CONCEPTO | C10: UND | D10: VALOR | H10: SUSTENTO
A11: 1 | B11: Numero de tapas (registros) | C11: und | D11: =10 | H11: COLECTOR REGISTROS Y TAPAS
A12: 2 | B12: Concreto f'c=210 por tapa: 0.68 x 0.68 x 0.08 | C12: m3 | D12: =0.68^2*0.08 | H12: DP-06B rev. 02
A13: 3 | B13: Encofrado lateral por tapa: 4 x 0.68 x 0.08 (molde de madera) | C13: m2 | D13: =2.72*0.08 | H13: DP-06B rev. 02
A14: 4 | B14: Tablero de vaciado: 0.80 x 0.80 x 1" = 6.89 p2 en 6 usos | C14: p2 | D14: 1.15 | H14: criterio de obra
A15: 5 | B15: Acero 3/8" de la parrilla por tapa (7 + 7 barras, L = 0.62) | C15: kg | D15: =48.608/10 | H15: COLECTOR ACERO
A16: 6 | B16: Acero 1/2" de borde de la abertura por registro (8 barras, L = 1.40) | C16: kg | D16: =111.328/10 | H16: COLECTOR ACERO
A17: 7 | B17: Fierro liso 1/2" de las 2 asas por tapa (desarrollo 0.50 c/u) | C17: kg | D17: =9.94/10 | H17: COLECTOR ACERO
A18: 8 | B18: Desperdicio de acero | C18: - | D18: 0.05 | H18: criterio
A19: 9 | B19: Cemento por m3 de concreto f'c=210 | C19: bol/m3 | D19: =9.73 | H19: COLECTOR INSUMOS (diseno de mezcla)
A20: 10 | B20: Arena gruesa por m3 | C20: m3/m3 | D20: =0.52 | H20: COLECTOR INSUMOS
A21: 11 | B21: Piedra chancada 1/2" por m3 | C21: m3/m3 | D21: =0.53 | H21: COLECTOR INSUMOS
A22: 12 | B22: Agua por m3 (mezcla) + curado de la tapa (0.01 m3) | C22: m3/m3 | D22: =0.186 | H22: COLECTOR INSUMOS
A23: 13 | B23: Mano de obra del concreto: operario / oficial / peon por m3 | C23: hh/m3 | D23: =0.8 | H23: COLECTOR INSUMOS (0.8 / 0.8 / 6.4)
A24: 14 | B24: Peon por m3 de concreto | C24: hh/m3 | D24: =6.4 | H24: COLECTOR INSUMOS
A25: 15 | B25: Mano de obra del acero: operario / oficial por kg | C25: hh/kg | D25: =0.032 | H25: COLECTOR INSUMOS
A26: 16 | B26: Mano de obra del encofrado: operario / oficial por m2 | C26: hh/m2 | D26: 0.8 | H26: COLECTOR INSUMOS (encofrado)
A27: 17 | B27: Colocacion de la tapa en el rebaje: operario + peon | C27: hh/und | D27: 1 | H27: criterio de obra: 1 hh por tapa
A29: 2. ANALISIS DE COSTO UNITARIO (formato Delphin)
A30: Partida | C30: 01.04.04.06.05.01 TAPA DE REGISTRO CIEGA DE CONCRETO ARMADO 0.68x0.68x0.08
A31: Partida del metrado | C31: 01.04.04.05.01 (hoja COLECTOR REGISTROS Y TAPAS)
A32: Unidad | C32: und
A33: Metrado | C33: ='RESUMEN ACU'!D14
A34: Rendimiento (und/dia, cuadrilla de 1 operario) | C34: =8/E37
A35: N° | B35: RECURSO | C35: UND | D35: CUADRILLA | E35: CANTIDAD POR TAPA | F35: PRECIO S/ | G35: PARCIAL S/ | H35: FUENTE DEL PRECIO
B36: MANO DE OBRA
A37: 1 | B37: Operario | C37: hh | D37: =E37*$C$34/8 | E37: =$D$12*$D$23+($D$15+$D$16+$D$17)*$D$25+$D$13*$D$26+$D$27 | F37: ='COSTO HORA HOMBRE 2026'!$G$11 | G37: =E37*F37 | H37: hoja COSTO HORA HOMBRE 2026 (tabla oficial CAPECO - FTCCP 2026)
A38: 2 | B38: Oficial | C38: hh | D38: =E38*$C$34/8 | E38: =$D$12*$D$23+($D$15+$D$16+$D$17)*$D$25+$D$13*$D$26 | F38: ='COSTO HORA HOMBRE 2026'!$G$12 | G38: =E38*F38 | H38: hoja COSTO HORA HOMBRE 2026 (tabla oficial CAPECO - FTCCP 2026)
A39: 3 | B39: Peon | C39: hh | D39: =E39*$C$34/8 | E39: =$D$12*$D$24+$D$27 | F39: ='COSTO HORA HOMBRE 2026'!$G$13 | G39: =E39*F39 | H39: hoja COSTO HORA HOMBRE 2026 (tabla oficial CAPECO - FTCCP 2026)
B40: Subtotal mano de obra | G40: =SUM(G37:G39)
B41: MATERIALES
A42: 4 | B42: Cemento Portland tipo I | C42: bol | E42: =$D$12*$D$19 | F42: 30.93 | G42: =E42*F42 | H42: Cemento Pacasmayo tipo I 42.5 kg: S/ 36.50 con IGV
A43: 5 | B43: Arena gruesa | C43: m3 | E43: =$D$12*$D$20 | F43: 40.68 | G43: =E43*F43 | H43: Agregados Tarapoto (Morales): S/ 48.00 el m3
...

Sheet ACU JUNTA DILATACION
A1: ANALISIS DE COSTO UNITARIO - JUNTA DE DILATACION E=1" CON TECNOPOR Y SELLADOR ASFALTICO EN COLECTOR
A2: ENTIDAD | C2: =+'RESUMEN ACU'!C4
A3: PROYECTO | C3: =+'RESUMEN ACU'!C5
A4: UBICACIÓN | C4: =+'RESUMEN ACU'!C6
A5: FECHA | C5: =+'RESUMEN ACU'!C7
A7: Partida de Delphin 01.04.04.06.01 JUNTA DE DILATACION E=1" CON TECNOPOR Y SELLADOR ASFALTICO EN COLECTOR (metrado 01.04.04.06.01, hoja COLECTOR JUNTAS Y EMPALMES). Se mide por metro de junta a lo largo del perimetro de la seccion. Cantidades de la lamina DD-03: plancha de tecnopor de 1" en toda la seccion y sellador asfaltico 1" x 2" (asfalto liquido RC-250 + arena gruesa) en las caras interiores y en la cara superior (EG-2013 MTC, 510). Celda amarilla = dato; verde = formula. Precios sin IGV.
A9: 1. CANTIDADES POR METRO DE JUNTA (lamina DD-03 y hoja COLECTOR JUNTAS Y EMPALMES)
A10: N° | B10: CONCEPTO | C10: UND | D10: VALOR | H10: SUSTENTO
A11: 1 | B11: Perimetro de la seccion en cada junta: 2 x 1.10 + 2 x (0.15 + 1.61 + 0.10) | C11: m | D11: =5.92 | H11: COLECTOR JUNTAS Y EMPALMES fila 11; DD-03 A
A12: 2 | B12: Numero de juntas de dilatacion (cada 4.00 m) | C12: und | D12: =17 | H12: COLECTOR JUNTAS Y EMPALMES fila 11; DD-03 E
A13: 3 | B13: Area de tecnopor por junta: seccion 1.10 x 1.86 menos el hueco 0.80 x 1.61 | C13: m2 | D13: =1.10*(0.15+1.61+0.10)-0.80*1.61 | H13: DD-03, cuadro de componentes
A14: 4 | B14: Tecnopor por metro de junta (area neta) | C14: m2/m | D14: =D13/D11 | H14: formula
A15: 5 | B15: Desperdicio por el corte del anillo en planchas de 1.20 x 2.40 | C15: - | D15: 0.1 | H15: criterio: recortes del hueco interior y de las esquinas
A16: 6 | B16: Area de una plancha de tecnopor 1" (1.20 x 2.40 m) | C16: m2 | D16: 2.88 | H16: medida comercial
A17: 7 | B17: Planchas de tecnopor por metro de junta | C17: pln/m | D17: =D14*(1+D15)/D16 | H17: formula
A18: 8 | B18: Longitud sellada por junta: caras interiores 2 x 1.61 + 0.80 y cara superior 1.10 | C18: m | D18: =2*1.61+0.80+1.10 | H18: DD-03, cuadro de componentes
A19: 9 | B19: Seccion del sellador 1" x 2" (0.0254 x 0.0508) | C19: m2 | D19: =0.0254*0.0508 | H19: DD-03 B; EG-2013 MTC, Seccion 510
A20: 10 | B20: Mezcla de sellador por metro de junta | C20: m3/m | D20: =D19*D18/D11 | H20: formula
A21: 11 | B21: Asfalto liquido RC-250 por m3 de mezcla | C21: gal/m3 | D21: 50 | H21: criterio: mezcla de ~2,000 kg/m3 con ~9 % de asfalto = 180 kg / 3.6 kg/gal
A22: 12 | B22: Arena gruesa por m3 de mezcla | C22: m3/m3 | D22: 1.05 | H22: criterio: arena suelta con 5 % de desperdicio
A23: 13 | B23: Operario por metro de junta (colocacion del tecnopor y sellado) | C23: hh/m | D23: =0.2 | H23: COLECTOR INSUMOS fila 71
A24: 14 | B24: Peon por metro de junta | C24: hh/m | D24: =0.2 | H24: COLECTOR INSUMOS fila 72
A26: 2. ANALISIS DE COSTO UNITARIO (formato Delphin)
A27: Partida | C27: 01.04.04.06.01 JUNTA DE DILATACION E=1" CON TECNOPOR Y SELLADOR ASFALTICO EN COLECTOR
A28: Partida del metrado | C28: 01.04.04.06.01 (hoja COLECTOR JUNTAS Y EMPALMES)
A29: Unidad | C29: m
A30: Metrado | C30: ='RESUMEN ACU'!D15
A31: Rendimiento (m/dia, cuadrilla de 1 operario) | C31: =8/E34
A32: N° | B32: RECURSO | C32: UND | D32: CUADRILLA | E32: CANTIDAD POR M | F32: PRECIO S/ | G32: PARCIAL S/ | H32: FUENTE DEL PRECIO
B33: MANO DE OBRA
A34: 1 | B34: Operario | C34: hh | D34: =E34*$C$31/8 | E34: =$D$23 | F34: ='COSTO HORA HOMBRE 2026'!$G$11 | G34: =E34*F34 | H34: hoja COSTO HORA HOMBRE 2026 (tabla oficial CAPECO - FTCCP 2026)
A35: 2 | B35: Peon | C35: hh | D35: =E35*$C$31/8 | E35: =$D$24 | F35: ='COSTO HORA HOMBRE 2026'!$G$13 | G35: =E35*F35 | H35: hoja COSTO HORA HOMBRE 2026 (tabla oficial CAPECO - FTCCP 2026)
B36: Subtotal mano de obra | G36: =SUM(G34:G35)
B37: MATERIALES
A38: 3 | B38: Plancha de tecnopor 1" x 1.20 x 2.40 m | C38: pln | E38: =$D$17 | F38: =13.9/1.18 | G38: =E38*F38 | H38: Sodimac Peru: plancha de poliestireno expandido 1" x 1.20 x 2.40 m (Dipropor) S/ 13.90 con IGV
A39: 4 | B39: Asfalto liquido RC-250 | C39: gal | E39: =$D$20*$D$21 | F39: =17.7/1.18 | G39: =E39*F39 | H39: Conselva: asfalto liquido RC-250 por galon S/ 17.70 con IGV (Petroperu publica su lista ex planta; confirmar en Tarapoto)
A40: 5 | B40: Arena gruesa | C40: m3 | E40: =$D$20*$D$22 | F40: ='ACU TAPA REGISTRO'!F43 | G40: =E40*F40 | H40: precio de la ACU TAPA REGISTRO (Agregados Tarapoto, Morales)
B41: Subtotal materiales | G41: =SUM(G38:G40)
B42: EQUIPOS
A43: 6 | B43: Herramientas manuales | C43: %mo | E43: 0.03 | F43: =+G36 | G43: =E43*F43 | H43: 3 % del costo de mano de obra (incluye recipiente para calentar el asfalto)
...

Sheet ACU JUNTA CERCO
A1: ANALISIS DE COSTO UNITARIO - JUNTA E=1" CON TECNOPOR Y SELLADOR ASFALTICO ENTRE COLECTOR Y CERCO PERIMETRICO
A2: ENTIDAD | C2: =+'RESUMEN ACU'!C4
A3: PROYECTO | C3: =+'RESUMEN ACU'!C5
A4: UBICACIÓN | C4: =+'RESUMEN ACU'!C6
A5: FECHA | C5: =+'RESUMEN ACU'!C7
A7: Partida de Delphin 01.04.04.06.02 JUNTA E=1" CON TECNOPOR Y SELLADOR ASFALTICO ENTRE COLECTOR Y CERCO PERIMETRICO (metrado 01.04.04.06.02, hoja COLECTOR JUNTAS Y EMPALMES). Cantidades de la lamina DD-03: junta longitudinal con plancha de tecnopor de 1" de 0.90 m de altura contra el cimiento del cerco, en todo el tramo pegado al cerco, con sellador asfaltico 1" x 2" (RC-250 + arena) en la cara superior. Al otro lado hay terreno natural: no lleva junta. Celda amarilla = dato; verde = formula. Precios sin IGV.
A9: 1. CANTIDADES POR METRO DE JUNTA (lamina DD-03 y hoja COLECTOR JUNTAS Y EMPALMES)
A10: N° | B10: CONCEPTO | C10: UND | D10: VALOR | H10: SUSTENTO
A11: 1 | B11: Junta contra el cimiento del cerco (0+000.00 a 0+058.81) | C11: m | D11: =58.805 | H11: COLECTOR JUNTAS Y EMPALMES fila 15
A12: 2 | B12: Altura de la plancha contra el cerco | C12: m | D12: 0.9 | H12: DD-03 C
A13: 3 | B13: Lado opuesto al cerco: terreno natural, sin junta | C13: m | D13: =0 | H13: COLECTOR JUNTAS Y EMPALMES fila 16 (0 m)
A14: 4 | B14: Altura de plancha en el lado opuesto (no aplica) | C14: m | D14: 0 | H14: DD-03 D
A15: 5 | B15: Longitud total de la partida | C15: m | D15: =58.805 | H15: COLECTOR JUNTAS Y EMPALMES fila 19
A16: 6 | B16: Tecnopor por metro de junta (promedio ponderado) | C16: m2/m | D16: =(D11*D12+D13*D14)/D15 | H16: formula
A17: 7 | B17: Desperdicio por el corte en tiras | C17: - | D17: 0.05 | H17: criterio
A18: 8 | B18: Area de una plancha de tecnopor 1" (1.20 x 2.40 m) | C18: m2 | D18: 2.88 | H18: medida comercial
A19: 9 | B19: Planchas de tecnopor por metro de junta | C19: pln/m | D19: =D16*(1+D17)/D18 | H19: formula
A20: 10 | B20: Mezcla de sellador por metro de junta: 1" x 2" en la cara superior (0.0254 x 0.0508) | C20: m3/m | D20: =0.0254*0.0508 | H20: DD-03 C; EG-2013 MTC, Seccion 510
A21: 11 | B21: Asfalto liquido RC-250 por m3 de mezcla | C21: gal/m3 | D21: 50 | H21: criterio: mezcla de ~2,000 kg/m3 con ~9 % de asfalto = 180 kg / 3.6 kg/gal
A22: 12 | B22: Arena gruesa por m3 de mezcla | C22: m3/m3 | D22: 1.05 | H22: criterio: arena suelta con 5 % de desperdicio
A23: 13 | B23: Peon por metro de junta (corte y colocacion de las tiras) | C23: hh/m | D23: =0.1 | H23: COLECTOR INSUMOS fila 74
A24: 14 | B24: Operario por metro de junta (sellado) | C24: hh/m | D24: =0.05 | H24: COLECTOR INSUMOS fila 76
A26: 2. ANALISIS DE COSTO UNITARIO (formato Delphin)
A27: Partida | C27: 01.04.04.06.02 JUNTA E=1" CON TECNOPOR Y SELLADOR ASFALTICO ENTRE COLECTOR Y CERCO PERIMETRICO
A28: Partida del metrado | C28: 01.04.04.06.02 (hoja COLECTOR JUNTAS Y EMPALMES)
A29: Unidad | C29: m
A30: Metrado | C30: ='RESUMEN ACU'!D16
A31: Rendimiento (m/dia, operario de sellado) | C31: =8/E34
A32: N° | B32: RECURSO | C32: UND | D32: CUADRILLA | E32: CANTIDAD POR M | F32: PRECIO S/ | G32: PARCIAL S/ | H32: FUENTE DEL PRECIO
B33: MANO DE OBRA
A34: 1 | B34: Operario | C34: hh | D34: =E34*$C$31/8 | E34: =$D$24 | F34: ='COSTO HORA HOMBRE 2026'!$G$11 | G34: =E34*F34 | H34: hoja COSTO HORA HOMBRE 2026 (tabla oficial CAPECO - FTCCP 2026)
A35: 2 | B35: Peon | C35: hh | D35: =E35*$C$31/8 | E35: =$D$23 | F35: ='COSTO HORA HOMBRE 2026'!$G$13 | G35: =E35*F35 | H35: hoja COSTO HORA HOMBRE 2026 (tabla oficial CAPECO - FTCCP 2026)
B36: Subtotal mano de obra | G36: =SUM(G34:G35)
B37: MATERIALES
A38: 3 | B38: Plancha de tecnopor 1" x 1.20 x 2.40 m | C38: pln | E38: =$D$19 | F38: =13.9/1.18 | G38: =E38*F38 | H38: Sodimac Peru: plancha de poliestireno expandido 1" x 1.20 x 2.40 m (Dipropor) S/ 13.90 con IGV
A39: 4 | B39: Asfalto liquido RC-250 | C39: gal | E39: =$D$20*$D$21 | F39: =17.7/1.18 | G39: =E39*F39 | H39: Conselva: asfalto liquido RC-250 por galon S/ 17.70 con IGV (Petroperu publica su lista ex planta; confirmar en Tarapoto)
A40: 5 | B40: Arena gruesa | C40: m3 | E40: =$D$20*$D$22 | F40: ='ACU TAPA REGISTRO'!F43 | G40: =E40*F40 | H40: precio de la ACU TAPA REGISTRO (Agregados Tarapoto, Morales)
B41: Subtotal materiales | G41: =SUM(G38:G40)
B42: EQUIPOS
A43: 6 | B43: Herramientas manuales | C43: %mo | E43: 0.03 | F43: =+G36 | G43: =E43*F43 | H43: 3 % del costo de mano de obra (incluye recipiente para calentar el asfalto)
...

Sheet ACU TAPA LATERAL CANALETA
A1: ANALISIS DE COSTO UNITARIO - TAPA LATERAL DE PLANCHA GALVANIZADA P/CANALETA SECCIÓN 0.25m x 0.20m
A2: ENTIDAD | C2: =+'RESUMEN ACU'!C4
A3: PROYECTO | C3: =+'RESUMEN ACU'!C5
A4: UBICACIÓN | C4: =+'RESUMEN ACU'!C6
A5: FECHA | C5: =+'RESUMEN ACU'!C7
A7: Partida 01.04.03.05.01.05 (ACU 3 de la hoja ACU CANALETAS de la planilla; datos de la hoja METRADO CANALETAS)
A9: DATOS DE CALCULO (de la hoja METRADO CANALETAS y de catalogo)
A10: N° | B10: DATO | C10: UND | D10: VALOR | H10: SUSTENTO
A11: 1 | B11: Fondo interior de la canaleta | C11: m | D11: =+0.25 | H11: METRADO CANALETAS F45
A12: 2 | B12: Altura interior de la canaleta | C12: m | D12: =+0.2 | H12: METRADO CANALETAS F46
A13: 3 | B13: Pestana superior (cada lado) | C13: m | D13: =+0.05 | H13: METRADO CANALETAS F47
A14: 4 | B14: Desarrollo de plancha por metro de canaleta | C14: m2/m | D14: =+0.75 | H14: fondo + 2 alturas + 2 pestanas
A15: 5 | B15: Espesor de plancha galvanizada | C15: mm | D15: =+0.9 | H15: METRADO CANALETAS F49
A16: 6 | B16: Separacion de soportes | C16: m | D16: =+0.6 | H16: METRADO CANALETAS F50
A17: 7 | B17: Peso de la plancha galvanizada | C17: kg/m2 | D17: =D15*7.85+0.3 | H17: espesor x 7.85 kg/m2 por mm + zinc (0.3 kg/m2)
A18: 8 | B18: Largo de la plancha comercial (1.22 x 2.44) | C18: m | D18: 2.44 | H18: catalogo; la canaleta se fabrica en tramos de 2.44 m
A19: 9 | B19: Traslape entre tramos | C19: m | D19: 0.05 | H19: criterio de obra (remachado y sellado)
A20: 10 | B20: Desarrollo de la platina de un soporte | C20: m | D20: =D11+2*D12+2*0.1 | H20: abraza la canaleta (fondo + 2 lados) + 2 orejas de fijacion de 0.10
A21: 11 | B21: Peso de la platina 1" x 1/8" | C21: kg/m | D21: 0.633 | H21: 25.4 x 3.18 mm x 7.85 = 0.633 kg/m
A22: 12 | B22: Largo de la platina comercial | C22: m | D22: 6 | H22: catalogo
A25: ACU: 01.04.03.05.01.05 TAPA LATERAL DE PLANCHA GALVANIZADA P/CANALETA SECCIÓN 0.25m x 0.20m
A26: Unidad | C26: und
A27: Metrado | C27: ='RESUMEN ACU'!D11
A28: Rendimiento (und/dia) | C28: 30 | E28: trazo, corte, doblez de pestanas, remachado y sellado en el extremo de la canaleta; cuadrilla 1 op + 0.5 peon
A29: N° | B29: RECURSO | C29: UND | D29: CUADRILLA | E29: CANTIDAD | F29: PRECIO S/ | G29: PARCIAL S/ | H29: SUSTENTO / FUENTE
B30: MANO DE OBRA
A31: 1 | B31: Operario (hojalatero) | C31: hh | D31: 1 | E31: =D31*8/$C$28 | F31: ='COSTO HORA HOMBRE 2026'!$G$11 | G31: =E31*F31 | H31: hoja COSTO HORA HOMBRE 2026 (tabla oficial CAPECO - FTCCP 2026)
A32: 2 | B32: Peon | C32: hh | D32: 0.5 | E32: =D32*8/$C$28 | F32: ='COSTO HORA HOMBRE 2026'!$G$13 | G32: =E32*F32 | H32: hoja COSTO HORA HOMBRE 2026 (tabla oficial CAPECO - FTCCP 2026)
B33: Subtotal mano de obra | G33: =SUM(G31:G32)
B34: MATERIALES
A35: 3 | B35: Plancha de acero galvanizado e=0.9 mm | C35: m2 | E35: =($D$11*$D$12+2*($D$11+$D$12)*0.03)*1.1 | F35: 26.95 | G35: =E35*F35 | H35: tapa 0.25 x 0.20 + pestana de 0.03 en el contorno, 10 % desperdicio
A36: 4 | B36: Remache pop 1/8" | C36: und | E36: 6 | F36: 0.1 | G36: =E36*F36 | H36: 6 por tapa
A37: 5 | B37: Sellador de poliuretano (cartucho 300 ml) | C37: und | E37: =($D$11+2*$D$12)/8 | F37: 21.19 | G37: =E37*F37 | H37: contorno de la tapa (0.65 m) / 8 m por cartucho
B38: Subtotal materiales | G38: =SUM(G35:G37)
B39: EQUIPOS
A40: 6 | B40: Herramientas manuales | C40: %mo | E40: 0.05 | F40: =+G33 | G40: =E40*F40 | H40: 5 % del costo de mano de obra (hojalateria)
B41: Subtotal equipos | G41: =SUM(G40:G40)
A42: COSTO UNITARIO DIRECTO (S/ por und) | G42: =+G33+G38+G41
A43: COSTO DIRECTO DE LA PARTIDA (metrado x costo unitario) | G43: =G42*C27

Sheet ACU CANALETA BANCAS OC-01
A1: ANALISIS DE COSTOS UNITARIOS - CANALETA DE TECHO DE BANCAS CON PERGOLA (OC-01)
A2: ENTIDAD | C2: ='RESUMEN ACU'!C4
A3: PROYECTO | C3: ='RESUMEN ACU'!C5
A4: UBICACIÓN | C4: ='RESUMEN ACU'!C6
A5: FECHA | C5: ='RESUMEN ACU'!C7
A7: Analisis de las partidas 01.04.03.05.04.01 y 01.04.03.05.04.03 (3 juegos OC-01 de tres techos de 3.79, 4.21 y 3.79 m; laminas DPL-41 y DPL-42). Mismo criterio de las canaletas de techo (hoja ACU CANALETAS de la planilla).
A9: DATOS DE CALCULO (hoja METRADO CANALETA BANCAS y especificaciones tecnicas)
A10: N° | B10: DATO | C10: UND | D10: VALOR | H10: SUSTENTO
A11: 1 | B11: Ancho interior de la canaleta | C11: m | D11: 0.18 | H11: METRADO CANALETA BANCAS F18; laminas DPL-41 y DPL-42
A12: 2 | B12: Altura interior de la canaleta | C12: m | D12: 0.21 | H12: METRADO CANALETA BANCAS F19
A13: 3 | B13: Ala posterior apoyada sobre la viga de la pergola | C13: m | D13: 0.1 | H13: especificacion 01.04.03.05.04.01
A14: 4 | B14: Desarrollo de plancha por metro de canaleta | C14: m2/m | D14: =D11+2*D12+D13 | H14: fondo + 2 lados + ala = 0.70 m
A15: 5 | B15: Espesor de plancha galvanizada | C15: mm | D15: 0.5 | H15: METRADO CANALETA BANCAS F20
A16: 6 | B16: Peso de la plancha galvanizada | C16: kg/m2 | D16: =D15*7.85+0.3 | H16: espesor x 7.85 kg/m2 por mm + zinc (0.3 kg/m2)
A17: 7 | B17: Pestana de la tapa lateral (contorno) | C17: m | D17: 0.02 | H17: especificacion 01.04.03.05.04.03
A18: 8 | B18: Piezas por techo | C18: und | D18: 1 | H18: una sola pieza por techo, sin uniones ni traslapes (especificacion)
A23: ACU 1: 01.04.03.05.04.01 CANALETA DE PLANCHA DE ACERO GALVANIZADO e=0.50mm, SECCIÓN 0.18m x 0.21m
A24: Unidad | C24: m
A25: Metrado | C25: ='RESUMEN ACU'!D12
A26: Rendimiento (m/dia) | C26: 25 | E26: fabricacion en una pieza por techo (corte y doblado en obra) y colocacion sobre sus dos soportes; cuadrilla 1 op + 1 peon
A27: N° | B27: RECURSO | C27: UND | D27: CUADRILLA | E27: CANTIDAD | F27: PRECIO S/ | G27: PARCIAL S/ | H27: SUSTENTO / FUENTE
B28: MANO DE OBRA
A29: 1 | B29: Operario (hojalatero) | C29: hh | D29: 1 | E29: =D29*8/$C$26 | F29: ='COSTO HORA HOMBRE 2026'!$G$11 | G29: =E29*F29 | H29: hoja COSTO HORA HOMBRE 2026 (tabla oficial CAPECO-FTCCP 2026)
A30: 2 | B30: Peon | C30: hh | D30: 1 | E30: =D30*8/$C$26 | F30: ='COSTO HORA HOMBRE 2026'!$G$13 | G30: =E30*F30 | H30: hoja COSTO HORA HOMBRE 2026 (tabla oficial CAPECO-FTCCP 2026)
B31: Subtotal mano de obra | G31: =SUM(G29:G30)
B32: MATERIALES
A33: 3 | B33: Plancha de acero galvanizado e=0.50 mm | C33: m2 | E33: =$D$14*1.05 | F33: ='PRECIOS DE INSUMOS'!$D$5 | G33: =E33*F33 | H33: desarrollo 0.70 m2/m x 1.05 desperdicio (sin traslapes: una pieza por techo)
B34: Subtotal materiales | G34: =SUM(G33:G33)
B35: EQUIPOS
A36: 4 | B36: Herramientas manuales | C36: %mo | E36: 0.05 | F36: =+G31 | G36: =E36*F36 | H36: 5 % del costo de mano de obra (hojalateria)
B37: Subtotal equipos | G37: =SUM(G36:G36)
A38: COSTO UNITARIO DIRECTO (S/ por m) | G38: =+G31+G34+G37
A39: COSTO DIRECTO DE LA PARTIDA (metrado x costo unitario) | G39: =G38*C25
A41: ACU 2: 01.04.03.05.04.03 TAPA LATERAL DE PLANCHA GALVANIZADA P/CANALETA SECCIÓN 0.18m x 0.21m
A42: Unidad | C42: und
A43: Metrado | C43: ='RESUMEN ACU'!D13
A44: Rendimiento (und/dia) | C44: 30 | E44: trazo, corte, doblez de pestanas, remachado y sellado en el extremo de la canaleta; cuadrilla 1 op + 0.5 peon
A45: N° | B45: RECURSO | C45: UND | D45: CUADRILLA | E45: CANTIDAD | F45: PRECIO S/ | G45: PARCIAL S/ | H45: SUSTENTO / FUENTE
B46: MANO DE OBRA
A47: 1 | B47: Operario (hojalatero) | C47: hh | D47: 1 | E47: =D47*8/$C$44 | F47: ='COSTO HORA HOMBRE 2026'!$G$11 | G47: =E47*F47 | H47: hoja COSTO HORA HOMBRE 2026 (tabla oficial CAPECO-FTCCP 2026)
...

Sheet COSTO HORA HOMBRE 2026
A1: COSTO DE LA HORA-HOMBRE 2026 - REGIMEN DE CONSTRUCCION CIVIL (TABLA OFICIAL CAPECO - FTCCP)
A2: ENTIDAD | C2: =+'RESUMEN ACU'!C4
A3: PROYECTO | C3: =+'RESUMEN ACU'!C5
A4: UBICACIÓN | C4: =+'RESUMEN ACU'!C6
A5: FECHA | C5: =+'RESUMEN ACU'!C7
A7: Costo de la hora-hombre en edificacion del 01.01.2026 al 31.12.2026, segun la tabla oficial elaborada entre CAPECO y la FTCCP (Remuneracion y condiciones de trabajo en construccion civil 2026, Acta final de negociacion colectiva, Exp. N° 339-2025-MTPE/2.14-NC). El resumen de la parte 1 es el que usan todas las ACU de la planilla. Celda amarilla = dato de la tabla oficial; verde = formula.
A9: 1. COSTO HORA-HOMBRE 2026 POR CATEGORIA (lo usan todas las ACU)
A10: N° | B10: CATEGORIA | C10: JORNAL BASICO (S/ dia) | D10: TOTAL POR DIA DE 8 h (S/) | G10: COSTO HH 2026 (S/ hh) | H10: FUENTE
A11: 1 | B11: Operario | C11: =D17 | D11: =D25 | G11: =D26 | H11: Tabla oficial CAPECO - FTCCP 2026 (Exp. N° 339-2025-MTPE/2.14-NC)
A12: 2 | B12: Oficial | C12: =E17 | D12: =E25 | G12: =E26 | H12: Tabla oficial CAPECO - FTCCP 2026 (Exp. N° 339-2025-MTPE/2.14-NC)
A13: 3 | B13: Peon | C13: =F17 | D13: =F25 | G13: =F26 | H13: Tabla oficial CAPECO - FTCCP 2026 (Exp. N° 339-2025-MTPE/2.14-NC)
A15: 2. COSTO HORA-HOMBRE EN EDIFICACION DEL 01.01.2026 AL 31.12.2026
A16: N° | B16: CONCEPTO | C16: BASE | D16: OPERARIO | E16: OFICIAL | F16: PEON | H16: SUSTENTO
A17: 1 | B17: Remuneracion basica del 01/01/2026 al 31/12/2026 | C17: jornal | D17: 89.3 | E17: 69.75 | F17: 62.8 | H17: R.M. 197-2025-TR; tabla oficial CAPECO - FTCCP 2026
A18: 2 | B18: Beneficios y leyes sociales sobre el jornal basico (%) | C18: =$D$50 | D18: =ROUND(D17*$C$18/100,2) | E18: =ROUND(E17*$C$18/100,2) | F18: =ROUND(F17*$C$18/100,2) | H18: parte 3: 112.20 % sobre el jornal basico
A19: 3 | B19: Bonificacion unificada de construccion (BUC) | C19: 32/30/30 % | D19: =ROUND(D17*0.32,2) | E19: =ROUND(E17*0.30,2) | F19: =ROUND(F17*0.30,2) | H19: 32 % operario; 30 % oficial y peon
A20: 4 | B20: Beneficios y leyes sociales sobre el BUC (%) | C20: =$E$50 | D20: =ROUND(D19*$C$20/100,2) | E20: =ROUND(E19*$C$20/100,2) | F20: =ROUND(F19*$C$20/100,2) | H20: parte 3: 12.25 % sobre el BUC
A21: 5 | B21: Seguro de vida ESSALUD + Vida (S/ 5.00 por mes) | C21: dia | D21: 0.16 | E21: 0.16 | F21: 0.16 | H21: tabla oficial
A22: 6 | B22: Fondo de capacitacion (Exp. N° 339-2025-MTPE/2.14-NC) | C22: dia | D22: 0.4 | E22: 0.31 | F22: 0.28 | H22: tabla oficial
A23: 7 | B23: Bonificacion por movilidad (R.M. N° 139-2024-TR) | C23: dia | D23: 8.6 | E23: 8.6 | F23: 8.6 | H23: S/ 8.60 por dia laborado en todo el pais
A24: 8 | B24: Overol (R.D. N° 777-87-DR-LIM): (2 x S/ 132.80) / 300 | C24: dia | D24: =ROUND(2*132.8/300,2) | E24: =ROUND(2*132.8/300,2) | F24: =ROUND(2*132.8/300,2) | H24: tabla oficial
B25: Total por dia de 8 horas (S/) | D25: =SUM(D17:D24) | E25: =SUM(E17:E24) | F25: =SUM(F17:F24)
B26: Costo de la hora-hombre (S/ hh) | D26: =ROUND(D25/8,2) | E26: =ROUND(E25/8,2) | F26: =ROUND(F25/8,2) | H26: total por dia / 8 horas
A28: 3. PORCENTAJES DE BENEFICIOS Y LEYES SOCIALES EN EDIFICACION (tabla oficial CAPECO - FTCCP 2026)
A29: N° | B29: CONCEPTO | D29: SOBRE JORNAL BASICO (%) | E29: SOBRE BUC (%) | H29: SUSTENTO
A30: 1 | B30: 1.01 Indemnizacion por tiempo de servicios | D30: 12 | H30: tabla oficial
A31: 2 | B31: 1.01 Indemnizacion por participacion de utilidades | D31: 3 | H31: tabla oficial
A32: 3 | B32: 1.02 SCTR: prestaciones asistenciales (Ley 26790) | D32: 1.3 | E32: 1.3 | H32: tabla oficial
A33: 4 | B33: 1.02 SCTR: prestaciones economicas | D33: 1.05 | E33: 1.05 | H33: tabla oficial
A34: 5 | B34: 1.04 Regimen de prestaciones de salud (ESSALUD) | D34: 9 | E34: 9 | H34: tabla oficial
A35: 6 | B35: 1.05 Seguro de vida ley | D35: 0.9 | E35: 0.9 | H35: tabla oficial
A36: 7 | B36: 2.01 Salario dominical | D36: 17.58 | H36: tabla oficial
A37: 8 | B37: 2.02 Vacaciones record (30 dias) | D37: 10 | H37: tabla oficial
A38: 9 | B38: 2.03 Gratificacion por Fiestas Patrias y Navidad | D38: 22.22 | H38: tabla oficial
A39: 10 | B39: 2.04 Jornales por dias feriados no laborables | D39: 4.33 | H39: tabla oficial
A40: 11 | B40: 2.05 Asignacion escolar (promedio 3 hijos) | D40: 25 | H40: tabla oficial
A41: 12 | B41: 3.01 ESSALUD sobre salario dominical (9 % de 17.58 %) | D41: 1.58 | H41: tabla oficial
A42: 13 | B42: 3.02 ESSALUD sobre vacaciones (9 % de 10.00 %) | D42: 0.9 | H42: tabla oficial
A43: 14 | B43: 3.03 ESSALUD sobre feriados (9 % de 4.33 %) | D43: 0.39 | H43: tabla oficial
A44: 15 | B44: 4.01 SCTR sobre salario dominical (2.35 % de 17.58 %) | D44: 0.41 | H44: tabla oficial
...
