Workbook

Sheet 1 COTIZACION
A1: COTIZACION DE INSUMOS - ACU TAPA DE REGISTRO 0.68 x 0.68 C/MARCO Y CONTRAMARCO (Delphin 01.04.04.06.05.01; metrado 01.04.04.05.01)
A2: PROYECTO: HOGAR DE REFUGIO TEMPORAL - MUJERES VIOLENTADAS, DISTRITO DE MORALES, SAN MARTIN - CUI N.° 2675514
A3: Busqueda de precios publicados: 14/10/2026. Precio publicado tal como lo muestra la tienda (con IGV, salvo la tarifa de agua). Precio sin IGV = precio publicado / contenido / factor IGV. Los precios de Sodimac y Promart son nacionales (ambas tienen tienda en Tarapoto); el precio de la tienda de Tarapoto puede variar.
A5: N° | B5: INSUMO DE LA ACU | C5: UND | D5: PRODUCTO COTIZADO | E5: PRESENTACION | F5: PRECIO PUBLICADO S/ | G5: CONTENIDO (UND ACU) | H5: IGV | I5: PRECIO S/ SIN IGV | J5: PRECIO ACTUAL ACU | K5: VARIACION | L5: TIENDA / FUENTE | M5: ENLACE | N5: ESTADO
A6: 1 | B6: Angulo L 1 1/2"x1 1/2"x1/8" | C6: kg | D6: Angulo de Acero 1 1/2 x 1 1/2 x 1/8 x 6M (Tupemesa) | E6: barra 6 m | F6: 39.9 | G6: =6*'2 ANGULOS'!C7 | H6: 1.18 | I6: =F6/G6/H6 | J6: 4.66 | K6: =IF(OR(J6="",F6=""),"",I6/J6-1) | L6: Sodimac Peru | M6: abrir | N6: COMPROBADO (precio nacional)
A7: 2 | B7: Angulo L 1"x1"x1/8" (alternativa) | C7: kg | D7: Angulo de Acero 25 x 25 x 3.0 x 6M (Tupemesa) | E7: barra 6 m | F7: 24.9 | G7: =6*'2 ANGULOS'!C8 | H7: 1.18 | I7: =F7/G7/H7 | K7: =IF(OR(J7="",F7=""),"",I7/J7-1) | L7: Sodimac Peru | M7: abrir | N7: COMPROBADO (sin stock en linea)
A8: 3 | B8: Angulo L 2"x2"x3/16" (actual) | C8: kg | D8: Ninguna tienda peruana publica precio en soles | E8: barra 6 m | G8: =6*'2 ANGULOS'!C10 | H8: 1.18 | I8: =J8 | J8: 4.66 | K8: =IF(OR(J8="",F8=""),"",I8/J8-1) | L8: - | M8: - | N8: SIN PRECIO PUBLICADO
A9: 4 | B9: Soldadura cellocord E6011 1/8" | C9: kg | D9: Soldadura Cellocord 1/8" (E-6011) | E9: caja 5 kg | F9: 109.9 | G9: 5 | H9: 1.18 | I9: =F9/G9/H9 | J9: 13.56 | K9: =IF(OR(J9="",F9=""),"",I9/J9-1) | L9: Sodimac Peru | M9: abrir | N9: COMPROBADO (precio nacional)
A10: 5 | B10: Cemento Portland tipo I | C10: bol | D10: Cemento Pacasmayo Tipo I Portland 42.5 kg | E10: bolsa 42.5 kg | F10: 36.5 | G10: 1 | H10: 1.18 | I10: =F10/G10/H10 | J10: 30.51 | K10: =IF(OR(J10="",F10=""),"",I10/J10-1) | L10: Ferreteria Dinova | M10: abrir | N10: COMPROBADO (marca que se distribuye en San Martin)
A11: 6 | B11: Arena gruesa | C11: m3 | D11: Arena gruesa - Agregados Tarapoto (Jr. Felipe Yap 220, Morales) | E11: m3 (delivery desde 3 m3) | F11: 48 | G11: 1 | H11: 1.18 | I11: =F11/G11/H11 | J11: 50.85 | K11: =IF(OR(J11="",F11=""),"",I11/J11-1) | L11: Agregados Tarapoto (Morales) | M11: abrir | N11: COMPROBADO LOCAL (Morales)
A12: 7 | B12: Piedra chancada 1/2" | C12: m3 | D12: En Tarapoto solo se publica la piedra chancada 3/4" a S/ 70.00 el m3 (mismo proveedor) | E12: m3 | G12: 1 | H12: 1.18 | I12: =J12 | J12: 101.69 | K12: =IF(OR(J12="",F12=""),"",I12/J12-1) | L12: Agregados Tarapoto (Morales) | M12: abrir | N12: SIN PRECIO PUBLICADO DE 1/2" (se mantiene el actual)
A13: 8 | B13: Agua | C13: m3 | D13: EMAPA San Martin, categoria comercial y otros, tramo de 30 m3 a mas: agua 6.80 + alcantarillado 1.53 | E13: m3 | F13: 8.33 | G13: 1 | H13: 1 | I13: =F13/G13/H13 | J13: 5 | K13: =IF(OR(J13="",F13=""),"",I13/J13-1) | L13: Res. 00077-2024-SUNASS-CD (El Peruano 18/12/2024); tarifa sin IGV | M13: abrir | N13: COMPROBADO (tarifa oficial Tarapoto)
A14: 9 | B14: Madera tornillo | C14: p2 | D14: Madera tornillo por pie | E14: p2 | F14: 5.2 | G14: 1 | H14: 1.18 | I14: =F14/G14/H14 | J14: 5.08 | K14: =IF(OR(J14="",F14=""),"",I14/J14-1) | L14: Maderas del Norte | M14: abrir | N14: REFERENCIA (la pagina no indica ciudad)
A15: 10 | B15: Acero corrugado 1/2" (borde de abertura) | C15: kg | D15: Barras de Acero 1/2" x 9 m Aceros Arequipa (8.946 kg) | E15: varilla 9 m | F15: 36.5 | G15: 8.946 | H15: 1.18 | I15: =F15/G15/H15 | J15: 3.81 | K15: =IF(OR(J15="",F15=""),"",I15/J15-1) | L15: Sodimac Peru | M15: abrir | N15: COMPROBADO (precio nacional)
A16: 11 | B16: Acero corrugado 3/8" (parrilla, asas, anclajes) | C16: kg | D16: Barras de Acero 3/8" x 9 m Aceros Arequipa (5.04 kg) | E16: varilla 9 m | F16: 20.35 | G16: 5.04 | H16: 1.18 | I16: =F16/G16/H16 | J16: 3.81 | K16: =IF(OR(J16="",F16=""),"",I16/J16-1) | L16: Sodimac Peru | M16: abrir | N16: COMPROBADO (precio nacional)
A17: 12 | B17: Alambre negro N 16 | C17: kg | D17: Alambre Recocido N° 16 x 10 kg (Prodac) | E17: rollo 10 kg | F17: 59.9 | G17: 10 | H17: 1.18 | I17: =F17/G17/H17 | J17: 5.08 | K17: =IF(OR(J17="",F17=""),"",I17/J17-1) | L17: Sodimac Peru | M17: abrir | N17: COMPROBADO (precio nacional)
A18: 13 | B18: Pintura anticorrosiva | C18: gal | D18: Anticorrosivo Vencedor Gris 1 gl | E18: galon | F18: 53 | G18: 1 | H18: 1.18 | I18: =F18/G18/H18 | J18: 59.32 | K18: =IF(OR(J18="",F18=""),"",I18/J18-1) | L18: Promart | M18: abrir | N18: COMPROBADO (precio nacional)
A19: 14 | B19: Esmalte sintetico | C19: gal | D19: Esmalte sintetico CPP negro 1 gl (cod. 30635) | E19: galon | F19: 57 | G19: 1 | H19: 1.18 | I19: =F19/G19/H19 | J19: 55.08 | K19: =IF(OR(J19="",F19=""),"",I19/J19-1) | L19: Promart | M19: abrir | N19: COMPROBADO (precio nacional)
A20: 15 | B20: Lija para fierro N° 80 | C20: und | D20: Lija Fierro 3M ASA grano 80 | E20: pliego | F20: 2.5 | G20: 1 | H20: 1.18 | I20: =F20/G20/H20 | K20: =IF(OR(J20="",F20=""),"",I20/J20-1) | L20: Sodimac Peru | M20: abrir | N20: COMPROBADO (precio nacional)
A21: 16 | B21: Thinner acrilico | C21: gal | D21: TOPEX Thinner Acrilico 3.5 L | E21: envase 3.5 L | F21: 38.9 | G21: =3.5/3.785 | H21: 1.18 | I21: =F21/G21/H21 | K21: =IF(OR(J21="",F21=""),"",I21/J21-1) | L21: Sodimac Peru | M21: abrir | N21: COMPROBADO (precio nacional)
A22: 17 | B22: Mezcladora 9-11 p3 | C22: hm | D22: Alquiler de mezcladora de concreto 9-11 p3 | E22: hora-maquina | F22: 15 | G22: 1 | H22: 1.18 | I22: =F22/G22/H22 | J22: 15 | K22: =IF(OR(J22="",F22=""),"",I22/J22-1) | L22: Konstrutecnia (Juliaca) | M22: abrir | N22: REFERENCIA (otra ciudad; no hay tarifa publicada en Tarapoto)
A23: 18 | B23: Vibrador de concreto | C23: hm | D23: Alquiler de vibradora de concreto 5.5 HP | E23: hora-maquina | F23: 13 | G23: 1 | H23: 1.18 | I23: =F23/G23/H23 | J23: 10 | K23: =IF(OR(J23="",F23=""),"",I23/J23-1) | L23: Konstrutecnia (Juliaca) | M23: abrir | N23: REFERENCIA (otra ciudad; no hay tarifa publicada en Tarapoto)
A24: 19 | B24: Maquina de soldar 250 A | C24: hm | D24: Ninguna empresa publica tarifa por hora o por dia (solo S/ 30 y S/ 55 sin periodo) | E24: hora-maquina | G24: 1 | H24: 1.18 | I24: =J24 | J24: 8 | K24: =IF(OR(J24="",F24=""),"",I24/J24-1) | L24: Ferropolis / ST America | M24: abrir | N24: SIN TARIFA PUBLICADA (se mantiene el actual)
A25: 20 | B25: Acero corrugado fy=4200 (ponderado de la tapa) | C25: kg | D25: 1/2": 111.33 kg + 3/8": 62.05 kg por las 10 tapas (hoja COLECTOR ACERO filas 33 a 36) | I25: =(I15*111.328+I16*62.048)/173.376 | J25: 3.81 | K25: =I25/J25-1 | L25: Sodimac Peru | M25: - | N25: COMPROBADO (precio nacional)
A26: 21 | B26: Operario | C26: hh | D26: Jornal basico 2026 S/ 89.30 por dia (convenio CAPECO-FTCCP 2026, R.M. 197-2025-TR); costo hora-hombre con beneficios sociales de la planilla | E26: hora-hombre | F26: 30.42 | G26: 1 | H26: 1 | I26: =F26/G26/H26 | J26: 30.42 | K26: =I26/J26-1 | L26: FTCCP - tablas salariales 2026 | M26: abrir | N26: JORNAL OFICIAL 2026; costo hh se mantiene (decision pendiente)
A27: 22 | B27: Oficial | C27: hh | D27: Jornal basico 2026 S/ 69.75 por dia (convenio CAPECO-FTCCP 2026, R.M. 197-2025-TR); costo hora-hombre con beneficios sociales de la planilla | E27: hora-hombre | F27: 22.95 | G27: 1 | H27: 1 | I27: =F27/G27/H27 | J27: 22.95 | K27: =I27/J27-1 | L27: FTCCP - tablas salariales 2026 | M27: abrir | N27: JORNAL OFICIAL 2026; costo hh se mantiene (decision pendiente)
A28: 23 | B28: Peon | C28: hh | D28: Jornal basico 2026 S/ 62.80 por dia (convenio CAPECO-FTCCP 2026, R.M. 197-2025-TR); costo hora-hombre con beneficios sociales de la planilla | E28: hora-hombre | F28: 20.79 | G28: 1 | H28: 1 | I28: =F28/G28/H28 | J28: 20.79 | K28: =I28/J28-1 | L28: FTCCP - tablas salariales 2026 | M28: abrir | N28: JORNAL OFICIAL 2026; costo hh se mantiene (decision pendiente)
A30: NOTAS
A31: 1. Verde = precio publicado y encontrado; naranja = referencia (otra ciudad o sin ciudad); rojo = sin precio publicado: se mantiene el precio actual y debe cotizarse en Tarapoto.
A32: 2. Angulo L 2"x2"x3/16": ninguna tienda en linea del Peru lo publica en soles; solo se vende por pedido a distribuidores. Por eso se propone el L 1 1/2"x1 1/2"x1/8" (hoja 2 ANGULOS).
A33: 3. Piedra chancada 1/2": en Tarapoto se publica la de 3/4" (S/ 70.00 el m3, Agregados Tarapoto, Morales); la de 1/2" debe cotizarse. En la tapa (8 cm) su incidencia es menor de S/ 2.00.
A34: 4. Arena (Agregados Tarapoto): se tomo el precio publicado como precio con IGV; si el proveedor no emite factura, usar S/ 48.00 directo (celda H11 = 1.00).
A35: 5. Lija y thinner reemplazan al global "Lija y thinner" de la ACU actual (ver DESAGREGADO_LIJA_THINNER_TAPA_REGISTRO_HOGAR_REFUGIO.xlsx).
A36: 6. Mano de obra: el jornal basico 2026 es oficial; el costo hora-hombre con beneficios sociales de la planilla (30.42 / 22.95 / 20.79) no se cambia en esta propuesta.

Sheet 2 ANGULOS
A1: PROPUESTA DE ANGULOS PARA MARCO Y CONTRAMARCO - TAPA DE REGISTRO 0.68 x 0.68 x 0.08 (DD-01, DD-02, DP-06B)
A2: PROYECTO: HOGAR DE REFUGIO TEMPORAL - MUJERES VIOLENTADAS, DISTRITO DE MORALES, SAN MARTIN - CUI N.° 2675514
A3: Los 10 registros (RS-01 a RS-07, CL y 2 en CC) estan fuera del ingreso vehicular OE-01 (prog. 0+026.32 a 0+031.33) y del porton de motos (0+039.04 a 0+041.04), bajo vereda y jardin: carga peatonal (E.020). El RS-03 (0+032.50) y el RS-04 (0+042.68) son los mas cercanos a los cruces.
A5: 1. ANGULOS COMERCIALES (barra de 6 m, ASTM A36)
A6: N° | B6: ANGULO | C6: PESO kg/m | D6: ALA mm | E6: ESPESOR mm | F6: PRECIO BARRA S/ (con IGV) | G6: S/ POR kg SIN IGV | H6: OBSERVACION
A7: 1 | B7: L 1 1/2"x1 1/2"x1/8" | C7: 1.83 | D7: 38.1 | E7: 3.18 | F7: ='1 COTIZACION'!F6 | G7: =F7/1.18/(6*C7) | H7: PROPUESTO para marco y contramarco: precio publicado (Sodimac Peru), 1 barra por tapa
A8: 2 | B8: L 1"x1"x1/8" | C8: 1.19 | D8: 25.4 | E8: 3.18 | F8: ='1 COTIZACION'!F7 | G8: =F8/1.18/(6*C8) | H8: Ala de 25 mm: asiento util de 15 mm con la holgura de 1 cm; no se recomienda
A9: 3 | B9: L 2"x2"x1/8" | C9: 2.46 | D9: 50.8 | E9: 3.18 | F9: sin precio | G9: - | H9: Sin precio publicado en tiendas
A10: 4 | B10: L 2"x2"x3/16" (actual contramarco) | C10: 3.63 | D10: 50.8 | E10: 4.76 | F10: sin precio | G10: - | H10: Sin precio publicado en tiendas; sobredimensionado para el asiento
A11: 5 | B11: L 1 1/2"x1 1/2"x3/16" | C11: 2.68 | D11: 38.1 | E11: 4.76 | F11: sin precio | G11: - | H11: Sin precio publicado en tiendas
A13: 2. VERIFICACION DEL CONTRAMARCO CON L 1 1/2"x1 1/2"x1/8" (carga peatonal)
A14: N° | B14: CONCEPTO | C14: VALOR | D14: UND | H14: SUSTENTO
A15: 1 | B15: Lado de la tapa | C15: 0.68 | D15: m | H15: DP-06B
A16: 2 | B16: Espesor de la tapa | C16: 0.08 | D16: m | H16: DP-06B
A17: 3 | B17: Peso de la tapa de concreto armado | C17: =C15^2*C16*2400 | D17: kg | H17: peso unitario 2400 kg/m3 (E.020)
A18: 4 | B18: Peso del marco L 1 1/2"x1/8" | C18: =4*C15*C7 | D18: kg | H18: 4 x 0.68 x 1.83
A19: 5 | B19: Carga muerta D | C19: =C17+C18 | D19: kg
A20: 6 | B20: Sobrecarga peatonal | C20: 500 | D20: kg/m2 | H20: E.020, veredas y pasadizos
A21: 7 | B21: Carga viva L sobre la tapa | C21: =C20*C15^2 | D21: kg
A22: 8 | B22: Carga ultima Wu = 1.4 D + 1.7 L | C22: =1.4*C19+1.7*C21 | D22: kg | H22: E.060
A23: 9 | B23: Holgura entre tapa y abertura | C23: 0.01 | D23: m | H23: DD-01, 1 cm por lado
A24: 10 | B24: Ancho de asiento util = ala - holgura | C24: =D7/1000-C23 | D24: m | H24: el ala horizontal apoya entera sobre el borde engrosado de concreto (corte B de DD-01)
A25: 11 | B25: Area de apoyo = 4 x 0.68 x ancho util | C25: =4*C15*C24*10000 | D25: cm2
A26: 12 | B26: Esfuerzo de aplastamiento sobre el concreto | C26: =C22/C25 | D26: kg/cm2
A27: 13 | B27: Resistencia al aplastamiento 0.65 x 0.85 x f'c (f'c = 210) | C27: =0.65*0.85*210 | D27: kg/cm2 | H27: E.060 10.17
A28: 14 | B28: Verificacion | C28: =IF(C26<C27,"CUMPLE","NO CUMPLE") | D28: -
A29: 15 | B29: Luz libre del registro = 0.70 - 2 x ala | C29: =0.70-2*D7/1000 | D29: m | H29: con L 2" era 0.60 m: mejora el acceso para limpieza
A30: 16 | B30: Longitud por tapa: contramarco 4 x 0.706 + marco 4 x 0.68 | C30: =4*(0.70+2*E7/1000)+4*0.68 | D30: m | H30: cabe en 1 barra de 6.00 m (un solo producto para marco y contramarco)
A31: 17 | B31: Barras de 6 m por tapa | C31: =ROUNDUP(C30/6,0) | D31: und
A33: 3. CONCLUSION
A34: El ala horizontal del contramarco descansa entera sobre el concreto del borde engrosado, de modo que el angulo no trabaja a flexion: protege la arista y sirve de asiento. El espesor de 3/16" no aporta resistencia necesaria; con 1/8" el esfuerzo de apoyo es muy inferior al admisible.
A35: Se propone un solo angulo L 1 1/2"x1 1/2"x1/8" para marco y contramarco: precio publicado, una barra de 6 m por tapa, menos peso (10.10 kg en lugar de 15.14 kg por tapa) y mayor luz libre.
A36: Al usar ala de 1 1/2", el asiento de concreto bajo el ala horizontal pasa de 50 mm a 38 mm. Los anclajes 3/8" se sueldan al ala vertical con cordon de 1/8" (espesor del angulo 3.2 mm).
A37: Si se aprueba, cambian: COLECTOR PARAMETROS (fila 36, 38 y 40), COLECTOR REGISTROS Y TAPAS (fila 23), DESAGREGADO TAPA REGISTRO, ACU TAPA REGISTRO, la descripcion de la planilla general (fila 317) y las laminas DD-01, DD-02, DP-06B y cuadros. Angulos de la partida: de 151.42 kg a 101.02 kg (10 tapas).

Sheet 3 ACU COMPARATIVO
A1: ACU TAPA DE REGISTRO 0.68 x 0.68 C/MARCO Y CONTRAMARCO - ACTUAL FRENTE A PROPUESTA CON PRECIOS COTIZADOS (por und de tapa)
A2: PROYECTO: HOGAR DE REFUGIO TEMPORAL - MUJERES VIOLENTADAS, DISTRITO DE MORALES, SAN MARTIN - CUI N.° 2675514
A3: Actual = ACU TAPA REGISTRO de la planilla vigente. Propuesta = marco y contramarco con L 1 1/2"x1 1/2"x1/8", lija y thinner desagregados y precios de la hoja 1 COTIZACION. Ratios de COLECTOR INSUMOS sin cambio. Mano de obra con el costo hora-hombre de la planilla.
A5: PARAMETROS DE LA PROPUESTA (por tapa)
A6: 1 | B6: Perimetro del contramarco (4 x 0.70) | C6: m | D6: 2.8
A7: 2 | B7: Perimetro del marco (4 x 0.68) | C7: m | D7: 2.72
A8: 3 | B8: Peso del angulo L 1 1/2"x1 1/2"x1/8" | C8: kg/m | D8: ='2 ANGULOS'!C7
A9: 4 | B9: Angulos por tapa | C9: kg | D9: =(D6+D7)*D8
A10: 5 | B10: Desarrollo pintado del angulo 1 1/2" (4 caras) | C10: m2/m | D10: 0.152
A11: 6 | B11: Area pintada por tapa | C11: m2 | D11: =(D6+D7)*D10
A12: 7 | B12: Concreto por tapa | C12: m3 | D12: 0.036992
A13: 8 | B13: Acero corrugado por tapa | C13: kg | D13: 17.3376
A15: N° | B15: RECURSO | C15: UND | D15: CANT. ACTUAL | E15: PRECIO ACTUAL | F15: PARCIAL ACTUAL | G15: CANT. PROPUESTA | H15: PRECIO COTIZADO | I15: PARCIAL PROPUESTA | J15: OBSERVACION
A16: MANO DE OBRA
A17: 1 | B17: Operario | C17: hh | D17: 3.4912928 | E17: 30.42 | F17: =D17*N(E17) | G17: =$D$9*0.1+$D$12*0.8+$D$13*0.032+$D$11*0.4+1 | H17: ='1 COTIZACION'!I26 | I17: =G17*N(H17) | J17: angulos 0.1 + concreto 0.8 + acero 0.032 + pintura 0.4 + colocacion 1
A18: 2 | B18: Oficial | C18: hh | D18: 2.0985568 | E18: 22.95 | F18: =D18*N(E18) | G18: =$D$9*0.1+$D$12*0.8+$D$13*0.032 | H18: ='1 COTIZACION'!I27 | I18: =G18*N(H18)
A19: 3 | B19: Peon | C19: hh | D19: 1.2367488 | E19: 20.79 | F19: =D19*N(E19) | G19: =$D$12*6.4+1 | H19: ='1 COTIZACION'!I28 | I19: =G19*N(H19)
A20: MATERIALES
A21: 4 | B21: Angulo L 2"x2"x3/16" | C21: kg | D21: 10.6722 | E21: 4.66 | F21: =D21*N(E21) | G21: 0 | I21: =G21*N(H21) | J21: se elimina
A22: 5 | B22: Angulo L 1 1/2"x1 1/2"x1/8" | C22: kg | D22: 5.22648 | E22: 4.66 | F22: =D22*N(E22) | G22: =$D$9*1.05 | H22: ='1 COTIZACION'!I6 | I22: =G22*N(H22) | J22: marco + contramarco, 5 % de desperdicio
A23: 6 | B23: Soldadura cellocord E6011 1/8" | C23: kg | D23: 0.454248 | E23: 13.56 | F23: =D23*N(E23) | G23: =$D$9*0.03 | H23: ='1 COTIZACION'!I9 | I23: =G23*N(H23)
A24: 7 | B24: Cemento Portland tipo I | C24: bol | D24: 0.35993216 | E24: 30.51 | F24: =D24*N(E24) | G24: =$D$12*9.73 | H24: ='1 COTIZACION'!I10 | I24: =G24*N(H24)
A25: 8 | B25: Arena gruesa | C25: m3 | D25: 0.01923584 | E25: 50.85 | F25: =D25*N(E25) | G25: =$D$12*0.52 | H25: ='1 COTIZACION'!I11 | I25: =G25*N(H25)
A26: 9 | B26: Piedra chancada 1/2" | C26: m3 | D26: 0.01960576 | E26: 101.69 | F26: =D26*N(E26) | G26: =$D$12*0.53 | H26: ='1 COTIZACION'!I12 | I26: =G26*N(H26) | J26: precio actual (sin precio publicado de 1/2")
A27: 10 | B27: Agua | C27: m3 | D27: 0.006880512 | E27: 5 | F27: =D27*N(E27) | G27: =$D$12*0.186 | H27: ='1 COTIZACION'!I13 | I27: =G27*N(H27)
A28: 11 | B28: Madera tornillo | C28: p2 | D28: 1.15 | E28: 5.08 | F28: =D28*N(E28) | G28: 1.15 | H28: ='1 COTIZACION'!I14 | I28: =G28*N(H28)
A29: 12 | B29: Acero corrugado fy=4200 | C29: kg | D29: 18.20448 | E29: 3.81 | F29: =D29*N(E29) | G29: =$D$13*1.05 | H29: ='1 COTIZACION'!I25 | I29: =G29*N(H29) | J29: precio ponderado 1/2" y 3/8"
A30: 13 | B30: Alambre negro N 16 | C30: kg | D30: 1.040256 | E30: 5.08 | F30: =D30*N(E30) | G30: =$D$13*0.06 | H30: ='1 COTIZACION'!I17 | I30: =G30*N(H30)
A31: 14 | B31: Pintura anticorrosiva | C31: gal | D31: 0.0785472 | E31: 59.32 | F31: =D31*N(E31) | G31: =$D$11*0.08 | H31: ='1 COTIZACION'!I18 | I31: =G31*N(H31)
A32: 15 | B32: Esmalte sintetico | C32: gal | D32: 0.0785472 | E32: 55.08 | F32: =D32*N(E32) | G32: =$D$11*0.08 | H32: ='1 COTIZACION'!I19 | I32: =G32*N(H32)
A33: 16 | B33: Lija y thinner | C33: glb | D33: 0.049092 | E33: 25.42 | F33: =D33*N(E33) | G33: 0 | I33: =G33*N(H33) | J33: se reemplaza por lija y thinner desagregados
A34: 17 | B34: Lija para fierro N° 80 | C34: und | D34: 0 | F34: =D34*N(E34) | G34: =$D$11*0.25 | H34: ='1 COTIZACION'!I20 | I34: =G34*N(H34) | J34: 0.25 und/m2
A35: 18 | B35: Thinner acrilico | C35: gal | D35: 0 | F35: =D35*N(E35) | G35: =$D$11*0.024 | H35: ='1 COTIZACION'!I21 | I35: =G35*N(H35) | J35: 0.024 gal/m2 (15 % de la pintura)
A36: EQUIPOS
A37: 19 | B37: Herramientas manuales | C37: %mo | D37: 0.03 | E37: =F41 | F37: =D37*F41 | G37: 0.03 | H37: =I41 | I37: =G37*I41 | J37: 3 % de la mano de obra
A38: 20 | B38: Mezcladora 9-11 p3 | C38: hm | D38: 0.0295936 | E38: 15 | F38: =D38*N(E38) | G38: =$D$12*0.8 | H38: ='1 COTIZACION'!I22 | I38: =G38*N(H38)
A39: 21 | B39: Vibrador de concreto | C39: hm | D39: 0.0295936 | E39: 10 | F39: =D39*N(E39) | G39: =$D$12*0.8 | H39: ='1 COTIZACION'!I23 | I39: =G39*N(H39)
A40: 22 | B40: Maquina de soldar 250 A | C40: hm | D40: 1.51416 | E40: 8 | F40: =D40*N(E40) | G40: =$D$9*0.1 | H40: ='1 COTIZACION'!I24 | I40: =G40*N(H40) | J40: precio actual (sin tarifa publicada)
B41: Subtotal mano de obra | F41: =SUM(F16:F19) | I41: =SUM(I16:I19)
B42: Subtotal materiales | F42: =SUM(F20:F35) | I42: =SUM(I20:I35)
...
