Workbook

Sheet MATRIZ
A1: MATRIZ DE SUSTENTO NORMATIVO DEL PROGRAMA ARQUITECTÓNICO
A2: Proyecto: “CREACIÓN DEL SERVICIO DE PROTECCIÓN A MUJERES VÍCTIMAS DE VIOLENCIA EN SITUACIÓN DE RIESGO DE FEMINICIDIO O PELIGRE SU INTEGRIDAD Y/O SALUD FÍSICA Y/O MENTAL EN HOGAR DE REFUGIO TEMPORAL DISTRITO DE MORALES DE LA PROVINCIA DE SAN MARTÍN DEL DEPARTAMENTO DE SAN MARTÍN”, CUI N.° 2675514
A4: ZONA | B4: AMBIENTE | C4: CANT. | D4: CAPACIDAD | E4: I.O. (m²/pers.) | F4: NORMA | G4: ÁREA MÍN. NORMA (m²) | H4: ÁREA MÍN. CALCULADA (m²) | I4: ÁREA PROYECTO (m²) | J4: RESULTADO | K4: LIN. MÍN. (m²) | L4: LIN. MÁX. (m²) | M4: LINEAMIENTOS | N4: ÁREA TOTAL PROGRAMA (m²) | O4: SUSTENTO
A5: Zona de obras exteriores
A6: Zona de obras exteriores | B6: Estacionamiento de autos | C6: 6 | F6: A.090 art. 17; lineamientos 3.8 | H6: =IF(AND(ISNUMBER(D6),ISNUMBER(E6)),D6*E6,IF(ISNUMBER(G6),G6,"—")) | I6: 12.5 | J6: =IF(AND(ISNUMBER(H6),ISNUMBER(I6)),IF(I6>=H6-0.001,"CUMPLE","NO CUMPLE"),"CONFORME") | M6: =IF(AND(ISNUMBER(K6),ISNUMBER(I6)),IF(AND(ISNUMBER(L6),I6<=L6),"EN RANGO","SUPERA"),"—") | N6: 244 | O6: La A.090 art. 17 pide 1 estacionamiento cada 6 personas del personal dentro del predio: las 6 plazas atienden hasta 36 personas. El estacionamiento interno permite que las usuarias desciendan dentro del refugio (lineamientos 3.8).
A7: Zona de obras exteriores | B7: Patio de descarga | C7: 3 | F7: Lineamientos 2.6 | H7: =IF(AND(ISNUMBER(D7),ISNUMBER(E7)),D7*E7,IF(ISNUMBER(G7),G7,"—")) | I7: 16 | J7: =IF(AND(ISNUMBER(H7),ISNUMBER(I7)),IF(I7>=H7-0.001,"CUMPLE","NO CUMPLE"),"CONFORME") | M7: =IF(AND(ISNUMBER(K7),ISNUMBER(I7)),IF(AND(ISNUMBER(L7),I7<=L7),"EN RANGO","SUPERA"),"—") | N7: 256 | O7: Zona de carga y descarga de proveedores (zaguán de servicio), con acceso a almacenes, despensa y residuos, separada de los espacios de las residentes (lineamientos 2.6).
A8: Zona de obras exteriores | B8: Estacionamiento de motos | C8: 12 | F8: A.090 art. 17 | H8: =IF(AND(ISNUMBER(D8),ISNUMBER(E8)),D8*E8,IF(ISNUMBER(G8),G8,"—")) | I8: 2.52 | J8: =IF(AND(ISNUMBER(H8),ISNUMBER(I8)),IF(I8>=H8-0.001,"CUMPLE","NO CUMPLE"),"CONFORME") | M8: =IF(AND(ISNUMBER(K8),ISNUMBER(I8)),IF(AND(ISNUMBER(L8),I8<=L8),"EN RANGO","SUPERA"),"—") | N8: 94.6 | O8: Estacionamiento del personal dentro del predio (A.090 art. 17).
A9: Zona de obras exteriores | B9: Garita + SS.HH. | C9: 1 | D9: 1 | E9: 3 | F9: R.V.M. 208-2019; lineamientos 2.4 | H9: =IF(AND(ISNUMBER(D9),ISNUMBER(E9)),D9*E9,IF(ISNUMBER(G9),G9,"—")) | I9: 10 | J9: =IF(AND(ISNUMBER(H9),ISNUMBER(I9)),IF(I9>=H9-0.001,"CUMPLE","NO CUMPLE"),"CONFORME") | M9: =IF(AND(ISNUMBER(K9),ISNUMBER(I9)),IF(AND(ISNUMBER(L9),I9<=L9),"EN RANGO","SUPERA"),"—") | N9: 10 | O9: Con 1 persona a 3.00 m² por persona (R.V.M. 208-2019), el área mínima es de 3.00 m², y el ambiente tiene 10.00 m². Caseta de vigilancia en el acceso principal, con servicio higiénico para el personal de guardia, comunicación interna y control de los accesos (lineamientos 2.4 y 2.6; R.V.M. 104-2019 num. 13.3.2).
A10: Zona de obras exteriores | B10: Cisterna y tanque elevado | C10: 1 | F10: IS.010; lineamientos 2.8 | H10: =IF(AND(ISNUMBER(D10),ISNUMBER(E10)),D10*E10,IF(ISNUMBER(G10),G10,"—")) | I10: 12 | J10: =IF(AND(ISNUMBER(H10),ISNUMBER(I10)),IF(I10>=H10-0.001,"CUMPLE","NO CUMPLE"),"CONFORME") | M10: =IF(AND(ISNUMBER(K10),ISNUMBER(I10)),IF(AND(ISNUMBER(L10),I10<=L10),"EN RANGO","SUPERA"),"—") | N10: 12 | O10: Almacenamiento de agua potable (lineamientos 2.8; A.030, anexos).
A11: Zona de obras exteriores | B11: PTAR | C11: 1 | F11: IS.020; A.030 anexos | H11: =IF(AND(ISNUMBER(D11),ISNUMBER(E11)),D11*E11,IF(ISNUMBER(G11),G11,"—")) | I11: 152 | J11: =IF(AND(ISNUMBER(H11),ISNUMBER(I11)),IF(I11>=H11-0.001,"CUMPLE","NO CUMPLE"),"CONFORME") | M11: =IF(AND(ISNUMBER(K11),ISNUMBER(I11)),IF(AND(ISNUMBER(L11),I11<=L11),"EN RANGO","SUPERA"),"—") | N11: 152 | O11: Tratamiento de las aguas residuales del local, previsto por la A.030 cuando no existe red pública de alcantarillado.
A12: Zona de obras exteriores | B12: Cunetas de drenaje pluvial | C12: 1 | F12: Drenaje pluvial | H12: =IF(AND(ISNUMBER(D12),ISNUMBER(E12)),D12*E12,IF(ISNUMBER(G12),G12,"—")) | I12: 410.1 | J12: =IF(AND(ISNUMBER(H12),ISNUMBER(I12)),IF(I12>=H12-0.001,"CUMPLE","NO CUMPLE"),"CONFORME") | M12: =IF(AND(ISNUMBER(K12),ISNUMBER(I12)),IF(AND(ISNUMBER(L12),I12<=L12),"EN RANGO","SUPERA"),"—") | N12: 410.1 | O12: Sistema de drenaje pluvial del local.
A13: Zona de obras exteriores | B13: Cerco perimétrico | C13: 1 | F13: Lineamientos 2.4 | H13: =IF(AND(ISNUMBER(D13),ISNUMBER(E13)),D13*E13,IF(ISNUMBER(G13),G13,"—")) | I13: 56.75 | J13: =IF(AND(ISNUMBER(H13),ISNUMBER(I13)),IF(I13>=H13-0.001,"CUMPLE","NO CUMPLE"),"CONFORME") | M13: =IF(AND(ISNUMBER(K13),ISNUMBER(I13)),IF(AND(ISNUMBER(L13),I13<=L13),"EN RANGO","SUPERA"),"—") | N13: 56.75 | O13: Cerco de seguridad en todo el perímetro (lineamientos 2.4: barda de al menos 2.00 m).
A14: Zona administrativa
A15: Zona administrativa | B15: Área de bienvenida | C15: 1 | D15: 5 | E15: 9.5 | F15: A.080 art. 6 | H15: =IF(AND(ISNUMBER(D15),ISNUMBER(E15)),D15*E15,IF(ISNUMBER(G15),G15,"—")) | I15: 47.5 | J15: =IF(AND(ISNUMBER(H15),ISNUMBER(I15)),IF(I15>=H15-0.001,"CUMPLE","NO CUMPLE"),"CONFORME") | K15: 30 | L15: 40 | M15: =IF(AND(ISNUMBER(K15),ISNUMBER(I15)),IF(AND(ISNUMBER(L15),I15<=L15),"EN RANGO","SUPERA"),"—") | N15: 47.5 | O15: Con 5 personas a 9.50 m² por persona (A.080 art. 6), el área mínima es de 47.50 m², y el ambiente tiene 47.50 m². Supera la superficie sugerida por los lineamientos (30.00 a 40.00 m²). Recibe a las usuarias desde el ingreso, como espacio acogedor de llegada (lineamientos 2.6 y 3.2).
A16: Zona administrativa | B16: Oficina de dirección | C16: 1 | D16: 2 | E16: 9.5 | F16: A.080 art. 6 | H16: =IF(AND(ISNUMBER(D16),ISNUMBER(E16)),D16*E16,IF(ISNUMBER(G16),G16,"—")) | I16: 19 | J16: =IF(AND(ISNUMBER(H16),ISNUMBER(I16)),IF(I16>=H16-0.001,"CUMPLE","NO CUMPLE"),"CONFORME") | K16: 6 | L16: 10 | M16: =IF(AND(ISNUMBER(K16),ISNUMBER(I16)),IF(AND(ISNUMBER(L16),I16<=L16),"EN RANGO","SUPERA"),"—") | N16: 19 | O16: Con 2 personas a 9.50 m² por persona (A.080 art. 6), el área mínima es de 19.00 m², y el ambiente tiene 19.00 m². Supera la superficie sugerida por los lineamientos (6.00 a 10.00 m²).
A17: Zona administrativa | B17: Sala de reuniones | C17: 1 | D17: 25 | E17: 1 | F17: A.090 art. 11 | H17: =IF(AND(ISNUMBER(D17),ISNUMBER(E17)),D17*E17,IF(ISNUMBER(G17),G17,"—")) | I17: 25 | J17: =IF(AND(ISNUMBER(H17),ISNUMBER(I17)),IF(I17>=H17-0.001,"CUMPLE","NO CUMPLE"),"CONFORME") | K17: 12 | L17: 20 | M17: =IF(AND(ISNUMBER(K17),ISNUMBER(I17)),IF(AND(ISNUMBER(L17),I17<=L17),"EN RANGO","SUPERA"),"—") | N17: 25 | O17: Con 25 personas a 1.00 m² por persona (A.090 art. 11), el área mínima es de 25.00 m², y el ambiente tiene 25.00 m². Supera la superficie sugerida por los lineamientos (12.00 a 20.00 m²).
A18: Zona administrativa | B18: Secretaría dirección | C18: 1 | D18: 1 | E18: 9.5 | F18: A.080 art. 6 | H18: =IF(AND(ISNUMBER(D18),ISNUMBER(E18)),D18*E18,IF(ISNUMBER(G18),G18,"—")) | I18: 9.5 | J18: =IF(AND(ISNUMBER(H18),ISNUMBER(I18)),IF(I18>=H18-0.001,"CUMPLE","NO CUMPLE"),"CONFORME") | M18: =IF(AND(ISNUMBER(K18),ISNUMBER(I18)),IF(AND(ISNUMBER(L18),I18<=L18),"EN RANGO","SUPERA"),"—") | N18: 9.5 | O18: Con 1 persona a 9.50 m² por persona (A.080 art. 6), el área mínima es de 9.50 m², y el ambiente tiene 9.50 m².
A19: Zona administrativa | B19: Oficina de administración | C19: 1 | D19: 2 | E19: 9.5 | F19: A.080 art. 6 | H19: =IF(AND(ISNUMBER(D19),ISNUMBER(E19)),D19*E19,IF(ISNUMBER(G19),G19,"—")) | I19: 19.5 | J19: =IF(AND(ISNUMBER(H19),ISNUMBER(I19)),IF(I19>=H19-0.001,"CUMPLE","NO CUMPLE"),"CONFORME") | M19: =IF(AND(ISNUMBER(K19),ISNUMBER(I19)),IF(AND(ISNUMBER(L19),I19<=L19),"EN RANGO","SUPERA"),"—") | N19: 19.5 | O19: Con 2 personas a 9.50 m² por persona (A.080 art. 6), el área mínima es de 19.00 m², y el ambiente tiene 19.50 m².
A20: Zona administrativa | B20: Sala de espera | C20: 1 | D20: 4 | E20: 9.5 | F20: A.080 art. 6 | H20: =IF(AND(ISNUMBER(D20),ISNUMBER(E20)),D20*E20,IF(ISNUMBER(G20),G20,"—")) | I20: 38 | J20: =IF(AND(ISNUMBER(H20),ISNUMBER(I20)),IF(I20>=H20-0.001,"CUMPLE","NO CUMPLE"),"CONFORME") | M20: =IF(AND(ISNUMBER(K20),ISNUMBER(I20)),IF(AND(ISNUMBER(L20),I20<=L20),"EN RANGO","SUPERA"),"—") | N20: 38 | O20: Con 4 personas a 9.50 m² por persona (A.080 art. 6), el área mínima es de 38.00 m², y el ambiente tiene 38.00 m². Área de espera junto a las oficinas (R.V.M. 104-2019 num. 13.1.1).
A21: Zona administrativa | B21: SS.HH. mujeres | C21: 1 | F21: A.090 art. 15 | H21: =IF(AND(ISNUMBER(D21),ISNUMBER(E21)),D21*E21,IF(ISNUMBER(G21),G21,"—")) | I21: 4 | J21: =IF(AND(ISNUMBER(H21),ISNUMBER(I21)),IF(I21>=H21-0.001,"CUMPLE","NO CUMPLE"),"CONFORME") | M21: =IF(AND(ISNUMBER(K21),ISNUMBER(I21)),IF(AND(ISNUMBER(L21),I21<=L21),"EN RANGO","SUPERA"),"—") | N21: 4 | O21: A.090 art. 15, de 7 a 25 empleados: mujeres 1 lavatorio y 1 inodoro.
A22: Zona administrativa | B22: SS.HH. varones | C22: 1 | F22: A.090 art. 15 | H22: =IF(AND(ISNUMBER(D22),ISNUMBER(E22)),D22*E22,IF(ISNUMBER(G22),G22,"—")) | I22: 7.2 | J22: =IF(AND(ISNUMBER(H22),ISNUMBER(I22)),IF(I22>=H22-0.001,"CUMPLE","NO CUMPLE"),"CONFORME") | M22: =IF(AND(ISNUMBER(K22),ISNUMBER(I22)),IF(AND(ISNUMBER(L22),I22<=L22),"EN RANGO","SUPERA"),"—") | N22: 7.2 | O22: A.090 art. 15, de 7 a 25 empleados: hombres 1 lavatorio, 1 urinario y 1 inodoro.
A23: Zona administrativa | B23: SS.HH. discapacitados | C23: 1 | F23: A.090 art. 16; A.120 | H23: =IF(AND(ISNUMBER(D23),ISNUMBER(E23)),D23*E23,IF(ISNUMBER(G23),G23,"—")) | I23: 5 | J23: =IF(AND(ISNUMBER(H23),ISNUMBER(I23)),IF(I23>=H23-0.001,"CUMPLE","NO CUMPLE"),"CONFORME") | M23: =IF(AND(ISNUMBER(K23),ISNUMBER(I23)),IF(AND(ISNUMBER(L23),I23<=L23),"EN RANGO","SUPERA"),"—") | N23: 5 | O23: Servicio para personas con discapacidad adicional a los aparatos exigibles (A.090 art. 16), con las dimensiones de la A.120.
A24: Zona administrativa | B24: Cuarto de limpieza | C24: 1 | F24: R.V.M. 104-2019 num. 13.3.5 | H24: =IF(AND(ISNUMBER(D24),ISNUMBER(E24)),D24*E24,IF(ISNUMBER(G24),G24,"—")) | I24: 4.8 | J24: =IF(AND(ISNUMBER(H24),ISNUMBER(I24)),IF(I24>=H24-0.001,"CUMPLE","NO CUMPLE"),"CONFORME") | M24: =IF(AND(ISNUMBER(K24),ISNUMBER(I24)),IF(AND(ISNUMBER(L24),I24<=L24),"EN RANGO","SUPERA"),"—") | N24: 4.8 | O24: Guardado de implementos de limpieza, con lavadero y sumidero (R.V.M. 104-2019 num. 13.3.5).
A25: Zona administrativa | B25: Sala de visitas | C25: 1 | D25: 5 | E25: 9.5 | F25: A.080 art. 6 | H25: =IF(AND(ISNUMBER(D25),ISNUMBER(E25)),D25*E25,IF(ISNUMBER(G25),G25,"—")) | I25: 47.5 | J25: =IF(AND(ISNUMBER(H25),ISNUMBER(I25)),IF(I25>=H25-0.001,"CUMPLE","NO CUMPLE"),"CONFORME") | M25: =IF(AND(ISNUMBER(K25),ISNUMBER(I25)),IF(AND(ISNUMBER(L25),I25<=L25),"EN RANGO","SUPERA"),"—") | N25: 47.5 | O25: Con 5 personas a 9.50 m² por persona (A.080 art. 6), el área mínima es de 47.50 m², y el ambiente tiene 47.50 m². Junto al ingreso y separada de las áreas privadas, para la confidencialidad de las usuarias (lineamientos 2.6).
A26: Zona administrativa | B26: Psicología | C26: 1 | D26: 2 | E26: 10 | F26: A.090 art. 11 | H26: =IF(AND(ISNUMBER(D26),ISNUMBER(E26)),D26*E26,IF(ISNUMBER(G26),G26,"—")) | I26: 20 | J26: =IF(AND(ISNUMBER(H26),ISNUMBER(I26)),IF(I26>=H26-0.001,"CUMPLE","NO CUMPLE"),"CONFORME") | K26: 9 | L26: 13 | M26: =IF(AND(ISNUMBER(K26),ISNUMBER(I26)),IF(AND(ISNUMBER(L26),I26<=L26),"EN RANGO","SUPERA"),"—") | N26: 20 | O26: Con 2 personas a 10.00 m² por persona (A.090 art. 11), el área mínima es de 20.00 m², y el ambiente tiene 20.00 m². Supera la superficie sugerida por los lineamientos (9.00 a 13.00 m²). Atención individual con privacidad acústica (lineamientos 3.5).
A27: Zona administrativa | B27: Asesoría legal | C27: 1 | D27: 2 | E27: 10 | F27: A.090 art. 11 | H27: =IF(AND(ISNUMBER(D27),ISNUMBER(E27)),D27*E27,IF(ISNUMBER(G27),G27,"—")) | I27: 20 | J27: =IF(AND(ISNUMBER(H27),ISNUMBER(I27)),IF(I27>=H27-0.001,"CUMPLE","NO CUMPLE"),"CONFORME") | K27: 6 | L27: 10 | M27: =IF(AND(ISNUMBER(K27),ISNUMBER(I27)),IF(AND(ISNUMBER(L27),I27<=L27),"EN RANGO","SUPERA"),"—") | N27: 20 | O27: Con 2 personas a 10.00 m² por persona (A.090 art. 11), el área mínima es de 20.00 m², y el ambiente tiene 20.00 m². Supera la superficie sugerida por los lineamientos (6.00 a 10.00 m²).
A28: Zona administrativa | B28: Asistencia social | C28: 1 | D28: 2 | E28: 10 | F28: A.090 art. 11 | H28: =IF(AND(ISNUMBER(D28),ISNUMBER(E28)),D28*E28,IF(ISNUMBER(G28),G28,"—")) | I28: 20 | J28: =IF(AND(ISNUMBER(H28),ISNUMBER(I28)),IF(I28>=H28-0.001,"CUMPLE","NO CUMPLE"),"CONFORME") | K28: 6 | L28: 10 | M28: =IF(AND(ISNUMBER(K28),ISNUMBER(I28)),IF(AND(ISNUMBER(L28),I28<=L28),"EN RANGO","SUPERA"),"—") | N28: 20 | O28: Con 2 personas a 10.00 m² por persona (A.090 art. 11), el área mínima es de 20.00 m², y el ambiente tiene 20.00 m². Supera la superficie sugerida por los lineamientos (6.00 a 10.00 m²).
A29: Zona administrativa | B29: Tópico | C29: 1 | D29: 3 | E29: 10 | F29: A.090 art. 11 | H29: =IF(AND(ISNUMBER(D29),ISNUMBER(E29)),D29*E29,IF(ISNUMBER(G29),G29,"—")) | I29: 30 | J29: =IF(AND(ISNUMBER(H29),ISNUMBER(I29)),IF(I29>=H29-0.001,"CUMPLE","NO CUMPLE"),"CONFORME") | K29: 9 | L29: 14 | M29: =IF(AND(ISNUMBER(K29),ISNUMBER(I29)),IF(AND(ISNUMBER(L29),I29<=L29),"EN RANGO","SUPERA"),"—") | N29: 30 | O29: Con 3 personas a 10.00 m² por persona (A.090 art. 11), el área mínima es de 30.00 m², y el ambiente tiene 30.00 m². Supera la superficie sugerida por los lineamientos (9.00 a 14.00 m²). Mayor que el tópico de la R.V.M. 104-2019 (7.00 m², cuadro 22).
A30: Zona administrativa | B30: Cuarto de cámaras de vigilancia | C30: 1 | D30: 4 | E30: 3 | F30: R.V.M. 208-2019; lineamientos 2.4 | H30: =IF(AND(ISNUMBER(D30),ISNUMBER(E30)),D30*E30,IF(ISNUMBER(G30),G30,"—")) | I30: 15 | J30: =IF(AND(ISNUMBER(H30),ISNUMBER(I30)),IF(I30>=H30-0.001,"CUMPLE","NO CUMPLE"),"CONFORME") | M30: =IF(AND(ISNUMBER(K30),ISNUMBER(I30)),IF(AND(ISNUMBER(L30),I30<=L30),"EN RANGO","SUPERA"),"—") | N30: 15 | O30: Con 4 personas a 3.00 m² por persona (R.V.M. 208-2019), el área mínima es de 12.00 m², y el ambiente tiene 15.00 m². Monitoreo del circuito cerrado de accesos, perímetro y áreas comunes (lineamientos 2.4 y 2.5).
A31: Zona administrativa | B31: Data center | C31: 1 | D31: 2 | F31: EM.010; lineamientos 2.8 | H31: =IF(AND(ISNUMBER(D31),ISNUMBER(E31)),D31*E31,IF(ISNUMBER(G31),G31,"—")) | I31: 6 | J31: =IF(AND(ISNUMBER(H31),ISNUMBER(I31)),IF(I31>=H31-0.001,"CUMPLE","NO CUMPLE"),"CONFORME") | M31: =IF(AND(ISNUMBER(K31),ISNUMBER(I31)),IF(AND(ISNUMBER(L31),I31<=L31),"EN RANGO","SUPERA"),"—") | N31: 6 | O31: Equipos de comunicaciones e internet (lineamientos 2.8).
A32: Zona administrativa | B32: Archivo | C32: 1 | D32: 2 | F32: R.V.M. 104-2019 cuadro 21 | G32: 6 | H32: =IF(AND(ISNUMBER(D32),ISNUMBER(E32)),D32*E32,IF(ISNUMBER(G32),G32,"—")) | I32: 12 | J32: =IF(AND(ISNUMBER(H32),ISNUMBER(I32)),IF(I32>=H32-0.001,"CUMPLE","NO CUMPLE"),"CONFORME") | M32: =IF(AND(ISNUMBER(K32),ISNUMBER(I32)),IF(AND(ISNUMBER(L32),I32<=L32),"EN RANGO","SUPERA"),"—") | N32: 12 | O32: El área mínima es de 6.00 m² y el ambiente tiene 12.00 m². R.V.M. 104-2019: archivo de 6.00 m², contiguo a las oficinas.
A33: Zona administrativa | B33: Depósito | C33: 1 | D33: 2 | F33: R.V.M. 104-2019 num. 13.3.1 | G33: 10 | H33: =IF(AND(ISNUMBER(D33),ISNUMBER(E33)),D33*E33,IF(ISNUMBER(G33),G33,"—")) | I33: 15 | J33: =IF(AND(ISNUMBER(H33),ISNUMBER(I33)),IF(I33>=H33-0.001,"CUMPLE","NO CUMPLE"),"CONFORME") | M33: =IF(AND(ISNUMBER(K33),ISNUMBER(I33)),IF(AND(ISNUMBER(L33),I33<=L33),"EN RANGO","SUPERA"),"—") | N33: 15 | O33: El área mínima es de 10.00 m² y el ambiente tiene 15.00 m². R.V.M. 104-2019: almacén o depósito no menor de 10.00 m².
A34: Zona de ambientes especializados
A35: Zona de ambientes especializados | B35: Taller de bisutería | C35: 1 | D35: 20 | E35: 3 | F35: A.040 art. 13 | H35: =IF(AND(ISNUMBER(D35),ISNUMBER(E35)),D35*E35,IF(ISNUMBER(G35),G35,"—")) | I35: 60 | J35: =IF(AND(ISNUMBER(H35),ISNUMBER(I35)),IF(I35>=H35-0.001,"CUMPLE","NO CUMPLE"),"CONFORME") | K35: 45 | M35: =IF(AND(ISNUMBER(K35),ISNUMBER(I35)),IF(AND(ISNUMBER(L35),I35<=L35),"EN RANGO","SUPERA"),"—") | N35: 60 | O35: Con 20 personas a 3.00 m² por persona (A.040 art. 13), el área mínima es de 60.00 m², y el ambiente tiene 60.00 m². Supera la superficie sugerida por los lineamientos (45.00 m²). Taller productivo para la autonomía económica de las usuarias (lineamientos 3.7).
A36: Zona de ambientes especializados | B36: Taller de repostería | C36: 1 | D36: 20 | E36: 3 | F36: A.040 art. 13 | H36: =IF(AND(ISNUMBER(D36),ISNUMBER(E36)),D36*E36,IF(ISNUMBER(G36),G36,"—")) | I36: 60 | J36: =IF(AND(ISNUMBER(H36),ISNUMBER(I36)),IF(I36>=H36-0.001,"CUMPLE","NO CUMPLE"),"CONFORME") | K36: 45 | M36: =IF(AND(ISNUMBER(K36),ISNUMBER(I36)),IF(AND(ISNUMBER(L36),I36<=L36),"EN RANGO","SUPERA"),"—") | N36: 60 | O36: Con 20 personas a 3.00 m² por persona (A.040 art. 13), el área mínima es de 60.00 m², y el ambiente tiene 60.00 m². Supera la superficie sugerida por los lineamientos (45.00 m²). Taller productivo para la autonomía económica de las usuarias (lineamientos 3.7).
A37: Zona de ambientes especializados | B37: Taller de costura | C37: 1 | D37: 20 | E37: 3 | F37: A.040 art. 13 | H37: =IF(AND(ISNUMBER(D37),ISNUMBER(E37)),D37*E37,IF(ISNUMBER(G37),G37,"—")) | I37: 60 | J37: =IF(AND(ISNUMBER(H37),ISNUMBER(I37)),IF(I37>=H37-0.001,"CUMPLE","NO CUMPLE"),"CONFORME") | K37: 45 | M37: =IF(AND(ISNUMBER(K37),ISNUMBER(I37)),IF(AND(ISNUMBER(L37),I37<=L37),"EN RANGO","SUPERA"),"—") | N37: 60 | O37: Con 20 personas a 3.00 m² por persona (A.040 art. 13), el área mínima es de 60.00 m², y el ambiente tiene 60.00 m². Supera la superficie sugerida por los lineamientos (45.00 m²). Taller productivo para la autonomía económica de las usuarias (lineamientos 3.7).
A38: Zona de ambientes especializados | B38: Terapia grupal | C38: 1 | D38: 5 | E38: 10 | F38: A.090 art. 11 | H38: =IF(AND(ISNUMBER(D38),ISNUMBER(E38)),D38*E38,IF(ISNUMBER(G38),G38,"—")) | I38: 50 | J38: =IF(AND(ISNUMBER(H38),ISNUMBER(I38)),IF(I38>=H38-0.001,"CUMPLE","NO CUMPLE"),"CONFORME") | K38: 15 | L38: 21 | M38: =IF(AND(ISNUMBER(K38),ISNUMBER(I38)),IF(AND(ISNUMBER(L38),I38<=L38),"EN RANGO","SUPERA"),"—") | N38: 50 | O38: Con 5 personas a 10.00 m² por persona (A.090 art. 11), el área mínima es de 50.00 m², y el ambiente tiene 50.00 m². Supera la superficie sugerida por los lineamientos (15.00 a 21.00 m²). Sesiones grupales con buena iluminación y ventilación natural (lineamientos 3.5).
A39: Zona de ambientes especializados | B39: Módulo infantil | C39: 1 | D39: 10 | E39: 2 | F39: R.V.M. 104-2019 cuadro 18 | H39: =IF(AND(ISNUMBER(D39),ISNUMBER(E39)),D39*E39,IF(ISNUMBER(G39),G39,"—")) | I39: 25 | J39: =IF(AND(ISNUMBER(H39),ISNUMBER(I39)),IF(I39>=H39-0.001,"CUMPLE","NO CUMPLE"),"CONFORME") | K39: 25 | L39: 30 | M39: =IF(AND(ISNUMBER(K39),ISNUMBER(I39)),IF(AND(ISNUMBER(L39),I39<=L39),"EN RANGO","SUPERA"),"—") | N39: 25 | O39: Con 10 personas a 2.00 m² por persona (R.V.M. 104-2019 cuadro 18), el área mínima es de 20.00 m², y el ambiente tiene 25.00 m². Se encuentra dentro de la superficie sugerida por los lineamientos (25.00 a 30.00 m²). Espacio de juego y aprendizaje para niñas y niños, acompañados por personal del hogar (lineamientos 3.2, ludoteca).
A40: Zona de ambientes especializados | B40: Módulo de enseñanza | C40: 1 | D40: 15 | E40: 2.4 | F40: R.V.M. 104-2019 cuadro 16 | H40: =IF(AND(ISNUMBER(D40),ISNUMBER(E40)),D40*E40,IF(ISNUMBER(G40),G40,"—")) | I40: 39 | J40: =IF(AND(ISNUMBER(H40),ISNUMBER(I40)),IF(I40>=H40-0.001,"CUMPLE","NO CUMPLE"),"CONFORME") | K40: 16 | L40: 21 | M40: =IF(AND(ISNUMBER(K40),ISNUMBER(I40)),IF(AND(ISNUMBER(L40),I40<=L40),"EN RANGO","SUPERA"),"—") | N40: 39 | O40: Con 15 personas a 2.40 m² por persona (R.V.M. 104-2019 cuadro 16), el área mínima es de 36.00 m², y el ambiente tiene 39.00 m². Supera la superficie sugerida por los lineamientos (16.00 a 21.00 m²). Continuidad educativa de niñas y niños (lineamientos 3.5).
A41: Zona de ambientes especializados | B41: SS.HH. mujeres | C41: 1 | F41: A.040 art. 20 (cuadro 8) | H41: =IF(AND(ISNUMBER(D41),ISNUMBER(E41)),D41*E41,IF(ISNUMBER(G41),G41,"—")) | I41: 17 | J41: =IF(AND(ISNUMBER(H41),ISNUMBER(I41)),IF(I41>=H41-0.001,"CUMPLE","NO CUMPLE"),"CONFORME") | M41: =IF(AND(ISNUMBER(K41),ISNUMBER(I41)),IF(AND(ISNUMBER(L41),I41<=L41),"EN RANGO","SUPERA"),"—") | N41: 17 | O41: A.040 cuadro 8: mujeres 1 inodoro cada 30 y 1 lavatorio cada 30.
...

Sheet RESIDENCIAL
A1: ZONA RESIDENCIAL: PLAZAS Y SERVICIOS HIGIÉNICOS (A.030 Y LINEAMIENTOS)
A2: Proyecto: “CREACIÓN DEL SERVICIO DE PROTECCIÓN A MUJERES VÍCTIMAS DE VIOLENCIA EN SITUACIÓN DE RIESGO DE FEMINICIDIO O PELIGRE SU INTEGRIDAD Y/O SALUD FÍSICA Y/O MENTAL EN HOGAR DE REFUGIO TEMPORAL DISTRITO DE MORALES DE LA PROVINCIA DE SAN MARTÍN DEL DEPARTAMENTO DE SAN MARTÍN”, CUI N.° 2675514
A4: HABITACIÓN | B4: CANT. | C4: CAPACIDAD | D4: PLAZAS | E4: ÁREA UNIT. (m²) | F4: m² POR PERSONA | G4: BAÑO PRIVADO
A5: Habitaciones simples - tipo I | B5: 3 | C5: 3 | D5: =B5*C5 | E5: 12 | F5: =E5/C5 | G5: SÍ
A6: Habitaciones simples - tipo II | B6: 3 | C6: 3 | D6: =B6*C6 | E6: 12 | F6: =E6/C6 | G6: SÍ
A7: Habitaciones doble - tipo I | B7: 3 | C7: 5 | D7: =B7*C7 | E7: 20 | F7: =E7/C7 | G7: NO
A8: Habitaciones doble - tipo II | B8: 7 | C8: 5 | D8: =B8*C8 | E8: 20 | F8: =E8/C8 | G8: NO
A9: Habitaciones triple - tipo I | B9: 3 | C9: 7 | D9: =B9*C9 | E9: 28 | F9: =E9/C9 | G9: SÍ
A10: Habitaciones triple - tipo II | B10: 3 | C10: 7 | D10: =B10*C10 | E10: 28 | F10: =E10/C10 | G10: SÍ
A11: Habitación especial | B11: 1 | C11: 3 | D11: =B11*C11 | E11: 12 | F11: =E11/C11 | G11: SÍ
A12: TOTAL | B12: =SUM(B5:B11) | D12: =SUM(D5:D11)
A14: CRITERIO | B14: REQUERIDO | C14: PROGRAMA | D14: RESULTADO
A15: Habitaciones con baño privado (%) - A.030 art. 6 num. 6 | B15: 50 | C15: =SUMIF(G5:G11,"SÍ",B5:B11)/B12*100 | D15: =IF(C15>=B15,"CUMPLE","NO CUMPLE")
A16: SS.HH. comunes: 2 por cada 4 habitaciones sin baño - A.030 art. 6 num. 7 | B16: =2*ROUNDUP(SUMIF(G5:G11,"NO",B5:B11)/4,0) | C16: 7 | D16: =IF(C16>=B16,"CUMPLE","NO CUMPLE")
A17: Baño compartido por un máximo de 3 habitaciones - lineamientos 3.4 | B17: =ROUNDUP(SUMIF(G5:G11,"NO",B5:B11)/3,0) | C17: 7 | D17: =IF(C17>=B17,"CUMPLE","NO CUMPLE")
A18: Patio exterior: 2.00 m² por niño(a), 2/3 de las plazas - R.V.M. 104-2019 num. 11.3; lineamientos 1.6 | B18: =ROUND(D12*2/3,0)*2 | C18: 361.7 | D18: =IF(C18>=B18,"CUMPLE","NO CUMPLE")
A19: Comedor: 1.00 m² por residente - lineamientos 3.2 | B19: =D12*1 | C19: 240 | D19: =IF(C19>=B19,"CUMPLE","NO CUMPLE")

Sheet INDICES
A1: ÍNDICES DE OCUPACIÓN DE LAS NORMAS
A2: Proyecto: “CREACIÓN DEL SERVICIO DE PROTECCIÓN A MUJERES VÍCTIMAS DE VIOLENCIA EN SITUACIÓN DE RIESGO DE FEMINICIDIO O PELIGRE SU INTEGRIDAD Y/O SALUD FÍSICA Y/O MENTAL EN HOGAR DE REFUGIO TEMPORAL DISTRITO DE MORALES DE LA PROVINCIA DE SAN MARTÍN DEL DEPARTAMENTO DE SAN MARTÍN”, CUI N.° 2675514
A4: CLAVE | B4: NORMA | C4: TEXTO DEL ARTÍCULO | D4: ÍNDICE
A5: A080 | B5: A.080 art. 6 | C5: El número de ocupantes de una edificación de oficinas se calculará a razón de una persona cada 9.5 m2. | D5: 9.5
A6: A090of | B6: A.090 art. 11 | C6: Ambientes para oficinas administrativas: 10.0 m2 por persona. | D6: 10
A7: A090reu | B7: A.090 art. 11 | C7: Ambientes de reunión: 1.0 m2 por persona. | D7: 1
A8: A090asi | B8: A.090 art. 11 | C8: Asilos y orfanatos: 6.0 m2 por persona. | D8: 6
A9: A090est | B9: A.090 art. 11 | C9: Estacionamientos de uso general: 16.0 m2 por persona. | D9: 16
A10: A030alb | B10: A.030 art. 5 | C10: Albergue: 04.0 m² por persona. | D10: 4
A11: A030eh | B11: A.030 art. 5 | C11: Establecimientos de hospedaje: 12.0 m² por persona. | D11: 12
A12: A040tal | B12: A.040 art. 13 | C12: Talleres y laboratorios: 3.0 m² por persona. | D12: 3
A13: A040sum | B13: A.040 art. 13 | C13: Salas de usos múltiples: 1.0 m² por persona. | D13: 1
A14: A040aula | B14: A.040 art. 13 | C14: Aulas: 1.5 m² por persona. | D14: 1.5
A15: R104aula | B15: R.V.M. 104-2019 cuadro 16 | C15: Aula de Ciclo II: capacidad 25 niños(as), I.O. 2.40 m², área 60.00 m². | D15: 2.4
A16: R104psi | B16: R.V.M. 104-2019 cuadro 18 | C16: Sala de psicomotricidad: capacidad 25 niños(as), I.O. 2.00 m², área 50.00 m². | D16: 2
... A20: R104reu | B20: R.V.M. 104-2019 num. 13.1.4 | C20: Sala de reuniones: I.O. de 1.50 m² por personal docente; no menor de 12.00 m². | D20: 1.5

Sheet NORMAS
A1: MARCO NORMATIVO
A2: Proyecto: “CREACIÓN DEL SERVICIO DE PROTECCIÓN A MUJERES VÍCTIMAS DE VIOLENCIA EN SITUACIÓN DE RIESGO DE FEMINICIDIO O PELIGRE SU INTEGRIDAD Y/O SALUD FÍSICA Y/O MENTAL EN HOGAR DE REFUGIO TEMPORAL DISTRITO DE MORALES DE LA PROVINCIA DE SAN MARTÍN DEL DEPARTAMENTO DE SAN MARTÍN”, CUI N.° 2675514
A4: GRUPO | B4: NORMA | C4: DISPOSITIVOS | D4: APLICACIÓN
A5: Marco legal del servicio | B5: Ley N.° 30364, Ley para prevenir, sancionar y erradicar la violencia contra las mujeres y los integrantes del grupo familiar, y su Reglamento (D.S. N.° 009-2016-MIMP y modificatorias) | C5: Ley y reglamento | D5: Marco del servicio de Hogares de Refugio Temporal: creación, implementación, registro y acreditación.
A6: Marco legal del servicio | B6: Ley N.° 31621 y su Reglamento (D.S. N.° 005-2023-MIMP) | C6: Ley y reglamento | D6: Promueve la implementación y el funcionamiento de los Hogares de Refugio Temporal por los gobiernos regionales y locales.
A7: Marco legal del servicio | B7: R.M. N.° 150-2016-MIMP: Lineamientos para la atención y funcionamiento de los Hogares de Refugio Temporal, criterios de derivación y modelo de reglamento interno | C7: Resolución ministerial | D7: Organización del servicio y de la atención; base de la programación funcional.
A8: Reglamento Nacional de Edificaciones | B8: Norma Técnica A.030 Hospedaje (R.M. N.° 005-2019-VIVIENDA) | C8: Arts. 4, 5 y 6; Anexos 1, 3 y 4 | D8: Zona residencial: cálculo de ocupantes (albergue 4.0 m²/persona), área mínima de habitación (6.00 m²), servicios higiénicos (2.50 m² mínimo, 50 % de habitaciones con baño privado), pasajes de 1.20 m.
A9: Reglamento Nacional de Edificaciones | B9: Norma Técnica A.040 Educación (R.M. N.° 068-2020-VIVIENDA) | C9: Arts. 13 y 20 | D9: Talleres, módulo de enseñanza, SUM y sus servicios higiénicos: índices de ocupación y dotación de aparatos sanitarios.
A10: Reglamento Nacional de Edificaciones | B10: Norma A.080 Oficinas (D.S. N.° 011-2006-VIVIENDA) | C10: Arts. 3, 6, 7, 9, 15 y 23 | D10: Zona administrativa: 9.5 m² por persona, altura libre 2.40 m, servicios para empleados, ambiente para basura.
A11: Reglamento Nacional de Edificaciones | B11: Norma A.090 Servicios Comunales (D.S. N.° 011-2006-VIVIENDA) | C11: Arts. 2, 6, 10, 11, 15, 16 y 17 | D11: Uso de protección social; tabla de ocupación (oficinas 10.0, asilos y orfanatos 6.0, reunión 1.0 m²/persona), servicios higiénicos para empleados y público, estacionamientos.
A12: Reglamento Nacional de Edificaciones | B12: Normas A.010 Condiciones generales de diseño, A.120 Accesibilidad universal y A.130 Requisitos de seguridad | C12: Exigidas por A.080 (arts. 3 y 9), A.090 (arts. 6 y 10) y A.030 (art. 4) | D12: Ventilación, iluminación, accesibilidad para personas con discapacidad, evacuación y seguridad.
A13: Normas del MINEDU | B13: R.V.M. N.° 104-2019-MINEDU, Norma Técnica "Criterios de diseño para locales educativos del nivel de Educación Inicial" | C13: Arts. 10, 12 y 13; cuadros 7, 16, 18, 19, 21 y 22 | D13: Módulo infantil, módulo de enseñanza, ambientes administrativos, tópico, archivo, almacén y servicios generales.
A14: Normas del MINEDU | B14: R.V.M. N.° 208-2019-MINEDU, Norma Técnica "Criterios de diseño para locales educativos de primaria y secundaria" | C14: Programación arquitectónica | D14: Índices citados en la programación para cocina, comedor/SUM, lavandería, patios, losa y servicios generales.
A15: Referencia internacional | B15: Lineamientos arquitectónicos para el diseño y construcción de refugios especializados para mujeres, sus hijas e hijos, víctimas de violencia extrema, familiar y/o de género (ONU-Habitat / CONAVIM, México, 2016) | C15: Capítulos I a IV | D15: Buena práctica: programa funcional en ocho áreas, superficies sugeridas por ambiente, seguridad, accesos, accesibilidad, diseño bioclimático y ecotecnias.

Sheet RESUMEN
A1: RESULTADO POR ZONA
A2: Proyecto: “CREACIÓN DEL SERVICIO DE PROTECCIÓN A MUJERES VÍCTIMAS DE VIOLENCIA EN SITUACIÓN DE RIESGO DE FEMINICIDIO O PELIGRE SU INTEGRIDAD Y/O SALUD FÍSICA Y/O MENTAL EN HOGAR DE REFUGIO TEMPORAL DISTRITO DE MORALES DE LA PROVINCIA DE SAN MARTÍN DEL DEPARTAMENTO DE SAN MARTÍN”, CUI N.° 2675514
A4: ZONA | B4: AMBIENTES | C4: CUMPLE | D4: CONFORME | E4: ÁREA PROYECTO (m²)
A5: Zona de obras exteriores | B5: =COUNTIFS(MATRIZ!$A$6:$A$82,A5,MATRIZ!$B$6:$B$82,"?*") | C5: =COUNTIFS(MATRIZ!$A$6:$A$82,A5,MATRIZ!$J$6:$J$82,"CUMPLE") | D5: =COUNTIFS(MATRIZ!$A$6:$A$82,A5,MATRIZ!$J$6:$J$82,"CONFORME") | E5: =SUMIF(MATRIZ!$A$6:$A$82,A5,MATRIZ!$N$6:$N$82)
A6: Zona administrativa | B6: =COUNTIFS(MATRIZ!$A$6:$A$82,A6,MATRIZ!$B$6:$B$82,"?*") | C6: =COUNTIFS(MATRIZ!$A$6:$A$82,A6,MATRIZ!$J$6:$J$82,"CUMPLE") | D6: =COUNTIFS(MATRIZ!$A$6:$A$82,A6,MATRIZ!$J$6:$J$82,"CONFORME") | E6: =SUMIF(MATRIZ!$A$6:$A$82,A6,MATRIZ!$N$6:$N$82)
A7: Zona de ambientes especializados | B7: =COUNTIFS(MATRIZ!$A$6:$A$82,A7,MATRIZ!$B$6:$B$82,"?*") | C7: =COUNTIFS(MATRIZ!$A$6:$A$82,A7,MATRIZ!$J$6:$J$82,"CUMPLE") | D7: =COUNTIFS(MATRIZ!$A$6:$A$82,A7,MATRIZ!$J$6:$J$82,"CONFORME") | E7: =SUMIF(MATRIZ!$A$6:$A$82,A7,MATRIZ!$N$6:$N$82)
A8: Zona residencial | B8: =COUNTIFS(MATRIZ!$A$6:$A$82,A8,MATRIZ!$B$6:$B$82,"?*") | C8: =COUNTIFS(MATRIZ!$A$6:$A$82,A8,MATRIZ!$J$6:$J$82,"CUMPLE") | D8: =COUNTIFS(MATRIZ!$A$6:$A$82,A8,MATRIZ!$J$6:$J$82,"CONFORME") | E8: =SUMIF(MATRIZ!$A$6:$A$82,A8,MATRIZ!$N$6:$N$82)
A9: Zona de servicios complementarios | B9: =COUNTIFS(MATRIZ!$A$6:$A$82,A9,MATRIZ!$B$6:$B$82,"?*") | C9: =COUNTIFS(MATRIZ!$A$6:$A$82,A9,MATRIZ!$J$6:$J$82,"CUMPLE") | D9: =COUNTIFS(MATRIZ!$A$6:$A$82,A9,MATRIZ!$J$6:$J$82,"CONFORME") | E9: =SUMIF(MATRIZ!$A$6:$A$82,A9,MATRIZ!$N$6:$N$82)
A10: Zona de servicios generales | B10: =COUNTIFS(MATRIZ!$A$6:$A$82,A10,MATRIZ!$B$6:$B$82,"?*") | C10: =COUNTIFS(MATRIZ!$A$6:$A$82,A10,MATRIZ!$J$6:$J$82,"CUMPLE") | D10: =COUNTIFS(MATRIZ!$A$6:$A$82,A10,MATRIZ!$J$6:$J$82,"CONFORME") | E10: =SUMIF(MATRIZ!$A$6:$A$82,A10,MATRIZ!$N$6:$N$82)
A11: Circulación | B11: =COUNTIFS(MATRIZ!$A$6:$A$82,A11,MATRIZ!$B$6:$B$82,"?*") | C11: =COUNTIFS(MATRIZ!$A$6:$A$82,A11,MATRIZ!$J$6:$J$82,"CUMPLE") | D11: =COUNTIFS(MATRIZ!$A$6:$A$82,A11,MATRIZ!$J$6:$J$82,"CONFORME") | E11: =SUMIF(MATRIZ!$A$6:$A$82,A11,MATRIZ!$N$6:$N$82)
A12: TOTAL | B12: =SUM(B5:B11) | C12: =SUM(C5:C11) | D12: =SUM(D5:D11) | E12: =SUM(E5:E11)
