Workbook

Sheet MEMORIA
A1: MEMORIA DE CALCULO - COLECTOR PLUVIAL TRAMO HOGAR DE REFUGIO TEMPORAL MUJERES VIOLENTADAS
A2: Colector pluvial frontal - tramo Hogar de Refugio Temporal Mujeres Violentadas (CUI 2675514), Morales - San Martin. Hidroconsult, Oct. 2026
A4: 1. OBJETO | B4: Dimensionar el tramo del colector pluvial frontal que recibe el aporte del CAR Varones (CUI 2705619, dato de su memoria) y las seis cunetas del Hogar de Refugio Temporal Mujeres Violentadas (CUI 2675514), y lo entrega al registro R-01 del colector del CAR Mujeres (CUI 2717013). Longitud 73.39 m, de la caja de llegada (0+000, limite con CAR Varones) a la caja de caida en el limite con CAR Mujeres.
A5: 2. NORMATIVA | B5: RNE CE.040 Drenaje Pluvial (RM 126-2021-VIVIENDA); RNE E.020 Cargas; RNE E.060 Concreto Armado; AASHTO LRFD (rueda HL-93 en el cruce de camiones); Chow, Hidraulica de canales abiertos (paso estandar).
A6: 3. HIDROLOGIA | B6: Metodo Racional con los coeficientes y areas de las memorias HIDRO-CE040 de cada proyecto, TR = 25 anos, tc = 15 min, I = 155.66 mm/h, FS = 1.15. Q = 258.7 + 301.9 = 560.6 L/s.
A7: 4. HIDRAULICA | B7: Colector cubierto de concreto armado b = 0.80 m, S = 0.30 %, n = 0.015. El fondo inicial (259.10) queda bajo las cunetas de arquitectura (NCF 259.70 a 260.12) y el fondo final (258.89) sobre el R-01 del receptor (258.72). La entrega es por caja de caida con poza de disipacion deprimida 0.40 m, ahogada por el tirante del receptor; el control del perfil es el tirante critico en el brink y el flujo en el colector es subcritico (F <= 0.90). El aporte externo cae en una caja de llegada con colchon de agua.
A8: 5. ESTRUCTURAS | B8: Marco cerrado monolitico: losa superior e = 0.10, muros e = 0.15 (altura interior 1.40 a 1.65 m) y losa de fondo e = 0.15 con un solo marco 3/8" @0.20 en el eje de la seccion y longitudinales 3/8" @0.25 (una capa; E.060 14.3.4); cruce de motos marco 3/8" @0.15; cruce de camiones losas e = 0.25 y doble marco 1/2" @0.15 (una capa en cada cara). Tapas de registro 0.68 x 0.68 x 0.08.
A9: 6. RESULTADOS | B9: Ver cuadro resumen y la hoja CUMPLIMIENTO (requisito, norma, criterio, valor y resultado). Secciones, acero y detalles en las laminas DP-01 a DP-10 y DA-01 a DA-03.
A11: Caudal de diseno del tramo (L/s) | B11: =CAUDALES!B12
A12: Intensidad de diseno (mm/h) | B12: =DATOS!B11
A13: Ancho interior adoptado (m) | B13: =DATOS!B17
A14: Pendiente del fondo (%) | B14: =DATOS!B23*100
A15: Cota de fondo inicial / final del colector (msnm) | B15: =TEXT(DATOS!B22,"0.00")&" / "&TEXT(EMPALME!B8,"0.00")
A16: Llenado maximo y/h | B16: =PERFIL_FLUJO!B93
A17: Borde libre minimo bajo losa (m) | B17: =PERFIL_FLUJO!B94
A18: Froude maximo en el colector | B18: =PERFIL_FLUJO!B95
A19: Estaciones hidraulicas que no cumplen | B19: =PERFIL_FLUJO!B96
A20: Velocidades y autolimpieza (0.90 a 3.0 m/s; tau >= 0.15 kg/m2) | B20: =PERFIL_FLUJO!B200
A21: Cunetas con caida libre al colector (de 6) | B21: =COUNTIF(CUNETAS!L5:L10,"CAIDA LIBRE")
A22: Resalto en la poza de la caja de caida | B22: =EMPALME!B19
A23: Elementos estructurales que no cumplen | B23: =COUNTIF(ESTRUCTURAL!E:E,"NO CUMPLE")
A24: Requisitos normativos que no cumplen o por verificar (hoja CUMPLIMIENTO) | B24: =COUNTIF(CUMPLIMIENTO!E:E,"NO CUMPLE*")+COUNTIF(CUMPLIMIENTO!E:E,"VERIFICAR*")
A26: NOTAS
B27: La llegada del CAR Varones (CUI 2705619) queda definida por su expediente: colector b = 0.60 con fondo 259.884 en la cara este de la CL y cuneta Eje 01 directa a la CL; la CL lleva su tapa en +261.15 (piso de Varones) y ventanas este 0.60 x 1.17 y norte 0.40 x 0.66.
B28: La ubicacion UTM es referencial: el plano de arquitectura se georreferencio haciendo coincidir el R-01 del CAR Mujeres con la esquina sur-oeste del frente y el rumbo del lindero (azimut 49.54). Verificar en campo.
B29: Las cunetas de arquitectura se toman como dato (perfiles 01 a 12 del plano PLANTA GENERAL REFUGIO, version 03-10-2026).

Sheet DATOS
A1: 1. DATOS DE DISENO
A2: Colector pluvial frontal - tramo Hogar de Refugio Temporal Mujeres Violentadas (CUI 2675514), Morales - San Martin. Hidroconsult, Oct. 2026
A4: PARAMETRO | B4: VALOR | C4: UND | D4: FUENTE / CRITERIO | E4: SIMBOLO
A5: HIDROLOGIA
A6: Periodo de retorno | B6: 25 | C6: anos | D6: Analisis estadistico de precipitaciones (memoria HIDRO-CE040 del proyecto) | E6: TR
A7: Precipitacion de diseno D=10 min | B7: 35.163 | C7: mm | D7: Dick-Peschke, P24 = 121.81 mm | E7: P10
A8: Precipitacion de diseno D=20 min | B8: 41.816 | C8: mm | D8: Dick-Peschke | E8: P20
A9: Tiempo de concentracion en el colector | B9: 15 | C9: min | D9: 10 min de entrada + recorrido en cunetas y colector | E9: tc
A10: Exponente de la curva P-D | B10: =LN(B8/B7)/LN(2) | C10: - | D10: b = ln(P20/P10)/ln 2 | E10: bx
A11: Intensidad de diseno I | B11: =B7*(B9/10)^B10/(B9/60) | C11: mm/h | D11: I = P10 (tc/10)^b / (tc/60) | E11: I
A12: Factor de seguridad FS | B12: 1.15 | C12: - | D12: Memorias de calculo HIDRO-CE040 | E12: FS
A13: Intensidad para D = 10 min (cunetas y montantes del estudio hidrologico) | B13: =B7*60/10 | C13: mm/h | D13: I10 = P10 x 60 / 10 = 210.98 mm/h: es la misma lluvia de 35.163 mm en 10 min, expresada como intensidad (igual al estudio hidrologico) | E13: I10
A14: Intensidad para D = 20 min | B14: =B8*60/20 | C14: mm/h | D14: I20 = P20 x 60 / 20 = 125.45 mm/h (analisis estadistico, hoja C. P diseno) | E14: I20
A15: Nota: el colector tiene tc = 15 min (mayor que los 10 min de cada cuneta), por eso su intensidad es 155.66 mm/h, interpolada en la curva P-D entre 10 y 20 min; es el mismo criterio del colector del CAR Mujeres (3 proyectos).
A16: GEOMETRIA DEL COLECTOR (tramo Hogar de Refugio)
A17: Ancho interior b | B17: 0.8 | C17: m | D17: Adoptado: llenado <= 85 % y regimen subcritico (hoja PERFIL_FLUJO) | E17: b
A18: Espesor de muros | B18: 0.15 | C18: m | D18: Muros de 1.40 a 1.65 m de altura interior (hoja ESTRUCTURAL) | E18: em
A19: Espesor de losa de fondo | B19: 0.15 | C19: m | E19: ef
A20: Espesor de losa superior (tramo normal y porton de motos) | B20: 0.1 | C20: m | D20: Vaciada monoliticamente con los muros | E20: et
A21: Espesor de losa superior en cruce de camiones | B21: 0.25 | C21: m | D21: Ingreso vehicular OE-01 (cisterna al PTAR) | E21: ec
A22: Cota de fondo inicial (0+000, caja de llegada) | B22: 259.1 | C22: msnm | D22: Fijada por las cunetas de arquitectura: la mas baja llega con NCF 259.70 (Eje 02) | E22: CF0
A23: Pendiente S | B23: 0.003 | C23: m/m | D23: Adoptada 0.30 %: regimen subcritico (F = 0.60) y fondo sobre el R-01 del receptor | E23: S
A24: Progresiva del quiebre 1 (45 grados) | B24: 58.81 | C24: m | D24: Salida del frente hacia el lindero | E24: pq1
A25: Progresiva del quiebre 2 (45 grados) | B25: 66.89 | C25: m | E25: pq2
A26: Progresiva del brink de la caida (fin del colector b=0.80) | B26: 69.89 | C26: m | D26: Inicio de la poza de disipacion | E26: pb
A27: Progresiva de entrega (0+000 del tramo CAR Mujeres) | B27: 73.39 | C27: m | D27: Cara aguas arriba del registro R-01 del receptor | E27: pf
A28: Longitud total del tramo | B28: =B27 | C28: m | E28: L
A29: NPT del frente (cara superior de la losa) | B29: 260.6 | C29: msnm | D29: Arquitectura: NT 260.50 + NPT 0.10 (estacionamientos e ingresos) | E29: NPT
A30: Cruce de camiones: inicio | B30: 26.32 | C30: m | D30: Ingreso vehicular OE-01 (4.415 m) + 0.30 m a cada lado | E30: pc1
A31: Cruce de camiones: fin | B31: 31.33 | C31: m | E31: pc2
A32: Cruce de motos: inicio | B32: 39.04 | C32: m | D32: Porton de motos (1.77 m), tramo de 2.00 m | E32: pm1
A33: Cruce de motos: fin | B33: 41.04 | C33: m | E33: pm2
A34: Coeficiente de Manning n | B34: 0.015 | C34: - | D34: Concreto vaciado in situ (Chow) | E34: n
A35: CRITERIOS DE VERIFICACION HIDRAULICA
A36: Llenado maximo admisible y/h (conducto cubierto) | B36: 0.85 | C36: - | D36: Criterio de conducto cerrado a superficie libre | E36: llen
A37: Borde libre minimo bajo losa | B37: 0.05 | C37: m | D37: Complementario al criterio de llenado | E37: BLmin
A38: RECEPTOR: COLECTOR DEL CAR MUJERES (CUI 2717013)
A39: Cota de fondo del receptor en su 0+000 (R-01) | B39: 258.72 | C39: msnm | D39: Plano DP-01 del tramo CAR Mujeres | E39: CFr
A40: Nivel de agua del receptor en su 0+000 | B40: 259.062 | C40: msnm | D40: Memoria del tramo CAR Mujeres (Q = 626 L/s en 0+000) | E40: NAr
A41: Ancho interior del receptor | B41: 1.5 | C41: m | E41: br
...

Sheet CAUDALES
A1: 2. CAUDALES DE DISENO - METODO RACIONAL Q = C I A FS
A2: Colector pluvial frontal - tramo Hogar de Refugio Temporal Mujeres Violentadas (CUI 2675514), Morales - San Martin. Hidroconsult, Oct. 2026
A4: PROYECTO | B4: AREA (m2) | C4: C x A (m2) | D4: C PONDERADO | E4: I (mm/h) | F4: Q (L/s) | G4: INGRESA AL COLECTOR EN | H4: FUENTE
A5: CAR Varones (CUI 2705619) - aporte externo | B5: 6752.03 | C5: 5203.3213 | D5: =C5/B5 | E5: =DATOS!$B$11 | F5: =C5*E5/3600000*DATOS!$B$12*1000 | G5: Caja de llegada CL (0+000) | H5: Memoria HIDRO-CE040 del proyecto, dato no validado
A6: Hogar de Refugio Temporal M. Violentadas (CUI 2675514) | B6: 7520.41 | C6: 6072.3596 | D6: =C6/B6 | E6: =DATOS!$B$11 | F6: =C6*E6/3600000*DATOS!$B$12*1000 | G6: Cunetas Ejes 01, 02, 06, 07, 11 y 12 | H6: Memoria HIDRO-CE040, 12 fichas
A7: TOTAL ENTREGADO AL CAR MUJERES | B7: =SUM(B5:B6) | C7: =SUM(C5:C6) | D7: =C7/B7 | F7: =SUM(F5:F6)
A9: Caudal de diseno adoptado (valores de las memorias de cada proyecto)
A10: CAR Varones | B10: 258.7 | C10: L/s
A11: Hogar de Refugio | B11: 301.9 | C11: L/s
A12: Q de diseno del tramo | B12: =B10+B11 | C12: L/s
A13: Q de diseno del tramo | B13: =B12/1000 | C13: m3/s
A15: Caudal que circula por el tramo (de aguas arriba hacia aguas abajo)
A16: PUNTO | B16: PROGRESIVA | C16: APORTE (L/s) | D16: Q ACUMULADO (L/s)
A17: Caja de llegada CL (CAR Varones) | B17: 0 | C17: =B10 | D17: =SUM($C$17:C17)
A18: Cuneta Eje 01 (perimetral este) - perfil 01 | B18: 1.07 | C18: =B11/6 | D18: =SUM($C$17:C18)
A19: Cuneta Eje 02 (estacionamiento) - perfil 02 | B19: 11.27 | C19: =B11/6 | D19: =SUM($C$17:C19)
A20: Cuneta Eje 06 (ingreso vehicular) - perfil 06 | B20: 32.5 | C20: =B11/6 | D20: =SUM($C$17:C20)
A21: Cuneta Eje 07 - perfil 07 | B21: 42.68 | C21: =B11/6 | D21: =SUM($C$17:C21)
A22: Cuneta Eje 11 - perfil 11 | B22: 60.89 | C22: =B11/6 | D22: =SUM($C$17:C22)
A23: Cuneta Eje 12 (perimetral oeste) - perfil 12 | B23: 69.56 | C23: =B11/6 | D23: =SUM($C$17:C23)
A25: Suma de picos sin desfase de tiempos y con FS = 1.15: hipotesis conservadora. El reparto del aporte del Refugio entre sus 6 cunetas es nominal; el perfil se verifica con el caudal total en todo el tramo.

Sheet CUNETAS
A1: 3. CUNETAS DE ARQUITECTURA QUE LLEGAN AL COLECTOR
A2: Colector pluvial frontal - tramo Hogar de Refugio Temporal Mujeres Violentadas (CUI 2675514), Morales - San Martin. Hidroconsult, Oct. 2026
A4: CUNETA (perfil de arquitectura) | B4: PERFIL | C4: PROGRESIVA (m) | D4: LONGITUD (m) | E4: NCT (msnm) | F4: NCF al cerco (msnm) | G4: H al cerco (m) | H4: PROLONG. (m) | I4: NCF en el muro (msnm) | J4: NA del colector (msnm) | K4: CAIDA LIBRE (m) | L4: VERIFICACION
A5: Eje 01 (perimetral este) | B5: 01 | C5: 1.07 | D5: 37.14 | E5: 260.6 | F5: 260.12 | G5: =E5-F5 | H5: 0.03 | I5: =F5-0.005*H5 | J5: =IFERROR(INDEX(PERFIL_FLUJO!$G$6:$G$200,MATCH(C5,PERFIL_FLUJO!$A$6:$A$200,0)),"") | K5: =I5-J5 | L5: =IF(K5>0,"CAIDA LIBRE","AHOGADA")
A6: Eje 02 (estacionamiento) | B6: 02 | C6: 11.27 | D6: 130.85 | E6: 260.6 | F6: 259.7 | G6: =E6-F6 | H6: 0.03 | I6: =F6-0.005*H6 | J6: =IFERROR(INDEX(PERFIL_FLUJO!$G$6:$G$200,MATCH(C6,PERFIL_FLUJO!$A$6:$A$200,0)),"") | K6: =I6-J6 | L6: =IF(K6>0,"CAIDA LIBRE","AHOGADA")
A7: Eje 06 (ingreso vehicular) | B7: 06 | C7: 32.5 | D7: 120.36 | E7: 260.6 | F7: 259.75 | G7: =E7-F7 | H7: 0.03 | I7: =F7-0.005*H7 | J7: =IFERROR(INDEX(PERFIL_FLUJO!$G$6:$G$200,MATCH(C7,PERFIL_FLUJO!$A$6:$A$200,0)),"") | K7: =I7-J7 | L7: =IF(K7>0,"CAIDA LIBRE","AHOGADA")
A8: Eje 07 | B8: 07 | C8: 42.68 | D8: 125.7 | E8: 260.6 | F8: 259.72 | G8: =E8-F8 | H8: 0.03 | I8: =F8-0.005*H8 | J8: =IFERROR(INDEX(PERFIL_FLUJO!$G$6:$G$200,MATCH(C8,PERFIL_FLUJO!$A$6:$A$200,0)),"") | K8: =I8-J8 | L8: =IF(K8>0,"CAIDA LIBRE","AHOGADA")
A9: Eje 11 | B9: 11 | C9: 60.89 | D9: 71.46 | E9: 260.6 | F9: 260 | G9: =E9-F9 | H9: 1.88 | I9: =F9-0.005*H9 | J9: =IFERROR(INDEX(PERFIL_FLUJO!$G$6:$G$200,MATCH(C9,PERFIL_FLUJO!$A$6:$A$200,0)),"") | K9: =I9-J9 | L9: =IF(K9>0,"CAIDA LIBRE","AHOGADA")
A10: Eje 12 (perimetral oeste) | B10: 12 | C10: 69.56 | D10: 109.12 | E10: 260.6 | F10: 259.8 | G10: =E10-F10 | H10: 5.39 | I10: =F10-0.005*H10 | J10: =IFERROR(INDEX(PERFIL_FLUJO!$G$6:$G$200,MATCH(C10,PERFIL_FLUJO!$A$6:$A$200,0)),"") | K10: =I10-J10 | L10: =IF(K10>0,"CAIDA LIBRE","AHOGADA")
A12: Seccion de las cunetas: 0.40 x H, muros 0.10, pendiente 0.5 % (plano de arquitectura, perfiles 01 a 12). Las prolongaciones fuera del cerco mantienen la misma pendiente. El empalme es por ventana 0.40 x H en el muro lado predio, con caida al fondo del colector y registro encima (lamina DP-06).

Sheet EMPALME
A1: 4. CAJA DE LLEGADA (0+000) Y CAJA DE CAIDA EN LA ENTREGA AL CAR MUJERES
A2: Colector pluvial frontal - tramo Hogar de Refugio Temporal Mujeres Violentadas (CUI 2675514), Morales - San Martin. Hidroconsult, Oct. 2026
A4: PARAMETRO | B4: VALOR | C4: UND | D4: FORMULA / CRITERIO
A5: A. CAJA DE CAIDA CC - ENTREGA AL REGISTRO R-01 DEL CAR MUJERES
A6: Caudal Q | B6: =CAUDALES!B13 | C6: m3/s
A7: Ancho del colector en el brink b | B7: =DATOS!B17 | C7: m
A8: Cota de fondo en el brink | B8: =DATOS!B22-DATOS!B23*DATOS!B26 | C8: msnm | D8: CF0 - S x pb
A9: Tirante critico en el brink yc | B9: =(B6^2/(9.81*B7^2))^(1/3) | C9: m | D9: yc = (Q2/(g b2))^(1/3): control de la caida libre
A10: Nivel de agua en el brink | B10: =B8+B9 | C10: msnm | D10: nivel de control del perfil de flujo (hoja PERFIL_FLUJO)
A11: Piso de la poza | B11: =DATOS!B39-DATOS!B48 | C11: msnm | D11: fondo del receptor - profundidad de poza
A12: Caida total (brink a piso de poza) | B12: =B8-B11 | C12: m
A13: Energia al pie respecto al piso E1 | B13: =B12+1.5*B9 | C13: m | D13: E1 = caida + 1.5 yc (sin perdidas, conservador)
A14: Tirante al pie y1 | B14: 0.1613 | C14: m | D14: y1 resuelto en Python (y1 + (Q/(b y1))^2/2g = E1); verificar: B14 + B15^2/19.62 = B13
A15: Velocidad al pie V1 | B15: =B6/(B7*B14) | C15: m/s | D15: V1 = Q/(b y1)
A16: Froude al pie F1 | B16: =B15/SQRT(9.81*B14) | C16: -
A17: Tirante conjugado y2 | B17: =B14/2*(SQRT(1+8*B16^2)-1) | C17: m | D17: resalto hidraulico en el ancho b (conservador: no considera la expansion a 1.50 m)
A18: Tirante disponible en la poza | B18: =DATOS!B40-B11 | C18: m | D18: NA del receptor - piso de la poza
A19: Verificacion del resalto | B19: =IF(B18>=B17,"RESALTO AHOGADO - CUMPLE","REVISAR PROFUNDIDAD DE POZA") | D19: el receptor ahoga el resalto dentro de la poza
A20: Longitud de resalto 6 y2 | B20: =6*B17 | C20: m | D20: referencia (resalto libre)
A21: Longitud de poza adoptada | B21: =DATOS!B49 | C21: m | D21: con umbral de salida de 0.40 m hasta el fondo del receptor; resalto ahogado
A22: Verificacion de longitud | B22: =IF(B21>=0.8*B20,"CUMPLE (resalto ahogado)","AMPLIAR POZA") | D22: poza >= 0.8 x 6 y2 para resalto ahogado (USBR)
A23: Nivel de agua en el receptor | B23: =DATOS!B40 | C23: msnm | D23: regimen subcritico aguas abajo del umbral (F = 0.67 en el receptor)
A25: B. CAJA DE LLEGADA CL (0+000) - CAIDA DEL APORTE DE CAR VARONES
A26: Cota de fondo de llegada del aporte externo | B26: =DATOS!B43 | C26: msnm | D26: expediente del CAR Varones (CUI 2705619): colector b = 0.60, fondo 259.884 en la cara este de la CL
A27: Piso de la poza de la caja | B27: =DATOS!B22-DATOS!B47 | C27: msnm | D27: CF0 - profundidad de poza
A28: Caida del aporte externo | B28: =B26-B27 | C28: m
A29: Nivel de agua en la caja (= inicio del colector) | B29: =PERFIL_FLUJO!G200 | C29: msnm | D29: nivel de agua en 0+000 (hoja PERFIL_FLUJO, ultima fila)
A30: Colchon de agua en la poza | B30: =B29-B27 | C30: m | D30: amortigua el chorro de 259 L/s
A31: Verificacion | B31: =IF(B30>=0.5,"CUMPLE (colchon >= 0.50 m)","REVISAR")
A32: Dimensiones interiores de la caja | B32: 1.50 x 1.00 | C32: m | D32: largo x ancho; profundidad hasta el piso de poza
A33: Verificacion de y1: y1 + V1^2/2g | B33: =B14+B15^2/(2*9.81) | C33: m | D33: debe ser igual a E1 (B13)

Sheet PERFIL_FLUJO
A1: 5. PERFIL DE FLUJO GRADUALMENTE VARIADO - METODO DEL PASO ESTANDAR (de aguas abajo hacia aguas arriba)
A2: Colector pluvial frontal - tramo Hogar de Refugio Temporal Mujeres Violentadas (CUI 2675514), Morales - San Martin. Hidroconsult, Oct. 2026
A3: Ecuacion de energia entre estaciones: y1 + V1^2/2g + z1 = y2 + V2^2/2g + z2 + dx (Sf1 + Sf2)/2 ; Sf = (n V / R^(2/3))^2 ; control: tirante critico en el brink de la caida (0+069.89)
P4: Biseccion del tirante y (lo, hi) en 30 iteraciones: f(y) = y + V^2/2g + z - E2 - dx (Sf + Sf2)/2
A5: PROGRESIVA (m) | B5: COTA FONDO | C5: Q (m3/s) | D5: b (m) | E5: yc (m) | F5: TIRANTE y (m) | G5: NIVEL DE AGUA | H5: VELOCIDAD (m/s) | I5: FROUDE | J5: COTA BAJO LOSA | K5: ALTURA INTERIOR h | L5: LLENADO y/h | M5: BORDE LIBRE (m) | N5: VERIFICACION | O5: ZONA
A6: 69.89 | B6: =DATOS!$B$22-DATOS!$B$23*A6 | C6: =CAUDALES!$B$13 | D6: =DATOS!$B$17 | E6: =(C6^2/(9.81*D6^2))^(1/3) | F6: =E6 | G6: =B6+F6 | H6: =C6/(D6*F6) | I6: =H6/SQRT(9.81*F6) | J6: =DATOS!$B$29-IF(AND(A6>=DATOS!$B$30,A6<DATOS!$B$31),DATOS!$B$21,DATOS!$B$20) | K6: =J6-B6 | L6: =F6/K6 | M6: =J6-G6 | N6: =IF(AND(L6<=DATOS!$B$36,M6>=DATOS!$B$37,I6<=1),"CUMPLE","NO CUMPLE") | O6: =IF(AND(A6>=DATOS!$B$30,A6<DATOS!$B$31),"cruce de camiones",IF(AND(A6>=DATOS!$B$32,A6<DATOS!$B$33),"cruce de motos","tramo normal"))
A7: 69.56 | B7: =DATOS!$B$22-DATOS!$B$23*A7 | C7: =CAUDALES!$B$13 | D7: =DATOS!$B$17 | E7: =(C7^2/(9.81*D7^2))^(1/3) | F7: =(BV7+BW7)/2 | G7: =B7+F7 | H7: =C7/(D7*F7) | I7: =H7/SQRT(9.81*F7) | J7: =DATOS!$B$29-IF(AND(A7>=DATOS!$B$30,A7<DATOS!$B$31),DATOS!$B$21,DATOS!$B$20) | K7: =J7-B7 | L7: =F7/K7 | M7: =J7-G7 | N7: =IF(AND(L7<=DATOS!$B$36,M7>=DATOS!$B$37,I7<=1),"CUMPLE","NO CUMPLE") | O7: =IF(AND(A7>=DATOS!$B$30,A7<DATOS!$B$31),"cruce de camiones",IF(AND(A7>=DATOS!$B$32,A7<DATOS!$B$33),"cruce de motos","tramo normal")) | P7: =E7*1.001 | Q7: 3 | R7: =IF((((P7+Q7)/2)+(C7/(D7*((P7+Q7)/2)))^2/(2*9.81)+B7-(G6+H6^2/(2*9.81))-(A6-A7)*(((DATOS!$B$34*(C7/(D7*((P7+Q7)/2)))/((D7*((P7+Q7)/2))/(D7+2*((P7+Q7)/2)))^(2/3))^2+((DATOS!$B$34*H6/((D6*F6)/(D6+2*F6))^(2/3))^2))/2))>0,P7,((P7+Q7)/2)) | S7: =IF((((P7+Q7)/2)+(C7/(D7*((P7+Q7)/2)))^2/(2*9.81)+B7-(G6+H6^2/(2*9.81))-(A6-A7)*(((DATOS!$B$34*(C7/(D7*((P7+Q7)/2)))/((D7*((P7+Q7)/2))/(D7+2*((P7+Q7)/2)))^(2/3))^2+((DATOS!$B$34*H6/((D6*F6)/(D6+2*F6))^(2/3))^2))/2))>0,((P7+Q7)/2),Q7) | T7: =IF((((R7+S7)/2)+(C7/(D7*((R7+S7)/2)))^2/(2*9.81)+B7-(G6+H6^2/(2*9.81))-(A6-A7)*(((DATOS!$B$34*(C7/(D7*((R7+S7)/2)))/((D7*((R7+S7)/2))/(D7+2*((R7+S7)/2)))^(2/3))^2+((DATOS!$B$34*H6/((D6*F6)/(D6+2*F6))^(2/3))^2))/2))>0,R7,((R7+S7)/2)) | U7: =IF((((R7+S7)/2)+(C7/(D7*((R7+S7)/2)))^2/(2*9.81)+B7-(G6+H6^2/(2*9.81))-(A6-A7)*(((DATOS!$B$34*(C7/(D7*((R7+S7)/2)))/((D7*((R7+S7)/2))/(D7+2*((R7+S7)/2)))^(2/3))^2+((DATOS!$B$34*H6/((D6*F6)/(D6+2*F6))^(2/3))^2))/2))>0,((R7+S7)/2),S7) | V7: =IF((((T7+U7)/2)+(C7/(D7*((T7+U7)/2)))^2/(2*9.81)+B7-(G6+H6^2/(2*9.81))-(A6-A7)*(((DATOS!$B$34*(C7/(D7*((T7+U7)/2)))/((D7*((T7+U7)/2))/(D7+2*((T7+U7)/2)))^(2/3))^2+((DATOS!$B$34*H6/((D6*F6)/(D6+2*F6))^(2/3))^2))/2))>0,T7,((T7+U7)/2)) | W7: =IF((((T7+U7)/2)+(C7/(D7*((T7+U7)/2)))^2/(2*9.81)+B7-(G6+H6^2/(2*9.81))-(A6-A7)*(((DATOS!$B$34*(C7/(D7*((T7+U7)/2)))/((D7*((T7+U7)/2))/(D7+2*((T7+U7)/2)))^(2/3))^2+((DATOS!$B$34*H6/((D6*F6)/(D6+2*F6))^(2/3))^2))/2))>0,((T7+U7)/2),U7) | X7: =IF((((V7+W7)/2)+(C7/(D7*((V7+W7)/2)))^2/(2*9.81)+B7-(G6+H6^2/(2*9.81))-(A6-A7)*(((DATOS!$B$34*(C7/(D7*((V7+W7)/2)))/((D7*((V7+W7)/2))/(D7+2*((V7+W7)/2)))^(2/3))^2+((DATOS!$B$34*H6/((D6*F6)/(D6+2*F6))^(2/3))^2))/2))>0,V7,((V7+W7)/2)) | Y7: =IF((((V7+W7)/2)+(C7/(D7*((V7+W7)/2)))^2/(2*9.81)+B7-(G6+H6^2/(2*9.81))-(A6-A7)*(((DATOS!$B$34*(C7/(D7*((V7+W7)/2)))/((D7*((V7+W7)/2))/(D7+2*((V7+W7)/2)))^(2/3))^2+((DATOS!$B$34*H6/((D6*F6)/(D6+2*F6))^(2/3))^2))/2))>0,((V7+W7)/2),W7) | Z7: =IF((((X7+Y7)/2)+(C7/(D7*((X7+Y7)/2)))^2/(2*9.81)+B7-(G6+H6^2/(2*9.81))-(A6-A7)*(((DATOS!$B$34*(C7/(D7*((X7+Y7)/2)))/((D7*((X7+Y7)/2))/(D7+2*((X7+Y7)/2)))^(2/3))^2+((DATOS!$B$34*H6/((D6*F6)/(D6+2*F6))^(2/3))^2))/2))>0,X7,((X7+Y7)/2)) | AA7: =IF((((X7+Y7)/2)+(C7/(D7*((X7+Y7)/2)))^2/(2*9.81)+B7-(G6+H6^2/(2*9.81))-(A6-A7)*(((DATOS!$B$34*(C7/(D7*((X7+Y7)/2)))/((D7*((X7+Y7)/2))/(D7+2*((X7+Y7)/2)))^(2/3))^2+((DATOS!$B$34*H6/((D6*F6)/(D6+2*F6))^(2/3))^2))/2))>0,((X7+Y7)/2),Y7) | AB7: =IF((((Z7+AA7)/2)+(C7/(D7*((Z7+AA7)/2)))^2/(2*9.81)+B7-(G6+H6^2/(2*9.81))-(A6-A7)*(((DATOS!$B$34*(C7/(D7*((Z7+AA7)/2)))/((D7*((Z7+AA7)/2))/(D7+2*((Z7+AA7)/2)))^(2/3))^2+((DATOS!$B$34*H6/((D6*F6)/(D6+2*F6))^(2/3))^2))/2))>0,Z7,((Z7+AA7)/2)) | AC7: =IF((((Z7+AA7)/2)+(C7/(D7*((Z7+AA7)/2)))^2/(2*9.81)+B7-(G6+H6^2/(2*9.81))-(A6-A7)*(((DATOS!$B$34*(C7/(D7*((Z7+AA7)/2)))/((D7*((Z7+AA7)/2))/(D7+2*((Z7+AA7)/2)))^(2/3))^2+((DATOS!$B$34*H6/((D6*F6)/(D6+2*F6))^(2/3))^2))/2))>0,((Z7+AA7)/2),AA7) | AD7: =IF((((AB7+AC7)/2)+(C7/(D7*((AB7+AC7)/2)))^2/(2*9.81)+B7-(G6+H6^2/(2*9.81))-(A6-A7)*(((DATOS!$B$34*(C7/(D7*((AB7+AC7)/2)))/((D7*((AB7+AC7)/2))/(D7+2*((AB7+AC7)/2)))^(2/3))^2+((DATOS!$B$34*H6/((D6*F6)/(D6+2*F6))^(2/3))^2))/2))>0,AB7,((AB7+AC7)/2)) | AE7: =IF((((AB7+AC7)/2)+(C7/(D7*((AB7+AC7)/2)))^2/(2*9.81)+B7-(G6+H6^2/(2*9.81))-(A6-A7)*(((DATOS!$B$34*(C7/(D7*((AB7+AC7)/2)))/((D7*((AB7+AC7)/2))/(D7+2*((AB7+AC7)/2)))^(2/3))^2+((DATOS!$B$34*H6/((D6*F6)/(D6+2*F6))^(2/3))^2))/2))>0,((AB7+AC7)/2),AC7) | AF7: =IF((((AD7+AE7)/2)+(C7/(D7*((AD7+AE7)/2)))^2/(2*9.81)+B7-(G6+H6^2/(2*9.81))-(A6-A7)*(((DATOS!$B$34*(C7/(D7*((AD7+AE7)/2)))/((D7*((AD7+AE7)/2))/(D7+2*((AD7+AE7)/2)))^(2/3))^2+((DATOS!$B$34*H6/((D6*F6)/(D6+2*F6))^(2/3))^2))/2))>0,AD7,((AD7+AE7)/2)) | AG7: =IF((((AD7+AE7)/2)+(C7/(D7*((AD7+AE7)/2)))^2/(2*9.81)+B7-(G6+H6^2/(2*9.81))-(A6-A7)*(((DATOS!$B$34*(C7/(D7*((AD7+AE7)/2)))/((D7*((AD7+AE7)/2))/(D7+2*((AD7+AE7)/2)))^(2/3))^2+((DATOS!$B$34*H6/((D6*F6)/(D6+2*F6))^(2/3))^2))/2))>0,((AD7+AE7)/2),AE7) | AH7: =IF((((AF7+AG7)/2)+(C7/(D7*((AF7+AG7)/2)))^2/(2*9.81)+B7-(G6+H6^2/(2*9.81))-(A6-A7)*(((DATOS!$B$34*(C7/(D7*((AF7+AG7)/2)))/((D7*((AF7+AG7)/2))/(D7+2*((AF7+AG7)/2)))^(2/3))^2+((DATOS!$B$34*H6/((D6*F6)/(D6+2*F6))^(2/3))^2))/2))>0,AF7,((AF7+AG7)/2)) | AI7: =IF((((AF7+AG7)/2)+(C7/(D7*((AF7+AG7)/2)))^2/(2*9.81)+B7-(G6+H6^2/(2*9.81))-(A6-A7)*(((DATOS!$B$34*(C7/(D7*((AF7+AG7)/2)))/((D7*((AF7+AG7)/2))/(D7+2*((AF7+AG7)/2)))^(2/3))^2+((DATOS!$B$34*H6/((D6*F6)/(D6+2*F6))^(2/3))^2))/2))>0,((AF7+AG7)/2),AG7) | AJ7: =IF((((AH7+AI7)/2)+(C7/(D7*((AH7+AI7)/2)))^2/(2*9.81)+B7-(G6+H6^2/(2*9.81))-(A6-A7)*(((DATOS!$B$34*(C7/(D7*((AH7+AI7)/2)))/((D7*((AH7+AI7)/2))/(D7+2*((AH7+AI7)/2)))^(2/3))^2+((DATOS!$B$34*H6/((D6*F6)/(D6+2*F6))^(2/3))^2))/2))>0,AH7,((AH7+AI7)/2)) | AK7: =IF((((AH7+AI7)/2)+(C7/(D7*((AH7+AI7)/2)))^2/(2*9.81)+B7-(G6+H6^2/(2*9.81))-(A6-A7)*(((DATOS!$B$34*(C7/(D7*((AH7+AI7)/2)))/((D7*((AH7+AI7)/2))/(D7+2*((AH7+AI7)/2)))^(2/3))^2+((DATOS!$B$34*H6/((D6*F6)/(D6+2*F6))^(2/3))^2))/2))>0,((AH7+AI7)/2),AI7) | AL7: =IF((((AJ7+AK7)/2)+(C7/(D7*((AJ7+AK7)/2)))^2/(2*9.81)+B7-(G6+H6^2/(2*9.81))-(A6-A7)*(((DATOS!$B$34*(C7/(D7*((AJ7+AK7)/2)))/((D7*((AJ7+AK7)/2))/(D7+2*((AJ7+AK7)/2)))^(2/3))^2+((DATOS!$B$34*H6/((D6*F6)/(D6+2*F6))^(2/3))^2))/2))>0,AJ7,((AJ7+AK7)/2)) | AM7: =IF((((AJ7+AK7)/2)+(C7/(D7*((AJ7+AK7)/2)))^2/(2*9.81)+B7-(G6+H6^2/(2*9.81))-(A6-A7)*(((DATOS!$B$34*(C7/(D7*((AJ7+AK7)/2)))/((D7*((AJ7+AK7)/2))/(D7+2*((AJ7+AK7)/2)))^(2/3))^2+((DATOS!$B$34*H6/((D6*F6)/(D6+2*F6))^(2/3))^2))/2))>0,((AJ7+AK7)/2),AK7) | AN7: =IF((((AL7+AM7)/2)+(C7/(D7*((AL7+AM7)/2)))^2/(2*9.81)+B7-(G6+H6^2/(2*9.81))-(A6-A7)*(((DATOS!$B$34*(C7/(D7*((AL7+AM7)/2)))/((D7*((AL7+AM7)/2))/(D7+2*((AL7+AM7)/2)))^(2/3))^2+((DATOS!$B$34*H6/((D6*F6)/(D6+2*F6))^(2/3))^2))/2))>0,AL7,((AL7+AM7)/2)) | AO7: =IF((((AL7+AM7)/2)+(C7/(D7*((AL7+AM7)/2)))^2/(2*9.81)+B7-(G6+H6^2/(2*9.81))-(A6-A7)*(((DATOS!$B$34*(C7/(D7*((AL7+AM7)/2)))/((D7*((AL7+AM7)/2))/(D7+2*((AL7+AM7)/2)))^(2/3))^2+((DATOS!$B$34*H6/((D6*F6)/(D6+2*F6))^(2/3))^2))/2))>0,((AL7+AM7)/2),AM7) | AP7: =IF((((AN7+AO7)/2)+(C7/(D7*((AN7+AO7)/2)))^2/(2*9.81)+B7-(G6+H6^2/(2*9.81))-(A6-A7)*(((DATOS!$B$34*(C7/(D7*((AN7+AO7)/2)))/((D7*((AN7+AO7)/2))/(D7+2*((AN7+AO7)/2)))^(2/3))^2+((DATOS!$B$34*H6/((D6*F6)/(D6+2*F6))^(2/3))^2))/2))>0,AN7,((AN7+AO7)/2)) | AQ7: =IF((((AN7+AO7)/2)+(C7/(D7*((AN7+AO7)/2)))^2/(2*9.81)+B7-(G6+H6^2/(2*9.81))-(A6-A7)*(((DATOS!$B$34*(C7/(D7*((AN7+AO7)/2)))/((D7*((AN7+AO7)/2))/(D7+2*((AN7+AO7)/2)))^(2/3))^2+((DATOS!$B$34*H6/((D6*F6)/(D6+2*F6))^(2/3))^2))/2))>0,((AN7+AO7)/2),AO7) | AR7: =IF((((AP7+AQ7)/2)+(C7/(D7*((AP7+AQ7)/2)))^2/(2*9.81)+B7-(G6+H6^2/(2*9.81))-(A6-A7)*(((DATOS!$B$34*(C7/(D7*((AP7+AQ7)/2)))/((D7*((AP7+AQ7)/2))/(D7+2*((AP7+AQ7)/2)))^(2/3))^2+((DATOS!$B$34*H6/((D6*F6)/(D6+2*F6))^(2/3))^2))/2))>0,AP7,((AP7+AQ7)/2)) | AS7: =IF((((AP7+AQ7)/2)+(C7/(D7*((AP7+AQ7)/2)))^2/(2*9.81)+B7-(G6+H6^2/(2*9.81))-(A6-A7)*(((DATOS!$B$34*(C7/(D7*((AP7+AQ7)/2)))/((D7*((AP7+AQ7)/2))/(D7+2*((AP7+AQ7)/2)))^(2/3))^2+((DATOS!$B$34*H6/((D6*F6)/(D6+2*F6))^(2/3))^2))/2))>0,((AP7+AQ7)/2),AQ7) | AT7: =IF((((AR7+AS7)/2)+(C7/(D7*((AR7+AS7)/2)))^2/(2*9.81)+B7-(G6+H6^2/(2*9.81))-(A6-A7)*(((DATOS!$B$34*(C7/(D7*((AR7+AS7)/2)))/((D7*((AR7+AS7)/2))/(D7+2*((AR7+AS7)/2)))^(2/3))^2+((DATOS!$B$34*H6/((D6*F6)/(D6+2*F6))^(2/3))^2))/2))>0,AR7,((AR7+AS7)/2)) | AU7: =IF((((AR7+AS7)/2)+(C7/(D7*((AR7+AS7)/2)))^2/(2*9.81)+B7-(G6+H6^2/(2*9.81))-(A6-A7)*(((DATOS!$B$34*(C7/(D7*((AR7+AS7)/2)))/((D7*((AR7+AS7)/2))/(D7+2*((AR7+AS7)/2)))^(2/3))^2+((DATOS!$B$34*H6/((D6*F6)/(D6+2*F6))^(2/3))^2))/2))>0,((AR7+AS7)/2),AS7) | AV7: =IF((((AT7+AU7)/2)+(C7/(D7*((AT7+AU7)/2)))^2/(2*9.81)+B7-(G6+H6^2/(2*9.81))-(A6-A7)*(((DATOS!$B$34*(C7/(D7*((AT7+AU7)/2)))/((D7*((AT7+AU7)/2))/(D7+2*((AT7+AU7)/2)))^(2/3))^2+((DATOS!$B$34*H6/((D6*F6)/(D6+2*F6))^(2/3))^2))/2))>0,AT7,((AT7+AU7)/2)) | AW7: =IF((((AT7+AU7)/2)+(C7/(D7*((AT7+AU7)/2)))^2/(2*9.81)+B7-(G6+H6^2/(2*9.81))-(A6-A7)*(((DATOS!$B$34*(C7/(D7*((AT7+AU7)/2)))/((D7*((AT7+AU7)/2))/(D7+2*((AT7+AU7)/2)))^(2/3))^2+((DATOS!$B$34*H6/((D6*F6)/(D6+2*F6))^(2/3))^2))/2))>0,((AT7+AU7)/2),AU7) | AX7: =IF((((AV7+AW7)/2)+(C7/(D7*((AV7+AW7)/2)))^2/(2*9.81)+B7-(G6+H6^2/(2*9.81))-(A6-A7)*(((DATOS!$B$34*(C7/(D7*((AV7+AW7)/2)))/((D7*((AV7+AW7)/2))/(D7+2*((AV7+AW7)/2)))^(2/3))^2+((DATOS!$B$34*H6/((D6*F6)/(D6+2*F6))^(2/3))^2))/2))>0,AV7,((AV7+AW7)/2)) | AY7: =IF((((AV7+AW7)/2)+(C7/(D7*((AV7+AW7)/2)))^2/(2*9.81)+B7-(G6+H6^2/(2*9.81))-(A6-A7)*(((DATOS!$B$34*(C7/(D7*((AV7+AW7)/2)))/((D7*((AV7+AW7)/2))/(D7+2*((AV7+AW7)/2)))^(2/3))^2+((DATOS!$B$34*H6/((D6*F6)/(D6+2*F6))^(2/3))^2))/2))>0,((AV7+AW7)/2),AW7) | AZ7: =IF((((AX7+AY7)/2)+(C7/(D7*((AX7+AY7)/2)))^2/(2*9.81)+B7-(G6+H6^2/(2*9.81))-(A6-A7)*(((DATOS!$B$34*(C7/(D7*((AX7+AY7)/2)))/((D7*((AX7+AY7)/2))/(D7+2*((AX7+AY7)/2)))^(2/3))^2+((DATOS!$B$34*H6/((D6*F6)/(D6+2*F6))^(2/3))^2))/2))>0,AX7,((AX7+AY7)/2)) | BA7: =IF((((AX7+AY7)/2)+(C7/(D7*((AX7+AY7)/2)))^2/(2*9.81)+B7-(G6+H6^2/(2*9.81))-(A6-A7)*(((DATOS!$B$34*(C7/(D7*((AX7+AY7)/2)))/((D7*((AX7+AY7)/2))/(D7+2*((AX7+AY7)/2)))^(2/3))^2+((DATOS!$B$34*H6/((D6*F6)/(D6+2*F6))^(2/3))^2))/2))>0,((AX7+AY7)/2),AY7) | BB7: =IF((((AZ7+BA7)/2)+(C7/(D7*((AZ7+BA7)/2)))^2/(2*9.81)+B7-(G6+H6^2/(2*9.81))-(A6-A7)*(((DATOS!$B$34*(C7/(D7*((AZ7+BA7)/2)))/((D7*((AZ7+BA7)/2))/(D7+2*((AZ7+BA7)/2)))^(2/3))^2+((DATOS!$B$34*H6/((D6*F6)/(D6+2*F6))^(2/3))^2))/2))>0,AZ7,((AZ7+BA7)/2)) | BC7: =IF((((AZ7+BA7)/2)+(C7/(D7*((AZ7+BA7)/2)))^2/(2*9.81)+B7-(G6+H6^2/(2*9.81))-(A6-A7)*(((DATOS!$B$34*(C7/(D7*((AZ7+BA7)/2)))/((D7*((AZ7+BA7)/2))/(D7+2*((AZ7+BA7)/2)))^(2/3))^2+((DATOS!$B$34*H6/((D6*F6)/(D6+2*F6))^(2/3))^2))/2))>0,((AZ7+BA7)/2),BA7) | BD7: =IF((((BB7+BC7)/2)+(C7/(D7*((BB7+BC7)/2)))^2/(2*9.81)+B7-(G6+H6^2/(2*9.81))-(A6-A7)*(((DATOS!$B$34*(C7/(D7*((BB7+BC7)/2)))/((D7*((BB7+BC7)/2))/(D7+2*((BB7+BC7)/2)))^(2/3))^2+((DATOS!$B$34*H6/((D6*F6)/(D6+2*F6))^(2/3))^2))/2))>0,BB7,((BB7+BC7)/2)) | BE7: =IF((((BB7+BC7)/2)+(C7/(D7*((BB7+BC7)/2)))^2/(2*9.81)+B7-(G6+H6^2/(2*9.81))-(A6-A7)*(((DATOS!$B$34*(C7/(D7*((BB7+BC7)/2)))/((D7*((BB7+BC7)/2))/(D7+2*((BB7+BC7)/2)))^(2/3))^2+((DATOS!$B$34*H6/((D6*F6)/(D6+2*F6))^(2/3))^2))/2))>0,((BB7+BC7)/2),BC7) | BF7: =IF((((BD7+BE7)/2)+(C7/(D7*((BD7+BE7)/2)))^2/(2*9.81)+B7-(G6+H6^2/(2*9.81))-(A6-A7)*(((DATOS!$B$34*(C7/(D7*((BD7+BE7)/2)))/((D7*((BD7+BE7)/2))/(D7+2*((BD7+BE7)/2)))^(2/3))^2+((DATOS!$B$34*H6/((D6*F6)/(D6+2*F6))^(2/3))^2))/2))>0,BD7,((BD7+BE7)/2)) | BG7: =IF((((BD7+BE7)/2)+(C7/(D7*((BD7+BE7)/2)))^2/(2*9.81)+B7-(G6+H6^2/(2*9.81))-(A6-A7)*(((DATOS!$B$34*(C7/(D7*((BD7+BE7)/2)))/((D7*((BD7+BE7)/2))/(D7+2*((BD7+BE7)/2)))^(2/3))^2+((DATOS!$B$34*H6/((D6*F6)/(D6+2*F6))^(2/3))^2))/2))>0,((BD7+BE7)/2),BE7) | BH7: =IF((((BF7+BG7)/2)+(C7/(D7*((BF7+BG7)/2)))^2/(2*9.81)+B7-(G6+H6^2/(2*9.81))-(A6-A7)*(((DATOS!$B$34*(C7/(D7*((BF7+BG7)/2)))/((D7*((BF7+BG7)/2))/(D7+2*((BF7+BG7)/2)))^(2/3))^2+((DATOS!$B$34*H6/((D6*F6)/(D6+2*F6))^(2/3))^2))/2))>0,BF7,((BF7+BG7)/2)) | BI7: =IF((((BF7+BG7)/2)+(C7/(D7*((BF7+BG7)/2)))^2/(2*9.81)+B7-(G6+H6^2/(2*9.81))-(A6-A7)*(((DATOS!$B$34*(C7/(D7*((BF7+BG7)/2)))/((D7*((BF7+BG7)/2))/(D7+2*((BF7+BG7)/2)))^(2/3))^2+((DATOS!$B$34*H6/((D6*F6)/(D6+2*F6))^(2/3))^2))/2))>0,((BF7+BG7)/2),BG7) | BJ7: =IF((((BH7+BI7)/2)+(C7/(D7*((BH7+BI7)/2)))^2/(2*9.81)+B7-(G6+H6^2/(2*9.81))-(A6-A7)*(((DATOS!$B$34*(C7/(D7*((BH7+BI7)/2)))/((D7*((BH7+BI7)/2))/(D7+2*((BH7+BI7)/2)))^(2/3))^2+((DATOS!$B$34*H6/((D6*F6)/(D6+2*F6))^(2/3))^2))/2))>0,BH7,((BH7+BI7)/2)) | BK7: =IF((((BH7+BI7)/2)+(C7/(D7*((BH7+BI7)/2)))^2/(2*9.81)+B7-(G6+H6^2/(2*9.81))-(A6-A7)*(((DATOS!$B$34*(C7/(D7*((BH7+BI7)/2)))/((D7*((BH7+BI7)/2))/(D7+2*((BH7+BI7)/2)))^(2/3))^2+((DATOS!$B$34*H6/((D6*F6)/(D6+2*F6))^(2/3))^2))/2))>0,((BH7+BI7)/2),BI7) | BL7: =IF((((BJ7+BK7)/2)+(C7/(D7*((BJ7+BK7)/2)))^2/(2*9.81)+B7-(G6+H6^2/(2*9.81))-(A6-A7)*(((DATOS!$B$34*(C7/(D7*((BJ7+BK7)/2)))/((D7*((BJ7+BK7)/2))/(D7+2*((BJ7+BK7)/2)))^(2/3))^2+((DATOS!$B$34*H6/((D6*F6)/(D6+2*F6))^(2/3))^2))/2))>0,BJ7,((BJ7+BK7)/2)) | BM7: =IF((((BJ7+BK7)/2)+(C7/(D7*((BJ7+BK7)/2)))^2/(2*9.81)+B7-(G6+H6^2/(2*9.81))-(A6-A7)*(((DATOS!$B$34*(C7/(D7*((BJ7+BK7)/2)))/((D7*((BJ7+BK7)/2))/(D7+2*((BJ7+BK7)/2)))^(2/3))^2+((DATOS!$B$34*H6/((D6*F6)/(D6+2*F6))^(2/3))^2))/2))>0,((BJ7+BK7)/2),BK7) | BN7: =IF((((BL7+BM7)/2)+(C7/(D7*((BL7+BM7)/2)))^2/(2*9.81)+B7-(G6+H6^2/(2*9.81))-(A6-A7)*(((DATOS!$B$34*(C7/(D7*((BL7+BM7)/2)))/((D7*((BL7+BM7)/2))/(D7+2*((BL7+BM7)/2)))^(2/3))^2+((DATOS!$B$34*H6/((D6*F6)/(D6+2*F6))^(2/3))^2))/2))>0,BL7,((BL7+BM7)/2)) | BO7: =IF((((BL7+BM7)/2)+(C7/(D7*((BL7+BM7)/2)))^2/(2*9.81)+B7-(G6+H6^2/(2*9.81))-(A6-A7)*(((DATOS!$B$34*(C7/(D7*((BL7+BM7)/2)))/((D7*((BL7+BM7)/2))/(D7+2*((BL7+BM7)/2)))^(2/3))^2+((DATOS!$B$34*H6/((D6*F6)/(D6+2*F6))^(2/3))^2))/2))>0,((BL7+BM7)/2),BM7) | BP7: =IF((((BN7+BO7)/2)+(C7/(D7*((BN7+BO7)/2)))^2/(2*9.81)+B7-(G6+H6^2/(2*9.81))-(A6-A7)*(((DATOS!$B$34*(C7/(D7*((BN7+BO7)/2)))/((D7*((BN7+BO7)/2))/(D7+2*((BN7+BO7)/2)))^(2/3))^2+((DATOS!$B$34*H6/((D6*F6)/(D6+2*F6))^(2/3))^2))/2))>0,BN7,((BN7+BO7)/2)) | BQ7: =IF((((BN7+BO7)/2)+(C7/(D7*((BN7+BO7)/2)))^2/(2*9.81)+B7-(G6+H6^2/(2*9.81))-(A6-A7)*(((DATOS!$B$34*(C7/(D7*((BN7+BO7)/2)))/((D7*((BN7+BO7)/2))/(D7+2*((BN7+BO7)/2)))^(2/3))^2+((DATOS!$B$34*H6/((D6*F6)/(D6+2*F6))^(2/3))^2))/2))>0,((BN7+BO7)/2),BO7) | BR7: =IF((((BP7+BQ7)/2)+(C7/(D7*((BP7+BQ7)/2)))^2/(2*9.81)+B7-(G6+H6^2/(2*9.81))-(A6-A7)*(((DATOS!$B$34*(C7/(D7*((BP7+BQ7)/2)))/((D7*((BP7+BQ7)/2))/(D7+2*((BP7+BQ7)/2)))^(2/3))^2+((DATOS!$B$34*H6/((D6*F6)/(D6+2*F6))^(2/3))^2))/2))>0,BP7,((BP7+BQ7)/2)) | BS7: =IF((((BP7+BQ7)/2)+(C7/(D7*((BP7+BQ7)/2)))^2/(2*9.81)+B7-(G6+H6^2/(2*9.81))-(A6-A7)*(((DATOS!$B$34*(C7/(D7*((BP7+BQ7)/2)))/((D7*((BP7+BQ7)/2))/(D7+2*((BP7+BQ7)/2)))^(2/3))^2+((DATOS!$B$34*H6/((D6*F6)/(D6+2*F6))^(2/3))^2))/2))>0,((BP7+BQ7)/2),BQ7) | BT7: =IF((((BR7+BS7)/2)+(C7/(D7*((BR7+BS7)/2)))^2/(2*9.81)+B7-(G6+H6^2/(2*9.81))-(A6-A7)*(((DATOS!$B$34*(C7/(D7*((BR7+BS7)/2)))/((D7*((BR7+BS7)/2))/(D7+2*((BR7+BS7)/2)))^(2/3))^2+((DATOS!$B$34*H6/((D6*F6)/(D6+2*F6))^(2/3))^2))/2))>0,BR7,((BR7+BS7)/2)) | BU7: =IF((((BR7+BS7)/2)+(C7/(D7*((BR7+BS7)/2)))^2/(2*9.81)+B7-(G6+H6^2/(2*9.81))-(A6-A7)*(((DATOS!$B$34*(C7/(D7*((BR7+BS7)/2)))/((D7*((BR7+BS7)/2))/(D7+2*((BR7+BS7)/2)))^(2/3))^2+((DATOS!$B$34*H6/((D6*F6)/(D6+2*F6))^(2/3))^2))/2))>0,((BR7+BS7)/2),BS7) | BV7: =IF((((BT7+BU7)/2)+(C7/(D7*((BT7+BU7)/2)))^2/(2*9.81)+B7-(G6+H6^2/(2*9.81))-(A6-A7)*(((DATOS!$B$34*(C7/(D7*((BT7+BU7)/2)))/((D7*((BT7+BU7)/2))/(D7+2*((BT7+BU7)/2)))^(2/3))^2+((DATOS!$B$34*H6/((D6*F6)/(D6+2*F6))^(2/3))^2))/2))>0,BT7,((BT7+BU7)/2)) | BW7: =IF((((BT7+BU7)/2)+(C7/(D7*((BT7+BU7)/2)))^2/(2*9.81)+B7-(G6+H6^2/(2*9.81))-(A6-A7)*(((DATOS!$B$34*(C7/(D7*((BT7+BU7)/2)))/((D7*((BT7+BU7)/2))/(D7+2*((BT7+BU7)/2)))^(2/3))^2+((DATOS!$B$34*H6/((D6*F6)/(D6+2*F6))^(2/3))^2))/2))>0,((BT7+BU7)/2),BU7)
A8: 69 | B8: =DATOS!$B$22-DATOS!$B$23*A8 | C8: =CAUDALES!$B$13 | D8: =DATOS!$B$17 | E8: =(C8^2/(9.81*D8^2))^(1/3) | F8: =(BV8+BW8)/2 | G8: =B8+F8 | H8: =C8/(D8*F8) | I8: =H8/SQRT(9.81*F8) | J8: =DATOS!$B$29-IF(AND(A8>=DATOS!$B$30,A8<DATOS!$B$31),DATOS!$B$21,DATOS!$B$20) | K8: =J8-B8 | L8: =F8/K8 | M8: =J8-G8 | N8: =IF(AND(L8<=DATOS!$B$36,M8>=DATOS!$B$37,I8<=1),"CUMPLE","NO CUMPLE") | O8: =IF(AND(A8>=DATOS!$B$30,A8<DATOS!$B$31),"cruce de camiones",IF(AND(A8>=DATOS!$B$32,A8<DATOS!$B$33),"cruce de motos","tramo normal")) | P8: =E8*1.001 | Q8: 3 | R8: =IF((((P8+Q8)/2)+(C8/(D8*((P8+Q8)/2)))^2/(2*9.81)+B8-(G7+H7^2/(2*9.81))-(A7-A8)*(((DATOS!$B$34*(C8/(D8*((P8+Q8)/2)))/((D8*((P8+Q8)/2))/(D8+2*((P8+Q8)/2)))^(2/3))^2+((DATOS!$B$34*H7/((D7*F7)/(D7+2*F7))^(2/3))^2))/2))>0,P8,((P8+Q8)/2)) | S8: =IF((((P8+Q8)/2)+(C8/(D8*((P8+Q8)/2)))^2/(2*9.81)+B8-(G7+H7^2/(2*9.81))-(A7-A8)*(((DATOS!$B$34*(C8/(D8*((P8+Q8)/2)))/((D8*((P8+Q8)/2))/(D8+2*((P8+Q8)/2)))^(2/3))^2+((DATOS!$B$34*H7/((D7*F7)/(D7+2*F7))^(2/3))^2))/2))>0,((P8+Q8)/2),Q8) | T8: =IF((((R8+S8)/2)+(C8/(D8*((R8+S8)/2)))^2/(2*9.81)+B8-(G7+H7^2/(2*9.81))-(A7-A8)*(((DATOS!$B$34*(C8/(D8*((R8+S8)/2)))/((D8*((R8+S8)/2))/(D8+2*((R8+S8)/2)))^(2/3))^2+((DATOS!$B$34*H7/((D7*F7)/(D7+2*F7))^(2/3))^2))/2))>0,R8,((R8+S8)/2)) | U8: =IF((((R8+S8)/2)+(C8/(D8*((R8+S8)/2)))^2/(2*9.81)+B8-(G7+H7^2/(2*9.81))-(A7-A8)*(((DATOS!$B$34*(C8/(D8*((R8+S8)/2)))/((D8*((R8+S8)/2))/(D8+2*((R8+S8)/2)))^(2/3))^2+((DATOS!$B$34*H7/((D7*F7)/(D7+2*F7))^(2/3))^2))/2))>0,((R8+S8)/2),S8) | V8: =IF((((T8+U8)/2)+(C8/(D8*((T8+U8)/2)))^2/(2*9.81)+B8-(G7+H7^2/(2*9.81))-(A7-A8)*(((DATOS!$B$34*(C8/(D8*((T8+U8)/2)))/((D8*((T8+U8)/2))/(D8+2*((T8+U8)/2)))^(2/3))^2+((DATOS!$B$34*H7/((D7*F7)/(D7+2*F7))^(2/3))^2))/2))>0,T8,((T8+U8)/2)) | W8: =IF((((T8+U8)/2)+(C8/(D8*((T8+U8)/2)))^2/(2*9.81)+B8-(G7+H7^2/(2*9.81))-(A7-A8)*(((DATOS!$B$34*(C8/(D8*((T8+U8)/2)))/((D8*((T8+U8)/2))/(D8+2*((T8+U8)/2)))^(2/3))^2+((DATOS!$B$34*H7/((D7*F7)/(D7+2*F7))^(2/3))^2))/2))>0,((T8+U8)/2),U8) | X8: =IF((((V8+W8)/2)+(C8/(D8*((V8+W8)/2)))^2/(2*9.81)+B8-(G7+H7^2/(2*9.81))-(A7-A8)*(((DATOS!$B$34*(C8/(D8*((V8+W8)/2)))/((D8*((V8+W8)/2))/(D8+2*((V8+W8)/2)))^(2/3))^2+((DATOS!$B$34*H7/((D7*F7)/(D7+2*F7))^(2/3))^2))/2))>0,V8,((V8+W8)/2)) | Y8: =IF((((V8+W8)/2)+(C8/(D8*((V8+W8)/2)))^2/(2*9.81)+B8-(G7+H7^2/(2*9.81))-(A7-A8)*(((DATOS!$B$34*(C8/(D8*((V8+W8)/2)))/((D8*((V8+W8)/2))/(D8+2*((V8+W8)/2)))^(2/3))^2+((DATOS!$B$34*H7/((D7*F7)/(D7+2*F7))^(2/3))^2))/2))>0,((V8+W8)/2),W8) | Z8: =IF((((X8+Y8)/2)+(C8/(D8*((X8+Y8)/2)))^2/(2*9.81)+B8-(G7+H7^2/(2*9.81))-(A7-A8)*(((DATOS!$B$34*(C8/(D8*((X8+Y8)/2)))/((D8*((X8+Y8)/2))/(D8+2*((X8+Y8)/2)))^(2/3))^2+((DATOS!$B$34*H7/((D7*F7)/(D7+2*F7))^(2/3))^2))/2))>0,X8,((X8+Y8)/2)) | AA8: =IF((((X8+Y8)/2)+(C8/(D8*((X8+Y8)/2)))^2/(2*9.81)+B8-(G7+H7^2/(2*9.81))-(A7-A8)*(((DATOS!$B$34*(C8/(D8*((X8+Y8)/2)))/((D8*((X8+Y8)/2))/(D8+2*((X8+Y8)/2)))^(2/3))^2+((DATOS!$B$34*H7/((D7*F7)/(D7+2*F7))^(2/3))^2))/2))>0,((X8+Y8)/2),Y8) | AB8: =IF((((Z8+AA8)/2)+(C8/(D8*((Z8+AA8)/2)))^2/(2*9.81)+B8-(G7+H7^2/(2*9.81))-(A7-A8)*(((DATOS!$B$34*(C8/(D8*((Z8+AA8)/2)))/((D8*((Z8+AA8)/2))/(D8+2*((Z8+AA8)/2)))^(2/3))^2+((DATOS!$B$34*H7/((D7*F7)/(D7+2*F7))^(2/3))^2))/2))>0,Z8,((Z8+AA8)/2)) | AC8: =IF((((Z8+AA8)/2)+(C8/(D8*((Z8+AA8)/2)))^2/(2*9.81)+B8-(G7+H7^2/(2*9.81))-(A7-A8)*(((DATOS!$B$34*(C8/(D8*((Z8+AA8)/2)))/((D8*((Z8+AA8)/2))/(D8+2*((Z8+AA8)/2)))^(2/3))^2+((DATOS!$B$34*H7/((D7*F7)/(D7+2*F7))^(2/3))^2))/2))>0,((Z8+AA8)/2),AA8) | AD8: =IF((((AB8+AC8)/2)+(C8/(D8*((AB8+AC8)/2)))^2/(2*9.81)+B8-(G7+H7^2/(2*9.81))-(A7-A8)*(((DATOS!$B$34*(C8/(D8*((AB8+AC8)/2)))/((D8*((AB8+AC8)/2))/(D8+2*((AB8+AC8)/2)))^(2/3))^2+((DATOS!$B$34*H7/((D7*F7)/(D7+2*F7))^(2/3))^2))/2))>0,AB8,((AB8+AC8)/2)) | AE8: =IF((((AB8+AC8)/2)+(C8/(D8*((AB8+AC8)/2)))^2/(2*9.81)+B8-(G7+H7^2/(2*9.81))-(A7-A8)*(((DATOS!$B$34*(C8/(D8*((AB8+AC8)/2)))/((D8*((AB8+AC8)/2))/(D8+2*((AB8+AC8)/2)))^(2/3))^2+((DATOS!$B$34*H7/((D7*F7)/(D7+2*F7))^(2/3))^2))/2))>0,((AB8+AC8)/2),AC8) | AF8: =IF((((AD8+AE8)/2)+(C8/(D8*((AD8+AE8)/2)))^2/(2*9.81)+B8-(G7+H7^2/(2*9.81))-(A7-A8)*(((DATOS!$B$34*(C8/(D8*((AD8+AE8)/2)))/((D8*((AD8+AE8)/2))/(D8+2*((AD8+AE8)/2)))^(2/3))^2+((DATOS!$B$34*H7/((D7*F7)/(D7+2*F7))^(2/3))^2))/2))>0,AD8,((AD8+AE8)/2)) | AG8: =IF((((AD8+AE8)/2)+(C8/(D8*((AD8+AE8)/2)))^2/(2*9.81)+B8-(G7+H7^2/(2*9.81))-(A7-A8)*(((DATOS!$B$34*(C8/(D8*((AD8+AE8)/2)))/((D8*((AD8+AE8)/2))/(D8+2*((AD8+AE8)/2)))^(2/3))^2+((DATOS!$B$34*H7/((D7*F7)/(D7+2*F7))^(2/3))^2))/2))>0,((AD8+AE8)/2),AE8) | AH8: =IF((((AF8+AG8)/2)+(C8/(D8*((AF8+AG8)/2)))^2/(2*9.81)+B8-(G7+H7^2/(2*9.81))-(A7-A8)*(((DATOS!$B$34*(C8/(D8*((AF8+AG8)/2)))/((D8*((AF8+AG8)/2))/(D8+2*((AF8+AG8)/2)))^(2/3))^2+((DATOS!$B$34*H7/((D7*F7)/(D7+2*F7))^(2/3))^2))/2))>0,AF8,((AF8+AG8)/2)) | AI8: =IF((((AF8+AG8)/2)+(C8/(D8*((AF8+AG8)/2)))^2/(2*9.81)+B8-(G7+H7^2/(2*9.81))-(A7-A8)*(((DATOS!$B$34*(C8/(D8*((AF8+AG8)/2)))/((D8*((AF8+AG8)/2))/(D8+2*((AF8+AG8)/2)))^(2/3))^2+((DATOS!$B$34*H7/((D7*F7)/(D7+2*F7))^(2/3))^2))/2))>0,((AF8+AG8)/2),AG8) | AJ8: =IF((((AH8+AI8)/2)+(C8/(D8*((AH8+AI8)/2)))^2/(2*9.81)+B8-(G7+H7^2/(2*9.81))-(A7-A8)*(((DATOS!$B$34*(C8/(D8*((AH8+AI8)/2)))/((D8*((AH8+AI8)/2))/(D8+2*((AH8+AI8)/2)))^(2/3))^2+((DATOS!$B$34*H7/((D7*F7)/(D7+2*F7))^(2/3))^2))/2))>0,AH8,((AH8+AI8)/2)) | AK8: =IF((((AH8+AI8)/2)+(C8/(D8*((AH8+AI8)/2)))^2/(2*9.81)+B8-(G7+H7^2/(2*9.81))-(A7-A8)*(((DATOS!$B$34*(C8/(D8*((AH8+AI8)/2)))/((D8*((AH8+AI8)/2))/(D8+2*((AH8+AI8)/2)))^(2/3))^2+((DATOS!$B$34*H7/((D7*F7)/(D7+2*F7))^(2/3))^2))/2))>0,((AH8+AI8)/2),AI8) | AL8: =IF((((AJ8+AK8)/2)+(C8/(D8*((AJ8+AK8)/2)))^2/(2*9.81)+B8-(G7+H7^2/(2*9.81))-(A7-A8)*(((DATOS!$B$34*(C8/(D8*((AJ8+AK8)/2)))/((D8*((AJ8+AK8)/2))/(D8+2*((AJ8+AK8)/2)))^(2/3))^2+((DATOS!$B$34*H7/((D7*F7)/(D7+2*F7))^(2/3))^2))/2))>0,AJ8,((AJ8+AK8)/2)) | AM8: =IF((((AJ8+AK8)/2)+(C8/(D8*((AJ8+AK8)/2)))^2/(2*9.81)+B8-(G7+H7^2/(2*9.81))-(A7-A8)*(((DATOS!$B$34*(C8/(D8*((AJ8+AK8)/2)))/((D8*((AJ8+AK8)/2))/(D8+2*((AJ8+AK8)/2)))^(2/3))^2+((DATOS!$B$34*H7/((D7*F7)/(D7+2*F7))^(2/3))^2))/2))>0,((AJ8+AK8)/2),AK8) | AN8: =IF((((AL8+AM8)/2)+(C8/(D8*((AL8+AM8)/2)))^2/(2*9.81)+B8-(G7+H7^2/(2*9.81))-(A7-A8)*(((DATOS!$B$34*(C8/(D8*((AL8+AM8)/2)))/((D8*((AL8+AM8)/2))/(D8+2*((AL8+AM8)/2)))^(2/3))^2+((DATOS!$B$34*H7/((D7*F7)/(D7+2*F7))^(2/3))^2))/2))>0,AL8,((AL8+AM8)/2)) | AO8: =IF((((AL8+AM8)/2)+(C8/(D8*((AL8+AM8)/2)))^2/(2*9.81)+B8-(G7+H7^2/(2*9.81))-(A7-A8)*(((DATOS!$B$34*(C8/(D8*((AL8+AM8)/2)))/((D8*((AL8+AM8)/2))/(D8+2*((AL8+AM8)/2)))^(2/3))^2+((DATOS!$B$34*H7/((D7*F7)/(D7+2*F7))^(2/3))^2))/2))>0,((AL8+AM8)/2),AM8) | AP8: =IF((((AN8+AO8)/2)+(C8/(D8*((AN8+AO8)/2)))^2/(2*9.81)+B8-(G7+H7^2/(2*9.81))-(A7-A8)*(((DATOS!$B$34*(C8/(D8*((AN8+AO8)/2)))/((D8*((AN8+AO8)/2))/(D8+2*((AN8+AO8)/2)))^(2/3))^2+((DATOS!$B$34*H7/((D7*F7)/(D7+2*F7))^(2/3))^2))/2))>0,AN8,((AN8+AO8)/2)) | AQ8: =IF((((AN8+AO8)/2)+(C8/(D8*((AN8+AO8)/2)))^2/(2*9.81)+B8-(G7+H7^2/(2*9.81))-(A7-A8)*(((DATOS!$B$34*(C8/(D8*((AN8+AO8)/2)))/((D8*((AN8+AO8)/2))/(D8+2*((AN8+AO8)/2)))^(2/3))^2+((DATOS!$B$34*H7/((D7*F7)/(D7+2*F7))^(2/3))^2))/2))>0,((AN8+AO8)/2),AO8) | AR8: =IF((((AP8+AQ8)/2)+(C8/(D8*((AP8+AQ8)/2)))^2/(2*9.81)+B8-(G7+H7^2/(2*9.81))-(A7-A8)*(((DATOS!$B$34*(C8/(D8*((AP8+AQ8)/2)))/((D8*((AP8+AQ8)/2))/(D8+2*((AP8+AQ8)/2)))^(2/3))^2+((DATOS!$B$34*H7/((D7*F7)/(D7+2*F7))^(2/3))^2))/2))>0,AP8,((AP8+AQ8)/2)) | AS8: =IF((((AP8+AQ8)/2)+(C8/(D8*((AP8+AQ8)/2)))^2/(2*9.81)+B8-(G7+H7^2/(2*9.81))-(A7-A8)*(((DATOS!$B$34*(C8/(D8*((AP8+AQ8)/2)))/((D8*((AP8+AQ8)/2))/(D8+2*((AP8+AQ8)/2)))^(2/3))^2+((DATOS!$B$34*H7/((D7*F7)/(D7+2*F7))^(2/3))^2))/2))>0,((AP8+AQ8)/2),AQ8) | AT8: =IF((((AR8+AS8)/2)+(C8/(D8*((AR8+AS8)/2)))^2/(2*9.81)+B8-(G7+H7^2/(2*9.81))-(A7-A8)*(((DATOS!$B$34*(C8/(D8*((AR8+AS8)/2)))/((D8*((AR8+AS8)/2))/(D8+2*((AR8+AS8)/2)))^(2/3))^2+((DATOS!$B$34*H7/((D7*F7)/(D7+2*F7))^(2/3))^2))/2))>0,AR8,((AR8+AS8)/2)) | AU8: =IF((((AR8+AS8)/2)+(C8/(D8*((AR8+AS8)/2)))^2/(2*9.81)+B8-(G7+H7^2/(2*9.81))-(A7-A8)*(((DATOS!$B$34*(C8/(D8*((AR8+AS8)/2)))/((D8*((AR8+AS8)/2))/(D8+2*((AR8+AS8)/2)))^(2/3))^2+((DATOS!$B$34*H7/((D7*F7)/(D7+2*F7))^(2/3))^2))/2))>0,((AR8+AS8)/2),AS8) | AV8: =IF((((AT8+AU8)/2)+(C8/(D8*((AT8+AU8)/2)))^2/(2*9.81)+B8-(G7+H7^2/(2*9.81))-(A7-A8)*(((DATOS!$B$34*(C8/(D8*((AT8+AU8)/2)))/((D8*((AT8+AU8)/2))/(D8+2*((AT8+AU8)/2)))^(2/3))^2+((DATOS!$B$34*H7/((D7*F7)/(D7+2*F7))^(2/3))^2))/2))>0,AT8,((AT8+AU8)/2)) | AW8: =IF((((AT8+AU8)/2)+(C8/(D8*((AT8+AU8)/2)))^2/(2*9.81)+B8-(G7+H7^2/(2*9.81))-(A7-A8)*(((DATOS!$B$34*(C8/(D8*((AT8+AU8)/2)))/((D8*((AT8+AU8)/2))/(D8+2*((AT8+AU8)/2)))^(2/3))^2+((DATOS!$B$34*H7/((D7*F7)/(D7+2*F7))^(2/3))^2))/2))>0,((AT8+AU8)/2),AU8) | AX8: =IF((((AV8+AW8)/2)+(C8/(D8*((AV8+AW8)/2)))^2/(2*9.81)+B8-(G7+H7^2/(2*9.81))-(A7-A8)*(((DATOS!$B$34*(C8/(D8*((AV8+AW8)/2)))/((D8*((AV8+AW8)/2))/(D8+2*((AV8+AW8)/2)))^(2/3))^2+((DATOS!$B$34*H7/((D7*F7)/(D7+2*F7))^(2/3))^2))/2))>0,AV8,((AV8+AW8)/2)) | AY8: =IF((((AV8+AW8)/2)+(C8/(D8*((AV8+AW8)/2)))^2/(2*9.81)+B8-(G7+H7^2/(2*9.81))-(A7-A8)*(((DATOS!$B$34*(C8/(D8*((AV8+AW8)/2)))/((D8*((AV8+AW8)/2))/(D8+2*((AV8+AW8)/2)))^(2/3))^2+((DATOS!$B$34*H7/((D7*F7)/(D7+2*F7))^(2/3))^2))/2))>0,((AV8+AW8)/2),AW8) | AZ8: =IF((((AX8+AY8)/2)+(C8/(D8*((AX8+AY8)/2)))^2/(2*9.81)+B8-(G7+H7^2/(2*9.81))-(A7-A8)*(((DATOS!$B$34*(C8/(D8*((AX8+AY8)/2)))/((D8*((AX8+AY8)/2))/(D8+2*((AX8+AY8)/2)))^(2/3))^2+((DATOS!$B$34*H7/((D7*F7)/(D7+2*F7))^(2/3))^2))/2))>0,AX8,((AX8+AY8)/2)) | BA8: =IF((((AX8+AY8)/2)+(C8/(D8*((AX8+AY8)/2)))^2/(2*9.81)+B8-(G7+H7^2/(2*9.81))-(A7-A8)*(((DATOS!$B$34*(C8/(D8*((AX8+AY8)/2)))/((D8*((AX8+AY8)/2))/(D8+2*((AX8+AY8)/2)))^(2/3))^2+((DATOS!$B$34*H7/((D7*F7)/(D7+2*F7))^(2/3))^2))/2))>0,((AX8+AY8)/2),AY8) | BB8: =IF((((AZ8+BA8)/2)+(C8/(D8*((AZ8+BA8)/2)))^2/(2*9.81)+B8-(G7+H7^2/(2*9.81))-(A7-A8)*(((DATOS!$B$34*(C8/(D8*((AZ8+BA8)/2)))/((D8*((AZ8+BA8)/2))/(D8+2*((AZ8+BA8)/2)))^(2/3))^2+((DATOS!$B$34*H7/((D7*F7)/(D7+2*F7))^(2/3))^2))/2))>0,AZ8,((AZ8+BA8)/2)) | BC8: =IF((((AZ8+BA8)/2)+(C8/(D8*((AZ8+BA8)/2)))^2/(2*9.81)+B8-(G7+H7^2/(2*9.81))-(A7-A8)*(((DATOS!$B$34*(C8/(D8*((AZ8+BA8)/2)))/((D8*((AZ8+BA8)/2))/(D8+2*((AZ8+BA8)/2)))^(2/3))^2+((DATOS!$B$34*H7/((D7*F7)/(D7+2*F7))^(2/3))^2))/2))>0,((AZ8+BA8)/2),BA8) | BD8: =IF((((BB8+BC8)/2)+(C8/(D8*((BB8+BC8)/2)))^2/(2*9.81)+B8-(G7+H7^2/(2*9.81))-(A7-A8)*(((DATOS!$B$34*(C8/(D8*((BB8+BC8)/2)))/((D8*((BB8+BC8)/2))/(D8+2*((BB8+BC8)/2)))^(2/3))^2+((DATOS!$B$34*H7/((D7*F7)/(D7+2*F7))^(2/3))^2))/2))>0,BB8,((BB8+BC8)/2)) | BE8: =IF((((BB8+BC8)/2)+(C8/(D8*((BB8+BC8)/2)))^2/(2*9.81)+B8-(G7+H7^2/(2*9.81))-(A7-A8)*(((DATOS!$B$34*(C8/(D8*((BB8+BC8)/2)))/((D8*((BB8+BC8)/2))/(D8+2*((BB8+BC8)/2)))^(2/3))^2+((DATOS!$B$34*H7/((D7*F7)/(D7+2*F7))^(2/3))^2))/2))>0,((BB8+BC8)/2),BC8) | BF8: =IF((((BD8+BE8)/2)+(C8/(D8*((BD8+BE8)/2)))^2/(2*9.81)+B8-(G7+H7^2/(2*9.81))-(A7-A8)*(((DATOS!$B$34*(C8/(D8*((BD8+BE8)/2)))/((D8*((BD8+BE8)/2))/(D8+2*((BD8+BE8)/2)))^(2/3))^2+((DATOS!$B$34*H7/((D7*F7)/(D7+2*F7))^(2/3))^2))/2))>0,BD8,((BD8+BE8)/2)) | BG8: =IF((((BD8+BE8)/2)+(C8/(D8*((BD8+BE8)/2)))^2/(2*9.81)+B8-(G7+H7^2/(2*9.81))-(A7-A8)*(((DATOS!$B$34*(C8/(D8*((BD8+BE8)/2)))/((D8*((BD8+BE8)/2))/(D8+2*((BD8+BE8)/2)))^(2/3))^2+((DATOS!$B$34*H7/((D7*F7)/(D7+2*F7))^(2/3))^2))/2))>0,((BD8+BE8)/2),BE8) | BH8: =IF((((BF8+BG8)/2)+(C8/(D8*((BF8+BG8)/2)))^2/(2*9.81)+B8-(G7+H7^2/(2*9.81))-(A7-A8)*(((DATOS!$B$34*(C8/(D8*((BF8+BG8)/2)))/((D8*((BF8+BG8)/2))/(D8+2*((BF8+BG8)/2)))^(2/3))^2+((DATOS!$B$34*H7/((D7*F7)/(D7+2*F7))^(2/3))^2))/2))>0,BF8,((BF8+BG8)/2)) | BI8: =IF((((BF8+BG8)/2)+(C8/(D8*((BF8+BG8)/2)))^2/(2*9.81)+B8-(G7+H7^2/(2*9.81))-(A7-A8)*(((DATOS!$B$34*(C8/(D8*((BF8+BG8)/2)))/((D8*((BF8+BG8)/2))/(D8+2*((BF8+BG8)/2)))^(2/3))^2+((DATOS!$B$34*H7/((D7*F7)/(D7+2*F7))^(2/3))^2))/2))>0,((BF8+BG8)/2),BG8) | BJ8: =IF((((BH8+BI8)/2)+(C8/(D8*((BH8+BI8)/2)))^2/(2*9.81)+B8-(G7+H7^2/(2*9.81))-(A7-A8)*(((DATOS!$B$34*(C8/(D8*((BH8+BI8)/2)))/((D8*((BH8+BI8)/2))/(D8+2*((BH8+BI8)/2)))^(2/3))^2+((DATOS!$B$34*H7/((D7*F7)/(D7+2*F7))^(2/3))^2))/2))>0,BH8,((BH8+BI8)/2)) | BK8: =IF((((BH8+BI8)/2)+(C8/(D8*((BH8+BI8)/2)))^2/(2*9.81)+B8-(G7+H7^2/(2*9.81))-(A7-A8)*(((DATOS!$B$34*(C8/(D8*((BH8+BI8)/2)))/((D8*((BH8+BI8)/2))/(D8+2*((BH8+BI8)/2)))^(2/3))^2+((DATOS!$B$34*H7/((D7*F7)/(D7+2*F7))^(2/3))^2))/2))>0,((BH8+BI8)/2),BI8) | BL8: =IF((((BJ8+BK8)/2)+(C8/(D8*((BJ8+BK8)/2)))^2/(2*9.81)+B8-(G7+H7^2/(2*9.81))-(A7-A8)*(((DATOS!$B$34*(C8/(D8*((BJ8+BK8)/2)))/((D8*((BJ8+BK8)/2))/(D8+2*((BJ8+BK8)/2)))^(2/3))^2+((DATOS!$B$34*H7/((D7*F7)/(D7+2*F7))^(2/3))^2))/2))>0,BJ8,((BJ8+BK8)/2)) | BM8: =IF((((BJ8+BK8)/2)+(C8/(D8*((BJ8+BK8)/2)))^2/(2*9.81)+B8-(G7+H7^2/(2*9.81))-(A7-A8)*(((DATOS!$B$34*(C8/(D8*((BJ8+BK8)/2)))/((D8*((BJ8+BK8)/2))/(D8+2*((BJ8+BK8)/2)))^(2/3))^2+((DATOS!$B$34*H7/((D7*F7)/(D7+2*F7))^(2/3))^2))/2))>0,((BJ8+BK8)/2),BK8) | BN8: =IF((((BL8+BM8)/2)+(C8/(D8*((BL8+BM8)/2)))^2/(2*9.81)+B8-(G7+H7^2/(2*9.81))-(A7-A8)*(((DATOS!$B$34*(C8/(D8*((BL8+BM8)/2)))/((D8*((BL8+BM8)/2))/(D8+2*((BL8+BM8)/2)))^(2/3))^2+((DATOS!$B$34*H7/((D7*F7)/(D7+2*F7))^(2/3))^2))/2))>0,BL8,((BL8+BM8)/2)) | BO8: =IF((((BL8+BM8)/2)+(C8/(D8*((BL8+BM8)/2)))^2/(2*9.81)+B8-(G7+H7^2/(2*9.81))-(A7-A8)*(((DATOS!$B$34*(C8/(D8*((BL8+BM8)/2)))/((D8*((BL8+BM8)/2))/(D8+2*((BL8+BM8)/2)))^(2/3))^2+((DATOS!$B$34*H7/((D7*F7)/(D7+2*F7))^(2/3))^2))/2))>0,((BL8+BM8)/2),BM8) | BP8: =IF((((BN8+BO8)/2)+(C8/(D8*((BN8+BO8)/2)))^2/(2*9.81)+B8-(G7+H7^2/(2*9.81))-(A7-A8)*(((DATOS!$B$34*(C8/(D8*((BN8+BO8)/2)))/((D8*((BN8+BO8)/2))/(D8+2*((BN8+BO8)/2)))^(2/3))^2+((DATOS!$B$34*H7/((D7*F7)/(D7+2*F7))^(2/3))^2))/2))>0,BN8,((BN8+BO8)/2)) | BQ8: =IF((((BN8+BO8)/2)+(C8/(D8*((BN8+BO8)/2)))^2/(2*9.81)+B8-(G7+H7^2/(2*9.81))-(A7-A8)*(((DATOS!$B$34*(C8/(D8*((BN8+BO8)/2)))/((D8*((BN8+BO8)/2))/(D8+2*((BN8+BO8)/2)))^(2/3))^2+((DATOS!$B$34*H7/((D7*F7)/(D7+2*F7))^(2/3))^2))/2))>0,((BN8+BO8)/2),BO8) | BR8: =IF((((BP8+BQ8)/2)+(C8/(D8*((BP8+BQ8)/2)))^2/(2*9.81)+B8-(G7+H7^2/(2*9.81))-(A7-A8)*(((DATOS!$B$34*(C8/(D8*((BP8+BQ8)/2)))/((D8*((BP8+BQ8)/2))/(D8+2*((BP8+BQ8)/2)))^(2/3))^2+((DATOS!$B$34*H7/((D7*F7)/(D7+2*F7))^(2/3))^2))/2))>0,BP8,((BP8+BQ8)/2)) | BS8: =IF((((BP8+BQ8)/2)+(C8/(D8*((BP8+BQ8)/2)))^2/(2*9.81)+B8-(G7+H7^2/(2*9.81))-(A7-A8)*(((DATOS!$B$34*(C8/(D8*((BP8+BQ8)/2)))/((D8*((BP8+BQ8)/2))/(D8+2*((BP8+BQ8)/2)))^(2/3))^2+((DATOS!$B$34*H7/((D7*F7)/(D7+2*F7))^(2/3))^2))/2))>0,((BP8+BQ8)/2),BQ8) | BT8: =IF((((BR8+BS8)/2)+(C8/(D8*((BR8+BS8)/2)))^2/(2*9.81)+B8-(G7+H7^2/(2*9.81))-(A7-A8)*(((DATOS!$B$34*(C8/(D8*((BR8+BS8)/2)))/((D8*((BR8+BS8)/2))/(D8+2*((BR8+BS8)/2)))^(2/3))^2+((DATOS!$B$34*H7/((D7*F7)/(D7+2*F7))^(2/3))^2))/2))>0,BR8,((BR8+BS8)/2)) | BU8: =IF((((BR8+BS8)/2)+(C8/(D8*((BR8+BS8)/2)))^2/(2*9.81)+B8-(G7+H7^2/(2*9.81))-(A7-A8)*(((DATOS!$B$34*(C8/(D8*((BR8+BS8)/2)))/((D8*((BR8+BS8)/2))/(D8+2*((BR8+BS8)/2)))^(2/3))^2+((DATOS!$B$34*H7/((D7*F7)/(D7+2*F7))^(2/3))^2))/2))>0,((BR8+BS8)/2),BS8) | BV8: =IF((((BT8+BU8)/2)+(C8/(D8*((BT8+BU8)/2)))^2/(2*9.81)+B8-(G7+H7^2/(2*9.81))-(A7-A8)*(((DATOS!$B$34*(C8/(D8*((BT8+BU8)/2)))/((D8*((BT8+BU8)/2))/(D8+2*((BT8+BU8)/2)))^(2/3))^2+((DATOS!$B$34*H7/((D7*F7)/(D7+2*F7))^(2/3))^2))/2))>0,BT8,((BT8+BU8)/2)) | BW8: =IF((((BT8+BU8)/2)+(C8/(D8*((BT8+BU8)/2)))^2/(2*9.81)+B8-(G7+H7^2/(2*9.81))-(A7-A8)*(((DATOS!$B$34*(C8/(D8*((BT8+BU8)/2)))/((D8*((BT8+BU8)/2))/(D8+2*((BT8+BU8)/2)))^(2/3))^2+((DATOS!$B$34*H7/((D7*F7)/(D7+2*F7))^(2/3))^2))/2))>0,((BT8+BU8)/2),BU8)
