Workbook

Sheet RESUMEN
A1: HOJA RESUMEN DE METRADOS - ARQUITECTURA: EQUIPAMIENTO Y MOBILIARIO
A2: PROYECTO | B2: “CREACIÓN DEL SERVICIO DE PROTECCIÓN A MUJERES VÍCTIMAS DE VIOLENCIA EN SITUACIÓN DE RIESGO DE FEMINICIDIO O PELIGRE SU INTEGRIDAD Y/O SALUD FÍSICA Y/O MENTAL EN HOGAR DE REFUGIO TEMPORAL DISTRITO DE MORALES DE LA PROVINCIA DE SAN MARTÍN DEL DEPARTAMENTO DE SAN MARTÍN”
A3: CUI | B3: N.° 2675514
A4: PROPIETARIO | B4: Gobierno Regional San Martín - Gerencia Territorial Bajo Mayo
A5: UBICACIÓN | B5: Morales / San Martín / San Martín
A6: ESPECIALIDAD | B6: ARQUITECTURA - EQUIPAMIENTO Y MOBILIARIO
A7: LÁMINAS | B7: EM-01 a EM-07 (equipamiento y mobiliario, escala 1/50)
A8: FECHA | B8: SETIEMBRE 2026
A10: PART. N.° | B10: CÓD. | C10: DESCRIPCIÓN | D10: UND | E10: METRADO
A11: 03 | C11: ARQUITECTURA
A12: 03.01 | C12: MOBILIARIO Y EQUIPAMIENTO
A13: 03.01.01 | C13: EQUIPOS
A14: 03.01.01.01 | B14: E1 | C14: PROYECTOR INTERACTIVO | D14: und | E14: =SUMIF('METRADO POR AMBIENTE'!$H$11:$H$262,F14,'METRADO POR AMBIENTE'!$G$11:$G$262) | F14: E1
A15: 03.01.01.02 | B15: E2 | C15: COMPUTADORA PORTÁTIL i5 | D15: und | E15: =SUMIF('METRADO POR AMBIENTE'!$H$11:$H$262,F15,'METRADO POR AMBIENTE'!$G$11:$G$262) | F15: E2
A16: 03.01.01.03 | B16: E3 | C16: PRESENTADOR INALÁMBRICO CON PUNTERO LÁSER | D16: und | E16: =SUMIF('METRADO POR AMBIENTE'!$H$11:$H$262,F16,'METRADO POR AMBIENTE'!$G$11:$G$262) | F16: E3
A17: 03.01.01.04 | B17: E4 | C17: RELOJ PARA ADOSAR A PARED | D17: und | E17: =SUMIF('METRADO POR AMBIENTE'!$H$11:$H$262,F17,'METRADO POR AMBIENTE'!$G$11:$G$262) | F17: E4
A18: 03.01.01.05 | B18: E5 | C18: LAVADORA DE 20 kg DE CARGA SUPERIOR | D18: und | E18: =SUMIF('METRADO POR AMBIENTE'!$H$11:$H$262,F18,'METRADO POR AMBIENTE'!$G$11:$G$262) | F18: E5
A19: 03.01.01.06 | B19: E6 | C19: COMPUTADORA i5 ESTACIONARIA | D19: und | E19: =SUMIF('METRADO POR AMBIENTE'!$H$11:$H$262,F19,'METRADO POR AMBIENTE'!$G$11:$G$262) | F19: E6
A20: 03.01.01.07 | B20: E7 | C20: PROYECTOR MULTIMEDIA | D20: und | E20: =SUMIF('METRADO POR AMBIENTE'!$H$11:$H$262,F20,'METRADO POR AMBIENTE'!$G$11:$G$262) | F20: E7
A21: 03.01.01.08 | B21: E9 | C21: IMPRESORA MULTIFUNCIONAL | D21: und | E21: =SUMIF('METRADO POR AMBIENTE'!$H$11:$H$262,F21,'METRADO POR AMBIENTE'!$G$11:$G$262) | F21: E9
A22: 03.01.01.09 | B22: E10 | C22: MÁQUINA DE CORTE TEXTIL | D22: und | E22: =SUMIF('METRADO POR AMBIENTE'!$H$11:$H$262,F22,'METRADO POR AMBIENTE'!$G$11:$G$262) | F22: E10
A23: 03.01.01.10 | B23: E13 | C23: COCINA INDUSTRIAL DE 2 HORNILLAS | D23: und | E23: =SUMIF('METRADO POR AMBIENTE'!$H$11:$H$262,F23,'METRADO POR AMBIENTE'!$G$11:$G$262) | F23: E13
A24: 03.01.01.11 | B24: E16 | C24: HORNO MICROONDAS DE 31 LITROS | D24: und | E24: =SUMIF('METRADO POR AMBIENTE'!$H$11:$H$262,F24,'METRADO POR AMBIENTE'!$G$11:$G$262) | F24: E16
A25: 03.01.01.12 | B25: E17 | C25: LICUADORA DE 1.5 LITROS | D25: und | E25: =SUMIF('METRADO POR AMBIENTE'!$H$11:$H$262,F25,'METRADO POR AMBIENTE'!$G$11:$G$262) | F25: E17
... A27: 03.01.01.14 | B27: E19 | C27: REFRIGERADORA DE 315 LITROS | D27: und | E27: =SUMIF('METRADO POR AMBIENTE'!$H$11:$H$262,F27,'METRADO POR AMBIENTE'!$G$11:$G$262) | F27: E19
A28: 03.01.02 | C28: MOBILIARIO
A29: 03.01.02.01 | B29: M3 | C29: SILLA REGULABLE DE ESTUDIANTE DE MADERA Y METAL 0.30 x 0.27 x 0.32 m | D29: und | E29: =SUMIF('METRADO POR AMBIENTE'!$H$11:$H$262,F29,'METRADO POR AMBIENTE'!$G$11:$G$262) | F29: M3
A30: 03.01.02.02 | B30: M4 | C30: MESA REGULABLE DE MADERA Y METAL 0.56 x 0.50 x 0.60 m | D30: und | E30: =SUMIF('METRADO POR AMBIENTE'!$H$11:$H$262,F30,'METRADO POR AMBIENTE'!$G$11:$G$262) | F30: M4
A31: 03.01.02.03 | B31: M7 | C31: SILLA DEL PROFESOR DE MADERA, MELAMINA Y METAL 0.45 x 0.40 x 0.36 m | D31: und | E31: =SUMIF('METRADO POR AMBIENTE'!$H$11:$H$262,F31,'METRADO POR AMBIENTE'!$G$11:$G$262) | F31: M7
A32: 03.01.02.04 | B32: M8 | C32: MESA PARA EL PROFESOR DE MADERA Y METAL 1.00 x 0.50 x 0.75 m | D32: und | E32: =SUMIF('METRADO POR AMBIENTE'!$H$11:$H$262,F32,'METRADO POR AMBIENTE'!$G$11:$G$262) | F32: M8
A33: 03.01.02.05 | B33: M9 | C33: MANIQUÍ DE COSTURA PARA CONFECCIÓN TEXTIL | D33: und | E33: =SUMIF('METRADO POR AMBIENTE'!$H$11:$H$262,F33,'METRADO POR AMBIENTE'!$G$11:$G$262) | F33: M9
A34: 03.01.02.06 | B34: M13 | C34: RACK DE SOPORTE METÁLICO PARA PROYECTOR EN TECHO | D34: und | E34: =SUMIF('METRADO POR AMBIENTE'!$H$11:$H$262,F34,'METRADO POR AMBIENTE'!$G$11:$G$262) | F34: M13
A35: 03.01.02.07 | B35: M15 | C35: ATRIL DE MESA PARA DIBUJO Y PINTURA | D35: und | E35: =SUMIF('METRADO POR AMBIENTE'!$H$11:$H$262,F35,'METRADO POR AMBIENTE'!$G$11:$G$262) | F35: M15
A36: 03.01.02.08 | B36: M16 | C36: MESA DE TRABAJO DE MADERA PARA ESTUDIANTES 0.90 x 1.80 x 0.56 m | D36: und | E36: =SUMIF('METRADO POR AMBIENTE'!$H$11:$H$262,F36,'METRADO POR AMBIENTE'!$G$11:$G$262) | F36: M16
A37: 03.01.02.09 | B37: M16 | C37: MESA DE CORTE TEXTIL 0.80 x 1.50 x 0.75 m | D37: und | E37: =SUMIF('METRADO POR AMBIENTE'!$H$11:$H$262,F37,'METRADO POR AMBIENTE'!$G$11:$G$262) | F37: M16-T
A38: 03.01.02.10 | B38: M19 | C38: MESA DE MADERA 1.00 x 1.80 x 0.75 m | D38: und | E38: =SUMIF('METRADO POR AMBIENTE'!$H$11:$H$262,F38,'METRADO POR AMBIENTE'!$G$11:$G$262) | F38: M19
A39: 03.01.02.11 | B39: M20 | C39: BIOMBO METÁLICO DE 3 CUERPOS | D39: und | E39: =SUMIF('METRADO POR AMBIENTE'!$H$11:$H$262,F39,'METRADO POR AMBIENTE'!$G$11:$G$262) | F39: M20
A40: 03.01.02.12 | B40: M21 | C40: MESA DE REUNIONES DE MADERA Y MELAMINA 2.40 x 1.00 x 0.75 m | D40: und | E40: =SUMIF('METRADO POR AMBIENTE'!$H$11:$H$262,F40,'METRADO POR AMBIENTE'!$G$11:$G$262) | F40: M21
... A75: 03.01.02.47 | B75: M79 | C75: CAMA CUNA DE UNA PLAZA, INCLUYE COLCHÓN | D75: und | E75: =SUMIF('METRADO POR AMBIENTE'!$H$11:$H$262,F75,'METRADO POR AMBIENTE'!$G$11:$G$262) | F75: M79
A76: 03.01.03 | C76: IMPLEMENTOS
...

Sheet METRADO POR AMBIENTE
A1: METRADO DE EQUIPAMIENTO Y MOBILIARIO POR AMBIENTE (LÁMINAS EM-01 A EM-07)
A2: PROYECTO | B2: “CREACIÓN DEL SERVICIO DE PROTECCIÓN A MUJERES VÍCTIMAS DE VIOLENCIA EN SITUACIÓN DE RIESGO DE FEMINICIDIO O PELIGRE SU INTEGRIDAD Y/O SALUD FÍSICA Y/O MENTAL EN HOGAR DE REFUGIO TEMPORAL DISTRITO DE MORALES DE LA PROVINCIA DE SAN MARTÍN DEL DEPARTAMENTO DE SAN MARTÍN”
A3: CUI | B3: N.° 2675514
A4: PROPIETARIO | B4: Gobierno Regional San Martín - Gerencia Territorial Bajo Mayo
A5: UBICACIÓN | B5: Morales / San Martín / San Martín
A6: ESPECIALIDAD | B6: ARQUITECTURA - EQUIPAMIENTO Y MOBILIARIO
A7: LÁMINAS | B7: EM-01 a EM-07 (equipamiento y mobiliario, escala 1/50)
A8: FECHA | B8: SETIEMBRE 2026
A10: EDIF. | B10: AMBIENTE | C10: LÁMINA | D10: CÓD. | E10: DESCRIPCIÓN | F10: UND | G10: CANTIDAD | H10: CLAVE
A11: E-01 Administración - SALA DE ESPERA Y SALA DE VISITA
A12: E-01 | B12: SALA DE ESPERA Y SALA DE VISITA | C12: EM-01 | D12: E4 | E12: RELOJ PARA ADOSAR A PARED | F12: und | G12: 2 | H12: E4
A13: E-01 | B13: SALA DE ESPERA Y SALA DE VISITA | C13: EM-01 | D13: M7 | E13: SILLA DEL PROFESOR DE MADERA, MELAMINA Y METAL 0.45 x 0.40 x 0.36 m | F13: und | G13: 9 | H13: M7
A14: E-01 | B14: SALA DE ESPERA Y SALA DE VISITA | C14: EM-01 | D14: M15 | E14: ATRIL DE MESA PARA DIBUJO Y PINTURA | F14: und | G14: 1 | H14: M15
A15: E-01 | B15: SALA DE ESPERA Y SALA DE VISITA | C15: EM-01 | D15: M32 | E15: SILLÓN PARA ACOPLAR 0.44 x 0.55 x 0.60 m | F15: und | G15: 3 | H15: M32
A16: E-01 | B16: SALA DE ESPERA Y SALA DE VISITA | C16: EM-01 | D16: M34 | E16: SOFÁ DE MADERA DE 2 CUERPOS 0.44 x 0.55 x 1.00 m | F16: und | G16: 2 | H16: M34
A17: E-01 | B17: SALA DE ESPERA Y SALA DE VISITA | C17: EM-01 | D17: M54 | E17: EXHIBIDOR DE LIBROS DE MELAMINA CON DIVISIONES ESCALONADAS 1.20 x 0.40 x 0.85 m | F17: und | G17: 1 | H17: M54
A18: E-01 | B18: SALA DE ESPERA Y SALA DE VISITA | C18: EM-01 | D18: M57 | E18: MUEBLE BAJO DE MELAMINA CON DOS PUERTAS Y DOS DIVISIONES HORIZONTALES 0.60 x 1.20 x 1.00 m | F18: und | G18: 1 | H18: M57
A19: E-01 | B19: SALA DE ESPERA Y SALA DE VISITA | C19: EM-01 | D19: M63 | E19: SOFÁ DE 3 CUERPOS 0.55 x 1.50 x 0.44 m | F19: und | G19: 2 | H19: M63
A20: E-01 | B20: SALA DE ESPERA Y SALA DE VISITA | C20: EM-01 | D20: M62 | E20: CESTO BOTA PAPELES DE ACERO CON PEDAL | F20: und | G20: 2 | H20: M62
A21: E-01 | B21: SALA DE ESPERA Y SALA DE VISITA | C21: EM-01 | D21: K20 | E21: COJINES | F21: und | G21: 4 | H21: K:E-01:SALA DE ESPERA Y SALA DE VISITA:K20
A22: E-01 | B22: SALA DE ESPERA Y SALA DE VISITA | C22: EM-01 | D22: K78 | E22: PISO ENCASTRABLE DE GOMA 25 mm | F22: und | G22: 3 | H22: K:E-01:SALA DE ESPERA Y SALA DE VISITA:K78
A23: E-01 Administración - ASISTENCIA SOCIAL
A24: E-01 | B24: ASISTENCIA SOCIAL | C24: EM-01 | D24: E4 | E24: RELOJ PARA ADOSAR A PARED | F24: und | G24: 1 | H24: E4
A25: E-01 | B25: ASISTENCIA SOCIAL | C25: EM-01 | D25: E6 | E25: COMPUTADORA i5 ESTACIONARIA | F25: und | G25: 3 | H25: E6
A26: E-01 | B26: ASISTENCIA SOCIAL | C26: EM-01 | D26: E9 | E26: IMPRESORA MULTIFUNCIONAL | F26: und | G26: 1 | H26: E9
A27: E-01 | B27: ASISTENCIA SOCIAL | C27: EM-01 | D27: M7 | E27: SILLA DEL PROFESOR DE MADERA, MELAMINA Y METAL 0.45 x 0.40 x 0.36 m | F27: und | G27: 6 | H27: M7
A28: E-01 | B28: ASISTENCIA SOCIAL | C28: EM-01 | D28: M31 | E28: ESCRITORIO DE MELAMINA CON CREDENZA MÓVIL 1.50 x 0.80 x 0.75 m | F28: und | G28: 3 | H28: M31
A29: E-01 | B29: ASISTENCIA SOCIAL | C29: EM-01 | D29: M36 | E29: ARMARIO DE MELAMINA CON 2 PUERTAS Y 4 NIVELES 0.90 x 0.45 x 1.80 m | F29: und | G29: 6 | H29: M36
A30: E-01 | B30: ASISTENCIA SOCIAL | C30: EM-01 | D30: M39 | E30: ARCHIVADOR DE MELAMINA CON TRES GAVETAS 0.60 x 0.46 x 1.20 m | F30: und | G30: 1 | H30: M39
A31: E-01 | B31: ASISTENCIA SOCIAL | C31: EM-01 | D31: M63 | E31: SOFÁ DE 3 CUERPOS 0.55 x 1.50 x 0.44 m | F31: und | G31: 2 | H31: M63
A32: E-01 | B32: ASISTENCIA SOCIAL | C32: EM-01 | D32: M62 | E32: CESTO BOTA PAPELES DE ACERO CON PEDAL | F32: und | G32: 1 | H32: M62
A33: E-01 Administración - PSICOLOGÍA, ÁREA LEGAL, OFICINA DE MONITOREO Y ADMINISTRACIÓN
A34: E-01 | B34: PSICOLOGÍA, ÁREA LEGAL, OFICINA DE MONITOREO Y ADMINISTRACIÓN | C34: EM-01 | D34: E4 | E34: RELOJ PARA ADOSAR A PARED | F34: und | G34: 4 | H34: E4
A35: E-01 | B35: PSICOLOGÍA, ÁREA LEGAL, OFICINA DE MONITOREO Y ADMINISTRACIÓN | C35: EM-01 | D35: E6 | E35: COMPUTADORA i5 ESTACIONARIA | F35: und | G35: 5 | H35: E6
A36: E-01 | B36: PSICOLOGÍA, ÁREA LEGAL, OFICINA DE MONITOREO Y ADMINISTRACIÓN | C36: EM-01 | D36: E9 | E36: IMPRESORA MULTIFUNCIONAL | F36: und | G36: 3 | H36: E9
A37: E-01 | B37: PSICOLOGÍA, ÁREA LEGAL, OFICINA DE MONITOREO Y ADMINISTRACIÓN | C37: EM-01 | D37: M7 | E37: SILLA DEL PROFESOR DE MADERA, MELAMINA Y METAL 0.45 x 0.40 x 0.36 m | F37: und | G37: 15 | H37: M7
A38: E-01 | B38: PSICOLOGÍA, ÁREA LEGAL, OFICINA DE MONITOREO Y ADMINISTRACIÓN | C38: EM-01 | D38: M31 | E38: ESCRITORIO DE MELAMINA CON CREDENZA MÓVIL 1.50 x 0.80 x 0.75 m | F38: und | G38: 5 | H38: M31
A39: E-01 | B39: PSICOLOGÍA, ÁREA LEGAL, OFICINA DE MONITOREO Y ADMINISTRACIÓN | C39: EM-01 | D39: M36 | E39: ARMARIO DE MELAMINA CON 2 PUERTAS Y 4 NIVELES 0.90 x 0.45 x 1.80 m | F39: und | G39: 10 | H39: M36
A40: E-01 | B40: PSICOLOGÍA, ÁREA LEGAL, OFICINA DE MONITOREO Y ADMINISTRACIÓN | C40: EM-01 | D40: M63 | E40: SOFÁ DE 3 CUERPOS 0.55 x 1.50 x 0.44 m | F40: und | G40: 3 | H40: M63
A41: E-01 | B41: PSICOLOGÍA, ÁREA LEGAL, OFICINA DE MONITOREO Y ADMINISTRACIÓN | C41: EM-01 | D41: M62 | E41: CESTO BOTA PAPELES DE ACERO CON PEDAL | F41: und | G41: 5 | H41: M62
...

Sheet POR EDIFICACIÓN
A1: EQUIPOS Y MOBILIARIO POR EDIFICACIÓN (UNIDADES)
A2: PROYECTO | B2: “CREACIÓN DEL SERVICIO DE PROTECCIÓN A MUJERES VÍCTIMAS DE VIOLENCIA EN SITUACIÓN DE RIESGO DE FEMINICIDIO O PELIGRE SU INTEGRIDAD Y/O SALUD FÍSICA Y/O MENTAL EN HOGAR DE REFUGIO TEMPORAL DISTRITO DE MORALES DE LA PROVINCIA DE SAN MARTÍN DEL DEPARTAMENTO DE SAN MARTÍN”
A3: CUI | B3: N.° 2675514
A4: PROPIETARIO | B4: Gobierno Regional San Martín - Gerencia Territorial Bajo Mayo
A5: UBICACIÓN | B5: Morales / San Martín / San Martín
A6: ESPECIALIDAD | B6: ARQUITECTURA - EQUIPAMIENTO Y MOBILIARIO
A7: LÁMINAS | B7: EM-01 a EM-07 (equipamiento y mobiliario, escala 1/50)
A8: FECHA | B8: SETIEMBRE 2026
A10: CÓD. | B10: DESCRIPCIÓN | C10: E-01 | D10: E-02 | E10: E-03 | F10: E-04 | G10: E-05 | H10: E-06 | I10: E-07 | J10: E-08 | K10: E-09 | L10: TOTAL | M10: CLAVE
A11: E1 | B11: PROYECTOR INTERACTIVO | C11: =SUMIFS('METRADO POR AMBIENTE'!$G$11:$G$262,'METRADO POR AMBIENTE'!$H$11:$H$262,$M11,'METRADO POR AMBIENTE'!$A$11:$A$262,C$10) | D11: =SUMIFS('METRADO POR AMBIENTE'!$G$11:$G$262,'METRADO POR AMBIENTE'!$H$11:$H$262,$M11,'METRADO POR AMBIENTE'!$A$11:$A$262,D$10) | E11: =SUMIFS('METRADO POR AMBIENTE'!$G$11:$G$262,'METRADO POR AMBIENTE'!$H$11:$H$262,$M11,'METRADO POR AMBIENTE'!$A$11:$A$262,E$10) | F11: =SUMIFS('METRADO POR AMBIENTE'!$G$11:$G$262,'METRADO POR AMBIENTE'!$H$11:$H$262,$M11,'METRADO POR AMBIENTE'!$A$11:$A$262,F$10) | G11: =SUMIFS('METRADO POR AMBIENTE'!$G$11:$G$262,'METRADO POR AMBIENTE'!$H$11:$H$262,$M11,'METRADO POR AMBIENTE'!$A$11:$A$262,G$10) | H11: =SUMIFS('METRADO POR AMBIENTE'!$G$11:$G$262,'METRADO POR AMBIENTE'!$H$11:$H$262,$M11,'METRADO POR AMBIENTE'!$A$11:$A$262,H$10) | I11: =SUMIFS('METRADO POR AMBIENTE'!$G$11:$G$262,'METRADO POR AMBIENTE'!$H$11:$H$262,$M11,'METRADO POR AMBIENTE'!$A$11:$A$262,I$10) | J11: =SUMIFS('METRADO POR AMBIENTE'!$G$11:$G$262,'METRADO POR AMBIENTE'!$H$11:$H$262,$M11,'METRADO POR AMBIENTE'!$A$11:$A$262,J$10) | K11: =SUMIFS('METRADO POR AMBIENTE'!$G$11:$G$262,'METRADO POR AMBIENTE'!$H$11:$H$262,$M11,'METRADO POR AMBIENTE'!$A$11:$A$262,K$10) | L11: =SUM(C11:K11) | M11: E1
A12: E2 | B12: COMPUTADORA PORTÁTIL i5 | C12: =SUMIFS('METRADO POR AMBIENTE'!$G$11:$G$262,'METRADO POR AMBIENTE'!$H$11:$H$262,$M12,'METRADO POR AMBIENTE'!$A$11:$A$262,C$10) | D12: =SUMIFS('METRADO POR AMBIENTE'!$G$11:$G$262,'METRADO POR AMBIENTE'!$H$11:$H$262,$M12,'METRADO POR AMBIENTE'!$A$11:$A$262,D$10) | E12: =SUMIFS('METRADO POR AMBIENTE'!$G$11:$G$262,'METRADO POR AMBIENTE'!$H$11:$H$262,$M12,'METRADO POR AMBIENTE'!$A$11:$A$262,E$10) | F12: =SUMIFS('METRADO POR AMBIENTE'!$G$11:$G$262,'METRADO POR AMBIENTE'!$H$11:$H$262,$M12,'METRADO POR AMBIENTE'!$A$11:$A$262,F$10) | G12: =SUMIFS('METRADO POR AMBIENTE'!$G$11:$G$262,'METRADO POR AMBIENTE'!$H$11:$H$262,$M12,'METRADO POR AMBIENTE'!$A$11:$A$262,G$10) | H12: =SUMIFS('METRADO POR AMBIENTE'!$G$11:$G$262,'METRADO POR AMBIENTE'!$H$11:$H$262,$M12,'METRADO POR AMBIENTE'!$A$11:$A$262,H$10) | I12: =SUMIFS('METRADO POR AMBIENTE'!$G$11:$G$262,'METRADO POR AMBIENTE'!$H$11:$H$262,$M12,'METRADO POR AMBIENTE'!$A$11:$A$262,I$10) | J12: =SUMIFS('METRADO POR AMBIENTE'!$G$11:$G$262,'METRADO POR AMBIENTE'!$H$11:$H$262,$M12,'METRADO POR AMBIENTE'!$A$11:$A$262,J$10) | K12: =SUMIFS('METRADO POR AMBIENTE'!$G$11:$G$262,'METRADO POR AMBIENTE'!$H$11:$H$262,$M12,'METRADO POR AMBIENTE'!$A$11:$A$262,K$10) | L12: =SUM(C12:K12) | M12: E2
A13: E3 | B13: PRESENTADOR INALÁMBRICO CON PUNTERO LÁSER | C13: =SUMIFS('METRADO POR AMBIENTE'!$G$11:$G$262,'METRADO POR AMBIENTE'!$H$11:$H$262,$M13,'METRADO POR AMBIENTE'!$A$11:$A$262,C$10) | D13: =SUMIFS('METRADO POR AMBIENTE'!$G$11:$G$262,'METRADO POR AMBIENTE'!$H$11:$H$262,$M13,'METRADO POR AMBIENTE'!$A$11:$A$262,D$10) | E13: =SUMIFS('METRADO POR AMBIENTE'!$G$11:$G$262,'METRADO POR AMBIENTE'!$H$11:$H$262,$M13,'METRADO POR AMBIENTE'!$A$11:$A$262,E$10) | F13: =SUMIFS('METRADO POR AMBIENTE'!$G$11:$G$262,'METRADO POR AMBIENTE'!$H$11:$H$262,$M13,'METRADO POR AMBIENTE'!$A$11:$A$262,F$10) | G13: =SUMIFS('METRADO POR AMBIENTE'!$G$11:$G$262,'METRADO POR AMBIENTE'!$H$11:$H$262,$M13,'METRADO POR AMBIENTE'!$A$11:$A$262,G$10) | H13: =SUMIFS('METRADO POR AMBIENTE'!$G$11:$G$262,'METRADO POR AMBIENTE'!$H$11:$H$262,$M13,'METRADO POR AMBIENTE'!$A$11:$A$262,H$10) | I13: =SUMIFS('METRADO POR AMBIENTE'!$G$11:$G$262,'METRADO POR AMBIENTE'!$H$11:$H$262,$M13,'METRADO POR AMBIENTE'!$A$11:$A$262,I$10) | J13: =SUMIFS('METRADO POR AMBIENTE'!$G$11:$G$262,'METRADO POR AMBIENTE'!$H$11:$H$262,$M13,'METRADO POR AMBIENTE'!$A$11:$A$262,J$10) | K13: =SUMIFS('METRADO POR AMBIENTE'!$G$11:$G$262,'METRADO POR AMBIENTE'!$H$11:$H$262,$M13,'METRADO POR AMBIENTE'!$A$11:$A$262,K$10) | L13: =SUM(C13:K13) | M13: E3
A14: E4 | B14: RELOJ PARA ADOSAR A PARED | C14: =SUMIFS('METRADO POR AMBIENTE'!$G$11:$G$262,'METRADO POR AMBIENTE'!$H$11:$H$262,$M14,'METRADO POR AMBIENTE'!$A$11:$A$262,C$10) | D14: =SUMIFS('METRADO POR AMBIENTE'!$G$11:$G$262,'METRADO POR AMBIENTE'!$H$11:$H$262,$M14,'METRADO POR AMBIENTE'!$A$11:$A$262,D$10) | E14: =SUMIFS('METRADO POR AMBIENTE'!$G$11:$G$262,'METRADO POR AMBIENTE'!$H$11:$H$262,$M14,'METRADO POR AMBIENTE'!$A$11:$A$262,E$10) | F14: =SUMIFS('METRADO POR AMBIENTE'!$G$11:$G$262,'METRADO POR AMBIENTE'!$H$11:$H$262,$M14,'METRADO POR AMBIENTE'!$A$11:$A$262,F$10) | G14: =SUMIFS('METRADO POR AMBIENTE'!$G$11:$G$262,'METRADO POR AMBIENTE'!$H$11:$H$262,$M14,'METRADO POR AMBIENTE'!$A$11:$A$262,G$10) | H14: =SUMIFS('METRADO POR AMBIENTE'!$G$11:$G$262,'METRADO POR AMBIENTE'!$H$11:$H$262,$M14,'METRADO POR AMBIENTE'!$A$11:$A$262,H$10) | I14: =SUMIFS('METRADO POR AMBIENTE'!$G$11:$G$262,'METRADO POR AMBIENTE'!$H$11:$H$262,$M14,'METRADO POR AMBIENTE'!$A$11:$A$262,I$10) | J14: =SUMIFS('METRADO POR AMBIENTE'!$G$11:$G$262,'METRADO POR AMBIENTE'!$H$11:$H$262,$M14,'METRADO POR AMBIENTE'!$A$11:$A$262,J$10) | K14: =SUMIFS('METRADO POR AMBIENTE'!$G$11:$G$262,'METRADO POR AMBIENTE'!$H$11:$H$262,$M14,'METRADO POR AMBIENTE'!$A$11:$A$262,K$10) | L14: =SUM(C14:K14) | M14: E4
A15: E5 | B15: LAVADORA DE 20 kg DE CARGA SUPERIOR | C15: =SUMIFS('METRADO POR AMBIENTE'!$G$11:$G$262,'METRADO POR AMBIENTE'!$H$11:$H$262,$M15,'METRADO POR AMBIENTE'!$A$11:$A$262,C$10) | D15: =SUMIFS('METRADO POR AMBIENTE'!$G$11:$G$262,'METRADO POR AMBIENTE'!$H$11:$H$262,$M15,'METRADO POR AMBIENTE'!$A$11:$A$262,D$10) | E15: =SUMIFS('METRADO POR AMBIENTE'!$G$11:$G$262,'METRADO POR AMBIENTE'!$H$11:$H$262,$M15,'METRADO POR AMBIENTE'!$A$11:$A$262,E$10) | F15: =SUMIFS('METRADO POR AMBIENTE'!$G$11:$G$262,'METRADO POR AMBIENTE'!$H$11:$H$262,$M15,'METRADO POR AMBIENTE'!$A$11:$A$262,F$10) | G15: =SUMIFS('METRADO POR AMBIENTE'!$G$11:$G$262,'METRADO POR AMBIENTE'!$H$11:$H$262,$M15,'METRADO POR AMBIENTE'!$A$11:$A$262,G$10) | H15: =SUMIFS('METRADO POR AMBIENTE'!$G$11:$G$262,'METRADO POR AMBIENTE'!$H$11:$H$262,$M15,'METRADO POR AMBIENTE'!$A$11:$A$262,H$10) | I15: =SUMIFS('METRADO POR AMBIENTE'!$G$11:$G$262,'METRADO POR AMBIENTE'!$H$11:$H$262,$M15,'METRADO POR AMBIENTE'!$A$11:$A$262,I$10) | J15: =SUMIFS('METRADO POR AMBIENTE'!$G$11:$G$262,'METRADO POR AMBIENTE'!$H$11:$H$262,$M15,'METRADO POR AMBIENTE'!$A$11:$A$262,J$10) | K15: =SUMIFS('METRADO POR AMBIENTE'!$G$11:$G$262,'METRADO POR AMBIENTE'!$H$11:$H$262,$M15,'METRADO POR AMBIENTE'!$A$11:$A$262,K$10) | L15: =SUM(C15:K15) | M15: E5
A16: E6 | B16: COMPUTADORA i5 ESTACIONARIA | C16: =SUMIFS('METRADO POR AMBIENTE'!$G$11:$G$262,'METRADO POR AMBIENTE'!$H$11:$H$262,$M16,'METRADO POR AMBIENTE'!$A$11:$A$262,C$10) | D16: =SUMIFS('METRADO POR AMBIENTE'!$G$11:$G$262,'METRADO POR AMBIENTE'!$H$11:$H$262,$M16,'METRADO POR AMBIENTE'!$A$11:$A$262,D$10) | E16: =SUMIFS('METRADO POR AMBIENTE'!$G$11:$G$262,'METRADO POR AMBIENTE'!$H$11:$H$262,$M16,'METRADO POR AMBIENTE'!$A$11:$A$262,E$10) | F16: =SUMIFS('METRADO POR AMBIENTE'!$G$11:$G$262,'METRADO POR AMBIENTE'!$H$11:$H$262,$M16,'METRADO POR AMBIENTE'!$A$11:$A$262,F$10) | G16: =SUMIFS('METRADO POR AMBIENTE'!$G$11:$G$262,'METRADO POR AMBIENTE'!$H$11:$H$262,$M16,'METRADO POR AMBIENTE'!$A$11:$A$262,G$10) | H16: =SUMIFS('METRADO POR AMBIENTE'!$G$11:$G$262,'METRADO POR AMBIENTE'!$H$11:$H$262,$M16,'METRADO POR AMBIENTE'!$A$11:$A$262,H$10) | I16: =SUMIFS('METRADO POR AMBIENTE'!$G$11:$G$262,'METRADO POR AMBIENTE'!$H$11:$H$262,$M16,'METRADO POR AMBIENTE'!$A$11:$A$262,I$10) | J16: =SUMIFS('METRADO POR AMBIENTE'!$G$11:$G$262,'METRADO POR AMBIENTE'!$H$11:$H$262,$M16,'METRADO POR AMBIENTE'!$A$11:$A$262,J$10) | K16: =SUMIFS('METRADO POR AMBIENTE'!$G$11:$G$262,'METRADO POR AMBIENTE'!$H$11:$H$262,$M16,'METRADO POR AMBIENTE'!$A$11:$A$262,K$10) | L16: =SUM(C16:K16) | M16: E6
A17: E7 | B17: PROYECTOR MULTIMEDIA | C17: =SUMIFS('METRADO POR AMBIENTE'!$G$11:$G$262,'METRADO POR AMBIENTE'!$H$11:$H$262,$M17,'METRADO POR AMBIENTE'!$A$11:$A$262,C$10) | D17: =SUMIFS('METRADO POR AMBIENTE'!$G$11:$G$262,'METRADO POR AMBIENTE'!$H$11:$H$262,$M17,'METRADO POR AMBIENTE'!$A$11:$A$262,D$10) | E17: =SUMIFS('METRADO POR AMBIENTE'!$G$11:$G$262,'METRADO POR AMBIENTE'!$H$11:$H$262,$M17,'METRADO POR AMBIENTE'!$A$11:$A$262,E$10) | F17: =SUMIFS('METRADO POR AMBIENTE'!$G$11:$G$262,'METRADO POR AMBIENTE'!$H$11:$H$262,$M17,'METRADO POR AMBIENTE'!$A$11:$A$262,F$10) | G17: =SUMIFS('METRADO POR AMBIENTE'!$G$11:$G$262,'METRADO POR AMBIENTE'!$H$11:$H$262,$M17,'METRADO POR AMBIENTE'!$A$11:$A$262,G$10) | H17: =SUMIFS('METRADO POR AMBIENTE'!$G$11:$G$262,'METRADO POR AMBIENTE'!$H$11:$H$262,$M17,'METRADO POR AMBIENTE'!$A$11:$A$262,H$10) | I17: =SUMIFS('METRADO POR AMBIENTE'!$G$11:$G$262,'METRADO POR AMBIENTE'!$H$11:$H$262,$M17,'METRADO POR AMBIENTE'!$A$11:$A$262,I$10) | J17: =SUMIFS('METRADO POR AMBIENTE'!$G$11:$G$262,'METRADO POR AMBIENTE'!$H$11:$H$262,$M17,'METRADO POR AMBIENTE'!$A$11:$A$262,J$10) | K17: =SUMIFS('METRADO POR AMBIENTE'!$G$11:$G$262,'METRADO POR AMBIENTE'!$H$11:$H$262,$M17,'METRADO POR AMBIENTE'!$A$11:$A$262,K$10) | L17: =SUM(C17:K17) | M17: E7
A18: E9 | B18: IMPRESORA MULTIFUNCIONAL | C18: =SUMIFS('METRADO POR AMBIENTE'!$G$11:$G$262,'METRADO POR AMBIENTE'!$H$11:$H$262,$M18,'METRADO POR AMBIENTE'!$A$11:$A$262,C$10) | D18: =SUMIFS('METRADO POR AMBIENTE'!$G$11:$G$262,'METRADO POR AMBIENTE'!$H$11:$H$262,$M18,'METRADO POR AMBIENTE'!$A$11:$A$262,D$10) | E18: =SUMIFS('METRADO POR AMBIENTE'!$G$11:$G$262,'METRADO POR AMBIENTE'!$H$11:$H$262,$M18,'METRADO POR AMBIENTE'!$A$11:$A$262,E$10) | F18: =SUMIFS('METRADO POR AMBIENTE'!$G$11:$G$262,'METRADO POR AMBIENTE'!$H$11:$H$262,$M18,'METRADO POR AMBIENTE'!$A$11:$A$262,F$10) | G18: =SUMIFS('METRADO POR AMBIENTE'!$G$11:$G$262,'METRADO POR AMBIENTE'!$H$11:$H$262,$M18,'METRADO POR AMBIENTE'!$A$11:$A$262,G$10) | H18: =SUMIFS('METRADO POR AMBIENTE'!$G$11:$G$262,'METRADO POR AMBIENTE'!$H$11:$H$262,$M18,'METRADO POR AMBIENTE'!$A$11:$A$262,H$10) | I18: =SUMIFS('METRADO POR AMBIENTE'!$G$11:$G$262,'METRADO POR AMBIENTE'!$H$11:$H$262,$M18,'METRADO POR AMBIENTE'!$A$11:$A$262,I$10) | J18: =SUMIFS('METRADO POR AMBIENTE'!$G$11:$G$262,'METRADO POR AMBIENTE'!$H$11:$H$262,$M18,'METRADO POR AMBIENTE'!$A$11:$A$262,J$10) | K18: =SUMIFS('METRADO POR AMBIENTE'!$G$11:$G$262,'METRADO POR AMBIENTE'!$H$11:$H$262,$M18,'METRADO POR AMBIENTE'!$A$11:$A$262,K$10) | L18: =SUM(C18:K18) | M18: E9
A19: E10 | B19: MÁQUINA DE CORTE TEXTIL | C19: =SUMIFS('METRADO POR AMBIENTE'!$G$11:$G$262,'METRADO POR AMBIENTE'!$H$11:$H$262,$M19,'METRADO POR AMBIENTE'!$A$11:$A$262,C$10) | D19: =SUMIFS('METRADO POR AMBIENTE'!$G$11:$G$262,'METRADO POR AMBIENTE'!$H$11:$H$262,$M19,'METRADO POR AMBIENTE'!$A$11:$A$262,D$10) | E19: =SUMIFS('METRADO POR AMBIENTE'!$G$11:$G$262,'METRADO POR AMBIENTE'!$H$11:$H$262,$M19,'METRADO POR AMBIENTE'!$A$11:$A$262,E$10) | F19: =SUMIFS('METRADO POR AMBIENTE'!$G$11:$G$262,'METRADO POR AMBIENTE'!$H$11:$H$262,$M19,'METRADO POR AMBIENTE'!$A$11:$A$262,F$10) | G19: =SUMIFS('METRADO POR AMBIENTE'!$G$11:$G$262,'METRADO POR AMBIENTE'!$H$11:$H$262,$M19,'METRADO POR AMBIENTE'!$A$11:$A$262,G$10) | H19: =SUMIFS('METRADO POR AMBIENTE'!$G$11:$G$262,'METRADO POR AMBIENTE'!$H$11:$H$262,$M19,'METRADO POR AMBIENTE'!$A$11:$A$262,H$10) | I19: =SUMIFS('METRADO POR AMBIENTE'!$G$11:$G$262,'METRADO POR AMBIENTE'!$H$11:$H$262,$M19,'METRADO POR AMBIENTE'!$A$11:$A$262,I$10) | J19: =SUMIFS('METRADO POR AMBIENTE'!$G$11:$G$262,'METRADO POR AMBIENTE'!$H$11:$H$262,$M19,'METRADO POR AMBIENTE'!$A$11:$A$262,J$10) | K19: =SUMIFS('METRADO POR AMBIENTE'!$G$11:$G$262,'METRADO POR AMBIENTE'!$H$11:$H$262,$M19,'METRADO POR AMBIENTE'!$A$11:$A$262,K$10) | L19: =SUM(C19:K19) | M19: E10
A20: E13 | B20: COCINA INDUSTRIAL DE 2 HORNILLAS | C20: =SUMIFS('METRADO POR AMBIENTE'!$G$11:$G$262,'METRADO POR AMBIENTE'!$H$11:$H$262,$M20,'METRADO POR AMBIENTE'!$A$11:$A$262,C$10) | D20: =SUMIFS('METRADO POR AMBIENTE'!$G$11:$G$262,'METRADO POR AMBIENTE'!$H$11:$H$262,$M20,'METRADO POR AMBIENTE'!$A$11:$A$262,D$10) | E20: =SUMIFS('METRADO POR AMBIENTE'!$G$11:$G$262,'METRADO POR AMBIENTE'!$H$11:$H$262,$M20,'METRADO POR AMBIENTE'!$A$11:$A$262,E$10) | F20: =SUMIFS('METRADO POR AMBIENTE'!$G$11:$G$262,'METRADO POR AMBIENTE'!$H$11:$H$262,$M20,'METRADO POR AMBIENTE'!$A$11:$A$262,F$10) | G20: =SUMIFS('METRADO POR AMBIENTE'!$G$11:$G$262,'METRADO POR AMBIENTE'!$H$11:$H$262,$M20,'METRADO POR AMBIENTE'!$A$11:$A$262,G$10) | H20: =SUMIFS('METRADO POR AMBIENTE'!$G$11:$G$262,'METRADO POR AMBIENTE'!$H$11:$H$262,$M20,'METRADO POR AMBIENTE'!$A$11:$A$262,H$10) | I20: =SUMIFS('METRADO POR AMBIENTE'!$G$11:$G$262,'METRADO POR AMBIENTE'!$H$11:$H$262,$M20,'METRADO POR AMBIENTE'!$A$11:$A$262,I$10) | J20: =SUMIFS('METRADO POR AMBIENTE'!$G$11:$G$262,'METRADO POR AMBIENTE'!$H$11:$H$262,$M20,'METRADO POR AMBIENTE'!$A$11:$A$262,J$10) | K20: =SUMIFS('METRADO POR AMBIENTE'!$G$11:$G$262,'METRADO POR AMBIENTE'!$H$11:$H$262,$M20,'METRADO POR AMBIENTE'!$A$11:$A$262,K$10) | L20: =SUM(C20:K20) | M20: E13
A21: E16 | B21: HORNO MICROONDAS DE 31 LITROS | C21: =SUMIFS('METRADO POR AMBIENTE'!$G$11:$G$262,'METRADO POR AMBIENTE'!$H$11:$H$262,$M21,'METRADO POR AMBIENTE'!$A$11:$A$262,C$10) | D21: =SUMIFS('METRADO POR AMBIENTE'!$G$11:$G$262,'METRADO POR AMBIENTE'!$H$11:$H$262,$M21,'METRADO POR AMBIENTE'!$A$11:$A$262,D$10) | E21: =SUMIFS('METRADO POR AMBIENTE'!$G$11:$G$262,'METRADO POR AMBIENTE'!$H$11:$H$262,$M21,'METRADO POR AMBIENTE'!$A$11:$A$262,E$10) | F21: =SUMIFS('METRADO POR AMBIENTE'!$G$11:$G$262,'METRADO POR AMBIENTE'!$H$11:$H$262,$M21,'METRADO POR AMBIENTE'!$A$11:$A$262,F$10) | G21: =SUMIFS('METRADO POR AMBIENTE'!$G$11:$G$262,'METRADO POR AMBIENTE'!$H$11:$H$262,$M21,'METRADO POR AMBIENTE'!$A$11:$A$262,G$10) | H21: =SUMIFS('METRADO POR AMBIENTE'!$G$11:$G$262,'METRADO POR AMBIENTE'!$H$11:$H$262,$M21,'METRADO POR AMBIENTE'!$A$11:$A$262,H$10) | I21: =SUMIFS('METRADO POR AMBIENTE'!$G$11:$G$262,'METRADO POR AMBIENTE'!$H$11:$H$262,$M21,'METRADO POR AMBIENTE'!$A$11:$A$262,I$10) | J21: =SUMIFS('METRADO POR AMBIENTE'!$G$11:$G$262,'METRADO POR AMBIENTE'!$H$11:$H$262,$M21,'METRADO POR AMBIENTE'!$A$11:$A$262,J$10) | K21: =SUMIFS('METRADO POR AMBIENTE'!$G$11:$G$262,'METRADO POR AMBIENTE'!$H$11:$H$262,$M21,'METRADO POR AMBIENTE'!$A$11:$A$262,K$10) | L21: =SUM(C21:K21) | M21: E16
A22: E17 | B22: LICUADORA DE 1.5 LITROS | C22: =SUMIFS('METRADO POR AMBIENTE'!$G$11:$G$262,'METRADO POR AMBIENTE'!$H$11:$H$262,$M22,'METRADO POR AMBIENTE'!$A$11:$A$262,C$10) | D22: =SUMIFS('METRADO POR AMBIENTE'!$G$11:$G$262,'METRADO POR AMBIENTE'!$H$11:$H$262,$M22,'METRADO POR AMBIENTE'!$A$11:$A$262,D$10) | E22: =SUMIFS('METRADO POR AMBIENTE'!$G$11:$G$262,'METRADO POR AMBIENTE'!$H$11:$H$262,$M22,'METRADO POR AMBIENTE'!$A$11:$A$262,E$10) | F22: =SUMIFS('METRADO POR AMBIENTE'!$G$11:$G$262,'METRADO POR AMBIENTE'!$H$11:$H$262,$M22,'METRADO POR AMBIENTE'!$A$11:$A$262,F$10) | G22: =SUMIFS('METRADO POR AMBIENTE'!$G$11:$G$262,'METRADO POR AMBIENTE'!$H$11:$H$262,$M22,'METRADO POR AMBIENTE'!$A$11:$A$262,G$10) | H22: =SUMIFS('METRADO POR AMBIENTE'!$G$11:$G$262,'METRADO POR AMBIENTE'!$H$11:$H$262,$M22,'METRADO POR AMBIENTE'!$A$11:$A$262,H$10) | I22: =SUMIFS('METRADO POR AMBIENTE'!$G$11:$G$262,'METRADO POR AMBIENTE'!$H$11:$H$262,$M22,'METRADO POR AMBIENTE'!$A$11:$A$262,I$10) | J22: =SUMIFS('METRADO POR AMBIENTE'!$G$11:$G$262,'METRADO POR AMBIENTE'!$H$11:$H$262,$M22,'METRADO POR AMBIENTE'!$A$11:$A$262,J$10) | K22: =SUMIFS('METRADO POR AMBIENTE'!$G$11:$G$262,'METRADO POR AMBIENTE'!$H$11:$H$262,$M22,'METRADO POR AMBIENTE'!$A$11:$A$262,K$10) | L22: =SUM(C22:K22) | M22: E17
... A71: M79 | B71: CAMA CUNA DE UNA PLAZA, INCLUYE COLCHÓN | C71: =SUMIFS('METRADO POR AMBIENTE'!$G$11:$G$262,'METRADO POR AMBIENTE'!$H$11:$H$262,$M71,'METRADO POR AMBIENTE'!$A$11:$A$262,C$10) | D71: =SUMIFS('METRADO POR AMBIENTE'!$G$11:$G$262,'METRADO POR AMBIENTE'!$H$11:$H$262,$M71,'METRADO POR AMBIENTE'!$A$11:$A$262,D$10) | E71: =SUMIFS('METRADO POR AMBIENTE'!$G$11:$G$262,'METRADO POR AMBIENTE'!$H$11:$H$262,$M71,'METRADO POR AMBIENTE'!$A$11:$A$262,E$10) | F71: =SUMIFS('METRADO POR AMBIENTE'!$G$11:$G$262,'METRADO POR AMBIENTE'!$H$11:$H$262,$M71,'METRADO POR AMBIENTE'!$A$11:$A$262,F$10) | G71: =SUMIFS('METRADO POR AMBIENTE'!$G$11:$G$262,'METRADO POR AMBIENTE'!$H$11:$H$262,$M71,'METRADO POR AMBIENTE'!$A$11:$A$262,G$10) | H71: =SUMIFS('METRADO POR AMBIENTE'!$G$11:$G$262,'METRADO POR AMBIENTE'!$H$11:$H$262,$M71,'METRADO POR AMBIENTE'!$A$11:$A$262,H$10) | I71: =SUMIFS('METRADO POR AMBIENTE'!$G$11:$G$262,'METRADO POR AMBIENTE'!$H$11:$H$262,$M71,'METRADO POR AMBIENTE'!$A$11:$A$262,I$10) | J71: =SUMIFS('METRADO POR AMBIENTE'!$G$11:$G$262,'METRADO POR AMBIENTE'!$H$11:$H$262,$M71,'METRADO POR AMBIENTE'!$A$11:$A$262,J$10) | K71: =SUMIFS('METRADO POR AMBIENTE'!$G$11:$G$262,'METRADO POR AMBIENTE'!$H$11:$H$262,$M71,'METRADO POR AMBIENTE'!$A$11:$A$262,K$10) | L71: =SUM(C71:K71) | M71: M79
B72: TOTAL | C72: =SUM(C11:C71) | D72: =SUM(D11:D71) | E72: =SUM(E11:E71) | F72: =SUM(F11:F71) | G72: =SUM(G11:G71) | H72: =SUM(H11:H71) | I72: =SUM(I11:I71) | J72: =SUM(J11:J71) | ... L72: =SUM(L11:L71)
