Workbook

Sheet RESUMEN
A2: RESUMEN METRADOS DE DRENAJE PLUVIAL
A4: ENTIDAD | B4: GERENCIA TERRITORIAL BAJO MAYO - TARAPOTO
A5: PROYECTO | B5: “CREACIÓN DEL SERVICIO DE PROTECCIÓN A MUJERES VÍCTIMAS DE VIOLENCIA EN SITUACIÓN DE RIESGO DE FEMINICIDIO O PELIGRE SU INTEGRIDAD Y/O SALUD FÍSICA Y/O MENTAL EN HOGAR DE REFUGIO TEMPORAL DISTRITO DE MORALES DE LA PROVINCIA DE SAN MARTÍN DEL DEPARTAMENTO DE SAN MARTÍN”, con CUI N.° 2675514
A6: UBICACIÓN | B6: SAN MARTIN - SAN MARTIN - MORALES
A7: FECHA | B7: 46266
A8: Item | B8: Descripción | C8: Unid. | D8: Total.
A9: 01.04.03 | B9: SISTEMA DE DRENAJE PLUVIAL
A10: 01.04.03.01 | B10: TRABAJOS PRELIMINARES
A11: 01.04.03.01.01 | B11: LIMPIEZA MANUAL DE TERRENO | C11: m² | D11: =+'PLANILLA GENERAL DE METRADOS'!K11 -> 956.872
A12: 01.04.03.01.02 | B12: TRAZO, NIVELES Y REPLANTEO PRELIMINAR | C12: m² | D12: =+'PLANILLA GENERAL DE METRADOS'!K24 -> 956.872
A13: 01.04.03.02 | B13: MOVIMIENTO DE TIERRAS
A14: 01.04.03.02.01 | B14: EXCAVACIÓN MANUAL DE ZANJAS P/CUNETAS | C14: m³ | D14: =+'PLANILLA GENERAL DE METRADOS'!K38 -> 619.79764
A15: 01.04.03.02.02 | B15: EXCAVACIÓN MANUAL DE ZANJAS P/DADOS DE CONCRETO | C15: m³ | D15: =+'PLANILLA GENERAL DE METRADOS'!K51 -> 2.912
A16: 01.04.03.02.03 | B16: REFINE, NIVELACIÓN Y COMPACTACIÓN EN TERRENO NORMAL | C16: m² | D16: =+'PLANILLA GENERAL DE METRADOS'!K54 -> 410.088
A17: 01.04.03.02.04 | B17: RELLENO COMPACTADO C/MATERIAL PROPIO SELECCIONADO | C17: m³ | D17: =+'PLANILLA GENERAL DE METRADOS'!K67 -> 343.77408
A18: 01.04.03.02.05 | B18: ELIMINACIÓN DE MATERIAL EXCEDENTE D<1Km | C18: m³ | D18: =+'PLANILLA GENERAL DE METRADOS'!K80 -> 331.22827
A19: 01.04.03.03 | B19: OBRAS DE CONCRETO SIMPLE
A20: 01.04.03.03.01 | B20: CONCRETO f'c=100 kg/cm2 PARA SOLADO E=4'' | C20: m² | D20: =+'PLANILLA GENERAL DE METRADOS'!K84 -> 410.088
A21: 01.04.03.03.02 | B21: CONCRETO f'c=140 Kg/cm2 PARA DADOS DE CONCRETO | C21: m³ | D21: =+'PLANILLA GENERAL DE METRADOS'!K97 -> 2.912
A22: 01.04.03.04 | B22: OBRAS DE CONCRETO ARMADO
A23: 01.04.03.04.02 | B23: CUNETAS
A24: 01.04.03.04.02.01 | B24: CONCRETO f'c=175 kg/cm2 PARA CUNETAS | C24: m³ | D24: =+'PLANILLA GENERAL DE METRADOS'!K101 -> 122.6458
A25: 01.04.03.04.02.02 | B25: ENCOFRADO Y DESENCOFRADO DE CUNETAS | C25: m² | D25: =+'PLANILLA GENERAL DE METRADOS'!K114 -> 1661.96
A26: 01.04.03.04.02.03 | B26: ACERO f'y=4200 kg/cm2 PARA CUNETA | C26: kg | D26: =+'PLANILLA GENERAL DE METRADOS'!K127 -> 4967.0517
A27: 01.04.03.04.02.04 | B27: CURADO DE CONCRETO EN CUNETA | C27: m² | D27: =+'METRADO DE CURADO'!M38 -> 1084.2059
A28: 01.04.03.04.03 | B28: VARIOS
A29: 01.04.03.04.03.01 | B29: REJILLA METALICA P/CUNETA C/PL 1''x 3/16'' Y ANGULO 1'' x 1'' x 3/16'', S/DETALLE | C29: m | D29: =+'PLANILLA GENERAL DE METRADOS'!K132 -> 510.11
A30: 01.04.03.04.03.02 | B30: TAPA DE INSPECCION 0.60m x 0.60m | C30: und | D30: =+'PLANILLA GENERAL DE METRADOS'!K133 -> 17
A31: 01.04.03.04.03.03 | B31: JUNTA DE DILATACION E=1" CON SELLADOR ASFALTO | C31: m | D31: =+'PLANILLA GENERAL DE METRADOS'!K134 -> 241.95954
A32: 01.04.03.04.03.04 | B32: LLORADERO DE TUBERIA PVC Ø3" C/FILTRO DE GRAVA Y GEOTEXTIL @1.50 m (CUNETA COLINDANTE CON AREA VERDE) | C32: und | D32: =+'PLANILLA GENERAL DE METRADOS'!K135 -> 157
A33: 01.04.03.05 | B33: RED DE COLECCIÓN
A34: 01.04.03.05.01 | B34: RED DE RECOLECCION TECHO
A35: 01.04.03.05.01.01 | B35: MONTANTE CON TUBERÍA PVC DE 4" | C35: m | D35: =+'PLANILLA GENERAL DE METRADOS'!K139 -> 380.86
A36: 01.04.03.05.01.02 | B36: FALSA COLUMNA P/MONTANTE DE 0.20m x 0.15m x 1.30m | C36: und | D36: =+'PLANILLA GENERAL DE METRADOS'!K140 -> 52
A37: 01.04.03.05.01.02.01 | B37: CONCRETO F´C=175 KG/CM2 EN FALSA COLUMNA | C37: m³ | D37: =+'PLANILLA GENERAL DE METRADOS'!K141 -> 2.028
A38: 01.04.03.05.01.02.02 | B38: ENCOFRADO Y DESENCOFRADO EN FALSA COLUMNA - MONTANTE PLUVIAL | C38: m² | D38: =+'PLANILLA GENERAL DE METRADOS'!K143 -> 33.8
A39: 01.04.03.05.01.02.03 | B39: ACERO FY=4200 KG/CM2 EN FALSA COLUMNA (MONTANTE PLUVIAL) | C39: kg | D39: =+'PLANILLA GENERAL DE METRADOS'!K146 -> 291.7824
A40: 01.04.03.05.01.03 | B40: CANALETA DE PLANCHA DE ACERO GALVANIZADO e=0.9mm, SECCIÓN 0.25m x 0.20m | C40: m | D40: =+'PLANILLA GENERAL DE METRADOS'!K149 -> 513.98
A41: 01.04.03.05.01.04 | B41: SOPORTE DE PLATINA F°G° 1" x 1/8" P/CANALETA | C41: und | D41: =+'PLANILLA GENERAL DE METRADOS'!K150 -> 884
A42: 01.04.03.05.01.05 | B42: TAPA LATERAL DE PLANCHA GALVANIZADA P/CANALETA | C42: und | D42: =+'PLANILLA GENERAL DE METRADOS'!K151 -> 40
...

Sheet PLANILLA GENERAL DE METRADOS
A2: RESUMEN METRADOS DE DRENAJE PLUVIAL
A3: ENTIDAD | B3: =+RESUMEN!B4 -> GERENCIA TERRITORIAL BAJO MAYO - TARAPOTO
A4: PROYECTO | B4: =+RESUMEN!B5 -> “CREACIÓN DEL SERVICIO DE PROTECCIÓN A MUJERES VÍCTIMAS DE VIOLENCIA EN SITUACIÓN DE RIESGO DE FEMINICIDIO O PELIGRE SU INTEGRIDAD Y/O SALUD FÍSICA Y/O MENTAL EN HOGAR DE REFUGIO TEMPORAL DISTRITO DE MORALES DE LA PROVINCIA DE SAN MARTÍN DEL DEPARTAMENTO DE SAN MARTÍN”, con CUI N.° 2675514
A5: UBICACIÓN | B5: =+RESUMEN!B6 -> SAN MARTIN - SAN MARTIN - MORALES
A6: FECHA | B6: =+RESUMEN!B7 -> 46266
A8: ITEM | B8: DESCRIPCION | C8: Nº DE VECES | D8: LARGO | E8: ANCHO | F8: ALTURA | G8: FACT. | H8: AREA | I8: VOLUMEN | J8: PARCIAL | K8: TOTAL | L8: UND
A9: 01.04.03 | B9: SISTEMA DE DRENAJE PLUVIAL
A10: 01.04.03.01 | B10: TRABAJOS PRELIMINARES
A11: 01.04.03.01.01 | B11: LIMPIEZA MANUAL DE TERRENO | K11: =SUM(J12:J23) -> 956.872 | L11: m²
B12: EJE 1 | C12: 1 | D12: 37.14 | E12: 1.4 | J12: =C12*D12*E12 -> 51.996
B13: EJE 2 | C13: 1 | D13: 130.85 | E13: 1.4 | J13: =C13*D13*E13 -> 183.19
B14: EJE 3 | C14: 1 | D14: 5.82 | E14: 1.4 | J14: =C14*D14*E14 -> 8.148
B15: EJE 4 | C15: 1 | D15: 8.6 | E15: 1.4 | J15: =C15*D15*E15 -> 12.04
B16: EJE 5 | C16: 1 | D16: 43.23 | E16: 1.4 | J16: =C16*D16*E16 -> 60.522
B17: EJE 6 | C17: 1 | D17: 120.36 | E17: 1.4 | J17: =C17*D17*E17 -> 168.504
B18: EJE 7 | C18: 1 | D18: 125.7 | E18: 1.4 | J18: =C18*D18*E18 -> 175.98
B19: EJE 8 | C19: 1 | D19: 8.2 | E19: 1.4 | J19: =C19*D19*E19 -> 11.48
B20: EJE 9 | C20: 1 | D20: 7 | E20: 1.4 | J20: =C20*D20*E20 -> 9.8
B21: EJE 10 | C21: 1 | D21: 16 | E21: 1.4 | J21: =C21*D21*E21 -> 22.4
B22: EJE 11 | C22: 1 | D22: 71.46 | E22: 1.4 | J22: =C22*D22*E22 -> 100.044
B23: EJE 12 | C23: 1 | D23: 109.12 | E23: 1.4 | J23: =C23*D23*E23 -> 152.768
A24: 01.04.03.01.02 | B24: TRAZO, NIVELES Y REPLANTEO PRELIMINAR | K24: =SUM(J25:J36) -> 956.872 | L24: m²
B25: EJE 1 | C25: 1 | D25: 37.14 | E25: 1.4 | J25: =C25*D25*E25 -> 51.996
B26: EJE 2 | C26: 1 | D26: 130.85 | E26: 1.4 | J26: =C26*D26*E26 -> 183.19
B27: EJE 3 | C27: 1 | D27: 5.82 | E27: 1.4 | J27: =C27*D27*E27 -> 8.148
B28: EJE 4 | C28: 1 | D28: 8.6 | E28: 1.4 | J28: =C28*D28*E28 -> 12.04
B29: EJE 5 | C29: 1 | D29: 43.23 | E29: 1.4 | J29: =C29*D29*E29 -> 60.522
B30: EJE 6 | C30: 1 | D30: 120.36 | E30: 1.4 | J30: =C30*D30*E30 -> 168.504
B31: EJE 7 | C31: 1 | D31: 125.7 | E31: 1.4 | J31: =C31*D31*E31 -> 175.98
B32: EJE 8 | C32: 1 | D32: 8.2 | E32: 1.4 | J32: =C32*D32*E32 -> 11.48
B33: EJE 9 | C33: 1 | D33: 7 | E33: 1.4 | J33: =C33*D33*E33 -> 9.8
B34: EJE 10 | C34: 1 | D34: 16 | E34: 1.4 | J34: =C34*D34*E34 -> 22.4
B35: EJE 11 | C35: 1 | D35: 71.46 | E35: 1.4 | J35: =C35*D35*E35 -> 100.044
B36: EJE 12 | C36: 1 | D36: 109.12 | E36: 1.4 | J36: =C36*D36*E36 -> 152.768
A37: 01.04.03.02 | B37: MOVIMIENTO DE TIERRAS
A38: 01.04.03.02.01 | B38: EXCAVACIÓN MANUAL DE ZANJAS P/CUNETAS | K38: =SUM(J39:J50) -> 619.79764 | L38: m³
B39: EJE 1 | C39: 1 | D39: 37.14 | E39: 1.4 | F39: 0.4 | J39: =C39*D39*E39*(F39+PARAMETROS!$B$15) -> 25.998
B40: EJE 2 | C40: 1 | D40: 130.85 | E40: 1.4 | F40: 0.62 | J40: =C40*D40*E40*(F40+PARAMETROS!$B$15) -> 131.8968
B41: EJE 3 | C41: 1 | D41: 5.82 | E41: 1.4 | F41: 0.3 | J41: =C41*D41*E41*(F41+PARAMETROS!$B$15) -> 3.2592
B42: EJE 4 | C42: 1 | D42: 8.6 | E42: 1.4 | F42: 0.32 | J42: =C42*D42*E42*(F42+PARAMETROS!$B$15) -> 5.0568
...

Sheet CONCRETO EN CUNETAS
B2: CONCRETO F´C=175 KG/CM2 PARA CUNETAS - DRENAJE PLUVIAL
B3: ENTIDAD | C3: =+RESUMEN!B4 -> GERENCIA TERRITORIAL BAJO MAYO - TARAPOTO
B4: PROYECTO | C4: =+RESUMEN!B5 -> “CREACIÓN DEL SERVICIO DE PROTECCIÓN A MUJERES VÍCTIMAS DE VIOLENCIA EN SITUACIÓN DE RIESGO DE FEMINICIDIO O PELIGRE SU INTEGRIDAD Y/O SALUD FÍSICA Y/O MENTAL EN HOGAR DE REFUGIO TEMPORAL DISTRITO DE MORALES DE LA PROVINCIA DE SAN MARTÍN DEL DEPARTAMENTO DE SAN MARTÍN”, con CUI N.° 2675514
B5: UBICACIÓN | C5: =+RESUMEN!B6 -> SAN MARTIN - SAN MARTIN - MORALES
B6: FECHA | C6: =+RESUMEN!B7 -> 46266
B7: OBRAS DE CONCRETO ARMADO
B9: LONGITUDES Y AREAS | E9: m3 | F9: Sub.TOTAL | G9: TOTAL (m3) | J9: LONGITUDES Y AREAS | M9: m3 | N9: Sub.TOTAL | O9: TOTAL (m3)
B10: CUNETA EJE 01 | C10: MUROS | D10: AREA | E10: 14.07 | F10: =E10*E11*E12 -> 2.814 | G10: =SUM(F10:F18) -> 5.3508 | J10: CUNETA EJE 07 | K10: MUROS | L10: AREA | M10: 74.5 | N10: =M10*M11*M12 -> 14.9 | O10: =SUM(N10:N18) -> 23.9066
D11: ESPESOR | E11: 0.1 | L11: ESPESOR | M11: 0.1
D12: CANT. | E12: 2 | L12: CANT. | M12: 2
C13: LOSA | D13: ESPESOR | E13: 0.1 | F13: =E13*E14*E15 -> 2.2284 | K13: LOSA | L13: ESPESOR | M13: 0.1 | N13: =M13*M14*M15 -> 7.542
D14: LONGITUD | E14: 37.14 | L14: LONGITUD | M14: 125.7
D15: ANCHO | E15: 0.6 | L15: ANCHO | M15: 0.6
C16: TAPA | D16: LONGITUD | E16: 5.14 | F16: =E16*E17*E18 -> 0.3084 | K16: TAPA | L16: LONGITUD | M16: 24.41 | N16: =M16*M17*M18 -> 1.4646
D17: ESPESOR | E17: 0.1 | L17: ESPESOR | M17: 0.1
D18: ANCHO | E18: 0.6 | L18: ANCHO | M18: 0.6
B21: LONGITUDES Y AREAS | E21: m3 | F21: Sub.TOTAL | G21: TOTAL (m3) | J21: LONGITUDES Y AREAS | M21: m3 | N21: Sub.TOTAL | O21: TOTAL (m3)
B22: CUNETA EJE 02 | C22: MUROS | D22: AREA | E22: 78.32 | F22: =E22*E23*E24 -> 15.664 | G22: =SUM(F22:F30) -> 25.4146 | J22: CUNETA EJE 08 | K22: MUROS | L22: AREA | M22: 2.62 | N22: =M22*M23*M24 -> 0.524 | O22: =SUM(N22:N30) -> 1.508
D23: ESPESOR | E23: 0.1 | L23: ESPESOR | M23: 0.1
D24: CANT. | E24: 2 | L24: CANT. | M24: 2
C25: LOSA | D25: ESPESOR | E25: 0.1 | F25: =E25*E26*E27 -> 7.851 | K25: LOSA | L25: ESPESOR | M25: 0.1 | N25: =M25*M26*M27 -> 0.492
D26: LONGITUD | E26: 130.85 | L26: LONGITUD | M26: 8.2
D27: ANCHO | E27: 0.6 | L27: ANCHO | M27: 0.6
C28: TAPA | D28: LONGITUD | E28: 31.66 | F28: =E28*E29*E30 -> 1.8996 | K28: TAPA | L28: LONGITUD | M28: 8.2 | N28: =M28*M29*M30 -> 0.492
D29: ESPESOR | E29: 0.1 | L29: ESPESOR | M29: 0.1
D30: ANCHO | E30: 0.6 | L30: ANCHO | M30: 0.6
B33: LONGITUDES Y AREAS | E33: m3 | F33: Sub.TOTAL | G33: TOTAL (m3) | J33: LONGITUDES Y AREAS | M33: m3 | N33: Sub.TOTAL | O33: TOTAL (m3)
B34: CUNETA EJE 03 | C34: MUROS | D34: AREA | E34: 1.83 | F34: =E34*E35*E36 -> 0.366 | G34: =SUM(F34:F42) -> 0.7152 | J34: CUNETA EJE 09 | K34: MUROS | L34: AREA | M34: 2.22 | N34: =M34*M35*M36 -> 0.444 | O34: =SUM(N34:N42) -> 1.284
D35: ESPESOR | E35: 0.1 | L35: ESPESOR | M35: 0.1
D36: CANT. | E36: 2 | L36: CANT. | M36: 2
C37: LOSA | D37: ESPESOR | E37: 0.1 | F37: =E37*E38*E39 -> 0.3492 | K37: LOSA | L37: ESPESOR | M37: 0.1 | N37: =M37*M38*M39 -> 0.42
D38: LONGITUD | E38: 5.82 | L38: LONGITUD | M38: 7
D39: ANCHO | E39: 0.6 | L39: ANCHO | M39: 0.6
C40: TAPA | D40: LONGITUD | E40: 0 | F40: =E40*E41*E42 -> 0 | K40: TAPA | L40: LONGITUD | M40: 7 | N40: =M40*M41*M42 -> 0.42
D41: ESPESOR | E41: 0.1 | L41: ESPESOR | M41: 0.1
D42: ANCHO | E42: 0.6 | L42: ANCHO | M42: 0.6
B45: LONGITUDES Y AREAS | E45: m3 | F45: Sub.TOTAL | G45: TOTAL (m3) | J45: LONGITUDES Y AREAS | M45: m3 | N45: Sub.TOTAL | O45: TOTAL (m3)
B46: CUNETA EJE 04 | C46: MUROS | D46: AREA | E46: 2.76 | F46: =E46*E47*E48 -> 0.552 | G46: =SUM(F46:F54) -> 1.068 | J46: CUNETA EJE 10 | K46: MUROS | L46: AREA | M46: 5.44 | N46: =M46*M47*M48 -> 1.088 | O46: =SUM(N46:N54) -> 2.048
D47: ESPESOR | E47: 0.1 | L47: ESPESOR | M47: 0.1
D48: CANT. | E48: 2 | L48: CANT. | M48: 2
...

Sheet ENCOFRADO Y DESENCOFRADO
B2: ENCOFRADO Y DESENCOFRADO CUNETAS - DRENAJE PLUVIAL
B3: ENTIDAD | C3: =+RESUMEN!B4 -> GERENCIA TERRITORIAL BAJO MAYO - TARAPOTO
B4: PROYECTO | C4: =+RESUMEN!B5 -> “CREACIÓN DEL SERVICIO DE PROTECCIÓN A MUJERES VÍCTIMAS DE VIOLENCIA EN SITUACIÓN DE RIESGO DE FEMINICIDIO O PELIGRE SU INTEGRIDAD Y/O SALUD FÍSICA Y/O MENTAL EN HOGAR DE REFUGIO TEMPORAL DISTRITO DE MORALES DE LA PROVINCIA DE SAN MARTÍN DEL DEPARTAMENTO DE SAN MARTÍN”, con CUI N.° 2675514
B5: UBICACIÓN | C5: =+RESUMEN!B6 -> SAN MARTIN - SAN MARTIN - MORALES
B6: FECHA | C6: =+RESUMEN!B7 -> 46266
B8: OBRAS DE CONCRETO ARMADO - ENCOFRADO Y DESENCOFRADO CUNETAS
B11: LONGITUDES Y AREAS | G11: Sub.TOTAL | H11: TOTAL (m2) | J11: LONGITUDES Y AREAS | O11: Sub.TOTAL | P11: TOTAL (m2)
B12: EJE1 | C12: ABIERTA | D12: MUROS EXTERNO | E12: AREA | F12: 15.36 | G12: =F12*F13 -> 30.72 | H12: =SUM(G12:G20) -> 66.796 | J12: EJE 2 | K12: NORMAL | L12: MUROS EXTERNO | M12: AREA | N12: 68.67 | O12: =N12*N13 -> 137.34 | P12: =SUM(O12:O20) -> 358.444
E13: CANT. | F13: 2 | M13: CANT. | N13: 2
D14: MURO INTERNO | E14: AREA | F14: 12.16 | G14: =F14*F15 -> 24.32 | L14: MURO INTERNO | M14: AREA | N14: 58.75 | O14: =N14*N15 -> 117.5
E15: CANTIDAD | F15: 2 | M15: CANTIDAD | N15: 2
C16: TAPADO | D16: MURO EXTERNO | E16: AREA | F16: 2.94 | G16: =F16*F17 -> 5.88 | K16: TAPADO | L16: MURO EXTERNO | M16: AREA | N16: 25.9 | O16: =N16*N17 -> 51.8
E17: CANT. | F17: 2 | M17: CANT. | N17: 2
D18: MURO INTERNO | E18: AREA | F18: 1.91 | G18: =(F18*F19)+F20 -> 5.876 | L18: MURO INTERNO | M18: AREA | N18: 19.57 | O18: =N18*N19+N20 -> 51.804
E19: CANTIDAD | F19: 2 | M19: CANTIDAD | N19: 2
E20: TAPA | F20: =5.14*0.4 -> 2.056 | M20: TAPA | N20: =31.66*0.4 -> 12.664
B22: LONGITUDES Y AREAS | G22: Sub.TOTAL | H22: TOTAL (m2) | J22: LONGITUDES Y AREAS | O22: Sub.TOTAL | P22: TOTAL (m2)
B23: EJE 3 | C23: ABIERTA | D23: MUROS EXTERNO | E23: AREA | F23: 2.41 | G23: =F23*F24 -> 4.82 | H23: =SUM(G23:G31) -> 8.48 | J23: EJE 4 | K23: NORMAL | L23: MUROS EXTERNO | M23: AREA | N23: 3.62 | O23: =N23*N24 -> 7.24 | P23: =SUM(O23:O31) -> 12.76
E24: CANT. | F24: 2 | M24: CANT. | N24: 2
D25: MURO INTERNO | E25: AREA | F25: 1.83 | G25: =F25*F26 -> 3.66 | L25: MURO INTERNO | M25: AREA | N25: 2.76 | O25: =N25*N26 -> 5.52
E26: CANTIDAD | F26: 2 | M26: CANTIDAD | N26: 2
C27: TAPADO | D27: MURO EXTERNO | E27: AREA | F27: 0 | G27: =F27*F28 -> 0 | K27: TAPADO | L27: MURO EXTERNO | M27: AREA | N27: 0 | O27: =N27*N28 -> 0
E28: CANT. | F28: 2 | M28: CANT. | N28: 2
D29: MURO INTERNO | E29: AREA | F29: 0 | G29: =F29*F30+F31 -> 0 | L29: MURO INTERNO | M29: AREA | N29: 0 | O29: =N29*N30+N31 -> 0
E30: CANTIDAD | F30: 2 | M30: CANTIDAD | N30: 2
E31: TAPA | F31: 0 | M31: TAPA | N31: 0
B33: LONGITUDES Y AREAS | G33: Sub.TOTAL | H33: TOTAL (m2) | J33: LONGITUDES Y AREAS | O33: Sub.TOTAL | P33: TOTAL (m2)
B34: EJE 5 | C34: NORMAL | D34: MUROS EXTERNO | E34: AREA | F34: 18.53 | G34: =F34*F35 -> 37.06 | H34: =SUM(G34:G42) -> 80.36 | J34: EJE 6 | K34: NORMAL | L34: MUROS EXTERNO | M34: AREA | N34: 63.19 | O34: =N34*N35 -> 126.38 | P34: =SUM(O34:O42) -> 318.54
E35: CANT. | F35: 2 | M35: CANT. | N35: 2
D36: MURO INTERNO | E36: AREA | F36: 14.78 | G36: =F36*F37 -> 29.56 | L36: MURO INTERNO | M36: AREA | N36: 53.74 | O36: =N36*N37 -> 107.48
E37: CANTIDAD | F37: 2 | M37: CANTIDAD | N37: 2
C38: TAPADO | D38: MURO EXTERNO | E38: AREA | F38: 3.43 | G38: =F38*F39 -> 6.86 | K38: TAPADO | L38: MURO EXTERNO | M38: AREA | N38: 21.16 | O38: =N38*N39 -> 42.32
E39: CANT. | F39: 2 | M39: CANT. | N39: 2
D40: MURO INTERNO | E40: AREA | F40: 2.3 | G40: =F40*F41+F42 -> 6.88 | L40: MURO INTERNO | M40: AREA | N40: 16 | O40: =N40*N41+N42 -> 42.36
E41: CANTIDAD | F41: 2 | M41: CANTIDAD | N41: 2
E42: TAPA | F42: =5.7*0.4 -> 2.28 | M42: TAPA | N42: =25.9*0.4 -> 10.36
B44: LONGITUDES Y AREAS | G44: Sub.TOTAL | H44: TOTAL (m2) | J44: LONGITUDES Y AREAS | O44: Sub.TOTAL | P44: TOTAL (m2)
B45: EJE 7 | C45: NORMAL | D45: MUROS EXTERNO | E45: AREA | F45: 68.6 | G45: =F45*F46 -> 137.2 | H45: =SUM(G45:G53) -> 337.7 | J45: EJE 8 | K45: NORMAL | L45: MUROS EXTERNO | M45: AREA | N45: 0 | O45: =N45*N46 -> 0 | P45: =SUM(O45:O53) -> 17.04
E46: CANT. | F46: 2 | M46: CANT. | N46: 2
D47: MURO INTERNO | E47: AREA | F47: 58.46 | G47: =F47*F48 -> 116.92 | L47: MURO INTERNO | M47: AREA | N47: 0 | O47: =N47*N48 -> 0
...

Sheet METRADO MONTANTES
B2: CALCULO DE MONTANTES POR EDIFICACION - DRENAJE PLUVIAL
B3: ENTIDAD | C3: =+RESUMEN!B4 -> GERENCIA TERRITORIAL BAJO MAYO - TARAPOTO
B4: PROYECTO | C4: =+RESUMEN!B5 -> “CREACIÓN DEL SERVICIO DE PROTECCIÓN A MUJERES VÍCTIMAS DE VIOLENCIA EN SITUACIÓN DE RIESGO DE FEMINICIDIO O PELIGRE SU INTEGRIDAD Y/O SALUD FÍSICA Y/O MENTAL EN HOGAR DE REFUGIO TEMPORAL DISTRITO DE MORALES DE LA PROVINCIA DE SAN MARTÍN DEL DEPARTAMENTO DE SAN MARTÍN”, con CUI N.° 2675514
B5: UBICACIÓN | C5: =+RESUMEN!B6 -> SAN MARTIN - SAN MARTIN - MORALES
B6: FECHA | C6: =+RESUMEN!B7 -> 46266
C9: MONTANTES | D9: LONG. TUBERIA PVC 4" | G9: CODO PVC 90° 4" | J9: ABRAZADERA 4" | M9: COLGADOR 4" | P9: CODO PVC 45° 4"
D10: VECES | E10: LONGITUD | F10: TOTAL (m) | G10: CANTIDAD | H10: VECES | I10: TOTAL (und) | J10: CANTIDAD | K10: VECES | L10: TOTAL (und) | M10: CANTIDAD | N10: VECES | O10: TOTAL (und) | P10: CANTIDAD | Q10: VECES | R10: TOTAL (und)
B11: EDIFICACION 01
B12: Lado A | C12: 3 | D12: =C12 -> 3 | E12: 5.9 | F12: =E12*D12 -> 17.7 | G12: 3 | H12: =C12 -> 3 | I12: =H12*G12 -> 9 | J12: =MAX(1,ROUNDDOWN(E12/4,0)) -> 1 | K12: =C12 -> 3 | L12: =K12*J12 -> 3 | M12: 2 | N12: =C12 -> 3 | O12: =N12*M12 -> 6 | R12: =Q12*P12 -> 0
B13: Lado B | C13: 3 | D13: =C13 -> 3 | E13: 5.9 | F13: =E13*D13 -> 17.7 | G13: 3 | H13: =C13 -> 3 | I13: =H13*G13 -> 9 | J13: =MAX(1,ROUNDDOWN(E13/4,0)) -> 1 | K13: =C13 -> 3 | L13: =K13*J13 -> 3 | M13: 2 | N13: =C13 -> 3 | O13: =N13*M13 -> 6 | R13: =Q13*P13 -> 0
B14: EDIFICACION 02
B15: Lado A | C15: 2 | D15: =C15 -> 2 | E15: 6.27 | F15: =E15*D15 -> 12.54 | G15: 3 | H15: =C15 -> 2 | I15: =H15*G15 -> 6 | J15: =MAX(1,ROUNDDOWN(E15/4,0)) -> 1 | K15: =C15 -> 2 | L15: =K15*J15 -> 2 | M15: 2 | N15: =C15 -> 2 | O15: =N15*M15 -> 4 | R15: =Q15*P15 -> 0
B16: Lado B | C16: 2 | D16: =C16 -> 2 | E16: 6.27 | F16: =E16*D16 -> 12.54 | G16: 3 | H16: =C16 -> 2 | I16: =H16*G16 -> 6 | J16: =MAX(1,ROUNDDOWN(E16/4,0)) -> 1 | K16: =C16 -> 2 | L16: =K16*J16 -> 2 | M16: 2 | N16: =C16 -> 2 | O16: =N16*M16 -> 4 | R16: =Q16*P16 -> 0
B17: EDIFICACION 03
B18: Lado A | C18: 2 | D18: =C18 -> 2 | E18: 6.35 | F18: =E18*D18 -> 12.7 | G18: 3 | H18: =C18 -> 2 | I18: =H18*G18 -> 6 | J18: =MAX(1,ROUNDDOWN(E18/4,0)) -> 1 | K18: =C18 -> 2 | L18: =K18*J18 -> 2 | M18: 2 | N18: =C18 -> 2 | O18: =N18*M18 -> 4 | R18: =Q18*P18 -> 0
B19: Lado B | C19: 2 | D19: =C19 -> 2 | E19: 6.35 | F19: =E19*D19 -> 12.7 | G19: 3 | H19: =C19 -> 2 | I19: =H19*G19 -> 6 | J19: =MAX(1,ROUNDDOWN(E19/4,0)) -> 1 | K19: =C19 -> 2 | L19: =K19*J19 -> 2 | M19: 2 | N19: =C19 -> 2 | O19: =N19*M19 -> 4 | R19: =Q19*P19 -> 0
B20: EDIFICACION 04
B21: Lado A | C21: 3 | D21: =C21 -> 3 | E21: 6.26 | F21: =E21*D21 -> 18.78 | G21: 3 | H21: =C21 -> 3 | I21: =H21*G21 -> 9 | J21: =MAX(1,ROUNDDOWN(E21/4,0)) -> 1 | K21: =C21 -> 3 | L21: =K21*J21 -> 3 | M21: 2 | N21: =C21 -> 3 | O21: =N21*M21 -> 6 | R21: =Q21*P21 -> 0
B22: Lado B | C22: 3 | D22: =C22 -> 3 | E22: 6.26 | F22: =E22*D22 -> 18.78 | G22: 3 | H22: =C22 -> 3 | I22: =H22*G22 -> 9 | J22: =MAX(1,ROUNDDOWN(E22/4,0)) -> 1 | K22: =C22 -> 3 | L22: =K22*J22 -> 3 | M22: 2 | N22: =C22 -> 3 | O22: =N22*M22 -> 6 | R22: =Q22*P22 -> 0
B23: EDIFICACION 05
B24: Lado A | C24: 3 | D24: =C24 -> 3 | E24: 7.53 | F24: =E24*D24 -> 22.59 | G24: 3 | H24: =C24 -> 3 | I24: =H24*G24 -> 9 | J24: =MAX(1,ROUNDDOWN(E24/4,0)) -> 1 | K24: =C24 -> 3 | L24: =K24*J24 -> 3 | M24: 2 | N24: =C24 -> 3 | O24: =N24*M24 -> 6 | R24: =Q24*P24 -> 0
B25: Lado B | C25: 3 | D25: =C25 -> 3 | E25: 7.53 | F25: =E25*D25 -> 22.59 | G25: 3 | H25: =C25 -> 3 | I25: =H25*G25 -> 9 | J25: =MAX(1,ROUNDDOWN(E25/4,0)) -> 1 | K25: =C25 -> 3 | L25: =K25*J25 -> 3 | M25: 2 | N25: =C25 -> 3 | O25: =N25*M25 -> 6 | R25: =Q25*P25 -> 0
B26: EDIFICACION 06
B27: Lado A | C27: 2 | D27: =C27 -> 2 | E27: 6.18 | F27: =E27*D27 -> 12.36 | G27: 3 | H27: =C27 -> 2 | I27: =H27*G27 -> 6 | J27: =MAX(1,ROUNDDOWN(E27/4,0)) -> 1 | K27: =C27 -> 2 | L27: =K27*J27 -> 2 | M27: 2 | N27: =C27 -> 2 | O27: =N27*M27 -> 4 | R27: =Q27*P27 -> 0
B28: Lado B | C28: 2 | D28: =C28 -> 2 | E28: 6.18 | F28: =E28*D28 -> 12.36 | G28: 3 | H28: =C28 -> 2 | I28: =H28*G28 -> 6 | J28: =MAX(1,ROUNDDOWN(E28/4,0)) -> 1 | K28: =C28 -> 2 | L28: =K28*J28 -> 2 | M28: 2 | N28: =C28 -> 2 | O28: =N28*M28 -> 4 | R28: =Q28*P28 -> 0
B29: EDIFICACION 07
B30: Lado A | C30: 3 | D30: =C30 -> 3 | E30: 6.24 | F30: =E30*D30 -> 18.72 | G30: 3 | H30: =C30 -> 3 | I30: =H30*G30 -> 9 | J30: =MAX(1,ROUNDDOWN(E30/4,0)) -> 1 | K30: =C30 -> 3 | L30: =K30*J30 -> 3 | M30: 2 | N30: =C30 -> 3 | O30: =N30*M30 -> 6 | R30: =Q30*P30 -> 0
B31: Lado B | C31: 3 | D31: =C31 -> 3 | E31: 6.24 | F31: =E31*D31 -> 18.72 | G31: 3 | H31: =C31 -> 3 | I31: =H31*G31 -> 9 | J31: =MAX(1,ROUNDDOWN(E31/4,0)) -> 1 | K31: =C31 -> 3 | L31: =K31*J31 -> 3 | M31: 2 | N31: =C31 -> 3 | O31: =N31*M31 -> 6 | R31: =Q31*P31 -> 0
B32: EDIFICACION 08
B33: Lado A | C33: 2 | D33: =C33 -> 2 | E33: 6.26 | F33: =E33*D33 -> 12.52 | G33: 3 | H33: =C33 -> 2 | I33: =H33*G33 -> 6 | J33: =MAX(1,ROUNDDOWN(E33/4,0)) -> 1 | K33: =C33 -> 2 | L33: =K33*J33 -> 2 | M33: 2 | N33: =C33 -> 2 | O33: =N33*M33 -> 4 | R33: =Q33*P33 -> 0
B34: Lado B | C34: 2 | D34: =C34 -> 2 | E34: 6.26 | F34: =E34*D34 -> 12.52 | G34: 3 | H34: =C34 -> 2 | I34: =H34*G34 -> 6 | J34: =MAX(1,ROUNDDOWN(E34/4,0)) -> 1 | K34: =C34 -> 2 | L34: =K34*J34 -> 2 | M34: 2 | N34: =C34 -> 2 | O34: =N34*M34 -> 4 | R34: =Q34*P34 -> 0
B35: EDIFICACION 09
B36: Lado A | C36: 2 | D36: =C36 -> 2 | E36: 6.26 | F36: =E36*D36 -> 12.52 | G36: 3 | H36: =C36 -> 2 | I36: =H36*G36 -> 6 | J36: =MAX(1,ROUNDDOWN(E36/4,0)) -> 1 | K36: =C36 -> 2 | L36: =K36*J36 -> 2 | M36: 2 | N36: =C36 -> 2 | O36: =N36*M36 -> 4 | R36: =Q36*P36 -> 0
B37: Lado B | C37: 2 | D37: =C37 -> 2 | E37: 6.26 | F37: =E37*D37 -> 12.52 | G37: 3 | H37: =C37 -> 2 | I37: =H37*G37 -> 6 | J37: =MAX(1,ROUNDDOWN(E37/4,0)) -> 1 | K37: =C37 -> 2 | L37: =K37*J37 -> 2 | M37: 2 | N37: =C37 -> 2 | O37: =N37*M37 -> 4 | R37: =Q37*P37 -> 0
B38: LOSA DEPORTIVA
B39: Lado A | C39: 4 | D39: =C39 -> 4 | E39: 11 | F39: =E39*D39 -> 44 | G39: 3 | H39: =C39 -> 4 | I39: =H39*G39 -> 12 | J39: 3 | K39: =C39 -> 4 | L39: =K39*J39 -> 12 | M39: 0 | N39: =C39 -> 4 | O39: =N39*M39 -> 0 | R39: =Q39*P39 -> 0
B40: Lado B | C40: 4 | D40: =C40 -> 4 | E40: 11 | F40: =E40*D40 -> 44 | G40: 3 | H40: =C40 -> 4 | I40: =H40*G40 -> 12 | J40: 3 | K40: =C40 -> 4 | L40: =K40*J40 -> 12 | M40: 0 | N40: =C40 -> 4 | O40: =N40*M40 -> 0 | R40: =Q40*P40 -> 0
B41: OBRA EXTERIOR 01 | C41: 1 | D41: =C41 -> 1 | E41: 6 | F41: =E41*D41 -> 6 | G41: 3 | H41: =C41 -> 1 | I41: =H41*G41 -> 3 | J41: 1 | K41: =C41 -> 1 | L41: =K41*J41 -> 1 | M41: 1 | N41: =C41 -> 1 | O41: =N41*M41 -> 1 | R41: =Q41*P41 -> 0
B42: OBRA EXTERIOR03 | C42: 1 | D42: =C42 -> 1 | E42: 6 | F42: =E42*D42 -> 6 | G42: 3 | H42: =C42 -> 1 | I42: =H42*G42 -> 3 | J42: 1 | K42: =C42 -> 1 | L42: =K42*J42 -> 1 | M42: 1 | N42: =C42 -> 1 | O42: =N42*M42 -> 1 | R42: =Q42*P42 -> 0
C43: =SUM(C11:C42) -> 54 | F43: =SUM(F11:F42) -> 380.86 | I43: =SUM(I11:I42) -> 162 | L43: =SUM(L11:L42) -> 70 | O43: =SUM(O11:O42) -> 90 | R43: =SUM(R11:R42) -> 0

Sheet METRADO CANALETAS
B2: METRADO DE CANALETAS DE TECHO - DRENAJE PLUVIAL
B3: ENTIDAD | C3: =+RESUMEN!B4 -> GERENCIA TERRITORIAL BAJO MAYO - TARAPOTO
B4: PROYECTO | C4: =+RESUMEN!B5 -> “CREACIÓN DEL SERVICIO DE PROTECCIÓN A MUJERES VÍCTIMAS DE VIOLENCIA EN SITUACIÓN DE RIESGO DE FEMINICIDIO O PELIGRE SU INTEGRIDAD Y/O SALUD FÍSICA Y/O MENTAL EN HOGAR DE REFUGIO TEMPORAL DISTRITO DE MORALES DE LA PROVINCIA DE SAN MARTÍN DEL DEPARTAMENTO DE SAN MARTÍN”, con CUI N.° 2675514
B5: UBICACIÓN | C5: =+RESUMEN!B6 -> SAN MARTIN - SAN MARTIN - MORALES
B6: FECHA | C6: =+RESUMEN!B7 -> 46266
B8: CANALETA DE PLANCHA DE ACERO GALVANIZADO - SECCIÓN INTERIOR 0.25 m (FONDO) x 0.20 m (ALTO) - TECHOS A DOS AGUAS: UNA CANALETA POR CADA LADO
B9: EDIFICACIÓN | C9: N° DE CANALETAS | D9: CANALETA 0.25 x 0.20 m | F9: SOPORTE PLATINA F°G° 1" x 1/8" | H9: TAPA LATERAL | J9: BOQUILLA A MONTANTE Ø4"
D10: LONGITUD (m) | E10: TOTAL (m) | F10: CANTIDAD | G10: TOTAL (und) | H10: CANTIDAD | I10: TOTAL (und) | J10: CANTIDAD | K10: TOTAL (und)
B11: EDIFICACION 01
B12: Lado 01 | C12: 1 | D12: 25.33 | E12: =C12*D12 -> 25.33 | F12: =IF(D12>0,ROUNDUP(D12/$F$50,0)+1,0) -> 44 | G12: =C12*F12 -> 44 | H12: =$F$51 -> 2 | I12: =C12*H12 -> 2 | J12: ='METRADO MONTANTES'!C12 -> 3 | K12: =C12*J12 -> 3
B13: Lado 02 | C13: 1 | D13: =D12 -> 25.33 | E13: =C13*D13 -> 25.33 | F13: =IF(D13>0,ROUNDUP(D13/$F$50,0)+1,0) -> 44 | G13: =C13*F13 -> 44 | H13: =$F$51 -> 2 | I13: =C13*H13 -> 2 | J13: ='METRADO MONTANTES'!C13 -> 3 | K13: =C13*J13 -> 3
B14: EDIFICACION 02
B15: Lado 01 | C15: 1 | D15: 14.33 | E15: =C15*D15 -> 14.33 | F15: =IF(D15>0,ROUNDUP(D15/$F$50,0)+1,0) -> 25 | G15: =C15*F15 -> 25 | H15: =$F$51 -> 2 | I15: =C15*H15 -> 2 | J15: ='METRADO MONTANTES'!C15 -> 2 | K15: =C15*J15 -> 2
B16: Lado 02 | C16: 1 | D16: =D15 -> 14.33 | E16: =C16*D16 -> 14.33 | F16: =IF(D16>0,ROUNDUP(D16/$F$50,0)+1,0) -> 25 | G16: =C16*F16 -> 25 | H16: =$F$51 -> 2 | I16: =C16*H16 -> 2 | J16: ='METRADO MONTANTES'!C16 -> 2 | K16: =C16*J16 -> 2
B17: EDIFICACION 03
B18: Lado 01 | C18: 1 | D18: 17.33 | E18: =C18*D18 -> 17.33 | F18: =IF(D18>0,ROUNDUP(D18/$F$50,0)+1,0) -> 30 | G18: =C18*F18 -> 30 | H18: =$F$51 -> 2 | I18: =C18*H18 -> 2 | J18: ='METRADO MONTANTES'!C18 -> 2 | K18: =C18*J18 -> 2
B19: Lado 02 | C19: 1 | D19: =D18 -> 17.33 | E19: =C19*D19 -> 17.33 | F19: =IF(D19>0,ROUNDUP(D19/$F$50,0)+1,0) -> 30 | G19: =C19*F19 -> 30 | H19: =$F$51 -> 2 | I19: =C19*H19 -> 2 | J19: ='METRADO MONTANTES'!C19 -> 2 | K19: =C19*J19 -> 2
B20: EDIFICACION 04
B21: Lado 01 | C21: 1 | D21: 38.13 | E21: =C21*D21 -> 38.13 | F21: =IF(D21>0,ROUNDUP(D21/$F$50,0)+1,0) -> 65 | G21: =C21*F21 -> 65 | H21: =$F$51 -> 2 | I21: =C21*H21 -> 2 | J21: ='METRADO MONTANTES'!C21 -> 3 | K21: =C21*J21 -> 3
B22: Lado 02 | C22: 1 | D22: =D21 -> 38.13 | E22: =C22*D22 -> 38.13 | F22: =IF(D22>0,ROUNDUP(D22/$F$50,0)+1,0) -> 65 | G22: =C22*F22 -> 65 | H22: =$F$51 -> 2 | I22: =C22*H22 -> 2 | J22: ='METRADO MONTANTES'!C22 -> 3 | K22: =C22*J22 -> 3
B23: EDIFICACION 05
B24: Lado 01 | C24: 1 | D24: 32.31 | E24: =C24*D24 -> 32.31 | F24: =IF(D24>0,ROUNDUP(D24/$F$50,0)+1,0) -> 55 | G24: =C24*F24 -> 55 | H24: =$F$51 -> 2 | I24: =C24*H24 -> 2 | J24: ='METRADO MONTANTES'!C24 -> 3 | K24: =C24*J24 -> 3
B25: Lado 02 | C25: 1 | D25: =D24 -> 32.31 | E25: =C25*D25 -> 32.31 | F25: =IF(D25>0,ROUNDUP(D25/$F$50,0)+1,0) -> 55 | G25: =C25*F25 -> 55 | H25: =$F$51 -> 2 | I25: =C25*H25 -> 2 | J25: ='METRADO MONTANTES'!C25 -> 3 | K25: =C25*J25 -> 3
B26: EDIFICACION 06
B27: Lado 01 | C27: 1 | D27: 20.73 | E27: =C27*D27 -> 20.73 | F27: =IF(D27>0,ROUNDUP(D27/$F$50,0)+1,0) -> 36 | G27: =C27*F27 -> 36 | H27: =$F$51 -> 2 | I27: =C27*H27 -> 2 | J27: ='METRADO MONTANTES'!C27 -> 2 | K27: =C27*J27 -> 2
B28: Lado 02 | C28: 1 | D28: =D27 -> 20.73 | E28: =C28*D28 -> 20.73 | F28: =IF(D28>0,ROUNDUP(D28/$F$50,0)+1,0) -> 36 | G28: =C28*F28 -> 36 | H28: =$F$51 -> 2 | I28: =C28*H28 -> 2 | J28: ='METRADO MONTANTES'!C28 -> 2 | K28: =C28*J28 -> 2
B29: EDIFICACION 07
B30: Lado 01 | C30: 1 | D30: 38.13 | E30: =C30*D30 -> 38.13 | F30: =IF(D30>0,ROUNDUP(D30/$F$50,0)+1,0) -> 65 | G30: =C30*F30 -> 65 | H30: =$F$51 -> 2 | I30: =C30*H30 -> 2 | J30: ='METRADO MONTANTES'!C30 -> 3 | K30: =C30*J30 -> 3
B31: Lado 02 | C31: 1 | D31: =D30 -> 38.13 | E31: =C31*D31 -> 38.13 | F31: =IF(D31>0,ROUNDUP(D31/$F$50,0)+1,0) -> 65 | G31: =C31*F31 -> 65 | H31: =$F$51 -> 2 | I31: =C31*H31 -> 2 | J31: ='METRADO MONTANTES'!C31 -> 3 | K31: =C31*J31 -> 3
B32: EDIFICACION 08
B33: Lado 01 | C33: 1 | D33: 20.73 | E33: =C33*D33 -> 20.73 | F33: =IF(D33>0,ROUNDUP(D33/$F$50,0)+1,0) -> 36 | G33: =C33*F33 -> 36 | H33: =$F$51 -> 2 | I33: =C33*H33 -> 2 | J33: ='METRADO MONTANTES'!C33 -> 2 | K33: =C33*J33 -> 2
B34: Lado 02 | C34: 1 | D34: =D33 -> 20.73 | E34: =C34*D34 -> 20.73 | F34: =IF(D34>0,ROUNDUP(D34/$F$50,0)+1,0) -> 36 | G34: =C34*F34 -> 36 | H34: =$F$51 -> 2 | I34: =C34*H34 -> 2 | J34: ='METRADO MONTANTES'!C34 -> 2 | K34: =C34*J34 -> 2
B35: EDIFICACION 09
B36: Lado 01 | C36: 1 | D36: 14.77 | E36: =C36*D36 -> 14.77 | F36: =IF(D36>0,ROUNDUP(D36/$F$50,0)+1,0) -> 26 | G36: =C36*F36 -> 26 | H36: =$F$51 -> 2 | I36: =C36*H36 -> 2 | J36: ='METRADO MONTANTES'!C36 -> 2 | K36: =C36*J36 -> 2
B37: Lado 02 | C37: 1 | D37: =D36 -> 14.77 | E37: =C37*D37 -> 14.77 | F37: =IF(D37>0,ROUNDUP(D37/$F$50,0)+1,0) -> 26 | G37: =C37*F37 -> 26 | H37: =$F$51 -> 2 | I37: =C37*H37 -> 2 | J37: ='METRADO MONTANTES'!C37 -> 2 | K37: =C37*J37 -> 2
B38: LOSA DEPORTIVA
B39: Lado 01 | C39: 1 | D39: 35.2 | E39: =C39*D39 -> 35.2 | F39: =IF(D39>0,ROUNDUP(D39/$F$50,0)+1,0) -> 60 | G39: =C39*F39 -> 60 | H39: =$F$51 -> 2 | I39: =C39*H39 -> 2 | J39: ='METRADO MONTANTES'!C39 -> 4 | K39: =C39*J39 -> 4
B40: Lado 02 | C40: 1 | D40: =D39 -> 35.2 | E40: =C40*D40 -> 35.2 | F40: =IF(D40>0,ROUNDUP(D40/$F$50,0)+1,0) -> 60 | G40: =C40*F40 -> 60 | H40: =$F$51 -> 2 | I40: =C40*H40 -> 2 | J40: ='METRADO MONTANTES'!C40 -> 4 | K40: =C40*J40 -> 4
B41: TOTAL | C41: =SUM(C11:C40) -> 20 | E41: =SUM(E11:E40) -> 513.98 | G41: =SUM(G11:G40) -> 884 | I41: =SUM(I11:I40) -> 40 | K41: =SUM(K11:K40) -> 52
B43: PARÁMETROS DE CÁLCULO - CANALETA
...

Sheet METRADO  EN PISO (SUMIDERO)
A1: PLANILLA DE METRADOS - RED DE DRENAJE EN PISO Y SUMIDEROS
A2: ENTIDAD | B2: =+RESUMEN!B4 -> GERENCIA TERRITORIAL BAJO MAYO - TARAPOTO
A3: PROYECTO | B3: =+RESUMEN!B5 -> “CREACIÓN DEL SERVICIO DE PROTECCIÓN A MUJERES VÍCTIMAS DE VIOLENCIA EN SITUACIÓN DE RIESGO DE FEMINICIDIO O PELIGRE SU INTEGRIDAD Y/O SALUD FÍSICA Y/O MENTAL EN HOGAR DE REFUGIO TEMPORAL DISTRITO DE MORALES DE LA PROVINCIA DE SAN MARTÍN DEL DEPARTAMENTO DE SAN MARTÍN”, con CUI N.° 2675514
A4: UBICACIÓN | B4: =+RESUMEN!B6 -> SAN MARTIN - SAN MARTIN - MORALES
A5: FECHA | B5: =+RESUMEN!B7 -> 46266
A7: SECTOR | B7: TUBERÍA 4" PVC-U Desagüe Clase Pesada (m) | C7: SUMIDERO DE 4" (und) | D7: CODO 90° x 4" (und) | E7: CODO 45° x 4" (und) | F7: TEE° x 4" (und) | G7: OBSERVACIÓN
A8: SECTOR 01 | B8: 26.52 | C8: 6 | D8: 4 | E8: 0 | F8: 2 | G8: Según sector
A9: SECTOR 02 | B9: 27.18 | C9: 8 | D9: 4 | E9: 0 | F9: 2 | G9: Según sector
A10: SECTOR 03 | B10: 32 | C10: 6 | D10: 6 | E10: 0 | F10: 0 | G10: Según sector
A11: SECTOR 04 | B11: 26.56 | C11: 10 | D11: 10 | E11: 0 | F11: 0 | G11: Según sector
A12: TOTAL | B12: =SUM(B8:B11) -> 112.26 | C12: =SUM(C8:C11) -> 30 | D12: =SUM(D8:D11) -> 24 | E12: =SUM(E8:E11) -> 0 | F12: =SUM(F8:F11) -> 4

Sheet METRADO ACERO
A2: METRADO DE ACERO EN CUNETAS - DRENAJE PLUVIAL
A3: ENTIDAD | B3: =+RESUMEN!B4 -> GERENCIA TERRITORIAL BAJO MAYO - TARAPOTO
A4: PROYECTO | B4: =+RESUMEN!B5 -> “CREACIÓN DEL SERVICIO DE PROTECCIÓN A MUJERES VÍCTIMAS DE VIOLENCIA EN SITUACIÓN DE RIESGO DE FEMINICIDIO O PELIGRE SU INTEGRIDAD Y/O SALUD FÍSICA Y/O MENTAL EN HOGAR DE REFUGIO TEMPORAL DISTRITO DE MORALES DE LA PROVINCIA DE SAN MARTÍN DEL DEPARTAMENTO DE SAN MARTÍN”, con CUI N.° 2675514
A5: UBICACIÓN | B5: =+RESUMEN!B6 -> SAN MARTIN - SAN MARTIN - MORALES
A6: FECHA | B6: =+RESUMEN!B7 -> 46266
A8: METRADO DETALLADO POR EJE Y POR TRAMO
A9: IDENTIFICACIÓN Y GEOMETRÍA | H9: ACERO LONGITUDINAL DEL CUERPO U | P9: ACERO TRANSVERSAL DEL CUERPO U | X9: ACERO TRANSVERSAL DE LA TAPA (SOLO CUNETA TAPADA) | AG9: RESULTADO
A10: N° | B10: EJE | C10: TRAMO | D10: TIPO DE CUNETA | E10: SEC. INI | F10: SEC. FIN | G10: LONGITUD TRAMO (m) | H10: Ø CUERPO | I10: FACTOR CUERPO (kg/m) | J10: SEP. LONG. (m) | K10: BARRAS LONG. INI | L10: BARRAS LONG. FIN | M10: BARRAS PROM. | N10: LONG. ACERO LONG. (m) | O10: KG LONG. | P10: SEP. TRANSV. U (m) | Q10: DES. TRANSV. U INI (m) | R10: DES. TRANSV. U FIN (m) | S10: DES. PROM. U (m) | T10: CANT. TRANSV. U | U10: LONG. ACERO TRANSV. U (m) | V10: KG TRANSV. U | W10: TOTAL KG CUERPO U | X10: Ø TAPA | Y10: FACTOR TAPA (kg/m) | Z10: SEP. TRANSV. TAPA (m) | AA10: LONG. BARRA TAPA INI (m) | AB10: LONG. BARRA TAPA FIN (m) | AC10: LONG. PROM. TAPA (m) | AD10: CANT. BARRAS TAPA | AE10: LONG. ACERO TAPA (m) | AF10: KG ACERO TAPA | AG10: TOTAL KG TRAMO
A11: 1 | B11: EJE 01 | C11: TRAMO 01 | D11: ABIERTA | E11: SEC 02 | F11: SEC 03 | G11: 12 | H11: 3/8" | I11: =IF(H11="","",IFERROR(VLOOKUP(H11,Listas!$A$4:$B$11,2,FALSE()),"")) -> 0.56 | J11: 0.21 | K11: 7 | L11: 7 | M11: =IF(B11="","",(K11+L11)/2) -> 7 | N11: =IF(B11="","",G11*M11) -> 84 | O11: =IF(B11="","",N11*I11) -> 47.04 | P11: 0.25 | Q11: 1.42 | R11: 1.5 | S11: =IF(B11="","",(Q11+R11)/2) -> 1.46 | T11: =IF(B11="","",IFERROR(IF($X$1="ENTERO (redondeo arriba)",ROUNDUP(G11/P11,0)+1,G11/P11+1),0)) -> 49 | U11: =IF(B11="","",S11*T11) -> 71.54 | V11: =IF(B11="","",U11*I11) -> 40.0624 | W11: =IF(B11="","",O11+V11) -> 87.1024 | AC11: =IF(B11="","",IF(D11="TAPADA",(AA11+AB11)/2,0)) -> 0 | AD11: =IF(B11="","",IF(D11="TAPADA",IFERROR(IF($X$1="ENTERO (redondeo arriba)",ROUNDUP(G11/Z11,0)+1,G11/Z11+1),0),0)) -> 0 | AE11: =IF(B11="","",IF(D11="TAPADA",AC11*AD11,0)) -> 0 | AF11: =IF(B11="","",IF(D11="TAPADA",AE11*Y11,0)) -> 0 | AG11: =IF(B11="","",W11+AF11) -> 87.1024
A12: 2 | B12: EJE 01 | C12: TRAMO 02 | D12: TAPADA | E12: SEC 03 | F12: SEC 04 | G12: 5.14 | H12: 3/8" | I12: =IF(H12="","",IFERROR(VLOOKUP(H12,Listas!$A$4:$B$11,2,FALSE()),"")) -> 0.56 | J12: 0.23 | K12: 8 | L12: 8 | M12: =IF(B12="","",(K12+L12)/2) -> 8 | N12: =IF(B12="","",G12*M12) -> 41.12 | O12: =IF(B12="","",N12*I12) -> 23.0272 | P12: 0.25 | Q12: 1.5 | R12: 1.58 | S12: =IF(B12="","",(Q12+R12)/2) -> 1.54 | T12: =IF(B12="","",IFERROR(IF($X$1="ENTERO (redondeo arriba)",ROUNDUP(G12/P12,0)+1,G12/P12+1),0)) -> 21.56 | U12: =IF(B12="","",S12*T12) -> 33.2024 | V12: =IF(B12="","",U12*I12) -> 18.593344 | W12: =IF(B12="","",O12+V12) -> 41.620544 | X12: 3/8" | Y12: 0.56 | Z12: 0.25 | AA12: 0.56 | AB12: 0.56 | AC12: =IF(B12="","",IF(D12="TAPADA",(AA12+AB12)/2,0)) -> 0.56 | AD12: =IF(B12="","",IF(D12="TAPADA",IFERROR(IF($X$1="ENTERO (redondeo arriba)",ROUNDUP(G12/Z12,0)+1,G12/Z12+1),0),0)) -> 21.56 | AE12: =IF(B12="","",IF(D12="TAPADA",AC12*AD12,0)) -> 12.0736 | AF12: =IF(B12="","",IF(D12="TAPADA",AE12*Y12,0)) -> 6.761216 | AG12: =IF(B12="","",W12+AF12) -> 48.38176
A13: 3 | B13: EJE 02 | C13: TRAMO 01 | D13: ABIERTA | E13: SEC 06 | F13: SEC 07 | G13: 17.5 | H13: 3/8" | I13: =IF(H13="","",IFERROR(VLOOKUP(H13,Listas!$A$4:$B$11,2,FALSE()),"")) -> 0.56 | J13: 0.23 | K13: 7 | L13: 7 | M13: =IF(B13="","",(K13+L13)/2) -> 7 | N13: =IF(B13="","",G13*M13) -> 122.5 | O13: =IF(B13="","",N13*I13) -> 68.6 | P13: 0.25 | Q13: 1.42 | R13: 1.58 | S13: =IF(B13="","",(Q13+R13)/2) -> 1.5 | T13: =IF(B13="","",IFERROR(IF($X$1="ENTERO (redondeo arriba)",ROUNDUP(G13/P13,0)+1,G13/P13+1),0)) -> 71 | U13: =IF(B13="","",S13*T13) -> 106.5 | V13: =IF(B13="","",U13*I13) -> 59.64 | W13: =IF(B13="","",O13+V13) -> 128.24 | AC13: =IF(B13="","",IF(D13="TAPADA",(AA13+AB13)/2,0)) -> 0 | AD13: =IF(B13="","",IF(D13="TAPADA",IFERROR(IF($X$1="ENTERO (redondeo arriba)",ROUNDUP(G13/Z13,0)+1,G13/Z13+1),0),0)) -> 0 | AE13: =IF(B13="","",IF(D13="TAPADA",AC13*AD13,0)) -> 0 | AF13: =IF(B13="","",IF(D13="TAPADA",AE13*Y13,0)) -> 0 | AG13: =IF(B13="","",W13+AF13) -> 128.24
A14: 4 | B14: EJE 02 | C14: TRAMO 02 | D14: TAPADA | E14: SEC 07 | F14: SEC 08 | G14: 10.2 | H14: 3/8" | I14: =IF(H14="","",IFERROR(VLOOKUP(H14,Listas!$A$4:$B$11,2,FALSE()),"")) -> 0.56 | J14: 0.22 | K14: 8 | L14: 10 | M14: =IF(B14="","",(K14+L14)/2) -> 9 | N14: =IF(B14="","",G14*M14) -> 91.8 | O14: =IF(B14="","",N14*I14) -> 51.408 | P14: 0.25 | Q14: 1.58 | R14: 1.66 | S14: =IF(B14="","",(Q14+R14)/2) -> 1.62 | T14: =IF(B14="","",IFERROR(IF($X$1="ENTERO (redondeo arriba)",ROUNDUP(G14/P14,0)+1,G14/P14+1),0)) -> 41.8 | U14: =IF(B14="","",S14*T14) -> 67.716 | V14: =IF(B14="","",U14*I14) -> 37.92096 | W14: =IF(B14="","",O14+V14) -> 89.32896 | X14: 3/8" | Y14: 0.56 | Z14: 0.25 | AA14: 0.56 | AB14: 0.56 | AC14: =IF(B14="","",IF(D14="TAPADA",(AA14+AB14)/2,0)) -> 0.56 | AD14: =IF(B14="","",IF(D14="TAPADA",IFERROR(IF($X$1="ENTERO (redondeo arriba)",ROUNDUP(G14/Z14,0)+1,G14/Z14+1),0),0)) -> 41.8 | AE14: =IF(B14="","",IF(D14="TAPADA",AC14*AD14,0)) -> 23.408 | AF14: =IF(B14="","",IF(D14="TAPADA",AE14*Y14,0)) -> 13.10848 | AG14: =IF(B14="","",W14+AF14) -> 102.43744
A15: 5 | B15: EJE 02 | C15: TRAMO 03 | D15: ABIERTA | E15: SEC 08 | F15: SEC 09 | G15: 31.33 | H15: 3/8" | I15: =IF(H15="","",IFERROR(VLOOKUP(H15,Listas!$A$4:$B$11,2,FALSE()),"")) -> 0.56 | J15: 0.2 | K15: 9 | L15: 9 | M15: =IF(B15="","",(K15+L15)/2) -> 9 | N15: =IF(B15="","",G15*M15) -> 281.97 | O15: =IF(B15="","",N15*I15) -> 157.9032 | P15: 0.25 | Q15: 1.66 | R15: 2.02 | S15: =IF(B15="","",(Q15+R15)/2) -> 1.84 | T15: =IF(B15="","",IFERROR(IF($X$1="ENTERO (redondeo arriba)",ROUNDUP(G15/P15,0)+1,G15/P15+1),0)) -> 126.32 | U15: =IF(B15="","",S15*T15) -> 232.4288 | V15: =IF(B15="","",U15*I15) -> 130.16013 | W15: =IF(B15="","",O15+V15) -> 288.06333 | AC15: =IF(B15="","",IF(D15="TAPADA",(AA15+AB15)/2,0)) -> 0 | AD15: =IF(B15="","",IF(D15="TAPADA",IFERROR(IF($X$1="ENTERO (redondeo arriba)",ROUNDUP(G15/Z15,0)+1,G15/Z15+1),0),0)) -> 0 | AE15: =IF(B15="","",IF(D15="TAPADA",AC15*AD15,0)) -> 0 | AF15: =IF(B15="","",IF(D15="TAPADA",AE15*Y15,0)) -> 0 | AG15: =IF(B15="","",W15+AF15) -> 288.06333
A16: 6 | B16: EJE 02 | C16: TRAMO 04 | D16: TAPADA | E16: SEC 09 | F16: SEC 10 | G16: 8.36 | H16: 3/8" | I16: =IF(H16="","",IFERROR(VLOOKUP(H16,Listas!$A$4:$B$11,2,FALSE()),"")) -> 0.56 | J16: 0.23 | K16: 10 | L16: 10 | M16: =IF(B16="","",(K16+L16)/2) -> 10 | N16: =IF(B16="","",G16*M16) -> 83.6 | O16: =IF(B16="","",N16*I16) -> 46.816 | P16: 0.25 | Q16: 2.02 | R16: 2.08 | S16: =IF(B16="","",(Q16+R16)/2) -> 2.05 | T16: =IF(B16="","",IFERROR(IF($X$1="ENTERO (redondeo arriba)",ROUNDUP(G16/P16,0)+1,G16/P16+1),0)) -> 34.44 | U16: =IF(B16="","",S16*T16) -> 70.602 | V16: =IF(B16="","",U16*I16) -> 39.53712 | W16: =IF(B16="","",O16+V16) -> 86.35312 | X16: 3/8" | Y16: 0.56 | Z16: 0.25 | AA16: 0.56 | AB16: 0.56 | AC16: =IF(B16="","",IF(D16="TAPADA",(AA16+AB16)/2,0)) -> 0.56 | AD16: =IF(B16="","",IF(D16="TAPADA",IFERROR(IF($X$1="ENTERO (redondeo arriba)",ROUNDUP(G16/Z16,0)+1,G16/Z16+1),0),0)) -> 34.44 | AE16: =IF(B16="","",IF(D16="TAPADA",AC16*AD16,0)) -> 19.2864 | AF16: =IF(B16="","",IF(D16="TAPADA",AE16*Y16,0)) -> 10.800384 | AG16: =IF(B16="","",W16+AF16) -> 97.153504
A17: 7 | B17: EJE 02 | C17: TRAMO 05 | D17: ABIERTA | E17: SEC 10 | F17: SEC 11 | G17: 30.36 | H17: 3/8" | I17: =IF(H17="","",IFERROR(VLOOKUP(H17,Listas!$A$4:$B$11,2,FALSE()),"")) -> 0.56 | J17: 0.22 | K17: 9 | L17: 11 | M17: =IF(B17="","",(K17+L17)/2) -> 10 | N17: =IF(B17="","",G17*M17) -> 303.6 | O17: =IF(B17="","",N17*I17) -> 170.016 | P17: 0.25 | Q17: 2.08 | R17: 2.36 | S17: =IF(B17="","",(Q17+R17)/2) -> 2.22 | T17: =IF(B17="","",IFERROR(IF($X$1="ENTERO (redondeo arriba)",ROUNDUP(G17/P17,0)+1,G17/P17+1),0)) -> 122.44 | U17: =IF(B17="","",S17*T17) -> 271.8168 | V17: =IF(B17="","",U17*I17) -> 152.21741 | W17: =IF(B17="","",O17+V17) -> 322.23341 | AC17: =IF(B17="","",IF(D17="TAPADA",(AA17+AB17)/2,0)) -> 0 | AD17: =IF(B17="","",IF(D17="TAPADA",IFERROR(IF($X$1="ENTERO (redondeo arriba)",ROUNDUP(G17/Z17,0)+1,G17/Z17+1),0),0)) -> 0 | AE17: =IF(B17="","",IF(D17="TAPADA",AC17*AD17,0)) -> 0 | AF17: =IF(B17="","",IF(D17="TAPADA",AE17*Y17,0)) -> 0 | AG17: =IF(B17="","",W17+AF17) -> 322.23341
A18: 8 | B18: EJE 02 | C18: TRAMO 06 | D18: TAPADA | E18: SEC 11 | F18: SEC 12 | G18: 2.25 | H18: 3/8" | I18: =IF(H18="","",IFERROR(VLOOKUP(H18,Listas!$A$4:$B$11,2,FALSE()),"")) -> 0.56 | J18: 0.22 | K18: 12 | L18: 12 | M18: =IF(B18="","",(K18+L18)/2) -> 12 | N18: =IF(B18="","",G18*M18) -> 27 | O18: =IF(B18="","",N18*I18) -> 15.12 | P18: 0.25 | Q18: 2.36 | R18: 2.42 | S18: =IF(B18="","",(Q18+R18)/2) -> 2.39 | T18: =IF(B18="","",IFERROR(IF($X$1="ENTERO (redondeo arriba)",ROUNDUP(G18/P18,0)+1,G18/P18+1),0)) -> 10 | U18: =IF(B18="","",S18*T18) -> 23.9 | V18: =IF(B18="","",U18*I18) -> 13.384 | W18: =IF(B18="","",O18+V18) -> 28.504 | X18: 3/8" | Y18: 0.56 | Z18: 0.25 | AA18: 0.56 | AB18: 0.56 | AC18: =IF(B18="","",IF(D18="TAPADA",(AA18+AB18)/2,0)) -> 0.56 | AD18: =IF(B18="","",IF(D18="TAPADA",IFERROR(IF($X$1="ENTERO (redondeo arriba)",ROUNDUP(G18/Z18,0)+1,G18/Z18+1),0),0)) -> 10 | AE18: =IF(B18="","",IF(D18="TAPADA",AC18*AD18,0)) -> 5.6 | AF18: =IF(B18="","",IF(D18="TAPADA",AE18*Y18,0)) -> 3.136 | AG18: =IF(B18="","",W18+AF18) -> 31.64
A19: 9 | B19: EJE 02 | C19: TRAMO 07 | D19: TAPADA | E19: SEC 13 | F19: SEC 14 | G19: 10.85 | H19: 3/8" | I19: =IF(H19="","",IFERROR(VLOOKUP(H19,Listas!$A$4:$B$11,2,FALSE()),"")) -> 0.56 | J19: 0.21 | K19: 12 | L19: 12 | M19: =IF(B19="","",(K19+L19)/2) -> 12 | N19: =IF(B19="","",G19*M19) -> 130.2 | O19: =IF(B19="","",N19*I19) -> 72.912 | P19: 0.25 | Q19: 2.32 | R19: 2.42 | S19: =IF(B19="","",(Q19+R19)/2) -> 2.37 | T19: =IF(B19="","",IFERROR(IF($X$1="ENTERO (redondeo arriba)",ROUNDUP(G19/P19,0)+1,G19/P19+1),0)) -> 44.4 | U19: =IF(B19="","",S19*T19) -> 105.228 | V19: =IF(B19="","",U19*I19) -> 58.92768 | W19: =IF(B19="","",O19+V19) -> 131.83968 | X19: 3/8" | Y19: 0.56 | Z19: 0.25 | AA19: 0.56 | AB19: 0.56 | AC19: =IF(B19="","",IF(D19="TAPADA",(AA19+AB19)/2,0)) -> 0.56 | AD19: =IF(B19="","",IF(D19="TAPADA",IFERROR(IF($X$1="ENTERO (redondeo arriba)",ROUNDUP(G19/Z19,0)+1,G19/Z19+1),0),0)) -> 44.4 | AE19: =IF(B19="","",IF(D19="TAPADA",AC19*AD19,0)) -> 24.864 | AF19: =IF(B19="","",IF(D19="TAPADA",AE19*Y19,0)) -> 13.92384 | AG19: =IF(B19="","",W19+AF19) -> 145.76352
A20: 10 | B20: EJE 05 | C20: TRAMO 01 | D20: ABIERTA | E20: SEC 20 | F20: SEC 21 | G20: 17.53 | H20: 3/8" | I20: =IF(H20="","",IFERROR(VLOOKUP(H20,Listas!$A$4:$B$11,2,FALSE()),"")) -> 0.56 | J20: 0.22 | K20: 7 | L20: 7 | M20: =IF(B20="","",(K20+L20)/2) -> 7 | N20: =IF(B20="","",G20*M20) -> 122.71 | O20: =IF(B20="","",N20*I20) -> 68.7176 | P20: 0.25 | Q20: 1.42 | R20: 1.58 | S20: =IF(B20="","",(Q20+R20)/2) -> 1.5 | T20: =IF(B20="","",IFERROR(IF($X$1="ENTERO (redondeo arriba)",ROUNDUP(G20/P20,0)+1,G20/P20+1),0)) -> 71.12 | U20: =IF(B20="","",S20*T20) -> 106.68 | V20: =IF(B20="","",U20*I20) -> 59.7408 | W20: =IF(B20="","",O20+V20) -> 128.4584 | AC20: =IF(B20="","",IF(D20="TAPADA",(AA20+AB20)/2,0)) -> 0 | AD20: =IF(B20="","",IF(D20="TAPADA",IFERROR(IF($X$1="ENTERO (redondeo arriba)",ROUNDUP(G20/Z20,0)+1,G20/Z20+1),0),0)) -> 0 | AE20: =IF(B20="","",IF(D20="TAPADA",AC20*AD20,0)) -> 0 | AF20: =IF(B20="","",IF(D20="TAPADA",AE20*Y20,0)) -> 0 | AG20: =IF(B20="","",W20+AF20) -> 128.4584
A21: 11 | B21: EJE 05 | C21: TRAMO 02 | D21: TAPADA | E21: SEC 21 | F21: SEC 22 | G21: 5.7 | H21: 3/8" | I21: =IF(H21="","",IFERROR(VLOOKUP(H21,Listas!$A$4:$B$11,2,FALSE()),"")) -> 0.56 | J21: 0.21 | K21: 8 | L21: 10 | M21: =IF(B21="","",(K21+L21)/2) -> 9 | N21: =IF(B21="","",G21*M21) -> 51.3 | O21: =IF(B21="","",N21*I21) -> 28.728 | P21: 0.25 | Q21: 1.58 | R21: 1.62 | S21: =IF(B21="","",(Q21+R21)/2) -> 1.6 | T21: =IF(B21="","",IFERROR(IF($X$1="ENTERO (redondeo arriba)",ROUNDUP(G21/P21,0)+1,G21/P21+1),0)) -> 23.8 | U21: =IF(B21="","",S21*T21) -> 38.08 | V21: =IF(B21="","",U21*I21) -> 21.3248 | W21: =IF(B21="","",O21+V21) -> 50.0528 | X21: 3/8" | Y21: 0.56 | Z21: 0.25 | AA21: 0.56 | AB21: 0.56 | AC21: =IF(B21="","",IF(D21="TAPADA",(AA21+AB21)/2,0)) -> 0.56 | AD21: =IF(B21="","",IF(D21="TAPADA",IFERROR(IF($X$1="ENTERO (redondeo arriba)",ROUNDUP(G21/Z21,0)+1,G21/Z21+1),0),0)) -> 23.8 | AE21: =IF(B21="","",IF(D21="TAPADA",AC21*AD21,0)) -> 13.328 | AF21: =IF(B21="","",IF(D21="TAPADA",AE21*Y21,0)) -> 7.46368 | AG21: =IF(B21="","",W21+AF21) -> 57.51648
A22: 12 | B22: EJE 06 | C22: TRAMO 01 | D22: ABIERTA | E22: SEC 24 | F22: SEC 25 | G22: 17.53 | H22: 3/8" | I22: =IF(H22="","",IFERROR(VLOOKUP(H22,Listas!$A$4:$B$11,2,FALSE()),"")) -> 0.56 | J22: 0.22 | K22: 7 | L22: 7 | M22: =IF(B22="","",(K22+L22)/2) -> 7 | N22: =IF(B22="","",G22*M22) -> 122.71 | O22: =IF(B22="","",N22*I22) -> 68.7176 | P22: 0.25 | Q22: 1.42 | R22: 1.58 | S22: =IF(B22="","",(Q22+R22)/2) -> 1.5 | T22: =IF(B22="","",IFERROR(IF($X$1="ENTERO (redondeo arriba)",ROUNDUP(G22/P22,0)+1,G22/P22+1),0)) -> 71.12 | U22: =IF(B22="","",S22*T22) -> 106.68 | V22: =IF(B22="","",U22*I22) -> 59.7408 | W22: =IF(B22="","",O22+V22) -> 128.4584 | AC22: =IF(B22="","",IF(D22="TAPADA",(AA22+AB22)/2,0)) -> 0 | AD22: =IF(B22="","",IF(D22="TAPADA",IFERROR(IF($X$1="ENTERO (redondeo arriba)",ROUNDUP(G22/Z22,0)+1,G22/Z22+1),0),0)) -> 0 | AE22: =IF(B22="","",IF(D22="TAPADA",AC22*AD22,0)) -> 0 | AF22: =IF(B22="","",IF(D22="TAPADA",AE22*Y22,0)) -> 0 | AG22: =IF(B22="","",W22+AF22) -> 128.4584
A23: 13 | B23: EJE 06 | C23: TRAMO 02 | D23: TAPADA | E23: SEC 25 | F23: SEC 26 | G23: 10.9 | H23: 3/8" | I23: =IF(H23="","",IFERROR(VLOOKUP(H23,Listas!$A$4:$B$11,2,FALSE()),"")) -> 0.56 | J23: 0.22 | K23: 8 | L23: 10 | M23: =IF(B23="","",(K23+L23)/2) -> 9 | N23: =IF(B23="","",G23*M23) -> 98.1 | O23: =IF(B23="","",N23*I23) -> 54.936 | P23: 0.25 | Q23: 1.58 | R23: 1.7 | S23: =IF(B23="","",(Q23+R23)/2) -> 1.64 | T23: =IF(B23="","",IFERROR(IF($X$1="ENTERO (redondeo arriba)",ROUNDUP(G23/P23,0)+1,G23/P23+1),0)) -> 44.6 | U23: =IF(B23="","",S23*T23) -> 73.144 | V23: =IF(B23="","",U23*I23) -> 40.96064 | W23: =IF(B23="","",O23+V23) -> 95.89664 | X23: 3/8" | Y23: 0.56 | Z23: 0.25 | AA23: 0.56 | AB23: 0.56 | AC23: =IF(B23="","",IF(D23="TAPADA",(AA23+AB23)/2,0)) -> 0.56 | AD23: =IF(B23="","",IF(D23="TAPADA",IFERROR(IF($X$1="ENTERO (redondeo arriba)",ROUNDUP(G23/Z23,0)+1,G23/Z23+1),0),0)) -> 44.6 | AE23: =IF(B23="","",IF(D23="TAPADA",AC23*AD23,0)) -> 24.976 | AF23: =IF(B23="","",IF(D23="TAPADA",AE23*Y23,0)) -> 13.98656 | AG23: =IF(B23="","",W23+AF23) -> 109.8832
A24: 14 | B24: EJE 06 | C24: TRAMO 03 | D24: ABIERTA | E24: SEC 26 | F24: SEC 27 | G24: 56.93 | H24: 3/8" | I24: =IF(H24="","",IFERROR(VLOOKUP(H24,Listas!$A$4:$B$11,2,FALSE()),"")) -> 0.56 | J24: 0.2 | K24: 9 | L24: 11 | M24: =IF(B24="","",(K24+L24)/2) -> 10 | N24: =IF(B24="","",G24*M24) -> 569.3 | O24: =IF(B24="","",N24*I24) -> 318.808 | P24: 0.25 | Q24: 1.7 | R24: 2.26 | S24: =IF(B24="","",(Q24+R24)/2) -> 1.98 | T24: =IF(B24="","",IFERROR(IF($X$1="ENTERO (redondeo arriba)",ROUNDUP(G24/P24,0)+1,G24/P24+1),0)) -> 228.72 | U24: =IF(B24="","",S24*T24) -> 452.8656 | V24: =IF(B24="","",U24*I24) -> 253.60474 | W24: =IF(B24="","",O24+V24) -> 572.41274 | AC24: =IF(B24="","",IF(D24="TAPADA",(AA24+AB24)/2,0)) -> 0 | AD24: =IF(B24="","",IF(D24="TAPADA",IFERROR(IF($X$1="ENTERO (redondeo arriba)",ROUNDUP(G24/Z24,0)+1,G24/Z24+1),0),0)) -> 0 | AE24: =IF(B24="","",IF(D24="TAPADA",AC24*AD24,0)) -> 0 | AF24: =IF(B24="","",IF(D24="TAPADA",AE24*Y24,0)) -> 0 | AG24: =IF(B24="","",W24+AF24) -> 572.41274
A25: 15 | B25: EJE 06 | C25: TRAMO 04 | D25: TAPADA | E25: SEC 27 | F25: SEC 28 | G25: 15 | H25: 3/8" | I25: =IF(H25="","",IFERROR(VLOOKUP(H25,Listas!$A$4:$B$11,2,FALSE()),"")) -> 0.56 | J25: 0.21 | K25: 12 | L25: 12 | M25: =IF(B25="","",(K25+L25)/2) -> 12 | N25: =IF(B25="","",G25*M25) -> 180 | O25: =IF(B25="","",N25*I25) -> 100.8 | P25: 0.25 | Q25: 2.26 | R25: 2.42 | S25: =IF(B25="","",(Q25+R25)/2) -> 2.34 | T25: =IF(B25="","",IFERROR(IF($X$1="ENTERO (redondeo arriba)",ROUNDUP(G25/P25,0)+1,G25/P25+1),0)) -> 61 | U25: =IF(B25="","",S25*T25) -> 142.74 | V25: =IF(B25="","",U25*I25) -> 79.9344 | W25: =IF(B25="","",O25+V25) -> 180.7344 | X25: 3/8" | Y25: 0.56 | Z25: 0.25 | AA25: 0.56 | AB25: 0.56 | AC25: =IF(B25="","",IF(D25="TAPADA",(AA25+AB25)/2,0)) -> 0.56 | AD25: =IF(B25="","",IF(D25="TAPADA",IFERROR(IF($X$1="ENTERO (redondeo arriba)",ROUNDUP(G25/Z25,0)+1,G25/Z25+1),0),0)) -> 61 | AE25: =IF(B25="","",IF(D25="TAPADA",AC25*AD25,0)) -> 34.16 | AF25: =IF(B25="","",IF(D25="TAPADA",AE25*Y25,0)) -> 19.1296 | AG25: =IF(B25="","",W25+AF25) -> 199.864
A26: 16 | B26: EJE 07 | C26: TRAMO 01 | D26: ABIERTA | E26: SEC 30 | F26: SEC 31 | G26: 17.53 | H26: 3/8" | I26: =IF(H26="","",IFERROR(VLOOKUP(H26,Listas!$A$4:$B$11,2,FALSE()),"")) -> 0.56 | J26: 0.22 | K26: 7 | L26: 7 | M26: =IF(B26="","",(K26+L26)/2) -> 7 | N26: =IF(B26="","",G26*M26) -> 122.71 | O26: =IF(B26="","",N26*I26) -> 68.7176 | P26: 0.25 | Q26: 1.42 | R26: 1.58 | S26: =IF(B26="","",(Q26+R26)/2) -> 1.5 | T26: =IF(B26="","",IFERROR(IF($X$1="ENTERO (redondeo arriba)",ROUNDUP(G26/P26,0)+1,G26/P26+1),0)) -> 71.12 | U26: =IF(B26="","",S26*T26) -> 106.68 | V26: =IF(B26="","",U26*I26) -> 59.7408 | W26: =IF(B26="","",O26+V26) -> 128.4584 | AC26: =IF(B26="","",IF(D26="TAPADA",(AA26+AB26)/2,0)) -> 0 | AD26: =IF(B26="","",IF(D26="TAPADA",IFERROR(IF($X$1="ENTERO (redondeo arriba)",ROUNDUP(G26/Z26,0)+1,G26/Z26+1),0),0)) -> 0 | AE26: =IF(B26="","",IF(D26="TAPADA",AC26*AD26,0)) -> 0 | AF26: =IF(B26="","",IF(D26="TAPADA",AE26*Y26,0)) -> 0 | AG26: =IF(B26="","",W26+AF26) -> 128.4584
A27: 17 | B27: EJE 07 | C27: TRAMO 02 | D27: TAPADA | E27: SEC 31 | F27: SEC 32 | G27: 7.66 | H27: 3/8" | I27: =IF(H27="","",IFERROR(VLOOKUP(H27,Listas!$A$4:$B$11,2,FALSE()),"")) -> 0.56 | J27: 0.22 | K27: 8 | L27: 10 | M27: =IF(B27="","",(K27+L27)/2) -> 9 | N27: =IF(B27="","",G27*M27) -> 68.94 | O27: =IF(B27="","",N27*I27) -> 38.6064 | P27: 0.25 | Q27: 1.58 | R27: 1.66 | S27: =IF(B27="","",(Q27+R27)/2) -> 1.62 | T27: =IF(B27="","",IFERROR(IF($X$1="ENTERO (redondeo arriba)",ROUNDUP(G27/P27,0)+1,G27/P27+1),0)) -> 31.64 | U27: =IF(B27="","",S27*T27) -> 51.2568 | V27: =IF(B27="","",U27*I27) -> 28.703808 | W27: =IF(B27="","",O27+V27) -> 67.310208 | X27: 3/8" | Y27: 0.56 | Z27: 0.25 | AA27: 0.56 | AB27: 0.56 | AC27: =IF(B27="","",IF(D27="TAPADA",(AA27+AB27)/2,0)) -> 0.56 | AD27: =IF(B27="","",IF(D27="TAPADA",IFERROR(IF($X$1="ENTERO (redondeo arriba)",ROUNDUP(G27/Z27,0)+1,G27/Z27+1),0),0)) -> 31.64 | AE27: =IF(B27="","",IF(D27="TAPADA",AC27*AD27,0)) -> 17.7184 | AF27: =IF(B27="","",IF(D27="TAPADA",AE27*Y27,0)) -> 9.922304 | AG27: =IF(B27="","",W27+AF27) -> 77.232512
A28: 18 | B28: EJE 07 | C28: TRAMO 03 | D28: ABIERTA | E28: SEC 32 | F28: SEC 33 | G28: 63.75 | H28: 3/8" | I28: =IF(H28="","",IFERROR(VLOOKUP(H28,Listas!$A$4:$B$11,2,FALSE()),"")) -> 0.56 | J28: 0.19 | K28: 9 | L28: 11 | M28: =IF(B28="","",(K28+L28)/2) -> 10 | N28: =IF(B28="","",G28*M28) -> 637.5 | O28: =IF(B28="","",N28*I28) -> 357 | P28: 0.25 | Q28: 1.66 | R28: 2.32 | S28: =IF(B28="","",(Q28+R28)/2) -> 1.99 | T28: =IF(B28="","",IFERROR(IF($X$1="ENTERO (redondeo arriba)",ROUNDUP(G28/P28,0)+1,G28/P28+1),0)) -> 256 | U28: =IF(B28="","",S28*T28) -> 509.44 | V28: =IF(B28="","",U28*I28) -> 285.2864 | W28: =IF(B28="","",O28+V28) -> 642.2864 | AC28: =IF(B28="","",IF(D28="TAPADA",(AA28+AB28)/2,0)) -> 0 | AD28: =IF(B28="","",IF(D28="TAPADA",IFERROR(IF($X$1="ENTERO (redondeo arriba)",ROUNDUP(G28/Z28,0)+1,G28/Z28+1),0),0)) -> 0 | AE28: =IF(B28="","",IF(D28="TAPADA",AC28*AD28,0)) -> 0 | AF28: =IF(B28="","",IF(D28="TAPADA",AE28*Y28,0)) -> 0 | AG28: =IF(B28="","",W28+AF28) -> 642.2864
A29: 19 | B29: EJE 07 | C29: TRAMO 04 | D29: TAPADA | E29: SEC 33 | F29: SEC 34 | G29: 11.47 | H29: 3/8" | I29: =IF(H29="","",IFERROR(VLOOKUP(H29,Listas!$A$4:$B$11,2,FALSE()),"")) -> 0.56 | J29: 0.21 | K29: 12 | L29: 12 | M29: =IF(B29="","",(K29+L29)/2) -> 12 | N29: =IF(B29="","",G29*M29) -> 137.64 | O29: =IF(B29="","",N29*I29) -> 77.0784 | P29: 0.25 | Q29: 2.32 | R29: 2.42 | S29: =IF(B29="","",(Q29+R29)/2) -> 2.37 | T29: =IF(B29="","",IFERROR(IF($X$1="ENTERO (redondeo arriba)",ROUNDUP(G29/P29,0)+1,G29/P29+1),0)) -> 46.88 | U29: =IF(B29="","",S29*T29) -> 111.1056 | V29: =IF(B29="","",U29*I29) -> 62.219136 | W29: =IF(B29="","",O29+V29) -> 139.29754 | X29: 3/8" | Y29: 0.56 | Z29: 0.25 | AA29: 0.56 | AB29: 0.56 | AC29: =IF(B29="","",IF(D29="TAPADA",(AA29+AB29)/2,0)) -> 0.56 | AD29: =IF(B29="","",IF(D29="TAPADA",IFERROR(IF($X$1="ENTERO (redondeo arriba)",ROUNDUP(G29/Z29,0)+1,G29/Z29+1),0),0)) -> 46.88 | AE29: =IF(B29="","",IF(D29="TAPADA",AC29*AD29,0)) -> 26.2528 | AF29: =IF(B29="","",IF(D29="TAPADA",AE29*Y29,0)) -> 14.701568 | AG29: =IF(B29="","",W29+AF29) -> 153.9991
A30: 20 | B30: EJE 07 | C30: TRAMO 05 | D30: TAPADA | E30: SEC 35 | F30: SEC 36 | G30: 5.17 | H30: 3/8" | I30: =IF(H30="","",IFERROR(VLOOKUP(H30,Listas!$A$4:$B$11,2,FALSE()),"")) -> 0.56 | J30: 0.21 | K30: 12 | L30: 12 | M30: =IF(B30="","",(K30+L30)/2) -> 12 | N30: =IF(B30="","",G30*M30) -> 62.04 | O30: =IF(B30="","",N30*I30) -> 34.7424 | P30: 0.25 | Q30: 2.32 | R30: 2.36 | S30: =IF(B30="","",(Q30+R30)/2) -> 2.34 | T30: =IF(B30="","",IFERROR(IF($X$1="ENTERO (redondeo arriba)",ROUNDUP(G30/P30,0)+1,G30/P30+1),0)) -> 21.68 | U30: =IF(B30="","",S30*T30) -> 50.7312 | V30: =IF(B30="","",U30*I30) -> 28.409472 | W30: =IF(B30="","",O30+V30) -> 63.151872 | X30: 3/8" | Y30: 0.56 | Z30: 0.25 | AA30: 0.56 | AB30: 0.56 | AC30: =IF(B30="","",IF(D30="TAPADA",(AA30+AB30)/2,0)) -> 0.56 | AD30: =IF(B30="","",IF(D30="TAPADA",IFERROR(IF($X$1="ENTERO (redondeo arriba)",ROUNDUP(G30/Z30,0)+1,G30/Z30+1),0),0)) -> 21.68 | AE30: =IF(B30="","",IF(D30="TAPADA",AC30*AD30,0)) -> 12.1408 | AF30: =IF(B30="","",IF(D30="TAPADA",AE30*Y30,0)) -> 6.798848 | AG30: =IF(B30="","",W30+AF30) -> 69.95072
A31: 21 | B31: EJE 08 | C31: TRAMO 01 | D31: TAPADA | E31: SEC 37 | F31: SEC 38 | G31: 8.2 | H31: 3/8" | I31: =IF(H31="","",IFERROR(VLOOKUP(H31,Listas!$A$4:$B$11,2,FALSE()),"")) -> 0.56 | J31: 0.21 | K31: 8 | L31: 8 | M31: =IF(B31="","",(K31+L31)/2) -> 8 | N31: =IF(B31="","",G31*M31) -> 65.6 | O31: =IF(B31="","",N31*I31) -> 36.736 | P31: 0.25 | Q31: 1.42 | R31: 1.48 | S31: =IF(B31="","",(Q31+R31)/2) -> 1.45 | T31: =IF(B31="","",IFERROR(IF($X$1="ENTERO (redondeo arriba)",ROUNDUP(G31/P31,0)+1,G31/P31+1),0)) -> 33.8 | U31: =IF(B31="","",S31*T31) -> 49.01 | V31: =IF(B31="","",U31*I31) -> 27.4456 | W31: =IF(B31="","",O31+V31) -> 64.1816 | X31: 3/8" | Y31: 0.56 | Z31: 0.25 | AA31: 0.56 | AB31: 0.56 | AC31: =IF(B31="","",IF(D31="TAPADA",(AA31+AB31)/2,0)) -> 0.56 | AD31: =IF(B31="","",IF(D31="TAPADA",IFERROR(IF($X$1="ENTERO (redondeo arriba)",ROUNDUP(G31/Z31,0)+1,G31/Z31+1),0),0)) -> 33.8 | AE31: =IF(B31="","",IF(D31="TAPADA",AC31*AD31,0)) -> 18.928 | AF31: =IF(B31="","",IF(D31="TAPADA",AE31*Y31,0)) -> 10.59968 | AG31: =IF(B31="","",W31+AF31) -> 74.78128
A32: 22 | B32: EJE 09 | C32: TRAMO 01 | D32: TAPADA | E32: SEC 39 | F32: SEC 40 | G32: 7 | H32: 3/8" | I32: =IF(H32="","",IFERROR(VLOOKUP(H32,Listas!$A$4:$B$11,2,FALSE()),"")) -> 0.56 | J32: 0.21 | K32: 8 | L32: 8 | M32: =IF(B32="","",(K32+L32)/2) -> 8 | N32: =IF(B32="","",G32*M32) -> 56 | O32: =IF(B32="","",N32*I32) -> 31.36 | P32: 0.25 | Q32: 1.42 | R32: 1.48 | S32: =IF(B32="","",(Q32+R32)/2) -> 1.45 | T32: =IF(B32="","",IFERROR(IF($X$1="ENTERO (redondeo arriba)",ROUNDUP(G32/P32,0)+1,G32/P32+1),0)) -> 29 | U32: =IF(B32="","",S32*T32) -> 42.05 | V32: =IF(B32="","",U32*I32) -> 23.548 | W32: =IF(B32="","",O32+V32) -> 54.908 | X32: 3/8" | Y32: 0.56 | Z32: 0.25 | AA32: 0.56 | AB32: 0.56 | AC32: =IF(B32="","",IF(D32="TAPADA",(AA32+AB32)/2,0)) -> 0.56 | AD32: =IF(B32="","",IF(D32="TAPADA",IFERROR(IF($X$1="ENTERO (redondeo arriba)",ROUNDUP(G32/Z32,0)+1,G32/Z32+1),0),0)) -> 29 | AE32: =IF(B32="","",IF(D32="TAPADA",AC32*AD32,0)) -> 16.24 | AF32: =IF(B32="","",IF(D32="TAPADA",AE32*Y32,0)) -> 9.0944 | AG32: =IF(B32="","",W32+AF32) -> 64.0024
A33: 23 | B33: EJE 11 | C33: TRAMO 01 | D33: ABIERTA | E33: SEC 44 | F33: SEC 45 | G33: 42.76 | H33: 3/8" | I33: =IF(H33="","",IFERROR(VLOOKUP(H33,Listas!$A$4:$B$11,2,FALSE()),"")) -> 0.56 | J33: 0.2 | K33: 7 | L33: 9 | M33: =IF(B33="","",(K33+L33)/2) -> 8 | N33: =IF(B33="","",G33*M33) -> 342.08 | O33: =IF(B33="","",N33*I33) -> 191.5648 | P33: 0.25 | Q33: 1.42 | R33: 1.82 | S33: =IF(B33="","",(Q33+R33)/2) -> 1.62 | T33: =IF(B33="","",IFERROR(IF($X$1="ENTERO (redondeo arriba)",ROUNDUP(G33/P33,0)+1,G33/P33+1),0)) -> 172.04 | U33: =IF(B33="","",S33*T33) -> 278.7048 | V33: =IF(B33="","",U33*I33) -> 156.07469 | W33: =IF(B33="","",O33+V33) -> 347.63949 | AC33: =IF(B33="","",IF(D33="TAPADA",(AA33+AB33)/2,0)) -> 0 | AD33: =IF(B33="","",IF(D33="TAPADA",IFERROR(IF($X$1="ENTERO (redondeo arriba)",ROUNDUP(G33/Z33,0)+1,G33/Z33+1),0),0)) -> 0 | AE33: =IF(B33="","",IF(D33="TAPADA",AC33*AD33,0)) -> 0 | AF33: =IF(B33="","",IF(D33="TAPADA",AE33*Y33,0)) -> 0 | AG33: =IF(B33="","",W33+AF33) -> 347.63949
A34: 24 | B34: EJE 11 | C34: TRAMO 02 | D34: TAPADA | E34: SEC 45 | F34: SEC 46 | G34: 2.2 | H34: 3/8" | I34: =IF(H34="","",IFERROR(VLOOKUP(H34,Listas!$A$4:$B$11,2,FALSE()),"")) -> 0.56 | J34: 0.2 | K34: 10 | L34: 10 | M34: =IF(B34="","",(K34+L34)/2) -> 10 | N34: =IF(B34="","",G34*M34) -> 22 | O34: =IF(B34="","",N34*I34) -> 12.32 | P34: 0.25 | Q34: 1.82 | R34: 1.84 | S34: =IF(B34="","",(Q34+R34)/2) -> 1.83 | T34: =IF(B34="","",IFERROR(IF($X$1="ENTERO (redondeo arriba)",ROUNDUP(G34/P34,0)+1,G34/P34+1),0)) -> 9.8 | U34: =IF(B34="","",S34*T34) -> 17.934 | V34: =IF(B34="","",U34*I34) -> 10.04304 | W34: =IF(B34="","",O34+V34) -> 22.36304 | X34: 3/8" | Y34: 0.56 | Z34: 0.25 | AA34: 0.56 | AB34: 0.56 | AC34: =IF(B34="","",IF(D34="TAPADA",(AA34+AB34)/2,0)) -> 0.56 | AD34: =IF(B34="","",IF(D34="TAPADA",IFERROR(IF($X$1="ENTERO (redondeo arriba)",ROUNDUP(G34/Z34,0)+1,G34/Z34+1),0),0)) -> 9.8 | AE34: =IF(B34="","",IF(D34="TAPADA",AC34*AD34,0)) -> 5.488 | AF34: =IF(B34="","",IF(D34="TAPADA",AE34*Y34,0)) -> 3.07328 | AG34: =IF(B34="","",W34+AF34) -> 25.43632
A35: 25 | B35: EJE 11 | C35: TRAMO 03 | D35: TAPADA | E35: SEC 47 | F35: SEC 48 | G35: 6.5 | H35: 3/8" | I35: =IF(H35="","",IFERROR(VLOOKUP(H35,Listas!$A$4:$B$11,2,FALSE()),"")) -> 0.56 | J35: 0.21 | K35: 10 | L35: 10 | M35: =IF(B35="","",(K35+L35)/2) -> 10 | N35: =IF(B35="","",G35*M35) -> 65 | O35: =IF(B35="","",N35*I35) -> 36.4 | P35: 0.25 | Q35: 1.76 | R35: 1.82 | S35: =IF(B35="","",(Q35+R35)/2) -> 1.79 | T35: =IF(B35="","",IFERROR(IF($X$1="ENTERO (redondeo arriba)",ROUNDUP(G35/P35,0)+1,G35/P35+1),0)) -> 27 | U35: =IF(B35="","",S35*T35) -> 48.33 | V35: =IF(B35="","",U35*I35) -> 27.0648 | W35: =IF(B35="","",O35+V35) -> 63.4648 | X35: 3/8" | Y35: 0.56 | Z35: 0.25 | AA35: 0.56 | AB35: 0.56 | AC35: =IF(B35="","",IF(D35="TAPADA",(AA35+AB35)/2,0)) -> 0.56 | AD35: =IF(B35="","",IF(D35="TAPADA",IFERROR(IF($X$1="ENTERO (redondeo arriba)",ROUNDUP(G35/Z35,0)+1,G35/Z35+1),0),0)) -> 27 | AE35: =IF(B35="","",IF(D35="TAPADA",AC35*AD35,0)) -> 15.12 | AF35: =IF(B35="","",IF(D35="TAPADA",AE35*Y35,0)) -> 8.4672 | AG35: =IF(B35="","",W35+AF35) -> 71.932
A36: 26 | B36: EJE 12 | C36: TRAMO 01 | D36: ABIERTA | E36: SEC 50 | F36: SEC 51 | G36: 32.48 | H36: 3/8" | I36: =IF(H36="","",IFERROR(VLOOKUP(H36,Listas!$A$4:$B$11,2,FALSE()),"")) -> 0.56 | J36: 0.2 | K36: 7 | L36: 1.76 | M36: =IF(B36="","",(K36+L36)/2) -> 4.38 | N36: =IF(B36="","",G36*M36) -> 142.2624 | O36: =IF(B36="","",N36*I36) -> 79.666944 | P36: 0.25 | Q36: 1.42 | R36: 1.76 | S36: =IF(B36="","",(Q36+R36)/2) -> 1.59 | T36: =IF(B36="","",IFERROR(IF($X$1="ENTERO (redondeo arriba)",ROUNDUP(G36/P36,0)+1,G36/P36+1),0)) -> 130.92 | U36: =IF(B36="","",S36*T36) -> 208.1628 | V36: =IF(B36="","",U36*I36) -> 116.57117 | W36: =IF(B36="","",O36+V36) -> 196.23811 | AC36: =IF(B36="","",IF(D36="TAPADA",(AA36+AB36)/2,0)) -> 0 | AD36: =IF(B36="","",IF(D36="TAPADA",IFERROR(IF($X$1="ENTERO (redondeo arriba)",ROUNDUP(G36/Z36,0)+1,G36/Z36+1),0),0)) -> 0 | AE36: =IF(B36="","",IF(D36="TAPADA",AC36*AD36,0)) -> 0 | AF36: =IF(B36="","",IF(D36="TAPADA",AE36*Y36,0)) -> 0 | AG36: =IF(B36="","",W36+AF36) -> 196.23811
