Workbook

Sheet RESUMEN
A2: RESUMEN METRADOS DE DRENAJE PLUVIAL
A4: ENTIDAD | B4: GERENCIA TERRITORIAL BAJO MAYO - TARAPOTO
A5: PROYECTO | B5: CREACIÓN DEL SERVICIO DE PROTECCIÓN INTEGRAL A NIÑAS, NIÑOS Y ADOLESCENTES SIN CUIDADOS PARENTALES O EN RIESGO DE PERDERLOS EN CENTRO DE ACOGIDA RESIDENCIAL - VARONES DISTRITO DE MORALES DE LA PROVINCIA DE SAN MARTÍN DEL DEPARTAMENTO DE SAN MARTÍN, con CUI N.° 2705619
A6: UBICACIÓN | B6: SAN MARTIN - SAN MARTIN - MORALES
A7: FECHA | B7: 46266
A8: Item | B8: Descripción | C8: Unid. | D8: Total.
A9: 01.04.03 | B9: SISTEMA DE DRENAJE PLUVIAL
A10: 01.04.03.01 | B10: TRABAJOS PRELIMINARES
A11: 01.04.03.01.01 | B11: LIMPIEZA MANUAL DE TERRENO | C11: m² | D11: =+'PLANILLA GENERAL DE METRADOS'!K11 -> 753.536
A12: 01.04.03.01.02 | B12: TRAZO, NIVELES Y REPLANTEO PRELIMINAR | C12: m² | D12: =+'PLANILLA GENERAL DE METRADOS'!K21 -> 753.536
A13: 01.04.03.02 | B13: MOVIMIENTO DE TIERRAS
A14: 01.04.03.02.01 | B14: EXCAVACIÓN MANUAL DE ZANJAS P/CUNETAS | C14: m³ | D14: =+'PLANILLA GENERAL DE METRADOS'!K32 -> 513.90864
A15: 01.04.03.02.02 | B15: EXCAVACIÓN MANUAL DE ZANJAS P/DADOS DE CONCRETO | C15: m³ | D15: =+'PLANILLA GENERAL DE METRADOS'!K42 -> 3.136
A16: 01.04.03.02.03 | B16: REFINE, NIVELACIÓN Y COMPACTACIÓN EN TERRENO NORMAL | C16: m² | D16: =+'PLANILLA GENERAL DE METRADOS'!K45 -> 322.944
A17: 01.04.03.02.04 | B17: RELLENO COMPACTADO C/MATERIAL PROPIO SELECCIONADO | C17: m³ | D17: =+'PLANILLA GENERAL DE METRADOS'!K55 -> 293.66208
A18: 01.04.03.02.05 | B18: ELIMINACIÓN DE MATERIAL EXCEDENTE D<1Km | C18: m³ | D18: =+'PLANILLA GENERAL DE METRADOS'!K65 -> 264.29587
A19: 01.04.03.03 | B19: OBRAS DE CONCRETO SIMPLE
A20: 01.04.03.03.01 | B20: CONCRETO f'c=100 kg/cm2 PARA SOLADO E=4'' | C20: m² | D20: =+'PLANILLA GENERAL DE METRADOS'!K69 -> 322.944
A21: 01.04.03.03.02 | B21: CONCRETO f'c=140 Kg/cm2 PARA DADOS DE CONCRETO | C21: m³ | D21: =+'PLANILLA GENERAL DE METRADOS'!K79 -> 3.136
A22: 01.04.03.04 | B22: OBRAS DE CONCRETO ARMADO
A23: 01.04.03.04.02 | B23: CUNETAS
A24: 01.04.03.04.02.01 | B24: CONCRETO f'c=175 kg/cm2 PARA CUNETAS | C24: m³ | D24: =+'PLANILLA GENERAL DE METRADOS'!K83 -> 94.1398
A25: 01.04.03.04.02.02 | B25: ENCOFRADO Y DESENCOFRADO DE CUNETAS | C25: m² | D25: =+'PLANILLA GENERAL DE METRADOS'!K93 -> 1245.916
A26: 01.04.03.04.02.03 | B26: ACERO f'y=4200 kg/cm2 PARA CUNETA | C26: kg | D26: =+'PLANILLA GENERAL DE METRADOS'!K103 -> 3354.7297
A27: 01.04.03.04.02.04 | B27: CURADO DE CONCRETO EN CUNETA | C27: m² | D27: =+'METRADO DE CURADO'!M27 -> 801.5833
A28: 01.04.03.04.03 | B28: VARIOS
A29: 01.04.03.04.03.01 | B29: REJILLA METALICA P/CUNETA C/PL 1''x 3/16'' Y ANGULO 1'' x 1'' x 3/16'', S/DETALLE | C29: m | D29: =+'PLANILLA GENERAL DE METRADOS'!K108 -> 373.85
A30: 01.04.03.04.03.02 | B30: TAPA DE INSPECCION 0.60m x 0.60m | C30: und | D30: =+'PLANILLA GENERAL DE METRADOS'!K109 -> 18
A31: 01.04.03.04.03.03 | B31: JUNTA DE DILATACION E=1" CON SELLADOR ASFALTO | C31: m | D31: =+'PLANILLA GENERAL DE METRADOS'!K110 -> 252.28688
A32: 01.04.03.04.03.04 | B32: LLORADERO DE TUBERIA PVC Ø3" C/FILTRO DE GRAVA Y GEOTEXTIL @1.50 m (CUNETA COLINDANTE CON AREA VERDE) | C32: und | D32: =+'PLANILLA GENERAL DE METRADOS'!K111 -> 226
A33: 01.04.03.05 | B33: RED DE COLECCIÓN
A34: 01.04.03.05.01 | B34: RED DE RECOLECCION TECHO
A35: 01.04.03.05.01.01 | B35: MONTANTE CON TUBERÍA PVC DE 4" | C35: m | D35: =+'PLANILLA GENERAL DE METRADOS'!K115 -> 408.02
A36: 01.04.03.05.01.02 | B36: FALSA COLUMNA P/MONTANTE DE 0.20m x 0.15m x 1.30m | C36: und | D36: =+'PLANILLA GENERAL DE METRADOS'!K116 -> 56
A37: 01.04.03.05.01.02.01 | B37: CONCRETO F´C=175 KG/CM2 EN FALSA COLUMNA | C37: m³ | D37: =+'PLANILLA GENERAL DE METRADOS'!K117 -> 2.184
A38: 01.04.03.05.01.02.02 | B38: ENCOFRADO Y DESENCOFRADO EN FALSA COLUMNA - MONTANTE PLUVIAL | C38: m² | D38: =+'PLANILLA GENERAL DE METRADOS'!K119 -> 36.4
A39: 01.04.03.05.01.02.03 | B39: ACERO FY=4200 KG/CM2 EN FALSA COLUMNA (MONTANTE PLUVIAL) | C39: kg | D39: =+'PLANILLA GENERAL DE METRADOS'!K122 -> 314.2272
A40: 01.04.03.05.01.03 | B40: CANALETA DE PLANCHA DE ACERO GALVANIZADO e=0.9mm, SECCIÓN 0.25m x 0.20m | C40: m | D40: =+'PLANILLA GENERAL DE METRADOS'!K125 -> 523.16
A41: 01.04.03.05.01.04 | B41: SOPORTE DE PLATINA F°G° 1" x 1/8" P/CANALETA | C41: und | D41: =+'PLANILLA GENERAL DE METRADOS'!K126 -> 906
A42: 01.04.03.05.01.05 | B42: TAPA LATERAL DE PLANCHA GALVANIZADA P/CANALETA | C42: und | D42: =+'PLANILLA GENERAL DE METRADOS'!K127 -> 44
...

Sheet PLANILLA GENERAL DE METRADOS
A2: RESUMEN METRADOS DE DRENAJE PLUVIAL
A3: ENTIDAD | B3: =+RESUMEN!B4 -> GERENCIA TERRITORIAL BAJO MAYO - TARAPOTO
A4: PROYECTO | B4: =+RESUMEN!B5 -> CREACIÓN DEL SERVICIO DE PROTECCIÓN INTEGRAL A NIÑAS, NIÑOS Y ADOLESCENTES SIN CUIDADOS PARENTALES O EN RIESGO DE PERDERLOS EN CENTRO DE ACOGIDA RESIDENCIAL - VARONES DISTRITO DE MORALES DE LA PROVINCIA DE SAN MARTÍN DEL DEPARTAMENTO DE SAN MARTÍN, con CUI N.° 2705619
A5: UBICACIÓN | B5: =+RESUMEN!B6 -> SAN MARTIN - SAN MARTIN - MORALES
A6: FECHA | B6: =+RESUMEN!B7 -> 46266
A8: ITEM | B8: DESCRIPCION | C8: Nº DE VECES | D8: LARGO | E8: ANCHO | F8: ALTURA | G8: FACT. | H8: AREA | I8: VOLUMEN | J8: PARCIAL | K8: TOTAL | L8: UND
A9: 01.04.03 | B9: SISTEMA DE DRENAJE PLUVIAL
A10: 01.04.03.01 | B10: TRABAJOS PRELIMINARES
A11: 01.04.03.01.01 | B11: LIMPIEZA MANUAL DE TERRENO | K11: =SUM(J12:J20) -> 753.536 | L11: m²
B12: EJE 1 | C12: 1 | D12: 111.53 | E12: 1.4 | J12: =C12*D12*E12 -> 156.142
B13: EJE 2 | C13: 1 | D13: 34.25 | E13: 1.4 | J13: =C13*D13*E13 -> 47.95
B14: EJE 3 | C14: 1 | D14: 22.4 | E14: 1.4 | J14: =C14*D14*E14 -> 31.36
B15: EJE 4 | C15: 1 | D15: 102.31 | E15: 1.4 | J15: =C15*D15*E15 -> 143.234
B16: EJE 5 | C16: 1 | D16: 42.2 | E16: 1.4 | J16: =C16*D16*E16 -> 59.08
B17: EJE 6 | C17: 1 | D17: 98.69 | E17: 1.4 | J17: =C17*D17*E17 -> 138.166
B18: EJE 7 | C18: 1 | D18: 23.6 | E18: 1.4 | J18: =C18*D18*E18 -> 33.04
B19: EJE 8 | C19: 1 | D19: 60.6 | E19: 1.4 | J19: =C19*D19*E19 -> 84.84
B20: EJE 9 | C20: 1 | D20: 42.66 | E20: 1.4 | J20: =C20*D20*E20 -> 59.724
A21: 01.04.03.01.02 | B21: TRAZO, NIVELES Y REPLANTEO PRELIMINAR | K21: =SUM(J22:J30) -> 753.536 | L21: m²
B22: EJE 1 | C22: 1 | D22: 111.53 | E22: 1.4 | J22: =C22*D22*E22 -> 156.142
B23: EJE 2 | C23: 1 | D23: 34.25 | E23: 1.4 | J23: =C23*D23*E23 -> 47.95
B24: EJE 3 | C24: 1 | D24: 22.4 | E24: 1.4 | J24: =C24*D24*E24 -> 31.36
B25: EJE 4 | C25: 1 | D25: 102.31 | E25: 1.4 | J25: =C25*D25*E25 -> 143.234
B26: EJE 5 | C26: 1 | D26: 42.2 | E26: 1.4 | J26: =C26*D26*E26 -> 59.08
B27: EJE 6 | C27: 1 | D27: 98.69 | E27: 1.4 | J27: =C27*D27*E27 -> 138.166
B28: EJE 7 | C28: 1 | D28: 23.6 | E28: 1.4 | J28: =C28*D28*E28 -> 33.04
B29: EJE 8 | C29: 1 | D29: 60.6 | E29: 1.4 | J29: =C29*D29*E29 -> 84.84
B30: EJE 9 | C30: 1 | D30: 42.66 | E30: 1.4 | J30: =C30*D30*E30 -> 59.724
A31: 01.04.03.02 | B31: MOVIMIENTO DE TIERRAS
A32: 01.04.03.02.01 | B32: EXCAVACIÓN MANUAL DE ZANJAS P/CUNETAS | K32: =SUM(J33:J41) -> 513.90864 | L32: m³
B33: EJE 1 | C33: 1 | D33: 111.53 | E33: 1.4 | F33: 0.65 | J33: =C33*D33*E33*(F33+PARAMETROS!$B$15) -> 117.1065
B34: EJE 2 | C34: 1 | D34: 34.25 | E34: 1.4 | F34: 0.49 | J34: =C34*D34*E34*(F34+PARAMETROS!$B$15) -> 28.2905
B35: EJE 3 | C35: 1 | D35: 22.4 | E35: 1.4 | F35: 0.46 | J35: =C35*D35*E35*(F35+PARAMETROS!$B$15) -> 17.5616
B36: EJE 4 | C36: 1 | D36: 102.31 | E36: 1.4 | F36: 0.63 | J36: =C36*D36*E36*(F36+PARAMETROS!$B$15) -> 104.56082
B37: EJE 5 | C37: 1 | D37: 42.2 | E37: 1.4 | F37: 0.5 | J37: =C37*D37*E37*(F37+PARAMETROS!$B$15) -> 35.448
B38: EJE 6 | C38: 1 | D38: 98.69 | E38: 1.4 | F38: 0.63 | J38: =C38*D38*E38*(F38+PARAMETROS!$B$15) -> 100.86118
B39: EJE 7 | C39: 1 | D39: 23.6 | E39: 1.4 | F39: 0.46 | J39: =C39*D39*E39*(F39+PARAMETROS!$B$15) -> 18.5024
B40: EJE 8 | C40: 1 | D40: 60.6 | E40: 1.4 | F40: 0.55 | J40: =C40*D40*E40*(F40+PARAMETROS!$B$15) -> 55.146
B41: EJE 9 | C41: 1 | D41: 42.66 | E41: 1.4 | F41: 0.51 | J41: =C41*D41*E41*(F41+PARAMETROS!$B$15) -> 36.43164
A42: 01.04.03.02.02 | B42: EXCAVACIÓN MANUAL DE ZANJAS P/DADOS DE CONCRETO | C42: 56 | K42: =J43*C42 -> 3.136 | L42: m³
...

Sheet CONCRETO EN CUNETAS
B2: CONCRETO F´C=175 KG/CM2 PARA CUNETAS - DRENAJE PLUVIAL
B3: ENTIDAD | C3: =+RESUMEN!B4 -> GERENCIA TERRITORIAL BAJO MAYO - TARAPOTO
B4: PROYECTO | C4: =+RESUMEN!B5 -> CREACIÓN DEL SERVICIO DE PROTECCIÓN INTEGRAL A NIÑAS, NIÑOS Y ADOLESCENTES SIN CUIDADOS PARENTALES O EN RIESGO DE PERDERLOS EN CENTRO DE ACOGIDA RESIDENCIAL - VARONES DISTRITO DE MORALES DE LA PROVINCIA DE SAN MARTÍN DEL DEPARTAMENTO DE SAN MARTÍN, con CUI N.° 2705619
B5: UBICACIÓN | C5: =+RESUMEN!B6 -> SAN MARTIN - SAN MARTIN - MORALES
B6: FECHA | C6: =+RESUMEN!B7 -> 46266
B7: OBRAS DE CONCRETO ARMADO
B9: LONGITUDES Y AREAS | E9: m3 | F9: Sub.TOTAL | G9: TOTAL (m3) | J9: LONGITUDES Y AREAS | M9: m3 | N9: Sub.TOTAL | O9: TOTAL (m3)
B10: CUNETA EJE 01 | C10: MUROS | D10: AREA | E10: 61.2 | F10: =E10*E11*E12 -> 12.24 | G10: =SUM(F10:F18) -> 21.3456 | J10: CUNETA EJE 07 | K10: MUROS | L10: AREA | M10: 8.46 | N10: =M10*M11*M12 -> 1.692 | O10: =SUM(N10:N18) -> 3.108
D11: ESPESOR | E11: 0.1 | L11: ESPESOR | M11: 0.1
D12: CANT. | E12: 2 | L12: CANT. | M12: 2
C13: LOSA | D13: ESPESOR | E13: 0.1 | F13: =E13*E14*E15 -> 6.6918 | K13: LOSA | L13: ESPESOR | M13: 0.1 | N13: =M13*M14*M15 -> 1.416
D14: LONGITUD | E14: 111.53 | L14: LONGITUD | M14: 23.6
D15: ANCHO | E15: 0.6 | L15: ANCHO | M15: 0.6
C16: TAPA | D16: LONGITUD | E16: 40.23 | F16: =E16*E17*E18 -> 2.4138 | K16: TAPA | L16: LONGITUD | M16: 0 | N16: =M16*M17*M18 -> 0
D17: ESPESOR | E17: 0.1 | L17: ESPESOR | M17: 0.1
D18: ANCHO | E18: 0.6 | L18: ANCHO | M18: 0.6
B21: LONGITUDES Y AREAS | E21: m3 | F21: Sub.TOTAL | G21: TOTAL (m3) | J21: LONGITUDES Y AREAS | M21: m3 | N21: Sub.TOTAL | O21: TOTAL (m3)
B22: CUNETA EJE 02 | C22: MUROS | D22: AREA | E22: 13.19 | F22: =E22*E23*E24 -> 2.638 | G22: =SUM(F22:F30) -> 4.693 | J22: CUNETA EJE 08 | K22: MUROS | L22: AREA | M22: 27.34 | N22: =M22*M23*M24 -> 5.468 | O22: =SUM(N22:N30) -> 9.749
D23: ESPESOR | E23: 0.1 | L23: ESPESOR | M23: 0.1
D24: CANT. | E24: 2 | L24: CANT. | M24: 2
C25: LOSA | D25: ESPESOR | E25: 0.1 | F25: =E25*E26*E27 -> 2.055 | K25: LOSA | L25: ESPESOR | M25: 0.1 | N25: =M25*M26*M27 -> 3.636
D26: LONGITUD | E26: 34.25 | L26: LONGITUD | M26: 60.6
D27: ANCHO | E27: 0.6 | L27: ANCHO | M27: 0.6
C28: TAPA | D28: LONGITUD | E28: 0 | F28: =E28*E29*E30 -> 0 | K28: TAPA | L28: LONGITUD | M28: 10.75 | N28: =M28*M29*M30 -> 0.645
D29: ESPESOR | E29: 0.1 | L29: ESPESOR | M29: 0.1
D30: ANCHO | E30: 0.6 | L30: ANCHO | M30: 0.6
B33: LONGITUDES Y AREAS | E33: m3 | F33: Sub.TOTAL | G33: TOTAL (m3) | J33: LONGITUDES Y AREAS | M33: m3 | N33: Sub.TOTAL | O33: TOTAL (m3)
B34: CUNETA EJE 03 | C34: MUROS | D34: AREA | E34: 7.98 | F34: =E34*E35*E36 -> 1.596 | G34: =SUM(F34:F42) -> 2.94 | J34: CUNETA EJE 09 | K34: MUROS | L34: AREA | M34: 17.67 | N34: =M34*M35*M36 -> 3.534 | O34: =SUM(N34:N42) -> 6.4932
D35: ESPESOR | E35: 0.1 | L35: ESPESOR | M35: 0.1
D36: CANT. | E36: 2 | L36: CANT. | M36: 2
C37: LOSA | D37: ESPESOR | E37: 0.1 | F37: =E37*E38*E39 -> 1.344 | K37: LOSA | L37: ESPESOR | M37: 0.1 | N37: =M37*M38*M39 -> 2.5596
D38: LONGITUD | E38: 22.4 | L38: LONGITUD | M38: 42.66
D39: ANCHO | E39: 0.6 | L39: ANCHO | M39: 0.6
C40: TAPA | D40: LONGITUD | E40: 0 | F40: =E40*E41*E42 -> 0 | K40: TAPA | L40: LONGITUD | M40: 6.66 | N40: =M40*M41*M42 -> 0.3996
D41: ESPESOR | E41: 0.1 | L41: ESPESOR | M41: 0.1
D42: ANCHO | E42: 0.6 | L42: ANCHO | M42: 0.6
B45: LONGITUDES Y AREAS | E45: m3 | F45: Sub.TOTAL | G45: TOTAL (m3) | J45: LONGITUDES Y AREAS | M45: m3 | N45: Sub.TOTAL | O45: TOTAL (m3)
B46: CUNETA EJE 04 | C46: MUROS | D46: AREA | E46: 54.29 | F46: =E46*E47*E48 -> 10.858 | G46: =SUM(F46:F54) -> 18.8362 | K46: MUROS | L46: AREA | M46: 0 | N46: =M46*M47*M48 -> 0 | O46: =SUM(N46:N54) -> 0
D47: ESPESOR | E47: 0.1 | L47: ESPESOR | M47: 0.1
D48: CANT. | E48: 2 | L48: CANT. | M48: 2
...

Sheet ENCOFRADO Y DESENCOFRADO
B2: ENCOFRADO Y DESENCOFRADO CUNETAS - DRENAJE PLUVIAL
B3: ENTIDAD | C3: =+RESUMEN!B4 -> GERENCIA TERRITORIAL BAJO MAYO - TARAPOTO
B4: PROYECTO | C4: =+RESUMEN!B5 -> CREACIÓN DEL SERVICIO DE PROTECCIÓN INTEGRAL A NIÑAS, NIÑOS Y ADOLESCENTES SIN CUIDADOS PARENTALES O EN RIESGO DE PERDERLOS EN CENTRO DE ACOGIDA RESIDENCIAL - VARONES DISTRITO DE MORALES DE LA PROVINCIA DE SAN MARTÍN DEL DEPARTAMENTO DE SAN MARTÍN, con CUI N.° 2705619
B5: UBICACIÓN | C5: =+RESUMEN!B6 -> SAN MARTIN - SAN MARTIN - MORALES
B6: FECHA | C6: =+RESUMEN!B7 -> 46266
B8: OBRAS DE CONCRETO ARMADO - ENCOFRADO Y DESENCOFRADO CUNETAS
B11: LONGITUDES Y AREAS | G11: Sub.TOTAL | H11: TOTAL (m2) | J11: LONGITUDES Y AREAS | O11: Sub.TOTAL | P11: TOTAL (m2)
B12: EJE 1 | C12: ABIERTA | D12: MUROS EXTERNO | E12: AREA | F12: 42.85 | G12: =F12*F13 -> 85.7 | H12: =SUM(G12:G20) -> 291.252 | J12: EJE 2 | K12: ABIERTA | L12: MUROS EXTERNO | M12: AREA | N12: 16.62 | O12: =N12*N13 -> 33.24 | P12: =SUM(O12:O20) -> 59.62
E13: CANT. | F13: 2 | M13: CANT. | N13: 2
D14: MURO INTERNO | E14: AREA | F14: 35.72 | G14: =F14*F15 -> 71.44 | L14: MURO INTERNO | M14: AREA | N14: 13.19 | O14: =N14*N15 -> 26.38
E15: CANTIDAD | F15: 2 | M15: CANTIDAD | N15: 2
C16: TAPADO | D16: MURO EXTERNO | E16: AREA | F16: 33.53 | G16: =F16*F17 -> 67.06 | K16: TAPADO | L16: MURO EXTERNO | M16: AREA | N16: 0 | O16: =N16*N17 -> 0
E17: CANT. | F17: 2 | M17: CANT. | N17: 2
D18: MURO INTERNO | E18: AREA | F18: 25.48 | G18: =(F18*F19)+F20 -> 67.052 | L18: MURO INTERNO | M18: AREA | N18: 0 | O18: =N18*N19+N20 -> 0
E19: CANTIDAD | F19: 2 | M19: CANTIDAD | N19: 2
E20: TAPA | F20: =40.23*0.4 -> 16.092 | M20: TAPA | N20: 0
B22: LONGITUDES Y AREAS | G22: Sub.TOTAL | H22: TOTAL (m2) | J22: LONGITUDES Y AREAS | O22: Sub.TOTAL | P22: TOTAL (m2)
B23: EJE 3 | C23: ABIERTA | D23: MUROS EXTERNO | E23: AREA | F23: 10.22 | G23: =F23*F24 -> 20.44 | H23: =SUM(G23:G31) -> 36.4 | J23: EJE 4 | K23: ABIERTA | L23: MUROS EXTERNO | M23: AREA | N23: 42.88 | O23: =N23*N24 -> 85.76 | P23: =SUM(O23:O31) -> 256.004
E24: CANT. | F24: 2 | M24: CANT. | N24: 2
D25: MURO INTERNO | E25: AREA | F25: 7.98 | G25: =F25*F26 -> 15.96 | L25: MURO INTERNO | M25: AREA | N25: 35.72 | O25: =N25*N26 -> 71.44
E26: CANTIDAD | F26: 2 | M26: CANTIDAD | N26: 2
C27: TAPADO | D27: MURO EXTERNO | E27: AREA | F27: 0 | G27: =F27*F28 -> 0 | K27: TAPADO | L27: MURO EXTERNO | M27: AREA | N27: 24.7 | O27: =N27*N28 -> 49.4
E28: CANT. | F28: 2 | M28: CANT. | N28: 2
D29: MURO INTERNO | E29: AREA | F29: 0 | G29: =F29*F30+F31 -> 0 | L29: MURO INTERNO | M29: AREA | N29: 18.57 | O29: =N29*N30+N31 -> 49.404
E30: CANTIDAD | F30: 2 | M30: CANTIDAD | N30: 2
E31: TAPA | F31: 0 | M31: TAPA | N31: =30.66*0.4 -> 12.264
B33: LONGITUDES Y AREAS | G33: Sub.TOTAL | H33: TOTAL (m2) | J33: LONGITUDES Y AREAS | O33: Sub.TOTAL | P33: TOTAL (m2)
B34: EJE 5 | C34: ABIERTA | D34: MUROS EXTERNO | E34: AREA | F34: 15.51 | G34: =F34*F35 -> 31.02 | H34: =SUM(G34:G42) -> 82.66 | J34: EJE 6 | K34: ABIERTA | L34: MUROS EXTERNO | M34: AREA | N34: 15.61 | O34: =N34*N35 -> 31.22 | P34: =SUM(O34:O42) -> 270.296
E35: CANT. | F35: 2 | M35: CANT. | N35: 2
D36: MURO INTERNO | E36: AREA | F36: 12.28 | G36: =F36*F37 -> 24.56 | L36: MURO INTERNO | M36: AREA | N36: 12.36 | O36: =N36*N37 -> 24.72
E37: CANTIDAD | F37: 2 | M37: CANTIDAD | N37: 2
C38: TAPADO | D38: MURO EXTERNO | E38: AREA | F38: 6.77 | G38: =F38*F39 -> 13.54 | K38: TAPADO | L38: MURO EXTERNO | M38: AREA | N38: 53.59 | O38: =N38*N39 -> 107.18
E39: CANT. | F39: 2 | M39: CANT. | N39: 2
D40: MURO INTERNO | E40: AREA | F40: 4.79 | G40: =F40*F41+F42 -> 13.54 | L40: MURO INTERNO | M40: AREA | N40: 40.35 | O40: =N40*N41+N42 -> 107.176
E41: CANTIDAD | F41: 2 | M41: CANTIDAD | N41: 2
E42: TAPA | F42: =9.9*0.4 -> 3.96 | M42: TAPA | N42: =66.19*0.4 -> 26.476
B44: LONGITUDES Y AREAS | G44: Sub.TOTAL | H44: TOTAL (m2) | J44: LONGITUDES Y AREAS | O44: Sub.TOTAL | P44: TOTAL (m2)
B45: EJE 7 | C45: ABIERTA | D45: MUROS EXTERNO | E45: AREA | F45: 10.82 | G45: =F45*F46 -> 21.64 | H45: =SUM(G45:G53) -> 38.56 | J45: EJE 8 | K45: ABIERTA | L45: MUROS EXTERNO | M45: AREA | N45: 26.15 | O45: =N45*N46 -> 52.3 | P45: =SUM(O45:O53) -> 127.92
E46: CANT. | F46: 2 | M46: CANT. | N46: 2
D47: MURO INTERNO | E47: AREA | F47: 8.46 | G47: =F47*F48 -> 16.92 | L47: MURO INTERNO | M47: AREA | N47: 21.17 | O47: =N47*N48 -> 42.34
...

Sheet METRADO MONTANTES
B2: CALCULO DE MONTANTES POR EDIFICACION - DRENAJE PLUVIAL
B3: ENTIDAD | C3: =+RESUMEN!B4 -> GERENCIA TERRITORIAL BAJO MAYO - TARAPOTO
B4: PROYECTO | C4: =+RESUMEN!B5 -> CREACIÓN DEL SERVICIO DE PROTECCIÓN INTEGRAL A NIÑAS, NIÑOS Y ADOLESCENTES SIN CUIDADOS PARENTALES O EN RIESGO DE PERDERLOS EN CENTRO DE ACOGIDA RESIDENCIAL - VARONES DISTRITO DE MORALES DE LA PROVINCIA DE SAN MARTÍN DEL DEPARTAMENTO DE SAN MARTÍN, con CUI N.° 2705619
B5: UBICACIÓN | C5: =+RESUMEN!B6 -> SAN MARTIN - SAN MARTIN - MORALES
B6: FECHA | C6: =+RESUMEN!B7 -> 46266
C9: MONTANTES | D9: LONG. TUBERIA PVC 4" | G9: CODO PVC 90° 4" | J9: ABRAZADERA 4" | M9: COLGADOR 4"
D10: VECES | E10: LONGITUD | F10: TOTAL (m) | G10: CANTIDAD | H10: VECES | I10: TOTAL (und) | J10: CANTIDAD | K10: VECES | L10: TOTAL (und) | M10: CANTIDAD | N10: VECES | O10: TOTAL (und)
B11: EDIFICACION 01
B12: Lado A | C12: 2 | D12: 2 | E12: 6.22 | F12: =E12*D12 -> 12.44 | G12: 3 | H12: 2 | I12: =H12*G12 -> 6 | J12: 1 | K12: 2 | L12: =K12*J12 -> 2 | M12: 2 | N12: 2 | O12: =N12*M12 -> 4
B13: Lado B | C13: 2 | D13: 2 | E13: 6.22 | F13: =E13*D13 -> 12.44 | G13: 3 | H13: 2 | I13: =H13*G13 -> 6 | J13: 1 | K13: 2 | L13: =K13*J13 -> 2 | M13: 2 | N13: 2 | O13: =N13*M13 -> 4
B14: EDIFICACION 02
B15: Lado A | C15: 2 | D15: 2 | E15: 6.2 | F15: =E15*D15 -> 12.4 | G15: 3 | H15: 2 | I15: =H15*G15 -> 6 | J15: 1 | K15: 2 | L15: =K15*J15 -> 2 | M15: 2 | N15: 2 | O15: =N15*M15 -> 4
B16: Lado B | C16: 2 | D16: 2 | E16: 6.2 | F16: =E16*D16 -> 12.4 | G16: 3 | H16: 2 | I16: =H16*G16 -> 6 | J16: 1 | K16: 2 | L16: =K16*J16 -> 2 | M16: 2 | N16: 2 | O16: =N16*M16 -> 4
B17: EDIFICACION 03
B18: Lado A | C18: 2 | D18: 2 | E18: 6.26 | F18: =E18*D18 -> 12.52 | G18: 3 | H18: 2 | I18: =H18*G18 -> 6 | J18: 1 | K18: 2 | L18: =K18*J18 -> 2 | M18: 2 | N18: 2 | O18: =N18*M18 -> 4
B19: Lado B | C19: 2 | D19: 2 | E19: 6.26 | F19: =E19*D19 -> 12.52 | G19: 3 | H19: 2 | I19: =H19*G19 -> 6 | J19: 1 | K19: 2 | L19: =K19*J19 -> 2 | M19: 2 | N19: 2 | O19: =N19*M19 -> 4
B20: EDIFICACION 04
B21: Lado A | C21: 2 | D21: 2 | E21: 6.16 | F21: =E21*D21 -> 12.32 | G21: 3 | H21: 2 | I21: =H21*G21 -> 6 | J21: 1 | K21: 2 | L21: =K21*J21 -> 2 | M21: 2 | N21: 2 | O21: =N21*M21 -> 4
B22: Lado B | C22: 2 | D22: 2 | E22: 6.16 | F22: =E22*D22 -> 12.32 | G22: 3 | H22: 2 | I22: =H22*G22 -> 6 | J22: 1 | K22: 2 | L22: =K22*J22 -> 2 | M22: 2 | N22: 2 | O22: =N22*M22 -> 4
B23: EDIFICACION 05
B24: Lado A | C24: 2 | D24: 2 | E24: 6.24 | F24: =E24*D24 -> 12.48 | G24: 3 | H24: 2 | I24: =H24*G24 -> 6 | J24: 1 | K24: 2 | L24: =K24*J24 -> 2 | M24: 2 | N24: 2 | O24: =N24*M24 -> 4
B25: Lado B | C25: 2 | D25: 2 | E25: 6.24 | F25: =E25*D25 -> 12.48 | G25: 3 | H25: 2 | I25: =H25*G25 -> 6 | J25: 1 | K25: 2 | L25: =K25*J25 -> 2 | M25: 2 | N25: 2 | O25: =N25*M25 -> 4
B26: EDIFICACION 06
B27: Lado A | C27: 2 | D27: 2 | E27: 6.21 | F27: =E27*D27 -> 12.42 | G27: 3 | H27: 2 | I27: =H27*G27 -> 6 | J27: 1 | K27: 2 | L27: =K27*J27 -> 2 | M27: 2 | N27: 2 | O27: =N27*M27 -> 4
B28: Lado B | C28: 2 | D28: 2 | E28: 6.21 | F28: =E28*D28 -> 12.42 | G28: 3 | H28: 2 | I28: =H28*G28 -> 6 | J28: 1 | K28: 2 | L28: =K28*J28 -> 2 | M28: 2 | N28: 2 | O28: =N28*M28 -> 4
B29: EDIFICACION 07
B30: Lado A | C30: 2 | D30: 2 | E30: 6.17 | F30: =E30*D30 -> 12.34 | G30: 3 | H30: 2 | I30: =H30*G30 -> 6 | J30: 1 | K30: 2 | L30: =K30*J30 -> 2 | M30: 2 | N30: 2 | O30: =N30*M30 -> 4
B31: Lado B | C31: 2 | D31: 2 | E31: 6.17 | F31: =E31*D31 -> 12.34 | G31: 3 | H31: 2 | I31: =H31*G31 -> 6 | J31: 1 | K31: 2 | L31: =K31*J31 -> 2 | M31: 2 | N31: 2 | O31: =N31*M31 -> 4
B32: EDIFICACION 08
B33: Lado A | C33: 2 | D33: 2 | E33: 7.33 | F33: =E33*D33 -> 14.66 | G33: 3 | H33: 2 | I33: =H33*G33 -> 6 | J33: 2 | K33: 2 | L33: =K33*J33 -> 4 | M33: 2 | N33: 2 | O33: =N33*M33 -> 4
B34: Lado B | C34: 2 | D34: 2 | E34: 7.33 | F34: =E34*D34 -> 14.66 | G34: 3 | H34: 2 | I34: =H34*G34 -> 6 | J34: 2 | K34: 2 | L34: =K34*J34 -> 4 | M34: 2 | N34: 2 | O34: =N34*M34 -> 4
B35: Lado A" | C35: 2 | D35: 2 | E35: 9.96 | F35: =E35*D35 -> 19.92 | G35: 3 | H35: 2 | I35: =H35*G35 -> 6 | J35: 2 | K35: 2 | L35: =K35*J35 -> 4 | M35: 2 | N35: 2 | O35: =N35*M35 -> 4
B36: Lado B" | C36: 2 | D36: 2 | E36: 9.96 | F36: =E36*D36 -> 19.92 | G36: 3 | H36: 2 | I36: =H36*G36 -> 6 | J36: 2 | K36: 2 | L36: =K36*J36 -> 4 | M36: 2 | N36: 2 | O36: =N36*M36 -> 4
B37: EDIFICACION 09
B38: Lado A | C38: 2 | D38: 2 | E38: 6.25 | F38: =E38*D38 -> 12.5 | G38: 3 | H38: 2 | I38: =H38*G38 -> 6 | J38: 1 | K38: 2 | L38: =K38*J38 -> 2 | M38: 2 | N38: 2 | O38: =N38*M38 -> 4
B39: Lado B | C39: 2 | D39: 2 | E39: 6.26 | F39: =E39*D39 -> 12.52 | G39: 3 | H39: 2 | I39: =H39*G39 -> 6 | J39: 1 | K39: 2 | L39: =K39*J39 -> 2 | M39: 2 | N39: 2 | O39: =N39*M39 -> 4
B40: EDIFICACION 10
B41: Lado A | C41: 2 | D41: 2 | E41: 6.2 | F41: =E41*D41 -> 12.4 | G41: 3 | H41: 2 | I41: =H41*G41 -> 6 | J41: 1 | K41: 2 | L41: =K41*J41 -> 2 | M41: 2 | N41: 2 | O41: =N41*M41 -> 4
B42: Lado B | C42: 2 | D42: 2 | E42: 6.2 | F42: =E42*D42 -> 12.4 | G42: 3 | H42: 2 | I42: =H42*G42 -> 6 | J42: 1 | K42: 2 | L42: =K42*J42 -> 2 | M42: 2 | N42: 2 | O42: =N42*M42 -> 4
B43: LOSA DEPORTIVA | F43: =E43*D43 -> 0 | I43: =H43*G43 -> 0 | L43: =K43*J43 -> 0 | O43: =N43*M43 -> 0
...

Sheet METRADO CANALETAS
B2: METRADO DE CANALETAS DE TECHO - DRENAJE PLUVIAL
B3: ENTIDAD | C3: =+RESUMEN!B4 -> GERENCIA TERRITORIAL BAJO MAYO - TARAPOTO
B4: PROYECTO | C4: =+RESUMEN!B5 -> CREACIÓN DEL SERVICIO DE PROTECCIÓN INTEGRAL A NIÑAS, NIÑOS Y ADOLESCENTES SIN CUIDADOS PARENTALES O EN RIESGO DE PERDERLOS EN CENTRO DE ACOGIDA RESIDENCIAL - VARONES DISTRITO DE MORALES DE LA PROVINCIA DE SAN MARTÍN DEL DEPARTAMENTO DE SAN MARTÍN, con CUI N.° 2705619
B5: UBICACIÓN | C5: =+RESUMEN!B6 -> SAN MARTIN - SAN MARTIN - MORALES
B6: FECHA | C6: =+RESUMEN!B7 -> 46266
B8: CANALETA DE PLANCHA DE ACERO GALVANIZADO - SECCIÓN INTERIOR 0.25 m (FONDO) x 0.20 m (ALTO) - TECHOS A DOS AGUAS: UNA CANALETA POR CADA LADO
B9: EDIFICACIÓN | C9: N° DE CANALETAS | D9: CANALETA 0.25 x 0.20 m | F9: SOPORTE PLATINA F°G° 1" x 1/8" | H9: TAPA LATERAL | J9: BOQUILLA A MONTANTE Ø4"
D10: LONGITUD (m) | E10: TOTAL (m) | F10: CANTIDAD | G10: TOTAL (und) | H10: CANTIDAD | I10: TOTAL (und) | J10: CANTIDAD | K10: TOTAL (und)
B11: EDIFICACION 01
B12: Lado 01 | C12: 1 | D12: 25.78 | E12: =C12*D12 -> 25.78 | F12: =IF(D12>0,ROUNDUP(D12/$F$53,0)+1,0) -> 44 | G12: =C12*F12 -> 44 | H12: =$F$54 -> 2 | I12: =C12*H12 -> 2 | J12: ='METRADO MONTANTES'!C12 -> 2 | K12: =C12*J12 -> 2
B13: Lado 02 | C13: 1 | D13: =D12 -> 25.78 | E13: =C13*D13 -> 25.78 | F13: =IF(D13>0,ROUNDUP(D13/$F$53,0)+1,0) -> 44 | G13: =C13*F13 -> 44 | H13: =$F$54 -> 2 | I13: =C13*H13 -> 2 | J13: ='METRADO MONTANTES'!C13 -> 2 | K13: =C13*J13 -> 2
B14: EDIFICACION 02
B15: Lado 01 | C15: 1 | D15: 14.77 | E15: =C15*D15 -> 14.77 | F15: =IF(D15>0,ROUNDUP(D15/$F$53,0)+1,0) -> 26 | G15: =C15*F15 -> 26 | H15: =$F$54 -> 2 | I15: =C15*H15 -> 2 | J15: ='METRADO MONTANTES'!C15 -> 2 | K15: =C15*J15 -> 2
B16: Lado 02 | C16: 1 | D16: =D15 -> 14.77 | E16: =C16*D16 -> 14.77 | F16: =IF(D16>0,ROUNDUP(D16/$F$53,0)+1,0) -> 26 | G16: =C16*F16 -> 26 | H16: =$F$54 -> 2 | I16: =C16*H16 -> 2 | J16: ='METRADO MONTANTES'!C16 -> 2 | K16: =C16*J16 -> 2
B17: EDIFICACION 03
B18: Lado 01 | C18: 1 | D18: 16.05 | E18: =C18*D18 -> 16.05 | F18: =IF(D18>0,ROUNDUP(D18/$F$53,0)+1,0) -> 28 | G18: =C18*F18 -> 28 | H18: =$F$54 -> 2 | I18: =C18*H18 -> 2 | J18: ='METRADO MONTANTES'!C18 -> 2 | K18: =C18*J18 -> 2
B19: Lado 02 | C19: 1 | D19: =D18 -> 16.05 | E19: =C19*D19 -> 16.05 | F19: =IF(D19>0,ROUNDUP(D19/$F$53,0)+1,0) -> 28 | G19: =C19*F19 -> 28 | H19: =$F$54 -> 2 | I19: =C19*H19 -> 2 | J19: ='METRADO MONTANTES'!C19 -> 2 | K19: =C19*J19 -> 2
B20: EDIFICACION 04
B21: Lado 01 | C21: 1 | D21: 27.15 | E21: =C21*D21 -> 27.15 | F21: =IF(D21>0,ROUNDUP(D21/$F$53,0)+1,0) -> 47 | G21: =C21*F21 -> 47 | H21: =$F$54 -> 2 | I21: =C21*H21 -> 2 | J21: ='METRADO MONTANTES'!C21 -> 2 | K21: =C21*J21 -> 2
B22: Lado 02 | C22: 1 | D22: =D21 -> 27.15 | E22: =C22*D22 -> 27.15 | F22: =IF(D22>0,ROUNDUP(D22/$F$53,0)+1,0) -> 47 | G22: =C22*F22 -> 47 | H22: =$F$54 -> 2 | I22: =C22*H22 -> 2 | J22: ='METRADO MONTANTES'!C22 -> 2 | K22: =C22*J22 -> 2
B23: EDIFICACION 05
B24: Lado 01 | C24: 1 | D24: 27.15 | E24: =C24*D24 -> 27.15 | F24: =IF(D24>0,ROUNDUP(D24/$F$53,0)+1,0) -> 47 | G24: =C24*F24 -> 47 | H24: =$F$54 -> 2 | I24: =C24*H24 -> 2 | J24: ='METRADO MONTANTES'!C24 -> 2 | K24: =C24*J24 -> 2
B25: Lado 02 | C25: 1 | D25: =D24 -> 27.15 | E25: =C25*D25 -> 27.15 | F25: =IF(D25>0,ROUNDUP(D25/$F$53,0)+1,0) -> 47 | G25: =C25*F25 -> 47 | H25: =$F$54 -> 2 | I25: =C25*H25 -> 2 | J25: ='METRADO MONTANTES'!C25 -> 2 | K25: =C25*J25 -> 2
B26: EDIFICACION 06
B27: Lado 01 | C27: 1 | D27: 27.2 | E27: =C27*D27 -> 27.2 | F27: =IF(D27>0,ROUNDUP(D27/$F$53,0)+1,0) -> 47 | G27: =C27*F27 -> 47 | H27: =$F$54 -> 2 | I27: =C27*H27 -> 2 | J27: ='METRADO MONTANTES'!C27 -> 2 | K27: =C27*J27 -> 2
B28: Lado 02 | C28: 1 | D28: =D27 -> 27.2 | E28: =C28*D28 -> 27.2 | F28: =IF(D28>0,ROUNDUP(D28/$F$53,0)+1,0) -> 47 | G28: =C28*F28 -> 47 | H28: =$F$54 -> 2 | I28: =C28*H28 -> 2 | J28: ='METRADO MONTANTES'!C28 -> 2 | K28: =C28*J28 -> 2
B29: EDIFICACION 07
B30: Lado 01 | C30: 1 | D30: 27.15 | E30: =C30*D30 -> 27.15 | F30: =IF(D30>0,ROUNDUP(D30/$F$53,0)+1,0) -> 47 | G30: =C30*F30 -> 47 | H30: =$F$54 -> 2 | I30: =C30*H30 -> 2 | J30: ='METRADO MONTANTES'!C30 -> 2 | K30: =C30*J30 -> 2
B31: Lado 02 | C31: 1 | D31: =D30 -> 27.15 | E31: =C31*D31 -> 27.15 | F31: =IF(D31>0,ROUNDUP(D31/$F$53,0)+1,0) -> 47 | G31: =C31*F31 -> 47 | H31: =$F$54 -> 2 | I31: =C31*H31 -> 2 | J31: ='METRADO MONTANTES'!C31 -> 2 | K31: =C31*J31 -> 2
B32: EDIFICACION 08
B33: Lado 01 | C33: 1 | D33: 34.58 | E33: =C33*D33 -> 34.58 | F33: =IF(D33>0,ROUNDUP(D33/$F$53,0)+1,0) -> 59 | G33: =C33*F33 -> 59 | H33: =$F$54 -> 2 | I33: =C33*H33 -> 2 | J33: ='METRADO MONTANTES'!C33+'METRADO MONTANTES'!C35 -> 4 | K33: =C33*J33 -> 4
B34: Lado 02 | C34: 1 | D34: =D33 -> 34.58 | E34: =C34*D34 -> 34.58 | F34: =IF(D34>0,ROUNDUP(D34/$F$53,0)+1,0) -> 59 | G34: =C34*F34 -> 59 | H34: =$F$54 -> 2 | I34: =C34*H34 -> 2 | J34: ='METRADO MONTANTES'!C34+'METRADO MONTANTES'!C36 -> 4 | K34: =C34*J34 -> 4
B35: EDIFICACION 09
B36: Lado 01 | C36: 1 | D36: 9.7 | E36: =C36*D36 -> 9.7 | F36: =IF(D36>0,ROUNDUP(D36/$F$53,0)+1,0) -> 18 | G36: =C36*F36 -> 18 | H36: =$F$54 -> 2 | I36: =C36*H36 -> 2 | J36: ='METRADO MONTANTES'!C38 -> 2 | K36: =C36*J36 -> 2
B37: Lado 02 | C37: 1 | D37: =D36 -> 9.7 | E37: =C37*D37 -> 9.7 | F37: =IF(D37>0,ROUNDUP(D37/$F$53,0)+1,0) -> 18 | G37: =C37*F37 -> 18 | H37: =$F$54 -> 2 | I37: =C37*H37 -> 2 | J37: ='METRADO MONTANTES'!C39 -> 2 | K37: =C37*J37 -> 2
B38: EDIFICACION 10
B39: Lado 01 | C39: 1 | D39: 15.4 | E39: =C39*D39 -> 15.4 | F39: =IF(D39>0,ROUNDUP(D39/$F$53,0)+1,0) -> 27 | G39: =C39*F39 -> 27 | H39: =$F$54 -> 2 | I39: =C39*H39 -> 2 | J39: ='METRADO MONTANTES'!C41 -> 2 | K39: =C39*J39 -> 2
B40: Lado 02 | C40: 1 | D40: =D39 -> 15.4 | E40: =C40*D40 -> 15.4 | F40: =IF(D40>0,ROUNDUP(D40/$F$53,0)+1,0) -> 27 | G40: =C40*F40 -> 27 | H40: =$F$54 -> 2 | I40: =C40*H40 -> 2 | J40: ='METRADO MONTANTES'!C42 -> 2 | K40: =C40*J40 -> 2
B41: LOSA DEPORTIVA
B42: Lado 01 | C42: 1 | D42: 36.65 | E42: =C42*D42 -> 36.65 | F42: =IF(D42>0,ROUNDUP(D42/$F$53,0)+1,0) -> 63 | G42: =C42*F42 -> 63 | H42: =$F$54 -> 2 | I42: =C42*H42 -> 2 | J42: ='METRADO MONTANTES'!C44 -> 4 | K42: =C42*J42 -> 4
...

Sheet METRADO  EN PISO (SUMIDERO)
A1: PLANILLA DE METRADOS - RED DE DRENAJE EN PISO Y SUMIDEROS
A2: ENTIDAD | B2: =+RESUMEN!B4 -> GERENCIA TERRITORIAL BAJO MAYO - TARAPOTO
A3: PROYECTO | B3: =+RESUMEN!B5 -> CREACIÓN DEL SERVICIO DE PROTECCIÓN INTEGRAL A NIÑAS, NIÑOS Y ADOLESCENTES SIN CUIDADOS PARENTALES O EN RIESGO DE PERDERLOS EN CENTRO DE ACOGIDA RESIDENCIAL - VARONES DISTRITO DE MORALES DE LA PROVINCIA DE SAN MARTÍN DEL DEPARTAMENTO DE SAN MARTÍN, con CUI N.° 2705619
A4: UBICACIÓN | B4: =+RESUMEN!B6 -> SAN MARTIN - SAN MARTIN - MORALES
A5: FECHA | B5: =+RESUMEN!B7 -> 46266
A7: SECTOR | B7: TUBERÍA 4" PVC-U Desagüe Clase Pesada (m) | C7: SUMIDERO DE 4" (und) | D7: CODO 90° x 4" (und) | E7: CODO 45° x 4" (und) | F7: TEE° x 4" (und) | G7: OBSERVACIÓN
A8: SECTOR 01 | B8: 19.1 | C8: 5 | D8: 5 | E8: 0 | F8: 0 | G8: Sin datos de Varones
A9: SECTOR 02 | B9: 57.98 | C9: 9 | D9: 6 | E9: 0 | F9: 3 | G9: Sin datos de Varones
A10: SECTOR 03 | B10: 15 | C10: 2 | D10: 2 | E10: 0 | F10: 0 | G10: Sin datos de Varones
A11: TOTAL | B11: =SUM(B8:B10) -> 92.08 | C11: =SUM(C8:C10) -> 16 | D11: =SUM(D8:D10) -> 13 | E11: =SUM(E8:E10) -> 0 | F11: =SUM(F8:F10) -> 3

Sheet METRADO ACERO
A2: METRADO DE ACERO EN CUNETAS - DRENAJE PLUVIAL
A3: ENTIDAD | B3: =+RESUMEN!B4 -> GERENCIA TERRITORIAL BAJO MAYO - TARAPOTO
A4: PROYECTO | B4: =+RESUMEN!B5 -> CREACIÓN DEL SERVICIO DE PROTECCIÓN INTEGRAL A NIÑAS, NIÑOS Y ADOLESCENTES SIN CUIDADOS PARENTALES O EN RIESGO DE PERDERLOS EN CENTRO DE ACOGIDA RESIDENCIAL - VARONES DISTRITO DE MORALES DE LA PROVINCIA DE SAN MARTÍN DEL DEPARTAMENTO DE SAN MARTÍN, con CUI N.° 2705619
A5: UBICACIÓN | B5: =+RESUMEN!B6 -> SAN MARTIN - SAN MARTIN - MORALES
A6: FECHA | B6: =+RESUMEN!B7 -> 46266
A8: METRADO DETALLADO POR EJE Y POR TRAMO
A9: IDENTIFICACIÓN Y GEOMETRÍA | H9: ACERO LONGITUDINAL DEL CUERPO U | P9: ACERO TRANSVERSAL DEL CUERPO U | X9: ACERO TRANSVERSAL DE LA TAPA (SOLO CUNETA TAPADA) | AG9: RESULTADO
A10: N° | B10: EJE | C10: TRAMO | D10: TIPO DE CUNETA | E10: SEC. INI | F10: SEC. FIN | G10: LONGITUD TRAMO (m) | H10: Ø CUERPO | I10: FACTOR CUERPO (kg/m) | J10: SEP. LONG. (m) | K10: BARRAS LONG. INI | L10: BARRAS LONG. FIN | M10: BARRAS PROM. | N10: LONG. ACERO LONG. (m) | O10: KG LONG. | P10: SEP. TRANSV. U (m) | Q10: DES. TRANSV. U INI (m) | R10: DES. TRANSV. U FIN (m) | S10: DES. PROM. U (m) | T10: CANT. TRANSV. U | U10: LONG. ACERO TRANSV. U (m) | V10: KG TRANSV. U | W10: TOTAL KG CUERPO U | X10: Ø TAPA | Y10: FACTOR TAPA (kg/m) | Z10: SEP. TRANSV. TAPA (m) | AA10: LONG. BARRA TAPA INI (m) | AB10: LONG. BARRA TAPA FIN (m) | AC10: LONG. PROM. TAPA (m) | AD10: CANT. BARRAS TAPA | AE10: LONG. ACERO TAPA (m) | AF10: KG ACERO TAPA | AG10: TOTAL KG TRAMO
A11: 1 | B11: EJE 01 | C11: TRAMO 01 | D11: TAPADA | E11: SEC 02 | F11: SEC 03 | G11: 6 | H11: 3/8" | I11: =IF(H11="","",IFERROR(VLOOKUP(H11,Listas!$A$4:$B$11,2,FALSE()),"")) -> 0.56 | J11: 0.2 | K11: 7 | L11: 7 | M11: =IF(B11="","",(K11+L11)/2) -> 7 | N11: =IF(B11="","",G11*M11) -> 42 | O11: =IF(B11="","",N11*I11) -> 23.52 | P11: 0.25 | Q11: 1.44 | R11: 1.5 | S11: =IF(B11="","",(Q11+R11)/2) -> 1.47 | T11: =IF(B11="","",IFERROR(IF($X$1="ENTERO (redondeo arriba)",ROUNDUP(G11/P11,0)+1,G11/P11+1),0)) -> 25 | U11: =IF(B11="","",S11*T11) -> 36.75 | V11: =IF(B11="","",U11*I11) -> 20.58 | W11: =IF(B11="","",O11+V11) -> 44.1 | X11: 3/8" | Y11: 0.56 | Z11: 0.25 | AA11: 0.56 | AB11: 0.56 | AC11: =IF(B11="","",IF(D11="TAPADA",(AA11+AB11)/2,0)) -> 0.56 | AD11: =IF(B11="","",IF(D11="TAPADA",IFERROR(IF($X$1="ENTERO (redondeo arriba)",ROUNDUP(G11/Z11,0)+1,G11/Z11+1),0),0)) -> 25 | AE11: =IF(B11="","",IF(D11="TAPADA",AC11*AD11,0)) -> 14 | AF11: =IF(B11="","",IF(D11="TAPADA",AE11*Y11,0)) -> 7.84 | AG11: =IF(B11="","",W11+AF11) -> 51.94
A12: 2 | B12: EJE 01 | C12: TRAMO 02 | D12: ABIERTA | E12: SEC 03 | F12: SEC 04 | G12: 58.1 | H12: 3/8" | I12: =IF(H12="","",IFERROR(VLOOKUP(H12,Listas!$A$4:$B$11,2,FALSE()),"")) -> 0.56 | J12: 0.22 | K12: 7 | L12: 9 | M12: =IF(B12="","",(K12+L12)/2) -> 8 | N12: =IF(B12="","",G12*M12) -> 464.8 | O12: =IF(B12="","",N12*I12) -> 260.288 | P12: 0.25 | Q12: 1.5 | R12: 2.06 | S12: =IF(B12="","",(Q12+R12)/2) -> 1.78 | T12: =IF(B12="","",IFERROR(IF($X$1="ENTERO (redondeo arriba)",ROUNDUP(G12/P12,0)+1,G12/P12+1),0)) -> 233.4 | U12: =IF(B12="","",S12*T12) -> 415.452 | V12: =IF(B12="","",U12*I12) -> 232.65312 | W12: =IF(B12="","",O12+V12) -> 492.94112 | AC12: =IF(B12="","",IF(D12="TAPADA",(AA12+AB12)/2,0)) -> 0 | AD12: =IF(B12="","",IF(D12="TAPADA",IFERROR(IF($X$1="ENTERO (redondeo arriba)",ROUNDUP(G12/Z12,0)+1,G12/Z12+1),0),0)) -> 0 | AE12: =IF(B12="","",IF(D12="TAPADA",AC12*AD12,0)) -> 0 | AF12: =IF(B12="","",IF(D12="TAPADA",AE12*Y12,0)) -> 0 | AG12: =IF(B12="","",W12+AF12) -> 492.94112
A13: 3 | B13: EJE 01 | C13: TRAMO 03 | D13: TAPADA | E13: SEC 04 | F13: SEC 07 | G13: 34.23 | H13: 3/8" | I13: =IF(H13="","",IFERROR(VLOOKUP(H13,Listas!$A$4:$B$11,2,FALSE()),"")) -> 0.56 | J13: 0.25 | K13: 8 | L13: 9 | M13: =IF(B13="","",(K13+L13)/2) -> 8.5 | N13: =IF(B13="","",G13*M13) -> 290.955 | O13: =IF(B13="","",N13*I13) -> 162.9348 | P13: 0.25 | Q13: 2.06 | R13: 2.2 | S13: =IF(B13="","",(Q13+R13)/2) -> 2.13 | T13: =IF(B13="","",IFERROR(IF($X$1="ENTERO (redondeo arriba)",ROUNDUP(G13/P13,0)+1,G13/P13+1),0)) -> 137.92 | U13: =IF(B13="","",S13*T13) -> 293.7696 | V13: =IF(B13="","",U13*I13) -> 164.51098 | W13: =IF(B13="","",O13+V13) -> 327.44578 | X13: 3/8" | Y13: 0.56 | Z13: 0.25 | AA13: 0.56 | AB13: 0.56 | AC13: =IF(B13="","",IF(D13="TAPADA",(AA13+AB13)/2,0)) -> 0.56 | AD13: =IF(B13="","",IF(D13="TAPADA",IFERROR(IF($X$1="ENTERO (redondeo arriba)",ROUNDUP(G13/Z13,0)+1,G13/Z13+1),0),0)) -> 137.92 | AE13: =IF(B13="","",IF(D13="TAPADA",AC13*AD13,0)) -> 77.2352 | AF13: =IF(B13="","",IF(D13="TAPADA",AE13*Y13,0)) -> 43.251712 | AG13: =IF(B13="","",W13+AF13) -> 370.69749
A14: 4 | B14: EJE 02 | C14: TRAMO 01 | D14: ABIERTA | E14: SEC 09 | F14: SEC 10 | G14: 14.25 | H14: 3/8" | I14: =IF(H14="","",IFERROR(VLOOKUP(H14,Listas!$A$4:$B$11,2,FALSE()),"")) -> 0.56 | J14: 0.2 | K14: 7 | L14: 8 | M14: =IF(B14="","",(K14+L14)/2) -> 7.5 | N14: =IF(B14="","",G14*M14) -> 106.875 | O14: =IF(B14="","",N14*I14) -> 59.85 | P14: 0.25 | Q14: 1.5 | R14: 1.64 | S14: =IF(B14="","",(Q14+R14)/2) -> 1.57 | T14: =IF(B14="","",IFERROR(IF($X$1="ENTERO (redondeo arriba)",ROUNDUP(G14/P14,0)+1,G14/P14+1),0)) -> 58 | U14: =IF(B14="","",S14*T14) -> 91.06 | V14: =IF(B14="","",U14*I14) -> 50.9936 | W14: =IF(B14="","",O14+V14) -> 110.8436 | AC14: =IF(B14="","",IF(D14="TAPADA",(AA14+AB14)/2,0)) -> 0 | AD14: =IF(B14="","",IF(D14="TAPADA",IFERROR(IF($X$1="ENTERO (redondeo arriba)",ROUNDUP(G14/Z14,0)+1,G14/Z14+1),0),0)) -> 0 | AE14: =IF(B14="","",IF(D14="TAPADA",AC14*AD14,0)) -> 0 | AF14: =IF(B14="","",IF(D14="TAPADA",AE14*Y14,0)) -> 0 | AG14: =IF(B14="","",W14+AF14) -> 110.8436
A15: 5 | B15: EJE 03 | C15: TRAMO 01 | D15: ABIERTA | E15: SEC 12 | F15: SEC 13 | G15: 2.4 | H15: 3/8" | I15: =IF(H15="","",IFERROR(VLOOKUP(H15,Listas!$A$4:$B$11,2,FALSE()),"")) -> 0.56 | J15: 0.2 | K15: 7 | L15: 8 | M15: =IF(B15="","",(K15+L15)/2) -> 7.5 | N15: =IF(B15="","",G15*M15) -> 18 | O15: =IF(B15="","",N15*I15) -> 10.08 | P15: 0.25 | Q15: 1.5 | R15: 1.54 | S15: =IF(B15="","",(Q15+R15)/2) -> 1.52 | T15: =IF(B15="","",IFERROR(IF($X$1="ENTERO (redondeo arriba)",ROUNDUP(G15/P15,0)+1,G15/P15+1),0)) -> 10.6 | U15: =IF(B15="","",S15*T15) -> 16.112 | V15: =IF(B15="","",U15*I15) -> 9.02272 | W15: =IF(B15="","",O15+V15) -> 19.10272 | AC15: =IF(B15="","",IF(D15="TAPADA",(AA15+AB15)/2,0)) -> 0 | AD15: =IF(B15="","",IF(D15="TAPADA",IFERROR(IF($X$1="ENTERO (redondeo arriba)",ROUNDUP(G15/Z15,0)+1,G15/Z15+1),0),0)) -> 0 | AE15: =IF(B15="","",IF(D15="TAPADA",AC15*AD15,0)) -> 0 | AF15: =IF(B15="","",IF(D15="TAPADA",AE15*Y15,0)) -> 0 | AG15: =IF(B15="","",W15+AF15) -> 19.10272
A16: 6 | B16: EJE 04 | C16: TRAMO 01 | D16: TAPADA | E16: SEC 15 | F16: SEC 16 | G16: 5.5 | H16: 3/8" | I16: =IF(H16="","",IFERROR(VLOOKUP(H16,Listas!$A$4:$B$11,2,FALSE()),"")) -> 0.56 | J16: 0.2 | K16: 7 | L16: 7 | M16: =IF(B16="","",(K16+L16)/2) -> 7 | N16: =IF(B16="","",G16*M16) -> 38.5 | O16: =IF(B16="","",N16*I16) -> 21.56 | P16: 0.25 | Q16: 1.42 | R16: 1.5 | S16: =IF(B16="","",(Q16+R16)/2) -> 1.46 | T16: =IF(B16="","",IFERROR(IF($X$1="ENTERO (redondeo arriba)",ROUNDUP(G16/P16,0)+1,G16/P16+1),0)) -> 23 | U16: =IF(B16="","",S16*T16) -> 33.58 | V16: =IF(B16="","",U16*I16) -> 18.8048 | W16: =IF(B16="","",O16+V16) -> 40.3648 | X16: 3/8" | Y16: 0.56 | Z16: 0.25 | AA16: 0.56 | AB16: 0.56 | AC16: =IF(B16="","",IF(D16="TAPADA",(AA16+AB16)/2,0)) -> 0.56 | AD16: =IF(B16="","",IF(D16="TAPADA",IFERROR(IF($X$1="ENTERO (redondeo arriba)",ROUNDUP(G16/Z16,0)+1,G16/Z16+1),0),0)) -> 23 | AE16: =IF(B16="","",IF(D16="TAPADA",AC16*AD16,0)) -> 12.88 | AF16: =IF(B16="","",IF(D16="TAPADA",AE16*Y16,0)) -> 7.2128 | AG16: =IF(B16="","",W16+AF16) -> 47.5776
A17: 7 | B17: EJE 04 | C17: TRAMO 02 | D17: ABIERTA | E17: SEC 16 | F17: SEC 17 | G17: 58 | H17: 3/8" | I17: =IF(H17="","",IFERROR(VLOOKUP(H17,Listas!$A$4:$B$11,2,FALSE()),"")) -> 0.56 | J17: 0.22 | K17: 7 | L17: 9 | M17: =IF(B17="","",(K17+L17)/2) -> 8 | N17: =IF(B17="","",G17*M17) -> 464 | O17: =IF(B17="","",N17*I17) -> 259.84 | P17: 0.25 | Q17: 1.5 | R17: 2.06 | S17: =IF(B17="","",(Q17+R17)/2) -> 1.78 | T17: =IF(B17="","",IFERROR(IF($X$1="ENTERO (redondeo arriba)",ROUNDUP(G17/P17,0)+1,G17/P17+1),0)) -> 233 | U17: =IF(B17="","",S17*T17) -> 414.74 | V17: =IF(B17="","",U17*I17) -> 232.2544 | W17: =IF(B17="","",O17+V17) -> 492.0944 | AC17: =IF(B17="","",IF(D17="TAPADA",(AA17+AB17)/2,0)) -> 0 | AD17: =IF(B17="","",IF(D17="TAPADA",IFERROR(IF($X$1="ENTERO (redondeo arriba)",ROUNDUP(G17/Z17,0)+1,G17/Z17+1),0),0)) -> 0 | AE17: =IF(B17="","",IF(D17="TAPADA",AC17*AD17,0)) -> 0 | AF17: =IF(B17="","",IF(D17="TAPADA",AE17*Y17,0)) -> 0 | AG17: =IF(B17="","",W17+AF17) -> 492.0944
A18: 8 | B18: EJE 04 | C18: TRAMO 03 | D18: TAPADA | E18: SEC 17 | F18: SEC 20 | G18: 25.16 | H18: 3/8" | I18: =IF(H18="","",IFERROR(VLOOKUP(H18,Listas!$A$4:$B$11,2,FALSE()),"")) -> 0.56 | J18: 0.25 | K18: 8 | L18: 8 | M18: =IF(B18="","",(K18+L18)/2) -> 8 | N18: =IF(B18="","",G18*M18) -> 201.28 | O18: =IF(B18="","",N18*I18) -> 112.7168 | P18: 0.25 | Q18: 2.06 | R18: 2.1 | S18: =IF(B18="","",(Q18+R18)/2) -> 2.08 | T18: =IF(B18="","",IFERROR(IF($X$1="ENTERO (redondeo arriba)",ROUNDUP(G18/P18,0)+1,G18/P18+1),0)) -> 101.64 | U18: =IF(B18="","",S18*T18) -> 211.4112 | V18: =IF(B18="","",U18*I18) -> 118.39027 | W18: =IF(B18="","",O18+V18) -> 231.10707 | X18: 3/8" | Y18: 0.56 | Z18: 0.25 | AA18: 0.56 | AB18: 0.56 | AC18: =IF(B18="","",IF(D18="TAPADA",(AA18+AB18)/2,0)) -> 0.56 | AD18: =IF(B18="","",IF(D18="TAPADA",IFERROR(IF($X$1="ENTERO (redondeo arriba)",ROUNDUP(G18/Z18,0)+1,G18/Z18+1),0),0)) -> 101.64 | AE18: =IF(B18="","",IF(D18="TAPADA",AC18*AD18,0)) -> 56.9184 | AF18: =IF(B18="","",IF(D18="TAPADA",AE18*Y18,0)) -> 31.874304 | AG18: =IF(B18="","",W18+AF18) -> 262.98138
A19: 9 | B19: EJE 05 | C19: TRAMO 01 | D19: ABIERTA | E19: SEC 22 | F19: SEC 23 | G19: 12.3 | H19: 3/8" | I19: =IF(H19="","",IFERROR(VLOOKUP(H19,Listas!$A$4:$B$11,2,FALSE()),"")) -> 0.56 | J19: 0.2 | K19: 7 | L19: 8 | M19: =IF(B19="","",(K19+L19)/2) -> 7.5 | N19: =IF(B19="","",G19*M19) -> 92.25 | O19: =IF(B19="","",N19*I19) -> 51.66 | P19: 0.25 | Q19: 1.5 | R19: 1.62 | S19: =IF(B19="","",(Q19+R19)/2) -> 1.56 | T19: =IF(B19="","",IFERROR(IF($X$1="ENTERO (redondeo arriba)",ROUNDUP(G19/P19,0)+1,G19/P19+1),0)) -> 50.2 | U19: =IF(B19="","",S19*T19) -> 78.312 | V19: =IF(B19="","",U19*I19) -> 43.85472 | W19: =IF(B19="","",O19+V19) -> 95.51472 | AC19: =IF(B19="","",IF(D19="TAPADA",(AA19+AB19)/2,0)) -> 0 | AD19: =IF(B19="","",IF(D19="TAPADA",IFERROR(IF($X$1="ENTERO (redondeo arriba)",ROUNDUP(G19/Z19,0)+1,G19/Z19+1),0),0)) -> 0 | AE19: =IF(B19="","",IF(D19="TAPADA",AC19*AD19,0)) -> 0 | AF19: =IF(B19="","",IF(D19="TAPADA",AE19*Y19,0)) -> 0 | AG19: =IF(B19="","",W19+AF19) -> 95.51472
A20: 10 | B20: EJE 05 | C20: TRAMO 02 | D20: TAPADA | E20: SEC 23 | F20: SEC 24 | G20: 9.9 | H20: 3/8" | I20: =IF(H20="","",IFERROR(VLOOKUP(H20,Listas!$A$4:$B$11,2,FALSE()),"")) -> 0.56 | J20: 0.22 | K20: 7 | L20: 8 | M20: =IF(B20="","",(K20+L20)/2) -> 7.5 | N20: =IF(B20="","",G20*M20) -> 74.25 | O20: =IF(B20="","",N20*I20) -> 41.58 | P20: 0.25 | Q20: 1.62 | R20: 1.72 | S20: =IF(B20="","",(Q20+R20)/2) -> 1.67 | T20: =IF(B20="","",IFERROR(IF($X$1="ENTERO (redondeo arriba)",ROUNDUP(G20/P20,0)+1,G20/P20+1),0)) -> 40.6 | U20: =IF(B20="","",S20*T20) -> 67.802 | V20: =IF(B20="","",U20*I20) -> 37.96912 | W20: =IF(B20="","",O20+V20) -> 79.54912 | X20: 3/8" | Y20: 0.56 | Z20: 0.25 | AA20: 0.56 | AB20: 0.56 | AC20: =IF(B20="","",IF(D20="TAPADA",(AA20+AB20)/2,0)) -> 0.56 | AD20: =IF(B20="","",IF(D20="TAPADA",IFERROR(IF($X$1="ENTERO (redondeo arriba)",ROUNDUP(G20/Z20,0)+1,G20/Z20+1),0),0)) -> 40.6 | AE20: =IF(B20="","",IF(D20="TAPADA",AC20*AD20,0)) -> 22.736 | AF20: =IF(B20="","",IF(D20="TAPADA",AE20*Y20,0)) -> 12.73216 | AG20: =IF(B20="","",W20+AF20) -> 92.28128
A21: 11 | B21: EJE 06 | C21: TRAMO 01 | D21: ABIERTA | E21: SEC 26 | F21: SEC 27 | G21: 12.5 | H21: 3/8" | I21: =IF(H21="","",IFERROR(VLOOKUP(H21,Listas!$A$4:$B$11,2,FALSE()),"")) -> 0.56 | J21: 0.2 | K21: 7 | L21: 8 | M21: =IF(B21="","",(K21+L21)/2) -> 7.5 | N21: =IF(B21="","",G21*M21) -> 93.75 | O21: =IF(B21="","",N21*I21) -> 52.5 | P21: 0.25 | Q21: 1.5 | R21: 1.62 | S21: =IF(B21="","",(Q21+R21)/2) -> 1.56 | T21: =IF(B21="","",IFERROR(IF($X$1="ENTERO (redondeo arriba)",ROUNDUP(G21/P21,0)+1,G21/P21+1),0)) -> 51 | U21: =IF(B21="","",S21*T21) -> 79.56 | V21: =IF(B21="","",U21*I21) -> 44.5536 | W21: =IF(B21="","",O21+V21) -> 97.0536 | AC21: =IF(B21="","",IF(D21="TAPADA",(AA21+AB21)/2,0)) -> 0 | AD21: =IF(B21="","",IF(D21="TAPADA",IFERROR(IF($X$1="ENTERO (redondeo arriba)",ROUNDUP(G21/Z21,0)+1,G21/Z21+1),0),0)) -> 0 | AE21: =IF(B21="","",IF(D21="TAPADA",AC21*AD21,0)) -> 0 | AF21: =IF(B21="","",IF(D21="TAPADA",AE21*Y21,0)) -> 0 | AG21: =IF(B21="","",W21+AF21) -> 97.0536
A22: 12 | B22: EJE 06 | C22: TRAMO 02 | D22: TAPADA | E22: SEC 27 | F22: SEC 30 | G22: 66.19 | H22: 3/8" | I22: =IF(H22="","",IFERROR(VLOOKUP(H22,Listas!$A$4:$B$11,2,FALSE()),"")) -> 0.56 | J22: 0.22 | K22: 7 | L22: 9 | M22: =IF(B22="","",(K22+L22)/2) -> 8 | N22: =IF(B22="","",G22*M22) -> 529.52 | O22: =IF(B22="","",N22*I22) -> 296.5312 | P22: 0.25 | Q22: 1.62 | R22: 2.08 | S22: =IF(B22="","",(Q22+R22)/2) -> 1.85 | T22: =IF(B22="","",IFERROR(IF($X$1="ENTERO (redondeo arriba)",ROUNDUP(G22/P22,0)+1,G22/P22+1),0)) -> 265.76 | U22: =IF(B22="","",S22*T22) -> 491.656 | V22: =IF(B22="","",U22*I22) -> 275.32736 | W22: =IF(B22="","",O22+V22) -> 571.85856 | X22: 3/8" | Y22: 0.56 | Z22: 0.25 | AA22: 0.56 | AB22: 0.56 | AC22: =IF(B22="","",IF(D22="TAPADA",(AA22+AB22)/2,0)) -> 0.56 | AD22: =IF(B22="","",IF(D22="TAPADA",IFERROR(IF($X$1="ENTERO (redondeo arriba)",ROUNDUP(G22/Z22,0)+1,G22/Z22+1),0),0)) -> 265.76 | AE22: =IF(B22="","",IF(D22="TAPADA",AC22*AD22,0)) -> 148.8256 | AF22: =IF(B22="","",IF(D22="TAPADA",AE22*Y22,0)) -> 83.342336 | AG22: =IF(B22="","",W22+AF22) -> 655.2009
A23: 13 | B23: EJE 07 | C23: TRAMO 01 | D23: ABIERTA | E23: SEC 32 | F23: SEC 33 | G23: 3.6 | H23: 3/8" | I23: =IF(H23="","",IFERROR(VLOOKUP(H23,Listas!$A$4:$B$11,2,FALSE()),"")) -> 0.56 | J23: 0.2 | K23: 7 | L23: 8 | M23: =IF(B23="","",(K23+L23)/2) -> 7.5 | N23: =IF(B23="","",G23*M23) -> 27 | O23: =IF(B23="","",N23*I23) -> 15.12 | P23: 0.25 | Q23: 1.5 | R23: 1.52 | S23: =IF(B23="","",(Q23+R23)/2) -> 1.51 | T23: =IF(B23="","",IFERROR(IF($X$1="ENTERO (redondeo arriba)",ROUNDUP(G23/P23,0)+1,G23/P23+1),0)) -> 15.4 | U23: =IF(B23="","",S23*T23) -> 23.254 | V23: =IF(B23="","",U23*I23) -> 13.02224 | W23: =IF(B23="","",O23+V23) -> 28.14224 | AC23: =IF(B23="","",IF(D23="TAPADA",(AA23+AB23)/2,0)) -> 0 | AD23: =IF(B23="","",IF(D23="TAPADA",IFERROR(IF($X$1="ENTERO (redondeo arriba)",ROUNDUP(G23/Z23,0)+1,G23/Z23+1),0),0)) -> 0 | AE23: =IF(B23="","",IF(D23="TAPADA",AC23*AD23,0)) -> 0 | AF23: =IF(B23="","",IF(D23="TAPADA",AE23*Y23,0)) -> 0 | AG23: =IF(B23="","",W23+AF23) -> 28.14224
A24: 14 | B24: EJE 08 | C24: TRAMO 01 | D24: ABIERTA | E24: SEC 35 | F24: SEC 36 | G24: 29.85 | H24: 3/8" | I24: =IF(H24="","",IFERROR(VLOOKUP(H24,Listas!$A$4:$B$11,2,FALSE()),"")) -> 0.56 | J24: 0.22 | K24: 7 | L24: 8 | M24: =IF(B24="","",(K24+L24)/2) -> 7.5 | N24: =IF(B24="","",G24*M24) -> 223.875 | O24: =IF(B24="","",N24*I24) -> 125.37 | P24: 0.25 | Q24: 1.5 | R24: 1.8 | S24: =IF(B24="","",(Q24+R24)/2) -> 1.65 | T24: =IF(B24="","",IFERROR(IF($X$1="ENTERO (redondeo arriba)",ROUNDUP(G24/P24,0)+1,G24/P24+1),0)) -> 120.4 | U24: =IF(B24="","",S24*T24) -> 198.66 | V24: =IF(B24="","",U24*I24) -> 111.2496 | W24: =IF(B24="","",O24+V24) -> 236.6196 | AC24: =IF(B24="","",IF(D24="TAPADA",(AA24+AB24)/2,0)) -> 0 | AD24: =IF(B24="","",IF(D24="TAPADA",IFERROR(IF($X$1="ENTERO (redondeo arriba)",ROUNDUP(G24/Z24,0)+1,G24/Z24+1),0),0)) -> 0 | AE24: =IF(B24="","",IF(D24="TAPADA",AC24*AD24,0)) -> 0 | AF24: =IF(B24="","",IF(D24="TAPADA",AE24*Y24,0)) -> 0 | AG24: =IF(B24="","",W24+AF24) -> 236.6196
A25: 15 | B25: EJE 08 | C25: TRAMO 02 | D25: TAPADA | E25: SEC 36 | F25: SEC 37 | G25: 10.75 | H25: 3/8" | I25: =IF(H25="","",IFERROR(VLOOKUP(H25,Listas!$A$4:$B$11,2,FALSE()),"")) -> 0.56 | J25: 0.22 | K25: 8 | L25: 9 | M25: =IF(B25="","",(K25+L25)/2) -> 8.5 | N25: =IF(B25="","",G25*M25) -> 91.375 | O25: =IF(B25="","",N25*I25) -> 51.17 | P25: 0.25 | Q25: 1.8 | R25: 1.9 | S25: =IF(B25="","",(Q25+R25)/2) -> 1.85 | T25: =IF(B25="","",IFERROR(IF($X$1="ENTERO (redondeo arriba)",ROUNDUP(G25/P25,0)+1,G25/P25+1),0)) -> 44 | U25: =IF(B25="","",S25*T25) -> 81.4 | V25: =IF(B25="","",U25*I25) -> 45.584 | W25: =IF(B25="","",O25+V25) -> 96.754 | X25: 3/8" | Y25: 0.56 | Z25: 0.25 | AA25: 0.56 | AB25: 0.56 | AC25: =IF(B25="","",IF(D25="TAPADA",(AA25+AB25)/2,0)) -> 0.56 | AD25: =IF(B25="","",IF(D25="TAPADA",IFERROR(IF($X$1="ENTERO (redondeo arriba)",ROUNDUP(G25/Z25,0)+1,G25/Z25+1),0),0)) -> 44 | AE25: =IF(B25="","",IF(D25="TAPADA",AC25*AD25,0)) -> 24.64 | AF25: =IF(B25="","",IF(D25="TAPADA",AE25*Y25,0)) -> 13.7984 | AG25: =IF(B25="","",W25+AF25) -> 110.5524
A26: 16 | B26: EJE 09 | C26: TRAMO 01 | D26: ABIERTA | E26: SEC 39 | F26: SEC 40 | G26: 16 | H26: 3/8" | I26: =IF(H26="","",IFERROR(VLOOKUP(H26,Listas!$A$4:$B$11,2,FALSE()),"")) -> 0.56 | J26: 0.22 | K26: 7 | L26: 8 | M26: =IF(B26="","",(K26+L26)/2) -> 7.5 | N26: =IF(B26="","",G26*M26) -> 120 | O26: =IF(B26="","",N26*I26) -> 67.2 | P26: 0.25 | Q26: 1.5 | R26: 1.7 | S26: =IF(B26="","",(Q26+R26)/2) -> 1.6 | T26: =IF(B26="","",IFERROR(IF($X$1="ENTERO (redondeo arriba)",ROUNDUP(G26/P26,0)+1,G26/P26+1),0)) -> 65 | U26: =IF(B26="","",S26*T26) -> 104 | V26: =IF(B26="","",U26*I26) -> 58.24 | W26: =IF(B26="","",O26+V26) -> 125.44 | AC26: =IF(B26="","",IF(D26="TAPADA",(AA26+AB26)/2,0)) -> 0 | AD26: =IF(B26="","",IF(D26="TAPADA",IFERROR(IF($X$1="ENTERO (redondeo arriba)",ROUNDUP(G26/Z26,0)+1,G26/Z26+1),0),0)) -> 0 | AE26: =IF(B26="","",IF(D26="TAPADA",AC26*AD26,0)) -> 0 | AF26: =IF(B26="","",IF(D26="TAPADA",AE26*Y26,0)) -> 0 | AG26: =IF(B26="","",W26+AF26) -> 125.44
A27: 17 | B27: EJE 09 | C27: TRAMO 02 | D27: TAPADA | E27: SEC 40 | F27: SEC 42 | G27: 6.66 | H27: 3/8" | I27: =IF(H27="","",IFERROR(VLOOKUP(H27,Listas!$A$4:$B$11,2,FALSE()),"")) -> 0.56 | J27: 0.22 | K27: 8 | L27: 8 | M27: =IF(B27="","",(K27+L27)/2) -> 8 | N27: =IF(B27="","",G27*M27) -> 53.28 | O27: =IF(B27="","",N27*I27) -> 29.8368 | P27: 0.25 | Q27: 1.7 | R27: 1.82 | S27: =IF(B27="","",(Q27+R27)/2) -> 1.76 | T27: =IF(B27="","",IFERROR(IF($X$1="ENTERO (redondeo arriba)",ROUNDUP(G27/P27,0)+1,G27/P27+1),0)) -> 27.64 | U27: =IF(B27="","",S27*T27) -> 48.6464 | V27: =IF(B27="","",U27*I27) -> 27.241984 | W27: =IF(B27="","",O27+V27) -> 57.078784 | X27: 3/8" | Y27: 0.56 | Z27: 0.25 | AA27: 0.56 | AB27: 0.56 | AC27: =IF(B27="","",IF(D27="TAPADA",(AA27+AB27)/2,0)) -> 0.56 | AD27: =IF(B27="","",IF(D27="TAPADA",IFERROR(IF($X$1="ENTERO (redondeo arriba)",ROUNDUP(G27/Z27,0)+1,G27/Z27+1),0),0)) -> 27.64 | AE27: =IF(B27="","",IF(D27="TAPADA",AC27*AD27,0)) -> 15.4784 | AF27: =IF(B27="","",IF(D27="TAPADA",AE27*Y27,0)) -> 8.667904 | AG27: =IF(B27="","",W27+AF27) -> 65.746688
A28: TOTALES DE LA PLANILLA | G28: =SUM(G11:G27) -> 371.39 | N28: =SUM(N11:N27) -> 2931.71 | O28: =SUM(O11:O27) -> 1641.7576 | U28: =SUM(U11:U27) -> 2686.1652 | V28: =SUM(V11:V27) -> 1504.2525 | W28: =SUM(W11:W27) -> 3146.0101 | AE28: =SUM(AE11:AE27) -> 372.7136 | AF28: =SUM(AF11:AF27) -> 208.71962 | AG28: =SUM(AG11:AG27) -> 3354.7297

Sheet METRADO DE CURADO
A1: METRADO DE CURADO DE CONCRETO EN CUNETAS
A2: ENTIDAD | C2: GERENCIA TERRITORIAL BAJO MAYO - TARAPOTO
A3: PROYECTO | C3: =+RESUMEN!B5 -> CREACIÓN DEL SERVICIO DE PROTECCIÓN INTEGRAL A NIÑAS, NIÑOS Y ADOLESCENTES SIN CUIDADOS PARENTALES O EN RIESGO DE PERDERLOS EN CENTRO DE ACOGIDA RESIDENCIAL - VARONES DISTRITO DE MORALES DE LA PROVINCIA DE SAN MARTÍN DEL DEPARTAMENTO DE SAN MARTÍN, con CUI N.° 2705619
A4: UBICACIÓN | C4: =+RESUMEN!B6 -> SAN MARTIN - SAN MARTIN - MORALES | K4: FECHA | L4: =+RESUMEN!B7 -> 46266
A6: N° | B6: EJE | C6: TRAMO | D6: TIPO DE CUNETA | E6: LONGITUD (m) | F6: ANCHO INTERIOR (m) | G6: ALTURA INT. INI (m) | H6: ALTURA INT. FIN (m) | I6: ALTURA PROM. (m) | J6: ÁREA 2 MUROS (m²) | K6: ÁREA FONDO (m²) | L6: ÁREA TAPA / TECHO (m²) | M6: TOTAL CURADO (m²) | N6: N° CARAS | O6: UND.
A7: 1 | B7: EJE 01 | C7: TRAMO 01 | D7: ABIERTA | E7: 13.2 | F7: 0.4 | G7: 0.3 | H7: 0.37 | I7: =IF(B7="","",(G7+H7)/2) -> 0.335 | J7: =IF(B7="","",2*E7*I7) -> 8.844 | K7: =IF(B7="","",E7*F7) -> 5.28 | L7: =IF(B7="","",IF(D7="TAPADA",E7*F7,0)) -> 0 | M7: =SUM(J7:L7) -> 14.124 | N7: =IF(B7="","",IF(D7="TAPADA",4,3)) -> 3 | O7: m²
A8: 2 | B8: EJE 01 | C8: TRAMO 02 | D8: TAPADA | E8: 6 | F8: 0.4 | G8: 0.37 | H8: 0.4 | I8: =IF(B8="","",(G8+H8)/2) -> 0.385 | J8: =IF(B8="","",2*E8*I8) -> 4.62 | K8: =IF(B8="","",E8*F8) -> 2.4 | L8: =IF(B8="","",IF(D8="TAPADA",E8*F8,0)) -> 2.4 | M8: =SUM(J8:L8) -> 9.42 | N8: =IF(B8="","",IF(D8="TAPADA",4,3)) -> 4 | O8: m²
A9: 3 | B9: EJE 01 | C9: TRAMO 03 | D9: ABIERTA | E9: 58.1 | F9: 0.4 | G9: 0.4 | H9: 0.68 | I9: =IF(B9="","",(G9+H9)/2) -> 0.54 | J9: =IF(B9="","",2*E9*I9) -> 62.748 | K9: =IF(B9="","",E9*F9) -> 23.24 | L9: =IF(B9="","",IF(D9="TAPADA",E9*F9,0)) -> 0 | M9: =SUM(J9:L9) -> 85.988 | N9: =IF(B9="","",IF(D9="TAPADA",4,3)) -> 3 | O9: m²
A10: 4 | B10: EJE 01 | C10: TRAMO 04 | D10: TAPADA | E10: 34.23 | F10: 0.4 | G10: 0.68 | H10: 0.75 | I10: =IF(B10="","",(G10+H10)/2) -> 0.715 | J10: =IF(B10="","",2*E10*I10) -> 48.9489 | K10: =IF(B10="","",E10*F10) -> 13.692 | L10: =IF(B10="","",IF(D10="TAPADA",E10*F10,0)) -> 13.692 | M10: =SUM(J10:L10) -> 76.3329 | N10: =IF(B10="","",IF(D10="TAPADA",4,3)) -> 4 | O10: m²
A11: 5 | B11: EJE 02 | C11: TRAMO 01 | D11: ABIERTA | E11: 34.25 | F11: 0.4 | G11: 0.3 | H11: 0.47 | I11: =IF(B11="","",(G11+H11)/2) -> 0.385 | J11: =IF(B11="","",2*E11*I11) -> 26.3725 | K11: =IF(B11="","",E11*F11) -> 13.7 | L11: =IF(B11="","",IF(D11="TAPADA",E11*F11,0)) -> 0 | M11: =SUM(J11:L11) -> 40.0725 | N11: =IF(B11="","",IF(D11="TAPADA",4,3)) -> 3 | O11: m²
A12: 6 | B12: EJE 03 | C12: TRAMO 01 | D12: ABIERTA | E12: 22.4 | F12: 0.4 | G12: 0.3 | H12: 0.42 | I12: =IF(B12="","",(G12+H12)/2) -> 0.36 | J12: =IF(B12="","",2*E12*I12) -> 16.128 | K12: =IF(B12="","",E12*F12) -> 8.96 | L12: =IF(B12="","",IF(D12="TAPADA",E12*F12,0)) -> 0 | M12: =SUM(J12:L12) -> 25.088 | N12: =IF(B12="","",IF(D12="TAPADA",4,3)) -> 3 | O12: m²
A13: 7 | B13: EJE 04 | C13: TRAMO 01 | D13: ABIERTA | E13: 13.65 | F13: 0.4 | G13: 0.3 | H13: 0.36 | I13: =IF(B13="","",(G13+H13)/2) -> 0.33 | J13: =IF(B13="","",2*E13*I13) -> 9.009 | K13: =IF(B13="","",E13*F13) -> 5.46 | L13: =IF(B13="","",IF(D13="TAPADA",E13*F13,0)) -> 0 | M13: =SUM(J13:L13) -> 14.469 | N13: =IF(B13="","",IF(D13="TAPADA",4,3)) -> 3 | O13: m²
A14: 8 | B14: EJE 04 | C14: TRAMO 02 | D14: TAPADA | E14: 5.5 | F14: 0.4 | G14: 0.36 | H14: 0.4 | I14: =IF(B14="","",(G14+H14)/2) -> 0.38 | J14: =IF(B14="","",2*E14*I14) -> 4.18 | K14: =IF(B14="","",E14*F14) -> 2.2 | L14: =IF(B14="","",IF(D14="TAPADA",E14*F14,0)) -> 2.2 | M14: =SUM(J14:L14) -> 8.58 | N14: =IF(B14="","",IF(D14="TAPADA",4,3)) -> 4 | O14: m²
A15: 9 | B15: EJE 04 | C15: TRAMO 03 | D15: ABIERTA | E15: 58 | F15: 0.4 | G15: 0.4 | H15: 0.68 | I15: =IF(B15="","",(G15+H15)/2) -> 0.54 | J15: =IF(B15="","",2*E15*I15) -> 62.64 | K15: =IF(B15="","",E15*F15) -> 23.2 | L15: =IF(B15="","",IF(D15="TAPADA",E15*F15,0)) -> 0 | M15: =SUM(J15:L15) -> 85.84 | N15: =IF(B15="","",IF(D15="TAPADA",4,3)) -> 3 | O15: m²
A16: 10 | B16: EJE 04 | C16: TRAMO 04 | D16: TAPADA | E16: 25.16 | F16: 0.4 | G16: 0.68 | H16: 0.7 | I16: =IF(B16="","",(G16+H16)/2) -> 0.69 | J16: =IF(B16="","",2*E16*I16) -> 34.7208 | K16: =IF(B16="","",E16*F16) -> 10.064 | L16: =IF(B16="","",IF(D16="TAPADA",E16*F16,0)) -> 10.064 | M16: =SUM(J16:L16) -> 54.8488 | N16: =IF(B16="","",IF(D16="TAPADA",4,3)) -> 4 | O16: m²
A17: 11 | B17: EJE 05 | C17: TRAMO 01 | D17: ABIERTA | E17: 32.3 | F17: 0.4 | G17: 0.3 | H17: 0.46 | I17: =IF(B17="","",(G17+H17)/2) -> 0.38 | J17: =IF(B17="","",2*E17*I17) -> 24.548 | K17: =IF(B17="","",E17*F17) -> 12.92 | L17: =IF(B17="","",IF(D17="TAPADA",E17*F17,0)) -> 0 | M17: =SUM(J17:L17) -> 37.468 | N17: =IF(B17="","",IF(D17="TAPADA",4,3)) -> 3 | O17: m²
A18: 12 | B18: EJE 05 | C18: TRAMO 02 | D18: TAPADA | E18: 9.9 | F18: 0.4 | G18: 0.46 | H18: 0.51 | I18: =IF(B18="","",(G18+H18)/2) -> 0.485 | J18: =IF(B18="","",2*E18*I18) -> 9.603 | K18: =IF(B18="","",E18*F18) -> 3.96 | L18: =IF(B18="","",IF(D18="TAPADA",E18*F18,0)) -> 3.96 | M18: =SUM(J18:L18) -> 17.523 | N18: =IF(B18="","",IF(D18="TAPADA",4,3)) -> 4 | O18: m²
... A25: 19 | B25: EJE 09 | C25: TRAMO 02 | D25: TAPADA | E25: 6.66 | F25: 0.4 | G25: 0.5 | H25: 0.56 | I25: =IF(B25="","",(G25+H25)/2) -> 0.53 | J25: =IF(B25="","",2*E25*I25) -> 7.0596 | K25: =IF(B25="","",E25*F25) -> 2.664 | L25: =IF(B25="","",IF(D25="TAPADA",E25*F25,0)) -> 2.664 | M25: =SUM(J25:L25) -> 12.3876 | N25: =IF(B25="","",IF(D25="TAPADA",4,3)) -> 4 | O25: m²
A27: TOTAL DE CURADO DE CONCRETO EN CUNETAS | M27: =SUM(M7:M25) -> 801.5833 | O27: m²

Sheet METRADO DE REJILLAS
A1: METRADO DE REJILLAS PARA CUNETAS
A2: ENTIDAD | C2: GERENCIA TERRITORIAL BAJO MAYO - TARAPOTO
A3: PROYECTO | C3: =+RESUMEN!B5 -> CREACIÓN DEL SERVICIO DE PROTECCIÓN INTEGRAL A NIÑAS, NIÑOS Y ADOLESCENTES SIN CUIDADOS PARENTALES O EN RIESGO DE PERDERLOS EN CENTRO DE ACOGIDA RESIDENCIAL - VARONES DISTRITO DE MORALES DE LA PROVINCIA DE SAN MARTÍN DEL DEPARTAMENTO DE SAN MARTÍN, con CUI N.° 2705619
A4: UBICACIÓN | C4: =+RESUMEN!B6 -> SAN MARTIN - SAN MARTIN - MORALES | G4: FECHA | H4: =+RESUMEN!B7 -> 46266
A6: N° | B6: EJE | C6: TRAMO | D6: TIPO DE CUNETA | E6: LONGITUD DEL TRAMO (m) | F6: DESCUENTO SIN REJILLA (m) | G6: LONGITUD CON REJILLA (m) | H6: UND.
A7: 1 | B7: EJE 01 | C7: TRAMO 01 | D7: ABIERTA | E7: 13.2 | F7: 0 | G7: =IF(B7="","",IF(D7="ABIERTA",IF(E7-F7<0,0,E7-F7),0)) -> 13.2 | H7: m
A8: 2 | B8: EJE 01 | C8: TRAMO 02 | D8: TAPADA | E8: 6 | F8: 0 | G8: =IF(B8="","",IF(D8="ABIERTA",IF(E8-F8<0,0,E8-F8),0)) -> 0 | H8: m
A9: 3 | B9: EJE 01 | C9: TRAMO 03 | D9: ABIERTA | E9: 58.1 | F9: 0 | G9: =IF(B9="","",IF(D9="ABIERTA",IF(E9-F9<0,0,E9-F9),0)) -> 58.1 | H9: m
A10: 4 | B10: EJE 01 | C10: TRAMO 04 | D10: TAPADA | E10: 34.23 | F10: 0 | G10: =IF(B10="","",IF(D10="ABIERTA",IF(E10-F10<0,0,E10-F10),0)) -> 0 | H10: m
A11: 5 | B11: EJE 02 | C11: TRAMO 01 | D11: ABIERTA | E11: 34.25 | F11: 0 | G11: =IF(B11="","",IF(D11="ABIERTA",IF(E11-F11<0,0,E11-F11),0)) -> 34.25 | H11: m
A12: 6 | B12: EJE 03 | C12: TRAMO 01 | D12: ABIERTA | E12: 22.4 | F12: 0 | G12: =IF(B12="","",IF(D12="ABIERTA",IF(E12-F12<0,0,E12-F12),0)) -> 22.4 | H12: m
A13: 7 | B13: EJE 04 | C13: TRAMO 01 | D13: ABIERTA | E13: 13.65 | F13: 0 | G13: =IF(B13="","",IF(D13="ABIERTA",IF(E13-F13<0,0,E13-F13),0)) -> 13.65 | H13: m
A14: 8 | B14: EJE 04 | C14: TRAMO 02 | D14: TAPADA | E14: 5.5 | F14: 0 | G14: =IF(B14="","",IF(D14="ABIERTA",IF(E14-F14<0,0,E14-F14),0)) -> 0 | H14: m
A15: 9 | B15: EJE 04 | C15: TRAMO 03 | D15: ABIERTA | E15: 58 | F15: 0 | G15: =IF(B15="","",IF(D15="ABIERTA",IF(E15-F15<0,0,E15-F15),0)) -> 58 | H15: m
A16: 10 | B16: EJE 04 | C16: TRAMO 04 | D16: TAPADA | E16: 25.16 | F16: 0 | G16: =IF(B16="","",IF(D16="ABIERTA",IF(E16-F16<0,0,E16-F16),0)) -> 0 | H16: m
A17: 11 | B17: EJE 05 | C17: TRAMO 01 | D17: ABIERTA | E17: 32.3 | F17: 0 | G17: =IF(B17="","",IF(D17="ABIERTA",IF(E17-F17<0,0,E17-F17),0)) -> 32.3 | H17: m
A18: 12 | B18: EJE 05 | C18: TRAMO 02 | D18: TAPADA | E18: 9.9 | F18: 0 | G18: =IF(B18="","",IF(D18="ABIERTA",IF(E18-F18<0,0,E18-F18),0)) -> 0 | H18: m
... A25: 19 | B25: EJE 09 | C25: TRAMO 02 | D25: TAPADA | E25: 6.66 | F25: 0 | G25: =IF(B25="","",IF(D25="ABIERTA",IF(E25-F25<0,0,E25-F25),0)) -> 0 | H25: m
A27: TOTAL CALCULADO DE REJILLA EN CUNETAS ABIERTAS | G27: =SUM(G7:G25) -> 373.85 | H27: m

Sheet METRADO JUNTA DE DILATACION
A1: PLANILLA DE METRADOS - JUNTA DE DILATACIÓN E=1" (0.0254 m) CON SELLADOR ASFÁLTICO EN CUNETAS: TODA LA SECCIÓN (2 MUROS + LOSA DE FONDO)
A2: ENTIDAD | B2: GERENCIA TERRITORIAL BAJO MAYO - TARAPOTO
A3: PROYECTO | B3: =+RESUMEN!B5 -> CREACIÓN DEL SERVICIO DE PROTECCIÓN INTEGRAL A NIÑAS, NIÑOS Y ADOLESCENTES SIN CUIDADOS PARENTALES O EN RIESGO DE PERDERLOS EN CENTRO DE ACOGIDA RESIDENCIAL - VARONES DISTRITO DE MORALES DE LA PROVINCIA DE SAN MARTÍN DEL DEPARTAMENTO DE SAN MARTÍN, con CUI N.° 2705619
A4: UBICACIÓN | B4: =+RESUMEN!B6 -> SAN MARTIN - SAN MARTIN - MORALES
A5: FECHA | B5: =+RESUMEN!B7 -> 46266
A7: PARÁMETROS
A8: Espaciamiento entre juntas (m) | B8: 3
A9: N° de muros con junta por cuneta | B9: 2
A10: Ancho interior del fondo (m) | B10: 0.4
A11: ITEM | B11: EJE / DESCRIPCIÓN | C11: UND. | D11: LONGITUD EJE (m) | E11: ÁREA MURO (m²) | F11: ALTURA MURO (m) | G11: ESPACIAMIENTO (m) | H11: N° DE JUNTAS | I11: LONG. POR JUNTA (m) 2 muros + fondo | J11: PARCIAL (ml)
A12: Descripccion | B12: JUNTA DE DILATACION E=1" CON SELLADOR ASFALTO | C12: ml | J12: =SUM(J13:J21) -> 252.28688
A13: 1 | B13: EJE 01 | D13: 111.53 | E13: =+'CONCRETO EN CUNETAS'!E10 -> 61.2 | F13: =E13/D13 -> 0.54873128 | G13: =B8 -> 3 | H13: =ROUNDUP(D13/G13,0) -> 38 | I13: =$B$9*F13+$B$10 -> 1.4974626 | J13: =H13*I13 -> 56.903578
A14: 2 | B14: EJE 02 | D14: 34.25 | E14: =+'CONCRETO EN CUNETAS'!E22 -> 13.19 | F14: =E14/D14 -> 0.38510949 | G14: =B8 -> 3 | H14: =ROUNDUP(D14/G14,0) -> 12 | I14: =$B$9*F14+$B$10 -> 1.170219 | J14: =H14*I14 -> 14.042628
A15: 3 | B15: EJE 03 | D15: 22.4 | E15: =+'CONCRETO EN CUNETAS'!E34 -> 7.98 | F15: =E15/D15 -> 0.35625 | G15: =B8 -> 3 | H15: =ROUNDUP(D15/G15,0) -> 8 | I15: =$B$9*F15+$B$10 -> 1.1125 | J15: =H15*I15 -> 8.9
A16: 4 | B16: EJE 04 | D16: 102.31 | E16: =+'CONCRETO EN CUNETAS'!E46 -> 54.29 | F16: =E16/D16 -> 0.53064217 | G16: =B8 -> 3 | H16: =ROUNDUP(D16/G16,0) -> 35 | I16: =$B$9*F16+$B$10 -> 1.4612843 | J16: =H16*I16 -> 51.144952
A17: 5 | B17: EJE 05 | D17: 42.2 | E17: =+'CONCRETO EN CUNETAS'!E58 -> 17.07 | F17: =E17/D17 -> 0.40450237 | G17: =B8 -> 3 | H17: =ROUNDUP(D17/G17,0) -> 15 | I17: =$B$9*F17+$B$10 -> 1.2090047 | J17: =H17*I17 -> 18.135071
A18: 6 | B18: EJE 06 | D18: 98.69 | E18: =+'CONCRETO EN CUNETAS'!E70 -> 52.71 | F18: =E18/D18 -> 0.53409667 | G18: =B8 -> 3 | H18: =ROUNDUP(D18/G18,0) -> 33 | I18: =$B$9*F18+$B$10 -> 1.4681933 | J18: =H18*I18 -> 48.45038
A19: 7 | B19: EJE 07 | D19: 23.6 | E19: =+'CONCRETO EN CUNETAS'!M10 -> 8.46 | F19: =E19/D19 -> 0.35847458 | G19: =B8 -> 3 | H19: =ROUNDUP(D19/G19,0) -> 8 | I19: =$B$9*F19+$B$10 -> 1.1169492 | J19: =H19*I19 -> 8.9355932
A20: 8 | B20: EJE 08 | D20: 60.6 | E20: =+'CONCRETO EN CUNETAS'!M22 -> 27.34 | F20: =E20/D20 -> 0.45115512 | G20: =B8 -> 3 | H20: =ROUNDUP(D20/G20,0) -> 21 | I20: =$B$9*F20+$B$10 -> 1.3023102 | J20: =H20*I20 -> 27.348515
A21: 9 | B21: EJE 09 | D21: 42.66 | E21: =+'CONCRETO EN CUNETAS'!M34 -> 17.67 | F21: =E21/D21 -> 0.41420534 | G21: =B8 -> 3 | H21: =ROUNDUP(D21/G21,0) -> 15 | I21: =$B$9*F21+$B$10 -> 1.2284107 | J21: =H21*I21 -> 18.42616
A23: NOTAS:
A24: 1. EG-2013 MTC, Seccion 510 (cunetas revestidas de concreto): la junta corta toda la seccion en U, es decir los dos muros y la losa de fondo, para que cada paño de 3.00 m trabaje independiente.
A25: 2. Longitud por junta = 2 x altura del muro (area del muro / longitud del eje, hoja CONCRETO EN CUNETAS) + ancho interior del fondo 0.40 m.
