Workbook

Sheet RESUMEN
A1: RESUMEN DE METRADOS - EVACUACIÓN Y SEÑALIZACIÓN
A2: PROYECTO | B2: “CREACIÓN DEL SERVICIO DE PROTECCIÓN INTEGRAL A NIÑAS, NIÑOS Y ADOLESCENTES SIN CUIDADOS PARENTALES O EN RIESGO DE PERDERLOS EN CENTRO DE ACOGIDA RESIDENCIAL - VARONES DISTRITO DE MORALES DE LA PROVINCIA DE SAN MARTÍN DEL DEPARTAMENTO DE SAN MARTÍN”
A3: CUI | B3: N.° 2705619
A4: ESPECIALIDAD | B4: ARQUITECTURA - EVACUACIÓN Y SEÑALIZACIÓN
A5: UBICACIÓN | B5: Distrito de Morales, provincia y departamento de San Martín
A6: LÁMINAS | B6: SE-S-01 Plano de señalización (esc. 1/150) y SE-E-01 Plano de evacuación (esc. 1/150)
A7: FECHA | B7: SETIEMBRE 2026
A9: ITEM | B9: DESCRIPCIÓN | C9: UND | D9: METRADO
A10: 01 | B10: SEÑALIZACIÓN, EVACUACIÓN Y SEGURIDAD
A11: 01.01 | B11: SEÑALES DE EVACUACIÓN Y EMERGENCIA
A12: 01.01.01 | B12: SEÑAL DE SALIDA CON BRAILLE | C12: und | D12: ='METRADO'!P12
A13: 01.01.02 | B13: SEÑAL DE ZONA SEGURA EN CASO DE SISMO CON BRAILLE | C13: und | D13: ='METRADO'!P13
A14: 01.01.03 | B14: LETRERO DE AFORO CON BRAILLE | C14: und | D14: ='METRADO'!P14
A15: 01.01.04 | B15: ZONA DE REUNIÓN (ZONA SEGURA EXTERNA) PINTADA EN PISO | C15: und | D15: ='METRADO'!P15
A16: 01.02 | B16: SEÑALES DE EQUIPOS CONTRA INCENDIO
A17: 01.02.01 | B17: SEÑAL DE UBICACIÓN DE EXTINTOR PQS CON BRAILLE | C17: und | D17: ='METRADO'!P17
A18: 01.02.02 | B18: SEÑAL DE UBICACIÓN DE EXTINTOR CO2 CON BRAILLE | C18: und | D18: ='METRADO'!P18
A19: 01.02.03 | B19: SEÑAL DE ALARMA CONTRA INCENDIOS CON BRAILLE | C19: und | D19: ='METRADO'!P19
A20: 01.02.04 | B20: SEÑAL DE AVISADOR SONORO CON BRAILLE | C20: und | D20: ='METRADO'!P20
A21: 01.02.05 | B21: SEÑAL DE CENTRAL DE ALARMA CONTRA INCENDIO CON BRAILLE | C21: und | D21: ='METRADO'!P21
A22: 01.03 | B22: SEÑALES DE ADVERTENCIA Y PROHIBICIÓN
A23: 01.03.01 | B23: SEÑAL DE ATENCIÓN RIESGO ELÉCTRICO CON BRAILLE | C23: und | D23: ='METRADO'!P23
A24: 01.03.02 | B24: SEÑAL DE RIESGO DE DESCARGA ELÉCTRICA CON BRAILLE | C24: und | D24: ='METRADO'!P24
A25: 01.03.03 | B25: SEÑAL DE PROHIBIDO EL INGRESO SOLO PERSONAL AUTORIZADO CON BRAILLE | C25: und | D25: ='METRADO'!P25
A26: 01.04 | B26: SEÑALES INFORMATIVAS
A27: 01.04.01 | B27: SEÑAL DE SERVICIOS HIGIÉNICOS PARA PERSONAS CON DISCAPACIDAD CON BRAILLE | C27: und | D27: ='METRADO'!P27
A28: 01.04.02 | B28: SEÑAL DE SERVICIOS HIGIÉNICOS MIXTO CON BRAILLE | C28: und | D28: ='METRADO'!P28
A29: 01.04.03 | B29: SEÑAL DE SERVICIOS HIGIÉNICOS MUJER CON BRAILLE | C29: und | D29: ='METRADO'!P29
A30: 01.04.04 | B30: SEÑAL DE SERVICIOS HIGIÉNICOS VARÓN CON BRAILLE | C30: und | D30: ='METRADO'!P30
A31: 01.04.05 | B31: SEÑAL DE BOTIQUÍN DE PRIMEROS AUXILIOS CON BRAILLE | C31: und | D31: ='METRADO'!P31
A32: 01.04.06 | B32: SEÑAL DE PUNTO ECOLÓGICO CON BRAILLE | C32: und | D32: ='METRADO'!P32
A33: 01.05 | B33: EQUIPOS DE PROTECCIÓN CONTRA INCENDIO Y EMERGENCIA
A34: 01.05.01 | B34: EXTINTOR DE POLVO QUÍMICO SECO (PQS) TIPO ABC DE 6 kg | C34: und | D34: ='METRADO'!P34
A35: 01.05.02 | B35: EXTINTOR DE DIÓXIDO DE CARBONO (CO2) DE 10 lb | C35: und | D35: ='METRADO'!P35
A36: 01.05.03 | B36: UNIDAD DE LUCES DE EMERGENCIA | C36: und | D36: ='METRADO'!P36
A37: 01.05.04 | B37: DETECTOR DE HUMO | C37: und | D37: ='METRADO'!P37

Sheet METRADO
A1: METRADO DE EVACUACIÓN Y SEÑALIZACIÓN POR EDIFICACIÓN
A2: PROYECTO | B2: “CREACIÓN DEL SERVICIO DE PROTECCIÓN INTEGRAL A NIÑAS, NIÑOS Y ADOLESCENTES SIN CUIDADOS PARENTALES O EN RIESGO DE PERDERLOS EN CENTRO DE ACOGIDA RESIDENCIAL - VARONES DISTRITO DE MORALES DE LA PROVINCIA DE SAN MARTÍN DEL DEPARTAMENTO DE SAN MARTÍN”
A3: CUI | B3: N.° 2705619
A4: ESPECIALIDAD | B4: ARQUITECTURA - EVACUACIÓN Y SEÑALIZACIÓN
A5: UBICACIÓN | B5: Distrito de Morales, provincia y departamento de San Martín
A6: LÁMINAS | B6: SE-S-01 Plano de señalización (esc. 1/150) y SE-E-01 Plano de evacuación (esc. 1/150)
A7: FECHA | B7: SETIEMBRE 2026
A9: ITEM | B9: DESCRIPCIÓN | C9: UND | D9: E-01 | E9: E-02 | F9: E-03 | G9: E-04 | H9: E-05 | I9: E-06 | J9: E-07 | K9: E-08 | L9: E-09 | M9: E-10 | N9: EXT | O9: SIN UBICAR | P9: TOTAL | Q9: LEYENDA SE-S-01 | R9: DIFERENCIA | S9: FUENTE DE LA CANTIDAD
D10: Administración | E10: Vestidores de la losa deportiva | F10: Módulo de madres sustitutas | G10: Módulo de 12 a 17 años (1) | H10: Módulo de 12 a 17 años (2) | I10: Módulo de 3 a 5 años | J10: Módulo de 6 a 11 años | K10: SUM y cocina | L10: SS.HH. público | M10: Servicios generales | N10: Exteriores
A11: 01 | B11: SEÑALES DE EVACUACIÓN Y EMERGENCIA
A12: 01.01 | B12: SEÑAL DE SALIDA CON BRAILLE | C12: und | D12: 19 | E12: 6 | F12: 4 | G12: 9 | H12: 8 | I12: 8 | J12: 9 | K12: 9 | L12: 3 | M12: 3 | N12: 2 | P12: =SUM(D12:O12) | Q12: 80 | R12: =P12-Q12 | S12: Planta de SE-S-01: símbolos dibujados (leyenda: 80)
A13: 01.02 | B13: SEÑAL DE ZONA SEGURA EN CASO DE SISMO CON BRAILLE | C13: und | D13: 5 | E13: 2 | F13: 2 | G13: 9 | H13: 9 | I13: 9 | J13: 9 | K13: 10 | L13: 2 | M13: 4 | N13: 1 | P13: =SUM(D13:O13) | Q13: 62 | R13: =P13-Q13 | S13: Planta de SE-S-01: símbolos dibujados (leyenda: 62)
A14: 01.03 | B14: LETRERO DE AFORO CON BRAILLE | C14: und | D14: 2 | E14: 2 | F14: 1 | G14: 1 | H14: 1 | I14: 1 | J14: 1 | K14: 2 | M14: 1 | N14: 2 | P14: =SUM(D14:O14) | Q14: 14 | R14: =P14-Q14 | S14: Planta de SE-S-01: símbolos dibujados (leyenda: 14)
A15: 01.04 | B15: ZONA DE REUNIÓN (ZONA SEGURA EXTERNA) PINTADA EN PISO | C15: und | N15: 13 | P15: =SUM(D15:O15) | Q15: 11 | R15: =P15-Q15 | S15: Lámina SE-E-01: zonas seguras S1 a S13 dibujadas
A16: 02 | B16: SEÑALES DE EQUIPOS CONTRA INCENDIO
A17: 02.01 | B17: SEÑAL DE UBICACIÓN DE EXTINTOR PQS CON BRAILLE | C17: und | D17: 1 | E17: 1 | F17: 1 | G17: 1 | H17: 1 | I17: 1 | J17: 1 | K17: 2 | P17: =SUM(D17:O17) | Q17: 9 | R17: =P17-Q17 | S17: Planta de SE-S-01: símbolos dibujados (leyenda: 9)
A18: 02.02 | B18: SEÑAL DE UBICACIÓN DE EXTINTOR CO2 CON BRAILLE | C18: und | K18: 2 | P18: =SUM(D18:O18) | Q18: 2 | R18: =P18-Q18 | S18: Planta de SE-S-01: símbolos dibujados (leyenda: 2)
A19: 02.03 | B19: SEÑAL DE ALARMA CONTRA INCENDIOS CON BRAILLE | C19: und | D19: 1 | F19: 1 | G19: 1 | H19: 1 | I19: 1 | J19: 1 | K19: 1 | L19: 1 | P19: =SUM(D19:O19) | Q19: 8 | R19: =P19-Q19 | S19: Planta de SE-S-01: símbolos dibujados (leyenda: 8)
A20: 02.04 | B20: SEÑAL DE AVISADOR SONORO CON BRAILLE | C20: und | O20: 8 | P20: =SUM(D20:O20) | Q20: 8 | R20: =P20-Q20 | S20: Leyenda de SE-S-01 (el símbolo es una imagen pegada sin ubicación en el DXF)
A21: 02.05 | B21: SEÑAL DE CENTRAL DE ALARMA CONTRA INCENDIO CON BRAILLE | C21: und | D21: 1 | P21: =SUM(D21:O21) | Q21: 1 | R21: =P21-Q21 | S21: Planta de SE-S-01: símbolos dibujados (leyenda: 1)
A22: 03 | B22: SEÑALES DE ADVERTENCIA Y PROHIBICIÓN
A23: 03.01 | B23: SEÑAL DE ATENCIÓN RIESGO ELÉCTRICO CON BRAILLE | C23: und | O23: 2 | P23: =SUM(D23:O23) | Q23: 2 | R23: =P23-Q23 | S23: Leyenda de SE-S-01 (el símbolo es una imagen pegada sin ubicación en el DXF)
A24: 03.02 | B24: SEÑAL DE RIESGO DE DESCARGA ELÉCTRICA CON BRAILLE | C24: und | O24: 4 | P24: =SUM(D24:O24) | Q24: 4 | R24: =P24-Q24 | S24: Leyenda de SE-S-01 (el símbolo es una imagen pegada sin ubicación en el DXF)
A25: 03.03 | B25: SEÑAL DE PROHIBIDO EL INGRESO SOLO PERSONAL AUTORIZADO CON BRAILLE | C25: und | O25: 1 | P25: =SUM(D25:O25) | Q25: 1 | R25: =P25-Q25 | S25: Leyenda de SE-S-01 (el símbolo es una imagen pegada sin ubicación en el DXF)
A26: 04 | B26: SEÑALES INFORMATIVAS
A27: 04.01 | B27: SEÑAL DE SERVICIOS HIGIÉNICOS PARA PERSONAS CON DISCAPACIDAD CON BRAILLE | C27: und | L27: 1 | P27: =SUM(D27:O27) | Q27: 1 | R27: =P27-Q27 | S27: Planta de SE-S-01: símbolos dibujados (leyenda: 1)
A28: 04.02 | B28: SEÑAL DE SERVICIOS HIGIÉNICOS MIXTO CON BRAILLE | C28: und | K28: 1 | P28: =SUM(D28:O28) | Q28: 1 | R28: =P28-Q28 | S28: Planta de SE-S-01: símbolos dibujados (leyenda: 1)
A29: 04.03 | B29: SEÑAL DE SERVICIOS HIGIÉNICOS MUJER CON BRAILLE | C29: und | D29: 1 | F29: 2 | L29: 1 | P29: =SUM(D29:O29) | Q29: 4 | R29: =P29-Q29 | S29: Planta de SE-S-01: símbolos dibujados (leyenda: 4)
A30: 04.04 | B30: SEÑAL DE SERVICIOS HIGIÉNICOS VARÓN CON BRAILLE | C30: und | D30: 1 | G30: 4 | H30: 4 | I30: 4 | J30: 4 | L30: 1 | P30: =SUM(D30:O30) | Q30: 18 | R30: =P30-Q30 | S30: Planta de SE-S-01: símbolos dibujados (leyenda: 18)
A31: 04.05 | B31: SEÑAL DE BOTIQUÍN DE PRIMEROS AUXILIOS CON BRAILLE | C31: und | D31: 2 | E31: 1 | F31: 2 | G31: 2 | H31: 2 | I31: 2 | J31: 2 | K31: 3 | L31: 2 | M31: 1 | N31: 1 | P31: =SUM(D31:O31) | Q31: 20 | R31: =P31-Q31 | S31: Planta de SE-S-01: símbolos dibujados (leyenda: 20)
A32: 04.06 | B32: SEÑAL DE PUNTO ECOLÓGICO CON BRAILLE | C32: und | H32: 1 | I32: 1 | J32: 1 | N32: 3 | P32: =SUM(D32:O32) | Q32: 6 | R32: =P32-Q32 | S32: Planta de SE-S-01: símbolos dibujados (leyenda: 6)
A33: 05 | B33: EQUIPOS DE PROTECCIÓN CONTRA INCENDIO Y EMERGENCIA
A34: 05.01 | B34: EXTINTOR DE POLVO QUÍMICO SECO (PQS) TIPO ABC DE 6 kg | C34: und | D34: 1 | E34: 1 | F34: 1 | G34: 1 | H34: 1 | I34: 1 | J34: 1 | K34: 2 | P34: =SUM(D34:O34) | Q34: 9 | R34: =P34-Q34 | S34: Planta de SE-S-01: símbolos dibujados (leyenda: 9)
A35: 05.02 | B35: EXTINTOR DE DIÓXIDO DE CARBONO (CO2) DE 10 lb | C35: und | K35: 2 | P35: =SUM(D35:O35) | Q35: 2 | R35: =P35-Q35 | S35: Planta de SE-S-01: símbolos dibujados (leyenda: 2)
A36: 05.03 | B36: UNIDAD DE LUCES DE EMERGENCIA | C36: und | D36: 9 | E36: 3 | F36: 2 | G36: 8 | H36: 8 | I36: 8 | J36: 8 | K36: 8 | L36: 4 | M36: 4 | N36: 2 | P36: =SUM(D36:O36) | Q36: 64 | R36: =P36-Q36 | S36: Planta de SE-S-01: símbolos dibujados (leyenda: 64)
A37: 05.04 | B37: DETECTOR DE HUMO | C37: und | D37: 12 | E37: 3 | F37: 2 | G37: 8 | H37: 8 | I37: 8 | J37: 7 | K37: 10 | M37: 5 | N37: 1 | P37: =SUM(D37:O37) | Q37: 64 | R37: =P37-Q37 | S37: Planta de SE-S-01: símbolos dibujados (leyenda: 64)
B38: TOTAL DE SEÑALES Y EQUIPOS | D38: =SUM(D11:D37) | E38: =SUM(E11:E37) | F38: =SUM(F11:F37) | G38: =SUM(G11:G37) | H38: =SUM(H11:H37) | I38: =SUM(I11:I37) | J38: =SUM(J11:J37) | K38: =SUM(K11:K37) | ... P38: =SUM(P11:P37)
A40: Notas:
A41: 1. Cantidad por edificación: cada símbolo de la planta de la lámina SE-S-01 se asigna a la edificación donde está (contorno del bloque de la planta general, con 0.60 m de margen para las señales de fachada); EXT = obras exteriores y complementarias (patios, ingresos, caseta, losa deportiva y circulaciones).
A42: 2. SIN UBICAR: señales que en el DXF son imágenes pegadas (avisador sonoro, atención riesgo eléctrico, riesgo de descarga eléctrica y prohibido el ingreso); su ubicación no se exporta y vale la cantidad de la leyenda. Se instalan donde indica la lámina SE-S-01 y en coordinación con el plano de instalaciones eléctricas.
...

Sheet ZONAS DE REUNIÓN
A1: ZONAS DE REUNIÓN (ZONAS SEGURAS EXTERNAS) PINTADAS EN EL PISO - LÁMINA SE-E-01
A2: PROYECTO | B2: “CREACIÓN DEL SERVICIO DE PROTECCIÓN INTEGRAL A NIÑAS, NIÑOS Y ADOLESCENTES SIN CUIDADOS PARENTALES O EN RIESGO DE PERDERLOS EN CENTRO DE ACOGIDA RESIDENCIAL - VARONES DISTRITO DE MORALES DE LA PROVINCIA DE SAN MARTÍN DEL DEPARTAMENTO DE SAN MARTÍN”
A3: CUI | B3: N.° 2705619
A4: ESPECIALIDAD | B4: ARQUITECTURA - EVACUACIÓN Y SEÑALIZACIÓN
A5: UBICACIÓN | B5: Distrito de Morales, provincia y departamento de San Martín
A6: LÁMINAS | B6: SE-S-01 Plano de señalización (esc. 1/150) y SE-E-01 Plano de evacuación (esc. 1/150)
A7: FECHA | B7: SETIEMBRE 2026
A9: Radio (m) | B9: 1.5 | C9: Ancho de línea (m) | D9: 0.1 | E9: Círculo pintado con pintura de tránsito color amarillo tráfico (leyenda de SE-E-01)
A11: N.° | B11: ZONA | C11: UBICACIÓN (edificación más cercana) | D11: RADIO (m) | E11: ANCHO (m) | F11: PERÍMETRO (m) | G11: ÁREA PINTADA (m²) | H11: UND
A12: 1 | B12: S1 | C12: E-01 Administración | D12: =$B$9 | E12: =$D$9 | F12: =2*PI()*D12 | G12: =F12*E12 | H12: 1
A13: 2 | B13: S2 | C13: E-10 Servicios generales | D13: =$B$9 | E13: =$D$9 | F13: =2*PI()*D13 | G13: =F13*E13 | H13: 1
A14: 3 | B14: S3 | C14: E-08 SUM y cocina | D14: =$B$9 | E14: =$D$9 | F14: =2*PI()*D14 | G14: =F14*E14 | H14: 1
A15: 4 | B15: S4 | C15: E-08 SUM y cocina | D15: =$B$9 | E15: =$D$9 | F15: =2*PI()*D15 | G15: =F15*E15 | H15: 1
A16: 5 | B16: S5 | C16: E-08 SUM y cocina | D16: =$B$9 | E16: =$D$9 | F16: =2*PI()*D16 | G16: =F16*E16 | H16: 1
A17: 6 | B17: S6 | C17: E-09 SS.HH. público | D17: =$B$9 | E17: =$D$9 | F17: =2*PI()*D17 | G17: =F17*E17 | H17: 1
A18: 7 | B18: S7 | C18: E-01 Administración | D18: =$B$9 | E18: =$D$9 | F18: =2*PI()*D18 | G18: =F18*E18 | H18: 1
A19: 8 | B19: S8 | C19: E-04 Módulo de 12 a 17 años (1) | D19: =$B$9 | E19: =$D$9 | F19: =2*PI()*D19 | G19: =F19*E19 | H19: 1
A20: 9 | B20: S9 | C20: E-02 Vestidores de la losa deportiva | D20: =$B$9 | E20: =$D$9 | F20: =2*PI()*D20 | G20: =F20*E20 | H20: 1
A21: 10 | B21: S10 | C21: E-07 Módulo de 6 a 11 años | D21: =$B$9 | E21: =$D$9 | F21: =2*PI()*D21 | G21: =F21*E21 | H21: 1
A22: 11 | B22: S11 | C22: E-04 Módulo de 12 a 17 años (1) | D22: =$B$9 | E22: =$D$9 | F22: =2*PI()*D22 | G22: =F22*E22 | H22: 1
A23: 12 | B23: S12 | C23: E-06 Módulo de 3 a 5 años | D23: =$B$9 | E23: =$D$9 | F23: =2*PI()*D23 | G23: =F23*E23 | H23: 1
A24: 13 | B24: S13 | C24: E-05 Módulo de 12 a 17 años (2) | D24: =$B$9 | E24: =$D$9 | F24: =2*PI()*D24 | G24: =F24*E24 | H24: 1
C25: TOTAL | F25: =SUM(F12:F24) | G25: =SUM(G12:G24) | H25: =SUM(H12:H24)

Sheet RUTAS Y AFOROS
A1: RUTAS DE EVACUACIÓN, AFOROS Y POBLACIÓN - LÁMINA SE-E-01
A2: PROYECTO | B2: “CREACIÓN DEL SERVICIO DE PROTECCIÓN INTEGRAL A NIÑAS, NIÑOS Y ADOLESCENTES SIN CUIDADOS PARENTALES O EN RIESGO DE PERDERLOS EN CENTRO DE ACOGIDA RESIDENCIAL - VARONES DISTRITO DE MORALES DE LA PROVINCIA DE SAN MARTÍN DEL DEPARTAMENTO DE SAN MARTÍN”
A3: CUI | B3: N.° 2705619
A4: ESPECIALIDAD | B4: ARQUITECTURA - EVACUACIÓN Y SEÑALIZACIÓN
A5: UBICACIÓN | B5: Distrito de Morales, provincia y departamento de San Martín
A6: LÁMINAS | B6: SE-S-01 Plano de señalización (esc. 1/150) y SE-E-01 Plano de evacuación (esc. 1/150)
A7: FECHA | B7: SETIEMBRE 2026
A9: Velocidad de desplazamiento (m/s) | D9: 0.6
A10: Recorrido máximo hasta un lugar seguro, sin rociadores - RNE A.130 (m) | D10: 45
A12: RUTA | B12: AMBIENTE QUE EVACÚA | C12: LONGITUD (m) | D12: TIEMPO DE DESPLAZAMIENTO (s) | E12: VERIFICACIÓN
A13: RUTA 01 | B13: Administración | C13: 23.74 | D13: =C13/$D$9 | E13: =IF(C13<=$D$10,"cumple","no cumple")
A14: RUTA 02 | B14: Servicios generales | C14: 15.51 | D14: =C14/$D$9 | E14: =IF(C14<=$D$10,"cumple","no cumple")
A15: RUTA 03 | B15: SUM + Cocina | C15: 37.3 | D15: =C15/$D$9 | E15: =IF(C15<=$D$10,"cumple","no cumple")
A16: RUTA 04 | B16: Cocina | C16: 14.07 | D16: =C16/$D$9 | E16: =IF(C16<=$D$10,"cumple","no cumple")
A17: RUTA 05 | B17: SUM | C17: 20.14 | D17: =C17/$D$9 | E17: =IF(C17<=$D$10,"cumple","no cumple")
A18: RUTA 06 | B18: SS.HH. público | C18: 20.38 | D18: =C18/$D$9 | E18: =IF(C18<=$D$10,"cumple","no cumple")
A19: RUTA 07 | B19: Administración | C19: 12.7 | D19: =C19/$D$9 | E19: =IF(C19<=$D$10,"cumple","no cumple")
A20: RUTA 08 | B20: Módulo madres | C20: 36.93 | D20: =C20/$D$9 | E20: =IF(C20<=$D$10,"cumple","no cumple")
A21: RUTA 09 | B21: Vestidores losa deportiva | C21: 17.68 | D21: =C21/$D$9 | E21: =IF(C21<=$D$10,"cumple","no cumple")
A22: RUTA 10 | B22: Módulo de 12 - 17 años | C22: 32.45 | D22: =C22/$D$9 | E22: =IF(C22<=$D$10,"cumple","no cumple")
A23: RUTA 11 | B23: Módulo de 6 - 11 años | C23: 32.58 | D23: =C23/$D$9 | E23: =IF(C23<=$D$10,"cumple","no cumple")
A24: RUTA 12 | B24: Módulo de 12 - 17 años | C24: 32.45 | D24: =C24/$D$9 | E24: =IF(C24<=$D$10,"cumple","no cumple")
A25: RUTA 13 | B25: Módulo de 3 - 5 años | C25: 32.58 | D25: =C25/$D$9 | E25: =IF(C25<=$D$10,"cumple","no cumple")
A27: EDIFICACIÓN | B27: AMBIENTE | C27: AFORO (personas)
A28: E-01 | B28: Administración | C28: 11
A29: E-02 | B29: Vestidores de la losa deportiva | C29: 5
A30: E-03 | B30: Módulo de madres sustitutas | C30: 5
A31: E-04 | B31: Módulo de 12 a 17 años (1) | C31: 11
A32: E-05 | B32: Módulo de 12 a 17 años (2) | C32: 11
A33: E-06 | B33: Módulo de 3 a 5 años | C33: 11
A34: E-07 | B34: Módulo de 6 a 11 años | C34: 11
A35: E-08 | B35: SUM | C35: 66
A36: E-08 | B36: Cocina | C36: 5
A37: E-09 | B37: SS.HH. público | C37: 6
A38: E-10 | B38: Servicios generales | C38: 4
A39: EXT | B39: Caseta de control (O.E. 04) | C39: 1
A41: POBLACIÓN | B41: DETALLE | C41: PERSONAS
A42: Personal | B42: Madres sustitutas | C42: 5
A43: Personal | B43: Personal administrativo | C43: 11
A44: Personal | B44: Personal de apoyo | C44: 6
...

Sheet SEÑALES
A1: CARACTERÍSTICAS DE LAS SEÑALES Y EQUIPOS (NTP 399.010-1, RNE A.120 Y A.130)
A2: PROYECTO | B2: “CREACIÓN DEL SERVICIO DE PROTECCIÓN INTEGRAL A NIÑAS, NIÑOS Y ADOLESCENTES SIN CUIDADOS PARENTALES O EN RIESGO DE PERDERLOS EN CENTRO DE ACOGIDA RESIDENCIAL - VARONES DISTRITO DE MORALES DE LA PROVINCIA DE SAN MARTÍN DEL DEPARTAMENTO DE SAN MARTÍN”
A3: CUI | B3: N.° 2705619
A4: ESPECIALIDAD | B4: ARQUITECTURA - EVACUACIÓN Y SEÑALIZACIÓN
A5: UBICACIÓN | B5: Distrito de Morales, provincia y departamento de San Martín
A6: LÁMINAS | B6: SE-S-01 Plano de señalización (esc. 1/150) y SE-E-01 Plano de evacuación (esc. 1/150)
A7: FECHA | B7: SETIEMBRE 2026
A9: ITEM | B9: PARTIDA | C9: DIMENSIONES | D9: MATERIAL | E9: ALTURA DE INSTALACIÓN | F9: ALTURA EN LA LEYENDA | G9: FUNCIÓN Y UBICACIÓN
A10: 01 | B10: SEÑALES DE EVACUACIÓN Y EMERGENCIA
A11: 01.01 | B11: SEÑAL DE SALIDA CON BRAILLE | C11: 0.30 x 0.20 m | D11: Lámina de PVC celtex de 3 mm con vinil fotoluminiscente impreso y placa de acrílico con texto en braille | E11: 2.10 m | F11: 2.10 | G11: Indica la puerta de salida y la dirección de la ruta de evacuación; sobre el dintel de las puertas de salida y en la circulación peatonal interna.
A12: 01.02 | B12: SEÑAL DE ZONA SEGURA EN CASO DE SISMO CON BRAILLE | C12: 0.20 x 0.30 m | D12: Lámina de PVC celtex de 3 mm con vinil fotoluminiscente impreso y placa de acrílico con texto en braille | E12: 1.80 m | F12: 1.80 | G12: Identifica los lugares de protección dentro de los ambientes (columnas y muros estructurales) durante un sismo.
A13: 01.03 | B13: LETRERO DE AFORO CON BRAILLE | C13: 0.30 x 0.20 m | D13: Lámina de PVC celtex de 3 mm con vinil adhesivo impreso y placa de acrílico con texto en braille | E13: 2.10 m | F13: 2.10 | G13: Indica la capacidad máxima de personas del ambiente; junto al ingreso, en el lado de la cerradura.
A14: 01.04 | B14: ZONA DE REUNIÓN (ZONA SEGURA EXTERNA) PINTADA EN PISO | C14: círculo de 1.50 m de radio, línea de 0.10 m | D14: Pintura de tránsito color amarillo sobre piso de concreto | E14: en piso | F14: EN PISO | G14: Lugar exterior de concentración de los ocupantes al final de cada ruta de evacuación (S1 a S13 de la lámina SE-E-01).
A15: 02 | B15: SEÑALES DE EQUIPOS CONTRA INCENDIO
A16: 02.01 | B16: SEÑAL DE UBICACIÓN DE EXTINTOR PQS CON BRAILLE | C16: 0.20 x 0.30 m | D16: Lámina de PVC celtex de 3 mm con vinil fotoluminiscente impreso y placa de acrílico con texto en braille | E16: 1.80 m | F16: 1.20 | G16: Identifica la ubicación del extintor de polvo químico seco; sobre el equipo.
A17: 02.02 | B17: SEÑAL DE UBICACIÓN DE EXTINTOR CO2 CON BRAILLE | C17: 0.20 x 0.30 m | D17: Lámina de PVC celtex de 3 mm con vinil fotoluminiscente impreso y placa de acrílico con texto en braille | E17: 1.80 m | F17: 1.20 | G17: Identifica la ubicación del extintor de dióxido de carbono; sobre el equipo.
A18: 02.03 | B18: SEÑAL DE ALARMA CONTRA INCENDIOS CON BRAILLE | C18: 0.20 x 0.30 m | D18: Lámina de PVC celtex de 3 mm con vinil fotoluminiscente impreso y placa de acrílico con texto en braille | E18: 1.80 m | F18: 1.80 | G18: Identifica la estación manual (pulsador) de alarma contra incendios.
A19: 02.04 | B19: SEÑAL DE AVISADOR SONORO CON BRAILLE | C19: 0.20 x 0.30 m | D19: Lámina de PVC celtex de 3 mm con vinil fotoluminiscente impreso y placa de acrílico con texto en braille | E19: 2.00 m | F19: 2.00 | G19: Identifica la sirena o avisador sonoro del sistema de alarma.
A20: 02.05 | B20: SEÑAL DE CENTRAL DE ALARMA CONTRA INCENDIO CON BRAILLE | C20: 0.20 x 0.30 m | D20: Lámina de PVC celtex de 3 mm con vinil fotoluminiscente impreso y placa de acrílico con texto en braille | E20: 1.10 m | F20: 1.10 | G20: Identifica el panel central del sistema de detección y alarma.
A21: 03 | B21: SEÑALES DE ADVERTENCIA Y PROHIBICIÓN
A22: 03.01 | B22: SEÑAL DE ATENCIÓN RIESGO ELÉCTRICO CON BRAILLE | C22: 0.20 x 0.30 m | D22: Lámina de PVC celtex de 3 mm con vinil adhesivo impreso y placa de acrílico con texto en braille | E22: 1.10 m | F22: 1.10 | G22: Advierte la presencia de tableros y equipos eléctricos; en la puerta o frente del tablero.
A23: 03.02 | B23: SEÑAL DE RIESGO DE DESCARGA ELÉCTRICA CON BRAILLE | C23: 0.20 x 0.30 m | D23: Lámina de PVC celtex de 3 mm con vinil adhesivo impreso y placa de acrílico con texto en braille | E23: 1.10 m | F23: 1.10 | G23: Advierte el riesgo de descarga eléctrica en tableros, subestación y grupo electrógeno.
A24: 03.03 | B24: SEÑAL DE PROHIBIDO EL INGRESO SOLO PERSONAL AUTORIZADO CON BRAILLE | C24: 0.30 x 0.20 m | D24: Lámina de PVC celtex de 3 mm con vinil adhesivo impreso y placa de acrílico con texto en braille | E24: 1.10 m | F24: 1.10 | G24: Restringe el ingreso a los ambientes técnicos al personal autorizado.
A25: 04 | B25: SEÑALES INFORMATIVAS
A26: 04.01 | B26: SEÑAL DE SERVICIOS HIGIÉNICOS PARA PERSONAS CON DISCAPACIDAD CON BRAILLE | C26: 0.20 x 0.20 m | D26: Lámina de PVC celtex de 3 mm con vinil adhesivo impreso y placa de acrílico con texto en braille | E26: 1.80 m | F26: 1.80 | G26: Identifica el servicio higiénico accesible.
A27: 04.02 | B27: SEÑAL DE SERVICIOS HIGIÉNICOS MIXTO CON BRAILLE | C27: 0.20 x 0.20 m | D27: Lámina de PVC celtex de 3 mm con vinil adhesivo impreso y placa de acrílico con texto en braille | E27: 1.80 m | F27: 1.80 | G27: Identifica el servicio higiénico de uso mixto.
A28: 04.03 | B28: SEÑAL DE SERVICIOS HIGIÉNICOS MUJER CON BRAILLE | C28: 0.20 x 0.20 m | D28: Lámina de PVC celtex de 3 mm con vinil adhesivo impreso y placa de acrílico con texto en braille | E28: 1.80 m | F28: 1.80 | G28: Identifica el servicio higiénico de mujeres.
A29: 04.04 | B29: SEÑAL DE SERVICIOS HIGIÉNICOS VARÓN CON BRAILLE | C29: 0.20 x 0.20 m | D29: Lámina de PVC celtex de 3 mm con vinil adhesivo impreso y placa de acrílico con texto en braille | E29: 1.80 m | F29: 1.80 | G29: Identifica el servicio higiénico de varones.
A30: 04.05 | B30: SEÑAL DE BOTIQUÍN DE PRIMEROS AUXILIOS CON BRAILLE | C30: 0.20 x 0.30 m | D30: Lámina de PVC celtex de 3 mm con vinil fotoluminiscente impreso y placa de acrílico con texto en braille | E30: 1.80 m | F30: 1.80 | G30: Identifica la ubicación del botiquín de primeros auxilios.
A31: 04.06 | B31: SEÑAL DE PUNTO ECOLÓGICO CON BRAILLE | C31: 0.30 x 0.20 m | D31: Lámina de PVC celtex de 3 mm con vinil adhesivo impreso y placa de acrílico con texto en braille | E31: 1.80 m | F31: — | G31: Identifica el punto de acopio selectivo de residuos sólidos.
A32: 05 | B32: EQUIPOS DE PROTECCIÓN CONTRA INCENDIO Y EMERGENCIA
A33: 05.01 | B33: EXTINTOR DE POLVO QUÍMICO SECO (PQS) TIPO ABC DE 6 kg | C33: extintor portátil de 6 kg, agente PQS multipropósito ABC | D33: Cilindro de acero con manómetro, manguera, soporte de pared y tarjeta de control | E33: 1.50 m (parte superior) | F33: — | G33: Combate fuegos de clase A, B y C en las edificaciones.
A34: 05.02 | B34: EXTINTOR DE DIÓXIDO DE CARBONO (CO2) DE 10 lb | C34: extintor portátil de 10 lb, agente CO2 | D34: Cilindro de acero sin costura con válvula, manguera con difusor, soporte de pared y tarjeta de control | E34: 1.50 m (parte superior) | F34: — | G34: Combate fuegos de clase B y C (equipos eléctricos de la cocina).
A35: 05.03 | B35: UNIDAD DE LUCES DE EMERGENCIA | C35: equipo de dos faros LED, autonomía mínima 90 min | D35: Equipo autónomo con batería recargable, 220 V | E35: 2.10 m | F35: 2.10 | G35: Ilumina las rutas de evacuación y las salidas al cortarse la energía.
A36: 05.04 | B36: DETECTOR DE HUMO | C36: detector fotoeléctrico de techo | D36: Equipo fotoeléctrico con base de montaje | E36: techo | F36: TECHO | G36: Detecta el humo en los ambientes y activa la alarma.
