Workbook

Sheet RESUMEN
A1: HOJA RESUMEN DE METRADOS - ARQUITECTURA: EQUIPAMIENTO Y MOBILIARIO
A2: PROYECTO | B2: “CREACIÓN DEL SERVICIO DE PROTECCIÓN INTEGRAL A NIÑAS, NIÑOS Y ADOLESCENTES SIN CUIDADOS PARENTALES O EN RIESGO DE PERDERLOS EN CENTRO DE ACOGIDA RESIDENCIAL - VARONES DISTRITO DE MORALES DE LA PROVINCIA DE SAN MARTÍN DEL DEPARTAMENTO DE SAN MARTÍN”
A3: CUI | B3: N.° 2705619
A4: PROPIETARIO | B4: Gobierno Regional San Martín - Gerencia Territorial Bajo Mayo
A5: UBICACIÓN | B5: Morales / San Martín / San Martín
A6: ESPECIALIDAD | B6: ARQUITECTURA - EQUIPAMIENTO Y MOBILIARIO
A7: LÁMINAS | B7: MB-01 a MB-09 (equipamiento y mobiliario, escala 1/150)
A8: FECHA | B8: SETIEMBRE 2026
A10: PART. N.° | B10: CÓD. | C10: DESCRIPCIÓN | D10: UND | E10: METRADO
A11: 03 | C11: ARQUITECTURA
A12: 03.01 | C12: MOBILIARIO Y EQUIPAMIENTO
A13: 03.01.01 | C13: EQUIPOS
A14: 03.01.01.01 | B14: E1 | C14: PROYECTOR INTERACTIVO | D14: und | E14: =SUMIF('METRADO POR AMBIENTE'!$I$11:$I$315,F14,'METRADO POR AMBIENTE'!$H$11:$H$315) | F14: E1
A15: 03.01.01.02 | B15: E2 | C15: COMPUTADORA PORTATIL I5 | D15: und | E15: =SUMIF('METRADO POR AMBIENTE'!$I$11:$I$315,F15,'METRADO POR AMBIENTE'!$H$11:$H$315) | F15: E2
A16: 03.01.01.03 | B16: E3 | C16: PRESENTADOR INALAMBRICO CON PUNTERO LASER | D16: und | E16: =SUMIF('METRADO POR AMBIENTE'!$I$11:$I$315,F16,'METRADO POR AMBIENTE'!$H$11:$H$315) | F16: E3
A17: 03.01.01.04 | B17: E4 | C17: RELOJ PARA ADOSAR A PARED | D17: und | E17: =SUMIF('METRADO POR AMBIENTE'!$I$11:$I$315,F17,'METRADO POR AMBIENTE'!$H$11:$H$315) | F17: E4
A18: 03.01.01.05 | B18: E5 | C18: LAVADORA DE 20KG DE CARGA SUPERIOR | D18: und | E18: =SUMIF('METRADO POR AMBIENTE'!$I$11:$I$315,F18,'METRADO POR AMBIENTE'!$H$11:$H$315) | F18: E5
A19: 03.01.01.06 | B19: E6 | C19: COMPUTADORA I5 ESTACIONARIA | D19: und | E19: =SUMIF('METRADO POR AMBIENTE'!$I$11:$I$315,F19,'METRADO POR AMBIENTE'!$H$11:$H$315) | F19: E6
A20: 03.01.01.07 | B20: E7 | C20: PROYECTOR MULTIMEDIA | D20: und | E20: =SUMIF('METRADO POR AMBIENTE'!$I$11:$I$315,F20,'METRADO POR AMBIENTE'!$H$11:$H$315) | F20: E7
A21: 03.01.01.08 | B21: E9 | C21: IMPRESORA MULTIFUNCIONAL | D21: und | E21: =SUMIF('METRADO POR AMBIENTE'!$I$11:$I$315,F21,'METRADO POR AMBIENTE'!$H$11:$H$315) | F21: E9
A22: 03.01.01.09 | B22: E13 | C22: COCINA INDUSTRIAL DE 2 HORNILLAS | D22: und | E22: =SUMIF('METRADO POR AMBIENTE'!$I$11:$I$315,F22,'METRADO POR AMBIENTE'!$H$11:$H$315) | F22: E13
A23: 03.01.01.10 | B23: E16 | C23: HORNO MICROONDAS DE 31 LITROS | D23: und | E23: =SUMIF('METRADO POR AMBIENTE'!$I$11:$I$315,F23,'METRADO POR AMBIENTE'!$H$11:$H$315) | F23: E16
A24: 03.01.01.11 | B24: E17 | C24: LICUADORA DE 1.5 LITROS | D24: und | E24: =SUMIF('METRADO POR AMBIENTE'!$I$11:$I$315,F24,'METRADO POR AMBIENTE'!$H$11:$H$315) | F24: E17
A25: 03.01.01.12 | B25: E18 | C25: ECRAN | D25: und | E25: =SUMIF('METRADO POR AMBIENTE'!$I$11:$I$315,F25,'METRADO POR AMBIENTE'!$H$11:$H$315) | F25: E18
... A27: 03.01.01.14 | B27: E20 | C27: BALON DE GAS | D27: und | E27: =SUMIF('METRADO POR AMBIENTE'!$I$11:$I$315,F27,'METRADO POR AMBIENTE'!$H$11:$H$315) | F27: E20
A28: 03.01.02 | C28: MOBILIARIO
A29: 03.01.02.01 | B29: M3 | C29: SILLA REGULABLE DE ESTUDIANTE DE MADERA Y METAL 0.30 X 0.27 X 0.32 M.(PRIMARIA) | D29: und | E29: =SUMIF('METRADO POR AMBIENTE'!$I$11:$I$315,F29,'METRADO POR AMBIENTE'!$H$11:$H$315) | F29: M3
A30: 03.01.02.02 | B30: M4 | C30: MESA REGULABLE DE MADERA Y METAL 0.56 X 0.50 X 0.60 M | D30: und | E30: =SUMIF('METRADO POR AMBIENTE'!$I$11:$I$315,F30,'METRADO POR AMBIENTE'!$H$11:$H$315) | F30: M4
A31: 03.01.02.03 | B31: M7 | C31: SILLA DEL PROFESOR DE MADERA Y METAL 0.45 X 0.40 X 0.36 M | D31: und | E31: =SUMIF('METRADO POR AMBIENTE'!$I$11:$I$315,F31,'METRADO POR AMBIENTE'!$H$11:$H$315) | F31: M7
A32: 03.01.02.04 | B32: M8 | C32: MESA PARA EL PROFESOR DE MADERA Y METAL 1.00 X 0.50 X 0.75 M | D32: und | E32: =SUMIF('METRADO POR AMBIENTE'!$I$11:$I$315,F32,'METRADO POR AMBIENTE'!$H$11:$H$315) | F32: M8
A33: 03.01.02.05 | B33: M13 | C33: RACK DE SOPORTE METALICO PARA PROYECTOR EN TECHO | D33: und | E33: =SUMIF('METRADO POR AMBIENTE'!$I$11:$I$315,F33,'METRADO POR AMBIENTE'!$H$11:$H$315) | F33: M13
A34: 03.01.02.06 | B34: M14 | C34: MACETERO 0.32 X 0.32 X 0.56 M | D34: und | E34: =SUMIF('METRADO POR AMBIENTE'!$I$11:$I$315,F34,'METRADO POR AMBIENTE'!$H$11:$H$315) | F34: M14
A35: 03.01.02.07 | B35: M15 | C35: ATRIL DE MESA PARA DIBUJO Y PINTURA | D35: und | E35: =SUMIF('METRADO POR AMBIENTE'!$I$11:$I$315,F35,'METRADO POR AMBIENTE'!$H$11:$H$315) | F35: M15
A36: 03.01.02.08 | B36: M16 | C36: MESA DE TRABAJO DE MADERA PARA ESTUDIANTES 0.90 X 1.80 X 0.56 M | D36: und | E36: =SUMIF('METRADO POR AMBIENTE'!$I$11:$I$315,F36,'METRADO POR AMBIENTE'!$H$11:$H$315) | F36: M16
A37: 03.01.02.09 | B37: M20 | C37: BIOMBO METALICO DE 3 CUERPOS | D37: und | E37: =SUMIF('METRADO POR AMBIENTE'!$I$11:$I$315,F37,'METRADO POR AMBIENTE'!$H$11:$H$315) | F37: M20
A38: 03.01.02.10 | B38: M21 | C38: MESA DE REUNIONES DE MADERA Y MELAMINA 2.40 X 1.00 X 0.75 M | D38: und | E38: =SUMIF('METRADO POR AMBIENTE'!$I$11:$I$315,F38,'METRADO POR AMBIENTE'!$H$11:$H$315) | F38: M21
A39: 03.01.02.11 | B39: M26 | C39: MESA DE TRABAJO DE ACERO INOXIDABLE 0.90 X 0.60 X 0.90 M | D39: und | E39: =SUMIF('METRADO POR AMBIENTE'!$I$11:$I$315,F39,'METRADO POR AMBIENTE'!$H$11:$H$315) | F39: M26
A40: 03.01.02.12 | B40: M27 | C40: SILLA DE RUEDAS | D40: und | E40: =SUMIF('METRADO POR AMBIENTE'!$I$11:$I$315,F40,'METRADO POR AMBIENTE'!$H$11:$H$315) | F40: M27
... A72: 03.01.02.44 | B72: M78 | C72: CAMA DE DOS PLAZAS (INCLUYE TARIMA) | D72: und | E72: =SUMIF('METRADO POR AMBIENTE'!$I$11:$I$315,F72,'METRADO POR AMBIENTE'!$H$11:$H$315) | F72: M78
A73: 03.01.03 | C73: IMPLEMENTOS
...

Sheet METRADO POR AMBIENTE
A1: METRADO DE EQUIPAMIENTO Y MOBILIARIO POR AMBIENTE (CUADROS DE LAS LÁMINAS MB-01 A MB-09)
A2: PROYECTO | B2: “CREACIÓN DEL SERVICIO DE PROTECCIÓN INTEGRAL A NIÑAS, NIÑOS Y ADOLESCENTES SIN CUIDADOS PARENTALES O EN RIESGO DE PERDERLOS EN CENTRO DE ACOGIDA RESIDENCIAL - VARONES DISTRITO DE MORALES DE LA PROVINCIA DE SAN MARTÍN DEL DEPARTAMENTO DE SAN MARTÍN”
A3: CUI | B3: N.° 2705619
A4: PROPIETARIO | B4: Gobierno Regional San Martín - Gerencia Territorial Bajo Mayo
A5: UBICACIÓN | B5: Morales / San Martín / San Martín
A6: ESPECIALIDAD | B6: ARQUITECTURA - EQUIPAMIENTO Y MOBILIARIO
A7: LÁMINAS | B7: MB-01 a MB-09 (equipamiento y mobiliario, escala 1/150)
A8: FECHA | B8: SETIEMBRE 2026
A10: EDIF. | B10: AMBIENTE | C10: LÁMINA | D10: CÓD. | E10: DESCRIPCIÓN | F10: UND | G10: CANT. CUADRO | H10: CANT. ADOPTADA | I10: CLAVE | J10: NOTA
A11: E-01 Administración - ASESORIA LEGAL
A12: E-01 | B12: ASESORIA LEGAL | C12: MB-01 | D12: E6 | E12: COMPUTADORA I5 ESTACIONARIA | F12: und | G12: 1 | H12: 1 | I12: E6
A13: E-01 | B13: ASESORIA LEGAL | C13: MB-01 | D13: E9 | E13: IMPRESORA MULTIFUNCIONAL | F13: und | G13: 1 | H13: 1 | I13: E9
A14: E-01 | B14: ASESORIA LEGAL | C14: MB-01 | D14: M7 | E14: SILLA DEL PROFESOR DE MADERA Y METAL 0.45 x 0.40 x 0.36 m. | F14: und | G14: 3 | H14: 3 | I14: M7
A15: E-01 | B15: ASESORIA LEGAL | C15: MB-01 | D15: M31 | E15: ESCRITORIO DE MELAMINA CON CREDENZA MOVIL 1.50 x 0.80 x 0.75 m. | F15: und | G15: 1 | H15: 1 | I15: M31
A16: E-01 | B16: ASESORIA LEGAL | C16: MB-01 | D16: M34 | E16: SOFA DE 2 CUERPOS 0.55X1.00X0.44M | F16: und | G16: 1 | H16: 1 | I16: M34
A17: E-01 | B17: ASESORIA LEGAL | C17: MB-01 | D17: M39 | E17: ARCHIVADOR DE MELAMINA CON TRES GAVETAS 0.60 X 0.46 X 1.20 M. | F17: und | G17: 1 | H17: 1 | I17: M39
A18: E-01 | B18: ASESORIA LEGAL | C18: MB-01 | D18: M62 | E18: CESTO BOTA PAPELES DE ACERO CON PEDAL | F18: und | G18: 1 | H18: 1 | I18: M62
A19: E-01 Administración - CONSULTORIO DE NUTRICION
A20: E-01 | B20: CONSULTORIO DE NUTRICION | C20: MB-01 | D20: E7 | E20: PROYECTOR MULTIMEDIA | F20: und | G20: 1 | H20: 1 | I20: E7
A21: E-01 | B21: CONSULTORIO DE NUTRICION | C21: MB-01 | D21: M7 | E21: SILLA DEL PROFESOR DE MADERA Y METAL 0.45 x 0.40 x 0.36 m. | F21: und | G21: 3 | H21: 3 | I21: M7
A22: E-01 | B22: CONSULTORIO DE NUTRICION | C22: MB-01 | D22: M28 | E22: ESCRITORIO DE MELAMINA CON DOS CAJONERAS 1.00 x 0.50 x 0.75 m | F22: und | G22: 1 | H22: 1 | I22: M28
A23: E-01 | B23: CONSULTORIO DE NUTRICION | C23: MB-01 | D23: M62 | E23: CESTO BOTA PAPELES DE ACERO CON PEDAL | F23: und | G23: 1 | H23: 1 | I23: M62
A24: E-01 | B24: CONSULTORIO DE NUTRICION | C24: MB-01 | D24: M65 | E24: CAMILLA METALICA RECLINABLE CON RESPALDO Y RUEDAS 1.80 X 0.60 X 0.70 M. | F24: und | G24: 1 | H24: 1 | I24: M65
A25: E-01 | B25: CONSULTORIO DE NUTRICION | C25: MB-01 | D25: M67 | E25: ESCALERA METÁLICA CON DOS PELDAÑOS 0.40 X 0.40 X 0.36 M. | F25: und | G25: 1 | H25: 1 | I25: M67
A26: E-01 Administración - DIRECCIÓN GENERAL
A27: E-01 | B27: DIRECCIÓN GENERAL | C27: MB-01 | D27: E6 | E27: COMPUTADORA I5 ESTACIONARIA | F27: und | G27: 1 | H27: 1 | I27: E6
A28: E-01 | B28: DIRECCIÓN GENERAL | C28: MB-01 | D28: E9 | E28: IMPRESORA MULTIFUNCIONAL | F28: und | G28: 1 | H28: 1 | I28: E9
A29: E-01 | B29: DIRECCIÓN GENERAL | C29: MB-01 | D29: M7 | E29: SILLA DEL PROFESOR DE MADERA Y METAL 0.45 x 0.40 x 0.36 m. | F29: und | G29: 3 | H29: 3 | I29: M7
A30: E-01 | B30: DIRECCIÓN GENERAL | C30: MB-01 | D30: M31 | E30: ESCRITORIO DE MELAMINA CON CREDENZA MOVIL 1.50 x 0.80 x 0.75 m. | F30: und | G30: 1 | H30: 1 | I30: M31
A31: E-01 | B31: DIRECCIÓN GENERAL | C31: MB-01 | D31: M34 | E31: SOFA DE 2 CUERPOS 0.55X1.00X0.44M | F31: und | G31: 1 | H31: 1 | I31: M34
A32: E-01 | B32: DIRECCIÓN GENERAL | C32: MB-01 | D32: M39 | E32: ARCHIVADOR DE MELAMINA CON TRES GAVETAS 0.60 X 0.46 X 1.20 M. | F32: und | G32: 1 | H32: 1 | I32: M39
A33: E-01 | B33: DIRECCIÓN GENERAL | C33: MB-01 | D33: M62 | E33: CESTO BOTA PAPELES DE ACERO CON PEDAL | F33: und | G33: 1 | H33: 1 | I33: M62
A34: E-01 Administración - EDUCADOR
A35: E-01 | B35: EDUCADOR | C35: MB-01 | D35: E6 | E35: COMPUTADORA I5 ESTACIONARIA | F35: und | G35: 1 | H35: 1 | I35: E6
A36: E-01 | B36: EDUCADOR | C36: MB-01 | D36: E9 | E36: IMPRESORA MULTIFUNCIONAL | F36: und | G36: 1 | H36: 1 | I36: E9
A37: E-01 | B37: EDUCADOR | C37: MB-01 | D37: M7 | E37: SILLA DEL PROFESOR DE MADERA Y METAL 0.45 x 0.40 x 0.36 m. | F37: und | G37: 3 | H37: 3 | I37: M7
A38: E-01 | B38: EDUCADOR | C38: MB-01 | D38: M31 | E38: ESCRITORIO DE MELAMINA CON CREDENZA MOVIL 1.50 x 0.80 x 0.75 m. | F38: und | G38: 1 | H38: 1 | I38: M31
A39: E-01 | B39: EDUCADOR | C39: MB-01 | D39: M36 | E39: ARMARIO PARA DOCENTE DE MELAMINA CON 2 PUERTAS 4 NIVELES 0.90 X 0.45 X 1.80 M. | F39: und | G39: 1 | H39: 1 | I39: M36
A40: E-01 | B40: EDUCADOR | C40: MB-01 | D40: M39 | E40: ARCHIVADOR DE MELAMINA CON TRES GAVETAS 0.60 X 0.46 X 1.20 M. | F40: und | G40: 1 | H40: 1 | I40: M39
A41: E-01 | B41: EDUCADOR | C41: MB-01 | D41: M62 | E41: CESTO BOTA PAPELES DE ACERO CON PEDAL | F41: und | G41: 1 | H41: 1 | I41: M62
...

Sheet VERIFICACIÓN
A1: VERIFICACIÓN DEL METRADO ORIGINAL CON EL PLANO (CUADROS DE EQUIPAMIENTO Y ETIQUETAS DE LA PLANTA)
A2: PROYECTO | B2: “CREACIÓN DEL SERVICIO DE PROTECCIÓN INTEGRAL A NIÑAS, NIÑOS Y ADOLESCENTES SIN CUIDADOS PARENTALES O EN RIESGO DE PERDERLOS EN CENTRO DE ACOGIDA RESIDENCIAL - VARONES DISTRITO DE MORALES DE LA PROVINCIA DE SAN MARTÍN DEL DEPARTAMENTO DE SAN MARTÍN”
A3: CUI | B3: N.° 2705619
A4: PROPIETARIO | B4: Gobierno Regional San Martín - Gerencia Territorial Bajo Mayo
A5: UBICACIÓN | B5: Morales / San Martín / San Martín
A6: ESPECIALIDAD | B6: ARQUITECTURA - EQUIPAMIENTO Y MOBILIARIO
A7: LÁMINAS | B7: MB-01 a MB-09 (equipamiento y mobiliario, escala 1/150)
A8: FECHA | B8: SETIEMBRE 2026
A10: CÓD. | B10: DESCRIPCIÓN | C10: METRADO ORIGINAL | D10: SUMA DE CUADROS | E10: ETIQUETAS EN PLANTA | F10: ADOPTADO | G10: DIFERENCIA (ADOPTADO - ORIGINAL) | H10: ESTADO | I10: OBSERVACIÓN
A11: E1 | B11: PROYECTOR INTERACTIVO | C11: 1 | D11: 1 | E11: 1 | F11: ='RESUMEN'!E14 | G11: =IF(ISNUMBER(C11),F11-C11,F11) | H11: =IF(G11=0,"conforme","corregir")
A12: E2 | B12: COMPUTADORA PORTATIL I5 | C12: 1 | D12: 1 | E12: 1 | F12: ='RESUMEN'!E15 | G12: =IF(ISNUMBER(C12),F12-C12,F12) | H12: =IF(G12=0,"conforme","corregir")
A13: E3 | B13: PRESENTADOR INALAMBRICO CON PUNTERO LASER | C13: 2 | D13: 2 | E13: 2 | F13: ='RESUMEN'!E16 | G13: =IF(ISNUMBER(C13),F13-C13,F13) | H13: =IF(G13=0,"conforme","corregir")
A14: E4 | B14: RELOJ PARA ADOSAR A PARED | C14: 1 | D14: 1 | E14: 1 | F14: ='RESUMEN'!E17 | G14: =IF(ISNUMBER(C14),F14-C14,F14) | H14: =IF(G14=0,"conforme","corregir")
A15: E5 | B15: LAVADORA DE 20KG DE CARGA SUPERIOR | C15: 10 | D15: 10 | E15: 10 | F15: ='RESUMEN'!E18 | G15: =IF(ISNUMBER(C15),F15-C15,F15) | H15: =IF(G15=0,"conforme","corregir")
A16: E6 | B16: COMPUTADORA I5 ESTACIONARIA | C16: 18 | D16: 43 | E16: 27 | F16: ='RESUMEN'!E19 | G16: =IF(ISNUMBER(C16),F16-C16,F16) | H16: =IF(G16=0,"conforme","corregir") | I16: El metrado original dice 18; el plano da 27. El cuadro repite las 5 computadoras del salón de estudios; en la planta hay 1 (escritorio de la madre). Ídem E-04.
A17: E7 | B17: PROYECTOR MULTIMEDIA | C17: 4 | D17: 4 | E17: 4 | F17: ='RESUMEN'!E20 | G17: =IF(ISNUMBER(C17),F17-C17,F17) | H17: =IF(G17=0,"conforme","corregir")
A18: E9 | B18: IMPRESORA MULTIFUNCIONAL | C18: 4 | D18: 4 | E18: 4 | F18: ='RESUMEN'!E21 | G18: =IF(ISNUMBER(C18),F18-C18,F18) | H18: =IF(G18=0,"conforme","corregir")
A19: E13 | B19: COCINA INDUSTRIAL DE 2 HORNILLAS | C19: 2 | D19: 2 | E19: 2 | F19: ='RESUMEN'!E22 | G19: =IF(ISNUMBER(C19),F19-C19,F19) | H19: =IF(G19=0,"conforme","corregir") | I19: Descripción del original: "Cocina de 2 hornillas".
A20: E16 | B20: HORNO MICROONDAS DE 31 LITROS | C20: 1 | D20: 1 | E20: 1 | F20: ='RESUMEN'!E23 | G20: =IF(ISNUMBER(C20),F20-C20,F20) | H20: =IF(G20=0,"conforme","corregir")
A21: E17 | B21: LICUADORA DE 1.5 LITROS | C21: 1 | D21: 1 | E21: 1 | F21: ='RESUMEN'!E24 | G21: =IF(ISNUMBER(C21),F21-C21,F21) | H21: =IF(G21=0,"conforme","corregir")
A22: E18 | B22: ECRAN | C22: 1 | D22: 1 | E22: 1 | F22: ='RESUMEN'!E25 | G22: =IF(ISNUMBER(C22),F22-C22,F22) | H22: =IF(G22=0,"conforme","corregir")
A23: E19 | B23: REFRIGERADORA 315 LITROS | C23: 1 | D23: 1 | E23: 1 | F23: ='RESUMEN'!E26 | G23: =IF(ISNUMBER(C23),F23-C23,F23) | H23: =IF(G23=0,"conforme","corregir")
A24: E20 | B24: BALON DE GAS | C24: 2 | D24: 2 | E24: 2 | F24: ='RESUMEN'!E27 | G24: =IF(ISNUMBER(C24),F24-C24,F24) | H24: =IF(G24=0,"conforme","corregir")
A25: M3 | B25: SILLA REGULABLE DE ESTUDIANTE DE MADERA Y METAL 0.30 X 0.27 X 0.32 M.(PRIMARIA) | C25: — | D25: 88 | E25: 88 | F25: ='RESUMEN'!E29 | G25: =IF(ISNUMBER(C25),F25-C25,F25) | H25: =IF(G25=0,"conforme","corregir") | I25: No figura en el metrado original.
A26: M4 | B26: MESA REGULABLE DE MADERA Y METAL 0.56 X 0.50 X 0.60 M | C26: — | D26: 16 | E26: 16 | F26: ='RESUMEN'!E30 | G26: =IF(ISNUMBER(C26),F26-C26,F26) | H26: =IF(G26=0,"conforme","corregir") | I26: No figura en el metrado original.
A27: M7 | B27: SILLA DEL PROFESOR DE MADERA Y METAL 0.45 X 0.40 X 0.36 M | C27: 52 | D27: 83 | E27: 80 | F27: ='RESUMEN'!E31 | G27: =IF(ISNUMBER(C27),F27-C27,F27) | H27: =IF(G27=0,"conforme","corregir") | I27: El metrado original dice 52; el plano da 80. El cuadro del tópico repite las 10 sillas de la sala de reuniones; se ajusta para que E-01 sume las 38 sillas M07 rotuladas en la planta, no 41. El proyector E7 del tópico sí está rotulado.
A28: M8 | B28: MESA PARA EL PROFESOR DE MADERA Y METAL 1.00 X 0.50 X 0.75 M | C28: 1 | D28: 1 | E28: 1 | F28: ='RESUMEN'!E32 | G28: =IF(ISNUMBER(C28),F28-C28,F28) | H28: =IF(G28=0,"conforme","corregir")
A29: M13 | B29: RACK DE SOPORTE METALICO PARA PROYECTOR EN TECHO | C29: 2 | D29: 2 | E29: 2 | F29: ='RESUMEN'!E33 | G29: =IF(ISNUMBER(C29),F29-C29,F29) | H29: =IF(G29=0,"conforme","corregir")
A30: M14 | B30: MACETERO 0.32 X 0.32 X 0.56 M | C30: — | D30: 2 | E30: 2 | F30: ='RESUMEN'!E34 | G30: =IF(ISNUMBER(C30),F30-C30,F30) | H30: =IF(G30=0,"conforme","corregir") | I30: No figura en el metrado original.
A31: M15 | B31: ATRIL DE MESA PARA DIBUJO Y PINTURA | C31: 1 | D31: 1 | E31: 1 | F31: ='RESUMEN'!E35 | G31: =IF(ISNUMBER(C31),F31-C31,F31) | H31: =IF(G31=0,"conforme","corregir")
A32: M16 | B32: MESA DE TRABAJO DE MADERA PARA ESTUDIANTES 0.90 X 1.80 X 0.56 M | C32: 12 | D32: 12 | E32: 12 | F32: ='RESUMEN'!E36 | G32: =IF(ISNUMBER(C32),F32-C32,F32) | H32: =IF(G32=0,"conforme","corregir")
A33: M20 | B33: BIOMBO METALICO DE 3 CUERPOS | C33: 1 | D33: 1 | E33: 1 | F33: ='RESUMEN'!E37 | G33: =IF(ISNUMBER(C33),F33-C33,F33) | H33: =IF(G33=0,"conforme","corregir")
A34: M21 | B34: MESA DE REUNIONES DE MADERA Y MELAMINA 2.40 X 1.00 X 0.75 M | C34: 1 | D34: 1 | E34: 1 | F34: ='RESUMEN'!E38 | G34: =IF(ISNUMBER(C34),F34-C34,F34) | H34: =IF(G34=0,"conforme","corregir")
A35: M26 | B35: MESA DE TRABAJO DE ACERO INOXIDABLE 0.90 X 0.60 X 0.90 M | C35: 3 | D35: 3 | E35: 3 | F35: ='RESUMEN'!E39 | G35: =IF(ISNUMBER(C35),F35-C35,F35) | H35: =IF(G35=0,"conforme","corregir")
A36: M27 | B36: SILLA DE RUEDAS | C36: 1 | D36: 1 | E36: 1 | F36: ='RESUMEN'!E40 | G36: =IF(ISNUMBER(C36),F36-C36,F36) | H36: =IF(G36=0,"conforme","corregir")
A37: M28 | B37: ESCRITORIO DE MELAMINA CON DOS CAJONERAS 1.00 X 0.50 X 0.75 M | C37: 4 | D37: 32 | E37: 32 | F37: ='RESUMEN'!E41 | G37: =IF(ISNUMBER(C37),F37-C37,F37) | H37: =IF(G37=0,"conforme","corregir") | I37: El metrado original dice 4; el plano da 32.
A38: M30 | B38: ESCRITORIO PARA COMPUTADORA DE MELAMINE 1.00 X 0.60 X 0.75 M | C38: 1 | D38: 1 | E38: 1 | F38: ='RESUMEN'!E42 | G38: =IF(ISNUMBER(C38),F38-C38,F38) | H38: =IF(G38=0,"conforme","corregir")
A39: M31 | B39: ESCRITORIO DE MELAMINA CON CREDENZA MOVIL 1.50 X 0.80 X 0.75 M | C39: 16 | D39: 16 | E39: 16 | F39: ='RESUMEN'!E43 | G39: =IF(ISNUMBER(C39),F39-C39,F39) | H39: =IF(G39=0,"conforme","corregir")
A40: M32 | B40: SILLON PARA ACOPLAR 0.44 X 0.55 X 0.60 M | C40: — | D40: 7 | E40: 7 | F40: ='RESUMEN'!E44 | G40: =IF(ISNUMBER(C40),F40-C40,F40) | H40: =IF(G40=0,"conforme","corregir") | I40: No figura en el metrado original.
A41: M34 | B41: SOFA DE 2 CUERPOS 0.55X1.00X0.44M | C41: 11 | D41: 7 | E41: 11 | F41: ='RESUMEN'!E45 | G41: =IF(ISNUMBER(C41),F41-C41,F41) | H41: =IF(G41=0,"conforme","corregir") | I41: En la planta hay 2 sofás de 2 cuerpos (M34) en la oficina de entrevista y estar; el cuadro dice 1. Ídem E-04.
...

Sheet VERIF. IMPLEMENTOS
A1: VERIFICACIÓN DE IMPLEMENTOS: METRADO ORIGINAL FRENTE A LOS CUADROS DEL PLANO
A2: PROYECTO | B2: “CREACIÓN DEL SERVICIO DE PROTECCIÓN INTEGRAL A NIÑAS, NIÑOS Y ADOLESCENTES SIN CUIDADOS PARENTALES O EN RIESGO DE PERDERLOS EN CENTRO DE ACOGIDA RESIDENCIAL - VARONES DISTRITO DE MORALES DE LA PROVINCIA DE SAN MARTÍN DEL DEPARTAMENTO DE SAN MARTÍN”
A3: CUI | B3: N.° 2705619
A4: PROPIETARIO | B4: Gobierno Regional San Martín - Gerencia Territorial Bajo Mayo
A5: UBICACIÓN | B5: Morales / San Martín / San Martín
A6: ESPECIALIDAD | B6: ARQUITECTURA - EQUIPAMIENTO Y MOBILIARIO
A7: LÁMINAS | B7: MB-01 a MB-09 (equipamiento y mobiliario, escala 1/150)
A8: FECHA | B8: SETIEMBRE 2026
A10: IMPLEMENTO | B10: METRADO ORIGINAL | C10: CUADROS DEL PLANO (ADOPTADO) | D10: ESTADO | E10: OBSERVACIÓN
A11: BIDÓN DE OXIGENO MEDICINAL | B11: 1 | C11: 1 | D11: conforme
A12: TENSIOMETRO | B12: 1 | C12: 1 | D12: conforme
A13: TERMOMETRO DIGITAL | B13: 1 | C13: 1 | D13: conforme
A14: ESTETOSCOPIO | B14: 1 | C14: 1 | D14: conforme
A15: PISO ENCASTRABLE DE GOMA DE 25MM | B15: 10 | C15: 50 | D15: corregir | E15: El metrado original dice 10; el cuadro del plano, 50.
A16: JUEGO DE COCINA | B16: 1 | C16: 1 | D16: conforme
A17: JUEGO DE LAVANDERIA | B17: 1 | C17: 1 | D17: conforme
A18: TOBOGAN CON ESCALADOR | B18: 1 | C18: 1 | D18: conforme
A19: PISCINA DE PELOTAS 150X33CM | B19: 1 | C19: 1 | D19: conforme
A20: JUEGO DE TEATRO PARA NIÑOS | B20: 1 | C20: 1 | D20: conforme
A21: COJINES CUADRADOS | B21: 4 | C21: 10 | D21: corregir | E21: El metrado original dice 4; el cuadro del plano, 10.
A22: PELOTAS DE BASQUETBOL #7 | B22: 24 | C22: 0 | D22: corregir | E22: No figura en los cuadros del plano.
A23: PELOTAS DE BASQUETBOL #5 | B23: 24 | C23: 0 | D23: corregir | E23: No figura en los cuadros del plano.
A24: TORRE DE BASQUETBOL Y ARCO DE FUTSAL, INCLUYE TABLERO Y REDES | B24: 8 | C24: 0 | D24: corregir | E24: No figura en los cuadros del plano.
A25: PELOTAS DE FUTSAL #5 | B25: 6 | C25: 0 | D25: corregir | E25: No figura en los cuadros del plano.
A26: PELOTAS DE FUTSAL #4 | B26: 6 | C26: 0 | D26: corregir | E26: No figura en los cuadros del plano.
A27: CONOS DE ENTRENAMIENTO | B27: 20 | C27: 0 | D27: corregir | E27: No figura en los cuadros del plano.
A28: PELOTAS DE VÓLEY #5 | B28: 6 | C28: 0 | D28: corregir | E28: No figura en los cuadros del plano.
A29: KIT DE VÓLEY INCL/ NET Y PARANTES TELESCÓPICOS | B29: 1 | C29: 1 | D29: conforme
A30: TABURETE DE MADERA PARA GIMNASIA | B30: 2 | C30: 4 | D30: corregir | E30: El metrado original dice 2; el cuadro del plano, 4.
A31: BARRA DE EQUILIBRIO | B31: 2 | C31: 0 | D31: corregir | E31: No figura en los cuadros del plano.
A32: ULA ULA | B32: 15 | C32: 0 | D32: corregir | E32: No figura en los cuadros del plano.
A33: PELOTA DE REBOTE | B33: 5 | C33: 0 | D33: corregir | E33: No figura en los cuadros del plano.
A34: CINTA MÉTRICA | B34: 2 | C34: 0 | D34: corregir | E34: No figura en los cuadros del plano.
A35: BALANZA ELECTRÓNICA | B35: 1 | C35: 0 | D35: corregir | E35: No figura en los cuadros del plano.
A36: INFLADOR DE PIE PARA PELOTAS | B36: 2 | C36: 2 | D36: conforme
A37: COLCHONETAS SIMPLES FORRADO CON CUERO 1.50X0.50 | B37: 30 | C37: 30 | D37: conforme
A38: FLEXABAND | B38: 10 | C38: 0 | D38: corregir | E38: No figura en los cuadros del plano.
A39: TESTIMONIO DE RELEVO DE PVC | B39: 15 | C39: 5 | D39: corregir | E39: El metrado original dice 15; el cuadro del plano, 5.
A40: CRONÓMETRO DIGITAL A PILAS | B40: 1 | C40: 0 | D40: corregir | E40: No figura en los cuadros del plano.
A41: JUEGO DE AJEDREZ | B41: 6 | C41: 0 | D41: corregir | E41: No figura en los cuadros del plano.
...

Sheet OBSERVACIONES
A1: OBSERVACIONES AL PLANO Y AL METRADO ORIGINAL
A2: PROYECTO | B2: “CREACIÓN DEL SERVICIO DE PROTECCIÓN INTEGRAL A NIÑAS, NIÑOS Y ADOLESCENTES SIN CUIDADOS PARENTALES O EN RIESGO DE PERDERLOS EN CENTRO DE ACOGIDA RESIDENCIAL - VARONES DISTRITO DE MORALES DE LA PROVINCIA DE SAN MARTÍN DEL DEPARTAMENTO DE SAN MARTÍN”
A3: CUI | B3: N.° 2705619
A4: PROPIETARIO | B4: Gobierno Regional San Martín - Gerencia Territorial Bajo Mayo
A5: UBICACIÓN | B5: Morales / San Martín / San Martín
A6: ESPECIALIDAD | B6: ARQUITECTURA - EQUIPAMIENTO Y MOBILIARIO
A7: LÁMINAS | B7: MB-01 a MB-09 (equipamiento y mobiliario, escala 1/150)
A8: FECHA | B8: SETIEMBRE 2026
A10: N.° | B10: DOCUMENTO | C10: OBSERVACIÓN
A11: 1 | B11: Lámina MB-02 | C11: El cuadro del almacén de implementos deportivos de E-02 está titulado "TÓPICO - EDIFICACIÓN 2".
A12: 2 | B12: Lámina MB-08 | C12: El cuadro del almacén de cocina y cuarto de gas (balones de gas y parihuelas) está titulado "OFICINA DE ENTREVISTA Y ESTAR - EDIFICACIÓN 6".
A13: 3 | B13: Lámina MB-01 | C13: El cuadro del tópico repite las 10 sillas de la sala de reuniones; la planta de E-01 rotula 38 sillas M07 en total, no 41.
A14: 4 | B14: Lámina MB-04 a MB-07 | C14: El cuadro del dormitorio de la madre repite las 5 computadoras del salón de estudios (en planta hay 1).
A15: 5 | B15: Lámina MB-04 a MB-07 | C15: El cuadro de la oficina de entrevista y estar pone 1 sofá de 2 cuerpos (M34); en planta hay 2.
A16: 6 | B16: Lámina MB-04 a MB-07 | C16: Los cuadros de dormitorio describen el código M55 como "mueble alto de melamina"; M55 es la cama con cabecera (dibujada).
A17: 7 | B17: Lámina MB-04, MB-05 | C17: El salón de estudios describe el código M28 como "escritorio con credenza móvil 1.50 x 0.80"; M28 es el escritorio con dos cajoneras 1.00 x 0.50 (dibujado).
A18: 8 | B18: Lámina MB-07 | C18: En el dormitorio de E-07 la planta rotula 10 credenzas M44 (una junto a cada cama) y el cuadro pone 10 armarios M37; se cuenta lo rotulado. Corregir el cuadro.
A19: 9 | B19: Lámina MB-07 | C19: El cuadro del taller de arte pone 1 mueble para mochilas (M56); en planta hay 5.
A20: 10 | B20: Lámina MB-06 | C20: En el salón de psicomotricidad de E-06 hay 10 cojines cuadrados (K78) dibujados y solo 7 rotulados; se metran los 10 del cuadro.
A21: 11 | B21: Lámina MB-02 | C21: El cuadro del almacén deportivo describe M51 como "exhibidor de libros"; M51 es el estante metálico ranurado.
A22: 12 | B22: Lámina MB-01, MB-06 | C22: Los códigos de implementos K32 y K33 se usan para dos cosas distintas (tópico: bidón de oxígeno y tensiómetro; psicomotricidad: piscina de pelotas y juego de teatro) y K78 para cojines cuadrados y piso encastrable.
... A31: 21 | B31: Metrado original | C31: Los implementos de la caseta de vigilancia (linterna, megáfono, chaleco) no tienen cuadro en el plano; si se requieren, deben agregarse al plano.
