Workbook

Sheet INDICE
A1: PLAN DE SEGURIDAD Y SALUD EN EL TRABAJO - MATRIZ IPERC Y PROGRAMAS
A2: MEJORAMIENTO DEL SERVICIO DE TRANSITABILIDAD VIAL INTERURBANA EN LA VÍA DEPARTAMENTAL SM-107, TRAMO TINGO DE PONASA - SHAMBOYACU, DISTRITO DE SHAMBOYACU, PROVINCIA DE PICOTA, DEPARTAMENTO DE SAN MARTÍN - CUI N.° 2673852
A4: N.° | B4: HOJA | C4: CONTENIDO
A5: 1 | B5: DATOS | C5: Datos generales de la obra
A6: 2 | B6: CRITERIOS | C6: Criterios de evaluación de la R.M. N.° 050-2013-TR
A7: 3 | B7: IPERC | C7: Matriz de identificación de peligros, evaluación de riesgos y medidas de control (con fórmulas)
A8: 4 | B8: RESUMEN | C8: Resumen de niveles de riesgo por proceso (fórmulas sobre el IPERC)
A9: 5 | B9: MAPA DE CALOR | C9: Probabilidad x severidad antes y después de los controles
A10: 6 | B10: EPP | C10: Matriz de equipos de protección personal por puesto
A11: 7 | B11: PETS-PETAR | C11: Procedimientos escritos de trabajo seguro y permisos de trabajo de alto riesgo
A12: 8 | B12: CAPACITACION | C12: Programa de capacitación y sensibilización
A13: 9 | B13: INSPECCIONES | C13: Programa de inspecciones
A14: 10 | B14: MONITOREO | C14: Monitoreo de agentes ocupacionales
A15: 11 | B15: INDICADORES | C15: Objetivos, metas e indicadores de SST (fórmulas)
A16: 12 | B16: PARTIDAS | C16: Relación de partidas del presupuesto y actividades evaluadas
A17: 13 | B17: EMERGENCIA | C17: Directorio de emergencia
B19: Leyenda: | C19: Celda amarilla = dato que se puede cambiar; celda verde = fórmula

Sheet DATOS
A1: DATOS GENERALES DE LA OBRA
A2: MEJORAMIENTO DEL SERVICIO DE TRANSITABILIDAD VIAL INTERURBANA EN LA VÍA DEPARTAMENTAL SM-107, TRAMO TINGO DE PONASA - SHAMBOYACU, DISTRITO DE SHAMBOYACU, PROVINCIA DE PICOTA, DEPARTAMENTO DE SAN MARTÍN - CUI N.° 2673852
A4: CONCEPTO | B4: VALOR
A5: Proyecto | B5: MEJORAMIENTO DEL SERVICIO DE TRANSITABILIDAD VIAL INTERURBANA EN LA VÍA DEPARTAMENTAL SM-107, TRAMO TINGO DE PONASA - SHAMBOYACU, DISTRITO DE SHAMBOYACU, PROVINCIA DE PICOTA, DEPARTAMENTO DE SAN MARTÍN
A6: CUI | B6: 2673852
A7: Entidad | B7: Gobierno Regional San Martín
A8: Unidad ejecutora | B8: Dirección Regional de Transportes y Comunicaciones San Martín
A9: Ubicación | B9: Distrito de Shamboyacu, provincia de Picota, departamento de San Martín
A10: Tipo de obra | B10: vial
A11: Descripción | B11: Mejoramiento de 25.35 km de la vía departamental SM-107 entre Tingo de Ponasa (km 19+343.39) y Shamboyacu (km 44+693.39): movimiento de tierras, pavimento de concreto asfáltico en caliente, alcantarillas, cunetas, muros de contención y de gaviones, señalización, reemplazo de cinco puentes (Tingo de Ponasa, Barco, Paucarillo, Apangurayco y Chanchamayco) y plan de manejo ambiental.
A12: Plazo de ejecución (días calendario) | B12: 720
A13: Modalidad | B13: Por contrata
A14: Altitud (msnm) | B14: 250 a 330
A15: Clima | B15: Cálido y húmedo de selva alta, con lluvias de octubre a abril
A16: Jornada de trabajo | B16: Lunes a sábado de 07:00 a 17:00 (48 horas semanales)
A17: Personal máximo previsto | B17: 160
A18: Horas hombre previstas | B18: 594880
A19: Órgano de SST | B19: Comité de SST (20 o más trabajadores)
A20: Actividades evaluadas | B20: 28
A21: Peligros evaluados | B21: 109

Sheet CRITERIOS
A1: CRITERIOS DE EVALUACIÓN DE RIESGOS (R.M. N.° 050-2013-TR)
A2: Probabilidad = A + B + C + D; nivel de riesgo = probabilidad x severidad
A4: ÍNDICE | B4: A. PERSONAS EXPUESTAS | C4: B. PROCEDIMIENTOS EXISTENTES | D4: C. CAPACITACIÓN | E4: D. EXPOSICIÓN AL RIESGO | F4: SEVERIDAD
A5: 1 | B5: 1 a 3 | C5: Existen, son satisfactorios y suficientes | D5: Personal entrenado; conoce el peligro y lo previene | E5: Al menos una vez al año (S) / esporádicamente (SO) | F5: Lesión sin incapacidad (S) / disconfort o incomodidad (SO)
A6: 2 | B6: 4 a 12 | C6: Existen parcialmente y no son satisfactorios o suficientes | D6: Personal parcialmente entrenado; conoce el peligro pero no toma acciones de control | E6: Al menos una vez al mes (S) / eventualmente (SO) | F6: Lesión con incapacidad temporal (S) / daño a la salud reversible (SO)
A7: 3 | B7: Más de 12 | C7: No existen | D7: Personal no entrenado; no conoce el peligro ni toma acciones de control | E7: Al menos una vez al día (S) / permanentemente (SO) | F7: Lesión con incapacidad permanente (S) / daño a la salud irreversible (SO)
A9: NIVEL | C9: RANGO (P x S) | D9: INTERPRETACIÓN
A10: Trivial | C10: 4 | D10: No se necesita adoptar ninguna acción.
A11: Tolerable | C11: 5 a 8 | D11: No se necesita mejorar la acción preventiva; se consideran soluciones más rentables o mejoras sin carga económica importante y se hacen comprobaciones periódicas para asegurar que se mantiene la eficacia de los controles.
A12: Moderado | C12: 9 a 16 | D12: Se deben hacer esfuerzos para reducir el riesgo, con medidas implementadas en un periodo determinado. Cuando está asociado a consecuencias extremadamente dañinas, se precisa una acción posterior para establecer con más precisión la probabilidad de daño.
A13: Importante | C13: 17 a 24 | D13: No debe comenzarse el trabajo hasta que se haya reducido el riesgo. Puede que se precisen recursos considerables. Cuando el riesgo corresponde a un trabajo que se está realizando, debe remediarse el problema en un tiempo inferior al de los riesgos moderados.
A14: Intolerable | C14: 25 a 36 | D14: No se debe comenzar ni continuar el trabajo hasta que se reduzca el riesgo. Si no es posible reducirlo, incluso con recursos ilimitados, debe prohibirse el trabajo.
A16: Riesgo significativo: nivel Importante o Intolerable. Evaluación inicial con B = 2 y C = 2 (procedimientos y capacitación parciales); evaluación residual con B = 1 y C = 1 (PETS, ATS, capacitación y supervisión implementados).

Sheet IPERC
A1: MATRIZ DE IDENTIFICACIÓN DE PELIGROS, EVALUACIÓN DE RIESGOS Y MEDIDAS DE CONTROL (IPERC LÍNEA BASE)
A2: MEJORAMIENTO DEL SERVICIO DE TRANSITABILIDAD VIAL INTERURBANA EN LA VÍA DEPARTAMENTAL SM-107, TRAMO TINGO DE PONASA - SHAMBOYACU, DISTRITO DE SHAMBOYACU, PROVINCIA DE PICOTA, DEPARTAMENTO DE SAN MARTÍN - CUI N.° 2673852
A4: IDENTIFICACIÓN | J4: EVALUACIÓN INICIAL | S4: MEDIDAS DE CONTROL (JERARQUÍA) | X4: EVALUACIÓN RESIDUAL | AG4: PROCEDIMIENTOS
A5: N.° | B5: PROCESO | C5: ACTIVIDAD | D5: PUESTOS | E5: R / NR | F5: PELIGRO | G5: RIESGO | H5: CONSECUENCIA | I5: S / SO | J5: A PERSONAS | K5: B PROCED. | L5: C CAPACIT. | M5: D EXPOSIC. | N5: PROBAB. A+B+C+D | O5: SEVERI- DAD | P5: P x S | Q5: NIVEL | R5: SIGNIFI- CATIVO | S5: ELIMINACIÓN | T5: SUSTITUCIÓN | U5: CONTROLES DE INGENIERÍA | V5: CONTROLES ADMINISTRATIVOS | W5: EPP | X5: A | Y5: B | Z5: C | AA5: D | AB5: PROBAB. | AC5: SEVERI- DAD | AD5: P x S | AE5: NIVEL | AF5: SIGNIFI- CATIVO | AG5: PETS | AH5: PETAR
A6: 1 | B6: Actividades generales | C6: Trabajos generales a campo abierto | D6: Todo el personal | E6: R | F6: Radiación solar y temperatura ambiente elevada | G6: Exposición prolongada a radiación UV y a calor | H6: Golpe de calor, deshidratación, quemaduras de piel | I6: SO | J6: 3 | K6: 2 | L6: 2 | M6: 3 | N6: =SUM(J6:M6) | O6: 2 | P6: =N6*O6 | Q6: =IF(P6<=4,"Trivial",IF(P6<=8,"Tolerable",IF(P6<=16,"Moderado",IF(P6<=24,"Importante","Intolerable")))) | R6: =IF(OR(Q6="Importante",Q6="Intolerable"),"Sí","No") | S6: No aplica | T6: No aplica | U6: Toldos o sombras en las zonas de descanso; puntos de hidratación con agua potable en cada frente | V6: Pausas de hidratación; rotación del personal en las horas de mayor radiación (11:00 a 15:00); charla de estrés térmico | W6: Bloqueador solar FPS 50+ y cortasol para casco | X6: 3 | Y6: 1 | Z6: 1 | AA6: 3 | AB6: =SUM(X6:AA6) | AC6: 1 | AD6: =AB6*AC6 | AE6: =IF(AD6<=4,"Trivial",IF(AD6<=8,"Tolerable",IF(AD6<=16,"Moderado",IF(AD6<=24,"Importante","Intolerable")))) | AF6: =IF(OR(AE6="Importante",AE6="Intolerable"),"Sí","No") | AG6: Reglamento interno de SST y charla diaria de 5 minutos | AH6: —
A7: 2 | B7: Actividades generales | C7: Trabajos generales a campo abierto | D7: Todo el personal | E7: R | F7: Lluvia intensa y tormenta eléctrica | G7: Resbalones y caídas; descarga eléctrica atmosférica | H7: Contusiones, fracturas, electrocución | I7: S | J7: 3 | K7: 2 | L7: 2 | M7: 2 | N7: =SUM(J7:M7) | O7: 3 | P7: =N7*O7 | Q7: =IF(P7<=4,"Trivial",IF(P7<=8,"Tolerable",IF(P7<=16,"Moderado",IF(P7<=24,"Importante","Intolerable")))) | R7: =IF(OR(Q7="Importante",Q7="Intolerable"),"Sí","No") | S7: No aplica | T7: No aplica | U7: Refugios temporales y vehículos cerrados en el frente | V7: Suspensión de trabajos a campo abierto con tormenta eléctrica (regla 30-30); monitoreo del pronóstico del SENAMHI; orden y limpieza de accesos | W7: Ropa impermeable (poncho o traje de agua) | X7: 3 | Y7: 1 | Z7: 1 | AA7: 1 | AB7: =SUM(X7:AA7) | AC7: 2 | AD7: =AB7*AC7 | AE7: =IF(AD7<=4,"Trivial",IF(AD7<=8,"Tolerable",IF(AD7<=16,"Moderado",IF(AD7<=24,"Importante","Intolerable")))) | AF7: =IF(OR(AE7="Importante",AE7="Intolerable"),"Sí","No") | AG7: Reglamento interno de SST y charla diaria de 5 minutos | AH7: —
A8: 3 | B8: Actividades generales | C8: Trabajos generales a campo abierto | D8: Todo el personal | E8: R | F8: Sismo | G8: Caída de objetos, colapso de estructuras provisionales o derrumbes | H8: Contusiones, aplastamiento, muerte | I8: S | J8: 3 | K8: 2 | L8: 2 | M8: 1 | N8: =SUM(J8:M8) | O8: 3 | P8: =N8*O8 | Q8: =IF(P8<=4,"Trivial",IF(P8<=8,"Tolerable",IF(P8<=16,"Moderado",IF(P8<=24,"Importante","Intolerable")))) | R8: =IF(OR(Q8="Importante",Q8="Intolerable"),"Sí","No") | S8: No aplica | T8: No aplica | U8: Estructuras provisionales arriostradas; almacenamiento estable de materiales | V8: Plan de respuesta ante emergencias; zonas seguras señalizadas; simulacros | W8: EPP básico | X8: 3 | Y8: 1 | Z8: 1 | AA8: 1 | AB8: =SUM(X8:AA8) | AC8: 2 | AD8: =AB8*AC8 | AE8: =IF(AD8<=4,"Trivial",IF(AD8<=8,"Tolerable",IF(AD8<=16,"Moderado",IF(AD8<=24,"Importante","Intolerable")))) | AF8: =IF(OR(AE8="Importante",AE8="Intolerable"),"Sí","No") | AG8: Reglamento interno de SST y charla diaria de 5 minutos | AH8: —
A9: 4 | B9: Actividades generales | C9: Trabajos generales a campo abierto | D9: Todo el personal | E9: R | F9: Carga de trabajo, jornadas extensas y trabajo lejos del hogar | G9: Fatiga y estrés laboral | H9: Trastornos psicosociales, errores y accidentes | I9: SO | J9: 3 | K9: 2 | L9: 2 | M9: 3 | N9: =SUM(J9:M9) | O9: 2 | P9: =N9*O9 | Q9: =IF(P9<=4,"Trivial",IF(P9<=8,"Tolerable",IF(P9<=16,"Moderado",IF(P9<=24,"Importante","Intolerable")))) | R9: =IF(OR(Q9="Importante",Q9="Intolerable"),"Sí","No") | S9: No aplica | T9: No aplica | U9: Campamento con condiciones adecuadas de descanso y alimentación | V9: Control de jornada y horas extras; programa de bienestar; canal de atención de quejas y hostigamiento | W9: No aplica | X9: 3 | Y9: 1 | Z9: 1 | AA9: 3 | AB9: =SUM(X9:AA9) | AC9: 1 | AD9: =AB9*AC9 | AE9: =IF(AD9<=4,"Trivial",IF(AD9<=8,"Tolerable",IF(AD9<=16,"Moderado",IF(AD9<=24,"Importante","Intolerable")))) | AF9: =IF(OR(AE9="Importante",AE9="Intolerable"),"Sí","No") | AG9: Reglamento interno de SST y charla diaria de 5 minutos | AH9: —
A10: 5 | B10: Actividades generales | C10: Trabajos en zona de selva (fauna y vectores) | D10: Todo el personal | E10: R | F10: Ofidios, arácnidos e insectos ponzoñosos | G10: Mordedura o picadura durante el trabajo en vegetación | H10: Envenenamiento, reacción alérgica, muerte | I10: S | J10: 3 | K10: 2 | L10: 2 | M10: 2 | N10: =SUM(J10:M10) | O10: 3 | P10: =N10*O10 | Q10: =IF(P10<=4,"Trivial",IF(P10<=8,"Tolerable",IF(P10<=16,"Moderado",IF(P10<=24,"Importante","Intolerable")))) | R10: =IF(OR(Q10="Importante",Q10="Intolerable"),"Sí","No") | S10: No aplica | T10: No aplica | U10: Desbroce y limpieza previa de las áreas de trabajo y de tránsito | V10: Inspección visual antes de iniciar; coordinación con el establecimiento de salud sobre suero antiofídico; plan de evacuación inmediata | W10: Polainas de protección contra mordeduras y botas de caña alta | X10: 3 | Y10: 1 | Z10: 1 | AA10: 2 | AB10: =SUM(X10:AA10) | AC10: 2 | AD10: =AB10*AC10 | AE10: =IF(AD10<=4,"Trivial",IF(AD10<=8,"Tolerable",IF(AD10<=16,"Moderado",IF(AD10<=24,"Importante","Intolerable")))) | AF10: =IF(OR(AE10="Importante",AE10="Intolerable"),"Sí","No") | AG10: PETS - Prevención de mordeduras de ofidios y enfermedades metaxénicas | AH10: —
A11: 6 | B11: Actividades generales | C11: Trabajos en zona de selva (fauna y vectores) | D11: Todo el personal | E11: R | F11: Mosquitos vectores (dengue, malaria, zika) | G11: Picadura de mosquitos infectados | H11: Enfermedad metaxénica | I11: SO | J11: 3 | K11: 2 | L11: 2 | M11: 3 | N11: =SUM(J11:M11) | O11: 2 | P11: =N11*O11 | Q11: =IF(P11<=4,"Trivial",IF(P11<=8,"Tolerable",IF(P11<=16,"Moderado",IF(P11<=24,"Importante","Intolerable")))) | R11: =IF(OR(Q11="Importante",Q11="Intolerable"),"Sí","No") | S11: No aplica | T11: No aplica | U11: Mallas mosquiteras en campamento; eliminación de recipientes con agua estancada | V11: Campaña de prevención con el establecimiento de salud; vigilancia de casos febriles | W11: Repelente de insectos y ropa de manga larga | X11: 3 | Y11: 1 | Z11: 1 | AA11: 3 | AB11: =SUM(X11:AA11) | AC11: 2 | AD11: =AB11*AC11 | AE11: =IF(AD11<=4,"Trivial",IF(AD11<=8,"Tolerable",IF(AD11<=16,"Moderado",IF(AD11<=24,"Importante","Intolerable")))) | AF11: =IF(OR(AE11="Importante",AE11="Intolerable"),"Sí","No") | AG11: PETS - Prevención de mordeduras de ofidios y enfermedades metaxénicas | AH11: —
A12: 7 | B12: Actividades generales | C12: Traslado de personal y materiales en vehículos | D12: Chofer, Todo el personal | E12: R | F12: Vehículos de transporte de personal en vías afirmadas y con pendiente | G12: Choque, despiste o volcadura | H12: Politraumatismo, muerte | I12: S | J12: 3 | K12: 2 | L12: 2 | M12: 3 | N12: =SUM(J12:M12) | O12: 3 | P12: =N12*O12 | Q12: =IF(P12<=4,"Trivial",IF(P12<=8,"Tolerable",IF(P12<=16,"Moderado",IF(P12<=24,"Importante","Intolerable")))) | R12: =IF(OR(Q12="Importante",Q12="Intolerable"),"Sí","No") | S12: No aplica | T12: No aplica | U12: Vehículos con cinturones, barras antivuelco en camionetas, GPS con control de velocidad; mantenimiento preventivo | V12: Conductores con licencia y capacitación en manejo defensivo; límite de velocidad; prohibido trasladar personal en tolvas; check-list diario | W12: Cinturón de seguridad | X12: 3 | Y12: 1 | Z12: 1 | AA12: 3 | AB12: =SUM(X12:AA12) | AC12: 2 | AD12: =AB12*AC12 | AE12: =IF(AD12<=4,"Trivial",IF(AD12<=8,"Tolerable",IF(AD12<=16,"Moderado",IF(AD12<=24,"Importante","Intolerable")))) | AF12: =IF(OR(AE12="Importante",AE12="Intolerable"),"Sí","No") | AG12: PETS - Transporte de personal y manejo defensivo | AH12: —
A13: 8 | B13: Actividades generales | C13: Traslado de personal y materiales en vehículos | D13: Chofer, Todo el personal | E13: R | F13: Conducción prolongada | G13: Fatiga y somnolencia del conductor | H13: Accidente de tránsito | I13: S | J13: 3 | K13: 2 | L13: 2 | M13: 2 | N13: =SUM(J13:M13) | O13: 3 | P13: =N13*O13 | Q13: =IF(P13<=4,"Trivial",IF(P13<=8,"Tolerable",IF(P13<=16,"Moderado",IF(P13<=24,"Importante","Intolerable")))) | R13: =IF(OR(Q13="Importante",Q13="Intolerable"),"Sí","No") | S13: No aplica | T13: No aplica | U13: No aplica | V13: Control de horas de manejo y descanso; prueba de alcoholemia aleatoria | W13: No aplica | X13: 3 | Y13: 1 | Z13: 1 | AA13: 2 | AB13: =SUM(X13:AA13) | AC13: 2 | AD13: =AB13*AC13 | AE13: =IF(AD13<=4,"Trivial",IF(AD13<=8,"Tolerable",IF(AD13<=16,"Moderado",IF(AD13<=24,"Importante","Intolerable")))) | AF13: =IF(OR(AE13="Importante",AE13="Intolerable"),"Sí","No") | AG13: PETS - Transporte de personal y manejo defensivo | AH13: —
A14: 9 | B14: Obras provisionales | C14: Campamento, almacenes, comedor, servicios higiénicos y cartel de obra | D14: Operario, Oficial, Peón, Almacenero | E14: R | F14: Manipulación manual de cargas | G14: Sobreesfuerzo por levantar o trasladar cargas pesadas o en mala postura | H14: Lumbalgia, hernias, lesiones musculoesqueléticas | I14: SO | J14: 2 | K14: 2 | L14: 2 | M14: 3 | N14: =SUM(J14:M14) | O14: 2 | P14: =N14*O14 | Q14: =IF(P14<=4,"Trivial",IF(P14<=8,"Tolerable",IF(P14<=16,"Moderado",IF(P14<=24,"Importante","Intolerable")))) | R14: =IF(OR(Q14="Importante",Q14="Intolerable"),"Sí","No") | S14: No aplica | T14: Uso de carretillas, montacargas o equipo para cargas mayores de 25 kg | U14: Puntos de acopio cerca del frente de trabajo | V14: Capacitación en levantamiento seguro (R.M. N.° 375-2008-TR); trabajo en pareja; pausas activas | W14: EPP básico; faja lumbar solo con indicación médica | X14: 2 | Y14: 1 | Z14: 1 | AA14: 3 | AB14: =SUM(X14:AA14) | AC14: 1 | AD14: =AB14*AC14 | AE14: =IF(AD14<=4,"Trivial",IF(AD14<=8,"Tolerable",IF(AD14<=16,"Moderado",IF(AD14<=24,"Importante","Intolerable")))) | AF14: =IF(OR(AE14="Importante",AE14="Intolerable"),"Sí","No") | AG14: PETS - Instalación de campamento y almacenamiento de materiales | AH14: —
A15: 10 | B15: Obras provisionales | C15: Campamento, almacenes, comedor, servicios higiénicos y cartel de obra | D15: Operario, Oficial, Peón, Almacenero | E15: R | F15: Herramientas manuales | G15: Golpes, cortes o atrapamiento al usar herramientas | H15: Contusiones, cortes, fracturas de dedos | I15: S | J15: 2 | K15: 2 | L15: 2 | M15: 3 | N15: =SUM(J15:M15) | O15: 2 | P15: =N15*O15 | Q15: =IF(P15<=4,"Trivial",IF(P15<=8,"Tolerable",IF(P15<=16,"Moderado",IF(P15<=24,"Importante","Intolerable")))) | R15: =IF(OR(Q15="Importante",Q15="Intolerable"),"Sí","No") | S15: No aplica | T15: No aplica | U15: Herramientas con mangos y guardas en buen estado | V15: Inspección de herramientas con cinta de color del mes; retiro de las defectuosas; ATS diario | W15: Guantes de cuero o badana, lentes de seguridad | X15: 2 | Y15: 1 | Z15: 1 | AA15: 3 | AB15: =SUM(X15:AA15) | AC15: 1 | AD15: =AB15*AC15 | AE15: =IF(AD15<=4,"Trivial",IF(AD15<=8,"Tolerable",IF(AD15<=16,"Moderado",IF(AD15<=24,"Importante","Intolerable")))) | AF15: =IF(OR(AE15="Importante",AE15="Intolerable"),"Sí","No") | AG15: PETS - Instalación de campamento y almacenamiento de materiales | AH15: —
A16: 11 | B16: Obras provisionales | C16: Campamento, almacenes, comedor, servicios higiénicos y cartel de obra | D16: Operario, Oficial, Peón, Almacenero | E16: R | F16: Combustibles y materiales inflamables | G16: Incendio o explosión | H16: Quemaduras, muerte, daño a instalaciones | I16: S | J16: 2 | K16: 2 | L16: 2 | M16: 2 | N16: =SUM(J16:M16) | O16: 3 | P16: =N16*O16 | Q16: =IF(P16<=4,"Trivial",IF(P16<=8,"Tolerable",IF(P16<=16,"Moderado",IF(P16<=24,"Importante","Intolerable")))) | R16: =IF(OR(Q16="Importante",Q16="Intolerable"),"Sí","No") | S16: No aplica | T16: No aplica | U16: Almacén ventilado con bandeja antiderrame, extintores PQS y señalización; distancia a fuentes de ignición | V16: Prohibido fumar; hojas de datos de seguridad (SDS) en el almacén; inspección mensual de extintores | W16: EPP básico | X16: 2 | Y16: 1 | Z16: 1 | AA16: 1 | AB16: =SUM(X16:AA16) | AC16: 3 | AD16: =AB16*AC16 | AE16: =IF(AD16<=4,"Trivial",IF(AD16<=8,"Tolerable",IF(AD16<=16,"Moderado",IF(AD16<=24,"Importante","Intolerable")))) | AF16: =IF(OR(AE16="Importante",AE16="Intolerable"),"Sí","No") | AG16: PETS - Instalación de campamento y almacenamiento de materiales | AH16: —
A17: 12 | B17: Obras provisionales | C17: Campamento, almacenes, comedor, servicios higiénicos y cartel de obra | D17: Operario, Oficial, Peón, Almacenero | E17: R | F17: Equipos eléctricos portátiles y extensiones | G17: Contacto eléctrico directo o indirecto | H17: Quemaduras, electrocución | I17: S | J17: 2 | K17: 2 | L17: 2 | M17: 2 | N17: =SUM(J17:M17) | O17: 3 | P17: =N17*O17 | Q17: =IF(P17<=4,"Trivial",IF(P17<=8,"Tolerable",IF(P17<=16,"Moderado",IF(P17<=24,"Importante","Intolerable")))) | R17: =IF(OR(Q17="Importante",Q17="Intolerable"),"Sí","No") | S17: No aplica | T17: No aplica | U17: Tablero provisional con interruptor diferencial y puesta a tierra; cables y enchufes industriales | V17: Inspección de equipos y extensiones; bloqueo y etiquetado; solo personal autorizado manipula el tablero | W17: Guantes de cuero o badana | X17: 2 | Y17: 1 | Z17: 1 | AA17: 2 | AB17: =SUM(X17:AA17) | AC17: 2 | AD17: =AB17*AC17 | AE17: =IF(AD17<=4,"Trivial",IF(AD17<=8,"Tolerable",IF(AD17<=16,"Moderado",IF(AD17<=24,"Importante","Intolerable")))) | AF17: =IF(OR(AE17="Importante",AE17="Intolerable"),"Sí","No") | AG17: PETS - Instalación de campamento y almacenamiento de materiales | AH17: —
... A114: 109 | B114: Gestión ambiental | C114: Manejo de residuos, servicios higiénicos portátiles y revegetación | D114: Peón, Operario | E114: R | F114: Manipulación manual de cargas | G114: Sobreesfuerzo por levantar o trasladar cargas pesadas o en mala postura | H114: Lumbalgia, hernias, lesiones musculoesqueléticas | I114: SO | J114: 2 | K114: 2 | L114: 2 | M114: 3 | N114: =SUM(J114:M114) | O114: 2 | P114: =N114*O114 | Q114: =IF(P114<=4,"Trivial",IF(P114<=8,"Tolerable",IF(P114<=16,"Moderado",IF(P114<=24,"Importante","Intolerable")))) | R114: =IF(OR(Q114="Importante",Q114="Intolerable"),"Sí","No") | S114: No aplica | T114: Uso de carretillas, montacargas o equipo para cargas mayores de 25 kg | U114: Puntos de acopio cerca del frente de trabajo | V114: Capacitación en levantamiento seguro (R.M. N.° 375-2008-TR); trabajo en pareja; pausas activas | W114: EPP básico; faja lumbar solo con indicación médica | X114: 2 | Y114: 1 | Z114: 1 | AA114: 3 | AB114: =SUM(X114:AA114) | AC114: 1 | AD114: =AB114*AC114 | AE114: =IF(AD114<=4,"Trivial",IF(AD114<=8,"Tolerable",IF(AD114<=16,"Moderado",IF(AD114<=24,"Importante","Intolerable")))) | AF114: =IF(OR(AE114="Importante",AE114="Intolerable"),"Sí","No") | AG114: PETS - Manejo de residuos sólidos y peligrosos | AH114: —

Sheet RESUMEN
A1: RESUMEN DE NIVELES DE RIESGO
A2: Fórmulas sobre la hoja IPERC: se actualiza al cambiar los índices
A4: PROCESO | B4: PELIGROS | C4: INICIAL TRIVIAL | D4: INICIAL TOLERABLE | E4: INICIAL MODERADO | F4: INICIAL IMPORTANTE | G4: INICIAL INTOLERABLE | H4: RESIDUAL TRIVIAL | I4: RESIDUAL TOLERABLE | J4: RESIDUAL MODERADO | K4: RESIDUAL IMPORTANTE | L4: RESIDUAL INTOLERABLE
A5: Actividades generales | B5: =COUNTIF(IPERC!$B$6:$B$114,A5) | C5: =COUNTIFS(IPERC!$B$6:$B$114,$A5,IPERC!$Q$6:$Q$114,"Trivial") | D5: =COUNTIFS(IPERC!$B$6:$B$114,$A5,IPERC!$Q$6:$Q$114,"Tolerable") | E5: =COUNTIFS(IPERC!$B$6:$B$114,$A5,IPERC!$Q$6:$Q$114,"Moderado") | F5: =COUNTIFS(IPERC!$B$6:$B$114,$A5,IPERC!$Q$6:$Q$114,"Importante") | G5: =COUNTIFS(IPERC!$B$6:$B$114,$A5,IPERC!$Q$6:$Q$114,"Intolerable") | H5: =COUNTIFS(IPERC!$B$6:$B$114,$A5,IPERC!$AE$6:$AE$114,"Trivial") | I5: =COUNTIFS(IPERC!$B$6:$B$114,$A5,IPERC!$AE$6:$AE$114,"Tolerable") | J5: =COUNTIFS(IPERC!$B$6:$B$114,$A5,IPERC!$AE$6:$AE$114,"Moderado") | K5: =COUNTIFS(IPERC!$B$6:$B$114,$A5,IPERC!$AE$6:$AE$114,"Importante") | L5: =COUNTIFS(IPERC!$B$6:$B$114,$A5,IPERC!$AE$6:$AE$114,"Intolerable")
A6: Obras provisionales | B6: =COUNTIF(IPERC!$B$6:$B$114,A6) | C6: =COUNTIFS(IPERC!$B$6:$B$114,$A6,IPERC!$Q$6:$Q$114,"Trivial") | D6: =COUNTIFS(IPERC!$B$6:$B$114,$A6,IPERC!$Q$6:$Q$114,"Tolerable") | E6: =COUNTIFS(IPERC!$B$6:$B$114,$A6,IPERC!$Q$6:$Q$114,"Moderado") | F6: =COUNTIFS(IPERC!$B$6:$B$114,$A6,IPERC!$Q$6:$Q$114,"Importante") | G6: =COUNTIFS(IPERC!$B$6:$B$114,$A6,IPERC!$Q$6:$Q$114,"Intolerable") | H6: =COUNTIFS(IPERC!$B$6:$B$114,$A6,IPERC!$AE$6:$AE$114,"Trivial") | I6: =COUNTIFS(IPERC!$B$6:$B$114,$A6,IPERC!$AE$6:$AE$114,"Tolerable") | J6: =COUNTIFS(IPERC!$B$6:$B$114,$A6,IPERC!$AE$6:$AE$114,"Moderado") | K6: =COUNTIFS(IPERC!$B$6:$B$114,$A6,IPERC!$AE$6:$AE$114,"Importante") | L6: =COUNTIFS(IPERC!$B$6:$B$114,$A6,IPERC!$AE$6:$AE$114,"Intolerable")
A7: Obras preliminares | B7: =COUNTIF(IPERC!$B$6:$B$114,A7) | C7: =COUNTIFS(IPERC!$B$6:$B$114,$A7,IPERC!$Q$6:$Q$114,"Trivial") | D7: =COUNTIFS(IPERC!$B$6:$B$114,$A7,IPERC!$Q$6:$Q$114,"Tolerable") | E7: =COUNTIFS(IPERC!$B$6:$B$114,$A7,IPERC!$Q$6:$Q$114,"Moderado") | F7: =COUNTIFS(IPERC!$B$6:$B$114,$A7,IPERC!$Q$6:$Q$114,"Importante") | G7: =COUNTIFS(IPERC!$B$6:$B$114,$A7,IPERC!$Q$6:$Q$114,"Intolerable") | H7: =COUNTIFS(IPERC!$B$6:$B$114,$A7,IPERC!$AE$6:$AE$114,"Trivial") | I7: =COUNTIFS(IPERC!$B$6:$B$114,$A7,IPERC!$AE$6:$AE$114,"Tolerable") | J7: =COUNTIFS(IPERC!$B$6:$B$114,$A7,IPERC!$AE$6:$AE$114,"Moderado") | K7: =COUNTIFS(IPERC!$B$6:$B$114,$A7,IPERC!$AE$6:$AE$114,"Importante") | L7: =COUNTIFS(IPERC!$B$6:$B$114,$A7,IPERC!$AE$6:$AE$114,"Intolerable")
A8: Demoliciones | B8: =COUNTIF(IPERC!$B$6:$B$114,A8) | C8: =COUNTIFS(IPERC!$B$6:$B$114,$A8,IPERC!$Q$6:$Q$114,"Trivial") | D8: =COUNTIFS(IPERC!$B$6:$B$114,$A8,IPERC!$Q$6:$Q$114,"Tolerable") | E8: =COUNTIFS(IPERC!$B$6:$B$114,$A8,IPERC!$Q$6:$Q$114,"Moderado") | F8: =COUNTIFS(IPERC!$B$6:$B$114,$A8,IPERC!$Q$6:$Q$114,"Importante") | G8: =COUNTIFS(IPERC!$B$6:$B$114,$A8,IPERC!$Q$6:$Q$114,"Intolerable") | H8: =COUNTIFS(IPERC!$B$6:$B$114,$A8,IPERC!$AE$6:$AE$114,"Trivial") | I8: =COUNTIFS(IPERC!$B$6:$B$114,$A8,IPERC!$AE$6:$AE$114,"Tolerable") | J8: =COUNTIFS(IPERC!$B$6:$B$114,$A8,IPERC!$AE$6:$AE$114,"Moderado") | K8: =COUNTIFS(IPERC!$B$6:$B$114,$A8,IPERC!$AE$6:$AE$114,"Importante") | L8: =COUNTIFS(IPERC!$B$6:$B$114,$A8,IPERC!$AE$6:$AE$114,"Intolerable")
A9: Movimiento de tierras | B9: =COUNTIF(IPERC!$B$6:$B$114,A9) | C9: =COUNTIFS(IPERC!$B$6:$B$114,$A9,IPERC!$Q$6:$Q$114,"Trivial") | D9: =COUNTIFS(IPERC!$B$6:$B$114,$A9,IPERC!$Q$6:$Q$114,"Tolerable") | E9: =COUNTIFS(IPERC!$B$6:$B$114,$A9,IPERC!$Q$6:$Q$114,"Moderado") | F9: =COUNTIFS(IPERC!$B$6:$B$114,$A9,IPERC!$Q$6:$Q$114,"Importante") | G9: =COUNTIFS(IPERC!$B$6:$B$114,$A9,IPERC!$Q$6:$Q$114,"Intolerable") | H9: =COUNTIFS(IPERC!$B$6:$B$114,$A9,IPERC!$AE$6:$AE$114,"Trivial") | I9: =COUNTIFS(IPERC!$B$6:$B$114,$A9,IPERC!$AE$6:$AE$114,"Tolerable") | J9: =COUNTIFS(IPERC!$B$6:$B$114,$A9,IPERC!$AE$6:$AE$114,"Moderado") | K9: =COUNTIFS(IPERC!$B$6:$B$114,$A9,IPERC!$AE$6:$AE$114,"Importante") | L9: =COUNTIFS(IPERC!$B$6:$B$114,$A9,IPERC!$AE$6:$AE$114,"Intolerable")
A10: Transporte | B10: =COUNTIF(IPERC!$B$6:$B$114,A10) | C10: =COUNTIFS(IPERC!$B$6:$B$114,$A10,IPERC!$Q$6:$Q$114,"Trivial") | D10: =COUNTIFS(IPERC!$B$6:$B$114,$A10,IPERC!$Q$6:$Q$114,"Tolerable") | E10: =COUNTIFS(IPERC!$B$6:$B$114,$A10,IPERC!$Q$6:$Q$114,"Moderado") | F10: =COUNTIFS(IPERC!$B$6:$B$114,$A10,IPERC!$Q$6:$Q$114,"Importante") | G10: =COUNTIFS(IPERC!$B$6:$B$114,$A10,IPERC!$Q$6:$Q$114,"Intolerable") | H10: =COUNTIFS(IPERC!$B$6:$B$114,$A10,IPERC!$AE$6:$AE$114,"Trivial") | I10: =COUNTIFS(IPERC!$B$6:$B$114,$A10,IPERC!$AE$6:$AE$114,"Tolerable") | J10: =COUNTIFS(IPERC!$B$6:$B$114,$A10,IPERC!$AE$6:$AE$114,"Moderado") | K10: =COUNTIFS(IPERC!$B$6:$B$114,$A10,IPERC!$AE$6:$AE$114,"Importante") | L10: =COUNTIFS(IPERC!$B$6:$B$114,$A10,IPERC!$AE$6:$AE$114,"Intolerable")
A11: Obras de concreto | B11: =COUNTIF(IPERC!$B$6:$B$114,A11) | C11: =COUNTIFS(IPERC!$B$6:$B$114,$A11,IPERC!$Q$6:$Q$114,"Trivial") | D11: =COUNTIFS(IPERC!$B$6:$B$114,$A11,IPERC!$Q$6:$Q$114,"Tolerable") | E11: =COUNTIFS(IPERC!$B$6:$B$114,$A11,IPERC!$Q$6:$Q$114,"Moderado") | F11: =COUNTIFS(IPERC!$B$6:$B$114,$A11,IPERC!$Q$6:$Q$114,"Importante") | G11: =COUNTIFS(IPERC!$B$6:$B$114,$A11,IPERC!$Q$6:$Q$114,"Intolerable") | H11: =COUNTIFS(IPERC!$B$6:$B$114,$A11,IPERC!$AE$6:$AE$114,"Trivial") | I11: =COUNTIFS(IPERC!$B$6:$B$114,$A11,IPERC!$AE$6:$AE$114,"Tolerable") | J11: =COUNTIFS(IPERC!$B$6:$B$114,$A11,IPERC!$AE$6:$AE$114,"Moderado") | K11: =COUNTIFS(IPERC!$B$6:$B$114,$A11,IPERC!$AE$6:$AE$114,"Importante") | L11: =COUNTIFS(IPERC!$B$6:$B$114,$A11,IPERC!$AE$6:$AE$114,"Intolerable")
A12: Obras de arte y drenaje | B12: =COUNTIF(IPERC!$B$6:$B$114,A12) | C12: =COUNTIFS(IPERC!$B$6:$B$114,$A12,IPERC!$Q$6:$Q$114,"Trivial") | D12: =COUNTIFS(IPERC!$B$6:$B$114,$A12,IPERC!$Q$6:$Q$114,"Tolerable") | E12: =COUNTIFS(IPERC!$B$6:$B$114,$A12,IPERC!$Q$6:$Q$114,"Moderado") | F12: =COUNTIFS(IPERC!$B$6:$B$114,$A12,IPERC!$Q$6:$Q$114,"Importante") | G12: =COUNTIFS(IPERC!$B$6:$B$114,$A12,IPERC!$Q$6:$Q$114,"Intolerable") | H12: =COUNTIFS(IPERC!$B$6:$B$114,$A12,IPERC!$AE$6:$AE$114,"Trivial") | I12: =COUNTIFS(IPERC!$B$6:$B$114,$A12,IPERC!$AE$6:$AE$114,"Tolerable") | J12: =COUNTIFS(IPERC!$B$6:$B$114,$A12,IPERC!$AE$6:$AE$114,"Moderado") | K12: =COUNTIFS(IPERC!$B$6:$B$114,$A12,IPERC!$AE$6:$AE$114,"Importante") | L12: =COUNTIFS(IPERC!$B$6:$B$114,$A12,IPERC!$AE$6:$AE$114,"Intolerable")
A13: Pavimentos | B13: =COUNTIF(IPERC!$B$6:$B$114,A13) | C13: =COUNTIFS(IPERC!$B$6:$B$114,$A13,IPERC!$Q$6:$Q$114,"Trivial") | D13: =COUNTIFS(IPERC!$B$6:$B$114,$A13,IPERC!$Q$6:$Q$114,"Tolerable") | E13: =COUNTIFS(IPERC!$B$6:$B$114,$A13,IPERC!$Q$6:$Q$114,"Moderado") | F13: =COUNTIFS(IPERC!$B$6:$B$114,$A13,IPERC!$Q$6:$Q$114,"Importante") | G13: =COUNTIFS(IPERC!$B$6:$B$114,$A13,IPERC!$Q$6:$Q$114,"Intolerable") | H13: =COUNTIFS(IPERC!$B$6:$B$114,$A13,IPERC!$AE$6:$AE$114,"Trivial") | I13: =COUNTIFS(IPERC!$B$6:$B$114,$A13,IPERC!$AE$6:$AE$114,"Tolerable") | J13: =COUNTIFS(IPERC!$B$6:$B$114,$A13,IPERC!$AE$6:$AE$114,"Moderado") | K13: =COUNTIFS(IPERC!$B$6:$B$114,$A13,IPERC!$AE$6:$AE$114,"Importante") | L13: =COUNTIFS(IPERC!$B$6:$B$114,$A13,IPERC!$AE$6:$AE$114,"Intolerable")
A14: Puentes y estructuras | B14: =COUNTIF(IPERC!$B$6:$B$114,A14) | C14: =COUNTIFS(IPERC!$B$6:$B$114,$A14,IPERC!$Q$6:$Q$114,"Trivial") | D14: =COUNTIFS(IPERC!$B$6:$B$114,$A14,IPERC!$Q$6:$Q$114,"Tolerable") | E14: =COUNTIFS(IPERC!$B$6:$B$114,$A14,IPERC!$Q$6:$Q$114,"Moderado") | F14: =COUNTIFS(IPERC!$B$6:$B$114,$A14,IPERC!$Q$6:$Q$114,"Importante") | G14: =COUNTIFS(IPERC!$B$6:$B$114,$A14,IPERC!$Q$6:$Q$114,"Intolerable") | H14: =COUNTIFS(IPERC!$B$6:$B$114,$A14,IPERC!$AE$6:$AE$114,"Trivial") | I14: =COUNTIFS(IPERC!$B$6:$B$114,$A14,IPERC!$AE$6:$AE$114,"Tolerable") | J14: =COUNTIFS(IPERC!$B$6:$B$114,$A14,IPERC!$AE$6:$AE$114,"Moderado") | K14: =COUNTIFS(IPERC!$B$6:$B$114,$A14,IPERC!$AE$6:$AE$114,"Importante") | L14: =COUNTIFS(IPERC!$B$6:$B$114,$A14,IPERC!$AE$6:$AE$114,"Intolerable")
A15: Señalización y seguridad vial | B15: =COUNTIF(IPERC!$B$6:$B$114,A15) | C15: =COUNTIFS(IPERC!$B$6:$B$114,$A15,IPERC!$Q$6:$Q$114,"Trivial") | D15: =COUNTIFS(IPERC!$B$6:$B$114,$A15,IPERC!$Q$6:$Q$114,"Tolerable") | E15: =COUNTIFS(IPERC!$B$6:$B$114,$A15,IPERC!$Q$6:$Q$114,"Moderado") | F15: =COUNTIFS(IPERC!$B$6:$B$114,$A15,IPERC!$Q$6:$Q$114,"Importante") | G15: =COUNTIFS(IPERC!$B$6:$B$114,$A15,IPERC!$Q$6:$Q$114,"Intolerable") | H15: =COUNTIFS(IPERC!$B$6:$B$114,$A15,IPERC!$AE$6:$AE$114,"Trivial") | I15: =COUNTIFS(IPERC!$B$6:$B$114,$A15,IPERC!$AE$6:$AE$114,"Tolerable") | J15: =COUNTIFS(IPERC!$B$6:$B$114,$A15,IPERC!$AE$6:$AE$114,"Moderado") | K15: =COUNTIFS(IPERC!$B$6:$B$114,$A15,IPERC!$AE$6:$AE$114,"Importante") | L15: =COUNTIFS(IPERC!$B$6:$B$114,$A15,IPERC!$AE$6:$AE$114,"Intolerable")
A16: Gestión ambiental | B16: =COUNTIF(IPERC!$B$6:$B$114,A16) | C16: =COUNTIFS(IPERC!$B$6:$B$114,$A16,IPERC!$Q$6:$Q$114,"Trivial") | D16: =COUNTIFS(IPERC!$B$6:$B$114,$A16,IPERC!$Q$6:$Q$114,"Tolerable") | E16: =COUNTIFS(IPERC!$B$6:$B$114,$A16,IPERC!$Q$6:$Q$114,"Moderado") | F16: =COUNTIFS(IPERC!$B$6:$B$114,$A16,IPERC!$Q$6:$Q$114,"Importante") | G16: =COUNTIFS(IPERC!$B$6:$B$114,$A16,IPERC!$Q$6:$Q$114,"Intolerable") | H16: =COUNTIFS(IPERC!$B$6:$B$114,$A16,IPERC!$AE$6:$AE$114,"Trivial") | I16: =COUNTIFS(IPERC!$B$6:$B$114,$A16,IPERC!$AE$6:$AE$114,"Tolerable") | J16: =COUNTIFS(IPERC!$B$6:$B$114,$A16,IPERC!$AE$6:$AE$114,"Moderado") | K16: =COUNTIFS(IPERC!$B$6:$B$114,$A16,IPERC!$AE$6:$AE$114,"Importante") | L16: =COUNTIFS(IPERC!$B$6:$B$114,$A16,IPERC!$AE$6:$AE$114,"Intolerable")
A17: TOTAL | B17: =SUM(B5:B16) | C17: =SUM(C5:C16) | D17: =SUM(D5:D16) | E17: =SUM(E5:E16) | F17: =SUM(F5:F16) | G17: =SUM(G5:G16) | H17: =SUM(H5:H16) | I17: =SUM(I5:I16) | ... L17: =SUM(L5:L16)
A19: Riesgos significativos antes de los controles | B19: =COUNTIF(IPERC!$R$6:$R$114,"Sí")
A20: Riesgos significativos después de los controles | B20: =COUNTIF(IPERC!$AF$6:$AF$114,"Sí")

Sheet MAPA DE CALOR
A1: MAPA DE CALOR: PROBABILIDAD x SEVERIDAD
A2: Número de peligros en cada celda (fórmulas sobre el IPERC)
A4: EVALUACIÓN INICIAL | F4: EVALUACIÓN RESIDUAL
A5: PROBABILIDAD | B5: SEVERIDAD 1 | C5: SEVERIDAD 2 | D5: SEVERIDAD 3 | F5: PROBABILIDAD | G5: SEVERIDAD 1 | H5: SEVERIDAD 2 | I5: SEVERIDAD 3
A6: 12 | B6: =COUNTIFS(IPERC!$N$6:$N$114,12,IPERC!$O$6:$O$114,1) | C6: =COUNTIFS(IPERC!$N$6:$N$114,12,IPERC!$O$6:$O$114,2) | D6: =COUNTIFS(IPERC!$N$6:$N$114,12,IPERC!$O$6:$O$114,3) | F6: 12 | G6: =COUNTIFS(IPERC!$AB$6:$AB$114,12,IPERC!$AC$6:$AC$114,1) | H6: =COUNTIFS(IPERC!$AB$6:$AB$114,12,IPERC!$AC$6:$AC$114,2) | I6: =COUNTIFS(IPERC!$AB$6:$AB$114,12,IPERC!$AC$6:$AC$114,3)
A7: 11 | B7: =COUNTIFS(IPERC!$N$6:$N$114,11,IPERC!$O$6:$O$114,1) | C7: =COUNTIFS(IPERC!$N$6:$N$114,11,IPERC!$O$6:$O$114,2) | D7: =COUNTIFS(IPERC!$N$6:$N$114,11,IPERC!$O$6:$O$114,3) | F7: 11 | G7: =COUNTIFS(IPERC!$AB$6:$AB$114,11,IPERC!$AC$6:$AC$114,1) | H7: =COUNTIFS(IPERC!$AB$6:$AB$114,11,IPERC!$AC$6:$AC$114,2) | I7: =COUNTIFS(IPERC!$AB$6:$AB$114,11,IPERC!$AC$6:$AC$114,3)
A8: 10 | B8: =COUNTIFS(IPERC!$N$6:$N$114,10,IPERC!$O$6:$O$114,1) | C8: =COUNTIFS(IPERC!$N$6:$N$114,10,IPERC!$O$6:$O$114,2) | D8: =COUNTIFS(IPERC!$N$6:$N$114,10,IPERC!$O$6:$O$114,3) | F8: 10 | G8: =COUNTIFS(IPERC!$AB$6:$AB$114,10,IPERC!$AC$6:$AC$114,1) | H8: =COUNTIFS(IPERC!$AB$6:$AB$114,10,IPERC!$AC$6:$AC$114,2) | I8: =COUNTIFS(IPERC!$AB$6:$AB$114,10,IPERC!$AC$6:$AC$114,3)
A9: 9 | B9: =COUNTIFS(IPERC!$N$6:$N$114,9,IPERC!$O$6:$O$114,1) | C9: =COUNTIFS(IPERC!$N$6:$N$114,9,IPERC!$O$6:$O$114,2) | D9: =COUNTIFS(IPERC!$N$6:$N$114,9,IPERC!$O$6:$O$114,3) | F9: 9 | G9: =COUNTIFS(IPERC!$AB$6:$AB$114,9,IPERC!$AC$6:$AC$114,1) | H9: =COUNTIFS(IPERC!$AB$6:$AB$114,9,IPERC!$AC$6:$AC$114,2) | I9: =COUNTIFS(IPERC!$AB$6:$AB$114,9,IPERC!$AC$6:$AC$114,3)
A10: 8 | B10: =COUNTIFS(IPERC!$N$6:$N$114,8,IPERC!$O$6:$O$114,1) | C10: =COUNTIFS(IPERC!$N$6:$N$114,8,IPERC!$O$6:$O$114,2) | D10: =COUNTIFS(IPERC!$N$6:$N$114,8,IPERC!$O$6:$O$114,3) | F10: 8 | G10: =COUNTIFS(IPERC!$AB$6:$AB$114,8,IPERC!$AC$6:$AC$114,1) | H10: =COUNTIFS(IPERC!$AB$6:$AB$114,8,IPERC!$AC$6:$AC$114,2) | I10: =COUNTIFS(IPERC!$AB$6:$AB$114,8,IPERC!$AC$6:$AC$114,3)
A11: 7 | B11: =COUNTIFS(IPERC!$N$6:$N$114,7,IPERC!$O$6:$O$114,1) | C11: =COUNTIFS(IPERC!$N$6:$N$114,7,IPERC!$O$6:$O$114,2) | D11: =COUNTIFS(IPERC!$N$6:$N$114,7,IPERC!$O$6:$O$114,3) | F11: 7 | G11: =COUNTIFS(IPERC!$AB$6:$AB$114,7,IPERC!$AC$6:$AC$114,1) | H11: =COUNTIFS(IPERC!$AB$6:$AB$114,7,IPERC!$AC$6:$AC$114,2) | I11: =COUNTIFS(IPERC!$AB$6:$AB$114,7,IPERC!$AC$6:$AC$114,3)
A12: 6 | B12: =COUNTIFS(IPERC!$N$6:$N$114,6,IPERC!$O$6:$O$114,1) | C12: =COUNTIFS(IPERC!$N$6:$N$114,6,IPERC!$O$6:$O$114,2) | D12: =COUNTIFS(IPERC!$N$6:$N$114,6,IPERC!$O$6:$O$114,3) | F12: 6 | G12: =COUNTIFS(IPERC!$AB$6:$AB$114,6,IPERC!$AC$6:$AC$114,1) | H12: =COUNTIFS(IPERC!$AB$6:$AB$114,6,IPERC!$AC$6:$AC$114,2) | I12: =COUNTIFS(IPERC!$AB$6:$AB$114,6,IPERC!$AC$6:$AC$114,3)
A13: 5 | B13: =COUNTIFS(IPERC!$N$6:$N$114,5,IPERC!$O$6:$O$114,1) | C13: =COUNTIFS(IPERC!$N$6:$N$114,5,IPERC!$O$6:$O$114,2) | D13: =COUNTIFS(IPERC!$N$6:$N$114,5,IPERC!$O$6:$O$114,3) | F13: 5 | G13: =COUNTIFS(IPERC!$AB$6:$AB$114,5,IPERC!$AC$6:$AC$114,1) | H13: =COUNTIFS(IPERC!$AB$6:$AB$114,5,IPERC!$AC$6:$AC$114,2) | I13: =COUNTIFS(IPERC!$AB$6:$AB$114,5,IPERC!$AC$6:$AC$114,3)
A14: 4 | B14: =COUNTIFS(IPERC!$N$6:$N$114,4,IPERC!$O$6:$O$114,1) | C14: =COUNTIFS(IPERC!$N$6:$N$114,4,IPERC!$O$6:$O$114,2) | D14: =COUNTIFS(IPERC!$N$6:$N$114,4,IPERC!$O$6:$O$114,3) | F14: 4 | G14: =COUNTIFS(IPERC!$AB$6:$AB$114,4,IPERC!$AC$6:$AC$114,1) | H14: =COUNTIFS(IPERC!$AB$6:$AB$114,4,IPERC!$AC$6:$AC$114,2) | I14: =COUNTIFS(IPERC!$AB$6:$AB$114,4,IPERC!$AC$6:$AC$114,3)

Sheet EPP
A1: MATRIZ DE EQUIPOS DE PROTECCIÓN PERSONAL POR PUESTO
A2: X = uso obligatorio; según las actividades del IPERC
A4: PUESTO | B4: Casco de seguridad con barbiquejo (ANSI Z89.1) | C4: Lentes de seguridad claros u oscuros (ANSI Z87.1) | D4: Calzado de seguridad con puntera (ASTM F2413) | E4: Botas de jebe con puntera de acero | F4: Chaleco o uniforme con cintas reflectivas (ANSI/ISEA 107) | G4: Guantes de cuero o badana | H4: Guantes de nitrilo o neopreno (químicos, cemento, asfalto) | I4: Guantes dieléctricos clase según tensión y guantes de cuero de protección | J4: Protector auditivo tipo tapón u orejera (ANSI S3.19) | K4: Respirador de media cara con filtros para polvo P100 (NIOSH) | L4: Respirador de media cara con cartuchos para vapores orgánicos (NIOSH) | M4: Arnés de cuerpo entero y línea de anclaje con absorbedor de impacto (ANSI Z359.11) | N4: Careta de soldar con filtro adecuado, mandil, escarpines y guantes de caña larga de cuero | O4: Careta facial de policarbonato | P4: Bloqueador solar FPS 50+ y cortasol para casco | Q4: Polainas de protección contra mordeduras y botas de caña alta | R4: Chaleco salvavidas | S4: Ropa de manga larga de algodón y guantes de caña larga resistentes al calor | T4: Repelente de insectos y ropa de manga larga | U4: Ropa impermeable (poncho o traje de agua)
A5: Todo el personal | B5: X | C5: X | D5: X | F5: X | G5: X | P5: X | Q5: X | T5: X | U5: X
A6: Chofer | B6: X | C6: X | D6: X | F6: X | G6: X | J6: X | K6: X
A7: Operario | B7: X | C7: X | D7: X | E7: X | F7: X | G7: X | H7: X | I7: X | J7: X | K7: X | L7: X | M7: X | O7: X | R7: X
A8: Oficial | B8: X | C8: X | D8: X | E8: X | F8: X | G8: X | H8: X | J8: X | M8: X | R8: X
A9: Peón | B9: X | C9: X | D9: X | E9: X | F9: X | G9: X | H9: X | I9: X | J9: X | K9: X | L9: X | M9: X | N9: X | O9: X | P9: X | R9: X | S9: X
A10: Almacenero | B10: X | C10: X | D10: X | F10: X | G10: X
A11: Operador de equipo | B11: X | C11: X | D11: X | E11: X | F11: X | G11: X | J11: X | K11: X | O11: X | P11: X | R11: X
A12: Rigger | B12: X | C12: X | D12: X | F12: X | G12: X | J12: X | L12: X | M12: X | N12: X
A13: Topógrafo | B13: X | C13: X | D13: X | F13: X | G13: X
A14: Ayudante de topografía | B14: X | C14: X | D14: X | F14: X | G14: X
A15: Controlador de tránsito (vigía) | B15: X | C15: X | D15: X | F15: X | G15: X | L15: X | P15: X
A16: Motosierrista | B16: X | C16: X | D16: X | F16: X | G16: X | J16: X | O16: X
A17: Vigía de maquinaria | B17: X | C17: X | D17: X | F17: X | G17: X | J17: X | K17: X
A18: Perforista | B18: X | C18: X | D18: X | F18: X | G18: X | J18: X | K18: X
A19: Disparador autorizado | B19: X | C19: X | D19: X | F19: X | G19: X | J19: X | K19: X
A20: Operador de cargador | B20: X | C20: X | D20: X | F20: X | G20: X
A21: Operario fierrero | B21: X | C21: X | D21: X | F21: X | G21: X
A22: Operario carpintero | B22: X | C22: X | D22: X | F22: X | G22: X | J22: X | M22: X
A23: Operador de mezcladora | B23: X | C23: X | D23: X | E23: X | F23: X | G23: X | H23: X
A24: Operador de pavimentadora | B24: X | C24: X | D24: X | F24: X | G24: X | L24: X | P24: X | S24: X
A25: Operador de rodillo | B25: X | C25: X | D25: X | F25: X | G25: X | L25: X | P25: X | S25: X
A26: Rastrillero | B26: X | C26: X | D26: X | F26: X | G26: X | L26: X | P26: X | S26: X
A27: Chofer de imprimadora | B27: X | C27: X | D27: X | F27: X | G27: X | L27: X | P27: X | S27: X
A28: Operario soldador | B28: X | C28: X | D28: X | F28: X | G28: X | J28: X | L28: X | M28: X | N28: X
A29: Montajista | B29: X | C29: X | D29: X | F29: X | G29: X | J29: X | L29: X | M29: X | N29: X
A30: Operador de grúa | B30: X | C30: X | D30: X | F30: X | G30: X | I30: X | J30: X | L30: X | M30: X | N30: X | R30: X
A31: Electricista | B31: X | C31: X | D31: X | F31: X | G31: X | I31: X | M31: X
A32: Mecánico | B32: X | C32: X | D32: X | F32: X | G32: X
A33: Abastecedor | B33: X | C33: X | D33: X | F33: X | G33: X

Sheet PETS-PETAR
A1: PROCEDIMIENTOS ESCRITOS DE TRABAJO SEGURO Y PERMISOS DE TRABAJO DE ALTO RIESGO
A2: MEJORAMIENTO DEL SERVICIO DE TRANSITABILIDAD VIAL INTERURBANA EN LA VÍA DEPARTAMENTAL SM-107, TRAMO TINGO DE PONASA - SHAMBOYACU, DISTRITO DE SHAMBOYACU, PROVINCIA DE PICOTA, DEPARTAMENTO DE SAN MARTÍN - CUI N.° 2673852
A4: CÓDIGO | B4: PROCEDIMIENTO | C4: ACTIVIDAD | D4: REQUIERE PETAR
A5: PETS-01 | B5: Reglamento interno de SST y charla diaria de 5 minutos | C5: Trabajos generales a campo abierto | D5: No
A6: PETS-02 | B6: PETS - Prevención de mordeduras de ofidios y enfermedades metaxénicas | C6: Trabajos en zona de selva (fauna y vectores) | D6: No
A7: PETS-03 | B7: PETS - Transporte de personal y manejo defensivo | C7: Traslado de personal y materiales en vehículos | D7: No
A8: PETS-04 | B8: PETS - Instalación de campamento y almacenamiento de materiales | C8: Campamento, almacenes, comedor, servicios higiénicos y cartel de obra | D8: No
A9: PETS-05 | B9: PETS - Movilización de equipos en cama baja | C9: Movilización y desmovilización de equipos y fletes | D9: No
A10: PETS-06 | B10: PETS - Trabajos de topografía en vía con tránsito | C10: Topografía, trazo, nivelación y replanteo | D10: No
A11: PETS-07 | B11: Plan de desvíos y PETS - Control de tránsito en zona de trabajo | C11: Mantenimiento del tránsito, desvíos y señalización temporal | D11: No
A12: PETS-08 | B12: PETS - Desbroce y tala de árboles | C12: Desbroce, limpieza de terreno y tala de árboles | D12: No
A13: PETS-09 | B13: PETS - Demolición de estructuras existentes | C13: Demolición de estructuras, escarificado y desmontaje | D13: Trabajos en altura (a partir de 1.80 m)
A14: PETS-10 | B14: PETS - Movimiento de tierras con maquinaria pesada | C14: Movimiento de tierras con maquinaria (corte, terraplén, eliminación, canteras y DME) | D14: No
A15: PETS-11 | B15: PETS - Corte en roca y voladura controlada | C15: Corte en roca (martillo hidráulico o voladura controlada) | D15: Uso de explosivos (voladura)
... A32: PETS-28 | B32: PETS - Manejo de residuos sólidos y peligrosos | C32: Manejo de residuos, servicios higiénicos portátiles y revegetación | D32: No
A34: N.° | B34: PETAR | C34: ACTIVIDADES
A35: 1 | B35: Trabajos en altura (a partir de 1.80 m) | C35: Demolición de estructuras, escarificado y desmontaje; Encofrado y desencofrado; Fabricación, arenado, pintura y montaje de estructuras metálicas; Trabajos en puentes sobre cauces (estribos, superestructura, prueba de carga); Reubicación de postes e interferencias con redes eléctricas
A36: 2 | B36: Uso de explosivos (voladura) | C36: Corte en roca (martillo hidráulico o voladura controlada)
A37: 3 | B37: Excavaciones y zanjas (profundidad mayor de 1.50 m) | C37: Excavación de zanjas y para estructuras
A38: 4 | B38: Trabajos en cauces, sobre agua o con riesgo de ahogamiento | C38: Trabajos en cauces, excavación bajo agua y encauzamiento; Trabajos en puentes sobre cauces (estribos, superestructura, prueba de carga)
A39: 5 | B39: Izaje de cargas con grúa o equipo de levante | C39: Instalación de alcantarillas, tuberías y elementos prefabricados; Fabricación, arenado, pintura y montaje de estructuras metálicas; Reubicación de postes e interferencias con redes eléctricas
A40: 6 | B40: Trabajos en caliente (soldadura, oxicorte, esmerilado, asfalto caliente) | C40: Imprimación, riego de liga y pavimento asfáltico en caliente; Fabricación, arenado, pintura y montaje de estructuras metálicas
A41: 7 | B41: Trabajos con energía eléctrica y cerca de líneas energizadas | C41: Reubicación de postes e interferencias con redes eléctricas

Sheet CAPACITACION
A1: PROGRAMA DE CAPACITACIÓN Y SENSIBILIZACIÓN EN SST
A2: X = mes programado; total de horas por fórmula
A4: N.° | B4: TEMA | C4: DIRIGIDO A | D4: HORAS | E4: FRECUENCIA | F4: M1 | G4: M2 | H4: M3 | I4: M4 | J4: M5 | K4: M6 | L4: M7 | M4: M8 | N4: M9 | O4: M10 | P4: M11 | Q4: M12 | R4: M13 | S4: M14 | T4: M15 | U4: M16 | V4: M17 | W4: M18 | X4: M19 | Y4: M20 | Z4: M21 | AA4: M22 | AB4: M23 | AC4: M24 | AD4: VECES | AE4: HORAS TOTAL
A5: 1 | B5: Inducción en SST para trabajadores nuevos (reglamento interno, IPERC del puesto, derechos y obligaciones) | C5: Todo el personal nuevo | D5: 4 | E5: al ingreso | F5: X | G5: X | H5: X | I5: X | J5: X | K5: X | L5: X | M5: X | N5: X | O5: X | P5: X | Q5: X | R5: X | S5: X | T5: X | U5: X | V5: X | W5: X | X5: X | Y5: X | Z5: X | AA5: X | AB5: X | AC5: X | AD5: =COUNTIF(F5:AC5,"X") | AE5: =D5*AD5
A6: 2 | B6: Identificación de peligros, evaluación de riesgos y uso del ATS | C6: Todo el personal | D6: 2 | E6: trimestral | F6: X | I6: X | L6: X | O6: X | R6: X | U6: X | X6: X | AA6: X | AD6: =COUNTIF(F6:AC6,"X") | AE6: =D6*AD6
A7: 3 | B7: Uso, conservación y reposición de EPP | C7: Todo el personal | D7: 1 | E7: trimestral | F7: X | I7: X | L7: X | O7: X | R7: X | U7: X | X7: X | AA7: X | AD7: =COUNTIF(F7:AC7,"X") | AE7: =D7*AD7
A8: 4 | B8: Orden y limpieza en obra | C8: Todo el personal | D8: 1 | E8: semestral | F8: X | L8: X | R8: X | X8: X | AD8: =COUNTIF(F8:AC8,"X") | AE8: =D8*AD8
A9: 5 | B9: Primeros auxilios y evacuación de heridos | C9: Brigadistas y capataces | D9: 4 | E9: semestral | F9: X | L9: X | R9: X | X9: X | AD9: =COUNTIF(F9:AC9,"X") | AE9: =D9*AD9
A10: 6 | B10: Prevención y uso de extintores | C10: Brigadistas y almaceneros | D10: 2 | E10: semestral | F10: X | L10: X | R10: X | X10: X | AD10: =COUNTIF(F10:AC10,"X") | AE10: =D10*AD10
A11: 7 | B11: Plan de respuesta ante emergencias y simulacros | C11: Todo el personal | D11: 2 | E11: semestral | F11: X | L11: X | R11: X | X11: X | AD11: =COUNTIF(F11:AC11,"X") | AE11: =D11*AD11
A12: 8 | B12: Manejo defensivo y reglamento de tránsito | C12: Choferes y operadores | D12: 4 | E12: semestral | F12: X | L12: X | R12: X | X12: X | AD12: =COUNTIF(F12:AC12,"X") | AE12: =D12*AD12
A13: 9 | B13: Ergonomía y levantamiento manual de cargas (R.M. N.° 375-2008-TR) | C13: Todo el personal | D13: 1 | E13: semestral | F13: X | L13: X | R13: X | X13: X | AD13: =COUNTIF(F13:AC13,"X") | AE13: =D13*AD13
A14: 10 | B14: Riesgos psicosociales, hostigamiento sexual y bienestar | C14: Todo el personal | D14: 1 | E14: anual | F14: X | R14: X | AD14: =COUNTIF(F14:AC14,"X") | AE14: =D14*AD14
A15: 11 | B15: Investigación de incidentes y accidentes | C15: Supervisores, capataces y comité | D15: 2 | E15: anual | F15: X | R15: X | AD15: =COUNTIF(F15:AC15,"X") | AE15: =D15*AD15
A16: 12 | B16: Trabajos en altura y uso del sistema de protección contra caídas | C16: Personal que trabaja en altura | D16: 4 | E16: semestral | F16: X | L16: X | R16: X | X16: X | AD16: =COUNTIF(F16:AC16,"X") | AE16: =D16*AD16
A17: 13 | B17: Manipulación de explosivos y voladura controlada | C17: Perforistas y disparadores autorizados | D17: 4 | E17: semestral | F17: X | L17: X | R17: X | X17: X | AD17: =COUNTIF(F17:AC17,"X") | AE17: =D17*AD17
A18: 14 | B18: Excavaciones y zanjas: taludes, entibados y PETAR | C18: Personal de excavaciones | D18: 2 | E18: semestral | F18: X | L18: X | R18: X | X18: X | AD18: =COUNTIF(F18:AC18,"X") | AE18: =D18*AD18
A19: 15 | B19: Trabajos en cauces y rescate acuático básico | C19: Personal que trabaja sobre o junto a cauces | D19: 2 | E19: semestral | F19: X | L19: X | R19: X | X19: X | AD19: =COUNTIF(F19:AC19,"X") | AE19: =D19*AD19
A20: 16 | B20: Izaje de cargas, señales al operador y aparejos | C20: Riggers, operadores de grúa y montajistas | D20: 4 | E20: semestral | F20: X | L20: X | R20: X | X20: X | AD20: =COUNTIF(F20:AC20,"X") | AE20: =D20*AD20
A21: 17 | B21: Trabajos en caliente y prevención de incendios | C21: Soldadores, asfaltadores y vigías | D21: 2 | E21: semestral | F21: X | L21: X | R21: X | X21: X | AD21: =COUNTIF(F21:AC21,"X") | AE21: =D21*AD21
A22: 18 | B22: Riesgo eléctrico, bloqueo y etiquetado (LOTO) | C22: Electricistas y personal autorizado | D22: 4 | E22: semestral | F22: X | L22: X | R22: X | X22: X | AD22: =COUNTIF(F22:AC22,"X") | AE22: =D22*AD22
A23: 19 | B23: Prevención de mordeduras de ofidios, picaduras y enfermedades metaxénicas | C23: Todo el personal | D23: 1 | E23: semestral | F23: X | L23: X | R23: X | X23: X | AD23: =COUNTIF(F23:AC23,"X") | AE23: =D23*AD23
A24: 20 | B24: Operación segura de maquinaria pesada, puntos ciegos y señales con el vigía | C24: Operadores, choferes y vigías | D24: 2 | E24: semestral | F24: X | L24: X | R24: X | X24: X | AD24: =COUNTIF(F24:AC24,"X") | AE24: =D24*AD24
A25: 21 | B25: Control de tránsito en zona de trabajo (Manual de Dispositivos de Control del Tránsito del MTC) | C25: Controladores de tránsito y capataces | D25: 2 | E25: semestral | F25: X | L25: X | R25: X | X25: X | AD25: =COUNTIF(F25:AC25,"X") | AE25: =D25*AD25

Sheet INSPECCIONES
A1: PROGRAMA DE INSPECCIONES DE SST
A2: MEJORAMIENTO DEL SERVICIO DE TRANSITABILIDAD VIAL INTERURBANA EN LA VÍA DEPARTAMENTAL SM-107, TRAMO TINGO DE PONASA - SHAMBOYACU, DISTRITO DE SHAMBOYACU, PROVINCIA DE PICOTA, DEPARTAMENTO DE SAN MARTÍN - CUI N.° 2673852
A4: N.° | B4: INSPECCIÓN | C4: RESPONSABLE | D4: FRECUENCIA
A5: 1 | B5: Pre-uso de maquinaria y vehículos (check-list) | C5: Operador / chofer | D5: Diaria
A6: 2 | B6: Frentes de trabajo: orden, señalización y cumplimiento del ATS | C6: Supervisor de SST / capataz | D6: Diaria
A7: 3 | B7: Herramientas manuales y eléctricas (cinta de color del mes) | C7: Capataz | D7: Mensual
A8: 4 | B8: Equipos de protección personal | C8: Supervisor de SST | D8: Mensual
A9: 5 | B9: Extintores, botiquines y camilla | C9: Supervisor de SST / brigadas | D9: Mensual
A10: 6 | B10: Campamento, almacenes, comedor y servicios higiénicos | C10: Supervisor de SST / administración | D10: Mensual
A11: 7 | B11: Instalaciones eléctricas provisionales y tableros | C11: Electricista | D11: Mensual
A12: 8 | B12: Inspección planeada general de la obra con el comité | C12: Comité o supervisor de SST | D12: Mensual
A13: 9 | B13: Almacén de combustibles y materiales peligrosos | C13: Almacenero / supervisor de SST | D13: Semanal
A14: 10 | B14: Andamios, escaleras, líneas de vida y arneses | C14: Supervisor de SST | D14: Diaria (tarjeta) / semanal
A15: 11 | B15: Excavaciones, taludes y entibados | C15: Persona competente designada | D15: Diaria y después de lluvias
A16: 12 | B16: Grúas, aparejos y accesorios de izaje | C16: Rigger / operador | D16: Antes de cada izaje
... A18: 14 | B18: Dispositivos de control de tránsito y desvíos | C18: Supervisor de SST / responsable de tránsito | D18: Diaria

Sheet MONITOREO
A1: MONITOREO DE AGENTES OCUPACIONALES
A2: Según los peligros de salud ocupacional del IPERC
A4: N.° | B4: AGENTE | C4: MÉTODO | D4: FRECUENCIA
A5: 1 | B5: Ruido | C5: Dosimetría de ruido por puesto (TLV 85 dB(A) para 8 h) | D5: Semestral
A6: 2 | B6: Polvo inhalable y respirable | C6: Muestreo gravimétrico personal | D6: Semestral
A7: 3 | B7: Sílice cristalina respirable | C7: Muestreo personal y análisis de laboratorio | D7: Semestral
A8: 4 | B8: Vibración mano-brazo y cuerpo entero | C8: Medición con acelerómetro (ISO 5349 / ISO 2631) | D8: Anual
A9: 5 | B9: Estrés térmico | C9: Índice WBGT en frentes a campo abierto | D9: En época de mayor temperatura
A10: 6 | B10: Vapores orgánicos y humos de asfalto | C10: Muestreo personal con tubos adsorbentes | D10: Semestral
A11: 7 | B11: Monóxido de carbono | C11: Detector de gases de lectura directa | D11: Antes de cada tarea con motobombas
A12: 8 | B12: Radiación ultravioleta solar | C12: Índice UV del SENAMHI y control de exposición | D12: Diaria
A13: 9 | B13: Factores ergonómicos (manipulación de cargas y posturas) | C13: Evaluación ergonómica (R.M. N.° 375-2008-TR) | D13: Anual

Sheet INDICADORES
A1: OBJETIVOS, METAS E INDICADORES DE SST
A2: Registrar cada mes los accidentes y días perdidos (celdas amarillas)
A4: MES | B4: TRABAJADORES | C4: HORAS HOMBRE TRABAJADAS | D4: ACCIDENTES INCAPACITANTES | E4: DÍAS PERDIDOS | F4: ÍNDICE DE FRECUENCIA | G4: ÍNDICE DE GRAVEDAD | H4: ÍNDICE DE ACCIDENTABILIDAD | I4: CAPACITACIONES EJECUTADAS (%) | J4: INSPECCIONES EJECUTADAS (%)
A5: 1 | B5: 35 | C5: =B5*8*26 | D5: 0 | E5: 0 | F5: =IF(C5=0,0,D5*1000000/C5) | G5: =IF(C5=0,0,E5*1000000/C5) | H5: =F5*G5/1000 | I5: 1 | J5: 1
A6: 2 | B6: 60 | C6: =B6*8*26 | D6: 0 | E6: 0 | F6: =IF(C6=0,0,D6*1000000/C6) | G6: =IF(C6=0,0,E6*1000000/C6) | H6: =F6*G6/1000 | I6: 1 | J6: 1
A7: 3 | B7: 95 | C7: =B7*8*26 | D7: 0 | E7: 0 | F7: =IF(C7=0,0,D7*1000000/C7) | G7: =IF(C7=0,0,E7*1000000/C7) | H7: =F7*G7/1000 | I7: 1 | J7: 1
A8: 4 | B8: 120 | C8: =B8*8*26 | D8: 0 | E8: 0 | F8: =IF(C8=0,0,D8*1000000/C8) | G8: =IF(C8=0,0,E8*1000000/C8) | H8: =F8*G8/1000 | I8: 1 | J8: 1
A9: 5 | B9: 140 | C9: =B9*8*26 | D9: 0 | E9: 0 | F9: =IF(C9=0,0,D9*1000000/C9) | G9: =IF(C9=0,0,E9*1000000/C9) | H9: =F9*G9/1000 | I9: 1 | J9: 1
A10: 6 | B10: 150 | C10: =B10*8*26 | D10: 0 | E10: 0 | F10: =IF(C10=0,0,D10*1000000/C10) | G10: =IF(C10=0,0,E10*1000000/C10) | H10: =F10*G10/1000 | I10: 1 | J10: 1
A11: 7 | B11: 155 | C11: =B11*8*26 | D11: 0 | E11: 0 | F11: =IF(C11=0,0,D11*1000000/C11) | G11: =IF(C11=0,0,E11*1000000/C11) | H11: =F11*G11/1000 | I11: 1 | J11: 1
A12: 8 | B12: 160 | C12: =B12*8*26 | D12: 0 | E12: 0 | F12: =IF(C12=0,0,D12*1000000/C12) | G12: =IF(C12=0,0,E12*1000000/C12) | H12: =F12*G12/1000 | I12: 1 | J12: 1
A13: 9 | B13: 160 | C13: =B13*8*26 | D13: 0 | E13: 0 | F13: =IF(C13=0,0,D13*1000000/C13) | G13: =IF(C13=0,0,E13*1000000/C13) | H13: =F13*G13/1000 | I13: 1 | J13: 1
A14: 10 | B14: 160 | C14: =B14*8*26 | D14: 0 | E14: 0 | F14: =IF(C14=0,0,D14*1000000/C14) | G14: =IF(C14=0,0,E14*1000000/C14) | H14: =F14*G14/1000 | I14: 1 | J14: 1
A15: 11 | B15: 160 | C15: =B15*8*26 | D15: 0 | E15: 0 | F15: =IF(C15=0,0,D15*1000000/C15) | G15: =IF(C15=0,0,E15*1000000/C15) | H15: =F15*G15/1000 | I15: 1 | J15: 1
A16: 12 | B16: 155 | C16: =B16*8*26 | D16: 0 | E16: 0 | F16: =IF(C16=0,0,D16*1000000/C16) | G16: =IF(C16=0,0,E16*1000000/C16) | H16: =F16*G16/1000 | I16: 1 | J16: 1
... A28: 24 | B28: 30 | C28: =B28*8*26 | D28: 0 | E28: 0 | F28: =IF(C28=0,0,D28*1000000/C28) | G28: =IF(C28=0,0,E28*1000000/C28) | H28: =F28*G28/1000 | I28: 1 | J28: 1
A29: TOTAL | B29: =MAX(B5:B28) | C29: =SUM(C5:C28) | D29: =SUM(D5:D28) | E29: =SUM(E5:E28) | F29: =IF(C29=0,0,D29*1000000/C29) | G29: =IF(C29=0,0,E29*1000000/C29) | H29: =F29*G29/1000 | I29: =AVERAGE(I5:I28) | J29: =AVERAGE(J5:J28)
A31: Índice de frecuencia = accidentes incapacitantes x 1,000,000 / horas hombre trabajadas. Índice de gravedad = días perdidos x 1,000,000 / horas hombre trabajadas. Índice de accidentabilidad = IF x IG / 1,000. Horas hombre = trabajadores x 8 h x 26 días.

Sheet PARTIDAS
A1: PARTIDAS DEL PRESUPUESTO Y ACTIVIDADES EVALUADAS EN EL IPERC
A2: Trazabilidad entre el presupuesto y el IPERC
A4: CÓDIGO | B4: ACTIVIDAD DEL IPERC | C4: PARTIDAS DEL PRESUPUESTO
A5: GEN | B5: Trabajos generales a campo abierto | C5: Actividad transversal a toda la obra
A6: GEN-SEL | B6: Trabajos en zona de selva (fauna y vectores) | C6: Actividad transversal a toda la obra
A7: TRAS | B7: Traslado de personal y materiales en vehículos | C7: Actividad transversal a toda la obra
A8: CAMP | B8: Campamento, almacenes, comedor, servicios higiénicos y cartel de obra | C8: 5 partidas: 1.01.01 CAMPAMENTO Y ALMACENES OBRA; 1.01.02 CARTEL DE IDENTIFICACION DE OBRA (3.60mx4.80m); 1.04.05 HABILITACION DE ACCESO A CAMPAMENTO Y PATIO DE MAQUINAS; 1.04.06 HABILITACION DE CAMPAMENTO Y PATIO DE MAQUINAS; 1.11.07.01 READECUCACION DE AMBIENTES DE AREAS AUXILIARES (DME, PATIO DE MAQUINAS, CAMPAMENTO, OTROS)
A9: MOVI | B9: Movilización y desmovilización de equipos y fletes | C9: 2 partidas: 1.01.03 MOVLIZACION DE EQUIPO Y MAQUINARIA PESADA; 1.01.04 FLETE TERRESTRE DE MATERIALES
A10: TOPO | B10: Topografía, trazo, nivelación y replanteo | C10: 12 partidas: 1.04.01 TOPOGRAFIA Y GEORREFERENCIACION; 1.08.01.02 TRAZO Y REPLANTEO; 1.08.02.02 TRAZO Y REPLANTEO; 1.08.03.02 TRAZO Y REPLANTEO; 1.08.04.02 TRAZO Y REPLANTEO; 1.08.05.02 TRAZO Y REPLANTEO; 1.08.06.02 TRAZO Y REPLANTEO; 1.10.01.01.02 TRAZO Y REPLANTEO; 1.10.02.01.02 TRAZO Y REPLANTEO; 1.10.03.01.02 TRAZO Y REPLANTEO TOPOGRAFICO; 1.10.04.01.02 TRAZO Y REPLANTEO TOPOGRAFICO; 1.10.05.01.02 TRAZO Y REPLANTEO TOPOGRAFICO
A11: TRAN | B11: Mantenimiento del tránsito, desvíos y señalización temporal | C11: 10 partidas: 1.02.03 SEÑALIZACION TRANSITORIA DE SEGURIDAD EN OBRA; 1.04.02 MANTENIMIENTO DE TRANSITO TEMPORAL Y SEGURIDAD VIAL; 1.04.11 DESVIO TEMPORAL DURANTE EJECUCION; 1.10.01.01.06 DESVIO TEMPORAL DURANTE LA EJECUCION; 1.10.02.01.06 DESVIO TEMPORAL DURANTE LA EJECUCION; 1.10.03.01.05 DESVIO TEMPORAL DURANTE LA EJECUCION; 1.10.04.01.05 DESVIO TEMPORAL DURANTE LA EJECUCION; 1.10.05.01.05 DESVIO TEMPORAL DURANTE LA EJECUCION; 1.11.06.01 SEÑALES TEMPORALES; 1.11.06.02 POSTES PARA SEÑALES TEMPORALES
A12: DESB | B12: Desbroce, limpieza de terreno y tala de árboles | C12: 12 partidas: 1.05.01 DESBROCE Y LIMPIEZA DE TERRENO; 1.08.01.01 LIMPIEZA DEL TERRENO; 1.08.02.01 LIMPIEZA DEL TERRENO; 1.08.03.01 LIMPIEZA DEL TERRENO; 1.08.04.01 LIMPIEZA Y DESBROCE DE TERRENO; 1.08.05.01 LIMPIEZA DEL TERRENO; 1.08.06.01 LIMPIEZA DEL TERRENO; 1.10.01.01.01 LIMPIEZA DEL TERRENO; 1.10.02.01.01 LIMPIEZA DEL TERRENO; 1.10.03.01.01 LIMPIEZA Y DESBROCE DE TERRENO NATURAL; 1.10.04.01.01 LIMPIEZA Y DESBROCE DE TERRENO NATURAL; 1.10.05.01.01 LIMPIEZA Y DESBROCE DE TERRENO NATURAL
A13: DEMO | B13: Demolición de estructuras, escarificado y desmontaje | C13: 12 partidas: 1.03.01 DEMOLICION DE ALCANTARILLA TIPO TMC EXISTENTE; 1.03.02 ESCARIFICADO DE CARPETA ASFALTICA EXISTENTE; 1.03.03 DEMOLICION DE CUNETAS EXISTENTE; 1.03.04 DEMOLICION DE BADEN EXISTENTE; 1.03.05 ELIMINACION DEMOLICION; 1.10.01.01.03 DEMOLICION DE ESTRIBO Y VIGA LOSA EXISTENTE; 1.10.01.01.04 DESMONTAJE Y TRASLADO DE DE VIGAS METALICAS; 1.10.02.01.03 DEMOLICION DE ESTRIBO Y VIGA LOSA EXISTENTE; 1.10.02.01.04 DESMONTAJE Y TRASLADO DE DE VIGAS METALICAS; 1.10.03.01.03 DEMOLICION DE ESTRIBO Y VIGA LOSA EXISTENTE; 1.10.04.01.03 DEMOLICION DE ESTRIBO Y VIGA LOSA EXISTENTE; 1.10.05.01.03 DEMOLICION DE ESTRIBO Y VIGA LOSA EXISTENTE
A14: MTMQ | B14: Movimiento de tierras con maquinaria (corte, terraplén, eliminación, canteras y DME) | C14: 25 partidas: 1.03.05 ELIMINACION DEMOLICION; 1.04.03 HABILITACION DE ACCESO A DEPOSITO DE MATERIAL EXCEDENTE DME; 1.04.04 HABILITACION DE DEPOSITO DE MATERIAL EXCEDENTE DME; 1.04.05 HABILITACION DE ACCESO A CAMPAMENTO Y PATIO DE MAQUINAS; 1.04.07 HABILITACION DE ACCESO A CANTERA; 1.04.08 HABILITACION DE CANTERA DE RIO; 1.04.09 HABILITACION DE ACCESO A FUENTE DE AGUA; 1.05.02 CORTE EN ROCA FIJA; 1.05.03 CORTE EN ROCA SUELTA; 1.05.04 CORTE DE MATERIAL SUELTO; 1.05.05 CONFORMACION DE TERRAPLENES; 1.05.06 MEJORAMIENTO DE SUELOS A NIVEL DE SUB RASANTE C/MATERIAL DE PRESTAMO; 1.06.01.01 SUB-BASE GRANULAR; 1.06.01.02 BASE GRANULAR; 1.08.04.03 CORTE DE TERRENO C/MAQUINARIA PESADA; 1.08.04.11 EXTRACCION DE PIEDRAS CON EQUIPO; 1.08.04.12 APILAMIENTO DE MATERIAL COLMATADO; 1.08.04.14 CARGUIO Y TRANSPORTE; 1.10.01.02.11 ELIMINACION DE MATERIAL EXCEDENTE D<1 Km; 1.10.02.02.11 ELIMINACION DE MATERIAL EXCEDENTE D<1 Km; 1.10.03.02.01.04 ELIMINACION DE MATERIAL EXCEDENTE D<1 Km; 1.10.04.02.01.04 ELIMINACION DE MATERIAL EXCEDENTE D<1 Km; 1.10.05.02.01.04 ELIMINACION DE MATERIAL EXCEDENTE D<1 Km; 1.11.01.01 DEPOSITO DE MATERIAL EXCEDENTE (ACOMODO); 1.11.04.01 RIEGO PARA CONTROL DE MATERIAL PARTICULADO
A15: ROCA | B15: Corte en roca (martillo hidráulico o voladura controlada) | C15: 2 partidas: 1.05.02 CORTE EN ROCA FIJA; 1.05.03 CORTE EN ROCA SUELTA
... A32: AMBI | B32: Manejo de residuos, servicios higiénicos portátiles y revegetación | C32: 9 partidas: 1.11.02.01.02 ALMACENAMIENTO Y TRANSPORTE DE DE RESIDUOS SOLIDOS; 1.11.02.01.03 RECOJO Y TRANSPORTE ESPECIALIZADO DE RESIDUOS SOLIDOS; 1.11.02.02.02 DISPOSICION FINAL DE RESIDUOS PELIGROSOS; 1.11.02.03.01 ALQUILER DE LETRINAS PORTATILES; 1.11.03.01 REVEGATACION EN ZONAS DE ESTABILIZACION; 1.11.05.02 SEMBRIO DE PLANTONES; 1.11.07.01 READECUCACION DE AMBIENTES DE AREAS AUXILIARES (DME, PATIO DE MAQUINAS, CAMPAMENTO, OTROS); 1.11.11.01 SUMINISTRO, PREPARACION Y COLOCACION DE CAPA SUPERFICIAL DE SUELO; 1.11.11.02 REVEGETACION

Sheet EMERGENCIA
A1: DIRECTORIO DE EMERGENCIA
A2: Completar o confirmar los teléfonos locales antes del inicio de la obra
A4: INSTITUCIÓN | B4: UBICACIÓN | C4: TELÉFONO
A5: Central de emergencias de la Policía Nacional del Perú | B5: Nacional | C5: 105
A6: Cuerpo General de Bomberos Voluntarios del Perú | B6: Nacional | C6: 116
A7: SAMU - Sistema de Atención Móvil de Urgencias (MINSA) | B7: Nacional | C7: 106
A8: Establecimiento de salud de Shamboyacu (primer nivel de atención) | B8: Shamboyacu, al final del tramo
