Workbook

Sheet CARÁTULA
A1: GOBIERNO REGIONAL SAN MARTÍN
A2: GERENCIA TERRITORIAL BAJO MAYO - TARAPOTO
A4: SERVICIO DE DISEÑO - DRENAJE PLUVIAL
A5: “MEJORAMIENTO Y AMPLIACIÓN DEL SERVICIO DE EDUCACIÓN PRIMARIA EN I.E. N° 0590 DISTRITO DE BARRANQUITA DE LA PROVINCIA DE LAMAS DEL DEPARTAMENTO DE SAN MARTÍN”
A6: C.I. N° 468901
A9: Vista aérea del local de la I.E. N° 0590 - Barranquita
A11: ANÁLISIS ESTADÍSTICO
A12: PRECIPITACIÓN MÁXIMA EN 24 HORAS Y TORMENTA DE DISEÑO
A14: ESPECIALIDAD: INSTALACIONES SANITARIAS - DRENAJE PLUVIAL
A15: Distrito de Barranquita - Provincia de Lamas - Departamento de San Martín
A17: OCTUBRE 2026

Sheet A. Estación
B2: Proyecto | C2: “MEJORAMIENTO Y AMPLIACIÓN DEL SERVICIO DE EDUCACIÓN PRIMARIA EN I.E. N° 0590 DISTRITO DE BARRANQUITA DE LA PROVINCIA DE LAMAS DEL DEPARTAMENTO DE SAN MARTÍN”, con C.I. N.° 468901
B3: Entidad | C3: GOBIERNO REGIONAL SAN MARTIN - GERENCIA TERRITORIAL BAJO MAYO - TARAPOTO
B4: Ubicación | C4: SAN MARTIN - LAMAS - BARRANQUITA
B5: Fecha | C5: OCTUBRE 2026
B7: PARTE I : DETERMINACIÓN DE PRECIPITACIONES DE DISEÑO MÁXIMAS EN 24 HORAS
B9: REGISTRO DE PRECIPITACIONES MÁXIMAS EN 24 HORAS (mm) - PONGO DE CAYNARACHI
B11: Código | C11: 003317 | F11: Dpto. | G11: : SAN MARTIN
B12: Tipo | C12: Convencional | F12: Provincia | G12: : LAMAS
B13: Altura | C13: 230 msnm. | F13: Distrito | G13: : CAYNARACHI
B15: Precipitación Máxima en 24 Horas (mm) - periodo 1989–2013
B16: Año | C16: Enero | D16: Febrero | E16: Marzo | F16: Abril | G16: Mayo | H16: Junio | I16: Julio | J16: Agosto | K16: Setiembre | L16: Octubre | M16: Noviembre | N16: Diciembre | O16: P Máxima
A18: =O18 -> 141.9 | B18: 1989 | C18: 74.4 | D18: 82.7 | E18: 80.1 | F18: 61.9 | G18: 78.4 | H18: 77.5 | I18: 76.1 | J18: 58.1 | K18: 64.4 | L18: 141.9 | M18: 69.4 | N18: 46.9 | O18: =MAX(C18:N18) -> 141.9
A19: =O19 -> 115.1 | B19: 1990 | C19: 81.5 | D19: 97.9 | E19: 62.6 | F19: 78.8 | G19: 61.2 | H19: 56.2 | I19: 41.6 | J19: 49.5 | K19: 65.4 | L19: 57.4 | M19: 115.1 | N19: 74 | O19: =MAX(C19:N19) -> 115.1
A20: =O20 -> 114.8 | B20: 1991 | C20: 46.5 | D20: 53.7 | E20: 106.7 | F20: 56.6 | G20: 60.3 | H20: 83.4 | I20: 33.4 | J20: 32.5 | K20: 95.3 | L20: 55.3 | M20: 114.8 | N20: 88.4 | O20: =MAX(C20:N20) -> 114.8
A21: =O21 -> 123 | B21: 1992 | C21: 63.3 | D21: 37.3 | E21: 103.8 | F21: 123 | G21: 98.7 | H21: 30.5 | I21: 45.3 | J21: 70.7 | K21: 60.2 | L21: 77.5 | M21: 50 | N21: 120.4 | O21: =MAX(C21:N21) -> 123
A22: =O22 -> 89.1 | B22: 1993 | C22: 64.2 | D22: 89.1 | E22: 73.7 | F22: 62.5 | G22: 72.7 | H22: 76.1 | I22: 37.3 | J22: 32.1 | K22: 75.2 | L22: 64.9 | M22: 46.6 | N22: 74 | O22: =MAX(C22:N22) -> 89.1
A23: =O23 -> 179.9 | B23: 1994 | C23: 63.2 | D23: 64 | E23: 143.2 | F23: 84.5 | G23: 82.1 | H23: 53.4 | I23: 76 | J23: 81.5 | K23: 65.5 | L23: 110.1 | M23: 60 | N23: 179.9 | O23: =MAX(C23:N23) -> 179.9
A24: =O24 -> 84.2 | B24: 1995 | C24: 37 | D24: 74.3 | E24: 77.6 | F24: 50.9 | G24: 84.2 | H24: 29.2 | I24: 30 | J24: 81.2 | K24: 44.2 | L24: 57.1 | M24: 46.1 | N24: 73.5 | O24: =MAX(C24:N24) -> 84.2
A25: =O25 -> 96.4 | B25: 1996 | C25: 96.4 | D25: 50.7 | E25: 73.2 | F25: 35.1 | G25: 60.2 | H25: 39.5 | I25: 14.8 | J25: 73 | K25: 29.1 | L25: 80.9 | M25: 55.9 | N25: 76.8 | O25: =MAX(C25:N25) -> 96.4
A26: =O26 -> 103.9 | B26: 1997 | C26: 87.3 | D26: 70.1 | E26: 53.1 | F26: 71.2 | G26: 51.5 | H26: 41.9 | I26: 17 | J26: 40 | K26: 65.5 | L26: 97.3 | M26: 86.9 | N26: 103.9 | O26: =MAX(C26:N26) -> 103.9
A27: =O27 -> 171.8 | B27: 1998 | C27: 72.5 | D27: 78.2 | E27: 95.4 | F27: 78.9 | G27: 67.1 | H27: 72.2 | I27: 56.6 | J27: 22 | K27: 31.9 | L27: 76.3 | M27: 171.8 | N27: 79.7 | O27: =MAX(C27:N27) -> 171.8
A28: =O28 -> 146 | B28: 1999 | C28: 146 | D28: 122 | E28: 75 | F28: 40.7 | G28: 64 | H28: 70.2 | I28: 35.5 | J28: 27.8 | K28: 61.5 | L28: 40.1 | M28: 62.1 | N28: 56.9 | O28: =MAX(C28:N28) -> 146
A29: =O29 -> 108.5 | B29: 2000 | C29: 56.8 | D29: 101.7 | E29: 59.5 | F29: 97 | G29: 65.4 | H29: 75.9 | I29: 43.1 | J29: 31.1 | K29: 108.5 | L29: 71.3 | M29: 87.4 | N29: 70.4 | O29: =MAX(C29:N29) -> 108.5
... A33: =O33 -> 90.2 | B33: 2004 | C33: 47.4 | D33: 81.6 | E33: 76.3 | F33: 75.3 | G33: 87 | H33: 32.5 | I33: 44.4 | J33: 55.5 | K33: 44.3 | L33: 75.5 | M33: 90.2 | N33: 66.1 | O33: =MAX(C33:N33) -> 90.2
A34: =O34 -> 97.3 | B34: 2005 | C34: S/D | D34: 80.8 | E34: 76.7 | F34: 97.3 | G34: 45 | H34: 65.6 | I34: 17 | J34: 75.6 | K34: 23 | L34: 70.5 | M34: 77.3 | N34: 66.2 | O34: =MAX(C34:N34) -> 97.3
A35: =O35 -> 102.5 | B35: 2006 | C35: 80.7 | D35: 39.5 | E35: 81.5 | F35: 66.9 | G35: 48.7 | H35: 68 | I35: 35.8 | J35: 51 | K35: 52.7 | L35: 71.6 | M35: 72.2 | N35: 102.5 | O35: =MAX(C35:N35) -> 102.5
A36: =O36 -> 77.3 | B36: 2007 | C36: 56.2 | D36: 33.3 | E36: 74.6 | F36: 76.5 | G36: 39.2 | H36: 46.8 | I36: 58.7 | J36: 33 | K36: 47.5 | L36: 76 | M36: 77.3 | N36: 76.5 | O36: =MAX(C36:N36) -> 77.3
A37: =O37 -> 100.4 | B37: 2008 | C37: 57.8 | D37: 86.9 | E37: 74 | F37: 70.5 | G37: 67 | H37: 51 | I37: S/D | J37: 25.9 | K37: 48 | L37: 55.2 | M37: 43 | N37: 100.4 | O37: =MAX(C37:N37) -> 100.4
A38: =O38 -> 87 | B38: 2009 | C38: 87 | D38: 69.7 | E38: 58 | F38: 52.2 | G38: 70 | H38: 75.5 | I38: 77.2 | J38: 25.3 | K38: 70.4 | L38: 76.2 | M38: 59 | N38: 78.8 | O38: =MAX(C38:N38) -> 87
A39: =O39 -> 128 | B39: 2010 | C39: 40 | D39: 79 | E39: 69.2 | F39: 128 | G39: 103 | H39: 56.5 | I39: 56.5 | J39: 15.2 | K39: 36.5 | L39: 75.8 | M39: 80.8 | N39: 73.8 | O39: =MAX(C39:N39) -> 128
B40: 2011 | C40: 73.8 | D40: 76.3 | E40: 80.8 | F40: 60.7 | G40: 77.8 | H40: 67.3 | I40: 58.8 | J40: 57.3 | K40: 57 | L40: 70 | M40: 101 | N40: 77.6 | O40: =MAX(C40:N40) -> 101
B41: 2012 | C41: 110.2 | D41: 56.5 | E41: 58 | F41: 87.2 | G41: 77.6 | H41: 25.5 | I41: 51.2 | J41: 12.1 | K41: 48 | L41: 48.2 | M41: 72 | N41: 54.8 | O41: =MAX(C41:N41) -> 110.2
B42: 2013 | C42: 78.7 | D42: 76.4 | E42: 64.5 | F42: 62.5 | G42: 53.6 | H42: 74.5 | I42: 81.2 | J42: 64.9 | K42: 54.8 | L42: 76.8 | M42: 84 | N42: 30.7 | O42: =MAX(C42:N42) -> 84

Sheet B.Modelo Distribución
B2: Proyecto | C2: =+'A. Estación'!C2 -> “MEJORAMIENTO Y AMPLIACIÓN DEL SERVICIO DE EDUCACIÓN PRIMARIA EN I.E. N° 0590 DISTRITO DE BARRANQUITA DE LA PROVINCIA DE LAMAS DEL DEPARTAMENTO DE SAN MARTÍN”, con C.I. N.° 468901
B3: Entidad | C3: =+'A. Estación'!C3 -> GOBIERNO REGIONAL SAN MARTIN - GERENCIA TERRITORIAL BAJO MAYO - TARAPOTO
B4: Ubicación | C4: =+'A. Estación'!C4 -> SAN MARTIN - LAMAS - BARRANQUITA
B5: Fecha | C5: =+'A. Estación'!C5 -> OCTUBRE 2026
B7: B. MODELOS DE DISTRIBUCIÓN DE DATOS ESTADÍSTICOS DE PRECIPITACIÓN MÁXIMAS EXTREMAS EN 24 HORAS
B9: Precipitación Máxima Anual en mm | F9: B.1. Distribución Normal | L9: B.3. Distribución Log Pearson III
B10: Año | C10: P máx | D10: Log P | F10: T (años) | G10: P | H10: w | I10: z | J10: P máx (mm) | L10: T (años) | M10: P | N10: w | O10: z | P10: KT | Q10: Log P | R10: P máx (mm)
B11: 1989 | C11: ='A. Estación'!O18 -> 141.9 | D11: =LOG(C11) -> 2.1519824 | F11: 2 | G11: =1/F11 -> 0.5 | H11: =(LN(1/G11^2))^0.5 -> 1.17741 | I11: =+H11-(2.515517+0.802853*H11+0.010328*H11^2)/(1+1.432788*H11+0.189269*H11^2+0.001308*H11^3) -> -1.0100668e-07 | J11: =+$C$36+I11*$C$38 -> 110.308 | L11: 2 | M11: =1/L11 -> 0.5 | N11: =(LN(1/M11^2))^0.5 -> 1.17741 | O11: =+N11-(2.515517+0.802853*N11+0.010328*N11^2)/(1+1.432788*N11+0.189269*N11^2+0.001308*N11^3) -> -1.0100668e-07 | P11: =+O11+(O11^2-1)*$D$40+1/3*(O11^3-6*O11)*$D$40^2-(O11^2-1)*$D$40^3+O11*$D$40^4+1/3*$D$40^5 -> -0.11280209 | Q11: =+$D$36+P11*$D$38 -> 2.0194962 | R11: =10^Q11 -> 104.59145
B12: 1990 | C12: ='A. Estación'!O19 -> 115.1 | D12: =LOG(C12) -> 2.0610753 | F12: 5 | G12: =1/F12 -> 0.2 | H12: =(LN(1/G12^2))^0.5 -> 1.7941226 | I12: =+H12-(2.515517+0.802853*H12+0.010328*H12^2)/(1+1.432788*H12+0.189269*H12^2+0.001308*H12^3) -> 0.84145672 | J12: =+$C$36+I12*$C$38 -> 133.50054 | L12: 5 | M12: =1/L12 -> 0.2 | N12: =(LN(1/M12^2))^0.5 -> 1.7941226 | O12: =+N12-(2.515517+0.802853*N12+0.010328*N12^2)/(1+1.432788*N12+0.189269*N12^2+0.001308*N12^3) -> 0.84145672 | P12: =+O12+(O12^2-1)*$D$40+1/3*(O12^3-6*O12)*$D$40^2-(O12^2-1)*$D$40^3+O12*$D$40^4+1/3*$D$40^5 -> 0.78927989 | Q12: =+$D$36+P12*$D$38 -> 2.1103921 | R12: =10^Q12 -> 128.94132
B13: 1991 | C13: ='A. Estación'!O20 -> 114.8 | D13: =LOG(C13) -> 2.0599419 | F13: 10 | G13: =1/F13 -> 0.1 | H13: =(LN(1/G13^2))^0.5 -> 2.145966 | I13: =+H13-(2.515517+0.802853*H13+0.010328*H13^2)/(1+1.432788*H13+0.189269*H13^2+0.001308*H13^3) -> 1.2817288 | J13: =+$C$36+I13*$C$38 -> 145.63548 | L13: 10 | M13: =1/L13 -> 0.1 | N13: =(LN(1/M13^2))^0.5 -> 2.145966 | O13: =+N13-(2.515517+0.802853*N13+0.010328*N13^2)/(1+1.432788*N13+0.189269*N13^2+0.001308*N13^3) -> 1.2817288 | P13: =+O13+(O13^2-1)*$D$40+1/3*(O13^3-6*O13)*$D$40^2-(O13^2-1)*$D$40^3+O13*$D$40^4+1/3*$D$40^5 -> 1.3301493 | Q13: =+$D$36+P13*$D$38 -> 2.1648914 | R13: =10^Q13 -> 146.18116
B14: 1992 | C14: ='A. Estación'!O21 -> 123 | D14: =LOG(C14) -> 2.0899051 | F14: 20 | G14: =1/F14 -> 0.05 | H14: =(LN(1/G14^2))^0.5 -> 2.4477468 | I14: =+H14-(2.515517+0.802853*H14+0.010328*H14^2)/(1+1.432788*H14+0.189269*H14^2+0.001308*H14^3) -> 1.6452114 | J14: =+$C$36+I14*$C$38 -> 155.65392 | L14: 20 | M14: =1/L14 -> 0.05 | N14: =(LN(1/M14^2))^0.5 -> 2.4477468 | O14: =+N14-(2.515517+0.802853*N14+0.010328*N14^2)/(1+1.432788*N14+0.189269*N14^2+0.001308*N14^3) -> 1.6452114 | P14: =+O14+(O14^2-1)*$D$40+1/3*(O14^3-6*O14)*$D$40^2-(O14^2-1)*$D$40^3+O14*$D$40^4+1/3*$D$40^5 -> 1.8144355 | Q14: =+$D$36+P14*$D$38 -> 2.2136892 | R14: =10^Q14 -> 163.56456
B15: 1993 | C15: ='A. Estación'!O22 -> 89.1 | D15: =LOG(C15) -> 1.9498777 | F15: 25 | G15: =1/F15 -> 0.04 | H15: =(LN(1/G15^2))^0.5 -> 2.5372725 | I15: =+H15-(2.515517+0.802853*H15+0.010328*H15^2)/(1+1.432788*H15+0.189269*H15^2+0.001308*H15^3) -> 1.7510765 | J15: =+$C$36+I15*$C$38 -> 158.57181 | L15: 25 | M15: =1/L15 -> 0.04 | N15: =(LN(1/M15^2))^0.5 -> 2.5372725 | O15: =+N15-(2.515517+0.802853*N15+0.010328*N15^2)/(1+1.432788*N15+0.189269*N15^2+0.001308*N15^3) -> 1.7510765 | P15: =+O15+(O15^2-1)*$D$40+1/3*(O15^3-6*O15)*$D$40^2-(O15^2-1)*$D$40^3+O15*$D$40^4+1/3*$D$40^5 -> 1.9621023 | Q15: =+$D$36+P15*$D$38 -> 2.2285685 | R15: =10^Q15 -> 169.26551
B16: 1994 | C16: ='A. Estación'!O23 -> 179.9 | D16: =LOG(C16) -> 2.2550312 | F16: 50 | G16: =1/F16 -> 0.02 | H16: =(LN(1/G16^2))^0.5 -> 2.7971496 | I16: =+H16-(2.515517+0.802853*H16+0.010328*H16^2)/(1+1.432788*H16+0.189269*H16^2+0.001308*H16^3) -> 2.0541886 | J16: =+$C$36+I16*$C$38 -> 166.9263 | L16: 50 | M16: =1/L16 -> 0.02 | N16: =(LN(1/M16^2))^0.5 -> 2.7971496 | O16: =+N16-(2.515517+0.802853*N16+0.010328*N16^2)/(1+1.432788*N16+0.189269*N16^2+0.001308*N16^3) -> 2.0541886 | P16: =+O16+(O16^2-1)*$D$40+1/3*(O16^3-6*O16)*$D$40^2-(O16^2-1)*$D$40^3+O16*$D$40^4+1/3*$D$40^5 -> 2.4018277 | Q16: =+$D$36+P16*$D$38 -> 2.2728762 | R16: =10^Q16 -> 187.44603
B17: 1995 | C17: ='A. Estación'!O24 -> 84.2 | D17: =LOG(C17) -> 1.9253121 | F17: 100 | G17: =1/F17 -> 0.01 | H17: =(LN(1/G17^2))^0.5 -> 3.0348543 | I17: =+H17-(2.515517+0.802853*H17+0.010328*H17^2)/(1+1.432788*H17+0.189269*H17^2+0.001308*H17^3) -> 2.3267853 | J17: =+$C$36+I17*$C$38 -> 174.43971 | L17: 100 | M17: =1/L17 -> 0.01 | N17: =(LN(1/M17^2))^0.5 -> 3.0348543 | O17: =+N17-(2.515517+0.802853*N17+0.010328*N17^2)/(1+1.432788*N17+0.189269*N17^2+0.001308*N17^3) -> 2.3267853 | P17: =+O17+(O17^2-1)*$D$40+1/3*(O17^3-6*O17)*$D$40^2-(O17^2-1)*$D$40^3+O17*$D$40^4+1/3*$D$40^5 -> 2.8191791 | Q17: =+$D$36+P17*$D$38 -> 2.3149296 | R17: =10^Q17 -> 206.50452
B18: 1996 | C18: ='A. Estación'!O25 -> 96.4 | D18: =LOG(C18) -> 1.984077 | F18: 200 | G18: =1/F18 -> 0.005 | H18: =(LN(1/G18^2))^0.5 -> 3.2552473 | I18: =+H18-(2.515517+0.802853*H18+0.010328*H18^2)/(1+1.432788*H18+0.189269*H18^2+0.001308*H18^3) -> 2.5762361 | J18: =+$C$36+I18*$C$38 -> 181.31517 | L18: 200 | M18: =1/L18 -> 0.005 | N18: =(LN(1/M18^2))^0.5 -> 3.2552473 | O18: =+N18-(2.515517+0.802853*N18+0.010328*N18^2)/(1+1.432788*N18+0.189269*N18^2+0.001308*N18^3) -> 2.5762361 | P18: =+O18+(O18^2-1)*$D$40+1/3*(O18^3-6*O18)*$D$40^2-(O18^2-1)*$D$40^3+O18*$D$40^4+1/3*$D$40^5 -> 3.2197296 | Q18: =+$D$36+P18*$D$38 -> 2.35529 | R18: =10^Q18 -> 226.61569
B19: 1997 | C19: ='A. Estación'!O26 -> 103.9 | D19: =LOG(C19) -> 2.0166155 | F19: 500 | G19: =1/F19 -> 0.002 | H19: =(LN(1/G19^2))^0.5 -> 3.5255094 | I19: =+H19-(2.515517+0.802853*H19+0.010328*H19^2)/(1+1.432788*H19+0.189269*H19^2+0.001308*H19^3) -> 2.8785061 | J19: =+$C$36+I19*$C$38 -> 189.64644 | L19: 500 | M19: =1/L19 -> 0.002 | N19: =(LN(1/M19^2))^0.5 -> 3.5255094 | O19: =+N19-(2.515517+0.802853*N19+0.010328*N19^2)/(1+1.432788*N19+0.189269*N19^2+0.001308*N19^3) -> 2.8785061 | P19: =+O19+(O19^2-1)*$D$40+1/3*(O19^3-6*O19)*$D$40^2-(O19^2-1)*$D$40^3+O19*$D$40^4+1/3*$D$40^5 -> 3.7295581 | Q19: =+$D$36+P19*$D$38 -> 2.4066615 | R19: =10^Q19 -> 255.07124
B20: 1998 | C20: ='A. Estación'!O27 -> 171.8 | D20: =LOG(C20) -> 2.2350232
B21: 1999 | C21: ='A. Estación'!O28 -> 146 | D21: =LOG(C21) -> 2.1643529
B22: 2000 | C22: ='A. Estación'!O29 -> 108.5 | D22: =LOG(C22) -> 2.0354297
B23: 2001 | C23: ='A. Estación'!O30 -> 78 | D23: =LOG(C23) -> 1.8920946
B24: 2002 | C24: ='A. Estación'!O31 -> 88.7 | D24: =LOG(C24) -> 1.9479236
B25: 2003 | C25: ='A. Estación'!O32 -> 138.5 | D25: =LOG(C25) -> 2.1414498
B26: 2004 | C26: ='A. Estación'!O33 -> 90.2 | D26: =LOG(C26) -> 1.9552065
B27: 2005 | C27: ='A. Estación'!O34 -> 97.3 | D27: =LOG(C27) -> 1.9881128
B28: 2006 | C28: ='A. Estación'!O35 -> 102.5 | D28: =LOG(C28) -> 2.0107239
B29: 2007 | C29: ='A. Estación'!O36 -> 77.3 | D29: =LOG(C29) -> 1.8881795
B30: 2008 | C30: ='A. Estación'!O37 -> 100.4 | D30: =LOG(C30) -> 2.0017337
B31: 2009 | C31: ='A. Estación'!O38 -> 87 | D31: =LOG(C31) -> 1.9395193
... B35: 2013 | C35: ='A. Estación'!O42 -> 84 | D35: =LOG(C35) -> 1.9242793
B36: m (media) | C36: =AVERAGE(C11:C35) -> 110.308 | D36: =AVERAGE(D11:D35) -> 2.0308624
B37: var (varianza) | C37: =+C38^2 -> 759.6841 | D37: =+D38^2 -> 0.010153054
B38: s (desv.Est) | C38: =STDEV(C11:C35) -> 27.562367 | D38: =STDEV(D11:D35) -> 0.10076237
B39: Coef. Asimetría | C39: =SKEW(C11:C35) -> 1.1317058 | D39: =SKEW(D11:D35) -> 0.685811
B40: k (Factor k) | D40: =+D39/6 -> 0.11430183
B41: n ( n°de datos) | C41: =COUNT(C11:C35) -> 25 | D41: =COUNT(D11:D35) -> 25
C44: B.4. Distribución Extrema Tipo I - Gumbel
C45: T (años) | D45: KT | E45: P máx (mm)
C46: 2 | D46: =-SQRT(6)/PI()*(0.5772+LN(LN(C46/(C46-1)))) -> -0.16427204 | E46: =$C$36+D46*$C$38 -> 105.78027
C47: 5 | D47: =-SQRT(6)/PI()*(0.5772+LN(LN(C47/(C47-1)))) -> 0.71945742 | E47: =$C$36+D47*$C$38 -> 130.13795
C48: 10 | D48: =-SQRT(6)/PI()*(0.5772+LN(LN(C48/(C48-1)))) -> 1.3045632 | E48: =$C$36+D48*$C$38 -> 146.26485
...

Sheet C. Prueba Kolmorov-Smirnov
B2: Proyecto | C2: ='A. Estación'!C2:O2 -> “MEJORAMIENTO Y AMPLIACIÓN DEL SERVICIO DE EDUCACIÓN PRIMARIA EN I.E. N° 0590 DISTRITO DE BARRANQUITA DE LA PROVINCIA DE LAMAS DEL DEPARTAMENTO DE SAN MARTÍN”, con C.I. N.° 468901
B3: Entidad | C3: ='A. Estación'!C3:O3 -> GOBIERNO REGIONAL SAN MARTIN - GERENCIA TERRITORIAL BAJO MAYO - TARAPOTO
B4: Ubicación | C4: ='A. Estación'!C4:O4 -> SAN MARTIN - LAMAS - BARRANQUITA
B5: Fecha | C5: ='A. Estación'!C5:O5 -> OCTUBRE 2026
B7: C. PRUEBA DE BONDAD DE KOLMOGOROV - SMIRNOV | AB7: Aparicio pag. 264
AB8: tabla para distribución Gumbel.
F9: X | K9: log X | P9: ln X | V9: X | AB9: n | AC9: my | AD9: sy
C10: Numero de datos n : | F10: =+'B.Modelo Distribución'!C41 -> 25 | H10: Numero de datos n : | K10: =+'B.Modelo Distribución'!C41 -> 25 | L10: Numero de datos n : | P10: =K10 -> 25 | R10: Numero de datos n : | V10: =P10 -> 25 | AB10: 10 | AC10: 0.4952 | AD10: 0.9496
C11: Promedio x : | F11: =AVERAGE(C22:C46) -> 110.308 | H11: Promedio Log x : | K11: =AVERAGE(D22:D46) -> 2.0308624 | L11: Promedio x : | P11: =AVERAGE(N22:N46) -> 4.6762335 | R11: Promedio x : | V11: =F11 -> 110.308 | AB11: 15 | AC11: 0.5128 | AD11: 1.0206
C12: Desviacion estándar s : | F12: =STDEV(C22:C46) -> 27.562367 | H12: Desviacion estándar s : | K12: =STDEV(D22:D46) -> 0.10076237 | L12: Desviacion estándar s : | P12: =STDEV(N22:N46) -> 0.23201392 | R12: Desviacion estándar s : | V12: =F12 -> 27.562367 | AB12: 20 | AC12: 0.5236 | AD12: 1.0628
C13: Coeficiente asimetria Cs (sesgo): | F13: =SKEW(C22:C46) -> 1.1317058 | H13: Coeficiente asimetría Cs (sesgo): | K13: =SKEW(D22:D46) -> 0.685811 | L13: Coeficiente asimetria Cs (sesgo): | P13: =SKEW(N22:N46) -> 0.685811 | R13: Coeficiente asimetria Cs (sesgo): | V13: =F13 -> 1.1317058 | AB13: 25 | AC13: 0.5309 | AD13: 1.0914
C14: k = Cs/6 : | F14: =F13/6 -> 0.18861763 | O14: k = Cs/6 : | P14: =P13/6 -> 0.11430183 | AB14: 30 | AC14: 0.5362 | AD14: 1.1124
C15: β1=(2/Cs)2: | F15: =(2/F13)^2 -> 3.1231507 | O15: β1=(2/Cs)2: | P15: =(2/P13)^2 -> 8.5045452 | AB15: 90 | AC15: 0.5586 | AD15: 1.2007
C16: α1=S/√β1 | F16: =F12/SQRT(F15) -> 15.596245 | O16: α1=S/√β1 | P16: =P12/SQRT(P15) -> 0.07955885 | U16: µY : | V16: =FORECAST(V10,$AC$13:$AC$14,$AB$13:$AB$14) -> 0.5309 | W16: media de datos | AB16: 95 | AC16: 0.5593 | AD16: 1.2037
C17: δ1=X-α1β1 | F17: =F11-F16*F15 -> 61.598576 | O17: δ1=X-α1β1 | P17: =P11-P16*P15 -> 3.9996216 | U17: sY : | V17: =FORECAST(V10,$AD$13:$AD$14,$AB$13:$AB$14) -> 1.0914 | AB17: xe =b-1/a ln ln (T/(T-1)
B20: N | C20: P = x | D20: P = LOG x | E20: P(X≥xT)OBS | F20: Distribución Normal | J20: Distribución Log Normal | N20: Distribución Log Pearson Tipo III | V20: Distribución Gumbel
D21: P = LOG x | F21: z | G21: F(Z) | H21: P(X≥xT)TEO | I21: D(N) | J21: z | K21: F(Z) | L21: P(X≥xT)TEO | M21: D(N) | N21: LnP | O21: Y=(x-δ1)/α1 | P21: 2Y | Q21: 2β1 | R21: χ2 | S21: Fx | T21: Fo | U21: D(N) | V21: P = x | W21: K | X21: Y | Y21: P(X≥xT)TEO | Z21: D(N)
B22: 1 | C22: =LARGE('A. Estación'!$O$18:$O$42,B22) -> 179.9 | D22: =LOG(C22) -> 2.2550312 | E22: =B22/(F$10+1) -> 0.038461538 | F22: =(C22-F$11)/F$12 -> 2.524892 | G22: =NORMSDIST(F22) -> 0.99421331 | H22: =1-G22 -> 0.0057866932 | I22: =ABS(H22-E22) -> 0.032674845 | J22: =(D22-K$11)/K$12 -> 2.2247271 | K22: =NORMSDIST(J22) -> 0.98695022 | L22: =1-K22 -> 0.013049782 | M22: =ABS(L22-E22) -> 0.025411756 | N22: =LN(C22) -> 5.1924011 | O22: =(N22-$P$17)/$P$16 -> 14.992417 | P22: =2*O22 -> 29.984835 | Q22: =2*$P$15 -> 17.00909 | R22: =CHIDIST(P22,Q22) -> 0.026454653 | S22: =R22 -> 0.026454653 | T22: =(B22/($P$10+1)) -> 0.038461538 | U22: =ABS(T22-S22) -> 0.012006886 | V22: =C22 -> 179.9 | W22: =(C22-V$11)/V$12 -> 2.524892 | X22: =W22*V$17+V$16 -> 3.2865671 | Y22: =1-EXP(-EXP(-X22)) -> 0.036691879 | Z22: =ABS(Y22-E22) -> 0.0017696599
B23: =+B22+1 -> 2 | C23: =LARGE('A. Estación'!$O$18:$O$42,B23) -> 171.8 | D23: =LOG(C23) -> 2.2350232 | E23: =B23/(F$10+1) -> 0.076923077 | F23: =(C23-F$11)/F$12 -> 2.231013 | G23: =NORMSDIST(F23) -> 0.98715987 | H23: =1-G23 -> 0.012840134 | I23: =ABS(H23-E23) -> 0.064082943 | J23: =(D23-K$11)/K$12 -> 2.0261609 | K23: =NORMSDIST(J23) -> 0.97862585 | L23: =1-K23 -> 0.021374152 | M23: =ABS(L23-E23) -> 0.055548925 | N23: =LN(C23) -> 5.146331 | O23: =(N23-$P$17)/$P$16 -> 14.413348 | P23: =2*O23 -> 28.826695 | Q23: =2*$P$15 -> 17.00909 | R23: =CHIDIST(P23,Q23) -> 0.036157938 | S23: =R23 -> 0.036157938 | T23: =(B23/($P$10+1)) -> 0.076923077 | U23: =ABS(T23-S23) -> 0.040765139 | V23: =C23 -> 171.8 | W23: =(C23-V$11)/V$12 -> 2.231013 | X23: =W23*V$17+V$16 -> 2.9658276 | Y23: =1-EXP(-EXP(-X23)) -> 0.050213272 | Z23: =ABS(Y23-E23) -> 0.026709805
B24: =+B23+1 -> 3 | C24: =LARGE('A. Estación'!$O$18:$O$42,B24) -> 146 | D24: =LOG(C24) -> 2.1643529 | E24: =B24/(F$10+1) -> 0.11538462 | F24: =(C24-F$11)/F$12 -> 1.2949541 | G24: =NORMSDIST(F24) -> 0.90233196 | H24: =1-G24 -> 0.097668037 | I24: =ABS(H24-E24) -> 0.017716579 | J24: =(D24-K$11)/K$12 -> 1.3248047 | K24: =NORMSDIST(J24) -> 0.90738204 | L24: =1-K24 -> 0.092617964 | M24: =ABS(L24-E24) -> 0.022766651 | N24: =LN(C24) -> 4.9836066 | O24: =(N24-$P$17)/$P$16 -> 12.368014 | P24: =2*O24 -> 24.736028 | Q24: =2*$P$15 -> 17.00909 | R24: =CHIDIST(P24,Q24) -> 0.100776 | S24: =R24 -> 0.100776 | T24: =(B24/($P$10+1)) -> 0.11538462 | U24: =ABS(T24-S24) -> 0.014608612 | V24: =C24 -> 146 | W24: =(C24-V$11)/V$12 -> 1.2949541 | X24: =W24*V$17+V$16 -> 1.9442129 | Y24: =1-EXP(-EXP(-X24)) -> 0.13333244 | Z24: =ABS(Y24-E24) -> 0.017947828
B25: =+B24+1 -> 4 | C25: =LARGE('A. Estación'!$O$18:$O$42,B25) -> 141.9 | D25: =LOG(C25) -> 2.1519824 | E25: =B25/(F$10+1) -> 0.15384615 | F25: =(C25-F$11)/F$12 -> 1.1462005 | G25: =NORMSDIST(F25) -> 0.8741439 | H25: =1-G25 -> 0.1258561 | I25: =ABS(H25-E25) -> 0.027990058 | J25: =(D25-K$11)/K$12 -> 1.2020361 | K25: =NORMSDIST(J25) -> 0.88532522 | L25: =1-K25 -> 0.11467478 | M25: =ABS(L25-E25) -> 0.039171376 | N25: =LN(C25) -> 4.9551226 | O25: =(N25-$P$17)/$P$16 -> 12.009989 | P25: =2*O25 -> 24.019979 | Q25: =2*$P$15 -> 17.00909 | R25: =CHIDIST(P25,Q25) -> 0.11889315 | S25: =R25 -> 0.11889315 | T25: =(B25/($P$10+1)) -> 0.15384615 | U25: =ABS(T25-S25) -> 0.034953002 | V25: =C25 -> 141.9 | W25: =(C25-V$11)/V$12 -> 1.1462005 | X25: =W25*V$17+V$16 -> 1.7818633 | Y25: =1-EXP(-EXP(-X25)) -> 0.15492021 | Z25: =ABS(Y25-E25) -> 0.0010740516
B26: =+B25+1 -> 5 | C26: =LARGE('A. Estación'!$O$18:$O$42,B26) -> 138.5 | D26: =LOG(C26) -> 2.1414498 | E26: =B26/(F$10+1) -> 0.19230769 | F26: =(C26-F$11)/F$12 -> 1.0228439 | G26: =NORMSDIST(F26) -> 0.84680918 | H26: =1-G26 -> 0.15319082 | I26: =ABS(H26-E26) -> 0.039116868 | J26: =(D26-K$11)/K$12 -> 1.0975067 | K26: =NORMSDIST(J26) -> 0.86379003 | L26: =1-K26 -> 0.13620997 | M26: =ABS(L26-E26) -> 0.056097724 | N26: =LN(C26) -> 4.9308703 | O26: =(N26-$P$17)/$P$16 -> 11.705155 | P26: =2*O26 -> 23.41031 | Q26: =2*$P$15 -> 17.00909 | R26: =CHIDIST(P26,Q26) -> 0.13636332 | S26: =R26 -> 0.13636332 | T26: =(B26/($P$10+1)) -> 0.19230769 | U26: =ABS(T26-S26) -> 0.055944373 | V26: =C26 -> 138.5 | W26: =(C26-V$11)/V$12 -> 1.0228439 | X26: =W26*V$17+V$16 -> 1.6472319 | Y26: =1-EXP(-EXP(-X26)) -> 0.17517354 | Z26: =ABS(Y26-E26) -> 0.017134152
B27: =+B26+1 -> 6 | C27: =LARGE('A. Estación'!$O$18:$O$42,B27) -> 128 | D27: =LOG(C27) -> 2.10721 | E27: =B27/(F$10+1) -> 0.23076923 | F27: =(C27-F$11)/F$12 -> 0.64188971 | G27: =NORMSDIST(F27) -> 0.7395276 | H27: =1-G27 -> 0.2604724 | I27: =ABS(H27-E27) -> 0.029703168 | J27: =(D27-K$11)/K$12 -> 0.75769928 | K27: =NORMSDIST(J27) -> 0.77568448 | L27: =1-K27 -> 0.22431552 | M27: =ABS(L27-E27) -> 0.0064537156 | N27: =LN(C27) -> 4.8520303 | O27: =(N27-$P$17)/$P$16 -> 10.71419 | P27: =2*O27 -> 21.42838 | Q27: =2*$P$15 -> 17.00909 | R27: =CHIDIST(P27,Q27) -> 0.20771262 | S27: =R27 -> 0.20771262 | T27: =(B27/($P$10+1)) -> 0.23076923 | U27: =ABS(T27-S27) -> 0.023056607 | V27: =C27 -> 128 | W27: =(C27-V$11)/V$12 -> 0.64188971 | X27: =W27*V$17+V$16 -> 1.2314584 | Y27: =1-EXP(-EXP(-X27)) -> 0.25313184 | Z27: =ABS(Y27-E27) -> 0.022362608
B28: =+B27+1 -> 7 | C28: =LARGE('A. Estación'!$O$18:$O$42,B28) -> 123 | D28: =LOG(C28) -> 2.0899051 | E28: =B28/(F$10+1) -> 0.26923077 | F28: =(C28-F$11)/F$12 -> 0.46048294 | G28: =NORMSDIST(F28) -> 0.67741519 | H28: =1-G28 -> 0.32258481 | I28: =ABS(H28-E28) -> 0.053354038 | J28: =(D28-K$11)/K$12 -> 0.58595998 | K28: =NORMSDIST(J28) -> 0.7210488 | L28: =1-K28 -> 0.2789512 | M28: =ABS(L28-E28) -> 0.0097204352 | N28: =LN(C28) -> 4.8121844 | O28: =(N28-$P$17)/$P$16 -> 10.213354 | P28: =2*O28 -> 20.426708 | Q28: =2*$P$15 -> 17.00909 | R28: =CHIDIST(P28,Q28) -> 0.25298753 | S28: =R28 -> 0.25298753 | T28: =(B28/($P$10+1)) -> 0.26923077 | U28: =ABS(T28-S28) -> 0.016243244 | V28: =C28 -> 123 | W28: =(C28-V$11)/V$12 -> 0.46048294 | X28: =W28*V$17+V$16 -> 1.0334711 | Y28: =1-EXP(-EXP(-X28)) -> 0.29936619 | Z28: =ABS(Y28-E28) -> 0.030135419
B29: =+B28+1 -> 8 | C29: =LARGE('A. Estación'!$O$18:$O$42,B29) -> 115.1 | D29: =LOG(C29) -> 2.0610753 | E29: =B29/(F$10+1) -> 0.30769231 | F29: =(C29-F$11)/F$12 -> 0.17386025 | G29: =NORMSDIST(F29) -> 0.56901235 | H29: =1-G29 -> 0.43098765 | I29: =ABS(H29-E29) -> 0.12329534 | J29: =(D29-K$11)/K$12 -> 0.29984336 | K29: =NORMSDIST(J29) -> 0.61785168 | L29: =1-K29 -> 0.38214832 | M29: =ABS(L29-E29) -> 0.074456013 | N29: =LN(C29) -> 4.7458013 | O29: =(N29-$P$17)/$P$16 -> 9.378965 | P29: =2*O29 -> 18.75793 | Q29: =2*$P$15 -> 17.00909 | R29: =CHIDIST(P29,Q29) -> 0.34260242 | S29: =R29 -> 0.34260242 | T29: =(B29/($P$10+1)) -> 0.30769231 | U29: =ABS(T29-S29) -> 0.034910112 | V29: =C29 -> 115.1 | W29: =(C29-V$11)/V$12 -> 0.17386025 | X29: =W29*V$17+V$16 -> 0.72065107 | Y29: =1-EXP(-EXP(-X29)) -> 0.38518597 | Z29: =ABS(Y29-E29) -> 0.077493663
B30: =+B29+1 -> 9 | C30: =LARGE('A. Estación'!$O$18:$O$42,B30) -> 114.8 | D30: =LOG(C30) -> 2.0599419 | E30: =B30/(F$10+1) -> 0.34615385 | F30: =(C30-F$11)/F$12 -> 0.16297584 | G30: =NORMSDIST(F30) -> 0.56473127 | H30: =1-G30 -> 0.43526873 | I30: =ABS(H30-E30) -> 0.089114882 | J30: =(D30-K$11)/K$12 -> 0.28859476 | K30: =NORMSDIST(J30) -> 0.61355425 | L30: =1-K30 -> 0.38644575 | M30: =ABS(L30-E30) -> 0.040291908 | N30: =LN(C30) -> 4.7431915 | O30: =(N30-$P$17)/$P$16 -> 9.3461612 | P30: =2*O30 -> 18.692322 | Q30: =2*$P$15 -> 17.00909 | R30: =CHIDIST(P30,Q30) -> 0.34647571 | S30: =R30 -> 0.34647571 | T30: =(B30/($P$10+1)) -> 0.34615385 | U30: =ABS(T30-S30) -> 0.00032186564 | V30: =C30 -> 114.8 | W30: =(C30-V$11)/V$12 -> 0.16297584 | X30: =W30*V$17+V$16 -> 0.70877183 | Y30: =1-EXP(-EXP(-X30)) -> 0.38874948 | Z30: =ABS(Y30-E30) -> 0.042595635
B31: =+B30+1 -> 10 | C31: =LARGE('A. Estación'!$O$18:$O$42,B31) -> 110.2 | D31: =LOG(C31) -> 2.0421816 | E31: =B31/(F$10+1) -> 0.38461538 | F31: =(C31-F$11)/F$12 -> -0.0039183862 | G31: =NORMSDIST(F31) -> 0.49843679 | H31: =1-G31 -> 0.50156321 | I31: =ABS(H31-E31) -> 0.11694782 | J31: =(D31-K$11)/K$12 -> 0.11233556 | K31: =NORMSDIST(J31) -> 0.54472133 | L31: =1-K31 -> 0.45527867 | M31: =ABS(L31-E31) -> 0.070663288 | N31: =LN(C31) -> 4.7022969 | O31: =(N31-$P$17)/$P$16 -> 8.8321444 | P31: =2*O31 -> 17.664289 | Q31: =2*$P$15 -> 17.00909 | R31: =CHIDIST(P31,Q31) -> 0.41030966 | S31: =R31 -> 0.41030966 | T31: =(B31/($P$10+1)) -> 0.38461538 | U31: =ABS(T31-S31) -> 0.025694275 | V31: =C31 -> 110.2 | W31: =(C31-V$11)/V$12 -> -0.0039183862 | X31: =W31*V$17+V$16 -> 0.52662347 | Y31: =1-EXP(-EXP(-X31)) -> 0.44600287 | Z31: =ABS(Y31-E31) -> 0.061387483
B32: =+B31+1 -> 11 | C32: =LARGE('A. Estación'!$O$18:$O$42,B32) -> 108.5 | D32: =LOG(C32) -> 2.0354297 | E32: =B32/(F$10+1) -> 0.42307692 | F32: =(C32-F$11)/F$12 -> -0.065596687 | G32: =NORMSDIST(F32) -> 0.47384946 | H32: =1-G32 -> 0.52615054 | I32: =ABS(H32-E32) -> 0.10307361 | J32: =(D32-K$11)/K$12 -> 0.045327844 | K32: =NORMSDIST(J32) -> 0.518077 | L32: =1-K32 -> 0.481923 | M32: =ABS(L32-E32) -> 0.058846074 | N32: =LN(C32) -> 4.6867502 | O32: =(N32-$P$17)/$P$16 -> 8.6367328 | P32: =2*O32 -> 17.273466 | Q32: =2*$P$15 -> 17.00909 | R32: =CHIDIST(P32,Q32) -> 0.43599268 | S32: =R32 -> 0.43599268 | T32: =(B32/($P$10+1)) -> 0.42307692 | U32: =ABS(T32-S32) -> 0.012915761 | V32: =C32 -> 108.5 | W32: =(C32-V$11)/V$12 -> -0.065596687 | X32: =W32*V$17+V$16 -> 0.45930778 | Y32: =1-EXP(-EXP(-X32)) -> 0.46832389 | Z32: =ABS(Y32-E32) -> 0.045246965
B33: =+B32+1 -> 12 | C33: =LARGE('A. Estación'!$O$18:$O$42,B33) -> 103.9 | D33: =LOG(C33) -> 2.0166155 | E33: =B33/(F$10+1) -> 0.46153846 | F33: =(C33-F$11)/F$12 -> -0.23249091 | G33: =NORMSDIST(F33) -> 0.40807837 | H33: =1-G33 -> 0.59192163 | I33: =ABS(H33-E33) -> 0.13038317 | J33: =(D33-K$11)/K$12 -> -0.14139058 | K33: =NORMSDIST(J33) -> 0.4437807 | L33: =1-K33 -> 0.5562193 | M33: =ABS(L33-E33) -> 0.094680842 | N33: =LN(C33) -> 4.6434289 | O33: =(N33-$P$17)/$P$16 -> 8.0922142 | P33: =2*O33 -> 16.184428 | Q33: =2*$P$15 -> 17.00909 | R33: =CHIDIST(P33,Q33) -> 0.51080025 | S33: =R33 -> 0.51080025 | T33: =(B33/($P$10+1)) -> 0.46153846 | U33: =ABS(T33-S33) -> 0.049261793 | V33: =C33 -> 103.9 | W33: =(C33-V$11)/V$12 -> -0.23249091 | X33: =W33*V$17+V$16 -> 0.27715942 | Y33: =1-EXP(-EXP(-X33)) -> 0.53136622 | Z33: =ABS(Y33-E33) -> 0.069827755
B34: =+B33+1 -> 13 | C34: =LARGE('A. Estación'!$O$18:$O$42,B34) -> 102.5 | D34: =LOG(C34) -> 2.0107239 | E34: =B34/(F$10+1) -> 0.5 | F34: =(C34-F$11)/F$12 -> -0.28328481 | G34: =NORMSDIST(F34) -> 0.38847926 | H34: =1-G34 -> 0.61152074 | I34: =ABS(H34-E34) -> 0.11152074 | J34: =(D34-K$11)/K$12 -> -0.19986164 | K34: =NORMSDIST(J34) -> 0.42079439 | L34: =1-K34 -> 0.57920561 | M34: =ABS(L34-E34) -> 0.079205605 | N34: =LN(C34) -> 4.6298628 | O34: =(N34-$P$17)/$P$16 -> 7.9216976 | P34: =2*O34 -> 15.843395 | Q34: =2*$P$15 -> 17.00909 | R34: =CHIDIST(P34,Q34) -> 0.53496276 | S34: =R34 -> 0.53496276 | T34: =(B34/($P$10+1)) -> 0.5 | U34: =ABS(T34-S34) -> 0.034962761 | V34: =C34 -> 102.5 | W34: =(C34-V$11)/V$12 -> -0.28328481 | X34: =W34*V$17+V$16 -> 0.22172296 | Y34: =1-EXP(-EXP(-X34)) -> 0.55118176 | Z34: =ABS(Y34-E34) -> 0.051181759
... B46: =+B45+1 -> 25 | C46: =LARGE('A. Estación'!$O$18:$O$42,B46) -> 77.3 | D46: =LOG(C46) -> 1.8881795 | E46: =B46/(F$10+1) -> 0.96153846 | F46: =(C46-F$11)/F$12 -> -1.1975749 | G46: =NORMSDIST(F46) -> 0.11554127 | H46: =1-G46 -> 0.88445873 | I46: =ABS(H46-E46) -> 0.077079734 | J46: =(D46-K$11)/K$12 -> -1.4160337 | K46: =NORMSDIST(J46) -> 0.078382823 | L46: =1-K46 -> 0.92161718 | M46: =ABS(L46-E46) -> 0.039921284 | N46: =LN(C46) -> 4.347694 | O46: =(N46-$P$17)/$P$16 -> 4.3750294 | P46: =2*O46 -> 8.7500589 | Q46: =2*$P$15 -> 17.00909 | R46: =CHIDIST(P46,Q46) -> 0.94777804 | S46: =R46 -> 0.94777804 | T46: =(B46/($P$10+1)) -> 0.96153846 | U46: =ABS(T46-S46) -> 0.013760417 | V46: =C46 -> 77.3 | W46: =(C46-V$11)/V$12 -> -1.1975749 | X46: =W46*V$17+V$16 -> -0.77613327 | Y46: =1-EXP(-EXP(-X46)) -> 0.88617048 | Z46: =ABS(Y46-E46) -> 0.075367982
H47: MAX. | I47: =MAX(I22:I46) -> 0.13038317 | L47: MAX. | M47: =MAX(M22:M46) -> 0.094680842 | T47: MAX. | U47: =MAX(U22:U46) -> 0.068283955 | Y47: MAX. | Z47: =MAX(Z22:Z46) -> 0.077493663
B49: RESUMEN DE RESULTADOS | AB49: =M47 -> 0.094680842 | AC49: =+IFERROR(AB49,"") -> 0.094680842 | AD49: =E51 -> Log - Normal
B50: Estadístico | D50: Función de Distribución | O50: n : | P50: =+F10 -> 25
B51: K-S | D51: Normal | E51: Log - Normal | G51: Log Pearson Tipo III | I51: Gumbel | O51: a : | P51: 0.05 | AB51: =U47 -> 0.068283955 | AC51: =+IFERROR(AB51,"") -> 0.068283955 | AD51: =G51 -> Log Pearson Tipo III
B52: D(N) | D52: =+I47 -> 0.13038317 | E52: =+AC49 -> 0.094680842 | G52: =+IFERROR(U47,"No se ajusta a la distribución Log-Pearson Tipo 3") -> 0.068283955 | I52: =+AC52 -> 0.077493663 | O52: Máximo tabular: | P52: =+(-LN($P$51/2)/2/$P$50)^0.5-1/6/$P$50 -> 0.26495364 | AB52: =Z47 -> 0.077493663 | AC52: =+IFERROR(AB52,"") -> 0.077493663 | AD52: =I51 -> Gumbel
P53: D(N) < Dα
F54: FUNCION DE DISTRIBUCION SELECCIONADA : | G54: =AC56 -> Log Pearson Tipo III
AB55: MINIMO | AC55: =MIN(AC47:AC52) -> 0.068283955
AB56: DISTRIBUCIÓN | AC56: =VLOOKUP(AC55,AC47:AE52,2,FALSE()) -> Log Pearson Tipo III

Sheet D.Resumen
B2: Proyecto | C2: ='A. Estación'!C2:O2 -> “MEJORAMIENTO Y AMPLIACIÓN DEL SERVICIO DE EDUCACIÓN PRIMARIA EN I.E. N° 0590 DISTRITO DE BARRANQUITA DE LA PROVINCIA DE LAMAS DEL DEPARTAMENTO DE SAN MARTÍN”, con C.I. N.° 468901
B3: Entidad | C3: ='A. Estación'!C3:O3 -> GOBIERNO REGIONAL SAN MARTIN - GERENCIA TERRITORIAL BAJO MAYO - TARAPOTO
B4: Ubicación | C4: ='A. Estación'!C4:O4 -> SAN MARTIN - LAMAS - BARRANQUITA
B5: Fecha | C5: ='A. Estación'!C5:O5 -> OCTUBRE 2026
B7: C.4 RESUMEN DE LOS RESULTADOS DE LAS DISTRIBUCIONES ESTADISTICAS
B9: Normales | E9: Valor | G9: T (años) | H9: Normal | I9: Log Normal | J9: Log Pearson III | K9: Gumbel | L9: Diseño
B10: Media Aritmética | E10: ='B.Modelo Distribución'!C36 -> 110.308 | G10: 2 | H10: ='B.Modelo Distribución'!J11 -> 110.308 | I10: ='B.Modelo Distribución'!H58 -> 107.36492 | J10: ='B.Modelo Distribución'!R11 -> 104.59145 | K10: ='B.Modelo Distribución'!E46 -> 105.78027 | L10: =IF('C. Prueba Kolmorov-Smirnov'!$G$54="Normal",H10,IF('C. Prueba Kolmorov-Smirnov'!$G$54="Log - Normal",I10,IF('C. Prueba Kolmorov-Smirnov'!$G$54="Gumbel",K10,J10))) -> 104.59145
B11: Desviación Estándar | E11: ='B.Modelo Distribución'!C38 -> 27.562367 | G11: 5 | H11: ='B.Modelo Distribución'!J12 -> 133.50054 | I11: ='B.Modelo Distribución'!H59 -> 130.51174 | J11: ='B.Modelo Distribución'!R12 -> 128.94132 | K11: ='B.Modelo Distribución'!E47 -> 130.13795 | L11: =IF('C. Prueba Kolmorov-Smirnov'!$G$54="Normal",H11,IF('C. Prueba Kolmorov-Smirnov'!$G$54="Log - Normal",I11,IF('C. Prueba Kolmorov-Smirnov'!$G$54="Gumbel",K11,J11))) -> 128.94132
B12: Coeficiente de Asimetría | E12: ='B.Modelo Distribución'!C39 -> 1.1317058 | G12: 10 | H12: ='B.Modelo Distribución'!J13 -> 145.63548 | I12: ='B.Modelo Distribución'!H60 -> 144.54811 | J12: ='B.Modelo Distribución'!R13 -> 146.18116 | K12: ='B.Modelo Distribución'!E48 -> 146.26485 | L12: =IF('C. Prueba Kolmorov-Smirnov'!$G$54="Normal",H12,IF('C. Prueba Kolmorov-Smirnov'!$G$54="Log - Normal",I12,IF('C. Prueba Kolmorov-Smirnov'!$G$54="Gumbel",K12,J12))) -> 146.18116
B13: Numero de datos | E13: ='B.Modelo Distribución'!C41 -> 25 | G13: 20 | H13: ='B.Modelo Distribución'!J14 -> 155.65392 | I13: ='B.Modelo Distribución'!H61 -> 157.26707 | J13: ='B.Modelo Distribución'!R14 -> 163.56456 | K13: ='B.Modelo Distribución'!E49 -> 161.73416 | L13: =IF('C. Prueba Kolmorov-Smirnov'!$G$54="Normal",H13,IF('C. Prueba Kolmorov-Smirnov'!$G$54="Log - Normal",I13,IF('C. Prueba Kolmorov-Smirnov'!$G$54="Gumbel",K13,J13))) -> 163.56456
B14: Variación del Coef. de Asimetría | E14: =6/E13 -> 0.24 | G14: 25 | H14: ='B.Modelo Distribución'!J15 -> 158.57181 | I14: ='B.Modelo Distribución'!H62 -> 161.17772 | J14: ='B.Modelo Distribución'!R15 -> 169.26551 | K14: ='B.Modelo Distribución'!E50 -> 166.64123 | L14: =IF('C. Prueba Kolmorov-Smirnov'!$G$54="Normal",H14,IF('C. Prueba Kolmorov-Smirnov'!$G$54="Log - Normal",I14,IF('C. Prueba Kolmorov-Smirnov'!$G$54="Gumbel",K14,J14))) -> 169.26551
B15: Desv. Est. Coef. de Asimetría | E15: =+SQRT(E14) -> 0.48989795 | G15: 50 | H15: ='B.Modelo Distribución'!J16 -> 166.9263 | I15: ='B.Modelo Distribución'!H63 -> 172.92083 | J15: ='B.Modelo Distribución'!R16 -> 187.44603 | K15: ='B.Modelo Distribución'!E51 -> 181.7576 | L15: =IF('C. Prueba Kolmorov-Smirnov'!$G$54="Normal",H15,IF('C. Prueba Kolmorov-Smirnov'!$G$54="Log - Normal",I15,IF('C. Prueba Kolmorov-Smirnov'!$G$54="Gumbel",K15,J15))) -> 187.44603
G16: 100 | H16: ='B.Modelo Distribución'!J17 -> 174.43971 | I16: ='B.Modelo Distribución'!H64 -> 184.21067 | J16: ='B.Modelo Distribución'!R17 -> 206.50452 | K16: ='B.Modelo Distribución'!E52 -> 196.76234 | L16: =IF('C. Prueba Kolmorov-Smirnov'!$G$54="Normal",H16,IF('C. Prueba Kolmorov-Smirnov'!$G$54="Log - Normal",I16,IF('C. Prueba Kolmorov-Smirnov'!$G$54="Gumbel",K16,J16))) -> 206.50452
B17: Logarítmica | E17: Valor | G17: 200 | H17: ='B.Modelo Distribución'!J18 -> 181.31517 | I17: ='B.Modelo Distribución'!H65 -> 195.18662 | J17: ='B.Modelo Distribución'!R18 -> 226.61569 | K17: ='B.Modelo Distribución'!E53 -> 211.71234 | L17: =IF('C. Prueba Kolmorov-Smirnov'!$G$54="Normal",H17,IF('C. Prueba Kolmorov-Smirnov'!$G$54="Log - Normal",I17,IF('C. Prueba Kolmorov-Smirnov'!$G$54="Gumbel",K17,J17))) -> 226.61569
B18: Media Aritmética | E18: =+'B.Modelo Distribución'!D36 -> 2.0308624 | G18: 500 | H18: ='B.Modelo Distribución'!J19 -> 189.64644 | I18: ='B.Modelo Distribución'!H66 -> 209.36664 | J18: ='B.Modelo Distribución'!R19 -> 255.07124 | K18: ='B.Modelo Distribución'!E54 -> 231.43603 | L18: =IF('C. Prueba Kolmorov-Smirnov'!$G$54="Normal",H18,IF('C. Prueba Kolmorov-Smirnov'!$G$54="Log - Normal",I18,IF('C. Prueba Kolmorov-Smirnov'!$G$54="Gumbel",K18,J18))) -> 255.07124
B19: Desviación Estándar | E19: =+'B.Modelo Distribución'!D38 -> 0.10076237
B20: Varianza | E20: =+'B.Modelo Distribución'!D37 -> 0.010153054
B21: Coeficiente de Asimetría | E21: =+'B.Modelo Distribución'!D39 -> 0.685811
B22: Numero de datos | E22: =+E13 -> 25
B23: Variación del Coef. de Asimetría | E23: =6/E22 -> 0.24
B24: D.S. Coef As | E24: =+SQRT(E23) -> 0.48989795
B25: K | E25: =+'B.Modelo Distribución'!D40 -> 0.11430183

Sheet A. Parametros
B2: Proyecto | C2: =+'A. Estación'!C2 -> “MEJORAMIENTO Y AMPLIACIÓN DEL SERVICIO DE EDUCACIÓN PRIMARIA EN I.E. N° 0590 DISTRITO DE BARRANQUITA DE LA PROVINCIA DE LAMAS DEL DEPARTAMENTO DE SAN MARTÍN”, con C.I. N.° 468901
B3: Entidad | C3: =+'A. Estación'!C3 -> GOBIERNO REGIONAL SAN MARTIN - GERENCIA TERRITORIAL BAJO MAYO - TARAPOTO
B4: Ubicación | C4: =+'A. Estación'!C4 -> SAN MARTIN - LAMAS - BARRANQUITA
B5: Fecha | C5: =+'A. Estación'!C5 -> OCTUBRE 2026
B7: PARTE II: DETERMINACIÓN DE LA TORMENTA DE DISEÑO
B8: A. PARAMETROS DE INTENSIDADES MAXIMAS
B9: Cuadro N°04: Lluvias máximas (mm)
B10: T | C10: P.Max | D10: Duración en minutos | L10: Duración | M10: Y | N10: X1 | O10: X2
B11: años | C11: 24 horas | D11: 5 | E11: 10 | F11: 15 | G11: 20 | H11: 30 | I11: 60 | L11: Minutos | M11: Log (I) | N11: Log (T) | O11: Log (t)
B12: 500 | C12: ='D.Resumen'!L18 -> 255.07124 | D12: =(0.21*LN($B12)+0.52)*(0.54*D$11^0.25-0.5)*$I$18 -> 20.34694 | E12: =(0.21*LN($B12)+0.52)*(0.54*E$11^0.25-0.5)*$I$18 -> 30.456778 | F12: =(0.21*LN($B12)+0.52)*(0.54*F$11^0.25-0.5)*$I$18 -> 37.235612 | G12: =(0.21*LN($B12)+0.52)*(0.54*G$11^0.25-0.5)*$I$18 -> 42.479468 | H12: =(0.21*LN($B12)+0.52)*(0.54*H$11^0.25-0.5)*$I$18 -> 50.540907 | I12: =(0.21*LN($B12)+0.52)*(0.54*I$11^0.25-0.5)*$I$18 -> 66.363657 | L12: =D11 -> 5 | M12: =LOG10(D25) -> 2.3877457 | N12: =LOG10($B25) -> 2.69897 | O12: =LOG10($D$24) -> 0.69897
B13: 200 | C13: ='D.Resumen'!L17 -> 226.61569 | D13: =(0.21*LN($B13)+0.52)*(0.54*(D$11^0.25)-0.5)*$I$18 -> 18.201716 | E13: =(0.21*LN($B13)+0.52)*(0.54*E$11^0.25-0.5)*$I$18 -> 27.24565 | F13: =(0.21*LN($B13)+0.52)*(0.54*F$11^0.25-0.5)*$I$18 -> 33.309777 | G13: =(0.21*LN($B13)+0.52)*(0.54*G$11^0.25-0.5)*$I$18 -> 38.000761 | H13: =(0.21*LN($B13)+0.52)*(0.54*H$11^0.25-0.5)*$I$18 -> 45.212263 | I13: =(0.21*LN($B13)+0.52)*(0.54*I$11^0.25-0.5)*$I$18 -> 59.366785 | M13: =LOG10(D26) -> 2.3392526 | N13: =LOG10($B26) -> 2.30103 | O13: =LOG10($D$24) -> 0.69897
B14: 100 | C14: ='D.Resumen'!L16 -> 206.50452 | D14: =(0.21*LN($B14)+0.52)*(0.54*D$11^0.25-0.5)*$I$18 -> 16.578916 | E14: =(0.21*LN($B14)+0.52)*(0.54*E$11^0.25-0.5)*$I$18 -> 24.816526 | F14: =(0.21*LN($B14)+0.52)*(0.54*F$11^0.25-0.5)*$I$18 -> 30.339997 | G14: =(0.21*LN($B14)+0.52)*(0.54*G$11^0.25-0.5)*$I$18 -> 34.61275 | H14: =(0.21*LN($B14)+0.52)*(0.54*H$11^0.25-0.5)*$I$18 -> 41.1813 | I14: =(0.21*LN($B14)+0.52)*(0.54*I$11^0.25-0.5)*$I$18 -> 54.073856 | M14: =LOG10(D27) -> 2.2986348 | N14: =LOG10($B27) -> 2 | O14: =LOG10($D$24) -> 0.69897
B15: 50 | C15: ='D.Resumen'!L15 -> 187.44603 | D15: =(0.21*LN($B15)+0.52)*(0.54*D$11^0.25-0.5)*$I$18 -> 14.956117 | E15: =(0.21*LN($B15)+0.52)*(0.54*E$11^0.25-0.5)*$I$18 -> 22.387401 | F15: =(0.21*LN($B15)+0.52)*(0.54*F$11^0.25-0.5)*$I$18 -> 27.370217 | G15: =(0.21*LN($B15)+0.52)*(0.54*G$11^0.25-0.5)*$I$18 -> 31.224738 | H15: =(0.21*LN($B15)+0.52)*(0.54*H$11^0.25-0.5)*$I$18 -> 37.150338 | I15: =(0.21*LN($B15)+0.52)*(0.54*I$11^0.25-0.5)*$I$18 -> 48.780927 | M15: =LOG10(D28) -> 2.2540645 | N15: =LOG10($B28) -> 1.69897 | O15: =LOG10($D$24) -> 0.69897
B16: 25 | C16: ='D.Resumen'!L14 -> 169.26551 | D16: =(0.21*LN($B16)+0.52)*(0.54*D$11^0.25-0.5)*$I$18 -> 13.333317 | E16: =(0.21*LN($B16)+0.52)*(0.54*E$11^0.25-0.5)*$I$18 -> 19.958277 | F16: =(0.21*LN($B16)+0.52)*(0.54*F$11^0.25-0.5)*$I$18 -> 24.400437 | G16: =(0.21*LN($B16)+0.52)*(0.54*G$11^0.25-0.5)*$I$18 -> 27.836727 | H16: =(0.21*LN($B16)+0.52)*(0.54*H$11^0.25-0.5)*$I$18 -> 33.119375 | I16: =(0.21*LN($B16)+0.52)*(0.54*I$11^0.25-0.5)*$I$18 -> 43.487998 | M16: =LOG10(D29) -> 2.20412 | N16: =LOG10($B29) -> 1.39794 | O16: =LOG10($D$24) -> 0.69897
B17: 20 | C17: ='D.Resumen'!L13 -> 163.56456 | D17: =(0.21*LN($B17)+0.52)*(0.54*D$11^0.25-0.5)*$I$18 -> 12.810892 | E17: =(0.21*LN($B17)+0.52)*(0.54*E$11^0.25-0.5)*$I$18 -> 19.176274 | F17: =(0.21*LN($B17)+0.52)*(0.54*F$11^0.25-0.5)*$I$18 -> 23.444381 | G17: =(0.21*LN($B17)+0.52)*(0.54*G$11^0.25-0.5)*$I$18 -> 26.746031 | H17: =(0.21*LN($B17)+0.52)*(0.54*H$11^0.25-0.5)*$I$18 -> 31.821694 | I17: =(0.21*LN($B17)+0.52)*(0.54*I$11^0.25-0.5)*$I$18 -> 41.784055 | M17: =LOG10(D30) -> 2.1866739 | N17: =LOG10($B30) -> 1.30103 | O17: =LOG10($D$24) -> 0.69897
B18: 10 | C18: ='D.Resumen'!L12 -> 146.18116 | D18: =(0.21*LN($B18)+0.52)*(0.54*D$11^0.25-0.5)*$I$18 -> 11.188093 | E18: =(0.21*LN($B18)+0.52)*(0.54*E$11^0.25-0.5)*$I$18 -> 16.74715 | F18: =(0.21*LN($B18)+0.52)*(0.54*F$11^0.25-0.5)*$I$18 -> 20.474601 | G18: =(0.21*LN($B18)+0.52)*(0.54*G$11^0.25-0.5)*$I$18 -> 23.35802 | H18: =(0.21*LN($B18)+0.52)*(0.54*H$11^0.25-0.5)*$I$18 -> 27.790731 | I18: =0.4602*C18^0.876 -> 36.256967 | M18: =LOG10(D31) -> 2.128076 | N18: =LOG10($B31) -> 1 | O18: =LOG10($D$24) -> 0.69897
B19: 5 | C19: ='D.Resumen'!L11 -> 128.94132 | D19: =(0.21*LN($B19)+0.52)*(0.54*D$11^0.25-0.5)*$I$18 -> 9.5652931 | E19: =(0.21*LN($B19)+0.52)*(0.54*E$11^0.25-0.5)*$I$18 -> 14.318025 | F19: =(0.21*LN($B19)+0.52)*(0.54*F$11^0.25-0.5)*$I$18 -> 17.504821 | G19: =(0.21*LN($B19)+0.52)*(0.54*G$11^0.25-0.5)*$I$18 -> 19.970009 | H19: =(0.21*LN($B19)+0.52)*(0.54*H$11^0.25-0.5)*$I$18 -> 23.759769 | I19: =(0.21*LN($B19)+0.52)*(0.54*I$11^0.25-0.5)*$I$18 -> 31.198197 | M19: =LOG10(D32) -> 2.0599419 | N19: =LOG10($B32) -> 0.69897 | O19: =LOG10($D$24) -> 0.69897
B20: 2 | C20: ='D.Resumen'!L10 -> 104.59145 | D20: =(0.21*LN($B20)+0.52)*(0.54*D$11^0.25-0.5)*$I$18 -> 7.4200688 | E20: =(0.21*LN($B20)+0.52)*(0.54*E$11^0.25-0.5)*$I$18 -> 11.106898 | F20: =(0.21*LN($B20)+0.52)*(0.54*F$11^0.25-0.5)*$I$18 -> 13.578985 | G20: =(0.21*LN($B20)+0.52)*(0.54*G$11^0.25-0.5)*$I$18 -> 15.491301 | H20: =(0.21*LN($B20)+0.52)*(0.54*H$11^0.25-0.5)*$I$18 -> 18.431125 | I20: =(0.21*LN($B20)+0.52)*(0.54*I$11^0.25-0.5)*$I$18 -> 24.201325 | M20: =LOG10(D33) -> 1.94939 | N20: =LOG10($B33) -> 0.30103 | O20: =LOG10($D$24) -> 0.69897
B21: Fuente: Modelo de Bell | L21: =E11 -> 10 | M21: =LOG10(E25) -> 2.2617385 | N21: =LOG10($B25) -> 2.69897 | O21: =LOG10($E$24) -> 1
B22: Cuadro N°05: Intensidades máximas (mm/hora) | M22: =LOG10(E26) -> 2.2135178 | N22: =LOG10($B26) -> 2.30103 | O22: =LOG10($E$24) -> 1
B23: T | C23: P.Max | D23: Duración en minutos | M23: =LOG10(E27) -> 2.1728947 | N23: =LOG10($B27) -> 2 | O23: =LOG10($E$24) -> 1
B24: años | C24: 24 horas | D24: 5 | E24: 10 | F24: 15 | G24: 20 | H24: 30 | I24: 60 | M24: =LOG10(E28) -> 2.128076 | N24: =LOG10($B28) -> 1.69897 | O24: =LOG10($E$24) -> 1
B25: 500 | C25: =C12 -> 255.07124 | D25: =ROUND(60*D12/D$11,1) -> 244.2 | E25: =ROUND(60*E12/E$11,1) -> 182.7 | F25: =ROUND(60*F12/F$11,1) -> 148.9 | G25: =ROUND(60*G12/G$11,1) -> 127.4 | H25: =ROUND(60*H12/H$11,1) -> 101.1 | I25: =ROUND(60*I12/I$11,1) -> 66.4 | M25: =LOG10(E29) -> 2.0780942 | N25: =LOG10($B29) -> 1.39794 | O25: =LOG10($E$24) -> 1
B26: 200 | C26: =C13 -> 226.61569 | D26: =ROUND(60*D13/D$11,1) -> 218.4 | E26: =ROUND(60*E13/E$11,1) -> 163.5 | F26: =ROUND(60*F13/F$11,1) -> 133.2 | G26: =ROUND(60*G13/G$11,1) -> 114 | H26: =ROUND(60*H13/H$11,1) -> 90.4 | I26: =ROUND(60*I13/I$11,1) -> 59.4 | M26: =LOG10(E30) -> 2.0610753 | N26: =LOG10($B30) -> 1.30103 | O26: =LOG10($E$24) -> 1
B27: 100 | C27: =C14 -> 206.50452 | D27: =ROUND(60*D14/D$11,1) -> 198.9 | E27: =ROUND(60*E14/E$11,1) -> 148.9 | F27: =ROUND(60*F14/F$11,1) -> 121.4 | G27: =ROUND(60*G14/G$11,1) -> 103.8 | H27: =ROUND(60*H14/H$11,1) -> 82.4 | I27: =ROUND(60*I14/I$11,1) -> 54.1 | M27: =LOG10(E31) -> 2.0021661 | N27: =LOG10($B31) -> 1 | O27: =LOG10($E$24) -> 1
B28: 50 | C28: =C15 -> 187.44603 | D28: =ROUND(60*D15/D$11,1) -> 179.5 | E28: =ROUND(60*E15/E$11,1) -> 134.3 | F28: =ROUND(60*F15/F$11,1) -> 109.5 | G28: =ROUND(60*G15/G$11,1) -> 93.7 | H28: =ROUND(60*H15/H$11,1) -> 74.3 | I28: =ROUND(60*I15/I$11,1) -> 48.8 | M28: =LOG10(E32) -> 1.9339932 | N28: =LOG10($B32) -> 0.69897 | O28: =LOG10($E$24) -> 1
B29: 25 | C29: =C16 -> 169.26551 | D29: =ROUND(60*D16/D$11,1) -> 160 | E29: =ROUND(60*E16/E$11,1) -> 119.7 | F29: =ROUND(60*F16/F$11,1) -> 97.6 | G29: =ROUND(60*G16/G$11,1) -> 83.5 | H29: =ROUND(60*H16/H$11,1) -> 66.2 | I29: =ROUND(60*I16/I$11,1) -> 43.5 | M29: =LOG10(E33) -> 1.8234742 | N29: =LOG10($B33) -> 0.30103 | O29: =LOG10($E$24) -> 1
B30: 20 | C30: =C17 -> 163.56456 | D30: =ROUND(60*D17/D$11,1) -> 153.7 | E30: =ROUND(60*E17/E$11,1) -> 115.1 | F30: =ROUND(60*F17/F$11,1) -> 93.8 | G30: =ROUND(60*G17/G$11,1) -> 80.2 | H30: =ROUND(60*H17/H$11,1) -> 63.6 | I30: =ROUND(60*I17/I$11,1) -> 41.8 | L30: =F11 -> 15 | M30: =LOG10(F25) -> 2.1728947 | N30: =LOG10($B25) -> 2.69897 | O30: =LOG10($F$24) -> 1.1760913
B31: 10 | C31: =C18 -> 146.18116 | D31: =ROUND(60*D18/D$11,1) -> 134.3 | E31: =ROUND(60*E18/E$11,1) -> 100.5 | F31: =ROUND(60*F18/F$11,1) -> 81.9 | G31: =ROUND(60*G18/G$11,1) -> 70.1 | H31: =ROUND(60*H18/H$11,1) -> 55.6 | I31: =ROUND(60*I18/I$11,1) -> 36.3 | M31: =LOG10(F26) -> 2.1245042 | N31: =LOG10($B26) -> 2.30103 | O31: =LOG10($F$24) -> 1.1760913
B32: 5 | C32: =C19 -> 128.94132 | D32: =ROUND(60*D19/D$11,1) -> 114.8 | E32: =ROUND(60*E19/E$11,1) -> 85.9 | F32: =ROUND(60*F19/F$11,1) -> 70 | G32: =ROUND(60*G19/G$11,1) -> 59.9 | H32: =ROUND(60*H19/H$11,1) -> 47.5 | I32: =ROUND(60*I19/I$11,1) -> 31.2 | M32: =LOG10(F27) -> 2.0842187 | N32: =LOG10($B27) -> 2 | O32: =LOG10($F$24) -> 1.1760913
B33: 2 | C33: =C20 -> 104.59145 | D33: =ROUND(60*D20/D$11,1) -> 89 | E33: =ROUND(60*E20/E$11,1) -> 66.6 | F33: =ROUND(60*F20/F$11,1) -> 54.3 | G33: =ROUND(60*G20/G$11,1) -> 46.5 | H33: =ROUND(60*H20/H$11,1) -> 36.9 | I33: =ROUND(60*I20/I$11,1) -> 24.2 | M33: =LOG10(F28) -> 2.0394141 | N33: =LOG10($B28) -> 1.69897 | O33: =LOG10($F$24) -> 1.1760913
M34: =LOG10(F29) -> 1.9894498 | N34: =LOG10($B29) -> 1.39794 | O34: =LOG10($F$24) -> 1.1760913
B35: Cuadro N°06: Ecuaciones de la Regresión Lineal Múltiple | M35: =LOG10(F30) -> 1.9722028 | N35: =LOG10($B30) -> 1.30103 | O35: =LOG10($F$24) -> 1.1760913
B36: Ecuación de la regresión Lineal Múltiple | F36: m(X1) - n(X2) + logK = Y | M36: =LOG10(F31) -> 1.9132839 | N36: =LOG10($B31) -> 1 | O36: =LOG10($F$24) -> 1.1760913
B37: Sistema de Ecuaciones Normalizada (1) | E37: AΣ(X1) + BΣ(X2) + C(n) = Σ(Y) | F37: mΣ(X1) + nΣ(X2) + (logK)(n) = Σ(Y) | M37: =LOG10(F32) -> 1.845098 | N37: =LOG10($B32) -> 0.69897 | O37: =LOG10($F$24) -> 1.1760913
B38: Sistema de Ecuaciones Normalizada (2) | E38: AΣ(X1²) + BΣ(X1)(X2) + CΣX1 = Σ(X1)(Y ) | F38: mΣ(X1²) + nΣ(X1)(X2) + (logK)ΣX1 = Σ(X1)(Y ) | M38: =LOG10(F33) -> 1.7347998 | N38: =LOG10($B33) -> 0.30103 | O38: =LOG10($F$24) -> 1.1760913
B39: Sistema de Ecuaciones Normalizada (3) | E39: AΣ(X1)(X2) + BΣ(X2²) + CΣX2 = Σ(X2)(Y ) | F39: mΣ(X1)(X2) + nΣ(X2²) + (logK)ΣX2 = Σ(X2)(Y ) | L39: =G11 -> 20 | M39: =LOG10(G25) -> 2.1051694 | N39: =LOG10($B25) -> 2.69897 | O39: =LOG10($G$24) -> 1.30103
M40: =LOG10(G26) -> 2.0569049 | N40: =LOG10($B26) -> 2.30103 | O40: =LOG10($G$24) -> 1.30103
B41: =B37 -> Sistema de Ecuaciones Normalizada (1) | F41: mΣ(X1) | G41: nΣ(X2) | H41: (logK)(n) | I41: Σ(Y) | M41: =LOG10(G27) -> 2.0161974 | N41: =LOG10($B27) -> 2 | O41: =LOG10($G$24) -> 1.30103
F42: =SUM(N12:N65) -> 80.38764 | G42: =SUM(O12:O65) -> 66.882274 | H42: =COUNT(M12:M65) -> 54 | I42: =SUM(M12:M65) -> 104.70132 | M42: =LOG10(G28) -> 1.9717396 | N42: =LOG10($B28) -> 1.69897 | O42: =LOG10($G$24) -> 1.30103
...

Sheet B. Int.maxima
B2: Proyecto | C2: ='A. Estación'!C2:O2 -> “MEJORAMIENTO Y AMPLIACIÓN DEL SERVICIO DE EDUCACIÓN PRIMARIA EN I.E. N° 0590 DISTRITO DE BARRANQUITA DE LA PROVINCIA DE LAMAS DEL DEPARTAMENTO DE SAN MARTÍN”, con C.I. N.° 468901
B3: Entidad | C3: ='A. Estación'!C3:O3 -> GOBIERNO REGIONAL SAN MARTIN - GERENCIA TERRITORIAL BAJO MAYO - TARAPOTO
B4: Ubicación | C4: ='A. Estación'!C4:O4 -> SAN MARTIN - LAMAS - BARRANQUITA
B5: Fecha | C5: ='A. Estación'!C5:O5 -> OCTUBRE 2026
B7: B. CÁLCULO DE INTENSIDADES MÁXIMAS (mm/h)
C9: I = | D9: K Tm
D10: tn
C12: K | D12: =ROUND(10^'A. Parametros'!I53,2) -> 211.66
C13: m | D13: ='A. Parametros'!I51 -> 0.17859513
C14: n | D14: =ABS('A. Parametros'!I52) -> 0.52689495
B16: Duración (t) | C16: Período de Retorno (T) en años
B17: (minutos) | C17: 2 | D17: 5 | E17: 10 | F17: 20 | G17: 25 | H17: 50 | I17: 100
B18: 10 | C18: =ROUND(($D$12*$C$17^$D$13)/B18^$D$14,2) -> 71.2 | D18: =ROUND(($D$12*$D$17^$D$13)/B18^$D$14,2) -> 83.86 | E18: =ROUND(($D$12*$E$17^$D$13)/B18^$D$14,2) -> 94.92 | F18: =ROUND(($D$12*$F$17^$D$13)/B18^$D$14,2) -> 107.42 | G18: =ROUND(($D$12*$G$17^$D$13)/B18^$D$14,2) -> 111.79 | H18: =ROUND(($D$12*$H$17^$D$13)/B18^$D$14,2) -> 126.52 | I18: =ROUND(($D$12*$I$17^$D$13)/B18^$D$14,2) -> 143.2
B19: 20 | C19: =ROUND(($D$12*$C$17^$D$13)/B19^$D$14,2) -> 49.42 | D19: =ROUND(($D$12*$D$17^$D$13)/B19^$D$14,2) -> 58.21 | E19: =ROUND(($D$12*$E$17^$D$13)/B19^$D$14,2) -> 65.88 | F19: =ROUND(($D$12*$F$17^$D$13)/B19^$D$14,2) -> 74.56 | G19: =ROUND(($D$12*$G$17^$D$13)/B19^$D$14,2) -> 77.59 | H19: =ROUND(($D$12*$H$17^$D$13)/B19^$D$14,2) -> 87.81 | I19: =ROUND(($D$12*$I$17^$D$13)/B19^$D$14,2) -> 99.39
B20: 30 | C20: =ROUND(($D$12*$C$17^$D$13)/B20^$D$14,2) -> 39.91 | D20: =ROUND(($D$12*$D$17^$D$13)/B20^$D$14,2) -> 47.01 | E20: =ROUND(($D$12*$E$17^$D$13)/B20^$D$14,2) -> 53.2 | F20: =ROUND(($D$12*$F$17^$D$13)/B20^$D$14,2) -> 60.22 | G20: =ROUND(($D$12*$G$17^$D$13)/B20^$D$14,2) -> 62.66 | H20: =ROUND(($D$12*$H$17^$D$13)/B20^$D$14,2) -> 70.92 | I20: =ROUND(($D$12*$I$17^$D$13)/B20^$D$14,2) -> 80.27
B21: 40 | C21: =ROUND(($D$12*$C$17^$D$13)/B21^$D$14,2) -> 34.3 | D21: =ROUND(($D$12*$D$17^$D$13)/B21^$D$14,2) -> 40.4 | E21: =ROUND(($D$12*$E$17^$D$13)/B21^$D$14,2) -> 45.72 | F21: =ROUND(($D$12*$F$17^$D$13)/B21^$D$14,2) -> 51.75 | G21: =ROUND(($D$12*$G$17^$D$13)/B21^$D$14,2) -> 53.85 | H21: =ROUND(($D$12*$H$17^$D$13)/B21^$D$14,2) -> 60.95 | I21: =ROUND(($D$12*$I$17^$D$13)/B21^$D$14,2) -> 68.98
B22: 50 | C22: =ROUND(($D$12*$C$17^$D$13)/B22^$D$14,2) -> 30.49 | D22: =ROUND(($D$12*$D$17^$D$13)/B22^$D$14,2) -> 35.92 | E22: =ROUND(($D$12*$E$17^$D$13)/B22^$D$14,2) -> 40.65 | F22: =ROUND(($D$12*$F$17^$D$13)/B22^$D$14,2) -> 46.01 | G22: =ROUND(($D$12*$G$17^$D$13)/B22^$D$14,2) -> 47.88 | H22: =ROUND(($D$12*$H$17^$D$13)/B22^$D$14,2) -> 54.19 | I22: =ROUND(($D$12*$I$17^$D$13)/B22^$D$14,2) -> 61.33
B23: 60 | C23: =ROUND(($D$12*$C$17^$D$13)/B23^$D$14,2) -> 27.7 | D23: =ROUND(($D$12*$D$17^$D$13)/B23^$D$14,2) -> 32.63 | E23: =ROUND(($D$12*$E$17^$D$13)/B23^$D$14,2) -> 36.93 | F23: =ROUND(($D$12*$F$17^$D$13)/B23^$D$14,2) -> 41.79 | G23: =ROUND(($D$12*$G$17^$D$13)/B23^$D$14,2) -> 43.49 | H23: =ROUND(($D$12*$H$17^$D$13)/B23^$D$14,2) -> 49.22 | I23: =ROUND(($D$12*$I$17^$D$13)/B23^$D$14,2) -> 55.71
B24: 70 | C24: =ROUND(($D$12*$C$17^$D$13)/B24^$D$14,2) -> 25.54 | D24: =ROUND(($D$12*$D$17^$D$13)/B24^$D$14,2) -> 30.08 | E24: =ROUND(($D$12*$E$17^$D$13)/B24^$D$14,2) -> 34.05 | F24: =ROUND(($D$12*$F$17^$D$13)/B24^$D$14,2) -> 38.53 | G24: =ROUND(($D$12*$G$17^$D$13)/B24^$D$14,2) -> 40.1 | H24: =ROUND(($D$12*$H$17^$D$13)/B24^$D$14,2) -> 45.38 | I24: =ROUND(($D$12*$I$17^$D$13)/B24^$D$14,2) -> 51.36
B25: 80 | C25: =ROUND(($D$12*$C$17^$D$13)/B25^$D$14,2) -> 23.81 | D25: =ROUND(($D$12*$D$17^$D$13)/B25^$D$14,2) -> 28.04 | E25: =ROUND(($D$12*$E$17^$D$13)/B25^$D$14,2) -> 31.73 | F25: =ROUND(($D$12*$F$17^$D$13)/B25^$D$14,2) -> 35.91 | G25: =ROUND(($D$12*$G$17^$D$13)/B25^$D$14,2) -> 37.37 | H25: =ROUND(($D$12*$H$17^$D$13)/B25^$D$14,2) -> 42.3 | I25: =ROUND(($D$12*$I$17^$D$13)/B25^$D$14,2) -> 47.87
B26: 90 | C26: =ROUND(($D$12*$C$17^$D$13)/B26^$D$14,2) -> 22.37 | D26: =ROUND(($D$12*$D$17^$D$13)/B26^$D$14,2) -> 26.35 | E26: =ROUND(($D$12*$E$17^$D$13)/B26^$D$14,2) -> 29.82 | F26: =ROUND(($D$12*$F$17^$D$13)/B26^$D$14,2) -> 33.75 | G26: =ROUND(($D$12*$G$17^$D$13)/B26^$D$14,2) -> 35.13 | H26: =ROUND(($D$12*$H$17^$D$13)/B26^$D$14,2) -> 39.75 | I26: =ROUND(($D$12*$I$17^$D$13)/B26^$D$14,2) -> 44.99
B27: 100 | C27: =ROUND(($D$12*$C$17^$D$13)/B27^$D$14,2) -> 21.16 | D27: =ROUND(($D$12*$D$17^$D$13)/B27^$D$14,2) -> 24.93 | E27: =ROUND(($D$12*$E$17^$D$13)/B27^$D$14,2) -> 28.21 | F27: =ROUND(($D$12*$F$17^$D$13)/B27^$D$14,2) -> 31.93 | G27: =ROUND(($D$12*$G$17^$D$13)/B27^$D$14,2) -> 33.23 | H27: =ROUND(($D$12*$H$17^$D$13)/B27^$D$14,2) -> 37.61 | I27: =ROUND(($D$12*$I$17^$D$13)/B27^$D$14,2) -> 42.56
B28: 110 | C28: =ROUND(($D$12*$C$17^$D$13)/B28^$D$14,2) -> 20.13 | D28: =ROUND(($D$12*$D$17^$D$13)/B28^$D$14,2) -> 23.71 | E28: =ROUND(($D$12*$E$17^$D$13)/B28^$D$14,2) -> 26.83 | F28: =ROUND(($D$12*$F$17^$D$13)/B28^$D$14,2) -> 30.37 | G28: =ROUND(($D$12*$G$17^$D$13)/B28^$D$14,2) -> 31.6 | H28: =ROUND(($D$12*$H$17^$D$13)/B28^$D$14,2) -> 35.77 | I28: =ROUND(($D$12*$I$17^$D$13)/B28^$D$14,2) -> 40.48
B29: 120 | C29: =ROUND(($D$12*$C$17^$D$13)/B29^$D$14,2) -> 19.23 | D29: =ROUND(($D$12*$D$17^$D$13)/B29^$D$14,2) -> 22.64 | E29: =ROUND(($D$12*$E$17^$D$13)/B29^$D$14,2) -> 25.63 | F29: =ROUND(($D$12*$F$17^$D$13)/B29^$D$14,2) -> 29.01 | G29: =ROUND(($D$12*$G$17^$D$13)/B29^$D$14,2) -> 30.19 | H29: =ROUND(($D$12*$H$17^$D$13)/B29^$D$14,2) -> 34.16 | I29: =ROUND(($D$12*$I$17^$D$13)/B29^$D$14,2) -> 38.67
K31: =+C17 -> 2 | L31: =+D17 -> 5 | M31: =+E17 -> 10 | N31: =+F17 -> 20 | O31: =+H17 -> 50 | P31: =+I17 -> 100

Sheet C. P diseño
B2: Proyecto | C2: ='A. Estación'!C2 -> “MEJORAMIENTO Y AMPLIACIÓN DEL SERVICIO DE EDUCACIÓN PRIMARIA EN I.E. N° 0590 DISTRITO DE BARRANQUITA DE LA PROVINCIA DE LAMAS DEL DEPARTAMENTO DE SAN MARTÍN”, con C.I. N.° 468901
B3: Entidad | C3: ='A. Estación'!C3 -> GOBIERNO REGIONAL SAN MARTIN - GERENCIA TERRITORIAL BAJO MAYO - TARAPOTO
B4: Ubicación | C4: ='A. Estación'!C4 -> SAN MARTIN - LAMAS - BARRANQUITA
B5: Fecha | C5: ='A. Estación'!C5 -> OCTUBRE 2026
B7: C. INTENSIDADES DE DISEÑO PARA PRECIPITACIONES MENORES A 24 HORAS (mm/h)
B9: Precipitación Pmax24 horas, T = 500 años | E9: ='D.Resumen'!L18 -> 255.07124
B10: D (min) | C10: D (horas) | D10: P (mm) | E10: I (mm/hr)
B11: 10 | C11: =+B11/60 -> 0.16666667 | D11: =+$E$9*(B11/1440)^0.25 -> 73.632725 | E11: =+D11/C11 -> 441.79635
B12: =+B11+10 -> 20 | C12: =+B12/60 -> 0.33333333 | D12: =+$E$9*(B12/1440)^0.25 -> 87.56456 | E12: =+D12/C12 -> 262.69368
B13: =+B12+10 -> 30 | C13: =+B13/60 -> 0.5 | D13: =+$E$9*(B13/1440)^0.25 -> 96.906115 | E13: =+D13/C13 -> 193.81223
B14: =+B13+10 -> 40 | C14: =+B14/60 -> 0.66666667 | D14: =+$E$9*(B14/1440)^0.25 -> 104.1324 | E14: =+D14/C14 -> 156.1986
B15: =+B14+10 -> 50 | C15: =+B15/60 -> 0.83333333 | D15: =+$E$9*(B15/1440)^0.25 -> 110.1066 | E15: =+D15/C15 -> 132.12793
B16: =+B15+10 -> 60 | C16: =+B16/60 -> 1 | D16: =+$E$9*(B16/1440)^0.25 -> 115.24144 | E16: =+D16/C16 -> 115.24144
B17: =+B16+10 -> 70 | C17: =+B17/60 -> 1.1666667 | D17: =+$E$9*(B17/1440)^0.25 -> 119.76926 | E17: =+D17/C17 -> 102.65937
B18: =+B17+10 -> 80 | C18: =+B18/60 -> 1.3333333 | D18: =+$E$9*(B18/1440)^0.25 -> 123.83499 | E18: =+D18/C18 -> 92.876241
B19: =+B18+10 -> 90 | C19: =+B19/60 -> 1.5 | D19: =+$E$9*(B19/1440)^0.25 -> 127.53562 | E19: =+D19/C19 -> 85.023747
B20: =+B19+10 -> 100 | C20: =+B20/60 -> 1.6666667 | D20: =+$E$9*(B20/1440)^0.25 -> 130.93956 | E20: =+D20/C20 -> 78.563735
B21: =+B20+10 -> 110 | C21: =+B21/60 -> 1.8333333 | D21: =+$E$9*(B21/1440)^0.25 -> 134.09699 | E21: =+D21/C21 -> 73.143815
B22: =+B21+10 -> 120 | C22: =+B22/60 -> 2 | D22: =+$E$9*(B22/1440)^0.25 -> 137.04594 | E22: =+D22/C22 -> 68.522971
B23: =+B22+10 -> 130 | C23: =+B23/60 -> 2.1666667 | D23: =+$E$9*(B23/1440)^0.25 -> 139.81595 | E23: =+D23/C23 -> 64.530437
... B34: =+B33+10 -> 240 | C34: =+B34/60 -> 4 | D34: =+$E$9*(B34/1440)^0.25 -> 162.97601 | E34: =+D34/C34 -> 40.744002
B35: 300 | C35: =+B35/60 -> 5 | D35: =+$E$9*(B35/1440)^0.25 -> 172.32615 | E35: =+D35/C35 -> 34.46523
B36: 360 | C36: =+B36/60 -> 6 | D36: =+$E$9*(B36/1440)^0.25 -> 180.3626 | E36: =+D36/C36 -> 30.060434
B37: 420 | C37: =+B37/60 -> 7 | D37: =+$E$9*(B37/1440)^0.25 -> 187.44903 | E37: =+D37/C37 -> 26.778433
B38: 480 | C38: =+B38/60 -> 8 | D38: =+$E$9*(B38/1440)^0.25 -> 193.81223 | E38: =+D38/C38 -> 24.226529
B39: 600 | C39: =+B39/60 -> 10 | D39: =+$E$9*(B39/1440)^0.25 -> 204.93148 | E39: =+D39/C39 -> 20.493148
B40: 660 | C40: =+B40/60 -> 11 | D40: =+$E$9*(B40/1440)^0.25 -> 209.87314 | E40: =+D40/C40 -> 19.079376
B41: 720 | C41: =+B41/60 -> 12 | D41: =+$E$9*(B41/1440)^0.25 -> 214.48849 | E41: =+D41/C41 -> 17.874041
B44: Precipitación Pmax24 horas, T = 100 años | E44: ='D.Resumen'!L16 -> 206.50452
B45: D (min) | C45: D (horas) | D45: P (mm) | E45: I (mm/hr)
B46: 10 | C46: =+B46/60 -> 0.16666667 | D46: =+$E$44*(B46/1440)^0.25 -> 59.612719 | E46: =+D46/C46 -> 357.67631
B47: =+B46+10 -> 20 | C47: =+B47/60 -> 0.33333333 | D47: =+$E$44*(B47/1440)^0.25 -> 70.891869 | E47: =+D47/C47 -> 212.67561
B48: =+B47+10 -> 30 | C48: =+B48/60 -> 0.5 | D48: =+$E$44*(B48/1440)^0.25 -> 78.45475 | E48: =+D48/C48 -> 156.9095
B49: =+B48+10 -> 40 | C49: =+B49/60 -> 0.66666667 | D49: =+$E$44*(B49/1440)^0.25 -> 84.305115 | E49: =+D49/C49 -> 126.45767
B50: =+B49+10 -> 50 | C50: =+B50/60 -> 0.83333333 | D50: =+$E$44*(B50/1440)^0.25 -> 89.141806 | E50: =+D50/C50 -> 106.97017
B51: =+B50+10 -> 60 | C51: =+B51/60 -> 1 | D51: =+$E$44*(B51/1440)^0.25 -> 93.298947 | E51: =+D51/C51 -> 93.298947
B52: =+B51+10 -> 70 | C52: =+B52/60 -> 1.1666667 | D52: =+$E$44*(B52/1440)^0.25 -> 96.964651 | E52: =+D52/C52 -> 83.112558
B53: =+B52+10 -> 80 | C53: =+B53/60 -> 1.3333333 | D53: =+$E$44*(B53/1440)^0.25 -> 100.25624 | E53: =+D53/C53 -> 75.192182
B54: =+B53+10 -> 90 | C54: =+B54/60 -> 1.5 | D54: =+$E$44*(B54/1440)^0.25 -> 103.25226 | E54: =+D54/C54 -> 68.834839
B55: =+B54+10 -> 100 | C55: =+B55/60 -> 1.6666667 | D55: =+$E$44*(B55/1440)^0.25 -> 106.00807 | E55: =+D55/C55 -> 63.604842
...
