Workbook

Sheet RESUMEN
A1: RESUMEN DEL PLANTEAMIENTO PRELIMINAR DE CUNETAS POR SISTEMA
A2: MEJORAMIENTO Y AMPLIACION DEL SERVICIO DE EDUCACION PRIMARIA EN LA I.E. N.° 0590, DISTRITO DE BARRANQUITA, PROVINCIA DE LAMAS, DEPARTAMENTO DE SAN MARTIN - C.I. N.° 468901
A4: SISTEMA | B4: LONGITUD (m) | C4: CON REJILLA (m) | D4: TAPADO (m) | E4: h MAXIMA (m) | F4: DESCARGA
A5: SISTEMA 1 - OESTE (descarga D1) | B5: =SUMIF(TRAMOS!$A$5:$A$70,1,TRAMOS!$E$5:$E$70) | C5: =SUMIF(TRAMOS!$A$5:$A$70,1,TRAMOS!$N$5:$N$70) | D5: =SUMIF(TRAMOS!$A$5:$A$70,1,TRAMOS!$M$5:$M$70) | E5: 0.894 | F5: D1: Cerco sur-oeste (lado C22-C1, x = 820.1): al talud natural que baja a la quebrada del oeste
A6: SISTEMA 2 - CENTRO Y FRENTE SUR (descarga D3) | B6: =SUMIF(TRAMOS!$A$5:$A$70,2,TRAMOS!$E$5:$E$70) | C6: =SUMIF(TRAMOS!$A$5:$A$70,2,TRAMOS!$N$5:$N$70) | D6: =SUMIF(TRAMOS!$A$5:$A$70,2,TRAMOS!$M$5:$M$70) | E6: 0.922 | F6: D3: Cerco sur junto a C14 (x = 935.5): al terreno exterior que baja al Jr. Alfonso Ugarte (183.00)
A7: SISTEMA 3 - NOR-ESTE Y LOSA (descarga D2) | B7: =SUMIF(TRAMOS!$A$5:$A$70,3,TRAMOS!$E$5:$E$70) | C7: =SUMIF(TRAMOS!$A$5:$A$70,3,TRAMOS!$N$5:$N$70) | D7: =SUMIF(TRAMOS!$A$5:$A$70,3,TRAMOS!$M$5:$M$70) | E7: 0.796 | F7: D2: Cerco norte (x = 965.5): pase en el cimiento del cerco al terreno exterior que baja a la quebrada del norte
A8: SISTEMA 4 - NORTE (descarga D4) | B8: =SUMIF(TRAMOS!$A$5:$A$70,4,TRAMOS!$E$5:$E$70) | C8: =SUMIF(TRAMOS!$A$5:$A$70,4,TRAMOS!$N$5:$N$70) | D8: =SUMIF(TRAMOS!$A$5:$A$70,4,TRAMOS!$M$5:$M$70) | E8: 0.501 | F8: D4: Cerco norte (lado C3-C4, x = 911.0): al talud natural que baja a la quebrada del norte
A9: TOTAL | B9: =SUM(B5:B8) | C9: =SUM(C5:C8) | D9: =SUM(D5:D8)
A11: NOTAS
A12: 1. Planteamiento preliminar: ejes de cuneta en las lineas magenta del plano PLANTA_GENERAL_590 ULTIMA VERSION (lados de cada bloque, techos a dos aguas) y uniones hasta las descargas.
A13: 2. Sentidos de flujo y descargas segun las curvas de nivel C-TOPO del mismo plano. Techos a dos aguas: cada alero descarga a su lado.
A14: 3. Area de intervencion = interior del cerco perimetrico: todas las cunetas quedan dentro del cerco (las perimetrales a 0.60 m de su eje).
A15: 4. Interior del cerco nivelado: pisos y pasadizos NPT +184.65; borde de cuneta +184.60; areas verdes +184.55; patio de maniobra +184.50 (cuneta al ras, con rejilla). Fuera del cerco, el terreno natural.
A16: 5. D1, D2, D3 y D4 salen por un pase en el cimiento del cerco. Fuera del cerco no hay obra.
A17: 6. Tramos de fuerte pendiente con V > 3.0 m/s: gradas de concreto (hoja HIDRAULICA). Verificacion completa en la hoja VERIFICACION.
A18: 7. Ver planos PLANTEAMIENTO_CUNETAS_IE0590_BARRANQUITA.dxf: DC-01 planta general de cunetas - planteamiento preliminar; DC-02 cuadro de tramos y secciones tipicas de cuneta; DC-03 a DC-11 perfiles longitudinales de cunetas por eje; DC-12 a DC-15 secciones transversales de cunetas; DC-16 isometrico de la red - vista desde el sur; DC-17 isometrico de la red - vista desde el norte; DC-18 cortes por las descargas d1, d2, d3 y d4; DC-19 cortes generales del terreno y la red; DC-20 detalle isometrico de las descargas por el cerco.

Sheet VERIFICACION
A1: VERIFICACION DEL PLANTEAMIENTO (11 COMPROBACIONES)
A2: MEJORAMIENTO Y AMPLIACION DEL SERVICIO DE EDUCACION PRIMARIA EN LA I.E. N.° 0590, DISTRITO DE BARRANQUITA, PROVINCIA DE LAMAS, DEPARTAMENTO DE SAN MARTIN - C.I. N.° 468901
A4: N. | B4: COMPROBACION | C4: RESULTADO | D4: DETALLE
A5: 1 | B5: Conectividad: todos los ramales llegan a una descarga | C5: CUMPLE | D5: 19 ramales: EJE-01->D1, EJE-02->D1, EJE-03->D1, EJE-04->D1, EJE-05->D1, EJE-06->D1, EJE-07->D3, EJE-08->D3, EJE-09->D3, EJE-10->D3, EJE-11->D3, EJE-12->D2, EJE-13->D2, EJE-14->D2, EJE-15->D2, EJE-16->D2, EJE-17->D4, EJE-18->D4, EJE-19->D4
A6: 2 | B6: Sin contrapendiente en la cota de fondo (cada 0.50 m) | C6: CUMPLE | D6: la cota de fondo baja en todos los puntos
A7: 3 | B7: Pendiente minima de la cota de fondo >= 0.5 % | C7: CUMPLE | D7: minima 0.50 % (EJE-01 P-01-P-02); maxima 20.16 %
A8: 4 | B8: Profundidad: 0.30 m al inicio y >= 0.25 m en todo el recorrido | C8: CUMPLE | D8: inicio 0.30 a 0.30; minima 0.25 (EJE-01); maxima 0.92 (EJE-07, prog 96.2)
A9: 5 | B9: Empalmes: la cuneta que llega no queda por debajo de la que recibe | C9: CUMPLE | D9: 15 empalmes; caida maxima 0.34 m (EJE-16 en P-44)
A10: 6 | B10: Descargas por el cerco: el agua sale por gravedad al terreno exterior sin obras fuera del cerco | C10: CUMPLE | D10: D1 C.F. 183.660: pase en el cimiento del cerco; el terreno exterior queda bajo la C.F. a 0.5 m del cerco; D2 C.F. 183.704: pase en el cimiento del cerco; el terreno exterior queda bajo la C.F. a 0.2 m del cerco; D3 C.F. 183.576: pase en el cimiento del cerco; el terreno exterior queda bajo la C.F. a 1.0 m del cerco; D4 C.F. 184.099: pase en el cimiento del cerco; el terreno exterior queda bajo la C.F. a 0.5 m del cerco
A11: 7 | B11: Borde de la cuneta 0.05 m bajo el NPT (+184.65) y 0.05 m sobre el area verde (+184.55) | C11: CUMPLE | D11: borde de cuneta +184.60 en la red dentro del cerco (NPT +184.65, area verde +184.55); junto al patio de maniobra (NTN +184.50) borde al ras +184.50 en 292 puntos
A12: 8 | B12: Capacidad con el caudal de diseno (borde libre >= 0.05 m) | C12: CUMPLE | D12: I = 211 mm/h, C = 0.80, area total 9393 m2; menor borde libre 0.115 m en EJE-01 P-03-D1 (Q 190.8 l/s, y 0.135, h 0.25)
A13: 9 | B13: Velocidad maxima 3.0 m/s (concreto) | C13: CUMPLE CON GRADAS | D13: tramos de fuerte pendiente con V > 3.0 m/s: EJE-01 P-03-D1 (S 8.0 %, V 3.91), EJE-07 P-30-D3 (S 17.2 %, V 4.37) -> gradas (escalones) de concreto
A14: 10 | B14: El eje no corta muros de los bloques (>= 0.30 m) | C14: CUMPLE | D14: distancia minima eje-muro 1.22 m en 1993 puntos revisados
A15: 11 | B15: Toda la red dentro del cerco perimetrico (limite de intervencion) | C15: CUMPLE | D15: ningun borde de cuneta pasa el cerco; solo las 4 salidas lo atraviesan
B17: DESCARGAS
B18: DESCARGA | C18: COTA DE FONDO | D18: SALIDA POR GRAVEDAD
B19: D1 | C19: 183.66 | D19: pase en el cimiento del cerco: el terreno exterior queda bajo la C.F. a 0.5 m (perfilado maximo 0.11 m, sin obra)
B20: D2 | C20: 183.704 | D20: pase en el cimiento del cerco: el terreno exterior queda bajo la C.F. a 0.2 m (perfilado maximo 0.00 m, sin obra)
B21: D3 | C21: 183.576 | D21: pase en el cimiento del cerco: el terreno exterior queda bajo la C.F. a 1.0 m (perfilado maximo 0.16 m, sin obra)
B22: D4 | C22: 184.099 | D22: pase en el cimiento del cerco: el terreno exterior queda bajo la C.F. a 0.5 m (perfilado maximo 0.15 m, sin obra)

Sheet CRITERIOS
A1: CRITERIOS DEL PLANTEAMIENTO PRELIMINAR DE CUNETAS
A2: MEJORAMIENTO Y AMPLIACION DEL SERVICIO DE EDUCACION PRIMARIA EN LA I.E. N.° 0590, DISTRITO DE BARRANQUITA, PROVINCIA DE LAMAS, DEPARTAMENTO DE SAN MARTIN - C.I. N.° 468901
A4: PARAMETRO | B4: VALOR | C4: UND | D4: OBSERVACION
A5: Ancho libre de la cuneta (b) | B5: 0.4 | C5: m | D5: Seccion rectangular de concreto
A6: Espesor de muros | B6: 0.1 | C6: m | D6: Ancho total = b + 2 muros
A7: Ancho total | B7: =B5+2*B6 | C7: m | D7: Criterio del usuario: 0.60 m
A8: Profundidad al inicio de cada ramal | B8: 0.3 | C8: m | D8: Criterio del usuario
A9: Profundidad minima | B9: 0.25 | C9: m | D9: Donde el terreno cae mas que la cuneta
A10: Pendiente de la cota de fondo | B10: 0.005 | C10: m/m | D10: 0.5 %; mayor donde el terreno cae mas
A11: Borde superior de la cuneta (rasante) | B11: 184.6 | C11: m | D11: Indicacion del usuario: NPT +184.65 (pisos y pasadizos), area verde +184.55
A12: Coeficiente de Manning (concreto) | B12: 0.013 | D12: Para la capacidad de cada tramo
A13: Borde libre | B13: 0.05 | C13: m | D13: Tirante maximo = h - borde libre
A15: Celda amarilla = dato; celda verde = formula. Los cambios de criterio se reflejan en las capacidades (hoja TRAMOS); las cotas de fondo vienen del trazo (rehacer el calculo si cambian h inicial o S).

Sheet HIDRAULICA
A1: CAUDAL DE DISENO, TIRANTE Y VELOCIDAD POR TRAMO (REFERENCIAL)
A2: MEJORAMIENTO Y AMPLIACION DEL SERVICIO DE EDUCACION PRIMARIA EN LA I.E. N.° 0590, DISTRITO DE BARRANQUITA, PROVINCIA DE LAMAS, DEPARTAMENTO DE SAN MARTIN - C.I. N.° 468901
A4: C (escorrentia) | B4: 0.8
A5: I (mm/h) | B5: 211
A6: Factor de seguridad | B6: 1.15
A7: Velocidad maxima (m/s) | B7: 3
A8: I: tc = 10 min, TR = 25 anos, P10 = 35.16 mm (estacion usada en el Hogar de Refugio - Morales); reemplazar por la del proyecto. Area tributaria: cada m2 dentro del cerco a la cuneta mas cercana.
A10: EJE | B10: DE | C10: A | D10: AREA (m2) | E10: Q (l/s) | F10: S (%) | G10: TIRANTE y (m) | H10: h (m) | I10: BORDE LIBRE (m) | J10: V (m/s) | K10: CAPACIDAD | L10: VELOCIDAD | M10: OBSERVACION
A11: EJE-01 | B11: P-01 | C11: P-02 | D11: 533 | E11: =1000*$B$4*$B$5*D11/3600000*$B$6 | F11: 0.5 | G11: 0.095 | H11: 0.3 | I11: =H11-G11 | J11: 0.84 | K11: =IF(I11>=0.05,"CUMPLE","NO CUMPLE") | L11: =IF(J11<=$B$7,"CUMPLE","GRADAS")
A12: EJE-01 | B12: P-02 | C12: P-03 | D12: 553 | E12: =1000*$B$4*$B$5*D12/3600000*$B$6 | F12: 20.16 | G12: 0.029 | H12: 0.46 | I12: =H12-G12 | J12: 2.82 | K12: =IF(I12>=0.05,"CUMPLE","NO CUMPLE") | L12: =IF(J12<=$B$7,"CUMPLE","GRADAS")
A13: EJE-01 | B13: P-03 | C13: D1 | D13: 3539 | E13: =1000*$B$4*$B$5*D13/3600000*$B$6 | F13: 8.03 | G13: 0.135 | H13: 0.25 | I13: =H13-G13 | J13: 3.91 | K13: =IF(I13>=0.05,"CUMPLE","NO CUMPLE") | L13: =IF(J13<=$B$7,"CUMPLE","GRADAS") | M13: gradas de concreto (escalones) en este tramo
A14: EJE-02 | B14: P-04 | C14: P-05 | D14: 436 | E14: =1000*$B$4*$B$5*D14/3600000*$B$6 | F14: 0.5 | G14: 0.083 | H14: 0.3 | I14: =H14-G14 | J14: 0.78 | K14: =IF(I14>=0.05,"CUMPLE","NO CUMPLE") | L14: =IF(J14<=$B$7,"CUMPLE","GRADAS")
A15: EJE-02 | B15: P-05 | C15: P-06 | D15: 528 | E15: =1000*$B$4*$B$5*D15/3600000*$B$6 | F15: 0.5 | G15: 0.094 | H15: 0.46 | I15: =H15-G15 | J15: 0.83 | K15: =IF(I15>=0.05,"CUMPLE","NO CUMPLE") | L15: =IF(J15<=$B$7,"CUMPLE","GRADAS")
A16: EJE-02 | B16: P-06 | C16: P-07 | D16: 965 | E16: =1000*$B$4*$B$5*D16/3600000*$B$6 | F16: 2.93 | G16: 0.078 | H16: 0.52 | I16: =H16-G16 | J16: 1.84 | K16: =IF(I16>=0.05,"CUMPLE","NO CUMPLE") | L16: =IF(J16<=$B$7,"CUMPLE","GRADAS")
A17: EJE-02 | B17: P-07 | C17: P-08 | D17: 2216 | E17: =1000*$B$4*$B$5*D17/3600000*$B$6 | F17: 0.5 | G17: 0.269 | H17: 0.77 | I17: =H17-G17 | J17: 1.24 | K17: =IF(I17>=0.05,"CUMPLE","NO CUMPLE") | L17: =IF(J17<=$B$7,"CUMPLE","GRADAS")
A18: EJE-02 | B18: P-08 | C18: P-03 | D18: 2979 | E18: =1000*$B$4*$B$5*D18/3600000*$B$6 | F18: 0.5 | G18: 0.339 | H18: 0.83 | I18: =H18-G18 | J18: 1.33 | K18: =IF(I18>=0.05,"CUMPLE","NO CUMPLE") | L18: =IF(J18<=$B$7,"CUMPLE","GRADAS")
A19: EJE-03 | B19: P-09 | C19: P-06 | D19: 368 | E19: =1000*$B$4*$B$5*D19/3600000*$B$6 | F19: 0.5 | G19: 0.074 | H19: 0.3 | I19: =H19-G19 | J19: 0.74 | K19: =IF(I19>=0.05,"CUMPLE","NO CUMPLE") | L19: =IF(J19<=$B$7,"CUMPLE","GRADAS")
A20: EJE-04 | B20: P-10 | C20: P-11 | D20: 383 | E20: =1000*$B$4*$B$5*D20/3600000*$B$6 | F20: 0.5 | G20: 0.076 | H20: 0.3 | I20: =H20-G20 | J20: 0.75 | K20: =IF(I20>=0.05,"CUMPLE","NO CUMPLE") | L20: =IF(J20<=$B$7,"CUMPLE","GRADAS")
A21: EJE-04 | B21: P-11 | C21: P-12 | D21: 456 | E21: =1000*$B$4*$B$5*D21/3600000*$B$6 | F21: 0.5 | G21: 0.085 | H21: 0.43 | I21: =H21-G21 | J21: 0.79 | K21: =IF(I21>=0.05,"CUMPLE","NO CUMPLE") | L21: =IF(J21<=$B$7,"CUMPLE","GRADAS")
A22: EJE-04 | B22: P-12 | C22: P-13 | D22: 585 | E22: =1000*$B$4*$B$5*D22/3600000*$B$6 | F22: 0.5 | G22: 0.101 | H22: 0.48 | I22: =H22-G22 | J22: 0.86 | K22: =IF(I22>=0.05,"CUMPLE","NO CUMPLE") | L22: =IF(J22<=$B$7,"CUMPLE","GRADAS")
A23: EJE-04 | B23: P-13 | C23: P-14 | D23: 782 | E23: =1000*$B$4*$B$5*D23/3600000*$B$6 | F23: 0.5 | G23: 0.124 | H23: 0.5 | I23: =H23-G23 | J23: 0.94 | K23: =IF(I23>=0.05,"CUMPLE","NO CUMPLE") | L23: =IF(J23<=$B$7,"CUMPLE","GRADAS")
A24: EJE-04 | B24: P-14 | C24: P-15 | D24: 858 | E24: =1000*$B$4*$B$5*D24/3600000*$B$6 | F24: 0.5 | G24: 0.132 | H24: 0.58 | I24: =H24-G24 | J24: 0.97 | K24: =IF(I24>=0.05,"CUMPLE","NO CUMPLE") | L24: =IF(J24<=$B$7,"CUMPLE","GRADAS")
A25: EJE-04 | B25: P-15 | C25: P-07 | D25: 1161 | E25: =1000*$B$4*$B$5*D25/3600000*$B$6 | F25: 0.5 | G25: 0.165 | H25: 0.61 | I25: =H25-G25 | J25: 1.05 | K25: =IF(I25>=0.05,"CUMPLE","NO CUMPLE") | L25: =IF(J25<=$B$7,"CUMPLE","GRADAS")
... A40: EJE-07 | B40: P-29 | C40: P-30 | D40: 2191 | E40: =1000*$B$4*$B$5*D40/3600000*$B$6 | F40: 0.5 | G40: 0.266 | H40: 0.88 | I40: =H40-G40 | J40: 1.24 | K40: =IF(I40>=0.05,"CUMPLE","NO CUMPLE") | L40: =IF(J40<=$B$7,"CUMPLE","GRADAS")
A41: EJE-07 | B41: P-30 | C41: D3 | D41: 2193 | E41: =1000*$B$4*$B$5*D41/3600000*$B$6 | F41: 17.21 | G41: 0.075 | H41: 0.25 | I41: =H41-G41 | J41: 4.37 | K41: =IF(I41>=0.05,"CUMPLE","NO CUMPLE") | L41: =IF(J41<=$B$7,"CUMPLE","GRADAS") | M41: gradas de concreto (escalones) en este tramo
A42: EJE-08 | B42: P-31 | C42: P-32 | D42: 47 | E42: =1000*$B$4*$B$5*D42/3600000*$B$6 | F42: 0.5 | G42: 0.02 | H42: 0.3 | I42: =H42-G42 | J42: 0.35 | K42: =IF(I42>=0.05,"CUMPLE","NO CUMPLE") | L42: =IF(J42<=$B$7,"CUMPLE","GRADAS")
A43: EJE-08 | B43: P-32 | C43: P-23 | D43: 488 | E43: =1000*$B$4*$B$5*D43/3600000*$B$6 | F43: 0.5 | G43: 0.089 | H43: 0.32 | I43: =H43-G43 | J43: 0.81 | K43: =IF(I43>=0.05,"CUMPLE","NO CUMPLE") | L43: =IF(J43<=$B$7,"CUMPLE","GRADAS")
A44: EJE-09 | B44: P-33 | C44: P-24 | D44: 342 | E44: =1000*$B$4*$B$5*D44/3600000*$B$6 | F44: 0.5 | G44: 0.07 | H44: 0.3 | I44: =H44-G44 | J44: 0.72 | K44: =IF(I44>=0.05,"CUMPLE","NO CUMPLE") | L44: =IF(J44<=$B$7,"CUMPLE","GRADAS")
A45: EJE-10 | B45: P-32 | C45: P-33 | D45: 205 | E45: =1000*$B$4*$B$5*D45/3600000*$B$6 | F45: 0.5 | G45: 0.05 | H45: 0.3 | I45: =H45-G45 | J45: 0.61 | K45: =IF(I45>=0.05,"CUMPLE","NO CUMPLE") | L45: =IF(J45<=$B$7,"CUMPLE","GRADAS")
A46: EJE-10 | B46: P-33 | C46: P-34 | D46: 239 | E46: =1000*$B$4*$B$5*D46/3600000*$B$6 | F46: 0.5 | G46: 0.055 | H46: 0.39 | I46: =H46-G46 | J46: 0.64 | K46: =IF(I46>=0.05,"CUMPLE","NO CUMPLE") | L46: =IF(J46<=$B$7,"CUMPLE","GRADAS")
A47: EJE-10 | B47: P-34 | C47: P-25 | D47: 335 | E47: =1000*$B$4*$B$5*D47/3600000*$B$6 | F47: 0.5 | G47: 0.069 | H47: 0.42 | I47: =H47-G47 | J47: 0.72 | K47: =IF(I47>=0.05,"CUMPLE","NO CUMPLE") | L47: =IF(J47<=$B$7,"CUMPLE","GRADAS")
A48: EJE-11 | B48: P-35 | C48: P-26 | D48: 301 | E48: =1000*$B$4*$B$5*D48/3600000*$B$6 | F48: 0.5 | G48: 0.064 | H48: 0.3 | I48: =H48-G48 | J48: 0.69 | K48: =IF(I48>=0.05,"CUMPLE","NO CUMPLE") | L48: =IF(J48<=$B$7,"CUMPLE","GRADAS")
A49: EJE-12 | B49: P-36 | C49: P-37 | D49: 242 | E49: =1000*$B$4*$B$5*D49/3600000*$B$6 | F49: 0.5 | G49: 0.056 | H49: 0.3 | I49: =H49-G49 | J49: 0.64 | K49: =IF(I49>=0.05,"CUMPLE","NO CUMPLE") | L49: =IF(J49<=$B$7,"CUMPLE","GRADAS")
A50: EJE-12 | B50: P-37 | C50: P-38 | D50: 532 | E50: =1000*$B$4*$B$5*D50/3600000*$B$6 | F50: 0.5 | G50: 0.095 | H50: 0.38 | I50: =H50-G50 | J50: 0.83 | K50: =IF(I50>=0.05,"CUMPLE","NO CUMPLE") | L50: =IF(J50<=$B$7,"CUMPLE","GRADAS")
A51: EJE-12 | B51: P-38 | C51: P-39 | D51: 855 | E51: =1000*$B$4*$B$5*D51/3600000*$B$6 | F51: 0.5 | G51: 0.132 | H51: 0.5 | I51: =H51-G51 | J51: 0.97 | K51: =IF(I51>=0.05,"CUMPLE","NO CUMPLE") | L51: =IF(J51<=$B$7,"CUMPLE","GRADAS")
A52: EJE-12 | B52: P-39 | C52: P-40 | D52: 1128 | E52: =1000*$B$4*$B$5*D52/3600000*$B$6 | F52: 0.5 | G52: 0.161 | H52: 0.57 | I52: =H52-G52 | J52: 1.05 | K52: =IF(I52>=0.05,"CUMPLE","NO CUMPLE") | L52: =IF(J52<=$B$7,"CUMPLE","GRADAS")
A53: EJE-12 | B53: P-40 | C53: P-41 | D53: 1869 | E53: =1000*$B$4*$B$5*D53/3600000*$B$6 | F53: 0.5 | G53: 0.235 | H53: 0.62 | I53: =H53-G53 | J53: 1.19 | K53: =IF(I53>=0.05,"CUMPLE","NO CUMPLE") | L53: =IF(J53<=$B$7,"CUMPLE","GRADAS")
... A76: EJE-19 | B76: P-62 | C76: P-61 | D76: 109 | E76: =1000*$B$4*$B$5*D76/3600000*$B$6 | F76: 0.5 | G76: 0.033 | H76: 0.3 | I76: =H76-G76 | J76: 0.48 | K76: =IF(I76>=0.05,"CUMPLE","NO CUMPLE") | L76: =IF(J76<=$B$7,"CUMPLE","GRADAS")

Sheet TRAMOS
A1: CUADRO DE TRAMOS DE CUNETAS - COTAS DE FONDO, PROFUNDIDADES, PENDIENTES Y CAPACIDAD
A2: MEJORAMIENTO Y AMPLIACION DEL SERVICIO DE EDUCACION PRIMARIA EN LA I.E. N.° 0590, DISTRITO DE BARRANQUITA, PROVINCIA DE LAMAS, DEPARTAMENTO DE SAN MARTIN - C.I. N.° 468901
A4: SISTEMA | B4: EJE | C4: DE | D4: A | E4: L (m) | F4: RASANTE DE | G4: RASANTE A | H4: COTA DE FONDO DE | I4: COTA DE FONDO A | J4: h DE (m) | K4: h A (m) | L4: S (%) | M4: TAPADO (m) | N4: CON REJILLA (m) | O4: TIRANTE MAX. (m) | P4: Q CAPACIDAD (l/s) | Q4: DESCRIPCION DEL EJE
A5: 1 | B5: EJE-01 | C5: P-01 | D5: P-02 | E5: 31.9 | F5: 184.6 | G5: 184.6 | H5: 184.3 | I5: 184.141 | J5: =F5-H5 | K5: =G5-I5 | L5: =100*(H5-I5)/E5 | M5: 0 | N5: =E5-M5 | O5: =MAX(MIN(J5,K5)-CRITERIOS!$B$13,0.01) | P5: =1000*CRITERIOS!$B$5*O5*((CRITERIOS!$B$5*O5)/(CRITERIOS!$B$5+2*O5))^(2/3)*SQRT(MAX(L5/100,CRITERIOS!$B$10))/CRITERIOS!$B$12 | Q5: Pabellon oeste A: lado nor-oeste y salida D1
A6: 1 | B6: EJE-01 | C6: P-02 | D6: P-03 | E6: 2.15 | F6: 184.6 | G6: 184.6 | H6: 184.141 | I6: 183.708 | J6: =F6-H6 | K6: =G6-I6 | L6: =100*(H6-I6)/E6 | M6: 0 | N6: =E6-M6 | O6: =MAX(MIN(J6,K6)-CRITERIOS!$B$13,0.01) | P6: =1000*CRITERIOS!$B$5*O6*((CRITERIOS!$B$5*O6)/(CRITERIOS!$B$5+2*O6))^(2/3)*SQRT(MAX(L6/100,CRITERIOS!$B$10))/CRITERIOS!$B$12 | Q6: Pabellon oeste A: lado nor-oeste y salida D1
A7: 1 | B7: EJE-01 | C7: P-03 | D7: D1 | E7: 0.6 | F7: 184.6 | G7: 183.91 | H7: 183.708 | I7: 183.66 | J7: =F7-H7 | K7: =G7-I7 | L7: =100*(H7-I7)/E7 | M7: 0.6 | N7: =E7-M7 | O7: =MAX(MIN(J7,K7)-CRITERIOS!$B$13,0.01) | P7: =1000*CRITERIOS!$B$5*O7*((CRITERIOS!$B$5*O7)/(CRITERIOS!$B$5+2*O7))^(2/3)*SQRT(MAX(L7/100,CRITERIOS!$B$10))/CRITERIOS!$B$12 | Q7: Pabellon oeste A: lado nor-oeste y salida D1
A8: 1 | B8: EJE-02 | C8: P-04 | D8: P-05 | E8: 32.42 | F8: 184.6 | G8: 184.6 | H8: 184.3 | I8: 184.138 | J8: =F8-H8 | K8: =G8-I8 | L8: =100*(H8-I8)/E8 | M8: 0 | N8: =E8-M8 | O8: =MAX(MIN(J8,K8)-CRITERIOS!$B$13,0.01) | P8: =1000*CRITERIOS!$B$5*O8*((CRITERIOS!$B$5*O8)/(CRITERIOS!$B$5+2*O8))^(2/3)*SQRT(MAX(L8/100,CRITERIOS!$B$10))/CRITERIOS!$B$12 | Q8: Pabellon oeste B: lado nor-este; pabellon A: lado sur-este; union a D1
A9: 1 | B9: EJE-02 | C9: P-05 | D9: P-06 | E9: 11.53 | F9: 184.6 | G9: 184.6 | H9: 184.138 | I9: 184.08 | J9: =F9-H9 | K9: =G9-I9 | L9: =100*(H9-I9)/E9 | M9: 0 | N9: =E9-M9 | O9: =MAX(MIN(J9,K9)-CRITERIOS!$B$13,0.01) | P9: =1000*CRITERIOS!$B$5*O9*((CRITERIOS!$B$5*O9)/(CRITERIOS!$B$5+2*O9))^(2/3)*SQRT(MAX(L9/100,CRITERIOS!$B$10))/CRITERIOS!$B$12 | Q9: Pabellon oeste B: lado nor-este; pabellon A: lado sur-este; union a D1
A10: 1 | B10: EJE-02 | C10: P-06 | D10: P-07 | E10: 8.68 | F10: 184.6 | G10: 184.6 | H10: 184.08 | I10: 183.826 | J10: =F10-H10 | K10: =G10-I10 | L10: =100*(H10-I10)/E10 | M10: 0 | N10: =E10-M10 | O10: =MAX(MIN(J10,K10)-CRITERIOS!$B$13,0.01) | P10: =1000*CRITERIOS!$B$5*O10*((CRITERIOS!$B$5*O10)/(CRITERIOS!$B$5+2*O10))^(2/3)*SQRT(MAX(L10/100,CRITERIOS!$B$10))/CRITERIOS!$B$12 | Q10: Pabellon oeste B: lado nor-este; pabellon A: lado sur-este; union a D1
A11: 1 | B11: EJE-02 | C11: P-07 | D11: P-08 | E11: 11.47 | F11: 184.6 | G11: 184.6 | H11: 183.826 | I11: 183.768 | J11: =F11-H11 | K11: =G11-I11 | L11: =100*(H11-I11)/E11 | M11: 0 | N11: =E11-M11 | O11: =MAX(MIN(J11,K11)-CRITERIOS!$B$13,0.01) | P11: =1000*CRITERIOS!$B$5*O11*((CRITERIOS!$B$5*O11)/(CRITERIOS!$B$5+2*O11))^(2/3)*SQRT(MAX(L11/100,CRITERIOS!$B$10))/CRITERIOS!$B$12 | Q11: Pabellon oeste B: lado nor-este; pabellon A: lado sur-este; union a D1
A12: 1 | B12: EJE-02 | C12: P-08 | D12: P-03 | E12: 12.1 | F12: 184.6 | G12: 184.6 | H12: 183.768 | I12: 183.708 | J12: =F12-H12 | K12: =G12-I12 | L12: =100*(H12-I12)/E12 | M12: 0 | N12: =E12-M12 | O12: =MAX(MIN(J12,K12)-CRITERIOS!$B$13,0.01) | P12: =1000*CRITERIOS!$B$5*O12*((CRITERIOS!$B$5*O12)/(CRITERIOS!$B$5+2*O12))^(2/3)*SQRT(MAX(L12/100,CRITERIOS!$B$10))/CRITERIOS!$B$12 | Q12: Pabellon oeste B: lado nor-este; pabellon A: lado sur-este; union a D1
A13: 1 | B13: EJE-03 | C13: P-09 | D13: P-06 | E13: 32.31 | F13: 184.6 | G13: 184.6 | H13: 184.3 | I13: 184.138 | J13: =F13-H13 | K13: =G13-I13 | L13: =100*(H13-I13)/E13 | M13: 0 | N13: =E13-M13 | O13: =MAX(MIN(J13,K13)-CRITERIOS!$B$13,0.01) | P13: =1000*CRITERIOS!$B$5*O13*((CRITERIOS!$B$5*O13)/(CRITERIOS!$B$5+2*O13))^(2/3)*SQRT(MAX(L13/100,CRITERIOS!$B$10))/CRITERIOS!$B$12 | Q13: Pabellon oeste B: lado sur-oeste (patio)
A14: 1 | B14: EJE-04 | C14: P-10 | D14: P-11 | E14: 26.1 | F14: 184.6 | G14: 184.6 | H14: 184.3 | I14: 184.17 | J14: =F14-H14 | K14: =G14-I14 | L14: =100*(H14-I14)/E14 | M14: 0 | N14: =E14-M14 | O14: =MAX(MIN(J14,K14)-CRITERIOS!$B$13,0.01) | P14: =1000*CRITERIOS!$B$5*O14*((CRITERIOS!$B$5*O14)/(CRITERIOS!$B$5+2*O14))^(2/3)*SQRT(MAX(L14/100,CRITERIOS!$B$10))/CRITERIOS!$B$12 | Q14: Bloque x=884.9 (lado oeste), bloque D (lado norte) y pabellon C (lado nor-este)
A15: 1 | B15: EJE-04 | C15: P-11 | D15: P-12 | E15: 9.43 | F15: 184.6 | G15: 184.6 | H15: 184.17 | I15: 184.122 | J15: =F15-H15 | K15: =G15-I15 | L15: =100*(H15-I15)/E15 | M15: 0 | N15: =E15-M15 | O15: =MAX(MIN(J15,K15)-CRITERIOS!$B$13,0.01) | P15: =1000*CRITERIOS!$B$5*O15*((CRITERIOS!$B$5*O15)/(CRITERIOS!$B$5+2*O15))^(2/3)*SQRT(MAX(L15/100,CRITERIOS!$B$10))/CRITERIOS!$B$12 | Q15: Bloque x=884.9 (lado oeste), bloque D (lado norte) y pabellon C (lado nor-este)
A16: 1 | B16: EJE-04 | C16: P-12 | D16: P-13 | E16: 3.78 | F16: 184.6 | G16: 184.6 | H16: 184.122 | I16: 184.103 | J16: =F16-H16 | K16: =G16-I16 | L16: =100*(H16-I16)/E16 | M16: 0 | N16: =E16-M16 | O16: =MAX(MIN(J16,K16)-CRITERIOS!$B$13,0.01) | P16: =1000*CRITERIOS!$B$5*O16*((CRITERIOS!$B$5*O16)/(CRITERIOS!$B$5+2*O16))^(2/3)*SQRT(MAX(L16/100,CRITERIOS!$B$10))/CRITERIOS!$B$12 | Q16: Bloque x=884.9 (lado oeste), bloque D (lado norte) y pabellon C (lado nor-este)
... A70: 4 | B70: EJE-19 | C70: P-62 | D70: P-61 | E70: 13.84 | F70: 184.6 | G70: 184.6 | H70: 184.3 | I70: 184.231 | J70: =F70-H70 | K70: =G70-I70 | L70: =100*(H70-I70)/E70 | M70: 0 | N70: =E70-M70 | O70: =MAX(MIN(J70,K70)-CRITERIOS!$B$13,0.01) | P70: =1000*CRITERIOS!$B$5*O70*((CRITERIOS!$B$5*O70)/(CRITERIOS!$B$5+2*O70))^(2/3)*SQRT(MAX(L70/100,CRITERIOS!$B$10))/CRITERIOS!$B$12 | Q70: Bloque del centro: lado norte (y=851.7), tramo oeste
D71: TOTAL | E71: =SUM(E5:E70) | M71: =SUM(M5:M70) | N71: =SUM(N5:N70)

Sheet NUDOS
A1: NUDOS DE LA RED (COORDENADAS UTM WGS84 DEL PLANO DE ARQUITECTURA)
A2: MEJORAMIENTO Y AMPLIACION DEL SERVICIO DE EDUCACION PRIMARIA EN LA I.E. N.° 0590, DISTRITO DE BARRANQUITA, PROVINCIA DE LAMAS, DEPARTAMENTO DE SAN MARTIN - C.I. N.° 468901
A4: NUDO | B4: ESTE (m) | C4: NORTE (m) | D4: EJES QUE PASAN | E4: DESCARGA / OBSERVACION
A5: P-01 | B5: 354844.67 | C5: 9249873.9 | D5: EJE-01
A6: P-02 | B6: 354822.02 | C6: 9249851.4 | D6: EJE-01
A7: P-03 | B7: 354820.54 | C7: 9249849.9 | D7: EJE-01, EJE-02
A8: P-04 | B8: 354876.15 | C8: 9249842.9 | D8: EJE-02
A9: P-05 | B9: 354853.1 | C9: 9249865.7 | D9: EJE-02
A10: P-06 | B10: 354844.95 | C10: 9249857.6 | D10: EJE-02, EJE-03
A11: P-07 | B11: 354838.81 | C11: 9249851.4 | D11: EJE-02, EJE-04
A12: P-08 | B12: 354830.7 | C12: 9249843.3 | D12: EJE-02, EJE-05
A13: P-09 | B13: 354867.8 | C13: 9249834.7 | D13: EJE-03
A14: P-10 | B14: 354884.91 | C14: 9249851.5 | D14: EJE-04
A15: P-11 | B15: 354884.91 | C15: 9249825.4 | D15: EJE-04
A16: P-12 | B16: 354885.1 | C16: 9249816 | D16: EJE-04, EJE-06
... A66: P-62 | B66: 354897.16 | C66: 9249851.7 | D66: EJE-19
A67: D1 | B67: 354820.12 | C67: 9249849.4 | D67: EJE-01 | E67: Cerco sur-oeste (lado C22-C1, x = 820.1): al talud natural que baja a la quebrada del oeste
A68: D2 | B68: 354965.5 | C68: 9249869.6 | D68: EJE-12 | E68: Cerco norte (x = 965.5): pase en el cimiento del cerco al terreno exterior que baja a la quebrada del norte
A69: D3 | B69: 354935.5 | C69: 9249792.2 | D69: EJE-07 | E69: Cerco sur junto a C14 (x = 935.5): al terreno exterior que baja al Jr. Alfonso Ugarte (183.00)
A70: D4 | B70: 354911 | C70: 9249854.7 | D70: EJE-17 | E70: Cerco norte (lado C3-C4, x = 911.0): al talud natural que baja a la quebrada del norte

Sheet SECCIONES
A1: SECCIONES DE LOS PERFILES LONGITUDINALES POR EJE
A2: MEJORAMIENTO Y AMPLIACION DEL SERVICIO DE EDUCACION PRIMARIA EN LA I.E. N.° 0590, DISTRITO DE BARRANQUITA, PROVINCIA DE LAMAS, DEPARTAMENTO DE SAN MARTIN - C.I. N.° 468901
A4: SECCION | B4: EJE | C4: PROGRESIVA (m) | D4: NCT | E4: NCF | F4: H (m) | G4: EL (m) | H4: EM (m) | I4: TIPO | J4: OBSERVACION
A5: S-01 | B5: EJE-01 | C5: 0 | D5: 184.6 | E5: 184.3 | F5: =D5-E5 | G5: 0.1 | H5: 0.1 | I5: CON REJILLA | J5: Inicio del eje
A6: S-02 | B6: EJE-01 | C6: 31.9 | D6: 184.6 | E6: 184.141 | F6: =D6-E6 | G6: 0.1 | H6: 0.1 | I6: CON REJILLA
A7: S-03 | B7: EJE-01 | C7: 34.05 | D7: 184.6 | E7: 183.708 | F7: =D7-E7 | G7: 0.1 | H7: 0.1 | I7: TAPADA | J7: Llega EJE-02
A8: S-04 | B8: EJE-01 | C8: 34.64 | D8: 183.91 | E8: 183.66 | F8: =D8-E8 | G8: 0.1 | H8: 0.1 | I8: TAPADA | J8: Descarga D1
A9: S-05 | B9: EJE-02 | C9: 0 | D9: 184.6 | E9: 184.3 | F9: =D9-E9 | G9: 0.1 | H9: 0.1 | I9: CON REJILLA | J9: Inicio del eje
A10: S-06 | B10: EJE-02 | C10: 32.42 | D10: 184.6 | E10: 184.138 | F10: =D10-E10 | G10: 0.1 | H10: 0.1 | I10: CON REJILLA
A11: S-07 | B11: EJE-02 | C11: 43.95 | D11: 184.6 | E11: 184.08 | F11: =D11-E11 | G11: 0.1 | H11: 0.1 | I11: CON REJILLA | J11: Llega EJE-03
A12: S-08 | B12: EJE-02 | C12: 52.63 | D12: 184.6 | E12: 183.826 | F12: =D12-E12 | G12: 0.1 | H12: 0.1 | I12: CON REJILLA | J12: Llega EJE-04
A13: S-09 | B13: EJE-02 | C13: 64.1 | D13: 184.6 | E13: 183.768 | F13: =D13-E13 | G13: 0.1 | H13: 0.1 | I13: CON REJILLA | J13: Llega EJE-05
A14: S-10 | B14: EJE-02 | C14: 76.2 | D14: 184.6 | E14: 183.708 | F14: =D14-E14 | G14: 0.1 | H14: 0.1 | I14: CON REJILLA | J14: Entrega a EJE-01
A15: S-11 | B15: EJE-03 | C15: 0 | D15: 184.6 | E15: 184.3 | F15: =D15-E15 | G15: 0.1 | H15: 0.1 | I15: CON REJILLA | J15: Inicio del eje
A16: S-12 | B16: EJE-03 | C16: 32.31 | D16: 184.6 | E16: 184.138 | F16: =D16-E16 | G16: 0.1 | H16: 0.1 | I16: CON REJILLA | J16: Entrega a EJE-02
A17: S-13 | B17: EJE-04 | C17: 0 | D17: 184.6 | E17: 184.3 | F17: =D17-E17 | G17: 0.1 | H17: 0.1 | I17: CON REJILLA | J17: Inicio del eje
A18: S-14 | B18: EJE-04 | C18: 26.1 | D18: 184.6 | E18: 184.17 | F18: =D18-E18 | G18: 0.1 | H18: 0.1 | I18: CON REJILLA
A19: S-15 | B19: EJE-04 | C19: 35.53 | D19: 184.6 | E19: 184.122 | F19: =D19-E19 | G19: 0.1 | H19: 0.1 | I19: CON REJILLA | J19: Llega EJE-06
A20: S-16 | B20: EJE-04 | C20: 39.31 | D20: 184.6 | E20: 184.103 | F20: =D20-E20 | G20: 0.1 | H20: 0.1 | I20: CON REJILLA
A21: S-17 | B21: EJE-04 | C21: 55.28 | D21: 184.6 | E21: 184.024 | F21: =D21-E21 | G21: 0.1 | H21: 0.1 | I21: CON REJILLA
A22: S-18 | B22: EJE-04 | C22: 62.07 | D22: 184.6 | E22: 183.99 | F22: =D22-E22 | G22: 0.1 | H22: 0.1 | I22: CON REJILLA
A23: S-19 | B23: EJE-04 | C23: 94.88 | D23: 184.6 | E23: 183.826 | F23: =D23-E23 | G23: 0.1 | H23: 0.1 | I23: CON REJILLA | J23: Entrega a EJE-02
A24: S-20 | B24: EJE-05 | C24: 0 | D24: 184.6 | E24: 184.3 | F24: =D24-E24 | G24: 0.1 | H24: 0.1 | I24: CON REJILLA | J24: Inicio del eje
A25: S-21 | B25: EJE-05 | C25: 21.32 | D25: 184.6 | E25: 184.193 | F25: =D25-E25 | G25: 0.1 | H25: 0.1 | I25: CON REJILLA
A26: S-22 | B26: EJE-05 | C26: 27.21 | D26: 184.6 | E26: 184.164 | F26: =D26-E26 | G26: 0.1 | H26: 0.1 | I26: CON REJILLA
A27: S-23 | B27: EJE-05 | C27: 45.04 | D27: 184.6 | E27: 184.075 | F27: =D27-E27 | G27: 0.1 | H27: 0.1 | I27: CON REJILLA
A28: S-24 | B28: EJE-05 | C28: 50.81 | D28: 184.6 | E28: 184.046 | F28: =D28-E28 | G28: 0.1 | H28: 0.1 | I28: CON REJILLA
A29: S-25 | B29: EJE-05 | C29: 89.97 | D29: 184.6 | E29: 183.85 | F29: =D29-E29 | G29: 0.1 | H29: 0.1 | I29: CON REJILLA | J29: Entrega a EJE-02
A30: S-26 | B30: EJE-06 | C30: 0 | D30: 184.6 | E30: 184.3 | F30: =D30-E30 | G30: 0.1 | H30: 0.1 | I30: CON REJILLA | J30: Inicio del eje
A31: S-27 | B31: EJE-06 | C31: 11.74 | D31: 184.6 | E31: 184.241 | F31: =D31-E31 | G31: 0.1 | H31: 0.1 | I31: CON REJILLA | J31: Entrega a EJE-04
A32: S-28 | B32: EJE-07 | C32: 0 | D32: 184.6 | E32: 184.3 | F32: =D32-E32 | G32: 0.1 | H32: 0.1 | I32: CON REJILLA | J32: Inicio del eje
A33: S-29 | B33: EJE-07 | C33: 11.51 | D33: 184.6 | E33: 184.102 | F33: =D33-E33 | G33: 0.1 | H33: 0.1 | I33: CON REJILLA | J33: Llega EJE-08
A34: S-30 | B34: EJE-07 | C34: 29.36 | D34: 184.6 | E34: 184.012 | F34: =D34-E34 | G34: 0.1 | H34: 0.1 | I34: CON REJILLA | J34: Llega EJE-09
A35: S-31 | B35: EJE-07 | C35: 35.48 | D35: 184.6 | E35: 183.982 | F35: =D35-E35 | G35: 0.1 | H35: 0.1 | I35: CON REJILLA
A36: S-32 | B36: EJE-07 | C36: 58.25 | D36: 184.6 | E36: 183.868 | F36: =D36-E36 | G36: 0.1 | H36: 0.1 | I36: CON REJILLA | J36: Llega EJE-10
A37: S-33 | B37: EJE-07 | C37: 70.02 | D37: 184.6 | E37: 183.809 | F37: =D37-E37 | G37: 0.1 | H37: 0.1 | I37: CON REJILLA | J37: Llega EJE-11
A38: S-34 | B38: EJE-07 | C38: 73.09 | D38: 184.6 | E38: 183.794 | F38: =D38-E38 | G38: 0.1 | H38: 0.1 | I38: TAPADA
A39: S-35 | B39: EJE-07 | C39: 81.05 | D39: 184.6 | E39: 183.754 | F39: =D39-E39 | G39: 0.1 | H39: 0.1 | I39: TAPADA
A40: S-36 | B40: EJE-07 | C40: 87.74 | D40: 184.6 | E40: 183.72 | F40: =D40-E40 | G40: 0.1 | H40: 0.1 | I40: TAPADA
A41: S-37 | B41: EJE-07 | C41: 95.95 | D41: 184.6 | E41: 183.679 | F41: =D41-E41 | G41: 0.1 | H41: 0.1 | I41: TAPADA
...
