Workbook

Sheet RESUMEN
A1: MEMORIA DE CALCULO - DRENAJE PLUVIAL (RED DE CUNETAS)
A2: PROYECTO: “MEJORAMIENTO Y AMPLIACIÓN DEL SERVICIO DE EDUCACIÓN PRIMARIA EN I.E. N° 0590 DISTRITO DE BARRANQUITA DE LA PROVINCIA DE LAMAS DEL DEPARTAMENTO DE SAN MARTÍN” - C.I. N° 468901
A3: ENTIDAD: GOBIERNO REGIONAL SAN MARTIN - GERENCIA TERRITORIAL BAJO MAYO - TARAPOTO - UBICACION: SAN MARTIN - LAMAS - BARRANQUITA - FECHA: OCTUBRE 2026
A8: CONCEPTO | B8: VALOR
A9: Estacion de referencia | B9: Pongo de Caynarachi (SENAMHI, codigo 003317), 1989–2013, 25 anos
A10: Factor aplicado a la serie | B10: =DATOS!B7
A11: Distribucion adoptada | B11: Log-Pearson III (menor D de Kolmogorov-Smirnov)
A12: Periodo de retorno (anos) | B12: =DATOS!B8
A13: Precipitacion maxima en 24 h de diseno (mm) | B13: =DATOS!B15
A14: Tiempo de concentracion (min) | B14: =DATOS!B9
A15: Intensidad de diseno (mm/h) | B15: =DATOS!B17
A16: Coeficiente de escorrentia ponderado | B16: =SUPERFICIES!C13
A17: Area de aporte dentro del cerco (m2) | B17: =SUPERFICIES!B13
A18: Caudal maximo en un tramo (l/s) | B18: =MAX(CAUDALES!H9:H99)
A19: Menor borde libre (m) | B19: =MIN(CAUDALES!P9:P99)
A20: Velocidad maxima (m/s) | B20: =MAX(CAUDALES!S9:S99)
A21: Tramos que no cumplen capacidad | B21: =COUNTIF(CAUDALES!Q9:Q99,"NO CUMPLE")
A22: Seccion de cuneta | B22: 0.60 m de ancho total: muros de 0.10 m y 0.40 m libres; profundidad variable 0.30 a 0.91 m

Sheet DATOS
A1: DATOS GENERALES Y PARAMETROS DE DISENO
A2: PROYECTO: “MEJORAMIENTO Y AMPLIACIÓN DEL SERVICIO DE EDUCACIÓN PRIMARIA EN I.E. N° 0590 DISTRITO DE BARRANQUITA DE LA PROVINCIA DE LAMAS DEL DEPARTAMENTO DE SAN MARTÍN” - C.I. N° 468901
A3: ENTIDAD: GOBIERNO REGIONAL SAN MARTIN - GERENCIA TERRITORIAL BAJO MAYO - TARAPOTO - UBICACION: SAN MARTIN - LAMAS - BARRANQUITA - FECHA: OCTUBRE 2026
A4: PARAMETRO | B4: VALOR | D4: FUENTE / CRITERIO
A5: Precipitacion media anual - estacion Pongo de Caynarachi (mm) | B5: 3853.16 | D5: Referencial: SENAMHI 2013-2017, Cuadro N° 05 del estudio hidrologico de Barranquita
A6: Precipitacion media anual - llanura de Barranquita (mm) | B6: 2375.57 | D6: Referencial: promedio de Navarro (2,349.79), Pelejo (2,332.92) y Shanusi (2,444.00), SENAMHI 2013-2017
A7: Factor aplicado a la serie de maximas | B7: 1 | D7: Serie medida de Pongo de Caynarachi (misma subcuenca del rio Caynarachi): sin transposicion
A8: Periodo de retorno de diseno T (anos) | B8: 25 | D8: Mismo criterio de los proyectos de Morales (T = 25 anos)
A9: Tiempo de concentracion de cunetas tc (min) | B9: 10 | D9: Duracion minima (Norma CE.040)
A10: Coeficiente de Manning para capacidad (concreto con rejilla) | B10: 0.015 | D10: CE.040; mismo valor de los proyectos de Morales
A11: Coeficiente de Manning para velocidad (concreto liso) | B11: 0.013 | D11: CE.040
A12: Luz libre de la cuneta b (m) | B12: 0.4 | D12: Planos DC-02: 0.40 m libres + muros 0.10 m = 0.60 m
A13: Borde libre minimo (m) | B13: 0.05 | D13: Criterio de diseno
A14: Velocidad maxima en concreto (m/s) | B14: 3 | D14: CE.040
A15: Precipitacion maxima en 24 h de diseno, T = 25 anos (mm) | B15: =FRECUENCIAS!I21 | D15: Hoja FRECUENCIAS (Log-Pearson III)
A16: Precipitacion en tc - Dick y Peschke P = P24 (tc/1440)^0.25 (mm) | B16: =B15*(B9/1440)^0.25 | D16: Dick y Peschke
A17: Intensidad de diseno I = P x 60 / tc (mm/h) | B17: =B16*60/B9 | D17: Para el metodo racional
A18: Coeficiente de escorrentia - techos y coberturas | B18: 0.88 | D18: CE.040 Anexo I, Tabla 1.a: concreto / techo, T = 25 anos
A19: Coeficiente de escorrentia - areas libres de concreto (veredas y patios) | B19: 0.88 | D19: CE.040 Anexo I, Tabla 1.a: concreto, T = 25 anos
A20: Coeficiente de escorrentia - patio de maniobra y estacionamiento | B20: 0.88 | D20: CE.040 Anexo I, Tabla 1.a: concreto, T = 25 anos
A21: Coeficiente de escorrentia - areas verdes y terreno | B21: 0.4 | D21: CE.040 Anexo I, Tabla 1.a: zona verde, valor mayor de la tabla (rellenos compactados), T = 25 anos
A22: Factor de seguridad de los caudales FS | B22: 1.15 | D22: Mismo criterio de los proyectos de Morales (Q = C I A FS)

Sheet SERIE
A1: PRECIPITACION MAXIMA EN 24 HORAS - ESTACION PONGO DE CAYNARACHI (SENAMHI, CODIGO 003317)
A2: PROYECTO: “MEJORAMIENTO Y AMPLIACIÓN DEL SERVICIO DE EDUCACIÓN PRIMARIA EN I.E. N° 0590 DISTRITO DE BARRANQUITA DE LA PROVINCIA DE LAMAS DEL DEPARTAMENTO DE SAN MARTÍN” - C.I. N° 468901
A3: ENTIDAD: GOBIERNO REGIONAL SAN MARTIN - GERENCIA TERRITORIAL BAJO MAYO - TARAPOTO - UBICACION: SAN MARTIN - LAMAS - BARRANQUITA - FECHA: OCTUBRE 2026
A8: Estacion: Pongo de Caynarachi (codigo 003317) - Meteorologica convencional - Altitud 230 m s. n. m. - Caynarachi, Lamas, San Martin - periodo 1989–2013 (25 anos completos mas recientes del registro diario)
A10: AÑO | B10: ENE | C10: FEB | D10: MAR | E10: ABR | F10: MAY | G10: JUN | H10: JUL | I10: AGO | J10: SET | K10: OCT | L10: NOV | M10: DIC | N10: P MAX ANUAL (mm) | O10: P MAX DE DISENO (mm) | P10: LOG10 P
A11: 1989 | B11: 74.4 | C11: 82.7 | D11: 80.1 | E11: 61.9 | F11: 78.4 | G11: 77.5 | H11: 76.1 | I11: 58.1 | J11: 64.4 | K11: 141.9 | L11: 69.4 | M11: 46.9 | N11: =MAX(B11:M11) | O11: =N11*DATOS!$B$7 | P11: =LOG10(O11)
A12: 1990 | B12: 81.5 | C12: 97.9 | D12: 62.6 | E12: 78.8 | F12: 61.2 | G12: 56.2 | H12: 41.6 | I12: 49.5 | J12: 65.4 | K12: 57.4 | L12: 115.1 | M12: 74 | N12: =MAX(B12:M12) | O12: =N12*DATOS!$B$7 | P12: =LOG10(O12)
A13: 1991 | B13: 46.5 | C13: 53.7 | D13: 106.7 | E13: 56.6 | F13: 60.3 | G13: 83.4 | H13: 33.4 | I13: 32.5 | J13: 95.3 | K13: 55.3 | L13: 114.8 | M13: 88.4 | N13: =MAX(B13:M13) | O13: =N13*DATOS!$B$7 | P13: =LOG10(O13)
A14: 1992 | B14: 63.3 | C14: 37.3 | D14: 103.8 | E14: 123 | F14: 98.7 | G14: 30.5 | H14: 45.3 | I14: 70.7 | J14: 60.2 | K14: 77.5 | L14: 50 | M14: 120.4 | N14: =MAX(B14:M14) | O14: =N14*DATOS!$B$7 | P14: =LOG10(O14)
A15: 1993 | B15: 64.2 | C15: 89.1 | D15: 73.7 | E15: 62.5 | F15: 72.7 | G15: 76.1 | H15: 37.3 | I15: 32.1 | J15: 75.2 | K15: 64.9 | L15: 46.6 | M15: 74 | N15: =MAX(B15:M15) | O15: =N15*DATOS!$B$7 | P15: =LOG10(O15)
A16: 1994 | B16: 63.2 | C16: 64 | D16: 143.2 | E16: 84.5 | F16: 82.1 | G16: 53.4 | H16: 76 | I16: 81.5 | J16: 65.5 | K16: 110.1 | L16: 60 | M16: 179.9 | N16: =MAX(B16:M16) | O16: =N16*DATOS!$B$7 | P16: =LOG10(O16)
A17: 1995 | B17: 37 | C17: 74.3 | D17: 77.6 | E17: 50.9 | F17: 84.2 | G17: 29.2 | H17: 30 | I17: 81.2 | J17: 44.2 | K17: 57.1 | L17: 46.1 | M17: 73.5 | N17: =MAX(B17:M17) | O17: =N17*DATOS!$B$7 | P17: =LOG10(O17)
A18: 1996 | B18: 96.4 | C18: 50.7 | D18: 73.2 | E18: 35.1 | F18: 60.2 | G18: 39.5 | H18: 14.8 | I18: 73 | J18: 29.1 | K18: 80.9 | L18: 55.9 | M18: 76.8 | N18: =MAX(B18:M18) | O18: =N18*DATOS!$B$7 | P18: =LOG10(O18)
A19: 1997 | B19: 87.3 | C19: 70.1 | D19: 53.1 | E19: 71.2 | F19: 51.5 | G19: 41.9 | H19: 17 | I19: 40 | J19: 65.5 | K19: 97.3 | L19: 86.9 | M19: 103.9 | N19: =MAX(B19:M19) | O19: =N19*DATOS!$B$7 | P19: =LOG10(O19)
A20: 1998 | B20: 72.5 | C20: 78.2 | D20: 95.4 | E20: 78.9 | F20: 67.1 | G20: 72.2 | H20: 56.6 | I20: 22 | J20: 31.9 | K20: 76.3 | L20: 171.8 | M20: 79.7 | N20: =MAX(B20:M20) | O20: =N20*DATOS!$B$7 | P20: =LOG10(O20)
A21: 1999 | B21: 146 | C21: 122 | D21: 75 | E21: 40.7 | F21: 64 | G21: 70.2 | H21: 35.5 | I21: 27.8 | J21: 61.5 | K21: 40.1 | L21: 62.1 | M21: 56.9 | N21: =MAX(B21:M21) | O21: =N21*DATOS!$B$7 | P21: =LOG10(O21)
A22: 2000 | B22: 56.8 | C22: 101.7 | D22: 59.5 | E22: 97 | F22: 65.4 | G22: 75.9 | H22: 43.1 | I22: 31.1 | J22: 108.5 | K22: 71.3 | L22: 87.4 | M22: 70.4 | N22: =MAX(B22:M22) | O22: =N22*DATOS!$B$7 | P22: =LOG10(O22)
... A26: 2004 | B26: 47.4 | C26: 81.6 | D26: 76.3 | E26: 75.3 | F26: 87 | G26: 32.5 | H26: 44.4 | I26: 55.5 | J26: 44.3 | K26: 75.5 | L26: 90.2 | M26: 66.1 | N26: =MAX(B26:M26) | O26: =N26*DATOS!$B$7 | P26: =LOG10(O26)
A27: 2005 | B27: S/D | C27: 80.8 | D27: 76.7 | E27: 97.3 | F27: 45 | G27: 65.6 | H27: 17 | I27: 75.6 | J27: 23 | K27: 70.5 | L27: 77.3 | M27: 66.2 | N27: =MAX(B27:M27) | O27: =N27*DATOS!$B$7 | P27: =LOG10(O27)
A28: 2006 | B28: 80.7 | C28: 39.5 | D28: 81.5 | E28: 66.9 | F28: 48.7 | G28: 68 | H28: 35.8 | I28: 51 | J28: 52.7 | K28: 71.6 | L28: 72.2 | M28: 102.5 | N28: =MAX(B28:M28) | O28: =N28*DATOS!$B$7 | P28: =LOG10(O28)
A29: 2007 | B29: 56.2 | C29: 33.3 | D29: 74.6 | E29: 76.5 | F29: 39.2 | G29: 46.8 | H29: 58.7 | I29: 33 | J29: 47.5 | K29: 76 | L29: 77.3 | M29: 76.5 | N29: =MAX(B29:M29) | O29: =N29*DATOS!$B$7 | P29: =LOG10(O29)
A30: 2008 | B30: 57.8 | C30: 86.9 | D30: 74 | E30: 70.5 | F30: 67 | G30: 51 | H30: S/D | I30: 25.9 | J30: 48 | K30: 55.2 | L30: 43 | M30: 100.4 | N30: =MAX(B30:M30) | O30: =N30*DATOS!$B$7 | P30: =LOG10(O30)
A31: 2009 | B31: 87 | C31: 69.7 | D31: 58 | E31: 52.2 | F31: 70 | G31: 75.5 | H31: 77.2 | I31: 25.3 | J31: 70.4 | K31: 76.2 | L31: 59 | M31: 78.8 | N31: =MAX(B31:M31) | O31: =N31*DATOS!$B$7 | P31: =LOG10(O31)
A32: 2010 | B32: 40 | C32: 79 | D32: 69.2 | E32: 128 | F32: 103 | G32: 56.5 | H32: 56.5 | I32: 15.2 | J32: 36.5 | K32: 75.8 | L32: 80.8 | M32: 73.8 | N32: =MAX(B32:M32) | O32: =N32*DATOS!$B$7 | P32: =LOG10(O32)
A33: 2011 | B33: 73.8 | C33: 76.3 | D33: 80.8 | E33: 60.7 | F33: 77.8 | G33: 67.3 | H33: 58.8 | I33: 57.3 | J33: 57 | K33: 70 | L33: 101 | M33: 77.6 | N33: =MAX(B33:M33) | O33: =N33*DATOS!$B$7 | P33: =LOG10(O33)
A34: 2012 | B34: 110.2 | C34: 56.5 | D34: 58 | E34: 87.2 | F34: 77.6 | G34: 25.5 | H34: 51.2 | I34: 12.1 | J34: 48 | K34: 48.2 | L34: 72 | M34: 54.8 | N34: =MAX(B34:M34) | O34: =N34*DATOS!$B$7 | P34: =LOG10(O34)
A35: 2013 | B35: 78.7 | C35: 76.4 | D35: 64.5 | E35: 62.5 | F35: 53.6 | G35: 74.5 | H35: 81.2 | I35: 64.9 | J35: 54.8 | K35: 76.8 | L35: 84 | M35: 30.7 | N35: =MAX(B35:M35) | O35: =N35*DATOS!$B$7 | P35: =LOG10(O35)
A37: Maximas mensuales obtenidas de los registros diarios del SENAMHI. S/D: enero de 2005 y julio de 2008 sin datos (se conservan los maximos de los otros once meses). 2014 (solo enero a abril) no se considera.

Sheet FRECUENCIAS
A1: ANALISIS DE FRECUENCIAS DE LA SERIE DE PONGO DE CAYNARACHI 1989-2013 (mm)
A2: PROYECTO: “MEJORAMIENTO Y AMPLIACIÓN DEL SERVICIO DE EDUCACIÓN PRIMARIA EN I.E. N° 0590 DISTRITO DE BARRANQUITA DE LA PROVINCIA DE LAMAS DEL DEPARTAMENTO DE SAN MARTÍN” - C.I. N° 468901
A3: ENTIDAD: GOBIERNO REGIONAL SAN MARTIN - GERENCIA TERRITORIAL BAJO MAYO - TARAPOTO - UBICACION: SAN MARTIN - LAMAS - BARRANQUITA - FECHA: OCTUBRE 2026
A5: Numero de datos n | B5: =COUNT(SERIE!$O$11:$O$35)
A6: Media aritmetica | B6: =AVERAGE(SERIE!$O$11:$O$35)
A7: Desviacion estandar | B7: =STDEV(SERIE!$O$11:$O$35)
A8: Coeficiente de asimetria | B8: =SKEW(SERIE!$O$11:$O$35)
A9: Media de log P | B9: =AVERAGE(SERIE!$P$11:$P$35)
A10: Desviacion estandar de log P | B10: =STDEV(SERIE!$P$11:$P$35)
A11: Coeficiente de asimetria de log P | B11: =SKEW(SERIE!$P$11:$P$35)
A12: Gumbel: alfa = raiz(6) s / pi | B12: =SQRT(6)*B7/PI()
A13: Gumbel: u = media - 0.5772 alfa | B13: =B6-0.5772*B12
A16: T (anos) | B16: z | C16: NORMAL | D16: LOG-NORMAL | E16: KT LP III | F16: LOG-PEARSON III | G16: KT GUMBEL | H16: GUMBEL | I16: DISEÑO (Log-Pearson III)
A17: 2 | B17: =SQRT(LN(A17^2))-(2.515517+0.802853*SQRT(LN(A17^2))+0.010328*SQRT(LN(A17^2))^2)/(1+1.432788*SQRT(LN(A17^2))+0.189269*SQRT(LN(A17^2))^2+0.001308*SQRT(LN(A17^2))^3) | C17: =$B$6+B17*$B$7 | D17: =10^($B$9+B17*$B$10) | E17: =B17+(B17^2-1)*($B$11/6)+1/3*(B17^3-6*B17)*($B$11/6)^2-(B17^2-1)*($B$11/6)^3+B17*($B$11/6)^4+1/3*($B$11/6)^5 | F17: =10^($B$9+E17*$B$10) | G17: =-SQRT(6)/PI()*(0.5772+LN(LN(A17/(A17-1)))) | H17: =$B$6+G17*$B$7 | I17: =F17
A18: 5 | B18: =SQRT(LN(A18^2))-(2.515517+0.802853*SQRT(LN(A18^2))+0.010328*SQRT(LN(A18^2))^2)/(1+1.432788*SQRT(LN(A18^2))+0.189269*SQRT(LN(A18^2))^2+0.001308*SQRT(LN(A18^2))^3) | C18: =$B$6+B18*$B$7 | D18: =10^($B$9+B18*$B$10) | E18: =B18+(B18^2-1)*($B$11/6)+1/3*(B18^3-6*B18)*($B$11/6)^2-(B18^2-1)*($B$11/6)^3+B18*($B$11/6)^4+1/3*($B$11/6)^5 | F18: =10^($B$9+E18*$B$10) | G18: =-SQRT(6)/PI()*(0.5772+LN(LN(A18/(A18-1)))) | H18: =$B$6+G18*$B$7 | I18: =F18
A19: 10 | B19: =SQRT(LN(A19^2))-(2.515517+0.802853*SQRT(LN(A19^2))+0.010328*SQRT(LN(A19^2))^2)/(1+1.432788*SQRT(LN(A19^2))+0.189269*SQRT(LN(A19^2))^2+0.001308*SQRT(LN(A19^2))^3) | C19: =$B$6+B19*$B$7 | D19: =10^($B$9+B19*$B$10) | E19: =B19+(B19^2-1)*($B$11/6)+1/3*(B19^3-6*B19)*($B$11/6)^2-(B19^2-1)*($B$11/6)^3+B19*($B$11/6)^4+1/3*($B$11/6)^5 | F19: =10^($B$9+E19*$B$10) | G19: =-SQRT(6)/PI()*(0.5772+LN(LN(A19/(A19-1)))) | H19: =$B$6+G19*$B$7 | I19: =F19
A20: 20 | B20: =SQRT(LN(A20^2))-(2.515517+0.802853*SQRT(LN(A20^2))+0.010328*SQRT(LN(A20^2))^2)/(1+1.432788*SQRT(LN(A20^2))+0.189269*SQRT(LN(A20^2))^2+0.001308*SQRT(LN(A20^2))^3) | C20: =$B$6+B20*$B$7 | D20: =10^($B$9+B20*$B$10) | E20: =B20+(B20^2-1)*($B$11/6)+1/3*(B20^3-6*B20)*($B$11/6)^2-(B20^2-1)*($B$11/6)^3+B20*($B$11/6)^4+1/3*($B$11/6)^5 | F20: =10^($B$9+E20*$B$10) | G20: =-SQRT(6)/PI()*(0.5772+LN(LN(A20/(A20-1)))) | H20: =$B$6+G20*$B$7 | I20: =F20
A21: 25 | B21: =SQRT(LN(A21^2))-(2.515517+0.802853*SQRT(LN(A21^2))+0.010328*SQRT(LN(A21^2))^2)/(1+1.432788*SQRT(LN(A21^2))+0.189269*SQRT(LN(A21^2))^2+0.001308*SQRT(LN(A21^2))^3) | C21: =$B$6+B21*$B$7 | D21: =10^($B$9+B21*$B$10) | E21: =B21+(B21^2-1)*($B$11/6)+1/3*(B21^3-6*B21)*($B$11/6)^2-(B21^2-1)*($B$11/6)^3+B21*($B$11/6)^4+1/3*($B$11/6)^5 | F21: =10^($B$9+E21*$B$10) | G21: =-SQRT(6)/PI()*(0.5772+LN(LN(A21/(A21-1)))) | H21: =$B$6+G21*$B$7 | I21: =F21
A22: 50 | B22: =SQRT(LN(A22^2))-(2.515517+0.802853*SQRT(LN(A22^2))+0.010328*SQRT(LN(A22^2))^2)/(1+1.432788*SQRT(LN(A22^2))+0.189269*SQRT(LN(A22^2))^2+0.001308*SQRT(LN(A22^2))^3) | C22: =$B$6+B22*$B$7 | D22: =10^($B$9+B22*$B$10) | E22: =B22+(B22^2-1)*($B$11/6)+1/3*(B22^3-6*B22)*($B$11/6)^2-(B22^2-1)*($B$11/6)^3+B22*($B$11/6)^4+1/3*($B$11/6)^5 | F22: =10^($B$9+E22*$B$10) | G22: =-SQRT(6)/PI()*(0.5772+LN(LN(A22/(A22-1)))) | H22: =$B$6+G22*$B$7 | I22: =F22
A23: 100 | B23: =SQRT(LN(A23^2))-(2.515517+0.802853*SQRT(LN(A23^2))+0.010328*SQRT(LN(A23^2))^2)/(1+1.432788*SQRT(LN(A23^2))+0.189269*SQRT(LN(A23^2))^2+0.001308*SQRT(LN(A23^2))^3) | C23: =$B$6+B23*$B$7 | D23: =10^($B$9+B23*$B$10) | E23: =B23+(B23^2-1)*($B$11/6)+1/3*(B23^3-6*B23)*($B$11/6)^2-(B23^2-1)*($B$11/6)^3+B23*($B$11/6)^4+1/3*($B$11/6)^5 | F23: =10^($B$9+E23*$B$10) | G23: =-SQRT(6)/PI()*(0.5772+LN(LN(A23/(A23-1)))) | H23: =$B$6+G23*$B$7 | I23: =F23
A24: 200 | B24: =SQRT(LN(A24^2))-(2.515517+0.802853*SQRT(LN(A24^2))+0.010328*SQRT(LN(A24^2))^2)/(1+1.432788*SQRT(LN(A24^2))+0.189269*SQRT(LN(A24^2))^2+0.001308*SQRT(LN(A24^2))^3) | C24: =$B$6+B24*$B$7 | D24: =10^($B$9+B24*$B$10) | E24: =B24+(B24^2-1)*($B$11/6)+1/3*(B24^3-6*B24)*($B$11/6)^2-(B24^2-1)*($B$11/6)^3+B24*($B$11/6)^4+1/3*($B$11/6)^5 | F24: =10^($B$9+E24*$B$10) | G24: =-SQRT(6)/PI()*(0.5772+LN(LN(A24/(A24-1)))) | H24: =$B$6+G24*$B$7 | I24: =F24
A25: 500 | B25: =SQRT(LN(A25^2))-(2.515517+0.802853*SQRT(LN(A25^2))+0.010328*SQRT(LN(A25^2))^2)/(1+1.432788*SQRT(LN(A25^2))+0.189269*SQRT(LN(A25^2))^2+0.001308*SQRT(LN(A25^2))^3) | C25: =$B$6+B25*$B$7 | D25: =10^($B$9+B25*$B$10) | E25: =B25+(B25^2-1)*($B$11/6)+1/3*(B25^3-6*B25)*($B$11/6)^2-(B25^2-1)*($B$11/6)^3+B25*($B$11/6)^4+1/3*($B$11/6)^5 | F25: =10^($B$9+E25*$B$10) | G25: =-SQRT(6)/PI()*(0.5772+LN(LN(A25/(A25-1)))) | H25: =$B$6+G25*$B$7 | I25: =F25
A27: Se adopta la distribucion Log-Pearson III: menor estadistico de Kolmogorov-Smirnov (hoja KS).
A28: z por la aproximacion de Abramowitz y Stegun; KT de Log Pearson III por la expresion de Kite (k = Cs/6); mismos calculos de la hoja ANALISIS_ESTADISTICO_IE0590_BARRANQUITA.xlsx.

Sheet KS
A1: PRUEBA DE BONDAD DE AJUSTE DE KOLMOGOROV-SMIRNOV (alfa = 0.05)
A2: PROYECTO: “MEJORAMIENTO Y AMPLIACIÓN DEL SERVICIO DE EDUCACIÓN PRIMARIA EN I.E. N° 0590 DISTRITO DE BARRANQUITA DE LA PROVINCIA DE LAMAS DEL DEPARTAMENTO DE SAN MARTÍN” - C.I. N° 468901
A3: ENTIDAD: GOBIERNO REGIONAL SAN MARTIN - GERENCIA TERRITORIAL BAJO MAYO - TARAPOTO - UBICACION: SAN MARTIN - LAMAS - BARRANQUITA - FECHA: OCTUBRE 2026
A8: m | B8: P ordenada de mayor a menor (mm) | C8: P(X>=x) observada m/(n+1) | D8: P teorica Normal | E8: P teorica Log-Normal | F8: P teorica Log-Pearson III | G8: P teorica Gumbel | H8: |D| Normal | I8: |D| Log-Normal | J8: |D| LP III | K8: |D| Gumbel
A9: 1 | B9: =LARGE(SERIE!$O$11:$O$35,A9) | C9: =A9/($N$9+1) | D9: =1-NORMSDIST((B9-FRECUENCIAS!$B$6)/FRECUENCIAS!$B$7) | E9: =1-NORMSDIST((LOG10(B9)-FRECUENCIAS!$B$9)/FRECUENCIAS!$B$10) | F9: =CHIDIST(2*(LN(B9)-$N$15)/$N$14,2*$N$13) | G9: =1-EXP(-EXP(-((B9-FRECUENCIAS!$B$6)/FRECUENCIAS!$B$7*$N$17+$N$16))) | H9: =ABS(D9-C9) | I9: =ABS(E9-C9) | J9: =ABS(F9-C9) | K9: =ABS(G9-C9) | M9: n | N9: =COUNT(SERIE!$O$11:$O$35)
A10: 2 | B10: =LARGE(SERIE!$O$11:$O$35,A10) | C10: =A10/($N$9+1) | D10: =1-NORMSDIST((B10-FRECUENCIAS!$B$6)/FRECUENCIAS!$B$7) | E10: =1-NORMSDIST((LOG10(B10)-FRECUENCIAS!$B$9)/FRECUENCIAS!$B$10) | F10: =CHIDIST(2*(LN(B10)-$N$15)/$N$14,2*$N$13) | G10: =1-EXP(-EXP(-((B10-FRECUENCIAS!$B$6)/FRECUENCIAS!$B$7*$N$17+$N$16))) | H10: =ABS(D10-C10) | I10: =ABS(E10-C10) | J10: =ABS(F10-C10) | K10: =ABS(G10-C10) | M10: media ln P | N10: 4.6762335
A11: 3 | B11: =LARGE(SERIE!$O$11:$O$35,A11) | C11: =A11/($N$9+1) | D11: =1-NORMSDIST((B11-FRECUENCIAS!$B$6)/FRECUENCIAS!$B$7) | E11: =1-NORMSDIST((LOG10(B11)-FRECUENCIAS!$B$9)/FRECUENCIAS!$B$10) | F11: =CHIDIST(2*(LN(B11)-$N$15)/$N$14,2*$N$13) | G11: =1-EXP(-EXP(-((B11-FRECUENCIAS!$B$6)/FRECUENCIAS!$B$7*$N$17+$N$16))) | H11: =ABS(D11-C11) | I11: =ABS(E11-C11) | J11: =ABS(F11-C11) | K11: =ABS(G11-C11) | M11: desv. ln P | N11: 0.23201392
A12: 4 | B12: =LARGE(SERIE!$O$11:$O$35,A12) | C12: =A12/($N$9+1) | D12: =1-NORMSDIST((B12-FRECUENCIAS!$B$6)/FRECUENCIAS!$B$7) | E12: =1-NORMSDIST((LOG10(B12)-FRECUENCIAS!$B$9)/FRECUENCIAS!$B$10) | F12: =CHIDIST(2*(LN(B12)-$N$15)/$N$14,2*$N$13) | G12: =1-EXP(-EXP(-((B12-FRECUENCIAS!$B$6)/FRECUENCIAS!$B$7*$N$17+$N$16))) | H12: =ABS(D12-C12) | I12: =ABS(E12-C12) | J12: =ABS(F12-C12) | K12: =ABS(G12-C12) | M12: Cs ln P | N12: 0.685811
A13: 5 | B13: =LARGE(SERIE!$O$11:$O$35,A13) | C13: =A13/($N$9+1) | D13: =1-NORMSDIST((B13-FRECUENCIAS!$B$6)/FRECUENCIAS!$B$7) | E13: =1-NORMSDIST((LOG10(B13)-FRECUENCIAS!$B$9)/FRECUENCIAS!$B$10) | F13: =CHIDIST(2*(LN(B13)-$N$15)/$N$14,2*$N$13) | G13: =1-EXP(-EXP(-((B13-FRECUENCIAS!$B$6)/FRECUENCIAS!$B$7*$N$17+$N$16))) | H13: =ABS(D13-C13) | I13: =ABS(E13-C13) | J13: =ABS(F13-C13) | K13: =ABS(G13-C13) | M13: beta = (2/Cs)^2 | N13: =(2/N12)^2
A14: 6 | B14: =LARGE(SERIE!$O$11:$O$35,A14) | C14: =A14/($N$9+1) | D14: =1-NORMSDIST((B14-FRECUENCIAS!$B$6)/FRECUENCIAS!$B$7) | E14: =1-NORMSDIST((LOG10(B14)-FRECUENCIAS!$B$9)/FRECUENCIAS!$B$10) | F14: =CHIDIST(2*(LN(B14)-$N$15)/$N$14,2*$N$13) | G14: =1-EXP(-EXP(-((B14-FRECUENCIAS!$B$6)/FRECUENCIAS!$B$7*$N$17+$N$16))) | H14: =ABS(D14-C14) | I14: =ABS(E14-C14) | J14: =ABS(F14-C14) | K14: =ABS(G14-C14) | M14: alfa = s/raiz(beta) | N14: =N11/SQRT(N13)
A15: 7 | B15: =LARGE(SERIE!$O$11:$O$35,A15) | C15: =A15/($N$9+1) | D15: =1-NORMSDIST((B15-FRECUENCIAS!$B$6)/FRECUENCIAS!$B$7) | E15: =1-NORMSDIST((LOG10(B15)-FRECUENCIAS!$B$9)/FRECUENCIAS!$B$10) | F15: =CHIDIST(2*(LN(B15)-$N$15)/$N$14,2*$N$13) | G15: =1-EXP(-EXP(-((B15-FRECUENCIAS!$B$6)/FRECUENCIAS!$B$7*$N$17+$N$16))) | H15: =ABS(D15-C15) | I15: =ABS(E15-C15) | J15: =ABS(F15-C15) | K15: =ABS(G15-C15) | M15: delta = media - alfa beta | N15: =N10-N14*N13
A16: 8 | B16: =LARGE(SERIE!$O$11:$O$35,A16) | C16: =A16/($N$9+1) | D16: =1-NORMSDIST((B16-FRECUENCIAS!$B$6)/FRECUENCIAS!$B$7) | E16: =1-NORMSDIST((LOG10(B16)-FRECUENCIAS!$B$9)/FRECUENCIAS!$B$10) | F16: =CHIDIST(2*(LN(B16)-$N$15)/$N$14,2*$N$13) | G16: =1-EXP(-EXP(-((B16-FRECUENCIAS!$B$6)/FRECUENCIAS!$B$7*$N$17+$N$16))) | H16: =ABS(D16-C16) | I16: =ABS(E16-C16) | J16: =ABS(F16-C16) | K16: =ABS(G16-C16) | M16: Gumbel: media yn (Aparicio, n = 25) | N16: 0.5309
A17: 9 | B17: =LARGE(SERIE!$O$11:$O$35,A17) | C17: =A17/($N$9+1) | D17: =1-NORMSDIST((B17-FRECUENCIAS!$B$6)/FRECUENCIAS!$B$7) | E17: =1-NORMSDIST((LOG10(B17)-FRECUENCIAS!$B$9)/FRECUENCIAS!$B$10) | F17: =CHIDIST(2*(LN(B17)-$N$15)/$N$14,2*$N$13) | G17: =1-EXP(-EXP(-((B17-FRECUENCIAS!$B$6)/FRECUENCIAS!$B$7*$N$17+$N$16))) | H17: =ABS(D17-C17) | I17: =ABS(E17-C17) | J17: =ABS(F17-C17) | K17: =ABS(G17-C17) | M17: Gumbel: desviacion sn | N17: 1.0914
A18: 10 | B18: =LARGE(SERIE!$O$11:$O$35,A18) | C18: =A18/($N$9+1) | D18: =1-NORMSDIST((B18-FRECUENCIAS!$B$6)/FRECUENCIAS!$B$7) | E18: =1-NORMSDIST((LOG10(B18)-FRECUENCIAS!$B$9)/FRECUENCIAS!$B$10) | F18: =CHIDIST(2*(LN(B18)-$N$15)/$N$14,2*$N$13) | G18: =1-EXP(-EXP(-((B18-FRECUENCIAS!$B$6)/FRECUENCIAS!$B$7*$N$17+$N$16))) | H18: =ABS(D18-C18) | I18: =ABS(E18-C18) | J18: =ABS(F18-C18) | K18: =ABS(G18-C18) | M18: D critico (alfa 0.05) | N18: =SQRT(-LN(0.05/2)/(2*N9))-1/(6*N9)
A19: 11 | B19: =LARGE(SERIE!$O$11:$O$35,A19) | C19: =A19/($N$9+1) | D19: =1-NORMSDIST((B19-FRECUENCIAS!$B$6)/FRECUENCIAS!$B$7) | E19: =1-NORMSDIST((LOG10(B19)-FRECUENCIAS!$B$9)/FRECUENCIAS!$B$10) | F19: =CHIDIST(2*(LN(B19)-$N$15)/$N$14,2*$N$13) | G19: =1-EXP(-EXP(-((B19-FRECUENCIAS!$B$6)/FRECUENCIAS!$B$7*$N$17+$N$16))) | H19: =ABS(D19-C19) | I19: =ABS(E19-C19) | J19: =ABS(F19-C19) | K19: =ABS(G19-C19)
A20: 12 | B20: =LARGE(SERIE!$O$11:$O$35,A20) | C20: =A20/($N$9+1) | D20: =1-NORMSDIST((B20-FRECUENCIAS!$B$6)/FRECUENCIAS!$B$7) | E20: =1-NORMSDIST((LOG10(B20)-FRECUENCIAS!$B$9)/FRECUENCIAS!$B$10) | F20: =CHIDIST(2*(LN(B20)-$N$15)/$N$14,2*$N$13) | G20: =1-EXP(-EXP(-((B20-FRECUENCIAS!$B$6)/FRECUENCIAS!$B$7*$N$17+$N$16))) | H20: =ABS(D20-C20) | I20: =ABS(E20-C20) | J20: =ABS(F20-C20) | K20: =ABS(G20-C20)
A21: 13 | B21: =LARGE(SERIE!$O$11:$O$35,A21) | C21: =A21/($N$9+1) | D21: =1-NORMSDIST((B21-FRECUENCIAS!$B$6)/FRECUENCIAS!$B$7) | E21: =1-NORMSDIST((LOG10(B21)-FRECUENCIAS!$B$9)/FRECUENCIAS!$B$10) | F21: =CHIDIST(2*(LN(B21)-$N$15)/$N$14,2*$N$13) | G21: =1-EXP(-EXP(-((B21-FRECUENCIAS!$B$6)/FRECUENCIAS!$B$7*$N$17+$N$16))) | H21: =ABS(D21-C21) | I21: =ABS(E21-C21) | J21: =ABS(F21-C21) | K21: =ABS(G21-C21)
A22: 14 | B22: =LARGE(SERIE!$O$11:$O$35,A22) | C22: =A22/($N$9+1) | D22: =1-NORMSDIST((B22-FRECUENCIAS!$B$6)/FRECUENCIAS!$B$7) | E22: =1-NORMSDIST((LOG10(B22)-FRECUENCIAS!$B$9)/FRECUENCIAS!$B$10) | F22: =CHIDIST(2*(LN(B22)-$N$15)/$N$14,2*$N$13) | G22: =1-EXP(-EXP(-((B22-FRECUENCIAS!$B$6)/FRECUENCIAS!$B$7*$N$17+$N$16))) | H22: =ABS(D22-C22) | I22: =ABS(E22-C22) | J22: =ABS(F22-C22) | K22: =ABS(G22-C22)
A23: 15 | B23: =LARGE(SERIE!$O$11:$O$35,A23) | C23: =A23/($N$9+1) | D23: =1-NORMSDIST((B23-FRECUENCIAS!$B$6)/FRECUENCIAS!$B$7) | E23: =1-NORMSDIST((LOG10(B23)-FRECUENCIAS!$B$9)/FRECUENCIAS!$B$10) | F23: =CHIDIST(2*(LN(B23)-$N$15)/$N$14,2*$N$13) | G23: =1-EXP(-EXP(-((B23-FRECUENCIAS!$B$6)/FRECUENCIAS!$B$7*$N$17+$N$16))) | H23: =ABS(D23-C23) | I23: =ABS(E23-C23) | J23: =ABS(F23-C23) | K23: =ABS(G23-C23)
A24: 16 | B24: =LARGE(SERIE!$O$11:$O$35,A24) | C24: =A24/($N$9+1) | D24: =1-NORMSDIST((B24-FRECUENCIAS!$B$6)/FRECUENCIAS!$B$7) | E24: =1-NORMSDIST((LOG10(B24)-FRECUENCIAS!$B$9)/FRECUENCIAS!$B$10) | F24: =CHIDIST(2*(LN(B24)-$N$15)/$N$14,2*$N$13) | G24: =1-EXP(-EXP(-((B24-FRECUENCIAS!$B$6)/FRECUENCIAS!$B$7*$N$17+$N$16))) | H24: =ABS(D24-C24) | I24: =ABS(E24-C24) | J24: =ABS(F24-C24) | K24: =ABS(G24-C24)
A25: 17 | B25: =LARGE(SERIE!$O$11:$O$35,A25) | C25: =A25/($N$9+1) | D25: =1-NORMSDIST((B25-FRECUENCIAS!$B$6)/FRECUENCIAS!$B$7) | E25: =1-NORMSDIST((LOG10(B25)-FRECUENCIAS!$B$9)/FRECUENCIAS!$B$10) | F25: =CHIDIST(2*(LN(B25)-$N$15)/$N$14,2*$N$13) | G25: =1-EXP(-EXP(-((B25-FRECUENCIAS!$B$6)/FRECUENCIAS!$B$7*$N$17+$N$16))) | H25: =ABS(D25-C25) | I25: =ABS(E25-C25) | J25: =ABS(F25-C25) | K25: =ABS(G25-C25)
A26: 18 | B26: =LARGE(SERIE!$O$11:$O$35,A26) | C26: =A26/($N$9+1) | D26: =1-NORMSDIST((B26-FRECUENCIAS!$B$6)/FRECUENCIAS!$B$7) | E26: =1-NORMSDIST((LOG10(B26)-FRECUENCIAS!$B$9)/FRECUENCIAS!$B$10) | F26: =CHIDIST(2*(LN(B26)-$N$15)/$N$14,2*$N$13) | G26: =1-EXP(-EXP(-((B26-FRECUENCIAS!$B$6)/FRECUENCIAS!$B$7*$N$17+$N$16))) | H26: =ABS(D26-C26) | I26: =ABS(E26-C26) | J26: =ABS(F26-C26) | K26: =ABS(G26-C26)
A27: 19 | B27: =LARGE(SERIE!$O$11:$O$35,A27) | C27: =A27/($N$9+1) | D27: =1-NORMSDIST((B27-FRECUENCIAS!$B$6)/FRECUENCIAS!$B$7) | E27: =1-NORMSDIST((LOG10(B27)-FRECUENCIAS!$B$9)/FRECUENCIAS!$B$10) | F27: =CHIDIST(2*(LN(B27)-$N$15)/$N$14,2*$N$13) | G27: =1-EXP(-EXP(-((B27-FRECUENCIAS!$B$6)/FRECUENCIAS!$B$7*$N$17+$N$16))) | H27: =ABS(D27-C27) | I27: =ABS(E27-C27) | J27: =ABS(F27-C27) | K27: =ABS(G27-C27)
A28: 20 | B28: =LARGE(SERIE!$O$11:$O$35,A28) | C28: =A28/($N$9+1) | D28: =1-NORMSDIST((B28-FRECUENCIAS!$B$6)/FRECUENCIAS!$B$7) | E28: =1-NORMSDIST((LOG10(B28)-FRECUENCIAS!$B$9)/FRECUENCIAS!$B$10) | F28: =CHIDIST(2*(LN(B28)-$N$15)/$N$14,2*$N$13) | G28: =1-EXP(-EXP(-((B28-FRECUENCIAS!$B$6)/FRECUENCIAS!$B$7*$N$17+$N$16))) | H28: =ABS(D28-C28) | I28: =ABS(E28-C28) | J28: =ABS(F28-C28) | K28: =ABS(G28-C28)
A29: 21 | B29: =LARGE(SERIE!$O$11:$O$35,A29) | C29: =A29/($N$9+1) | D29: =1-NORMSDIST((B29-FRECUENCIAS!$B$6)/FRECUENCIAS!$B$7) | E29: =1-NORMSDIST((LOG10(B29)-FRECUENCIAS!$B$9)/FRECUENCIAS!$B$10) | F29: =CHIDIST(2*(LN(B29)-$N$15)/$N$14,2*$N$13) | G29: =1-EXP(-EXP(-((B29-FRECUENCIAS!$B$6)/FRECUENCIAS!$B$7*$N$17+$N$16))) | H29: =ABS(D29-C29) | I29: =ABS(E29-C29) | J29: =ABS(F29-C29) | K29: =ABS(G29-C29)
A30: 22 | B30: =LARGE(SERIE!$O$11:$O$35,A30) | C30: =A30/($N$9+1) | D30: =1-NORMSDIST((B30-FRECUENCIAS!$B$6)/FRECUENCIAS!$B$7) | E30: =1-NORMSDIST((LOG10(B30)-FRECUENCIAS!$B$9)/FRECUENCIAS!$B$10) | F30: =CHIDIST(2*(LN(B30)-$N$15)/$N$14,2*$N$13) | G30: =1-EXP(-EXP(-((B30-FRECUENCIAS!$B$6)/FRECUENCIAS!$B$7*$N$17+$N$16))) | H30: =ABS(D30-C30) | I30: =ABS(E30-C30) | J30: =ABS(F30-C30) | K30: =ABS(G30-C30)
... A33: 25 | B33: =LARGE(SERIE!$O$11:$O$35,A33) | C33: =A33/($N$9+1) | D33: =1-NORMSDIST((B33-FRECUENCIAS!$B$6)/FRECUENCIAS!$B$7) | E33: =1-NORMSDIST((LOG10(B33)-FRECUENCIAS!$B$9)/FRECUENCIAS!$B$10) | F33: =CHIDIST(2*(LN(B33)-$N$15)/$N$14,2*$N$13) | G33: =1-EXP(-EXP(-((B33-FRECUENCIAS!$B$6)/FRECUENCIAS!$B$7*$N$17+$N$16))) | H33: =ABS(D33-C33) | I33: =ABS(E33-C33) | J33: =ABS(F33-C33) | K33: =ABS(G33-C33)
G34: D max | H34: =MAX(H9:H33) | I34: =MAX(I9:I33) | J34: =MAX(J9:J33) | K34: =MAX(K9:K33)
G35: D critico | H35: =$N$18 | I35: =$N$18 | J35: =$N$18 | K35: =$N$18
G36: Ajuste | H36: =IF(H34<H35,"ACEPTA","RECHAZA") | I36: =IF(I34<I35,"ACEPTA","RECHAZA") | J36: =IF(J34<J35,"ACEPTA","RECHAZA") | K36: =IF(K34<K35,"ACEPTA","RECHAZA")
A38: Log-Pearson III: distribucion gamma de ln P (CHIDIST con 2 beta grados de libertad); Gumbel con la media yn y la desviacion sn de la variable reducida para n datos (Aparicio, pag. 264); D critico = raiz(-ln(alfa/2)/(2n)) - 1/(6n). Se adopta la de menor D: Log-Pearson III.

Sheet IDF
A1: LLUVIAS E INTENSIDADES MAXIMAS: MODELO DE BELL (CURVAS IDF) Y DICK Y PESCHKE (DISENO)
A2: PROYECTO: “MEJORAMIENTO Y AMPLIACIÓN DEL SERVICIO DE EDUCACIÓN PRIMARIA EN I.E. N° 0590 DISTRITO DE BARRANQUITA DE LA PROVINCIA DE LAMAS DEL DEPARTAMENTO DE SAN MARTÍN” - C.I. N° 468901
A3: ENTIDAD: GOBIERNO REGIONAL SAN MARTIN - GERENCIA TERRITORIAL BAJO MAYO - TARAPOTO - UBICACION: SAN MARTIN - LAMAS - BARRANQUITA - FECHA: OCTUBRE 2026
A8: Intensidades de diseno - Dick y Peschke: P (mm) para la duracion D: P = P24 (D / 1440)^0.25
A9: D (min) | B9: T = 2 | C9: T = 5 | D9: T = 10 | E9: T = 20 | F9: T = 25 | G9: T = 50 | H9: T = 100 | I9: T = 200 | J9: T = 500
A10: 5 | B10: =FRECUENCIAS!$I$17*($A10/1440)^0.25 | C10: =FRECUENCIAS!$I$18*($A10/1440)^0.25 | D10: =FRECUENCIAS!$I$19*($A10/1440)^0.25 | E10: =FRECUENCIAS!$I$20*($A10/1440)^0.25 | F10: =FRECUENCIAS!$I$21*($A10/1440)^0.25 | G10: =FRECUENCIAS!$I$22*($A10/1440)^0.25 | H10: =FRECUENCIAS!$I$23*($A10/1440)^0.25 | I10: =FRECUENCIAS!$I$24*($A10/1440)^0.25 | J10: =FRECUENCIAS!$I$25*($A10/1440)^0.25
A11: 10 | B11: =FRECUENCIAS!$I$17*($A11/1440)^0.25 | C11: =FRECUENCIAS!$I$18*($A11/1440)^0.25 | D11: =FRECUENCIAS!$I$19*($A11/1440)^0.25 | E11: =FRECUENCIAS!$I$20*($A11/1440)^0.25 | F11: =FRECUENCIAS!$I$21*($A11/1440)^0.25 | G11: =FRECUENCIAS!$I$22*($A11/1440)^0.25 | H11: =FRECUENCIAS!$I$23*($A11/1440)^0.25 | I11: =FRECUENCIAS!$I$24*($A11/1440)^0.25 | J11: =FRECUENCIAS!$I$25*($A11/1440)^0.25
A12: 15 | B12: =FRECUENCIAS!$I$17*($A12/1440)^0.25 | C12: =FRECUENCIAS!$I$18*($A12/1440)^0.25 | D12: =FRECUENCIAS!$I$19*($A12/1440)^0.25 | E12: =FRECUENCIAS!$I$20*($A12/1440)^0.25 | F12: =FRECUENCIAS!$I$21*($A12/1440)^0.25 | G12: =FRECUENCIAS!$I$22*($A12/1440)^0.25 | H12: =FRECUENCIAS!$I$23*($A12/1440)^0.25 | I12: =FRECUENCIAS!$I$24*($A12/1440)^0.25 | J12: =FRECUENCIAS!$I$25*($A12/1440)^0.25
A13: 20 | B13: =FRECUENCIAS!$I$17*($A13/1440)^0.25 | C13: =FRECUENCIAS!$I$18*($A13/1440)^0.25 | D13: =FRECUENCIAS!$I$19*($A13/1440)^0.25 | E13: =FRECUENCIAS!$I$20*($A13/1440)^0.25 | F13: =FRECUENCIAS!$I$21*($A13/1440)^0.25 | G13: =FRECUENCIAS!$I$22*($A13/1440)^0.25 | H13: =FRECUENCIAS!$I$23*($A13/1440)^0.25 | I13: =FRECUENCIAS!$I$24*($A13/1440)^0.25 | J13: =FRECUENCIAS!$I$25*($A13/1440)^0.25
A14: 30 | B14: =FRECUENCIAS!$I$17*($A14/1440)^0.25 | C14: =FRECUENCIAS!$I$18*($A14/1440)^0.25 | D14: =FRECUENCIAS!$I$19*($A14/1440)^0.25 | E14: =FRECUENCIAS!$I$20*($A14/1440)^0.25 | F14: =FRECUENCIAS!$I$21*($A14/1440)^0.25 | G14: =FRECUENCIAS!$I$22*($A14/1440)^0.25 | H14: =FRECUENCIAS!$I$23*($A14/1440)^0.25 | I14: =FRECUENCIAS!$I$24*($A14/1440)^0.25 | J14: =FRECUENCIAS!$I$25*($A14/1440)^0.25
A15: 60 | B15: =FRECUENCIAS!$I$17*($A15/1440)^0.25 | C15: =FRECUENCIAS!$I$18*($A15/1440)^0.25 | D15: =FRECUENCIAS!$I$19*($A15/1440)^0.25 | E15: =FRECUENCIAS!$I$20*($A15/1440)^0.25 | F15: =FRECUENCIAS!$I$21*($A15/1440)^0.25 | G15: =FRECUENCIAS!$I$22*($A15/1440)^0.25 | H15: =FRECUENCIAS!$I$23*($A15/1440)^0.25 | I15: =FRECUENCIAS!$I$24*($A15/1440)^0.25 | J15: =FRECUENCIAS!$I$25*($A15/1440)^0.25
A16: 90 | B16: =FRECUENCIAS!$I$17*($A16/1440)^0.25 | C16: =FRECUENCIAS!$I$18*($A16/1440)^0.25 | D16: =FRECUENCIAS!$I$19*($A16/1440)^0.25 | E16: =FRECUENCIAS!$I$20*($A16/1440)^0.25 | F16: =FRECUENCIAS!$I$21*($A16/1440)^0.25 | G16: =FRECUENCIAS!$I$22*($A16/1440)^0.25 | H16: =FRECUENCIAS!$I$23*($A16/1440)^0.25 | I16: =FRECUENCIAS!$I$24*($A16/1440)^0.25 | J16: =FRECUENCIAS!$I$25*($A16/1440)^0.25
A17: 120 | B17: =FRECUENCIAS!$I$17*($A17/1440)^0.25 | C17: =FRECUENCIAS!$I$18*($A17/1440)^0.25 | D17: =FRECUENCIAS!$I$19*($A17/1440)^0.25 | E17: =FRECUENCIAS!$I$20*($A17/1440)^0.25 | F17: =FRECUENCIAS!$I$21*($A17/1440)^0.25 | G17: =FRECUENCIAS!$I$22*($A17/1440)^0.25 | H17: =FRECUENCIAS!$I$23*($A17/1440)^0.25 | I17: =FRECUENCIAS!$I$24*($A17/1440)^0.25 | J17: =FRECUENCIAS!$I$25*($A17/1440)^0.25
A18: 240 | B18: =FRECUENCIAS!$I$17*($A18/1440)^0.25 | C18: =FRECUENCIAS!$I$18*($A18/1440)^0.25 | D18: =FRECUENCIAS!$I$19*($A18/1440)^0.25 | E18: =FRECUENCIAS!$I$20*($A18/1440)^0.25 | F18: =FRECUENCIAS!$I$21*($A18/1440)^0.25 | G18: =FRECUENCIAS!$I$22*($A18/1440)^0.25 | H18: =FRECUENCIAS!$I$23*($A18/1440)^0.25 | I18: =FRECUENCIAS!$I$24*($A18/1440)^0.25 | J18: =FRECUENCIAS!$I$25*($A18/1440)^0.25
A19: 360 | B19: =FRECUENCIAS!$I$17*($A19/1440)^0.25 | C19: =FRECUENCIAS!$I$18*($A19/1440)^0.25 | D19: =FRECUENCIAS!$I$19*($A19/1440)^0.25 | E19: =FRECUENCIAS!$I$20*($A19/1440)^0.25 | F19: =FRECUENCIAS!$I$21*($A19/1440)^0.25 | G19: =FRECUENCIAS!$I$22*($A19/1440)^0.25 | H19: =FRECUENCIAS!$I$23*($A19/1440)^0.25 | I19: =FRECUENCIAS!$I$24*($A19/1440)^0.25 | J19: =FRECUENCIAS!$I$25*($A19/1440)^0.25
A20: 720 | B20: =FRECUENCIAS!$I$17*($A20/1440)^0.25 | C20: =FRECUENCIAS!$I$18*($A20/1440)^0.25 | D20: =FRECUENCIAS!$I$19*($A20/1440)^0.25 | E20: =FRECUENCIAS!$I$20*($A20/1440)^0.25 | F20: =FRECUENCIAS!$I$21*($A20/1440)^0.25 | G20: =FRECUENCIAS!$I$22*($A20/1440)^0.25 | H20: =FRECUENCIAS!$I$23*($A20/1440)^0.25 | I20: =FRECUENCIAS!$I$24*($A20/1440)^0.25 | J20: =FRECUENCIAS!$I$25*($A20/1440)^0.25
A21: 1440 | B21: =FRECUENCIAS!$I$17*($A21/1440)^0.25 | C21: =FRECUENCIAS!$I$18*($A21/1440)^0.25 | D21: =FRECUENCIAS!$I$19*($A21/1440)^0.25 | E21: =FRECUENCIAS!$I$20*($A21/1440)^0.25 | F21: =FRECUENCIAS!$I$21*($A21/1440)^0.25 | G21: =FRECUENCIAS!$I$22*($A21/1440)^0.25 | H21: =FRECUENCIAS!$I$23*($A21/1440)^0.25 | I21: =FRECUENCIAS!$I$24*($A21/1440)^0.25 | J21: =FRECUENCIAS!$I$25*($A21/1440)^0.25
A24: I (mm/h) = P x 60 / D
A25: D (min) | B25: T = 2 | C25: T = 5 | D25: T = 10 | E25: T = 20 | F25: T = 25 | G25: T = 50 | H25: T = 100 | I25: T = 200 | J25: T = 500
A26: 5 | B26: =B10*60/$A26 | C26: =C10*60/$A26 | D26: =D10*60/$A26 | E26: =E10*60/$A26 | F26: =F10*60/$A26 | G26: =G10*60/$A26 | H26: =H10*60/$A26 | I26: =I10*60/$A26 | J26: =J10*60/$A26
A27: 10 | B27: =B11*60/$A27 | C27: =C11*60/$A27 | D27: =D11*60/$A27 | E27: =E11*60/$A27 | F27: =F11*60/$A27 | G27: =G11*60/$A27 | H27: =H11*60/$A27 | I27: =I11*60/$A27 | J27: =J11*60/$A27
A28: 15 | B28: =B12*60/$A28 | C28: =C12*60/$A28 | D28: =D12*60/$A28 | E28: =E12*60/$A28 | F28: =F12*60/$A28 | G28: =G12*60/$A28 | H28: =H12*60/$A28 | I28: =I12*60/$A28 | J28: =J12*60/$A28
A29: 20 | B29: =B13*60/$A29 | C29: =C13*60/$A29 | D29: =D13*60/$A29 | E29: =E13*60/$A29 | F29: =F13*60/$A29 | G29: =G13*60/$A29 | H29: =H13*60/$A29 | I29: =I13*60/$A29 | J29: =J13*60/$A29
A30: 30 | B30: =B14*60/$A30 | C30: =C14*60/$A30 | D30: =D14*60/$A30 | E30: =E14*60/$A30 | F30: =F14*60/$A30 | G30: =G14*60/$A30 | H30: =H14*60/$A30 | I30: =I14*60/$A30 | J30: =J14*60/$A30
A31: 60 | B31: =B15*60/$A31 | C31: =C15*60/$A31 | D31: =D15*60/$A31 | E31: =E15*60/$A31 | F31: =F15*60/$A31 | G31: =G15*60/$A31 | H31: =H15*60/$A31 | I31: =I15*60/$A31 | J31: =J15*60/$A31
A32: 90 | B32: =B16*60/$A32 | C32: =C16*60/$A32 | D32: =D16*60/$A32 | E32: =E16*60/$A32 | F32: =F16*60/$A32 | G32: =G16*60/$A32 | H32: =H16*60/$A32 | I32: =I16*60/$A32 | J32: =J16*60/$A32
A33: 120 | B33: =B17*60/$A33 | C33: =C17*60/$A33 | D33: =D17*60/$A33 | E33: =E17*60/$A33 | F33: =F17*60/$A33 | G33: =G17*60/$A33 | H33: =H17*60/$A33 | I33: =I17*60/$A33 | J33: =J17*60/$A33
A34: 240 | B34: =B18*60/$A34 | C34: =C18*60/$A34 | D34: =D18*60/$A34 | E34: =E18*60/$A34 | F34: =F18*60/$A34 | G34: =G18*60/$A34 | H34: =H18*60/$A34 | I34: =I18*60/$A34 | J34: =J18*60/$A34
A35: 360 | B35: =B19*60/$A35 | C35: =C19*60/$A35 | D35: =D19*60/$A35 | E35: =E19*60/$A35 | F35: =F19*60/$A35 | G35: =G19*60/$A35 | H35: =H19*60/$A35 | I35: =I19*60/$A35 | J35: =J19*60/$A35
A36: 720 | B36: =B20*60/$A36 | C36: =C20*60/$A36 | D36: =D20*60/$A36 | E36: =E20*60/$A36 | F36: =F20*60/$A36 | G36: =G20*60/$A36 | H36: =H20*60/$A36 | I36: =I20*60/$A36 | J36: =J20*60/$A36
A37: 1440 | B37: =B21*60/$A37 | C37: =C21*60/$A37 | D37: =D21*60/$A37 | E37: =E21*60/$A37 | F37: =F21*60/$A37 | G37: =G21*60/$A37 | H37: =H21*60/$A37 | I37: =I21*60/$A37 | J37: =J21*60/$A37
A40: Regresion multiple I = K T^m / t^n de las intensidades del modelo de Bell (filas inferiores; 5 a 60 min, todos los T):
A41: K | B41: 211.66
A42: m | B42: 0.1786
A43: n | B43: 0.5269
A45: Comprobacion: I (T = 25, t = 10 min) con la ecuacion IDF (mm/h) | F45: =B41*25^B42/10^B43
A46: Modelo de Bell: P(T,t) = (0.21 ln T + 0.52)(0.54 t^0.25 - 0.50) P60(10); P60(10) = 0.4602 P24(10)^0.876 = | I46: =0.4602*FRECUENCIAS!$I$19^0.876
A47: T (anos) | B47: P t = 5 min | C47: P t = 10 min | D47: P t = 15 min | E47: P t = 20 min | F47: P t = 30 min | G47: P t = 60 min
A48: 500 | B48: =(0.21*LN($A48)+0.52)*(0.54*5^0.25-0.5)*$I$46 | C48: =(0.21*LN($A48)+0.52)*(0.54*10^0.25-0.5)*$I$46 | D48: =(0.21*LN($A48)+0.52)*(0.54*15^0.25-0.5)*$I$46 | E48: =(0.21*LN($A48)+0.52)*(0.54*20^0.25-0.5)*$I$46 | F48: =(0.21*LN($A48)+0.52)*(0.54*30^0.25-0.5)*$I$46 | G48: =(0.21*LN($A48)+0.52)*(0.54*60^0.25-0.5)*$I$46
A49: 200 | B49: =(0.21*LN($A49)+0.52)*(0.54*5^0.25-0.5)*$I$46 | C49: =(0.21*LN($A49)+0.52)*(0.54*10^0.25-0.5)*$I$46 | D49: =(0.21*LN($A49)+0.52)*(0.54*15^0.25-0.5)*$I$46 | E49: =(0.21*LN($A49)+0.52)*(0.54*20^0.25-0.5)*$I$46 | F49: =(0.21*LN($A49)+0.52)*(0.54*30^0.25-0.5)*$I$46 | G49: =(0.21*LN($A49)+0.52)*(0.54*60^0.25-0.5)*$I$46
...

Sheet SUPERFICIES
A1: COEFICIENTE DE ESCORRENTIA PONDERADO (AREA DENTRO DEL CERCO)
A2: PROYECTO: “MEJORAMIENTO Y AMPLIACIÓN DEL SERVICIO DE EDUCACIÓN PRIMARIA EN I.E. N° 0590 DISTRITO DE BARRANQUITA DE LA PROVINCIA DE LAMAS DEL DEPARTAMENTO DE SAN MARTÍN” - C.I. N° 468901
A3: ENTIDAD: GOBIERNO REGIONAL SAN MARTIN - GERENCIA TERRITORIAL BAJO MAYO - TARAPOTO - UBICACION: SAN MARTIN - LAMAS - BARRANQUITA - FECHA: OCTUBRE 2026
A8: TIPO DE SUPERFICIE | B8: AREA (m2) | C8: C | D8: C x A | E8: % DEL AREA
A9: Techos: edificaciones, corredores, patio civico techado y losa multiusos techada | B9: 5548 | C9: =DATOS!$B$18 | D9: =B9*C9 | E9: =B9/$B$13
A10: Areas libres de concreto: veredas, patios, atrio y circulaciones | B10: 901 | C10: =DATOS!$B$19 | D10: =B10*C10 | E10: =B10/$B$13
A11: Patio de maniobra y estacionamiento (pavimento de concreto) | B11: 623 | C11: =DATOS!$B$20 | D11: =B11*C11 | E11: =B11/$B$13
A12: Areas verdes y terreno natural (relleno nivelado) | B12: 2321 | C12: =DATOS!$B$21 | D12: =B12*C12 | E12: =B12/$B$13
A13: TOTAL / C PONDERADO | B13: =SUM(B9:B12) | C13: =D13/B13 | D13: =SUM(D9:D12) | E13: =SUM(E9:E12)
A15: DETALLE POR ZONA (NOMBRES DEL CUADRO DE AREAS DE ARQUITECTURA)
A16: ZONA | B16: AREA (m2) | C16: C | D16: C x A | E16: TIPO
A17: Coberturas de las edificaciones y corredores techados | B17: 4129.6 | C17: =DATOS!$B$18 | D17: =B17*C17 | E17: TECHO
A18: Patio civico techado | B18: 517.7 | C18: =DATOS!$B$18 | D18: =B18*C18 | E18: TECHO
A19: Losa multiusos tipo I techada | B19: 829.4 | C19: =DATOS!$B$18 | D19: =B19*C19 | E19: TECHO
A20: Patio 01: ingreso principal | B20: 118.8 | C20: =DATOS!$B$19 | D20: =B20*C20 | E20: AREA LIBRE
A21: Patio 02: circulacion principal | B21: 194.2 | C21: =DATOS!$B$19 | D21: =B21*C21 | E21: AREA LIBRE
A22: Patio 03: area privada de estudiantes | B22: 257.9 | C22: =DATOS!$B$19 | D22: =B22*C22 | E22: AREA LIBRE
A23: Patio 04: asta de bandera | B23: 87.7 | C23: =DATOS!$B$19 | D23: =B23*C23 | E23: AREA LIBRE
A24: Veredas, circulaciones, atrio y losa del area de tratamiento | B24: 202.5 | C24: =DATOS!$B$19 | D24: =B24*C24 | E24: AREA LIBRE
A25: Patio de maniobra y estacionamiento | B25: 647.3 | C25: =DATOS!$B$20 | D25: =B25*C25 | E25: ESTACIONAM.
A26: Areas verdes, jardines y terreno natural nivelado | B26: 2379.7 | C26: =DATOS!$B$21 | D26: =B26*C26 | E26: AREA VERDE
A27: TOTAL (AREA DENTRO DEL CERCO) | B27: =SUM(B17:B26) | C27: =D27/B27 | D27: =SUM(D17:D26)
A29: Areas medidas a escala real en la planta del proyecto dentro del cerco. Tabla superior: celdas de 1 m2 asignadas a cada tramo (base del calculo de caudales). Detalle: poligonos de cada zona (techos = proyeccion de coberturas, incluye patio civico y losa multiusos techados; areas libres = veredas, patios, atrio y circulaciones; patio de maniobra y estacionamiento; el resto, areas verdes y terreno nivelado).

Sheet CAUDALES
A1: CAUDALES DE DISENO (METODO RACIONAL) Y VERIFICACION HIDRAULICA (MANNING) POR TRAMO
A2: PROYECTO: “MEJORAMIENTO Y AMPLIACIÓN DEL SERVICIO DE EDUCACIÓN PRIMARIA EN I.E. N° 0590 DISTRITO DE BARRANQUITA DE LA PROVINCIA DE LAMAS DEL DEPARTAMENTO DE SAN MARTÍN” - C.I. N° 468901
A3: ENTIDAD: GOBIERNO REGIONAL SAN MARTIN - GERENCIA TERRITORIAL BAJO MAYO - TARAPOTO - UBICACION: SAN MARTIN - LAMAS - BARRANQUITA - FECHA: OCTUBRE 2026
A8: EJE | B8: DE | C8: A | D8: AREA ACUM. (m2) | E8: C POND. | F8: I (mm/h) | G8: Q (m3/s) | H8: Q (l/s) | I8: S (%) | J8: h LIBRE (m) | K8: y (m) n=0.015 | L8: A=b y (m2) | M8: P=b+2y (m) | N8: R (m) | O8: Q MANNING (m3/s) | P8: BORDE LIBRE (m) | Q8: CAPACIDAD | R8: y (m) n=0.013 | S8: V (m/s) | T8: VELOCIDAD
A9: EJE-01 | B9: P-01 | C9: P-02 | D9: 533 | E9: 0.575 | F9: =DATOS!$B$17 | G9: =E9*F9*D9*DATOS!$B$22/3600000 | H9: =G9*1000 | I9: 0.5 | J9: 0.3 | K9: 0.0948 | L9: =DATOS!$B$12*K9 | M9: =DATOS!$B$12+2*K9 | N9: =L9/M9 | O9: =L9*N9^(2/3)*SQRT(I9/100)/DATOS!$B$10 | P9: =J9-K9 | Q9: =IF(P9>=DATOS!$B$13-0.001,"CUMPLE","NO CUMPLE") | R9: 0.086 | S9: =G9/(DATOS!$B$12*R9) | T9: =IF(S9<=DATOS!$B$14,"CUMPLE","NO CUMPLE")
A10: EJE-01 | B10: P-02 | C10: P-03 | D10: 559 | E10: 0.567 | F10: =DATOS!$B$17 | G10: =E10*F10*D10*DATOS!$B$22/3600000 | H10: =G10*1000 | I10: 0.5 | J10: 0.46 | K10: 0.0971 | L10: =DATOS!$B$12*K10 | M10: =DATOS!$B$12+2*K10 | N10: =L10/M10 | O10: =L10*N10^(2/3)*SQRT(I10/100)/DATOS!$B$10 | P10: =J10-K10 | Q10: =IF(P10>=DATOS!$B$13-0.001,"CUMPLE","NO CUMPLE") | R10: 0.088 | S10: =G10/(DATOS!$B$12*R10) | T10: =IF(S10<=DATOS!$B$14,"CUMPLE","NO CUMPLE")
A11: EJE-02 | B11: P-04 | C11: P-05 | D11: 413 | E11: 0.621 | F11: =DATOS!$B$17 | G11: =E11*F11*D11*DATOS!$B$22/3600000 | H11: =G11*1000 | I11: 0.5 | J11: 0.3 | K11: 0.0839 | L11: =DATOS!$B$12*K11 | M11: =DATOS!$B$12+2*K11 | N11: =L11/M11 | O11: =L11*N11^(2/3)*SQRT(I11/100)/DATOS!$B$10 | P11: =J11-K11 | Q11: =IF(P11>=DATOS!$B$13-0.001,"CUMPLE","NO CUMPLE") | R11: 0.0761 | S11: =G11/(DATOS!$B$12*R11) | T11: =IF(S11<=DATOS!$B$14,"CUMPLE","NO CUMPLE")
A12: EJE-02 | B12: P-05 | C12: P-06 | D12: 440 | E12: 0.617 | F12: =DATOS!$B$17 | G12: =E12*F12*D12*DATOS!$B$22/3600000 | H12: =G12*1000 | I12: 0.5 | J12: 0.46 | K12: 0.0872 | L12: =DATOS!$B$12*K12 | M12: =DATOS!$B$12+2*K12 | N12: =L12/M12 | O12: =L12*N12^(2/3)*SQRT(I12/100)/DATOS!$B$10 | P12: =J12-K12 | Q12: =IF(P12>=DATOS!$B$13-0.001,"CUMPLE","NO CUMPLE") | R12: 0.0791 | S12: =G12/(DATOS!$B$12*R12) | T12: =IF(S12<=DATOS!$B$14,"CUMPLE","NO CUMPLE")
A13: EJE-02 | B13: P-06 | C13: P-07 | D13: 528 | E13: 0.661 | F13: =DATOS!$B$17 | G13: =E13*F13*D13*DATOS!$B$22/3600000 | H13: =G13*1000 | I13: 0.5 | J13: 0.46 | K13: 0.1038 | L13: =DATOS!$B$12*K13 | M13: =DATOS!$B$12+2*K13 | N13: =L13/M13 | O13: =L13*N13^(2/3)*SQRT(I13/100)/DATOS!$B$10 | P13: =J13-K13 | Q13: =IF(P13>=DATOS!$B$13-0.001,"CUMPLE","NO CUMPLE") | R13: 0.094 | S13: =G13/(DATOS!$B$12*R13) | T13: =IF(S13<=DATOS!$B$14,"CUMPLE","NO CUMPLE")
A14: EJE-02 | B14: P-07 | C14: P-08 | D14: 965 | E14: 0.727 | F14: =DATOS!$B$17 | G14: =E14*F14*D14*DATOS!$B$22/3600000 | H14: =G14*1000 | I14: 2.92 | J14: 0.52 | K14: 0.0913 | L14: =DATOS!$B$12*K14 | M14: =DATOS!$B$12+2*K14 | N14: =L14/M14 | O14: =L14*N14^(2/3)*SQRT(I14/100)/DATOS!$B$10 | P14: =J14-K14 | Q14: =IF(P14>=DATOS!$B$13-0.001,"CUMPLE","NO CUMPLE") | R14: 0.0828 | S14: =G14/(DATOS!$B$12*R14) | T14: =IF(S14<=DATOS!$B$14,"CUMPLE","NO CUMPLE")
A15: EJE-02 | B15: P-08 | C15: P-09 | D15: 2225 | E15: 0.711 | F15: =DATOS!$B$17 | G15: =E15*F15*D15*DATOS!$B$22/3600000 | H15: =G15*1000 | I15: 0.5 | J15: 0.77 | K15: 0.318 | L15: =DATOS!$B$12*K15 | M15: =DATOS!$B$12+2*K15 | N15: =L15/M15 | O15: =L15*N15^(2/3)*SQRT(I15/100)/DATOS!$B$10 | P15: =J15-K15 | Q15: =IF(P15>=DATOS!$B$13-0.001,"CUMPLE","NO CUMPLE") | R15: 0.284 | S15: =G15/(DATOS!$B$12*R15) | T15: =IF(S15<=DATOS!$B$14,"CUMPLE","NO CUMPLE")
A16: EJE-02 | B16: P-09 | C16: P-10 | D16: 2226 | E16: 0.711 | F16: =DATOS!$B$17 | G16: =E16*F16*D16*DATOS!$B$22/3600000 | H16: =G16*1000 | I16: 0.5 | J16: 0.83 | K16: 0.3181 | L16: =DATOS!$B$12*K16 | M16: =DATOS!$B$12+2*K16 | N16: =L16/M16 | O16: =L16*N16^(2/3)*SQRT(I16/100)/DATOS!$B$10 | P16: =J16-K16 | Q16: =IF(P16>=DATOS!$B$13-0.001,"CUMPLE","NO CUMPLE") | R16: 0.2841 | S16: =G16/(DATOS!$B$12*R16) | T16: =IF(S16<=DATOS!$B$14,"CUMPLE","NO CUMPLE")
A17: EJE-02 | B17: P-10 | C17: P-11 | D17: 2979 | E17: 0.715 | F17: =DATOS!$B$17 | G17: =E17*F17*D17*DATOS!$B$22/3600000 | H17: =G17*1000 | I17: 0.5 | J17: 0.83 | K17: 0.4044 | L17: =DATOS!$B$12*K17 | M17: =DATOS!$B$12+2*K17 | N17: =L17/M17 | O17: =L17*N17^(2/3)*SQRT(I17/100)/DATOS!$B$10 | P17: =J17-K17 | Q17: =IF(P17>=DATOS!$B$13-0.001,"CUMPLE","NO CUMPLE") | R17: 0.36 | S17: =G17/(DATOS!$B$12*R17) | T17: =IF(S17<=DATOS!$B$14,"CUMPLE","NO CUMPLE")
A18: EJE-02 | B18: P-11 | C18: P-03 | D18: 2980 | E18: 0.715 | F18: =DATOS!$B$17 | G18: =E18*F18*D18*DATOS!$B$22/3600000 | H18: =G18*1000 | I18: 0.5 | J18: 0.79 | K18: 0.4046 | L18: =DATOS!$B$12*K18 | M18: =DATOS!$B$12+2*K18 | N18: =L18/M18 | O18: =L18*N18^(2/3)*SQRT(I18/100)/DATOS!$B$10 | P18: =J18-K18 | Q18: =IF(P18>=DATOS!$B$13-0.001,"CUMPLE","NO CUMPLE") | R18: 0.3601 | S18: =G18/(DATOS!$B$12*R18) | T18: =IF(S18<=DATOS!$B$14,"CUMPLE","NO CUMPLE")
A19: EJE-02 | B19: P-03 | C19: D1 | D19: 3539 | E19: 0.692 | F19: =DATOS!$B$17 | G19: =E19*F19*D19*DATOS!$B$22/3600000 | H19: =G19*1000 | I19: 0.5 | J19: 0.79 | K19: 0.4535 | L19: =DATOS!$B$12*K19 | M19: =DATOS!$B$12+2*K19 | N19: =L19/M19 | O19: =L19*N19^(2/3)*SQRT(I19/100)/DATOS!$B$10 | P19: =J19-K19 | Q19: =IF(P19>=DATOS!$B$13-0.001,"CUMPLE","NO CUMPLE") | R19: 0.403 | S19: =G19/(DATOS!$B$12*R19) | T19: =IF(S19<=DATOS!$B$14,"CUMPLE","NO CUMPLE")
A20: EJE-03 | B20: P-12 | C20: P-07 | D20: 368 | E20: 0.794 | F20: =DATOS!$B$17 | G20: =E20*F20*D20*DATOS!$B$22/3600000 | H20: =G20*1000 | I20: 0.5 | J20: 0.3 | K20: 0.0918 | L20: =DATOS!$B$12*K20 | M20: =DATOS!$B$12+2*K20 | N20: =L20/M20 | O20: =L20*N20^(2/3)*SQRT(I20/100)/DATOS!$B$10 | P20: =J20-K20 | Q20: =IF(P20>=DATOS!$B$13-0.001,"CUMPLE","NO CUMPLE") | R20: 0.0833 | S20: =G20/(DATOS!$B$12*R20) | T20: =IF(S20<=DATOS!$B$14,"CUMPLE","NO CUMPLE")
... A99: EJE-19 | B99: P-88 | C99: P-86 | D99: 109 | E99: 0.704 | F99: =DATOS!$B$17 | G99: =E99*F99*D99*DATOS!$B$22/3600000 | H99: =G99*1000 | I99: 0.5 | J99: 0.37 | K99: 0.038 | L99: =DATOS!$B$12*K99 | M99: =DATOS!$B$12+2*K99 | N99: =L99/M99 | O99: =L99*N99^(2/3)*SQRT(I99/100)/DATOS!$B$10 | P99: =J99-K99 | Q99: =IF(P99>=DATOS!$B$13-0.001,"CUMPLE","NO CUMPLE") | R99: 0.0346 | S99: =G99/(DATOS!$B$12*R99) | T99: =IF(S99<=DATOS!$B$14,"CUMPLE","NO CUMPLE")
A101: y: tirante normal por Manning resuelto por iteracion (Q Manning = Q de diseno). En tramos tapados, h libre = altura bajo la losa tapa. Area acumulada: celdas de 1 m2 asignadas a la cuneta mas cercana mas las areas de los ejes que entregan aguas arriba.

Sheet DESCARGAS
A1: DESCARGAS POR EL CERCO PERIMETRICO
A2: PROYECTO: “MEJORAMIENTO Y AMPLIACIÓN DEL SERVICIO DE EDUCACIÓN PRIMARIA EN I.E. N° 0590 DISTRITO DE BARRANQUITA DE LA PROVINCIA DE LAMAS DEL DEPARTAMENTO DE SAN MARTÍN” - C.I. N° 468901
A3: ENTIDAD: GOBIERNO REGIONAL SAN MARTIN - GERENCIA TERRITORIAL BAJO MAYO - TARAPOTO - UBICACION: SAN MARTIN - LAMAS - BARRANQUITA - FECHA: OCTUBRE 2026
A8: DESCARGA | B8: COTA DE FONDO (m) | C8: TERRENO AL PIE (m) | D8: SALE A (m del cerco) | E8: ESTADO | F8: RECEPTOR
A9: D1 | B9: 183.759 | C9: 183.91 | D9: 0.5 | E9: SALE POR GRAVEDAD | F9: Cerco sur-oeste (lado C22-C1, x = 820.1): al talud natural que baja a la quebrada del oeste
A10: D2 | B10: 183.758 | C10: 180.55 | D10: 0.25 | E10: SALE POR GRAVEDAD | F10: Cerco norte (x = 965.5): pase en el cimiento del cerco al terreno exterior que baja a la quebrada del norte
A11: D3 | B11: 183.736 | C11: 183.83 | D11: 0.5 | E11: SALE POR GRAVEDAD | F11: Cerco sur junto a C14 (x = 935.5): al terreno exterior que baja al Jr. Alfonso Ugarte (183.00)
A12: D4 | B12: 184.145 | C12: 184.46 | D12: 0.5 | E12: SALE POR GRAVEDAD | F12: Cerco norte (lado C3-C4, x = 911.0): al talud natural que baja a la quebrada del norte
