Workbook

Sheet RESUMEN
A2: RESUMEN METRADOS DE DRENAJE PLUVIAL
A3: ENTIDAD | B3: GOBIERNO REGIONAL SAN MARTIN - GERENCIA TERRITORIAL BAJO MAYO - TARAPOTO
A4: PROYECTO | B4: “MEJORAMIENTO Y AMPLIACIÓN DEL SERVICIO DE EDUCACIÓN PRIMARIA EN I.E. N° 0590 DISTRITO DE BARRANQUITA DE LA PROVINCIA DE LAMAS DEL DEPARTAMENTO DE SAN MARTÍN” - C.I. N° 468901
A5: UBICACIÓN | B5: SAN MARTIN - LAMAS - BARRANQUITA
A6: FECHA | B6: OCTUBRE 2026
A8: Item | B8: Descripción | C8: Unid. | D8: Total.
A9: 01 | B9: SISTEMA DE DRENAJE PLUVIAL - RED DE CUNETAS
A10: 01.01 | B10: TRABAJOS PRELIMINARES
A11: 01.01.01 | B11: LIMPIEZA MANUAL DE TERRENO | C11: m² | D11: ='PLANILLA GENERAL DE METRADOS'!K11
A12: 01.01.02 | B12: TRAZO, NIVELES Y REPLANTEO PRELIMINAR | C12: m² | D12: ='PLANILLA GENERAL DE METRADOS'!K31
A13: 01.02 | B13: MOVIMIENTO DE TIERRAS
A14: 01.02.01 | B14: EXCAVACIÓN MANUAL DE ZANJAS P/CUNETAS | C14: m³ | D14: ='PLANILLA GENERAL DE METRADOS'!K52
A15: 01.02.02 | B15: REFINE, NIVELACIÓN Y COMPACTACIÓN EN TERRENO NORMAL | C15: m² | D15: ='PLANILLA GENERAL DE METRADOS'!K72
A16: 01.02.03 | B16: RELLENO COMPACTADO C/MATERIAL PROPIO SELECCIONADO | C16: m³ | D16: ='PLANILLA GENERAL DE METRADOS'!K92
A17: 01.02.04 | B17: ELIMINACIÓN DE MATERIAL EXCEDENTE D<1Km | C17: m³ | D17: ='PLANILLA GENERAL DE METRADOS'!K112
A18: 01.02.05 | B18: PERFILADO MANUAL DE TERRENO EN DESCARGAS | C18: m² | D18: ='PLANILLA GENERAL DE METRADOS'!K114
A19: 01.03 | B19: OBRAS DE CONCRETO SIMPLE
A20: 01.03.01 | B20: CONCRETO f'c=100 kg/cm2 PARA SOLADO E=4'' | C20: m² | D20: ='PLANILLA GENERAL DE METRADOS'!K120
A21: 01.04 | B21: OBRAS DE CONCRETO ARMADO
A22: 01.04.01 | B22: CUNETAS
A23: 01.04.01.01 | B23: CONCRETO f'c=175 kg/cm2 PARA CUNETAS | C23: m³ | D23: ='PLANILLA GENERAL DE METRADOS'!K142
A24: 01.04.01.02 | B24: ENCOFRADO Y DESENCOFRADO DE CUNETAS | C24: m² | D24: ='PLANILLA GENERAL DE METRADOS'!K190
A25: 01.04.01.03 | B25: ACERO f'y=4200 kg/cm2 PARA CUNETA | C25: kg | D25: ='PLANILLA GENERAL DE METRADOS'!K234
A26: 01.04.01.04 | B26: CURADO DE CONCRETO EN CUNETA | C26: m² | D26: ='PLANILLA GENERAL DE METRADOS'!K254
A27: 01.04.02 | B27: VARIOS
A28: 01.04.02.01 | B28: REJILLA METALICA P/CUNETA C/PL 1''x 3/16'' Y ANGULO 1'' x 1'' x 3/16'' | C28: m | D28: ='PLANILLA GENERAL DE METRADOS'!K318
A29: 01.04.02.02 | B29: TAPA DE INSPECCION 0.60m x 0.60m | C29: und | D29: ='PLANILLA GENERAL DE METRADOS'!K338
A30: 01.04.02.03 | B30: JUNTA DE DILATACION E=1" CON SELLADOR ASFALTO | C30: m | D30: ='PLANILLA GENERAL DE METRADOS'!K343
A31: 01.04.02.04 | B31: JUNTA E=1" CON SELLADOR ASFALTICO ENTRE CUNETA Y PISO ADYACENTE | C31: m | D31: ='PLANILLA GENERAL DE METRADOS'!K363

Sheet PLANILLA GENERAL DE METRADOS
A2: PLANILLA GENERAL DE METRADOS - DRENAJE PLUVIAL
A3: ENTIDAD | B3: GOBIERNO REGIONAL SAN MARTIN - GERENCIA TERRITORIAL BAJO MAYO - TARAPOTO
A4: PROYECTO | B4: “MEJORAMIENTO Y AMPLIACIÓN DEL SERVICIO DE EDUCACIÓN PRIMARIA EN I.E. N° 0590 DISTRITO DE BARRANQUITA DE LA PROVINCIA DE LAMAS DEL DEPARTAMENTO DE SAN MARTÍN” - C.I. N° 468901
A5: UBICACIÓN | B5: SAN MARTIN - LAMAS - BARRANQUITA
A6: FECHA | B6: OCTUBRE 2026
A8: ITEM | B8: DESCRIPCION | C8: Nº DE VECES | D8: LARGO | E8: ANCHO | F8: ALTURA | G8: FACT. | H8: AREA | I8: VOLUMEN | J8: PARCIAL | K8: TOTAL | L8: UND
A9: 01 | B9: SISTEMA DE DRENAJE PLUVIAL - RED DE CUNETAS
A10: 01.01 | B10: TRABAJOS PRELIMINARES
A11: 01.01.01 | B11: LIMPIEZA MANUAL DE TERRENO | K11: =SUM(J12:J30) | L11: m²
B12: EJE-01 | C12: 1 | D12: 34.34 | E12: =PARAMETROS!$B$12 | J12: =C12*D12*E12
B13: EJE-02 | C13: 1 | D13: 76.04 | E13: =PARAMETROS!$B$12 | J13: =C13*D13*E13
B14: EJE-03 | C14: 1 | D14: 32.31 | E14: =PARAMETROS!$B$12 | J14: =C14*D14*E14
B15: EJE-04 | C15: 1 | D15: 94.34 | E15: =PARAMETROS!$B$12 | J15: =C15*D15*E15
B16: EJE-05 | C16: 1 | D16: 90.56 | E16: =PARAMETROS!$B$12 | J16: =C16*D16*E16
B17: EJE-06 | C17: 1 | D17: 12.3 | E17: =PARAMETROS!$B$12 | J17: =C17*D17*E17
B18: EJE-07 | C18: 1 | D18: 94.69 | E18: =PARAMETROS!$B$12 | J18: =C18*D18*E18
B19: EJE-08 | C19: 1 | D19: 39.68 | E19: =PARAMETROS!$B$12 | J19: =C19*D19*E19
B20: EJE-09 | C20: 1 | D20: 35.8 | E20: =PARAMETROS!$B$12 | J20: =C20*D20*E20
B21: EJE-10 | C21: 1 | D21: 36.9 | E21: =PARAMETROS!$B$12 | J21: =C21*D21*E21
B22: EJE-11 | C22: 1 | D22: 30.36 | E22: =PARAMETROS!$B$12 | J22: =C22*D22*E22
B23: EJE-12 | C23: 1 | D23: 118.38 | E23: =PARAMETROS!$B$12 | J23: =C23*D23*E23
... B30: EJE-19 | C30: 1 | D30: 14.09 | E30: =PARAMETROS!$B$12 | J30: =C30*D30*E30
A31: 01.01.02 | B31: TRAZO, NIVELES Y REPLANTEO PRELIMINAR | K31: =SUM(J32:J50) | L31: m²
B32: EJE-01 | C32: 1 | D32: 34.34 | E32: =PARAMETROS!$B$12 | J32: =C32*D32*E32
B33: EJE-02 | C33: 1 | D33: 76.04 | E33: =PARAMETROS!$B$12 | J33: =C33*D33*E33
B34: EJE-03 | C34: 1 | D34: 32.31 | E34: =PARAMETROS!$B$12 | J34: =C34*D34*E34
B35: EJE-04 | C35: 1 | D35: 94.34 | E35: =PARAMETROS!$B$12 | J35: =C35*D35*E35
B36: EJE-05 | C36: 1 | D36: 90.56 | E36: =PARAMETROS!$B$12 | J36: =C36*D36*E36
B37: EJE-06 | C37: 1 | D37: 12.3 | E37: =PARAMETROS!$B$12 | J37: =C37*D37*E37
B38: EJE-07 | C38: 1 | D38: 94.69 | E38: =PARAMETROS!$B$12 | J38: =C38*D38*E38
B39: EJE-08 | C39: 1 | D39: 39.68 | E39: =PARAMETROS!$B$12 | J39: =C39*D39*E39
B40: EJE-09 | C40: 1 | D40: 35.8 | E40: =PARAMETROS!$B$12 | J40: =C40*D40*E40
B41: EJE-10 | C41: 1 | D41: 36.9 | E41: =PARAMETROS!$B$12 | J41: =C41*D41*E41
B42: EJE-11 | C42: 1 | D42: 30.36 | E42: =PARAMETROS!$B$12 | J42: =C42*D42*E42
B43: EJE-12 | C43: 1 | D43: 118.38 | E43: =PARAMETROS!$B$12 | J43: =C43*D43*E43
... B50: EJE-19 | C50: 1 | D50: 14.09 | E50: =PARAMETROS!$B$12 | J50: =C50*D50*E50
A51: 01.02 | B51: MOVIMIENTO DE TIERRAS
A52: 01.02.01 | B52: EXCAVACIÓN MANUAL DE ZANJAS P/CUNETAS | K52: =SUM(J53:J71) | L52: m³
B53: EJE-01 (h prom. 0.386 m) | C53: 1 | D53: 34.34 | E53: =PARAMETROS!$B$12 | F53: 0.386 | J53: =C53*D53*E53*(F53+PARAMETROS!$B$8+PARAMETROS!$B$10)
B54: EJE-02 (h prom. 0.568 m) | C54: 1 | D54: 76.04 | E54: =PARAMETROS!$B$12 | F54: 0.568 | J54: =C54*D54*E54*(F54+PARAMETROS!$B$8+PARAMETROS!$B$10)
...

Sheet METRADO ACERO
A2: ACERO f'y = 4200 kg/cm2 PARA CUNETAS - BARRAS DE 3/8"
A3: ENTIDAD | B3: GOBIERNO REGIONAL SAN MARTIN - GERENCIA TERRITORIAL BAJO MAYO - TARAPOTO
A4: PROYECTO | B4: “MEJORAMIENTO Y AMPLIACIÓN DEL SERVICIO DE EDUCACIÓN PRIMARIA EN I.E. N° 0590 DISTRITO DE BARRANQUITA DE LA PROVINCIA DE LAMAS DEL DEPARTAMENTO DE SAN MARTÍN” - C.I. N° 468901
A5: UBICACIÓN | B5: SAN MARTIN - LAMAS - BARRANQUITA
A6: FECHA | B6: OCTUBRE 2026
A8: EJE | B8: LONG. CON ACERO (m) | C8: h PROM. CON ACERO (m) | D8: LONG. TAPADA (m) | E8: LONG. U (m) | F8: N° DE U | G8: N° BARRAS LONG. | H8: kg U | I8: kg LONGIT. | J8: kg LOSA TAPA | K8: TOTAL (kg)
A9: EJE-01 | B9: 14.4 | C9: 0.436 | D9: 0 | E9: =IF(B9>0,2*(C9+PARAMETROS!$B$8-2*PARAMETROS!$B$16)+(PARAMETROS!$B$5-2*PARAMETROS!$B$16)+0.2,0) | F9: =IF(B9>0,B9/PARAMETROS!$B$18,0) | G9: =IF(B9>0,2*(CEILING(ROUND(C9/PARAMETROS!$B$19,6),1)+1)+(CEILING(ROUND((PARAMETROS!$B$5-2*PARAMETROS!$B$16)/PARAMETROS!$B$19,6),1)+1),0) | H9: =F9*E9*PARAMETROS!$B$17 | I9: =G9*B9*PARAMETROS!$B$17 | J9: =IF(B9>0,(D9/PARAMETROS!$B$19)*(PARAMETROS!$B$5-2*PARAMETROS!$B$16+0.2)*PARAMETROS!$B$17+3*D9*PARAMETROS!$B$17,0) | K9: =H9+I9+J9
A10: EJE-02 | B10: 56.15 | C10: 0.645 | D10: 0.76 | E10: =IF(B10>0,2*(C10+PARAMETROS!$B$8-2*PARAMETROS!$B$16)+(PARAMETROS!$B$5-2*PARAMETROS!$B$16)+0.2,0) | F10: =IF(B10>0,B10/PARAMETROS!$B$18,0) | G10: =IF(B10>0,2*(CEILING(ROUND(C10/PARAMETROS!$B$19,6),1)+1)+(CEILING(ROUND((PARAMETROS!$B$5-2*PARAMETROS!$B$16)/PARAMETROS!$B$19,6),1)+1),0) | H10: =F10*E10*PARAMETROS!$B$17 | I10: =G10*B10*PARAMETROS!$B$17 | J10: =IF(B10>0,(D10/PARAMETROS!$B$19)*(PARAMETROS!$B$5-2*PARAMETROS!$B$16+0.2)*PARAMETROS!$B$17+3*D10*PARAMETROS!$B$17,0) | K10: =H10+I10+J10
A11: EJE-03 | B11: 12.42 | C11: 0.431 | D11: 0 | E11: =IF(B11>0,2*(C11+PARAMETROS!$B$8-2*PARAMETROS!$B$16)+(PARAMETROS!$B$5-2*PARAMETROS!$B$16)+0.2,0) | F11: =IF(B11>0,B11/PARAMETROS!$B$18,0) | G11: =IF(B11>0,2*(CEILING(ROUND(C11/PARAMETROS!$B$19,6),1)+1)+(CEILING(ROUND((PARAMETROS!$B$5-2*PARAMETROS!$B$16)/PARAMETROS!$B$19,6),1)+1),0) | H11: =F11*E11*PARAMETROS!$B$17 | I11: =G11*B11*PARAMETROS!$B$17 | J11: =IF(B11>0,(D11/PARAMETROS!$B$19)*(PARAMETROS!$B$5-2*PARAMETROS!$B$16+0.2)*PARAMETROS!$B$17+3*D11*PARAMETROS!$B$17,0) | K11: =H11+I11+J11
A12: EJE-04 | B12: 74.15 | C12: 0.586 | D12: 0 | E12: =IF(B12>0,2*(C12+PARAMETROS!$B$8-2*PARAMETROS!$B$16)+(PARAMETROS!$B$5-2*PARAMETROS!$B$16)+0.2,0) | F12: =IF(B12>0,B12/PARAMETROS!$B$18,0) | G12: =IF(B12>0,2*(CEILING(ROUND(C12/PARAMETROS!$B$19,6),1)+1)+(CEILING(ROUND((PARAMETROS!$B$5-2*PARAMETROS!$B$16)/PARAMETROS!$B$19,6),1)+1),0) | H12: =F12*E12*PARAMETROS!$B$17 | I12: =G12*B12*PARAMETROS!$B$17 | J12: =IF(B12>0,(D12/PARAMETROS!$B$19)*(PARAMETROS!$B$5-2*PARAMETROS!$B$16+0.2)*PARAMETROS!$B$17+3*D12*PARAMETROS!$B$17,0) | K12: =H12+I12+J12
A13: EJE-05 | B13: 70.73 | C13: 0.576 | D13: 0 | E13: =IF(B13>0,2*(C13+PARAMETROS!$B$8-2*PARAMETROS!$B$16)+(PARAMETROS!$B$5-2*PARAMETROS!$B$16)+0.2,0) | F13: =IF(B13>0,B13/PARAMETROS!$B$18,0) | G13: =IF(B13>0,2*(CEILING(ROUND(C13/PARAMETROS!$B$19,6),1)+1)+(CEILING(ROUND((PARAMETROS!$B$5-2*PARAMETROS!$B$16)/PARAMETROS!$B$19,6),1)+1),0) | H13: =F13*E13*PARAMETROS!$B$17 | I13: =G13*B13*PARAMETROS!$B$17 | J13: =IF(B13>0,(D13/PARAMETROS!$B$19)*(PARAMETROS!$B$5-2*PARAMETROS!$B$16+0.2)*PARAMETROS!$B$17+3*D13*PARAMETROS!$B$17,0) | K13: =H13+I13+J13
A14: EJE-06 | B14: 0 | C14: 0 | D14: 0 | E14: =IF(B14>0,2*(C14+PARAMETROS!$B$8-2*PARAMETROS!$B$16)+(PARAMETROS!$B$5-2*PARAMETROS!$B$16)+0.2,0) | F14: =IF(B14>0,B14/PARAMETROS!$B$18,0) | G14: =IF(B14>0,2*(CEILING(ROUND(C14/PARAMETROS!$B$19,6),1)+1)+(CEILING(ROUND((PARAMETROS!$B$5-2*PARAMETROS!$B$16)/PARAMETROS!$B$19,6),1)+1),0) | H14: =F14*E14*PARAMETROS!$B$17 | I14: =G14*B14*PARAMETROS!$B$17 | J14: =IF(B14>0,(D14/PARAMETROS!$B$19)*(PARAMETROS!$B$5-2*PARAMETROS!$B$16+0.2)*PARAMETROS!$B$17+3*D14*PARAMETROS!$B$17,0) | K14: =H14+I14+J14
A15: EJE-07 | B15: 88.94 | C15: 0.69 | D15: 22.9 | E15: =IF(B15>0,2*(C15+PARAMETROS!$B$8-2*PARAMETROS!$B$16)+(PARAMETROS!$B$5-2*PARAMETROS!$B$16)+0.2,0) | F15: =IF(B15>0,B15/PARAMETROS!$B$18,0) | G15: =IF(B15>0,2*(CEILING(ROUND(C15/PARAMETROS!$B$19,6),1)+1)+(CEILING(ROUND((PARAMETROS!$B$5-2*PARAMETROS!$B$16)/PARAMETROS!$B$19,6),1)+1),0) | H15: =F15*E15*PARAMETROS!$B$17 | I15: =G15*B15*PARAMETROS!$B$17 | J15: =IF(B15>0,(D15/PARAMETROS!$B$19)*(PARAMETROS!$B$5-2*PARAMETROS!$B$16+0.2)*PARAMETROS!$B$17+3*D15*PARAMETROS!$B$17,0) | K15: =H15+I15+J15
A16: EJE-08 | B16: 19.89 | C16: 0.449 | D16: 0 | E16: =IF(B16>0,2*(C16+PARAMETROS!$B$8-2*PARAMETROS!$B$16)+(PARAMETROS!$B$5-2*PARAMETROS!$B$16)+0.2,0) | F16: =IF(B16>0,B16/PARAMETROS!$B$18,0) | G16: =IF(B16>0,2*(CEILING(ROUND(C16/PARAMETROS!$B$19,6),1)+1)+(CEILING(ROUND((PARAMETROS!$B$5-2*PARAMETROS!$B$16)/PARAMETROS!$B$19,6),1)+1),0) | H16: =F16*E16*PARAMETROS!$B$17 | I16: =G16*B16*PARAMETROS!$B$17 | J16: =IF(B16>0,(D16/PARAMETROS!$B$19)*(PARAMETROS!$B$5-2*PARAMETROS!$B$16+0.2)*PARAMETROS!$B$17+3*D16*PARAMETROS!$B$17,0) | K16: =H16+I16+J16
A17: EJE-09 | B17: 15.91 | C17: 0.439 | D17: 0 | E17: =IF(B17>0,2*(C17+PARAMETROS!$B$8-2*PARAMETROS!$B$16)+(PARAMETROS!$B$5-2*PARAMETROS!$B$16)+0.2,0) | F17: =IF(B17>0,B17/PARAMETROS!$B$18,0) | G17: =IF(B17>0,2*(CEILING(ROUND(C17/PARAMETROS!$B$19,6),1)+1)+(CEILING(ROUND((PARAMETROS!$B$5-2*PARAMETROS!$B$16)/PARAMETROS!$B$19,6),1)+1),0) | H17: =F17*E17*PARAMETROS!$B$17 | I17: =G17*B17*PARAMETROS!$B$17 | J17: =IF(B17>0,(D17/PARAMETROS!$B$19)*(PARAMETROS!$B$5-2*PARAMETROS!$B$16+0.2)*PARAMETROS!$B$17+3*D17*PARAMETROS!$B$17,0) | K17: =H17+I17+J17
A18: EJE-10 | B18: 16.75 | C18: 0.443 | D18: 0 | E18: =IF(B18>0,2*(C18+PARAMETROS!$B$8-2*PARAMETROS!$B$16)+(PARAMETROS!$B$5-2*PARAMETROS!$B$16)+0.2,0) | F18: =IF(B18>0,B18/PARAMETROS!$B$18,0) | G18: =IF(B18>0,2*(CEILING(ROUND(C18/PARAMETROS!$B$19,6),1)+1)+(CEILING(ROUND((PARAMETROS!$B$5-2*PARAMETROS!$B$16)/PARAMETROS!$B$19,6),1)+1),0) | H18: =F18*E18*PARAMETROS!$B$17 | I18: =G18*B18*PARAMETROS!$B$17 | J18: =IF(B18>0,(D18/PARAMETROS!$B$19)*(PARAMETROS!$B$5-2*PARAMETROS!$B$16+0.2)*PARAMETROS!$B$17+3*D18*PARAMETROS!$B$17,0) | K18: =H18+I18+J18
A19: EJE-11 | B19: 10.95 | C19: 0.424 | D19: 0.5 | E19: =IF(B19>0,2*(C19+PARAMETROS!$B$8-2*PARAMETROS!$B$16)+(PARAMETROS!$B$5-2*PARAMETROS!$B$16)+0.2,0) | F19: =IF(B19>0,B19/PARAMETROS!$B$18,0) | G19: =IF(B19>0,2*(CEILING(ROUND(C19/PARAMETROS!$B$19,6),1)+1)+(CEILING(ROUND((PARAMETROS!$B$5-2*PARAMETROS!$B$16)/PARAMETROS!$B$19,6),1)+1),0) | H19: =F19*E19*PARAMETROS!$B$17 | I19: =G19*B19*PARAMETROS!$B$17 | J19: =IF(B19>0,(D19/PARAMETROS!$B$19)*(PARAMETROS!$B$5-2*PARAMETROS!$B$16+0.2)*PARAMETROS!$B$17+3*D19*PARAMETROS!$B$17,0) | K19: =H19+I19+J19
A20: EJE-12 | B20: 98.55 | C20: 0.577 | D20: 15.22 | E20: =IF(B20>0,2*(C20+PARAMETROS!$B$8-2*PARAMETROS!$B$16)+(PARAMETROS!$B$5-2*PARAMETROS!$B$16)+0.2,0) | F20: =IF(B20>0,B20/PARAMETROS!$B$18,0) | G20: =IF(B20>0,2*(CEILING(ROUND(C20/PARAMETROS!$B$19,6),1)+1)+(CEILING(ROUND((PARAMETROS!$B$5-2*PARAMETROS!$B$16)/PARAMETROS!$B$19,6),1)+1),0) | H20: =F20*E20*PARAMETROS!$B$17 | I20: =G20*B20*PARAMETROS!$B$17 | J20: =IF(B20>0,(D20/PARAMETROS!$B$19)*(PARAMETROS!$B$5-2*PARAMETROS!$B$16+0.2)*PARAMETROS!$B$17+3*D20*PARAMETROS!$B$17,0) | K20: =H20+I20+J20
... A27: EJE-19 | B27: 0 | C27: 0 | D27: 0 | E27: =IF(B27>0,2*(C27+PARAMETROS!$B$8-2*PARAMETROS!$B$16)+(PARAMETROS!$B$5-2*PARAMETROS!$B$16)+0.2,0) | F27: =IF(B27>0,B27/PARAMETROS!$B$18,0) | G27: =IF(B27>0,2*(CEILING(ROUND(C27/PARAMETROS!$B$19,6),1)+1)+(CEILING(ROUND((PARAMETROS!$B$5-2*PARAMETROS!$B$16)/PARAMETROS!$B$19,6),1)+1),0) | H27: =F27*E27*PARAMETROS!$B$17 | I27: =G27*B27*PARAMETROS!$B$17 | J27: =IF(B27>0,(D27/PARAMETROS!$B$19)*(PARAMETROS!$B$5-2*PARAMETROS!$B$16+0.2)*PARAMETROS!$B$17+3*D27*PARAMETROS!$B$17,0) | K27: =H27+I27+J27
A28: TOTAL | K28: =SUM(K9:K27)
A30: Acero solo donde h >= 0.40 m (de la rejilla al fondo) o en tramo tapado; con h < 0.40 m la cuneta es de concreto simple. U de 3/8" @0.25 m con ganchos de 0.10 m; longitudinales de 3/8" @0.20 m en muros y losa de fondo; losa tapa: 3/8" @0.20 m transversal y 3 barras longitudinales.

Sheet PARAMETROS
A2: PARAMETROS DEL METRADO - RED DE CUNETAS
A3: ENTIDAD | B3: GOBIERNO REGIONAL SAN MARTIN - GERENCIA TERRITORIAL BAJO MAYO - TARAPOTO
A4: PROYECTO | B4: “MEJORAMIENTO Y AMPLIACIÓN DEL SERVICIO DE EDUCACIÓN PRIMARIA EN I.E. N° 0590 DISTRITO DE BARRANQUITA DE LA PROVINCIA DE LAMAS DEL DEPARTAMENTO DE SAN MARTÍN” - C.I. N° 468901
A5: Ancho exterior de la cuneta (m) | B5: 0.6
A6: Luz libre interior (m) | B6: 0.4
A7: Espesor de muros (m) | B7: 0.1
A8: Espesor de losa de fondo (m) | B8: 0.1
A9: Espesor de losa tapa en tramos tapados (m) | B9: 0.1
A10: Espesor de solado f'c = 100 kg/cm2 (m) | B10: 0.1
A11: Sobreancho de excavacion a cada lado (m) | B11: 0.15
A12: Ancho de excavacion (m) | B12: =B5+2*B11
A13: Profundidad adicional bajo la cota de fondo: losa + solado (m) | B13: =B8+B10
A14: Factor de esponjamiento para eliminacion | B14: 1.25
A15: Junta de dilatacion en la seccion en U cada (m) | B15: 3
A16: Recubrimiento del acero (m) | B16: 0.04
A17: Peso de la barra de 3/8" (kg/m) | B17: 0.56
A18: Separacion de las U de 3/8" (m) | B18: 0.25
A19: Separacion de barras longitudinales de 3/8" (m) | B19: 0.2
A20: Profundidad minima con acero (m): h >= 0.40 o tramo tapado | B20: 0.4
A21: Tapa de inspeccion: lado (m) | B21: 0.6
A22: Tapa de inspeccion: espesor (m) | B22: 0.1
A24: Fuente: planos DC-01 a DC-19 (secciones tipicas DC-02, perfiles DC-03 a DC-11, secciones DC-12 a DC-14, descargas DC-16 a DC-19).
