Workbook
Name CoefAsimE6: '[1]N-LN-LP3_VEI'!$C$50
Name CuadroResultados: #N/A
Name DatosOrdenadosLogaritmo: #N/A
Name DatosOrdenadosNormal: #N/A
Name Desv_Estand_LogP: '[1]N-LN-LP3_VEI'!$C$47
Name Desv_Estand_P: '[1]N-LN-LP3_VEI'!$B$47
Name MaxValor: #N/A
Name NumeroDatos: #REF!
Name Promedio_LogP: '[1]N-LN-LP3_VEI'!$C$46
Name Promedio_P: '[1]N-LN-LP3_VEI'!$B$46
Name Registrados_P: #N/A
Name Registrados_TR: #N/A
Name Registro: #N/A
Name tabla: #N/A
Name ValoresRangoLogaritmo: #N/A
Name ValoresRangoNormal: #N/A

Sheet A. Estación
B2: Proyecto | C2: “CREACIÓN DEL SERVICIO DE PROTECCIÓN INTEGRAL A NIÑAS, NIÑOS Y ADOLESCENTES SIN CUIDADOS PARENTALES O EN RIESGO DE PERDERLOS EN CENTRO DE ACOGIDA RESIDENCIAL - VARONES DISTRITO DE MORALES DE LA PROVINCIA DE SAN MARTÍN DEL DEPARTAMENTO DE SAN MARTÍN”, con CUI N.° 2705619
B3: Entidad | C3: GERENCIA TERRITORIAL BAJO MAYO
B4: Ubicación | C4: SAN MARTIN - SAN MARTIN - MORALES
B5: Fecha | C5: SETIEMBRE 2026
B7: PARTE I : DETERMINACIÓN DE PRECIPITACIONES DE DISEÑO MÁXIMAS EN 24 HORAS
B9: REGISTRO DE PRECIPITACIONES MÁXIMAS EN 24 HORAS (mm) - ESTACIÓN CO:TARAPOTO
B11: Latitud | C11: 06° 28′ S | F11: Dpto. | G11: : SAN MARTIN
B12: Longitud | C12: 76° 22′ O | F12: Provincia | G12: :SAN MARTIN
B13: Altura | C13: 356 msnm. | F13: Distrito | G13: TARAPOTO
B15: Precipitación Máxima en 24 Horas (mm)
B16: Año | C16: Enero | D16: Febrero | E16: Marzo | F16: Abril | G16: Mayo | H16: Junio | I16: Julio | J16: Agosto | K16: Setiembre | L16: Octubre | M16: Noviembre | N16: Diciembre | O16: P Máxima
A18: =O18 -> 79.3 | B18: 1999 | C18: 79.3 | D18: 42.5 | E18: 39.3 | F18: 16.9 | G18: 54.5 | H18: 17.5 | I18: 27.9 | J18: 23 | K18: 11.3 | L18: 17.3 | M18: 48.8 | N18: 46.5 | O18: =MAX(C18:N18) -> 79.3
A19: =O19 -> 82.5 | B19: 2000 | C19: 27.5 | D19: 34.2 | E19: 15.6 | F19: 34.7 | G19: 30.2 | H19: 12.6 | I19: 17.5 | J19: 52.6 | K19: 82.5 | L19: 19.4 | M19: 24.2 | N19: 30.3 | O19: =MAX(C19:N19) -> 82.5
A20: =O20 -> 75.9 | B20: 2001 | C20: 16.2 | D20: 32 | E20: 35 | F20: 75.9 | G20: 40.3 | H20: 13.8 | I20: 40.6 | J20: 21.3 | K20: 24.3 | L20: 61 | M20: 30 | N20: 42.2 | O20: =MAX(C20:N20) -> 75.9
A21: =O21 -> 43.6 | B21: 2002 | C21: 9.3 | D21: 30 | E21: 14.8 | F21: 39.8 | G21: 12.5 | H21: 43.6 | I21: 35.3 | J21: 7.1 | K21: 5.8 | L21: 32.3 | M21: 27.5 | N21: 20.7 | O21: =MAX(C21:N21) -> 43.6
A22: =O22 -> 84.5 | B22: 2003 | C22: 74 | D22: 37 | E22: 54.6 | F22: 33.1 | G22: 37.6 | H22: 27.5 | I22: 17.8 | J22: 18 | K22: 18 | L22: 84.5 | M22: 40.2 | N22: 52.2 | O22: =MAX(C22:N22) -> 84.5
A23: =O23 -> 64.2 | B23: 2004 | C23: 15.8 | D23: 64.2 | E23: 24 | F23: 26.2 | G23: 48.1 | H23: 30.7 | I23: 25.7 | J23: 25.6 | K23: 28.2 | L23: 33.2 | M23: 46.2 | N23: 59.9 | O23: =MAX(C23:N23) -> 64.2
A24: =O24 -> 71 | B24: 2005 | C24: 15.9 | D24: 33.7 | E24: 48.8 | F24: 44 | G24: 22.4 | H24: 26.8 | I24: 16.3 | J24: 15.5 | K24: 26 | L24: 45 | M24: 71 | N24: 9.3 | O24: =MAX(C24:N24) -> 71
A25: =O25 -> 113.3 | B25: 2006 | C25: 38.5 | D25: 44.5 | E25: 41.5 | F25: 52 | G25: 39 | H25: 17.3 | I25: 113.3 | J25: 7 | K25: 18.5 | L25: 39.2 | M25: 74 | N25: 28 | O25: =MAX(C25:N25) -> 113.3
A26: =O26 -> 63.5 | B26: 2007 | C26: 37 | D26: 7.5 | E26: 48 | F26: 21 | G26: 45.4 | H26: 16.5 | I26: 60 | J26: 46.2 | K26: 45.2 | L26: 37.8 | M26: 63.5 | N26: 18.5 | O26: =MAX(C26:N26) -> 63.5
A27: =O27 -> 91 | B27: 2008 | C27: 25.6 | D27: 91 | E27: 27.5 | F27: 51 | G27: 25.6 | H27: 24 | I27: 9.3 | J27: 10.4 | K27: 38 | L27: 17.4 | M27: 18 | N27: 15.3 | O27: =MAX(C27:N27) -> 91
A28: =O28 -> 49 | B28: 2009 | C28: 29.4 | D28: 49 | E28: 28 | F28: 35.5 | G28: 36.5 | H28: 47 | I28: 9.1 | J28: 25 | K28: 31.5 | L28: 18.4 | M28: 25.5 | N28: 42 | O28: =MAX(C28:N28) -> 49
A29: =O29 -> 98.4 | B29: 2010 | C29: 32.2 | D29: 62.4 | E29: 17.6 | F29: 72.8 | G29: 31.6 | H29: 40.6 | I29: 6.1 | J29: 44.5 | K29: 23.9 | L29: 27.7 | M29: 98.4 | N29: 47.8 | O29: =MAX(C29:N29) -> 98.4
... A38: =O38 -> 86.9 | B38: 2019 | C38: 42.9 | D38: 42.3 | E38: 20.8 | F38: 23.5 | G38: 32 | H38: 9.7 | I38: 39.8 | J38: 23.7 | K38: 25.3 | L38: 86.9 | M38: 36.4 | N38: 44 | O38: =MAX(C38:N38) -> 86.9
A39: =O39 -> 152.5 | B39: 2020 | C39: 152.5 | D39: 33 | E39: 50.6 | F39: S/D | G39: S/D | H39: S/D | I39: S/D | J39: 32.2 | K39: 32.9 | L39: 50.6 | M39: 38.4 | N39: 14.2 | O39: =MAX(C39:N39) -> 152.5
B40: 2021 | C40: 42.4 | D40: 46.8 | E40: 73.5 | F40: 28.5 | G40: 12.9 | H40: 32.4 | I40: 59.9 | J40: 24.3 | K40: 54.3 | L40: 28.8 | M40: 30.8 | N40: 69.7 | O40: =MAX(C40:N40) -> 73.5
B41: 2022 | C41: 15 | D41: 48.8 | E41: 54.4 | F41: 39 | G41: 48.1 | H41: 17 | I41: 15.8 | J41: 40.9 | K41: 32.8 | L41: 31.6 | M41: 85.2 | N41: 43 | O41: =MAX(C41:N41) -> 85.2
B42: 2023 | C42: 58 | D42: 22.8 | E42: 92.4 | F42: 43.3 | G42: 25.8 | H42: 9.2 | I42: 14.5 | J42: 26 | K42: 14 | L42: 14.2 | M42: 77.5 | N42: 56.5 | O42: =MAX(C42:N42) -> 92.4
B43: 2024 | C43: 57.8 | D43: 72.2 | E43: 30.8 | F43: 34.5 | G43: 16.4 | H43: 10.4 | I43: 6 | J43: — | K43: — | L43: — | M43: — | N43: — | O43: =MAX(C43:N43) -> 72.2

Sheet B.Modelo Distribución
B2: Proyecto | C2: =+'A. Estación'!C2 -> “CREACIÓN DEL SERVICIO DE PROTECCIÓN INTEGRAL A NIÑAS, NIÑOS Y ADOLESCENTES SIN CUIDADOS PARENTALES O EN RIESGO DE PERDERLOS EN CENTRO DE ACOGIDA RESIDENCIAL - VARONES DISTRITO DE MORALES DE LA PROVINCIA DE SAN MARTÍN DEL DEPARTAMENTO DE SAN MARTÍN”, con CUI N.° 2705619
B3: Entidad | C3: =+'A. Estación'!C3 -> GERENCIA TERRITORIAL BAJO MAYO
B4: Ubicación | C4: =+'A. Estación'!C4 -> SAN MARTIN - SAN MARTIN - MORALES
B5: Fecha | C5: =+'A. Estación'!C5 -> SETIEMBRE 2026
B7: B. MODELOS DE DISTRIBUCIÓN DE DATOS ESTADÍSTICOS DE PRECIPITACIÓN MÁXIMAS EXTREMAS EN 24 HORAS
B9: Precipitación Máxima Anual en mm | F9: B.1. Distribución Normal | L9: B.3. Distribución Log Pearson III
B10: Año | C10: P máx | D10: Log P | F10: T (años) | G10: P | H10: w | I10: z | J10: P máx (mm) | L10: T (años) | M10: P | N10: w | O10: z | P10: KT | Q10: Log P | R10: P máx (mm)
B11: 1999 | C11: ='A. Estación'!O18 -> 79.3 | D11: =LOG(C11) -> 1.8992732 | F11: 2 | G11: =1/F11 -> 0.5 | H11: =(LN(1/G11^2))^0.5 -> 1.17741 | I11: =+H11-(2.515517+0.802853*H11+0.010328*H11^2)/(1+1.432788*H11+0.189269*H11^2+0.001308*H11^3) -> -1.0100668e-07 | J11: =+$C$37+I11*$C$39 -> 79.353844 | L11: 2 | M11: =1/L11 -> 0.5 | N11: =(LN(1/M11^2))^0.5 -> 1.17741 | O11: =+N11-(2.515517+0.802853*N11+0.010328*N11^2)/(1+1.432788*N11+0.189269*N11^2+0.001308*N11^3) -> -1.0100668e-07 | P11: =+O11+(O11^2-1)*$D$41+1/3*(O11^3-6*O11)*$D$41^2-(O11^2-1)*$D$41^3+O11*$D$41^4+1/3*$D$41^5 -> -0.026040841 | Q11: =+$D$37+P11*$D$39 -> 1.8817547 | R11: =10^Q11 -> 76.164876
B12: 2000 | C12: ='A. Estación'!O19 -> 82.5 | D12: =LOG(C12) -> 1.9164539 | F12: 5 | G12: =1/F12 -> 0.2 | H12: =(LN(1/G12^2))^0.5 -> 1.7941226 | I12: =+H12-(2.515517+0.802853*H12+0.010328*H12^2)/(1+1.432788*H12+0.189269*H12^2+0.001308*H12^3) -> 0.84145672 | J12: =+$C$37+I12*$C$39 -> 97.923318 | L12: 5 | M12: =1/L12 -> 0.2 | N12: =(LN(1/M12^2))^0.5 -> 1.7941226 | O12: =+N12-(2.515517+0.802853*N12+0.010328*N12^2)/(1+1.432788*N12+0.189269*N12^2+0.001308*N12^3) -> 0.84145672 | P12: =+O12+(O12^2-1)*$D$41+1/3*(O12^3-6*O12)*$D$41^2-(O12^2-1)*$D$41^3+O12*$D$41^4+1/3*$D$41^5 -> 0.83284659 | Q12: =+$D$37+P12*$D$39 -> 1.9803112 | R12: =10^Q12 -> 95.567724
B13: 2001 | C13: ='A. Estación'!O20 -> 75.9 | D13: =LOG(C13) -> 1.8802418 | F13: 10 | G13: =1/F13 -> 0.1 | H13: =(LN(1/G13^2))^0.5 -> 2.145966 | I13: =+H13-(2.515517+0.802853*H13+0.010328*H13^2)/(1+1.432788*H13+0.189269*H13^2+0.001308*H13^3) -> 1.2817288 | J13: =+$C$37+I13*$C$39 -> 107.63935 | L13: 10 | M13: =1/L13 -> 0.1 | N13: =(LN(1/M13^2))^0.5 -> 2.145966 | O13: =+N13-(2.515517+0.802853*N13+0.010328*N13^2)/(1+1.432788*N13+0.189269*N13^2+0.001308*N13^3) -> 1.2817288 | P13: =+O13+(O13^2-1)*$D$41+1/3*(O13^3-6*O13)*$D$41^2-(O13^2-1)*$D$41^3+O13*$D$41^4+1/3*$D$41^5 -> 1.297205 | Q13: =+$D$37+P13*$D$39 -> 2.0335959 | R13: =10^Q13 -> 108.04282
B14: 2002 | C14: ='A. Estación'!O21 -> 43.6 | D14: =LOG(C14) -> 1.6394865 | F14: 20 | G14: =1/F14 -> 0.05 | H14: =(LN(1/G14^2))^0.5 -> 2.4477468 | I14: =+H14-(2.515517+0.802853*H14+0.010328*H14^2)/(1+1.432788*H14+0.189269*H14^2+0.001308*H14^3) -> 1.6452114 | J14: =+$C$37+I14*$C$39 -> 115.66077 | L14: 20 | M14: =1/L14 -> 0.05 | N14: =(LN(1/M14^2))^0.5 -> 2.4477468 | O14: =+N14-(2.515517+0.802853*N14+0.010328*N14^2)/(1+1.432788*N14+0.189269*N14^2+0.001308*N14^3) -> 1.6452114 | P14: =+O14+(O14^2-1)*$D$41+1/3*(O14^3-6*O14)*$D$41^2-(O14^2-1)*$D$41^3+O14*$D$41^4+1/3*$D$41^5 -> 1.6884301 | Q14: =+$D$37+P14*$D$39 -> 2.0784886 | R14: =10^Q14 -> 119.80878
B15: 2003 | C15: ='A. Estación'!O22 -> 84.5 | D15: =LOG(C15) -> 1.9268567 | F15: 25 | G15: =1/F15 -> 0.04 | H15: =(LN(1/G15^2))^0.5 -> 2.5372725 | I15: =+H15-(2.515517+0.802853*H15+0.010328*H15^2)/(1+1.432788*H15+0.189269*H15^2+0.001308*H15^3) -> 1.7510765 | J15: =+$C$37+I15*$C$39 -> 117.99703 | L15: 25 | M15: =1/L15 -> 0.04 | N15: =(LN(1/M15^2))^0.5 -> 2.5372725 | O15: =+N15-(2.515517+0.802853*N15+0.010328*N15^2)/(1+1.432788*N15+0.189269*N15^2+0.001308*N15^3) -> 1.7510765 | P15: =+O15+(O15^2-1)*$D$41+1/3*(O15^3-6*O15)*$D$41^2-(O15^2-1)*$D$41^3+O15*$D$41^4+1/3*$D$41^5 -> 1.8037217 | Q15: =+$D$37+P15*$D$39 -> 2.0917182 | R15: =10^Q15 -> 123.51458
B16: 2004 | C16: ='A. Estación'!O23 -> 64.2 | D16: =LOG(C16) -> 1.807535 | F16: 50 | G16: =1/F16 -> 0.02 | H16: =(LN(1/G16^2))^0.5 -> 2.7971496 | I16: =+H16-(2.515517+0.802853*H16+0.010328*H16^2)/(1+1.432788*H16+0.189269*H16^2+0.001308*H16^3) -> 2.0541886 | J16: =+$C$37+I16*$C$39 -> 124.68618 | L16: 50 | M16: =1/L16 -> 0.02 | N16: =(LN(1/M16^2))^0.5 -> 2.7971496 | O16: =+N16-(2.515517+0.802853*N16+0.010328*N16^2)/(1+1.432788*N16+0.189269*N16^2+0.001308*N16^3) -> 2.0541886 | P16: =+O16+(O16^2-1)*$D$41+1/3*(O16^3-6*O16)*$D$41^2-(O16^2-1)*$D$41^3+O16*$D$41^4+1/3*$D$41^5 -> 2.1372049 | Q16: =+$D$37+P16*$D$39 -> 2.1299851 | R16: =10^Q16 -> 134.89166
B17: 2005 | C17: ='A. Estación'!O24 -> 71 | D17: =LOG(C17) -> 1.8512583 | F17: 100 | G17: =1/F17 -> 0.01 | H17: =(LN(1/G17^2))^0.5 -> 3.0348543 | I17: =+H17-(2.515517+0.802853*H17+0.010328*H17^2)/(1+1.432788*H17+0.189269*H17^2+0.001308*H17^3) -> 2.3267853 | J17: =+$C$37+I17*$C$39 -> 130.70191 | L17: 100 | M17: =1/L17 -> 0.01 | N17: =(LN(1/M17^2))^0.5 -> 3.0348543 | O17: =+N17-(2.515517+0.802853*N17+0.010328*N17^2)/(1+1.432788*N17+0.189269*N17^2+0.001308*N17^3) -> 2.3267853 | P17: =+O17+(O17^2-1)*$D$41+1/3*(O17^3-6*O17)*$D$41^2-(O17^2-1)*$D$41^3+O17*$D$41^4+1/3*$D$41^5 -> 2.4414198 | Q17: =+$D$37+P17*$D$39 -> 2.1648935 | R17: =10^Q17 -> 146.18186
B18: 2006 | C18: ='A. Estación'!O25 -> 113.3 | D18: =LOG(C18) -> 2.0542299 | F18: 200 | G18: =1/F18 -> 0.005 | H18: =(LN(1/G18^2))^0.5 -> 3.2552473 | I18: =+H18-(2.515517+0.802853*H18+0.010328*H18^2)/(1+1.432788*H18+0.189269*H18^2+0.001308*H18^3) -> 2.5762361 | J18: =+$C$37+I18*$C$39 -> 136.20685 | L18: 200 | M18: =1/L18 -> 0.005 | N18: =(LN(1/M18^2))^0.5 -> 3.2552473 | O18: =+N18-(2.515517+0.802853*N18+0.010328*N18^2)/(1+1.432788*N18+0.189269*N18^2+0.001308*N18^3) -> 2.5762361 | P18: =+O18+(O18^2-1)*$D$41+1/3*(O18^3-6*O18)*$D$41^2-(O18^2-1)*$D$41^3+O18*$D$41^4+1/3*$D$41^5 -> 2.7234002 | Q18: =+$D$37+P18*$D$39 -> 2.1972505 | R18: =10^Q18 -> 157.48908
B19: 2007 | C19: ='A. Estación'!O26 -> 63.5 | D19: =LOG(C19) -> 1.8027737 | F19: 500 | G19: =1/F19 -> 0.002 | H19: =(LN(1/G19^2))^0.5 -> 3.5255094 | I19: =+H19-(2.515517+0.802853*H19+0.010328*H19^2)/(1+1.432788*H19+0.189269*H19^2+0.001308*H19^3) -> 2.8785061 | J19: =+$C$37+I19*$C$39 -> 142.87742 | L19: 500 | M19: =1/L19 -> 0.002 | N19: =(LN(1/M19^2))^0.5 -> 3.5255094 | O19: =+N19-(2.515517+0.802853*N19+0.010328*N19^2)/(1+1.432788*N19+0.189269*N19^2+0.001308*N19^3) -> 2.8785061 | P19: =+O19+(O19^2-1)*$D$41+1/3*(O19^3-6*O19)*$D$41^2-(O19^2-1)*$D$41^3+O19*$D$41^4+1/3*$D$41^5 -> 3.0697243 | Q19: =+$D$37+P19*$D$39 -> 2.2369908 | R19: =10^Q19 -> 172.58014
B20: 2008 | C20: ='A. Estación'!O27 -> 91 | D20: =LOG(C20) -> 1.9590414
B21: 2009 | C21: ='A. Estación'!O28 -> 49 | D21: =LOG(C21) -> 1.6901961
B22: 2010 | C22: ='A. Estación'!O29 -> 98.4 | D22: =LOG(C22) -> 1.9929951
B23: 2011 | C23: ='A. Estación'!O30 -> 65.2 | D23: =LOG(C23) -> 1.8142476
B24: 2012 | C24: ='A. Estación'!O31 -> 100.5 | D24: =LOG(C24) -> 2.0021661
B25: 2013 | C25: ='A. Estación'!O32 -> 71.7 | D25: =LOG(C25) -> 1.8555192
B26: 2014 | C26: ='A. Estación'!O33 -> 89.5 | D26: =LOG(C26) -> 1.951823
B27: 2015 | C27: ='A. Estación'!O34 -> 64.2 | D27: =LOG(C27) -> 1.807535
B28: 2016 | C28: ='A. Estación'!O35 -> 50 | D28: =LOG(C28) -> 1.69897
B29: 2017 | C29: ='A. Estación'!O36 -> 73.6 | D29: =LOG(C29) -> 1.8668778
B30: 2018 | C30: ='A. Estación'!O37 -> 69.6 | D30: =LOG(C30) -> 1.8426092
B31: 2019 | C31: ='A. Estación'!O38 -> 86.9 | D31: =LOG(C31) -> 1.9390198
... B36: 2024 | C36: ='A. Estación'!O43 -> 72.2 | D36: =LOG(C36) -> 1.8585372
B37: m (media) | C37: =AVERAGE(C11:C36) -> 79.353846 | D37: =AVERAGE(D11:D36) -> 1.8847429
B38: var (varianza) | C38: =+C39^2 -> 487.00738 | D38: =+D39^2 -> 0.013167342
B39: s (desv.Est) | C39: =STDEV(C11:C36) -> 22.068244 | D39: =STDEV(D11:D36) -> 0.11474904
B40: Coef. Asimetría | C40: =SKEW(C11:C36) -> 1.3586958 | D40: =SKEW(D11:D36) -> 0.15635063
B41: k (Factor k) | D41: =+D40/6 -> 0.026058439
B42: n ( n°de datos) | C42: =COUNT(C11:C36) -> 26 | D42: =COUNT(D11:D36) -> 26
C45: B.4. Distribución Extrema Tipo I - Gumbel
C46: T (años) | D46: KT | E46: P máx (mm)
C47: 2 | D47: =-SQRT(6)/PI()*(0.5772+LN(LN(C47/(C47-1)))) -> -0.16427204 | E47: =$C$37+D47*$C$39 -> 75.728651
C48: 5 | D48: =-SQRT(6)/PI()*(0.5772+LN(LN(C48/(C48-1)))) -> 0.71945742 | E48: =$C$37+D48*$C$39 -> 95.231008
C49: 10 | D49: =-SQRT(6)/PI()*(0.5772+LN(LN(C49/(C49-1)))) -> 1.3045632 | E49: =$C$37+D49*$C$39 -> 108.14327
...

Sheet C. Prueba Kolmorov-Smirnov
B2: Proyecto | C2: ='A. Estación'!C2:O2 -> “CREACIÓN DEL SERVICIO DE PROTECCIÓN INTEGRAL A NIÑAS, NIÑOS Y ADOLESCENTES SIN CUIDADOS PARENTALES O EN RIESGO DE PERDERLOS EN CENTRO DE ACOGIDA RESIDENCIAL - VARONES DISTRITO DE MORALES DE LA PROVINCIA DE SAN MARTÍN DEL DEPARTAMENTO DE SAN MARTÍN”, con CUI N.° 2705619
B3: Entidad | C3: ='A. Estación'!C3:O3 -> GERENCIA TERRITORIAL BAJO MAYO
B4: Ubicación | C4: ='A. Estación'!C4:O4 -> SAN MARTIN - SAN MARTIN - MORALES
B5: Fecha | C5: ='A. Estación'!C5:O5 -> SETIEMBRE 2026
B7: C. PRUEBA DE BONDAD DE KOLMOGOROV - SMIRNOV | AB7: Aparicio pag. 264
AB8: tabla para distribución Gumbel.
F9: X | K9: log X | P9: ln X | V9: X | AB9: n | AC9: my | AD9: sy
C10: Numero de datos n : | F10: =+'B.Modelo Distribución'!C42 -> 26 | H10: Numero de datos n : | K10: =+'B.Modelo Distribución'!C42 -> 26 | L10: Numero de datos n : | P10: =K10 -> 26 | R10: Numero de datos n : | V10: =P10 -> 26 | AB10: 10 | AC10: 0.4952 | AD10: 0.9496
C11: Promedio x : | F11: =AVERAGE(C22:C47) -> 79.353846 | H11: Promedio Log x : | K11: =AVERAGE(D22:D47) -> 1.8847429 | L11: Promedio x : | P11: =AVERAGE(N22:N47) -> 4.3397809 | R11: Promedio x : | V11: =F11 -> 79.353846 | AB11: 15 | AC11: 0.5128 | AD11: 1.0206
C12: Desviacion estándar s : | F12: =STDEV(C22:C47) -> 22.068244 | H12: Desviacion estándar s : | K12: =STDEV(D22:D47) -> 0.11474904 | L12: Desviacion estándar s : | P12: =STDEV(N22:N47) -> 0.26421943 | R12: Desviacion estándar s : | V12: =F12 -> 22.068244 | AB12: 20 | AC12: 0.5236 | AD12: 1.0628
C13: Coeficiente asimetria Cs (sesgo): | F13: =SKEW(C22:C47) -> 1.3586958 | H13: Coeficiente asimetría Cs (sesgo): | K13: =SKEW(D22:D47) -> 0.15635063 | L13: Coeficiente asimetria Cs (sesgo): | P13: =SKEW(N22:N47) -> 0.15635063 | R13: Coeficiente asimetria Cs (sesgo): | V13: =F13 -> 1.3586958 | AB13: 25 | AC13: 0.5309 | AD13: 1.0914
C14: k = Cs/6 : | F14: =F13/6 -> 0.2264493 | O14: k = Cs/6 : | P14: =P13/6 -> 0.026058439 | AB14: 30 | AC14: 0.5362 | AD14: 1.1124
C15: β1=(2/Cs)2: | F15: =(2/F13)^2 -> 2.1667836 | O15: β1=(2/Cs)2: | P15: =(2/P13)^2 -> 163.62916 | AB15: 90 | AC15: 0.5586 | AD15: 1.2007
C16: α1=S/√β1 | F16: =F12/SQRT(F15) -> 14.992015 | O16: α1=S/√β1 | P16: =P12/SQRT(P15) -> 0.020655437 | U16: µY : | V16: =FORECAST(V10,$AC$13:$AC$14,$AB$13:$AB$14) -> 0.53196 | W16: media de datos | AB16: 95 | AC16: 0.5593 | AD16: 1.2037
C17: δ1=X-α1β1 | F17: =F11-F16*F15 -> 46.869395 | O17: δ1=X-α1β1 | P17: =P11-P16*P15 -> 0.95994904 | U17: sY : | V17: =FORECAST(V10,$AD$13:$AD$14,$AB$13:$AB$14) -> 1.0956 | AB17: xe =b-1/a ln ln (T/(T-1)
B20: N | C20: P = x | D20: P = LOG x | E20: P(X≥xT)OBS | F20: Distribución Normal | J20: Distribución Log Normal | N20: Distribución Log Pearson Tipo III | V20: Distribución Gumbel
D21: P = LOG x | F21: z | G21: F(Z) | H21: P(X≥xT)TEO | I21: D(N) | J21: z | K21: F(Z) | L21: P(X≥xT)TEO | M21: D(N) | N21: LnP | O21: Y=(x-δ1)/α1 | P21: 2Y | Q21: 2β1 | R21: χ2 | S21: Fx | T21: Fo | U21: D(N) | V21: P = x | W21: K | X21: Y | Y21: P(X≥xT)TEO | Z21: D(N)
B22: 1 | C22: =LARGE('A. Estación'!$O$18:$O$43,B22) -> 152.5 | D22: =LOG(C22) -> 2.1832698 | E22: =B22/(F$10+1) -> 0.037037037 | F22: =(C22-F$11)/F$12 -> 3.3145435 | G22: =NORMSDIST(F22) -> 0.99954104 | H22: =1-G22 -> 0.0004589645 | I22: =ABS(H22-E22) -> 0.036578073 | J22: =(D22-K$11)/K$12 -> 2.6015638 | K22: =NORMSDIST(J22) -> 0.99536001 | L22: =1-K22 -> 0.00463999 | M22: =ABS(L22-E22) -> 0.032397047 | N22: =LN(C22) -> 5.0271646 | O22: =(N22-$P$17)/$P$16 -> 196.90774 | P22: =2*O22 -> 393.81549 | Q22: =2*$P$15 -> 327.25832 | R22: =CHIDIST(P22,Q22) -> 0.0065876198 | S22: =R22 -> 0.0065876198 | T22: =(B22/($P$10+1)) -> 0.037037037 | U22: =ABS(T22-S22) -> 0.030449417 | V22: =C22 -> 152.5 | W22: =(C22-V$11)/V$12 -> 3.3145435 | X22: =W22*V$17+V$16 -> 4.1633738 | Y22: =1-EXP(-EXP(-X22)) -> 0.015434635 | Z22: =ABS(Y22-E22) -> 0.021602402
B23: =+B22+1 -> 2 | C23: =LARGE('A. Estación'!$O$18:$O$43,B23) -> 113.3 | D23: =LOG(C23) -> 2.0542299 | E23: =B23/(F$10+1) -> 0.074074074 | F23: =(C23-F$11)/F$12 -> 1.5382354 | G23: =NORMSDIST(F23) -> 0.93800447 | H23: =1-G23 -> 0.061995534 | I23: =ABS(H23-E23) -> 0.01207854 | J23: =(D23-K$11)/K$12 -> 1.4770234 | K23: =NORMSDIST(J23) -> 0.93016531 | L23: =1-K23 -> 0.069834686 | M23: =ABS(L23-E23) -> 0.0042393878 | N23: =LN(C23) -> 4.7300392 | O23: =(N23-$P$17)/$P$16 -> 182.52289 | P23: =2*O23 -> 365.04578 | Q23: =2*$P$15 -> 327.25832 | R23: =CHIDIST(P23,Q23) -> 0.07221872 | S23: =R23 -> 0.07221872 | T23: =(B23/($P$10+1)) -> 0.074074074 | U23: =ABS(T23-S23) -> 0.0018553537 | V23: =C23 -> 113.3 | W23: =(C23-V$11)/V$12 -> 1.5382354 | X23: =W23*V$17+V$16 -> 2.2172507 | Y23: =1-EXP(-EXP(-X23)) -> 0.10318719 | Z23: =ABS(Y23-E23) -> 0.029113111
B24: =+B23+1 -> 3 | C24: =LARGE('A. Estación'!$O$18:$O$43,B24) -> 100.5 | D24: =LOG(C24) -> 2.0021661 | E24: =B24/(F$10+1) -> 0.11111111 | F24: =(C24-F$11)/F$12 -> 0.95821643 | G24: =NORMSDIST(F24) -> 0.83102318 | H24: =1-G24 -> 0.16897682 | I24: =ABS(H24-E24) -> 0.057865705 | J24: =(D24-K$11)/K$12 -> 1.0233041 | K24: =NORMSDIST(J24) -> 0.84691796 | L24: =1-K24 -> 0.15308204 | M24: =ABS(L24-E24) -> 0.041970928 | N24: =LN(C24) -> 4.6101577 | O24: =(N24-$P$17)/$P$16 -> 176.71902 | P24: =2*O24 -> 353.43805 | Q24: =2*$P$15 -> 327.25832 | R24: =CHIDIST(P24,Q24) -> 0.15077999 | S24: =R24 -> 0.15077999 | T24: =(B24/($P$10+1)) -> 0.11111111 | U24: =ABS(T24-S24) -> 0.039668877 | V24: =C24 -> 100.5 | W24: =(C24-V$11)/V$12 -> 0.95821643 | X24: =W24*V$17+V$16 -> 1.5817819 | Y24: =1-EXP(-EXP(-X24)) -> 0.18584816 | Z24: =ABS(Y24-E24) -> 0.074737048
B25: =+B24+1 -> 4 | C25: =LARGE('A. Estación'!$O$18:$O$43,B25) -> 98.4 | D25: =LOG(C25) -> 1.9929951 | E25: =B25/(F$10+1) -> 0.14814815 | F25: =(C25-F$11)/F$12 -> 0.86305707 | G25: =NORMSDIST(F25) -> 0.80594696 | H25: =1-G25 -> 0.19405304 | I25: =ABS(H25-E25) -> 0.045904897 | J25: =(D25-K$11)/K$12 -> 0.9433822 | K25: =NORMSDIST(J25) -> 0.82725728 | L25: =1-K25 -> 0.17274272 | M25: =ABS(L25-E25) -> 0.024594574 | N25: =LN(C25) -> 4.5890408 | O25: =(N25-$P$17)/$P$16 -> 175.69668 | P25: =2*O25 -> 351.39336 | Q25: =2*$P$15 -> 327.25832 | R25: =CHIDIST(P25,Q25) -> 0.16927524 | S25: =R25 -> 0.16927524 | T25: =(B25/($P$10+1)) -> 0.14814815 | U25: =ABS(T25-S25) -> 0.021127094 | V25: =C25 -> 98.4 | W25: =(C25-V$11)/V$12 -> 0.86305707 | X25: =W25*V$17+V$16 -> 1.4775253 | Y25: =1-EXP(-EXP(-X25)) -> 0.20403631 | Z25: =ABS(Y25-E25) -> 0.055888166
B26: =+B25+1 -> 5 | C26: =LARGE('A. Estación'!$O$18:$O$43,B26) -> 92.4 | D26: =LOG(C26) -> 1.965672 | E26: =B26/(F$10+1) -> 0.18518519 | F26: =(C26-F$11)/F$12 -> 0.59117318 | G26: =NORMSDIST(F26) -> 0.7227978 | H26: =1-G26 -> 0.2772022 | I26: =ABS(H26-E26) -> 0.092017011 | J26: =(D26-K$11)/K$12 -> 0.70527016 | K26: =NORMSDIST(J26) -> 0.75967894 | L26: =1-K26 -> 0.24032106 | M26: =ABS(L26-E26) -> 0.055135877 | N26: =LN(C26) -> 4.526127 | O26: =(N26-$P$17)/$P$16 -> 172.65081 | P26: =2*O26 -> 345.30162 | Q26: =2*$P$15 -> 327.25832 | R26: =CHIDIST(P26,Q26) -> 0.23310135 | S26: =R26 -> 0.23310135 | T26: =(B26/($P$10+1)) -> 0.18518519 | U26: =ABS(T26-S26) -> 0.047916164 | V26: =C26 -> 92.4 | W26: =(C26-V$11)/V$12 -> 0.59117318 | X26: =W26*V$17+V$16 -> 1.1796493 | Y26: =1-EXP(-EXP(-X26)) -> 0.26463368 | Z26: =ABS(Y26-E26) -> 0.079448495
B27: =+B26+1 -> 6 | C27: =LARGE('A. Estación'!$O$18:$O$43,B27) -> 91 | D27: =LOG(C27) -> 1.9590414 | E27: =B27/(F$10+1) -> 0.22222222 | F27: =(C27-F$11)/F$12 -> 0.5277336 | G27: =NORMSDIST(F27) -> 0.70115788 | H27: =1-G27 -> 0.29884212 | I27: =ABS(H27-E27) -> 0.076619901 | J27: =(D27-K$11)/K$12 -> 0.64748686 | K27: =NORMSDIST(J27) -> 0.74134155 | L27: =1-K27 -> 0.25865845 | M27: =ABS(L27-E27) -> 0.036436227 | N27: =LN(C27) -> 4.5108595 | O27: =(N27-$P$17)/$P$16 -> 171.91166 | P27: =2*O27 -> 343.82332 | Q27: =2*$P$15 -> 327.25832 | R27: =CHIDIST(P27,Q27) -> 0.25052079 | S27: =R27 -> 0.25052079 | T27: =(B27/($P$10+1)) -> 0.22222222 | U27: =ABS(T27-S27) -> 0.028298563 | V27: =C27 -> 91 | W27: =(C27-V$11)/V$12 -> 0.5277336 | X27: =W27*V$17+V$16 -> 1.1101449 | Y27: =1-EXP(-EXP(-X27)) -> 0.28072477 | Z27: =ABS(Y27-E27) -> 0.058502548
B28: =+B27+1 -> 7 | C28: =LARGE('A. Estación'!$O$18:$O$43,B28) -> 89.5 | D28: =LOG(C28) -> 1.951823 | E28: =B28/(F$10+1) -> 0.25925926 | F28: =(C28-F$11)/F$12 -> 0.45976263 | G28: =NORMSDIST(F28) -> 0.6771567 | H28: =1-G28 -> 0.3228433 | I28: =ABS(H28-E28) -> 0.063584045 | J28: =(D28-K$11)/K$12 -> 0.58458126 | K28: =NORMSDIST(J28) -> 0.72058534 | L28: =1-K28 -> 0.27941466 | M28: =ABS(L28-E28) -> 0.020155397 | N28: =LN(C28) -> 4.4942386 | O28: =(N28-$P$17)/$P$16 -> 171.10699 | P28: =2*O28 -> 342.21397 | Q28: =2*$P$15 -> 327.25832 | R28: =CHIDIST(P28,Q28) -> 0.27030111 | S28: =R28 -> 0.27030111 | T28: =(B28/($P$10+1)) -> 0.25925926 | U28: =ABS(T28-S28) -> 0.011041849 | V28: =C28 -> 89.5 | W28: =(C28-V$11)/V$12 -> 0.45976263 | X28: =W28*V$17+V$16 -> 1.0356759 | Y28: =1-EXP(-EXP(-X28)) -> 0.29881699 | Z28: =ABS(Y28-E28) -> 0.039557727
B29: =+B28+1 -> 8 | C29: =LARGE('A. Estación'!$O$18:$O$43,B29) -> 86.9 | D29: =LOG(C29) -> 1.9390198 | E29: =B29/(F$10+1) -> 0.2962963 | F29: =(C29-F$11)/F$12 -> 0.34194628 | G29: =NORMSDIST(F29) -> 0.63380434 | H29: =1-G29 -> 0.36619566 | I29: =ABS(H29-E29) -> 0.069899364 | J29: =(D29-K$11)/K$12 -> 0.47300508 | K29: =NORMSDIST(J29) -> 0.68189522 | L29: =1-K29 -> 0.31810478 | M29: =ABS(L29-E29) -> 0.021808481 | N29: =LN(C29) -> 4.464758 | O29: =(N29-$P$17)/$P$16 -> 169.67973 | P29: =2*O29 -> 339.35946 | Q29: =2*$P$15 -> 327.25832 | R29: =CHIDIST(P29,Q29) -> 0.3073674 | S29: =R29 -> 0.3073674 | T29: =(B29/($P$10+1)) -> 0.2962963 | U29: =ABS(T29-S29) -> 0.011071105 | V29: =C29 -> 86.9 | W29: =(C29-V$11)/V$12 -> 0.34194628 | X29: =W29*V$17+V$16 -> 0.90659634 | Y29: =1-EXP(-EXP(-X29)) -> 0.33228685 | Z29: =ABS(Y29-E29) -> 0.035990553
B30: =+B29+1 -> 9 | C30: =LARGE('A. Estación'!$O$18:$O$43,B30) -> 85.2 | D30: =LOG(C30) -> 1.9304396 | E30: =B30/(F$10+1) -> 0.33333333 | F30: =(C30-F$11)/F$12 -> 0.26491251 | G30: =NORMSDIST(F30) -> 0.60446157 | H30: =1-G30 -> 0.39553843 | I30: =ABS(H30-E30) -> 0.062205097 | J30: =(D30-K$11)/K$12 -> 0.39823163 | K30: =NORMSDIST(J30) -> 0.65477027 | L30: =1-K30 -> 0.34522973 | M30: =ABS(L30-E30) -> 0.011896393 | N30: =LN(C30) -> 4.4450014 | O30: =(N30-$P$17)/$P$16 -> 168.72325 | P30: =2*O30 -> 337.44649 | Q30: =2*$P$15 -> 327.25832 | R30: =CHIDIST(P30,Q30) -> 0.33351659 | S30: =R30 -> 0.33351659 | T30: =(B30/($P$10+1)) -> 0.33333333 | U30: =ABS(T30-S30) -> 0.00018325974 | V30: =C30 -> 85.2 | W30: =(C30-V$11)/V$12 -> 0.26491251 | X30: =W30*V$17+V$16 -> 0.82219815 | Y30: =1-EXP(-EXP(-X30)) -> 0.35561866 | Z30: =ABS(Y30-E30) -> 0.022285326
B31: =+B30+1 -> 10 | C31: =LARGE('A. Estación'!$O$18:$O$43,B31) -> 84.5 | D31: =LOG(C31) -> 1.9268567 | E31: =B31/(F$10+1) -> 0.37037037 | F31: =(C31-F$11)/F$12 -> 0.23319272 | G31: =NORMSDIST(F31) -> 0.59219412 | H31: =1-G31 -> 0.40780588 | I31: =ABS(H31-E31) -> 0.037435508 | J31: =(D31-K$11)/K$12 -> 0.36700796 | K31: =NORMSDIST(J31) -> 0.64319346 | L31: =1-K31 -> 0.35680654 | M31: =ABS(L31-E31) -> 0.013563831 | N31: =LN(C31) -> 4.4367515 | O31: =(N31-$P$17)/$P$16 -> 168.32384 | P31: =2*O31 -> 336.64768 | Q31: =2*$P$15 -> 327.25832 | R31: =CHIDIST(P31,Q31) -> 0.34471982 | S31: =R31 -> 0.34471982 | T31: =(B31/($P$10+1)) -> 0.37037037 | U31: =ABS(T31-S31) -> 0.025650549 | V31: =C31 -> 84.5 | W31: =(C31-V$11)/V$12 -> 0.23319272 | X31: =W31*V$17+V$16 -> 0.78744595 | Y31: =1-EXP(-EXP(-X31)) -> 0.36555547 | Z31: =ABS(Y31-E31) -> 0.0048148992
B32: =+B31+1 -> 11 | C32: =LARGE('A. Estación'!$O$18:$O$43,B32) -> 82.5 | D32: =LOG(C32) -> 1.9164539 | E32: =B32/(F$10+1) -> 0.40740741 | F32: =(C32-F$11)/F$12 -> 0.14256476 | G32: =NORMSDIST(F32) -> 0.55668303 | H32: =1-G32 -> 0.44331697 | I32: =ABS(H32-E32) -> 0.035909559 | J32: =(D32-K$11)/K$12 -> 0.27635134 | K32: =NORMSDIST(J32) -> 0.60886089 | L32: =1-K32 -> 0.39113911 | M32: =ABS(L32-E32) -> 0.016268294 | N32: =LN(C32) -> 4.4127983 | O32: =(N32-$P$17)/$P$16 -> 167.16418 | P32: =2*O32 -> 334.32836 | Q32: =2*$P$15 -> 327.25832 | R32: =CHIDIST(P32,Q32) -> 0.37810074 | S32: =R32 -> 0.37810074 | T32: =(B32/($P$10+1)) -> 0.40740741 | U32: =ABS(T32-S32) -> 0.029306672 | V32: =C32 -> 82.5 | W32: =(C32-V$11)/V$12 -> 0.14256476 | X32: =W32*V$17+V$16 -> 0.68815395 | Y32: =1-EXP(-EXP(-X32)) -> 0.3949855 | Z32: =ABS(Y32-E32) -> 0.012421904
B33: =+B32+1 -> 12 | C33: =LARGE('A. Estación'!$O$18:$O$43,B33) -> 79.3 | D33: =LOG(C33) -> 1.8992732 | E33: =B33/(F$10+1) -> 0.44444444 | F33: =(C33-F$11)/F$12 -> -0.0024399836 | G33: =NORMSDIST(F33) -> 0.49902659 | H33: =1-G33 -> 0.50097341 | I33: =ABS(H33-E33) -> 0.056528967 | J33: =(D33-K$11)/K$12 -> 0.12662668 | K33: =NORMSDIST(J33) -> 0.55038206 | L33: =1-K33 -> 0.44961794 | M33: =ABS(L33-E33) -> 0.0051734971 | N33: =LN(C33) -> 4.3732381 | O33: =(N33-$P$17)/$P$16 -> 165.24894 | P33: =2*O33 -> 330.49788 | Q33: =2*$P$15 -> 327.25832 | R33: =CHIDIST(P33,Q33) -> 0.43551803 | S33: =R33 -> 0.43551803 | T33: =(B33/($P$10+1)) -> 0.44444444 | U33: =ABS(T33-S33) -> 0.0089264125 | V33: =C33 -> 79.3 | W33: =(C33-V$11)/V$12 -> -0.0024399836 | X33: =W33*V$17+V$16 -> 0.52928675 | Y33: =1-EXP(-EXP(-X33)) -> 0.44513195 | Z33: =ABS(Y33-E33) -> 0.00068750465
B34: =+B33+1 -> 13 | C34: =LARGE('A. Estación'!$O$18:$O$43,B34) -> 75.9 | D34: =LOG(C34) -> 1.8802418 | E34: =B34/(F$10+1) -> 0.48148148 | F34: =(C34-F$11)/F$12 -> -0.15650752 | G34: =NORMSDIST(F34) -> 0.4378165 | H34: =1-G34 -> 0.5621835 | I34: =ABS(H34-E34) -> 0.080702023 | J34: =(D34-K$11)/K$12 -> -0.039225794 | K34: =NORMSDIST(J34) -> 0.48435518 | L34: =1-K34 -> 0.51564482 | M34: =ABS(L34-E34) -> 0.034163334 | N34: =LN(C34) -> 4.3294167 | O34: =(N34-$P$17)/$P$16 -> 163.12739 | P34: =2*O34 -> 326.25479 | Q34: =2*$P$15 -> 327.25832 | R34: =CHIDIST(P34,Q34) -> 0.50123064 | S34: =R34 -> 0.50123064 | T34: =(B34/($P$10+1)) -> 0.48148148 | U34: =ABS(T34-S34) -> 0.019749154 | V34: =C34 -> 75.9 | W34: =(C34-V$11)/V$12 -> -0.15650752 | X34: =W34*V$17+V$16 -> 0.36049036 | Y34: =1-EXP(-EXP(-X34)) -> 0.50208918 | Z34: =ABS(Y34-E34) -> 0.0206077
... B47: =+B46+1 -> 26 | C47: =LARGE('A. Estación'!$O$18:$O$43,B47) -> 43.6 | D47: =LOG(C47) -> 1.6394865 | E47: =B47/(F$10+1) -> 0.96296296 | F47: =(C47-F$11)/F$12 -> -1.6201491 | G47: =NORMSDIST(F47) -> 0.052600122 | H47: =1-G47 -> 0.94739988 | I47: =ABS(H47-E47) -> 0.015563085 | J47: =(D47-K$11)/K$12 -> -2.1373287 | K47: =NORMSDIST(J47) -> 0.016285635 | L47: =1-K47 -> 0.98371437 | M47: =ABS(L47-E47) -> 0.020751402 | N47: =LN(C47) -> 3.7750572 | O47: =(N47-$P$17)/$P$16 -> 136.28896 | P47: =2*O47 -> 272.57793 | Q47: =2*$P$15 -> 327.25832 | R47: =CHIDIST(P47,Q47) -> 0.98721417 | S47: =R47 -> 0.98721417 | T47: =(B47/($P$10+1)) -> 0.96296296 | U47: =ABS(T47-S47) -> 0.02425121 | V47: =C47 -> 43.6 | W47: =(C47-V$11)/V$12 -> -1.6201491 | X47: =W47*V$17+V$16 -> -1.2430754 | Y47: =1-EXP(-EXP(-X47)) -> 0.96876629 | Z47: =ABS(Y47-E47) -> 0.0058033233
H48: MAX. | I48: =MAX(I22:I47) -> 0.092017011 | L48: MAX. | M48: =MAX(M22:M47) -> 0.089362099 | T48: MAX. | U48: =MAX(U22:U47) -> 0.096417109 | Y48: MAX. | Z48: =MAX(Z22:Z45) -> 0.12695298
B50: RESUMEN DE RESULTADOS | AB50: =M48 -> 0.089362099 | AC50: =+IFERROR(AB50,"") -> 0.089362099 | AD50: =E52 -> Log - Normal
B51: Estadístico | D51: Función de Distribución | O51: n : | P51: =+F10 -> 26
B52: K-S | D52: Normal | E52: Log - Normal | G52: Log Pearson Tipo III | I52: Gumbel | O52: a : | P52: 0.05 | AB52: =U48 -> 0.096417109 | AC52: =+IFERROR(AB52,"") -> 0.096417109 | AD52: =G52 -> Log Pearson Tipo III
B53: D(N) | D53: =+I48 -> 0.092017011 | E53: =+AC50 -> 0.089362099 | G53: =+IFERROR(U48,"No se ajusta a la distribución Log-Pearson Tipo 3") -> 0.096417109 | I53: =+AC53 -> 0.12695298 | O53: Máximo tabular: | P53: =+(-LN($P$52/2)/2/$P$51)^0.5-1/6/$P$51 -> 0.25993536 | AB53: =Z48 -> 0.12695298 | AC53: =+IFERROR(AB53,"") -> 0.12695298 | AD53: =I52 -> Gumbel
P54: D(N) < Dα
F55: FUNCION DE DISTRIBUCION SELECCIONADA : | G55: =AC57 -> Log - Normal
AB56: MINIMO | AC56: =MIN(AC48:AC53) -> 0.089362099
AB57: DISTRIBUCIÓN | AC57: =VLOOKUP(AC56,AC48:AE53,2,FALSE) -> Log - Normal

Sheet D.Resumen
B2: Proyecto | C2: ='A. Estación'!C2:O2 -> “CREACIÓN DEL SERVICIO DE PROTECCIÓN INTEGRAL A NIÑAS, NIÑOS Y ADOLESCENTES SIN CUIDADOS PARENTALES O EN RIESGO DE PERDERLOS EN CENTRO DE ACOGIDA RESIDENCIAL - VARONES DISTRITO DE MORALES DE LA PROVINCIA DE SAN MARTÍN DEL DEPARTAMENTO DE SAN MARTÍN”, con CUI N.° 2705619
B3: Entidad | C3: ='A. Estación'!C3:O3 -> GERENCIA TERRITORIAL BAJO MAYO
B4: Ubicación | C4: ='A. Estación'!C4:O4 -> SAN MARTIN - SAN MARTIN - MORALES
B5: Fecha | C5: ='A. Estación'!C5:O5 -> SETIEMBRE 2026
B7: C.4 RESUMEN DE LOS RESULTADOS DE LAS DISTRIBUCIONES ESTADISTICAS
B9: Normales | E9: Valor | G9: T (años) | H9: Normal | I9: Log Normal | J9: Log Pearson III | K9: Gumbel | L9: Diseño
B10: Media Aritmética | E10: ='B.Modelo Distribución'!C37 -> 79.353846 | G10: 2 | H10: ='B.Modelo Distribución'!J11 -> 79.353844 | I10: ='B.Modelo Distribución'!H59 -> 76.690733 | J10: ='B.Modelo Distribución'!R11 -> 76.164876 | K10: ='B.Modelo Distribución'!E47 -> 75.728651 | L10: =+I10 -> 76.690733
B11: Desviación Estándar | E11: ='B.Modelo Distribución'!C39 -> 22.068244 | G11: 5 | H11: ='B.Modelo Distribución'!J12 -> 97.923318 | I11: ='B.Modelo Distribución'!H60 -> 95.785385 | J11: ='B.Modelo Distribución'!R12 -> 95.567724 | K11: ='B.Modelo Distribución'!E48 -> 95.231008 | L11: =+I11 -> 95.785385
B12: Coeficiente de Asimetría | E12: ='B.Modelo Distribución'!C40 -> 1.3586958 | G12: 10 | H12: ='B.Modelo Distribución'!J13 -> 107.63935 | I12: ='B.Modelo Distribución'!H61 -> 107.60192 | J12: ='B.Modelo Distribución'!R13 -> 108.04282 | K12: ='B.Modelo Distribución'!E49 -> 108.14327 | L12: =+I12 -> 107.60192
B13: Numero de datos | E13: ='B.Modelo Distribución'!C42 -> 26 | G13: 20 | H13: ='B.Modelo Distribución'!J14 -> 115.66077 | I13: ='B.Modelo Distribución'!H62 -> 118.44844 | J13: ='B.Modelo Distribución'!R14 -> 119.80878 | K13: ='B.Modelo Distribución'!E50 -> 120.52901 | L13: =+I13 -> 118.44844
B14: Variación del Coef. de Asimetría | E14: =6/E13 -> 0.23076923 | G14: 25 | H14: ='B.Modelo Distribución'!J15 -> 117.99703 | I14: ='B.Modelo Distribución'!H63 -> 121.8084 | J14: ='B.Modelo Distribución'!R15 -> 123.51458 | K14: ='B.Modelo Distribución'!E51 -> 124.45794 | L14: =+I14 -> 121.8084
B15: Desv. Est. Coef. de Asimetría | E15: =+SQRT(E14) -> 0.48038446 | G15: 50 | H15: ='B.Modelo Distribución'!J16 -> 124.68618 | I15: ='B.Modelo Distribución'!H64 -> 131.96509 | J15: ='B.Modelo Distribución'!R16 -> 134.89166 | K15: ='B.Modelo Distribución'!E52 -> 136.56109 | L15: =+I15 -> 131.96509
G16: 100 | H16: ='B.Modelo Distribución'!J17 -> 130.70191 | I16: ='B.Modelo Distribución'!H65 -> 141.82059 | J16: ='B.Modelo Distribución'!R17 -> 146.18186 | K16: ='B.Modelo Distribución'!E53 -> 148.57488 | L16: =+I16 -> 141.82059
B17: Logarítmica | E17: Valor | G17: 200 | H17: ='B.Modelo Distribución'!J18 -> 136.20685 | I17: ='B.Modelo Distribución'!H66 -> 151.48287 | J17: ='B.Modelo Distribución'!R18 -> 157.48908 | K17: ='B.Modelo Distribución'!E54 -> 160.54483 | L17: =+I17 -> 151.48287
B18: Media Aritmética | E18: =+'B.Modelo Distribución'!D37 -> 1.8847429 | G18: 500 | H18: ='B.Modelo Distribución'!J19 -> 142.87742 | I18: ='B.Modelo Distribución'!H67 -> 164.07738 | J18: ='B.Modelo Distribución'!R19 -> 172.58014 | K18: ='B.Modelo Distribución'!E55 -> 176.33691 | L18: =+I18 -> 164.07738
B19: Desviación Estándar | E19: =+'B.Modelo Distribución'!D39 -> 0.11474904
B20: Varianza | E20: =+'B.Modelo Distribución'!D38 -> 0.013167342
B21: Coeficiente de Asimetría | E21: =+'B.Modelo Distribución'!D40 -> 0.15635063
B22: Numero de datos | E22: =+E13 -> 26
B23: Variación del Coef. de Asimetría | E23: =6/E22 -> 0.23076923
B24: D.S. Coef As | E24: =+SQRT(E23) -> 0.48038446
B25: K | E25: =+'B.Modelo Distribución'!D41 -> 0.026058439

Sheet A. Parametros
B2: Proyecto | C2: =+'A. Estación'!C2 -> “CREACIÓN DEL SERVICIO DE PROTECCIÓN INTEGRAL A NIÑAS, NIÑOS Y ADOLESCENTES SIN CUIDADOS PARENTALES O EN RIESGO DE PERDERLOS EN CENTRO DE ACOGIDA RESIDENCIAL - VARONES DISTRITO DE MORALES DE LA PROVINCIA DE SAN MARTÍN DEL DEPARTAMENTO DE SAN MARTÍN”, con CUI N.° 2705619
B3: Entidad | C3: =+'A. Estación'!C3 -> GERENCIA TERRITORIAL BAJO MAYO
B4: Ubicación | C4: =+'A. Estación'!C4 -> SAN MARTIN - SAN MARTIN - MORALES
B5: Fecha | C5: =+'A. Estación'!C5 -> SETIEMBRE 2026
B7: PARTE II: DETERMINACIÓN DE LA TORMENTA DE DISEÑO
B8: A. PARAMETROS DE INTENSIDADES MAXIMAS
B9: Cuadro N°04: Lluvias máximas (mm)
B10: T | C10: P.Max | D10: Duración en minutos | L10: Duración | M10: Y | N10: X1 | O10: X2
B11: años | C11: 24 horas | D11: 5 | E11: 10 | F11: 15 | G11: 20 | H11: 30 | I11: 60 | L11: Minutos | M11: Log (I) | N11: Log (T) | O11: Log (t)
B12: 500 | C12: =D.Resumen!L18 -> 164.07738 | D12: =(0.21*LN($B12)+0.52)*(0.54*D$11^0.25-0.5)*$I$18 -> 15.557099 | E12: =(0.21*LN($B12)+0.52)*(0.54*E$11^0.25-0.5)*$I$18 -> 23.286995 | F12: =(0.21*LN($B12)+0.52)*(0.54*F$11^0.25-0.5)*$I$18 -> 28.470035 | G12: =(0.21*LN($B12)+0.52)*(0.54*G$11^0.25-0.5)*$I$18 -> 32.479443 | H12: =(0.21*LN($B12)+0.52)*(0.54*H$11^0.25-0.5)*$I$18 -> 38.64315 | I12: =(0.21*LN($B12)+0.52)*(0.54*I$11^0.25-0.5)*$I$18 -> 50.741092 | L12: =D11 -> 5 | M12: =LOG10(D25) -> 2.2711443 | N12: =LOG10($B25) -> 2.69897 | O12: =LOG10($D$24) -> 0.69897
B13: 200 | C13: =D.Resumen!L17 -> 151.48287 | D13: =(0.21*LN($B13)+0.52)*(0.54*(D$11^0.25)-0.5)*$I$18 -> 13.916878 | E13: =(0.21*LN($B13)+0.52)*(0.54*E$11^0.25-0.5)*$I$18 -> 20.831794 | F13: =(0.21*LN($B13)+0.52)*(0.54*F$11^0.25-0.5)*$I$18 -> 25.468374 | G13: =(0.21*LN($B13)+0.52)*(0.54*G$11^0.25-0.5)*$I$18 -> 29.055061 | H13: =(0.21*LN($B13)+0.52)*(0.54*H$11^0.25-0.5)*$I$18 -> 34.568915 | I13: =(0.21*LN($B13)+0.52)*(0.54*I$11^0.25-0.5)*$I$18 -> 45.391343 | M13: =LOG10(D26) -> 2.2227165 | N13: =LOG10($B26) -> 2.30103 | O13: =LOG10($D$24) -> 0.69897
B14: 100 | C14: =D.Resumen!L16 -> 141.82059 | D14: =(0.21*LN($B14)+0.52)*(0.54*D$11^0.25-0.5)*$I$18 -> 12.676099 | E14: =(0.21*LN($B14)+0.52)*(0.54*E$11^0.25-0.5)*$I$18 -> 18.974506 | F14: =(0.21*LN($B14)+0.52)*(0.54*F$11^0.25-0.5)*$I$18 -> 23.197705 | G14: =(0.21*LN($B14)+0.52)*(0.54*G$11^0.25-0.5)*$I$18 -> 26.464616 | H14: =(0.21*LN($B14)+0.52)*(0.54*H$11^0.25-0.5)*$I$18 -> 31.486875 | I14: =(0.21*LN($B14)+0.52)*(0.54*I$11^0.25-0.5)*$I$18 -> 41.344414 | M14: =LOG10(D27) -> 2.1821292 | N14: =LOG10($B27) -> 2 | O14: =LOG10($D$24) -> 0.69897
B15: 50 | C15: =D.Resumen!L15 -> 131.96509 | D15: =(0.21*LN($B15)+0.52)*(0.54*D$11^0.25-0.5)*$I$18 -> 11.43532 | E15: =(0.21*LN($B15)+0.52)*(0.54*E$11^0.25-0.5)*$I$18 -> 17.117218 | F15: =(0.21*LN($B15)+0.52)*(0.54*F$11^0.25-0.5)*$I$18 -> 20.927037 | G15: =(0.21*LN($B15)+0.52)*(0.54*G$11^0.25-0.5)*$I$18 -> 23.874171 | H15: =(0.21*LN($B15)+0.52)*(0.54*H$11^0.25-0.5)*$I$18 -> 28.404834 | I15: =(0.21*LN($B15)+0.52)*(0.54*I$11^0.25-0.5)*$I$18 -> 37.297485 | M15: =LOG10(D28) -> 2.1373541 | N15: =LOG10($B28) -> 1.69897 | O15: =LOG10($D$24) -> 0.69897
B16: 25 | C16: =D.Resumen!L14 -> 121.8084 | D16: =(0.21*LN($B16)+0.52)*(0.54*D$11^0.25-0.5)*$I$18 -> 10.194542 | E16: =(0.21*LN($B16)+0.52)*(0.54*E$11^0.25-0.5)*$I$18 -> 15.25993 | F16: =(0.21*LN($B16)+0.52)*(0.54*F$11^0.25-0.5)*$I$18 -> 18.656368 | G16: =(0.21*LN($B16)+0.52)*(0.54*G$11^0.25-0.5)*$I$18 -> 21.283727 | H16: =(0.21*LN($B16)+0.52)*(0.54*H$11^0.25-0.5)*$I$18 -> 25.322794 | I16: =(0.21*LN($B16)+0.52)*(0.54*I$11^0.25-0.5)*$I$18 -> 33.250556 | M16: =LOG10(D29) -> 2.0874265 | N16: =LOG10($B29) -> 1.39794 | O16: =LOG10($D$24) -> 0.69897
B17: 20 | C17: =D.Resumen!L13 -> 118.44844 | D17: =(0.21*LN($B17)+0.52)*(0.54*D$11^0.25-0.5)*$I$18 -> 9.7951001 | E17: =(0.21*LN($B17)+0.52)*(0.54*E$11^0.25-0.5)*$I$18 -> 14.662017 | F17: =(0.21*LN($B17)+0.52)*(0.54*F$11^0.25-0.5)*$I$18 -> 17.925376 | G17: =(0.21*LN($B17)+0.52)*(0.54*G$11^0.25-0.5)*$I$18 -> 20.44979 | H17: =(0.21*LN($B17)+0.52)*(0.54*H$11^0.25-0.5)*$I$18 -> 24.330599 | I17: =(0.21*LN($B17)+0.52)*(0.54*I$11^0.25-0.5)*$I$18 -> 31.947736 | M17: =LOG10(D30) -> 2.0700379 | N17: =LOG10($B30) -> 1.30103 | O17: =LOG10($D$24) -> 0.69897
B18: 10 | C18: =D.Resumen!L12 -> 107.60192 | D18: =(0.21*LN($B18)+0.52)*(0.54*D$11^0.25-0.5)*$I$18 -> 8.5543212 | E18: =(0.21*LN($B18)+0.52)*(0.54*E$11^0.25-0.5)*$I$18 -> 12.804729 | F18: =(0.21*LN($B18)+0.52)*(0.54*F$11^0.25-0.5)*$I$18 -> 15.654707 | G18: =(0.21*LN($B18)+0.52)*(0.54*G$11^0.25-0.5)*$I$18 -> 17.859345 | H18: =(0.21*LN($B18)+0.52)*(0.54*H$11^0.25-0.5)*$I$18 -> 21.248559 | I18: =0.4602*C18^0.876 -> 27.721771 | M18: =LOG10(D31) -> 2.0115704 | N18: =LOG10($B31) -> 1 | O18: =LOG10($D$24) -> 0.69897
B19: 5 | C19: =D.Resumen!L11 -> 95.785385 | D19: =(0.21*LN($B19)+0.52)*(0.54*D$11^0.25-0.5)*$I$18 -> 7.3135424 | E19: =(0.21*LN($B19)+0.52)*(0.54*E$11^0.25-0.5)*$I$18 -> 10.947441 | F19: =(0.21*LN($B19)+0.52)*(0.54*F$11^0.25-0.5)*$I$18 -> 13.384038 | G19: =(0.21*LN($B19)+0.52)*(0.54*G$11^0.25-0.5)*$I$18 -> 15.2689 | H19: =(0.21*LN($B19)+0.52)*(0.54*H$11^0.25-0.5)*$I$18 -> 18.166518 | I19: =(0.21*LN($B19)+0.52)*(0.54*I$11^0.25-0.5)*$I$18 -> 23.853878 | M19: =LOG10(D32) -> 1.9434945 | N19: =LOG10($B32) -> 0.69897 | O19: =LOG10($D$24) -> 0.69897
B20: 2 | C20: =D.Resumen!L10 -> 76.690733 | D20: =(0.21*LN($B20)+0.52)*(0.54*D$11^0.25-0.5)*$I$18 -> 5.673322 | E20: =(0.21*LN($B20)+0.52)*(0.54*E$11^0.25-0.5)*$I$18 -> 8.4922403 | F20: =(0.21*LN($B20)+0.52)*(0.54*F$11^0.25-0.5)*$I$18 -> 10.382378 | G20: =(0.21*LN($B20)+0.52)*(0.54*G$11^0.25-0.5)*$I$18 -> 11.844518 | H20: =(0.21*LN($B20)+0.52)*(0.54*H$11^0.25-0.5)*$I$18 -> 14.092283 | I20: =(0.21*LN($B20)+0.52)*(0.54*I$11^0.25-0.5)*$I$18 -> 18.504129 | M20: =LOG10(D33) -> 1.8331471 | N20: =LOG10($B33) -> 0.30103 | O20: =LOG10($D$24) -> 0.69897
B21: Fuente: Modelo de Bell | L21: =E11 -> 10 | M21: =LOG10(E25) -> 2.1451964 | N21: =LOG10($B25) -> 2.69897 | O21: =LOG10($E$24) -> 1
B22: Cuadro N°05: Intensidades máximas (mm/hora) | M22: =LOG10(E26) -> 2.09691 | N22: =LOG10($B26) -> 2.30103 | O22: =LOG10($E$24) -> 1
B23: T | C23: P.Max | D23: Duración en minutos | M23: =LOG10(E27) -> 2.0561423 | N23: =LOG10($B27) -> 2 | O23: =LOG10($E$24) -> 1
B24: años | C24: 24 horas | D24: 5 | E24: 10 | F24: 15 | G24: 20 | H24: 30 | I24: 60 | M24: =LOG10(E28) -> 2.0115704 | N24: =LOG10($B28) -> 1.69897 | O24: =LOG10($E$24) -> 1
B25: 500 | C25: =C12 -> 164.07738 | D25: =ROUND(60*D12/D$11,1) -> 186.7 | E25: =ROUND(60*E12/E$11,1) -> 139.7 | F25: =ROUND(60*F12/F$11,1) -> 113.9 | G25: =ROUND(60*G12/G$11,1) -> 97.4 | H25: =ROUND(60*H12/H$11,1) -> 77.3 | I25: =ROUND(60*I12/I$11,1) -> 50.7 | M25: =LOG10(E29) -> 1.9618955 | N25: =LOG10($B29) -> 1.39794 | O25: =LOG10($E$24) -> 1
B26: 200 | C26: =C13 -> 151.48287 | D26: =ROUND(60*D13/D$11,1) -> 167 | E26: =ROUND(60*E13/E$11,1) -> 125 | F26: =ROUND(60*F13/F$11,1) -> 101.9 | G26: =ROUND(60*G13/G$11,1) -> 87.2 | H26: =ROUND(60*H13/H$11,1) -> 69.1 | I26: =ROUND(60*I13/I$11,1) -> 45.4 | M26: =LOG10(E30) -> 1.9444827 | N26: =LOG10($B30) -> 1.30103 | O26: =LOG10($E$24) -> 1
B27: 100 | C27: =C14 -> 141.82059 | D27: =ROUND(60*D14/D$11,1) -> 152.1 | E27: =ROUND(60*E14/E$11,1) -> 113.8 | F27: =ROUND(60*F14/F$11,1) -> 92.8 | G27: =ROUND(60*G14/G$11,1) -> 79.4 | H27: =ROUND(60*H14/H$11,1) -> 63 | I27: =ROUND(60*I14/I$11,1) -> 41.3 | M27: =LOG10(E31) -> 1.8853612 | N27: =LOG10($B31) -> 1 | O27: =LOG10($E$24) -> 1
B28: 50 | C28: =C15 -> 131.96509 | D28: =ROUND(60*D15/D$11,1) -> 137.2 | E28: =ROUND(60*E15/E$11,1) -> 102.7 | F28: =ROUND(60*F15/F$11,1) -> 83.7 | G28: =ROUND(60*G15/G$11,1) -> 71.6 | H28: =ROUND(60*H15/H$11,1) -> 56.8 | I28: =ROUND(60*I15/I$11,1) -> 37.3 | M28: =LOG10(E32) -> 1.8175654 | N28: =LOG10($B32) -> 0.69897 | O28: =LOG10($E$24) -> 1
B29: 25 | C29: =C16 -> 121.8084 | D29: =ROUND(60*D16/D$11,1) -> 122.3 | E29: =ROUND(60*E16/E$11,1) -> 91.6 | F29: =ROUND(60*F16/F$11,1) -> 74.6 | G29: =ROUND(60*G16/G$11,1) -> 63.9 | H29: =ROUND(60*H16/H$11,1) -> 50.6 | I29: =ROUND(60*I16/I$11,1) -> 33.3 | M29: =LOG10(E33) -> 1.7075702 | N29: =LOG10($B33) -> 0.30103 | O29: =LOG10($E$24) -> 1
B30: 20 | C30: =C17 -> 118.44844 | D30: =ROUND(60*D17/D$11,1) -> 117.5 | E30: =ROUND(60*E17/E$11,1) -> 88 | F30: =ROUND(60*F17/F$11,1) -> 71.7 | G30: =ROUND(60*G17/G$11,1) -> 61.3 | H30: =ROUND(60*H17/H$11,1) -> 48.7 | I30: =ROUND(60*I17/I$11,1) -> 31.9 | L30: =F11 -> 15 | M30: =LOG10(F25) -> 2.0565237 | N30: =LOG10($B25) -> 2.69897 | O30: =LOG10($F$24) -> 1.1760913
B31: 10 | C31: =C18 -> 107.60192 | D31: =ROUND(60*D18/D$11,1) -> 102.7 | E31: =ROUND(60*E18/E$11,1) -> 76.8 | F31: =ROUND(60*F18/F$11,1) -> 62.6 | G31: =ROUND(60*G18/G$11,1) -> 53.6 | H31: =ROUND(60*H18/H$11,1) -> 42.5 | I31: =ROUND(60*I18/I$11,1) -> 27.7 | M31: =LOG10(F26) -> 2.0081742 | N31: =LOG10($B26) -> 2.30103 | O31: =LOG10($F$24) -> 1.1760913
B32: 5 | C32: =C19 -> 95.785385 | D32: =ROUND(60*D19/D$11,1) -> 87.8 | E32: =ROUND(60*E19/E$11,1) -> 65.7 | F32: =ROUND(60*F19/F$11,1) -> 53.5 | G32: =ROUND(60*G19/G$11,1) -> 45.8 | H32: =ROUND(60*H19/H$11,1) -> 36.3 | I32: =ROUND(60*I19/I$11,1) -> 23.9 | M32: =LOG10(F27) -> 1.967548 | N32: =LOG10($B27) -> 2 | O32: =LOG10($F$24) -> 1.1760913
B33: 2 | C33: =C20 -> 76.690733 | D33: =ROUND(60*D20/D$11,1) -> 68.1 | E33: =ROUND(60*E20/E$11,1) -> 51 | F33: =ROUND(60*F20/F$11,1) -> 41.5 | G33: =ROUND(60*G20/G$11,1) -> 35.5 | H33: =ROUND(60*H20/H$11,1) -> 28.2 | I33: =ROUND(60*I20/I$11,1) -> 18.5 | M33: =LOG10(F28) -> 1.9227255 | N33: =LOG10($B28) -> 1.69897 | O33: =LOG10($F$24) -> 1.1760913
M34: =LOG10(F29) -> 1.8727388 | N34: =LOG10($B29) -> 1.39794 | O34: =LOG10($F$24) -> 1.1760913
B35: Cuadro N°06: Ecuaciones de la Regresión Lineal Múltiple | M35: =LOG10(F30) -> 1.8555192 | N35: =LOG10($B30) -> 1.30103 | O35: =LOG10($F$24) -> 1.1760913
B36: Ecuación de la regresión Lineal Múltiple | F36: m(X1) - n(X2) + logK = Y | M36: =LOG10(F31) -> 1.7965743 | N36: =LOG10($B31) -> 1 | O36: =LOG10($F$24) -> 1.1760913
B37: Sistema de Ecuaciones Normalizada (1) | E37: AΣ(X1) + BΣ(X2) + C(n) = Σ(Y) | F37: mΣ(X1) + nΣ(X2) + (logK)(n) = Σ(Y) | M37: =LOG10(F32) -> 1.7283538 | N37: =LOG10($B32) -> 0.69897 | O37: =LOG10($F$24) -> 1.1760913
B38: Sistema de Ecuaciones Normalizada (2) | E38: AΣ(X1²) + BΣ(X1)(X2) + CΣX1 = Σ(X1)(Y ) | F38: mΣ(X1²) + nΣ(X1)(X2) + (logK)ΣX1 = Σ(X1)(Y ) | M38: =LOG10(F33) -> 1.6180481 | N38: =LOG10($B33) -> 0.30103 | O38: =LOG10($F$24) -> 1.1760913
B39: Sistema de Ecuaciones Normalizada (3) | E39: AΣ(X1)(X2) + BΣ(X2²) + CΣX2 = Σ(X2)(Y ) | F39: mΣ(X1)(X2) + nΣ(X2²) + (logK)ΣX2 = Σ(X2)(Y ) | L39: =G11 -> 20 | M39: =LOG10(G25) -> 1.988559 | N39: =LOG10($B25) -> 2.69897 | O39: =LOG10($G$24) -> 1.30103
M40: =LOG10(G26) -> 1.9405165 | N40: =LOG10($B26) -> 2.30103 | O40: =LOG10($G$24) -> 1.30103
B41: =B37 -> Sistema de Ecuaciones Normalizada (1) | F41: mΣ(X1) | G41: nΣ(X2) | H41: (logK)(n) | I41: Σ(Y) | M41: =LOG10(G27) -> 1.8998205 | N41: =LOG10($B27) -> 2 | O41: =LOG10($G$24) -> 1.30103
F42: =SUM(N12:N65) -> 80.38764 | G42: =SUM(O12:O65) -> 66.882274 | H42: =COUNT(M12:M65) -> 54 | I42: =SUM(M12:M65) -> 98.404527 | M42: =LOG10(G28) -> 1.854913 | N42: =LOG10($B28) -> 1.69897 | O42: =LOG10($G$24) -> 1.30103
...

Sheet B. Int.maxima
B2: Proyecto | C2: ='A. Estación'!C2:O2 -> “CREACIÓN DEL SERVICIO DE PROTECCIÓN INTEGRAL A NIÑAS, NIÑOS Y ADOLESCENTES SIN CUIDADOS PARENTALES O EN RIESGO DE PERDERLOS EN CENTRO DE ACOGIDA RESIDENCIAL - VARONES DISTRITO DE MORALES DE LA PROVINCIA DE SAN MARTÍN DEL DEPARTAMENTO DE SAN MARTÍN”, con CUI N.° 2705619
B3: Entidad | C3: ='A. Estación'!C3:O3 -> GERENCIA TERRITORIAL BAJO MAYO
B4: Ubicación | C4: ='A. Estación'!C4:O4 -> SAN MARTIN - SAN MARTIN - MORALES
B5: Fecha | C5: ='A. Estación'!C5:O5 -> SETIEMBRE 2026
B7: B. CÁLCULO DE INTENSIDADES MÁXIMAS (mm/h)
C9: I = | D9: K Tm
D10: tn
C12: K | D12: =ROUND(10^'A. Parametros'!I53,2) -> 161.94
C13: m | D13: ='A. Parametros'!I51 -> 0.1785709
C14: n | D14: =ABS('A. Parametros'!I52) -> 0.52712166
B16: Duración (t) | C16: Período de Retorno (T) en años
B17: (minutos) | C17: 2 | D17: 5 | E17: 10 | F17: 20 | G17: 25 | H17: 50 | I17: 100
B18: 10 | C18: =ROUND(($D$12*$C$17^$D$13)/B18^$D$14,2) -> 54.45 | D18: =ROUND(($D$12*$D$17^$D$13)/B18^$D$14,2) -> 64.13 | E18: =ROUND(($D$12*$E$17^$D$13)/B18^$D$14,2) -> 72.58 | F18: =ROUND(($D$12*$F$17^$D$13)/B18^$D$14,2) -> 82.14 | G18: =ROUND(($D$12*$G$17^$D$13)/B18^$D$14,2) -> 85.48 | H18: =ROUND(($D$12*$H$17^$D$13)/B18^$D$14,2) -> 96.74 | I18: =ROUND(($D$12*$I$17^$D$13)/B18^$D$14,2) -> 109.49
B19: 20 | C19: =ROUND(($D$12*$C$17^$D$13)/B19^$D$14,2) -> 37.78 | D19: =ROUND(($D$12*$D$17^$D$13)/B19^$D$14,2) -> 44.5 | E19: =ROUND(($D$12*$E$17^$D$13)/B19^$D$14,2) -> 50.36 | F19: =ROUND(($D$12*$F$17^$D$13)/B19^$D$14,2) -> 57 | G19: =ROUND(($D$12*$G$17^$D$13)/B19^$D$14,2) -> 59.32 | H19: =ROUND(($D$12*$H$17^$D$13)/B19^$D$14,2) -> 67.13 | I19: =ROUND(($D$12*$I$17^$D$13)/B19^$D$14,2) -> 75.98
B20: 30 | C20: =ROUND(($D$12*$C$17^$D$13)/B20^$D$14,2) -> 30.51 | D20: =ROUND(($D$12*$D$17^$D$13)/B20^$D$14,2) -> 35.94 | E20: =ROUND(($D$12*$E$17^$D$13)/B20^$D$14,2) -> 40.67 | F20: =ROUND(($D$12*$F$17^$D$13)/B20^$D$14,2) -> 46.03 | G20: =ROUND(($D$12*$G$17^$D$13)/B20^$D$14,2) -> 47.9 | H20: =ROUND(($D$12*$H$17^$D$13)/B20^$D$14,2) -> 54.21 | I20: =ROUND(($D$12*$I$17^$D$13)/B20^$D$14,2) -> 61.36
B21: 40 | C21: =ROUND(($D$12*$C$17^$D$13)/B21^$D$14,2) -> 26.22 | D21: =ROUND(($D$12*$D$17^$D$13)/B21^$D$14,2) -> 30.88 | E21: =ROUND(($D$12*$E$17^$D$13)/B21^$D$14,2) -> 34.95 | F21: =ROUND(($D$12*$F$17^$D$13)/B21^$D$14,2) -> 39.55 | G21: =ROUND(($D$12*$G$17^$D$13)/B21^$D$14,2) -> 41.16 | H21: =ROUND(($D$12*$H$17^$D$13)/B21^$D$14,2) -> 46.59 | I21: =ROUND(($D$12*$I$17^$D$13)/B21^$D$14,2) -> 52.72
B22: 50 | C22: =ROUND(($D$12*$C$17^$D$13)/B22^$D$14,2) -> 23.31 | D22: =ROUND(($D$12*$D$17^$D$13)/B22^$D$14,2) -> 27.45 | E22: =ROUND(($D$12*$E$17^$D$13)/B22^$D$14,2) -> 31.07 | F22: =ROUND(($D$12*$F$17^$D$13)/B22^$D$14,2) -> 35.17 | G22: =ROUND(($D$12*$G$17^$D$13)/B22^$D$14,2) -> 36.59 | H22: =ROUND(($D$12*$H$17^$D$13)/B22^$D$14,2) -> 41.42 | I22: =ROUND(($D$12*$I$17^$D$13)/B22^$D$14,2) -> 46.87
B23: 60 | C23: =ROUND(($D$12*$C$17^$D$13)/B23^$D$14,2) -> 21.17 | D23: =ROUND(($D$12*$D$17^$D$13)/B23^$D$14,2) -> 24.94 | E23: =ROUND(($D$12*$E$17^$D$13)/B23^$D$14,2) -> 28.22 | F23: =ROUND(($D$12*$F$17^$D$13)/B23^$D$14,2) -> 31.94 | G23: =ROUND(($D$12*$G$17^$D$13)/B23^$D$14,2) -> 33.24 | H23: =ROUND(($D$12*$H$17^$D$13)/B23^$D$14,2) -> 37.62 | I23: =ROUND(($D$12*$I$17^$D$13)/B23^$D$14,2) -> 42.58
B24: 70 | C24: =ROUND(($D$12*$C$17^$D$13)/B24^$D$14,2) -> 19.52 | D24: =ROUND(($D$12*$D$17^$D$13)/B24^$D$14,2) -> 22.99 | E24: =ROUND(($D$12*$E$17^$D$13)/B24^$D$14,2) -> 26.02 | F24: =ROUND(($D$12*$F$17^$D$13)/B24^$D$14,2) -> 29.45 | G24: =ROUND(($D$12*$G$17^$D$13)/B24^$D$14,2) -> 30.65 | H24: =ROUND(($D$12*$H$17^$D$13)/B24^$D$14,2) -> 34.69 | I24: =ROUND(($D$12*$I$17^$D$13)/B24^$D$14,2) -> 39.26
B25: 80 | C25: =ROUND(($D$12*$C$17^$D$13)/B25^$D$14,2) -> 18.19 | D25: =ROUND(($D$12*$D$17^$D$13)/B25^$D$14,2) -> 21.43 | E25: =ROUND(($D$12*$E$17^$D$13)/B25^$D$14,2) -> 24.25 | F25: =ROUND(($D$12*$F$17^$D$13)/B25^$D$14,2) -> 27.45 | G25: =ROUND(($D$12*$G$17^$D$13)/B25^$D$14,2) -> 28.56 | H25: =ROUND(($D$12*$H$17^$D$13)/B25^$D$14,2) -> 32.33 | I25: =ROUND(($D$12*$I$17^$D$13)/B25^$D$14,2) -> 36.59
B26: 90 | C26: =ROUND(($D$12*$C$17^$D$13)/B26^$D$14,2) -> 17.1 | D26: =ROUND(($D$12*$D$17^$D$13)/B26^$D$14,2) -> 20.14 | E26: =ROUND(($D$12*$E$17^$D$13)/B26^$D$14,2) -> 22.79 | F26: =ROUND(($D$12*$F$17^$D$13)/B26^$D$14,2) -> 25.8 | G26: =ROUND(($D$12*$G$17^$D$13)/B26^$D$14,2) -> 26.84 | H26: =ROUND(($D$12*$H$17^$D$13)/B26^$D$14,2) -> 30.38 | I26: =ROUND(($D$12*$I$17^$D$13)/B26^$D$14,2) -> 34.39
B27: 100 | C27: =ROUND(($D$12*$C$17^$D$13)/B27^$D$14,2) -> 16.18 | D27: =ROUND(($D$12*$D$17^$D$13)/B27^$D$14,2) -> 19.05 | E27: =ROUND(($D$12*$E$17^$D$13)/B27^$D$14,2) -> 21.56 | F27: =ROUND(($D$12*$F$17^$D$13)/B27^$D$14,2) -> 24.4 | G27: =ROUND(($D$12*$G$17^$D$13)/B27^$D$14,2) -> 25.39 | H27: =ROUND(($D$12*$H$17^$D$13)/B27^$D$14,2) -> 28.74 | I27: =ROUND(($D$12*$I$17^$D$13)/B27^$D$14,2) -> 32.53
B28: 110 | C28: =ROUND(($D$12*$C$17^$D$13)/B28^$D$14,2) -> 15.38 | D28: =ROUND(($D$12*$D$17^$D$13)/B28^$D$14,2) -> 18.12 | E28: =ROUND(($D$12*$E$17^$D$13)/B28^$D$14,2) -> 20.51 | F28: =ROUND(($D$12*$F$17^$D$13)/B28^$D$14,2) -> 23.21 | G28: =ROUND(($D$12*$G$17^$D$13)/B28^$D$14,2) -> 24.15 | H28: =ROUND(($D$12*$H$17^$D$13)/B28^$D$14,2) -> 27.33 | I28: =ROUND(($D$12*$I$17^$D$13)/B28^$D$14,2) -> 30.93
B29: 120 | C29: =ROUND(($D$12*$C$17^$D$13)/B29^$D$14,2) -> 14.69 | D29: =ROUND(($D$12*$D$17^$D$13)/B29^$D$14,2) -> 17.31 | E29: =ROUND(($D$12*$E$17^$D$13)/B29^$D$14,2) -> 19.59 | F29: =ROUND(($D$12*$F$17^$D$13)/B29^$D$14,2) -> 22.17 | G29: =ROUND(($D$12*$G$17^$D$13)/B29^$D$14,2) -> 23.07 | H29: =ROUND(($D$12*$H$17^$D$13)/B29^$D$14,2) -> 26.11 | I29: =ROUND(($D$12*$I$17^$D$13)/B29^$D$14,2) -> 29.55
K31: =+C17 -> 2 | L31: =+D17 -> 5 | M31: =+E17 -> 10 | N31: =+F17 -> 20 | O31: =+H17 -> 50 | P31: =+I17 -> 100

Sheet C. P diseño
B2: Proyecto | C2: ='A. Estación'!C2 -> “CREACIÓN DEL SERVICIO DE PROTECCIÓN INTEGRAL A NIÑAS, NIÑOS Y ADOLESCENTES SIN CUIDADOS PARENTALES O EN RIESGO DE PERDERLOS EN CENTRO DE ACOGIDA RESIDENCIAL - VARONES DISTRITO DE MORALES DE LA PROVINCIA DE SAN MARTÍN DEL DEPARTAMENTO DE SAN MARTÍN”, con CUI N.° 2705619
B3: Entidad | C3: ='A. Estación'!C3 -> GERENCIA TERRITORIAL BAJO MAYO
B4: Ubicación | C4: ='A. Estación'!C4 -> SAN MARTIN - SAN MARTIN - MORALES
B5: Fecha | C5: ='A. Estación'!C5 -> SETIEMBRE 2026
B7: C. INTENSIDADES DE DISEÑO PARA PRECIPITACIONES MENORES A 24 HORAS (mm/h)
B9: Precipitación Pmax24 horas, T = 500 años | E9: =D.Resumen!L18 -> 164.07738
B10: D (min) | C10: D (horas) | D10: P (mm) | E10: I (mm/hr)
B11: 10 | C11: =+B11/60 -> 0.16666667 | D11: =+$E$9*(B11/1440)^0.25 -> 47.365059 | E11: =+D11/C11 -> 284.19035
B12: =+B11+10 -> 20 | C12: =+B12/60 -> 0.33333333 | D12: =+$E$9*(B12/1440)^0.25 -> 56.326865 | E12: =+D12/C12 -> 168.9806
B13: =+B12+10 -> 30 | C13: =+B13/60 -> 0.5 | D13: =+$E$9*(B13/1440)^0.25 -> 62.335923 | E13: =+D13/C13 -> 124.67185
B14: =+B13+10 -> 40 | C14: =+B14/60 -> 0.66666667 | D14: =+$E$9*(B14/1440)^0.25 -> 66.984309 | E14: =+D14/C14 -> 100.47646
B15: =+B14+10 -> 50 | C15: =+B15/60 -> 0.83333333 | D15: =+$E$9*(B15/1440)^0.25 -> 70.827283 | E15: =+D15/C15 -> 84.99274
B16: =+B15+10 -> 60 | C16: =+B16/60 -> 1 | D16: =+$E$9*(B16/1440)^0.25 -> 74.130324 | E16: =+D16/C16 -> 74.130324
B17: =+B16+10 -> 70 | C17: =+B17/60 -> 1.1666667 | D17: =+$E$9*(B17/1440)^0.25 -> 77.042895 | E17: =+D17/C17 -> 66.036767
B18: =+B17+10 -> 80 | C18: =+B18/60 -> 1.3333333 | D18: =+$E$9*(B18/1440)^0.25 -> 79.658217 | E18: =+D18/C18 -> 59.743663
B19: =+B18+10 -> 90 | C19: =+B19/60 -> 1.5 | D19: =+$E$9*(B19/1440)^0.25 -> 82.038689 | E19: =+D19/C19 -> 54.692459
B20: =+B19+10 -> 100 | C20: =+B20/60 -> 1.6666667 | D20: =+$E$9*(B20/1440)^0.25 -> 84.228309 | E20: =+D20/C20 -> 50.536986
B21: =+B20+10 -> 110 | C21: =+B21/60 -> 1.8333333 | D21: =+$E$9*(B21/1440)^0.25 -> 86.259365 | E21: =+D21/C21 -> 47.050563
B22: =+B21+10 -> 120 | C22: =+B22/60 -> 2 | D22: =+$E$9*(B22/1440)^0.25 -> 88.156308 | E22: =+D22/C22 -> 44.078154
B23: =+B22+10 -> 130 | C23: =+B23/60 -> 2.1666667 | D23: =+$E$9*(B23/1440)^0.25 -> 89.938144 | E23: =+D23/C23 -> 41.509913
... B34: =+B33+10 -> 240 | C34: =+B34/60 -> 4 | D34: =+$E$9*(B34/1440)^0.25 -> 104.83611 | E34: =+D34/C34 -> 26.209027
B35: 300 | C35: =+B35/60 -> 5 | D35: =+$E$9*(B35/1440)^0.25 -> 110.85069 | E35: =+D35/C35 -> 22.170138
B36: 360 | C36: =+B36/60 -> 6 | D36: =+$E$9*(B36/1440)^0.25 -> 116.02023 | E36: =+D36/C36 -> 19.336704
B37: 420 | C37: =+B37/60 -> 7 | D37: =+$E$9*(B37/1440)^0.25 -> 120.57865 | E37: =+D37/C37 -> 17.225521
B38: 480 | C38: =+B38/60 -> 8 | D38: =+$E$9*(B38/1440)^0.25 -> 124.67185 | E38: =+D38/C38 -> 15.583981
B39: 600 | C39: =+B39/60 -> 10 | D39: =+$E$9*(B39/1440)^0.25 -> 131.82443 | E39: =+D39/C39 -> 13.182443
B40: 660 | C40: =+B40/60 -> 11 | D40: =+$E$9*(B40/1440)^0.25 -> 135.0032 | E40: =+D40/C40 -> 12.273018
B41: 720 | C41: =+B41/60 -> 12 | D41: =+$E$9*(B41/1440)^0.25 -> 137.97208 | E41: =+D41/C41 -> 11.497673
B44: Precipitación Pmax24 horas, T = 100 años | E44: =D.Resumen!L16 -> 141.82059
B45: D (min) | C45: D (horas) | D45: P (mm) | E45: I (mm/hr)
B46: 10 | C46: =+B46/60 -> 0.16666667 | D46: =+$E$44*(B46/1440)^0.25 -> 40.940077 | E46: =+D46/C46 -> 245.64046
B47: =+B46+10 -> 20 | C47: =+B47/60 -> 0.33333333 | D47: =+$E$44*(B47/1440)^0.25 -> 48.686231 | E47: =+D47/C47 -> 146.05869
B48: =+B47+10 -> 30 | C48: =+B48/60 -> 0.5 | D48: =+$E$44*(B48/1440)^0.25 -> 53.880171 | E48: =+D48/C48 -> 107.76034
B49: =+B48+10 -> 40 | C49: =+B49/60 -> 0.66666667 | D49: =+$E$44*(B49/1440)^0.25 -> 57.898012 | E49: =+D49/C49 -> 86.847018
B50: =+B49+10 -> 50 | C50: =+B50/60 -> 0.83333333 | D50: =+$E$44*(B50/1440)^0.25 -> 61.219694 | E50: =+D50/C50 -> 73.463633
B51: =+B50+10 -> 60 | C51: =+B51/60 -> 1 | D51: =+$E$44*(B51/1440)^0.25 -> 64.074683 | E51: =+D51/C51 -> 64.074683
B52: =+B51+10 -> 70 | C52: =+B52/60 -> 1.1666667 | D52: =+$E$44*(B52/1440)^0.25 -> 66.59217 | E52: =+D52/C52 -> 57.079003
B53: =+B52+10 -> 80 | C53: =+B53/60 -> 1.3333333 | D53: =+$E$44*(B53/1440)^0.25 -> 68.852728 | E53: =+D53/C53 -> 51.639546
B54: =+B53+10 -> 90 | C54: =+B54/60 -> 1.5 | D54: =+$E$44*(B54/1440)^0.25 -> 70.910293 | E54: =+D54/C54 -> 47.273529
B55: =+B54+10 -> 100 | C55: =+B55/60 -> 1.6666667 | D55: =+$E$44*(B55/1440)^0.25 -> 72.802896 | E55: =+D55/C55 -> 43.681738
...

Sheet Hoja1
C5: Tabla N° Áreas de drenaje de techo en edificaciones | H5: Tabla N.° Áreas libres de concreto frotachado | M5: Tabla N.° Area Verde
C6: N.° | D6: Descripción | E6: Coeficiente de escorrentía C | F6: Área (m²) | H6: N.° | I6: Descripción | J6: Coeficiente de escorrentía C | K6: Área (m²) | M6: N.° | N6: Descripción | O6: Coeficiente de escorrentía C | P6: Área (m²)
C7: 1 | D7: Edificacion 01 | E7: 0.88 | F7: 298.379 | H7: 1 | I7: Área libre de cemento frotachado 01 | J7: 0.88 | K7: 44.64 | M7: 1 | N7: Área verde | O7: 0.29 | P7: 1232.207
C8: 2 | D8: Edificacion 02 | E8: 0.88 | F8: 130.502 | H8: 2 | I8: Área libre de cemento frotachado 02 | J8: 0.88 | K8: 9.966
C9: 3 | D9: Edificacion 03 | E9: 0.88 | F9: 128.562 | H9: 3 | I9: Área libre de cemento frotachado 03 | J9: 0.88 | K9: 952.438 | M9: Tabla N.° Áreas libres de Pavimento (Estacionamiento)
C10: 4 | D10: Edificacion 04 | E10: 0.88 | F10: 374.026 | H10: 4 | I10: Área libre de cemento frotachado 04 | J10: 0.88 | K10: 185.756 | M10: N.° | N10: Descripción | O10: Coeficiente de escorrentía C | P10: Área (m²)
C11: 5 | D11: Edificacion 05 | E11: 0.88 | F11: 374.014 | H11: 5 | I11: Área libre de cemento frotachado 05 | J11: 0.88 | K11: 71.801 | M11: 1 | N11: Estacionamiento (Pavimento)01 | O11: 0.86 | P11: 574.373
C12: 6 | D12: Edificacion 06 | E12: 0.88 | F12: 376.656
C13: 7 | D13: Edificacion 07 | E13: 0.88 | F13: 371.425
C14: 8 | D14: Edificacion 08 | E14: 0.88 | F14: 474.759
C15: 9 | D15: Edificacion 09 | E15: 0.88 | F15: 101.752
C16: 10 | D16: Edificacion 10 | E16: 0.88 | F16: 100.987
C17: 11 | D17: Losa Deportiva | E17: 0.88 | F17: 855.77
C18: 12 | D18: Guardiania | E18: 0.88 | F18: 62.929
C19: 13 | D19: Entrada 01 | E19: 0.88 | F19: 15.535
C20: 14 | D20: Entrada 02 | E20: 0.88 | F20: 15.535
C27: Edificación | D27: Techo (m²) | E27: Vereda (m²) | F27: Pavimento (m²) | G27: Verde (m²)
C28: Edificación 01 | D28: 298.38 | E28: 102.51 | F28: 0 | G28: 99.89
C29: Edificación 02 | D29: 130.5 | E29: 44.84 | F29: 287.185 | G29: 43.69
C30: Edificación 03 | D30: 128.56 | E30: 44.17 | F30: 287.185 | G30: 43.04
C31: Edificación 04 | D31: 374.03 | E31: 128.5 | F31: 0 | G31: 125.21
C32: Edificación 05 | D32: 374.01 | E32: 128.5 | F32: 0 | G32: 125.2
C33: Edificación 06 | D33: 376.66 | E33: 129.41 | F33: 0 | G33: 126.09
C34: Edificación 07 | D34: 371.43 | E34: 127.61 | F34: 0 | G34: 124.34
C35: Edificación 08 | D35: 474.76 | E35: 163.11 | F35: 0 | G35: 158.93
C36: Edificación 09 | D36: 101.75 | E36: 34.96 | F36: 0 | G36: 34.06
C37: Edificación 10 | D37: 100.99 | E37: 34.7 | F37: 0 | G37: 33.81
C38: Losa Deportiva | D38: 855.77 | E38: 294.01 | F38: 0 | G38: 286.48
C39: Guardianía | D39: 62.929 | E39: 21.62 | F39: 0 | G39: 21.07
... C41: Entrada 02 | D41: 15.535 | E41: 5.34 | F41: 0 | G41: 5.2

Sheet 210
B2: Caudales en Techos de Edificaciones | I2: Caudales en Áreas Verdes
B3: Descripción | C3: Coef. Escorrentia | D3: Intensidad máx. (mm/h) | E3: Area m2 | F3: Área (ha) | G3: Caudal (m3/s) | I3: Descripción | J3: Coef. Escorrentia | K3: Intensidad máx. (mm/h) | L3: Area m2 | M3: Área (ha) | N3: Caudal (m3/s)
B4: AREADO 1 | C4: 0.95 | D4: 210.98 | E4: 984.78 | F4: =E4/10000 -> 0.098478 | G4: =C4*D4*F4/360 -> 0.0548279 | I4: area verde 1 | J4: 0.95 | K4: 210.98 | L4: 107.11 | M4: =L4/10000 -> 0.010711 | N4: =J4*K4*M4/360 -> 0.005963379
B5: AREADO 2 | C5: 0.95 | D5: 210.98 | E5: 597.7 | F5: =E5/10000 -> 0.05977 | G5: =C5*D5*F5/360 -> 0.033277114 | I5: area verde 2 | J5: 0.95 | K5: 210.98 | L5: 103.14 | M5: =L5/10000 -> 0.010314 | N5: =J5*K5*M5/360 -> 0.0057423481
B6: AREADO 3 | C6: 0.95 | D6: 210.98 | E6: 234.4 | F6: =E6/10000 -> 0.02344 | G6: =C6*D6*F6/360 -> 0.013050285 | I6: area verde 3 | J6: 0.95 | K6: 210.98 | L6: 231.55 | M6: =L6/10000 -> 0.023155 | N6: =J6*K6*M6/360 -> 0.012891611
B7: AREADO 4 | C7: 0.95 | D7: 210.98 | E7: 305.6 | F7: =E7/10000 -> 0.03056 | G7: =C7*D7*F7/360 -> 0.017014365 | I7: area verde 4 | J7: 0.95 | K7: 210.98 | L7: 74.87 | M7: =L7/10000 -> 0.007487 | N7: =J7*K7*M7/360 -> 0.004168408
B8: AREADO 5 | C8: 0.95 | D8: 210.98 | E8: 224.59 | F8: =E8/10000 -> 0.022459 | G8: =C8*D8*F8/360 -> 0.012504111 | I8: area verde 5 | J8: 0.95 | K8: 210.98 | L8: 98.73 | M8: =L8/10000 -> 0.009873 | N8: =J8*K8*M8/360 -> 0.0054968202
B9: AREADO 6 | C9: 0.95 | D9: 210.98 | E9: 66.06 | F9: =E9/10000 -> 0.006606 | G9: =C9*D9*F9/360 -> 0.0036779088 | I9: area verde 6 | J9: 0.95 | K9: 210.98 | L9: 293.88 | M9: =L9/10000 -> 0.029388 | N9: =J9*K9*M9/360 -> 0.016361851
B10: AREADO 7 | C10: 0.95 | D10: 210.98 | E10: 196.47 | F10: =E10/10000 -> 0.019647 | G10: =C10*D10*F10/360 -> 0.010938522 | I10: area verde 7 | J10: 0.95 | K10: 210.98 | L10: 38.91 | M10: =L10/10000 -> 0.003891 | N10: =J10*K10*M10/360 -> 0.0021663251
