Workbook

Sheet MEMORIA
A1: MEMORIA DE CALCULO - COLECTOR PLUVIAL TRAMO CAR MUJERES (PREPARADO PARA LOS TRES PROYECTOS)
A2: Colector pluvial frontal - tramo CAR Mujeres (CUI 2717013), dimensionado para recibir CAR Varones (CUI 2705619) y Hogar de Refugio (CUI 2675514) - Morales, San Martin
A4: 1. OBJETO | B4: Dimensionar el tramo del colector frontal del CAR Mujeres (0+000 a 0+139.08) para conducir, ademas de su propio caudal, los caudales del CAR Varones y del Hogar de Refugio, que se conectan aguas arriba, con secciones economicas, enterradas y con tapa a ras de vereda.
A5: 2. NORMATIVA | B5: RNE CE.040 Drenaje Pluvial (RM 126-2021-VIVIENDA); RNE E.020 Cargas; RNE E.060 Concreto Armado; AASHTO LRFD para carga de rueda en cruces vehiculares.
A6: 3. HIDROLOGIA | B6: Metodo Racional con los coeficientes y areas de las memorias de calculo de cada proyecto. TR = 25 anos; intensidad para tc = 15 min de la curva precipitacion-duracion del analisis estadistico; FS = 1.15 (hoja CAUDALES).
A7: 4. HIDRAULICA | B7: La salida esta controlada por la calzada de la Crta. Oasis (cresta 258.54), sobre la que el agua rebalsa. Por ello no basta el tirante normal: se calcula el perfil de flujo por el metodo del paso estandar desde la salida hasta el Eje 02, con el caudal que entra en cada eje (hojas SALIDA y PERFIL_FLUJO). Criterio: llenado <= 85 % de la altura interior y borde libre >= 0.05 m bajo la tapa.
A8: 5. ESTRUCTURAS | B8: Tapas, losa superior del cruce de camiones, muros y losa de fondo verificados a flexion y corte con E.060, con cuantia minima por temperatura (hoja ESTRUCTURAL).
A9: 6. RESULTADOS | B9: Colector cubierto de concreto armado, ancho interior b = 1.50 m, losa superior monolitica en todo su recorrido (a ras de vereda hasta 0+078.42 y h = 0.60 m hasta la salida con dos aleros), registros de limpieza con tapa removible; todo dentro del lindero. Llenado maximo, borde libre minimo y numero de estaciones que no cumplen: ver abajo (se actualizan con las formulas).
A11: Caudal total en la salida (L/s) | B11: =CAUDALES!F8
A12: Nivel de control en la salida (msnm) | B12: =SALIDA!B10
A13: Ancho interior adoptado (m) | B13: =DATOS!B14
A14: Llenado maximo y/h | B14: =PERFIL_FLUJO!B82
A15: Borde libre minimo bajo tapa (m) | B15: =PERFIL_FLUJO!B83
A16: Estaciones hidraulicas que no cumplen | B16: =PERFIL_FLUJO!B84
A17: Elementos estructurales que no cumplen | B17: =COUNTIF(ESTRUCTURAL!E:E,"NO CUMPLE")
A19: NOTA | B19: El cruce de la Crta. Oasis (baden o alcantarilla) queda fuera del alcance del proyecto y se indica en la memoria descriptiva para la entidad a cargo de la via. Capacidad portante a confirmar con el EMS.

Sheet DATOS
A1: 1. DATOS DE DISENO
A2: Colector pluvial frontal - tramo CAR Mujeres (CUI 2717013), dimensionado para recibir CAR Varones (CUI 2705619) y Hogar de Refugio (CUI 2675514) - Morales, San Martin
A4: PARAMETRO | B4: VALOR | C4: UND | D4: FUENTE / CRITERIO | E4: SIMBOLO
A5: HIDROLOGIA
A6: Periodo de retorno | B6: 25 | C6: anos | D6: Analisis estadistico de precipitaciones (memorias de calculo) | E6: TR
A7: Precipitacion de diseno D=10 min | B7: 35.163 | C7: mm | D7: Analisis estadistico, hoja C. P diseno | E7: P10
A8: Precipitacion de diseno D=20 min | B8: 41.816 | C8: mm | D8: Analisis estadistico, hoja C. P diseno | E8: P20
A9: Tiempo de concentracion en la salida | B9: 15 | C9: min | D9: 10 min de entrada + recorrido en cunetas y colector | E9: tc
A10: Exponente de la curva P-D | B10: =LN(DATOS!$B$8/DATOS!$B$7)/LN(2) | C10: - | D10: b = ln(P20/P10)/ln 2 | E10: bx
A11: Intensidad de diseno I | B11: =DATOS!$B$7*(DATOS!$B$9/10)^DATOS!$B$10/(DATOS!$B$9/60) | C11: mm/h | D11: I = P10 (tc/10)^b / (tc/60) | E11: I
A12: Factor de seguridad FS | B12: 1.15 | C12: - | D12: Memorias de calculo HIDRO-CE040 | E12: FS
A13: GEOMETRIA DEL COLECTOR (tramo CAR Mujeres)
A14: Ancho interior b | B14: 1.5 | C14: m | D14: Adoptado: llenado <= 85% en todo el tramo (hoja PERFIL_FLUJO) | E14: b
A15: Espesor de muros y losa (tramo normal) | B15: 0.1 | C15: m | E15: e
A16: Cota de fondo inicial (Eje 02, 0+000) | B16: 258.72 | C16: msnm | D16: Cuneta Eje 02 NCF 258.73 | E16: CF0
A17: Cota de fondo en la salida (0+139.08) | B17: 258.3 | C17: msnm | D17: Topografia: 0.24 m bajo la cresta de la via | E17: CFs
A18: Longitud del colector | B18: 139.08 | C18: m | D18: Eje a 0.85 m del lindero; ultimos 4 m desviados 0.85 m hacia el predio para la salida con aleros | E18: L
A19: Pendiente S | B19: =(DATOS!$B$16-DATOS!$B$17)/DATOS!$B$18 | C19: m/m | E19: S
A20: Progresiva fin del tramo en vereda (quiebre C-1) | B20: 78.42 | C20: m | E20: PKC1
A21: NPT vereda (cara superior de tapa) | B21: 259.25 | C21: msnm | D21: Arquitectura CAR Mujeres | E21: NPT
A22: Espesor de losa superior (monolitica) | B22: 0.1 | C22: m | D22: Ver hoja ESTRUCTURAL | E22: et
A23: Tramo cruce de camiones: inicio | B23: 54 | C23: m | D23: Ingreso secundario | E23: pc1
A24: Tramo cruce de camiones: fin | B24: 60 | C24: m | E24: pc2
A25: Espesor losa superior en cruce de camiones | B25: 0.2 | C25: m | D25: Losa vaciada in situ monolitica | E25: ec
A26: Altura interior tramo final (fuera de vereda) | B26: 0.6 | C26: m | D26: Colector cubierto con losa superior | E26: hab
A27: Coeficiente de Manning n | B27: 0.015 | C27: - | D27: Concreto vaciado in situ (Chow) | E27: n
A28: CRITERIOS DE VERIFICACION HIDRAULICA
A29: Llenado maximo admisible y/h (conducto cubierto) | B29: 0.85 | C29: - | D29: Criterio de conducto cerrado a superficie libre | E29: llen
A30: Borde libre minimo bajo tapa | B30: 0.05 | C30: m | D30: Complementario al criterio de llenado | E30: BLmin
A31: Cresta de la via frente a la salida | B31: 258.54 | C31: msnm | D31: Topografia TIN (berma/calzada Crta. Oasis) | E31: cresta
A32: Longitud efectiva de vertido sobre la berma | B32: 4 | C32: m | D32: Salida con dos aleros a 45 grados: el agua sale por la una (2.91 m) y se abre sobre la berma hasta la cresta | E32: Lw
A33: Coeficiente de vertedero de cresta ancha | B33: 1.7 | C33: m0.5/s | D33: Q = C L H^1.5 | E33: Cw
A35: Azul = dato editable; negro = formula; verde = vinculo.

Sheet CAUDALES
A1: 2. CAUDALES DE DISENO - METODO RACIONAL Q = C I A FS
A2: Colector pluvial frontal - tramo CAR Mujeres (CUI 2717013), dimensionado para recibir CAR Varones (CUI 2705619) y Hogar de Refugio (CUI 2675514) - Morales, San Martin
A4: PROYECTO | B4: AREA (m2) | C4: C x A (m2) | D4: C PONDERADO | E4: I (mm/h) | F4: Q (L/s) | G4: INGRESA AL COLECTOR EN | H4: FUENTE
A5: CAR Varones (Katiuska) | B5: 6752.06 | C5: 5203.3213 | D5: =C5/B5 | E5: =DATOS!$B$11 | F5: =C5*E5/3600000*DATOS!$B$12*1000 | G5: Caja de llegada (Eje 02) | H5: Memoria HIDRO-CE040, 14 fichas
A6: Hogar de Refugio M. Violentadas (Solange) | B6: 7520.41 | C6: 6072.3596 | D6: =C6/B6 | E6: =DATOS!$B$11 | F6: =C6*E6/3600000*DATOS!$B$12*1000 | G6: Caja de llegada (Eje 02) | H6: Memoria HIDRO-CE040, 11 fichas
A7: CAR Mujeres (Wilma) | B7: 7491.56 | C7: 5274.4494 | D7: =C7/B7 | E7: =DATOS!$B$11 | F7: =C7*E7/3600000*DATOS!$B$12*1000 | G7: Ejes 02, 07, 10 y 12 (1/4 en cada uno) | H7: Memoria HIDRO-CE040, 13 fichas
A8: TOTAL EN LA SALIDA | B8: =SUM(B5:B7) | C8: =SUM(C5:C7) | D8: =C8/B8 | F8: =SUM(F5:F7)
A10: Caudal que circula por cada punto del tramo CAR Mujeres (de aguas arriba hacia la salida)
A11: PUNTO | B11: PROGRESIVA | C11: APORTE (L/s) | D11: Q ACUMULADO (L/s)
A12: Eje 02 (con llegada de Varones + M. Violentadas) | B12: 0 | C12: =F5+F6+F7/4 | D12: =SUM($C$12:C12)
A13: Eje 07 | B13: 37.95 | C13: =F7/4 | D13: =SUM($C$12:C13)
A14: Eje 10 | B14: 49.38 | C14: =F7/4 | D14: =SUM($C$12:C14)
A15: Eje 12 | B15: 60.15 | C15: =F7/4 | D15: =SUM($C$12:C15)
A17: Suma de picos sin desfase de tiempos y con FS = 1.15: hipotesis conservadora.

Sheet SALIDA
A1: 3. CONDICION DE CONTROL EN LA SALIDA
A2: Colector pluvial frontal - tramo CAR Mujeres (CUI 2717013), dimensionado para recibir CAR Varones (CUI 2705619) y Hogar de Refugio (CUI 2675514) - Morales, San Martin
A4: PARAMETRO | B4: VALOR | C4: UND | D4: FORMULA
A5: Caudal total Q | B5: =CAUDALES!F8/1000 | C5: m3/s
A6: Carga sobre la cresta de la via H | B6: =(B5/(DATOS!$B$32*DATOS!$B$33))^(2/3) | C6: m | D6: H = (Q / (Cw Lw))^(2/3)
A7: Nivel de agua por vertido sobre la via | B7: =DATOS!$B$31+B6 | C7: msnm | D7: cresta + H
A8: Tirante critico en el canal yc | B8: =(B5^2/(9.81*DATOS!$B$14^2))^(1/3) | C8: m | D8: yc = (Q2 / (g b2))^(1/3)
A9: Nivel critico en la salida | B9: =DATOS!$B$17+B8 | C9: msnm | D9: CF salida + yc
A10: NIVEL DE CONTROL EN LA SALIDA | B10: =MAX(B7,B9) | C10: msnm | D10: El mayor: gobierna el vertido sobre la via (remanso)
A12: El agua sale rebalsando la calzada de la Crta. Oasis (cresta 258.54): esa cota controla el nivel del colector aguas arriba.

Sheet PERFIL_FLUJO
A1: 4. PERFIL DE FLUJO GRADUALMENTE VARIADO - METODO DEL PASO ESTANDAR (desde la salida hacia aguas arriba)
A2: Colector pluvial frontal - tramo CAR Mujeres (CUI 2717013), dimensionado para recibir CAR Varones (CUI 2705619) y Hogar de Refugio (CUI 2675514) - Morales, San Martin
A3: Ecuacion de energia entre estaciones: y2 + V2^2/2g + z2 = y1 + V1^2/2g + z1 + (Sf1+Sf2)/2 * dx ; Sf = (n V / R^(2/3))^2. El tirante de cada fila se resuelve por biseccion en las columnas auxiliares (desde la columna P).
A4: PROGRESIVA (m) | B4: COTA FONDO | C4: Q (m3/s) | D4: yc (m) | E4: TIRANTE y (m) | F4: NIVEL DE AGUA | G4: VELOCIDAD (m/s) | H4: FROUDE | I4: TECHO DISPONIBLE | J4: ALTURA INTERIOR h | K4: LLENADO y/h | L4: BORDE LIBRE (m) | M4: VERIFICACION | N4: TRAMO
A5: 139.08 | B5: =DATOS!$B$16-DATOS!$B$19*A5 | C5: =IF(A5<CAUDALES!$B$13,CAUDALES!$D$12,IF(A5<CAUDALES!$B$14,CAUDALES!$D$13,IF(A5<CAUDALES!$B$15,CAUDALES!$D$14,CAUDALES!$D$15)))/1000 | D5: =(C5^2/(9.81*DATOS!$B$14^2))^(1/3) | E5: =SALIDA!B10-B5 | F5: =B5+E5 | G5: =C5/(DATOS!$B$14*E5) | H5: =G5/SQRT(9.81*E5) | I5: =IF(A5<=DATOS!$B$20,DATOS!$B$21-IF(AND(A5>=DATOS!$B$23,A5<DATOS!$B$24),DATOS!$B$25,DATOS!$B$22),B5+DATOS!$B$26) | J5: =I5-B5 | K5: =E5/J5 | L5: =I5-F5 | M5: =IF(AND(K5<=DATOS!$B$29,L5>=DATOS!$B$30),"CUMPLE","NO CUMPLE") | N5: =IF(A5>DATOS!$B$20,"cubierto - tramo final",IF(AND(A5>=DATOS!$B$23,A5<DATOS!$B$24),"cubierto - camiones","cubierto"))
A6: 138 | B6: =DATOS!$B$16-DATOS!$B$19*A6 | C6: =IF(A6<CAUDALES!$B$13,CAUDALES!$D$12,IF(A6<CAUDALES!$B$14,CAUDALES!$D$13,IF(A6<CAUDALES!$B$15,CAUDALES!$D$14,CAUDALES!$D$15)))/1000 | D6: =(C6^2/(9.81*DATOS!$B$14^2))^(1/3) | E6: =(BT6+BU6)/2 | F6: =B6+E6 | G6: =C6/(DATOS!$B$14*E6) | H6: =G6/SQRT(9.81*E6) | I6: =IF(A6<=DATOS!$B$20,DATOS!$B$21-IF(AND(A6>=DATOS!$B$23,A6<DATOS!$B$24),DATOS!$B$25,DATOS!$B$22),B6+DATOS!$B$26) | J6: =I6-B6 | K6: =E6/J6 | L6: =I6-F6 | M6: =IF(AND(K6<=DATOS!$B$29,L6>=DATOS!$B$30),"CUMPLE","NO CUMPLE") | N6: =IF(A6>DATOS!$B$20,"cubierto - tramo final",IF(AND(A6>=DATOS!$B$23,A6<DATOS!$B$24),"cubierto - camiones","cubierto")) | P6: =D6*1.001 | Q6: 2 | R6: =IF((((P6+Q6)/2)+(C6/(DATOS!$B$14*((P6+Q6)/2)))^2/(2*9.81)+B6-(E5+(C5/(DATOS!$B$14*E5))^2/(2*9.81)+B5+0.5*(((DATOS!$B$27*C5/(DATOS!$B$14*E5))^2/((DATOS!$B$14*E5)/(DATOS!$B$14+2*E5))^(4/3))+((DATOS!$B$27*C6/(DATOS!$B$14*((P6+Q6)/2)))^2/((DATOS!$B$14*((P6+Q6)/2))/(DATOS!$B$14+2*((P6+Q6)/2)))^(4/3)))*(A5-A6)))<0,((P6+Q6)/2),P6) | S6: =IF((((P6+Q6)/2)+(C6/(DATOS!$B$14*((P6+Q6)/2)))^2/(2*9.81)+B6-(E5+(C5/(DATOS!$B$14*E5))^2/(2*9.81)+B5+0.5*(((DATOS!$B$27*C5/(DATOS!$B$14*E5))^2/((DATOS!$B$14*E5)/(DATOS!$B$14+2*E5))^(4/3))+((DATOS!$B$27*C6/(DATOS!$B$14*((P6+Q6)/2)))^2/((DATOS!$B$14*((P6+Q6)/2))/(DATOS!$B$14+2*((P6+Q6)/2)))^(4/3)))*(A5-A6)))<0,Q6,((P6+Q6)/2)) | T6: =IF((((R6+S6)/2)+(C6/(DATOS!$B$14*((R6+S6)/2)))^2/(2*9.81)+B6-(E5+(C5/(DATOS!$B$14*E5))^2/(2*9.81)+B5+0.5*(((DATOS!$B$27*C5/(DATOS!$B$14*E5))^2/((DATOS!$B$14*E5)/(DATOS!$B$14+2*E5))^(4/3))+((DATOS!$B$27*C6/(DATOS!$B$14*((R6+S6)/2)))^2/((DATOS!$B$14*((R6+S6)/2))/(DATOS!$B$14+2*((R6+S6)/2)))^(4/3)))*(A5-A6)))<0,((R6+S6)/2),R6) | U6: =IF((((R6+S6)/2)+(C6/(DATOS!$B$14*((R6+S6)/2)))^2/(2*9.81)+B6-(E5+(C5/(DATOS!$B$14*E5))^2/(2*9.81)+B5+0.5*(((DATOS!$B$27*C5/(DATOS!$B$14*E5))^2/((DATOS!$B$14*E5)/(DATOS!$B$14+2*E5))^(4/3))+((DATOS!$B$27*C6/(DATOS!$B$14*((R6+S6)/2)))^2/((DATOS!$B$14*((R6+S6)/2))/(DATOS!$B$14+2*((R6+S6)/2)))^(4/3)))*(A5-A6)))<0,S6,((R6+S6)/2)) | V6: =IF((((T6+U6)/2)+(C6/(DATOS!$B$14*((T6+U6)/2)))^2/(2*9.81)+B6-(E5+(C5/(DATOS!$B$14*E5))^2/(2*9.81)+B5+0.5*(((DATOS!$B$27*C5/(DATOS!$B$14*E5))^2/((DATOS!$B$14*E5)/(DATOS!$B$14+2*E5))^(4/3))+((DATOS!$B$27*C6/(DATOS!$B$14*((T6+U6)/2)))^2/((DATOS!$B$14*((T6+U6)/2))/(DATOS!$B$14+2*((T6+U6)/2)))^(4/3)))*(A5-A6)))<0,((T6+U6)/2),T6) | W6: =IF((((T6+U6)/2)+(C6/(DATOS!$B$14*((T6+U6)/2)))^2/(2*9.81)+B6-(E5+(C5/(DATOS!$B$14*E5))^2/(2*9.81)+B5+0.5*(((DATOS!$B$27*C5/(DATOS!$B$14*E5))^2/((DATOS!$B$14*E5)/(DATOS!$B$14+2*E5))^(4/3))+((DATOS!$B$27*C6/(DATOS!$B$14*((T6+U6)/2)))^2/((DATOS!$B$14*((T6+U6)/2))/(DATOS!$B$14+2*((T6+U6)/2)))^(4/3)))*(A5-A6)))<0,U6,((T6+U6)/2)) | X6: =IF((((V6+W6)/2)+(C6/(DATOS!$B$14*((V6+W6)/2)))^2/(2*9.81)+B6-(E5+(C5/(DATOS!$B$14*E5))^2/(2*9.81)+B5+0.5*(((DATOS!$B$27*C5/(DATOS!$B$14*E5))^2/((DATOS!$B$14*E5)/(DATOS!$B$14+2*E5))^(4/3))+((DATOS!$B$27*C6/(DATOS!$B$14*((V6+W6)/2)))^2/((DATOS!$B$14*((V6+W6)/2))/(DATOS!$B$14+2*((V6+W6)/2)))^(4/3)))*(A5-A6)))<0,((V6+W6)/2),V6) | Y6: =IF((((V6+W6)/2)+(C6/(DATOS!$B$14*((V6+W6)/2)))^2/(2*9.81)+B6-(E5+(C5/(DATOS!$B$14*E5))^2/(2*9.81)+B5+0.5*(((DATOS!$B$27*C5/(DATOS!$B$14*E5))^2/((DATOS!$B$14*E5)/(DATOS!$B$14+2*E5))^(4/3))+((DATOS!$B$27*C6/(DATOS!$B$14*((V6+W6)/2)))^2/((DATOS!$B$14*((V6+W6)/2))/(DATOS!$B$14+2*((V6+W6)/2)))^(4/3)))*(A5-A6)))<0,W6,((V6+W6)/2)) | Z6: =IF((((X6+Y6)/2)+(C6/(DATOS!$B$14*((X6+Y6)/2)))^2/(2*9.81)+B6-(E5+(C5/(DATOS!$B$14*E5))^2/(2*9.81)+B5+0.5*(((DATOS!$B$27*C5/(DATOS!$B$14*E5))^2/((DATOS!$B$14*E5)/(DATOS!$B$14+2*E5))^(4/3))+((DATOS!$B$27*C6/(DATOS!$B$14*((X6+Y6)/2)))^2/((DATOS!$B$14*((X6+Y6)/2))/(DATOS!$B$14+2*((X6+Y6)/2)))^(4/3)))*(A5-A6)))<0,((X6+Y6)/2),X6) | AA6: =IF((((X6+Y6)/2)+(C6/(DATOS!$B$14*((X6+Y6)/2)))^2/(2*9.81)+B6-(E5+(C5/(DATOS!$B$14*E5))^2/(2*9.81)+B5+0.5*(((DATOS!$B$27*C5/(DATOS!$B$14*E5))^2/((DATOS!$B$14*E5)/(DATOS!$B$14+2*E5))^(4/3))+((DATOS!$B$27*C6/(DATOS!$B$14*((X6+Y6)/2)))^2/((DATOS!$B$14*((X6+Y6)/2))/(DATOS!$B$14+2*((X6+Y6)/2)))^(4/3)))*(A5-A6)))<0,Y6,((X6+Y6)/2)) | AB6: =IF((((Z6+AA6)/2)+(C6/(DATOS!$B$14*((Z6+AA6)/2)))^2/(2*9.81)+B6-(E5+(C5/(DATOS!$B$14*E5))^2/(2*9.81)+B5+0.5*(((DATOS!$B$27*C5/(DATOS!$B$14*E5))^2/((DATOS!$B$14*E5)/(DATOS!$B$14+2*E5))^(4/3))+((DATOS!$B$27*C6/(DATOS!$B$14*((Z6+AA6)/2)))^2/((DATOS!$B$14*((Z6+AA6)/2))/(DATOS!$B$14+2*((Z6+AA6)/2)))^(4/3)))*(A5-A6)))<0,((Z6+AA6)/2),Z6) | AC6: =IF((((Z6+AA6)/2)+(C6/(DATOS!$B$14*((Z6+AA6)/2)))^2/(2*9.81)+B6-(E5+(C5/(DATOS!$B$14*E5))^2/(2*9.81)+B5+0.5*(((DATOS!$B$27*C5/(DATOS!$B$14*E5))^2/((DATOS!$B$14*E5)/(DATOS!$B$14+2*E5))^(4/3))+((DATOS!$B$27*C6/(DATOS!$B$14*((Z6+AA6)/2)))^2/((DATOS!$B$14*((Z6+AA6)/2))/(DATOS!$B$14+2*((Z6+AA6)/2)))^(4/3)))*(A5-A6)))<0,AA6,((Z6+AA6)/2)) | AD6: =IF((((AB6+AC6)/2)+(C6/(DATOS!$B$14*((AB6+AC6)/2)))^2/(2*9.81)+B6-(E5+(C5/(DATOS!$B$14*E5))^2/(2*9.81)+B5+0.5*(((DATOS!$B$27*C5/(DATOS!$B$14*E5))^2/((DATOS!$B$14*E5)/(DATOS!$B$14+2*E5))^(4/3))+((DATOS!$B$27*C6/(DATOS!$B$14*((AB6+AC6)/2)))^2/((DATOS!$B$14*((AB6+AC6)/2))/(DATOS!$B$14+2*((AB6+AC6)/2)))^(4/3)))*(A5-A6)))<0,((AB6+AC6)/2),AB6) | AE6: =IF((((AB6+AC6)/2)+(C6/(DATOS!$B$14*((AB6+AC6)/2)))^2/(2*9.81)+B6-(E5+(C5/(DATOS!$B$14*E5))^2/(2*9.81)+B5+0.5*(((DATOS!$B$27*C5/(DATOS!$B$14*E5))^2/((DATOS!$B$14*E5)/(DATOS!$B$14+2*E5))^(4/3))+((DATOS!$B$27*C6/(DATOS!$B$14*((AB6+AC6)/2)))^2/((DATOS!$B$14*((AB6+AC6)/2))/(DATOS!$B$14+2*((AB6+AC6)/2)))^(4/3)))*(A5-A6)))<0,AC6,((AB6+AC6)/2)) | AF6: =IF((((AD6+AE6)/2)+(C6/(DATOS!$B$14*((AD6+AE6)/2)))^2/(2*9.81)+B6-(E5+(C5/(DATOS!$B$14*E5))^2/(2*9.81)+B5+0.5*(((DATOS!$B$27*C5/(DATOS!$B$14*E5))^2/((DATOS!$B$14*E5)/(DATOS!$B$14+2*E5))^(4/3))+((DATOS!$B$27*C6/(DATOS!$B$14*((AD6+AE6)/2)))^2/((DATOS!$B$14*((AD6+AE6)/2))/(DATOS!$B$14+2*((AD6+AE6)/2)))^(4/3)))*(A5-A6)))<0,((AD6+AE6)/2),AD6) | AG6: =IF((((AD6+AE6)/2)+(C6/(DATOS!$B$14*((AD6+AE6)/2)))^2/(2*9.81)+B6-(E5+(C5/(DATOS!$B$14*E5))^2/(2*9.81)+B5+0.5*(((DATOS!$B$27*C5/(DATOS!$B$14*E5))^2/((DATOS!$B$14*E5)/(DATOS!$B$14+2*E5))^(4/3))+((DATOS!$B$27*C6/(DATOS!$B$14*((AD6+AE6)/2)))^2/((DATOS!$B$14*((AD6+AE6)/2))/(DATOS!$B$14+2*((AD6+AE6)/2)))^(4/3)))*(A5-A6)))<0,AE6,((AD6+AE6)/2)) | AH6: =IF((((AF6+AG6)/2)+(C6/(DATOS!$B$14*((AF6+AG6)/2)))^2/(2*9.81)+B6-(E5+(C5/(DATOS!$B$14*E5))^2/(2*9.81)+B5+0.5*(((DATOS!$B$27*C5/(DATOS!$B$14*E5))^2/((DATOS!$B$14*E5)/(DATOS!$B$14+2*E5))^(4/3))+((DATOS!$B$27*C6/(DATOS!$B$14*((AF6+AG6)/2)))^2/((DATOS!$B$14*((AF6+AG6)/2))/(DATOS!$B$14+2*((AF6+AG6)/2)))^(4/3)))*(A5-A6)))<0,((AF6+AG6)/2),AF6) | AI6: =IF((((AF6+AG6)/2)+(C6/(DATOS!$B$14*((AF6+AG6)/2)))^2/(2*9.81)+B6-(E5+(C5/(DATOS!$B$14*E5))^2/(2*9.81)+B5+0.5*(((DATOS!$B$27*C5/(DATOS!$B$14*E5))^2/((DATOS!$B$14*E5)/(DATOS!$B$14+2*E5))^(4/3))+((DATOS!$B$27*C6/(DATOS!$B$14*((AF6+AG6)/2)))^2/((DATOS!$B$14*((AF6+AG6)/2))/(DATOS!$B$14+2*((AF6+AG6)/2)))^(4/3)))*(A5-A6)))<0,AG6,((AF6+AG6)/2)) | AJ6: =IF((((AH6+AI6)/2)+(C6/(DATOS!$B$14*((AH6+AI6)/2)))^2/(2*9.81)+B6-(E5+(C5/(DATOS!$B$14*E5))^2/(2*9.81)+B5+0.5*(((DATOS!$B$27*C5/(DATOS!$B$14*E5))^2/((DATOS!$B$14*E5)/(DATOS!$B$14+2*E5))^(4/3))+((DATOS!$B$27*C6/(DATOS!$B$14*((AH6+AI6)/2)))^2/((DATOS!$B$14*((AH6+AI6)/2))/(DATOS!$B$14+2*((AH6+AI6)/2)))^(4/3)))*(A5-A6)))<0,((AH6+AI6)/2),AH6) | AK6: =IF((((AH6+AI6)/2)+(C6/(DATOS!$B$14*((AH6+AI6)/2)))^2/(2*9.81)+B6-(E5+(C5/(DATOS!$B$14*E5))^2/(2*9.81)+B5+0.5*(((DATOS!$B$27*C5/(DATOS!$B$14*E5))^2/((DATOS!$B$14*E5)/(DATOS!$B$14+2*E5))^(4/3))+((DATOS!$B$27*C6/(DATOS!$B$14*((AH6+AI6)/2)))^2/((DATOS!$B$14*((AH6+AI6)/2))/(DATOS!$B$14+2*((AH6+AI6)/2)))^(4/3)))*(A5-A6)))<0,AI6,((AH6+AI6)/2)) | AL6: =IF((((AJ6+AK6)/2)+(C6/(DATOS!$B$14*((AJ6+AK6)/2)))^2/(2*9.81)+B6-(E5+(C5/(DATOS!$B$14*E5))^2/(2*9.81)+B5+0.5*(((DATOS!$B$27*C5/(DATOS!$B$14*E5))^2/((DATOS!$B$14*E5)/(DATOS!$B$14+2*E5))^(4/3))+((DATOS!$B$27*C6/(DATOS!$B$14*((AJ6+AK6)/2)))^2/((DATOS!$B$14*((AJ6+AK6)/2))/(DATOS!$B$14+2*((AJ6+AK6)/2)))^(4/3)))*(A5-A6)))<0,((AJ6+AK6)/2),AJ6) | AM6: =IF((((AJ6+AK6)/2)+(C6/(DATOS!$B$14*((AJ6+AK6)/2)))^2/(2*9.81)+B6-(E5+(C5/(DATOS!$B$14*E5))^2/(2*9.81)+B5+0.5*(((DATOS!$B$27*C5/(DATOS!$B$14*E5))^2/((DATOS!$B$14*E5)/(DATOS!$B$14+2*E5))^(4/3))+((DATOS!$B$27*C6/(DATOS!$B$14*((AJ6+AK6)/2)))^2/((DATOS!$B$14*((AJ6+AK6)/2))/(DATOS!$B$14+2*((AJ6+AK6)/2)))^(4/3)))*(A5-A6)))<0,AK6,((AJ6+AK6)/2)) | AN6: =IF((((AL6+AM6)/2)+(C6/(DATOS!$B$14*((AL6+AM6)/2)))^2/(2*9.81)+B6-(E5+(C5/(DATOS!$B$14*E5))^2/(2*9.81)+B5+0.5*(((DATOS!$B$27*C5/(DATOS!$B$14*E5))^2/((DATOS!$B$14*E5)/(DATOS!$B$14+2*E5))^(4/3))+((DATOS!$B$27*C6/(DATOS!$B$14*((AL6+AM6)/2)))^2/((DATOS!$B$14*((AL6+AM6)/2))/(DATOS!$B$14+2*((AL6+AM6)/2)))^(4/3)))*(A5-A6)))<0,((AL6+AM6)/2),AL6) | AO6: =IF((((AL6+AM6)/2)+(C6/(DATOS!$B$14*((AL6+AM6)/2)))^2/(2*9.81)+B6-(E5+(C5/(DATOS!$B$14*E5))^2/(2*9.81)+B5+0.5*(((DATOS!$B$27*C5/(DATOS!$B$14*E5))^2/((DATOS!$B$14*E5)/(DATOS!$B$14+2*E5))^(4/3))+((DATOS!$B$27*C6/(DATOS!$B$14*((AL6+AM6)/2)))^2/((DATOS!$B$14*((AL6+AM6)/2))/(DATOS!$B$14+2*((AL6+AM6)/2)))^(4/3)))*(A5-A6)))<0,AM6,((AL6+AM6)/2)) | AP6: =IF((((AN6+AO6)/2)+(C6/(DATOS!$B$14*((AN6+AO6)/2)))^2/(2*9.81)+B6-(E5+(C5/(DATOS!$B$14*E5))^2/(2*9.81)+B5+0.5*(((DATOS!$B$27*C5/(DATOS!$B$14*E5))^2/((DATOS!$B$14*E5)/(DATOS!$B$14+2*E5))^(4/3))+((DATOS!$B$27*C6/(DATOS!$B$14*((AN6+AO6)/2)))^2/((DATOS!$B$14*((AN6+AO6)/2))/(DATOS!$B$14+2*((AN6+AO6)/2)))^(4/3)))*(A5-A6)))<0,((AN6+AO6)/2),AN6) | AQ6: =IF((((AN6+AO6)/2)+(C6/(DATOS!$B$14*((AN6+AO6)/2)))^2/(2*9.81)+B6-(E5+(C5/(DATOS!$B$14*E5))^2/(2*9.81)+B5+0.5*(((DATOS!$B$27*C5/(DATOS!$B$14*E5))^2/((DATOS!$B$14*E5)/(DATOS!$B$14+2*E5))^(4/3))+((DATOS!$B$27*C6/(DATOS!$B$14*((AN6+AO6)/2)))^2/((DATOS!$B$14*((AN6+AO6)/2))/(DATOS!$B$14+2*((AN6+AO6)/2)))^(4/3)))*(A5-A6)))<0,AO6,((AN6+AO6)/2)) | AR6: =IF((((AP6+AQ6)/2)+(C6/(DATOS!$B$14*((AP6+AQ6)/2)))^2/(2*9.81)+B6-(E5+(C5/(DATOS!$B$14*E5))^2/(2*9.81)+B5+0.5*(((DATOS!$B$27*C5/(DATOS!$B$14*E5))^2/((DATOS!$B$14*E5)/(DATOS!$B$14+2*E5))^(4/3))+((DATOS!$B$27*C6/(DATOS!$B$14*((AP6+AQ6)/2)))^2/((DATOS!$B$14*((AP6+AQ6)/2))/(DATOS!$B$14+2*((AP6+AQ6)/2)))^(4/3)))*(A5-A6)))<0,((AP6+AQ6)/2),AP6) | AS6: =IF((((AP6+AQ6)/2)+(C6/(DATOS!$B$14*((AP6+AQ6)/2)))^2/(2*9.81)+B6-(E5+(C5/(DATOS!$B$14*E5))^2/(2*9.81)+B5+0.5*(((DATOS!$B$27*C5/(DATOS!$B$14*E5))^2/((DATOS!$B$14*E5)/(DATOS!$B$14+2*E5))^(4/3))+((DATOS!$B$27*C6/(DATOS!$B$14*((AP6+AQ6)/2)))^2/((DATOS!$B$14*((AP6+AQ6)/2))/(DATOS!$B$14+2*((AP6+AQ6)/2)))^(4/3)))*(A5-A6)))<0,AQ6,((AP6+AQ6)/2)) | AT6: =IF((((AR6+AS6)/2)+(C6/(DATOS!$B$14*((AR6+AS6)/2)))^2/(2*9.81)+B6-(E5+(C5/(DATOS!$B$14*E5))^2/(2*9.81)+B5+0.5*(((DATOS!$B$27*C5/(DATOS!$B$14*E5))^2/((DATOS!$B$14*E5)/(DATOS!$B$14+2*E5))^(4/3))+((DATOS!$B$27*C6/(DATOS!$B$14*((AR6+AS6)/2)))^2/((DATOS!$B$14*((AR6+AS6)/2))/(DATOS!$B$14+2*((AR6+AS6)/2)))^(4/3)))*(A5-A6)))<0,((AR6+AS6)/2),AR6) | AU6: =IF((((AR6+AS6)/2)+(C6/(DATOS!$B$14*((AR6+AS6)/2)))^2/(2*9.81)+B6-(E5+(C5/(DATOS!$B$14*E5))^2/(2*9.81)+B5+0.5*(((DATOS!$B$27*C5/(DATOS!$B$14*E5))^2/((DATOS!$B$14*E5)/(DATOS!$B$14+2*E5))^(4/3))+((DATOS!$B$27*C6/(DATOS!$B$14*((AR6+AS6)/2)))^2/((DATOS!$B$14*((AR6+AS6)/2))/(DATOS!$B$14+2*((AR6+AS6)/2)))^(4/3)))*(A5-A6)))<0,AS6,((AR6+AS6)/2)) | AV6: =IF((((AT6+AU6)/2)+(C6/(DATOS!$B$14*((AT6+AU6)/2)))^2/(2*9.81)+B6-(E5+(C5/(DATOS!$B$14*E5))^2/(2*9.81)+B5+0.5*(((DATOS!$B$27*C5/(DATOS!$B$14*E5))^2/((DATOS!$B$14*E5)/(DATOS!$B$14+2*E5))^(4/3))+((DATOS!$B$27*C6/(DATOS!$B$14*((AT6+AU6)/2)))^2/((DATOS!$B$14*((AT6+AU6)/2))/(DATOS!$B$14+2*((AT6+AU6)/2)))^(4/3)))*(A5-A6)))<0,((AT6+AU6)/2),AT6) | AW6: =IF((((AT6+AU6)/2)+(C6/(DATOS!$B$14*((AT6+AU6)/2)))^2/(2*9.81)+B6-(E5+(C5/(DATOS!$B$14*E5))^2/(2*9.81)+B5+0.5*(((DATOS!$B$27*C5/(DATOS!$B$14*E5))^2/((DATOS!$B$14*E5)/(DATOS!$B$14+2*E5))^(4/3))+((DATOS!$B$27*C6/(DATOS!$B$14*((AT6+AU6)/2)))^2/((DATOS!$B$14*((AT6+AU6)/2))/(DATOS!$B$14+2*((AT6+AU6)/2)))^(4/3)))*(A5-A6)))<0,AU6,((AT6+AU6)/2)) | AX6: =IF((((AV6+AW6)/2)+(C6/(DATOS!$B$14*((AV6+AW6)/2)))^2/(2*9.81)+B6-(E5+(C5/(DATOS!$B$14*E5))^2/(2*9.81)+B5+0.5*(((DATOS!$B$27*C5/(DATOS!$B$14*E5))^2/((DATOS!$B$14*E5)/(DATOS!$B$14+2*E5))^(4/3))+((DATOS!$B$27*C6/(DATOS!$B$14*((AV6+AW6)/2)))^2/((DATOS!$B$14*((AV6+AW6)/2))/(DATOS!$B$14+2*((AV6+AW6)/2)))^(4/3)))*(A5-A6)))<0,((AV6+AW6)/2),AV6) | AY6: =IF((((AV6+AW6)/2)+(C6/(DATOS!$B$14*((AV6+AW6)/2)))^2/(2*9.81)+B6-(E5+(C5/(DATOS!$B$14*E5))^2/(2*9.81)+B5+0.5*(((DATOS!$B$27*C5/(DATOS!$B$14*E5))^2/((DATOS!$B$14*E5)/(DATOS!$B$14+2*E5))^(4/3))+((DATOS!$B$27*C6/(DATOS!$B$14*((AV6+AW6)/2)))^2/((DATOS!$B$14*((AV6+AW6)/2))/(DATOS!$B$14+2*((AV6+AW6)/2)))^(4/3)))*(A5-A6)))<0,AW6,((AV6+AW6)/2)) | AZ6: =IF((((AX6+AY6)/2)+(C6/(DATOS!$B$14*((AX6+AY6)/2)))^2/(2*9.81)+B6-(E5+(C5/(DATOS!$B$14*E5))^2/(2*9.81)+B5+0.5*(((DATOS!$B$27*C5/(DATOS!$B$14*E5))^2/((DATOS!$B$14*E5)/(DATOS!$B$14+2*E5))^(4/3))+((DATOS!$B$27*C6/(DATOS!$B$14*((AX6+AY6)/2)))^2/((DATOS!$B$14*((AX6+AY6)/2))/(DATOS!$B$14+2*((AX6+AY6)/2)))^(4/3)))*(A5-A6)))<0,((AX6+AY6)/2),AX6) | BA6: =IF((((AX6+AY6)/2)+(C6/(DATOS!$B$14*((AX6+AY6)/2)))^2/(2*9.81)+B6-(E5+(C5/(DATOS!$B$14*E5))^2/(2*9.81)+B5+0.5*(((DATOS!$B$27*C5/(DATOS!$B$14*E5))^2/((DATOS!$B$14*E5)/(DATOS!$B$14+2*E5))^(4/3))+((DATOS!$B$27*C6/(DATOS!$B$14*((AX6+AY6)/2)))^2/((DATOS!$B$14*((AX6+AY6)/2))/(DATOS!$B$14+2*((AX6+AY6)/2)))^(4/3)))*(A5-A6)))<0,AY6,((AX6+AY6)/2)) | BB6: =IF((((AZ6+BA6)/2)+(C6/(DATOS!$B$14*((AZ6+BA6)/2)))^2/(2*9.81)+B6-(E5+(C5/(DATOS!$B$14*E5))^2/(2*9.81)+B5+0.5*(((DATOS!$B$27*C5/(DATOS!$B$14*E5))^2/((DATOS!$B$14*E5)/(DATOS!$B$14+2*E5))^(4/3))+((DATOS!$B$27*C6/(DATOS!$B$14*((AZ6+BA6)/2)))^2/((DATOS!$B$14*((AZ6+BA6)/2))/(DATOS!$B$14+2*((AZ6+BA6)/2)))^(4/3)))*(A5-A6)))<0,((AZ6+BA6)/2),AZ6) | BC6: =IF((((AZ6+BA6)/2)+(C6/(DATOS!$B$14*((AZ6+BA6)/2)))^2/(2*9.81)+B6-(E5+(C5/(DATOS!$B$14*E5))^2/(2*9.81)+B5+0.5*(((DATOS!$B$27*C5/(DATOS!$B$14*E5))^2/((DATOS!$B$14*E5)/(DATOS!$B$14+2*E5))^(4/3))+((DATOS!$B$27*C6/(DATOS!$B$14*((AZ6+BA6)/2)))^2/((DATOS!$B$14*((AZ6+BA6)/2))/(DATOS!$B$14+2*((AZ6+BA6)/2)))^(4/3)))*(A5-A6)))<0,BA6,((AZ6+BA6)/2)) | BD6: =IF((((BB6+BC6)/2)+(C6/(DATOS!$B$14*((BB6+BC6)/2)))^2/(2*9.81)+B6-(E5+(C5/(DATOS!$B$14*E5))^2/(2*9.81)+B5+0.5*(((DATOS!$B$27*C5/(DATOS!$B$14*E5))^2/((DATOS!$B$14*E5)/(DATOS!$B$14+2*E5))^(4/3))+((DATOS!$B$27*C6/(DATOS!$B$14*((BB6+BC6)/2)))^2/((DATOS!$B$14*((BB6+BC6)/2))/(DATOS!$B$14+2*((BB6+BC6)/2)))^(4/3)))*(A5-A6)))<0,((BB6+BC6)/2),BB6) | BE6: =IF((((BB6+BC6)/2)+(C6/(DATOS!$B$14*((BB6+BC6)/2)))^2/(2*9.81)+B6-(E5+(C5/(DATOS!$B$14*E5))^2/(2*9.81)+B5+0.5*(((DATOS!$B$27*C5/(DATOS!$B$14*E5))^2/((DATOS!$B$14*E5)/(DATOS!$B$14+2*E5))^(4/3))+((DATOS!$B$27*C6/(DATOS!$B$14*((BB6+BC6)/2)))^2/((DATOS!$B$14*((BB6+BC6)/2))/(DATOS!$B$14+2*((BB6+BC6)/2)))^(4/3)))*(A5-A6)))<0,BC6,((BB6+BC6)/2)) | BF6: =IF((((BD6+BE6)/2)+(C6/(DATOS!$B$14*((BD6+BE6)/2)))^2/(2*9.81)+B6-(E5+(C5/(DATOS!$B$14*E5))^2/(2*9.81)+B5+0.5*(((DATOS!$B$27*C5/(DATOS!$B$14*E5))^2/((DATOS!$B$14*E5)/(DATOS!$B$14+2*E5))^(4/3))+((DATOS!$B$27*C6/(DATOS!$B$14*((BD6+BE6)/2)))^2/((DATOS!$B$14*((BD6+BE6)/2))/(DATOS!$B$14+2*((BD6+BE6)/2)))^(4/3)))*(A5-A6)))<0,((BD6+BE6)/2),BD6) | BG6: =IF((((BD6+BE6)/2)+(C6/(DATOS!$B$14*((BD6+BE6)/2)))^2/(2*9.81)+B6-(E5+(C5/(DATOS!$B$14*E5))^2/(2*9.81)+B5+0.5*(((DATOS!$B$27*C5/(DATOS!$B$14*E5))^2/((DATOS!$B$14*E5)/(DATOS!$B$14+2*E5))^(4/3))+((DATOS!$B$27*C6/(DATOS!$B$14*((BD6+BE6)/2)))^2/((DATOS!$B$14*((BD6+BE6)/2))/(DATOS!$B$14+2*((BD6+BE6)/2)))^(4/3)))*(A5-A6)))<0,BE6,((BD6+BE6)/2)) | BH6: =IF((((BF6+BG6)/2)+(C6/(DATOS!$B$14*((BF6+BG6)/2)))^2/(2*9.81)+B6-(E5+(C5/(DATOS!$B$14*E5))^2/(2*9.81)+B5+0.5*(((DATOS!$B$27*C5/(DATOS!$B$14*E5))^2/((DATOS!$B$14*E5)/(DATOS!$B$14+2*E5))^(4/3))+((DATOS!$B$27*C6/(DATOS!$B$14*((BF6+BG6)/2)))^2/((DATOS!$B$14*((BF6+BG6)/2))/(DATOS!$B$14+2*((BF6+BG6)/2)))^(4/3)))*(A5-A6)))<0,((BF6+BG6)/2),BF6) | BI6: =IF((((BF6+BG6)/2)+(C6/(DATOS!$B$14*((BF6+BG6)/2)))^2/(2*9.81)+B6-(E5+(C5/(DATOS!$B$14*E5))^2/(2*9.81)+B5+0.5*(((DATOS!$B$27*C5/(DATOS!$B$14*E5))^2/((DATOS!$B$14*E5)/(DATOS!$B$14+2*E5))^(4/3))+((DATOS!$B$27*C6/(DATOS!$B$14*((BF6+BG6)/2)))^2/((DATOS!$B$14*((BF6+BG6)/2))/(DATOS!$B$14+2*((BF6+BG6)/2)))^(4/3)))*(A5-A6)))<0,BG6,((BF6+BG6)/2)) | BJ6: =IF((((BH6+BI6)/2)+(C6/(DATOS!$B$14*((BH6+BI6)/2)))^2/(2*9.81)+B6-(E5+(C5/(DATOS!$B$14*E5))^2/(2*9.81)+B5+0.5*(((DATOS!$B$27*C5/(DATOS!$B$14*E5))^2/((DATOS!$B$14*E5)/(DATOS!$B$14+2*E5))^(4/3))+((DATOS!$B$27*C6/(DATOS!$B$14*((BH6+BI6)/2)))^2/((DATOS!$B$14*((BH6+BI6)/2))/(DATOS!$B$14+2*((BH6+BI6)/2)))^(4/3)))*(A5-A6)))<0,((BH6+BI6)/2),BH6) | BK6: =IF((((BH6+BI6)/2)+(C6/(DATOS!$B$14*((BH6+BI6)/2)))^2/(2*9.81)+B6-(E5+(C5/(DATOS!$B$14*E5))^2/(2*9.81)+B5+0.5*(((DATOS!$B$27*C5/(DATOS!$B$14*E5))^2/((DATOS!$B$14*E5)/(DATOS!$B$14+2*E5))^(4/3))+((DATOS!$B$27*C6/(DATOS!$B$14*((BH6+BI6)/2)))^2/((DATOS!$B$14*((BH6+BI6)/2))/(DATOS!$B$14+2*((BH6+BI6)/2)))^(4/3)))*(A5-A6)))<0,BI6,((BH6+BI6)/2)) | BL6: =IF((((BJ6+BK6)/2)+(C6/(DATOS!$B$14*((BJ6+BK6)/2)))^2/(2*9.81)+B6-(E5+(C5/(DATOS!$B$14*E5))^2/(2*9.81)+B5+0.5*(((DATOS!$B$27*C5/(DATOS!$B$14*E5))^2/((DATOS!$B$14*E5)/(DATOS!$B$14+2*E5))^(4/3))+((DATOS!$B$27*C6/(DATOS!$B$14*((BJ6+BK6)/2)))^2/((DATOS!$B$14*((BJ6+BK6)/2))/(DATOS!$B$14+2*((BJ6+BK6)/2)))^(4/3)))*(A5-A6)))<0,((BJ6+BK6)/2),BJ6) | BM6: =IF((((BJ6+BK6)/2)+(C6/(DATOS!$B$14*((BJ6+BK6)/2)))^2/(2*9.81)+B6-(E5+(C5/(DATOS!$B$14*E5))^2/(2*9.81)+B5+0.5*(((DATOS!$B$27*C5/(DATOS!$B$14*E5))^2/((DATOS!$B$14*E5)/(DATOS!$B$14+2*E5))^(4/3))+((DATOS!$B$27*C6/(DATOS!$B$14*((BJ6+BK6)/2)))^2/((DATOS!$B$14*((BJ6+BK6)/2))/(DATOS!$B$14+2*((BJ6+BK6)/2)))^(4/3)))*(A5-A6)))<0,BK6,((BJ6+BK6)/2)) | BN6: =IF((((BL6+BM6)/2)+(C6/(DATOS!$B$14*((BL6+BM6)/2)))^2/(2*9.81)+B6-(E5+(C5/(DATOS!$B$14*E5))^2/(2*9.81)+B5+0.5*(((DATOS!$B$27*C5/(DATOS!$B$14*E5))^2/((DATOS!$B$14*E5)/(DATOS!$B$14+2*E5))^(4/3))+((DATOS!$B$27*C6/(DATOS!$B$14*((BL6+BM6)/2)))^2/((DATOS!$B$14*((BL6+BM6)/2))/(DATOS!$B$14+2*((BL6+BM6)/2)))^(4/3)))*(A5-A6)))<0,((BL6+BM6)/2),BL6) | BO6: =IF((((BL6+BM6)/2)+(C6/(DATOS!$B$14*((BL6+BM6)/2)))^2/(2*9.81)+B6-(E5+(C5/(DATOS!$B$14*E5))^2/(2*9.81)+B5+0.5*(((DATOS!$B$27*C5/(DATOS!$B$14*E5))^2/((DATOS!$B$14*E5)/(DATOS!$B$14+2*E5))^(4/3))+((DATOS!$B$27*C6/(DATOS!$B$14*((BL6+BM6)/2)))^2/((DATOS!$B$14*((BL6+BM6)/2))/(DATOS!$B$14+2*((BL6+BM6)/2)))^(4/3)))*(A5-A6)))<0,BM6,((BL6+BM6)/2)) | BP6: =IF((((BN6+BO6)/2)+(C6/(DATOS!$B$14*((BN6+BO6)/2)))^2/(2*9.81)+B6-(E5+(C5/(DATOS!$B$14*E5))^2/(2*9.81)+B5+0.5*(((DATOS!$B$27*C5/(DATOS!$B$14*E5))^2/((DATOS!$B$14*E5)/(DATOS!$B$14+2*E5))^(4/3))+((DATOS!$B$27*C6/(DATOS!$B$14*((BN6+BO6)/2)))^2/((DATOS!$B$14*((BN6+BO6)/2))/(DATOS!$B$14+2*((BN6+BO6)/2)))^(4/3)))*(A5-A6)))<0,((BN6+BO6)/2),BN6) | BQ6: =IF((((BN6+BO6)/2)+(C6/(DATOS!$B$14*((BN6+BO6)/2)))^2/(2*9.81)+B6-(E5+(C5/(DATOS!$B$14*E5))^2/(2*9.81)+B5+0.5*(((DATOS!$B$27*C5/(DATOS!$B$14*E5))^2/((DATOS!$B$14*E5)/(DATOS!$B$14+2*E5))^(4/3))+((DATOS!$B$27*C6/(DATOS!$B$14*((BN6+BO6)/2)))^2/((DATOS!$B$14*((BN6+BO6)/2))/(DATOS!$B$14+2*((BN6+BO6)/2)))^(4/3)))*(A5-A6)))<0,BO6,((BN6+BO6)/2)) | BR6: =IF((((BP6+BQ6)/2)+(C6/(DATOS!$B$14*((BP6+BQ6)/2)))^2/(2*9.81)+B6-(E5+(C5/(DATOS!$B$14*E5))^2/(2*9.81)+B5+0.5*(((DATOS!$B$27*C5/(DATOS!$B$14*E5))^2/((DATOS!$B$14*E5)/(DATOS!$B$14+2*E5))^(4/3))+((DATOS!$B$27*C6/(DATOS!$B$14*((BP6+BQ6)/2)))^2/((DATOS!$B$14*((BP6+BQ6)/2))/(DATOS!$B$14+2*((BP6+BQ6)/2)))^(4/3)))*(A5-A6)))<0,((BP6+BQ6)/2),BP6) | BS6: =IF((((BP6+BQ6)/2)+(C6/(DATOS!$B$14*((BP6+BQ6)/2)))^2/(2*9.81)+B6-(E5+(C5/(DATOS!$B$14*E5))^2/(2*9.81)+B5+0.5*(((DATOS!$B$27*C5/(DATOS!$B$14*E5))^2/((DATOS!$B$14*E5)/(DATOS!$B$14+2*E5))^(4/3))+((DATOS!$B$27*C6/(DATOS!$B$14*((BP6+BQ6)/2)))^2/((DATOS!$B$14*((BP6+BQ6)/2))/(DATOS!$B$14+2*((BP6+BQ6)/2)))^(4/3)))*(A5-A6)))<0,BQ6,((BP6+BQ6)/2)) | BT6: =IF((((BR6+BS6)/2)+(C6/(DATOS!$B$14*((BR6+BS6)/2)))^2/(2*9.81)+B6-(E5+(C5/(DATOS!$B$14*E5))^2/(2*9.81)+B5+0.5*(((DATOS!$B$27*C5/(DATOS!$B$14*E5))^2/((DATOS!$B$14*E5)/(DATOS!$B$14+2*E5))^(4/3))+((DATOS!$B$27*C6/(DATOS!$B$14*((BR6+BS6)/2)))^2/((DATOS!$B$14*((BR6+BS6)/2))/(DATOS!$B$14+2*((BR6+BS6)/2)))^(4/3)))*(A5-A6)))<0,((BR6+BS6)/2),BR6) | BU6: =IF((((BR6+BS6)/2)+(C6/(DATOS!$B$14*((BR6+BS6)/2)))^2/(2*9.81)+B6-(E5+(C5/(DATOS!$B$14*E5))^2/(2*9.81)+B5+0.5*(((DATOS!$B$27*C5/(DATOS!$B$14*E5))^2/((DATOS!$B$14*E5)/(DATOS!$B$14+2*E5))^(4/3))+((DATOS!$B$27*C6/(DATOS!$B$14*((BR6+BS6)/2)))^2/((DATOS!$B$14*((BR6+BS6)/2))/(DATOS!$B$14+2*((BR6+BS6)/2)))^(4/3)))*(A5-A6)))<0,BS6,((BR6+BS6)/2))
A7: 136 | B7: =DATOS!$B$16-DATOS!$B$19*A7 | C7: =IF(A7<CAUDALES!$B$13,CAUDALES!$D$12,IF(A7<CAUDALES!$B$14,CAUDALES!$D$13,IF(A7<CAUDALES!$B$15,CAUDALES!$D$14,CAUDALES!$D$15)))/1000 | D7: =(C7^2/(9.81*DATOS!$B$14^2))^(1/3) | E7: =(BT7+BU7)/2 | F7: =B7+E7 | G7: =C7/(DATOS!$B$14*E7) | H7: =G7/SQRT(9.81*E7) | I7: =IF(A7<=DATOS!$B$20,DATOS!$B$21-IF(AND(A7>=DATOS!$B$23,A7<DATOS!$B$24),DATOS!$B$25,DATOS!$B$22),B7+DATOS!$B$26) | J7: =I7-B7 | K7: =E7/J7 | L7: =I7-F7 | M7: =IF(AND(K7<=DATOS!$B$29,L7>=DATOS!$B$30),"CUMPLE","NO CUMPLE") | N7: =IF(A7>DATOS!$B$20,"cubierto - tramo final",IF(AND(A7>=DATOS!$B$23,A7<DATOS!$B$24),"cubierto - camiones","cubierto")) | P7: =D7*1.001 | Q7: 2 | R7: =IF((((P7+Q7)/2)+(C7/(DATOS!$B$14*((P7+Q7)/2)))^2/(2*9.81)+B7-(E6+(C6/(DATOS!$B$14*E6))^2/(2*9.81)+B6+0.5*(((DATOS!$B$27*C6/(DATOS!$B$14*E6))^2/((DATOS!$B$14*E6)/(DATOS!$B$14+2*E6))^(4/3))+((DATOS!$B$27*C7/(DATOS!$B$14*((P7+Q7)/2)))^2/((DATOS!$B$14*((P7+Q7)/2))/(DATOS!$B$14+2*((P7+Q7)/2)))^(4/3)))*(A6-A7)))<0,((P7+Q7)/2),P7) | S7: =IF((((P7+Q7)/2)+(C7/(DATOS!$B$14*((P7+Q7)/2)))^2/(2*9.81)+B7-(E6+(C6/(DATOS!$B$14*E6))^2/(2*9.81)+B6+0.5*(((DATOS!$B$27*C6/(DATOS!$B$14*E6))^2/((DATOS!$B$14*E6)/(DATOS!$B$14+2*E6))^(4/3))+((DATOS!$B$27*C7/(DATOS!$B$14*((P7+Q7)/2)))^2/((DATOS!$B$14*((P7+Q7)/2))/(DATOS!$B$14+2*((P7+Q7)/2)))^(4/3)))*(A6-A7)))<0,Q7,((P7+Q7)/2)) | T7: =IF((((R7+S7)/2)+(C7/(DATOS!$B$14*((R7+S7)/2)))^2/(2*9.81)+B7-(E6+(C6/(DATOS!$B$14*E6))^2/(2*9.81)+B6+0.5*(((DATOS!$B$27*C6/(DATOS!$B$14*E6))^2/((DATOS!$B$14*E6)/(DATOS!$B$14+2*E6))^(4/3))+((DATOS!$B$27*C7/(DATOS!$B$14*((R7+S7)/2)))^2/((DATOS!$B$14*((R7+S7)/2))/(DATOS!$B$14+2*((R7+S7)/2)))^(4/3)))*(A6-A7)))<0,((R7+S7)/2),R7) | U7: =IF((((R7+S7)/2)+(C7/(DATOS!$B$14*((R7+S7)/2)))^2/(2*9.81)+B7-(E6+(C6/(DATOS!$B$14*E6))^2/(2*9.81)+B6+0.5*(((DATOS!$B$27*C6/(DATOS!$B$14*E6))^2/((DATOS!$B$14*E6)/(DATOS!$B$14+2*E6))^(4/3))+((DATOS!$B$27*C7/(DATOS!$B$14*((R7+S7)/2)))^2/((DATOS!$B$14*((R7+S7)/2))/(DATOS!$B$14+2*((R7+S7)/2)))^(4/3)))*(A6-A7)))<0,S7,((R7+S7)/2)) | V7: =IF((((T7+U7)/2)+(C7/(DATOS!$B$14*((T7+U7)/2)))^2/(2*9.81)+B7-(E6+(C6/(DATOS!$B$14*E6))^2/(2*9.81)+B6+0.5*(((DATOS!$B$27*C6/(DATOS!$B$14*E6))^2/((DATOS!$B$14*E6)/(DATOS!$B$14+2*E6))^(4/3))+((DATOS!$B$27*C7/(DATOS!$B$14*((T7+U7)/2)))^2/((DATOS!$B$14*((T7+U7)/2))/(DATOS!$B$14+2*((T7+U7)/2)))^(4/3)))*(A6-A7)))<0,((T7+U7)/2),T7) | W7: =IF((((T7+U7)/2)+(C7/(DATOS!$B$14*((T7+U7)/2)))^2/(2*9.81)+B7-(E6+(C6/(DATOS!$B$14*E6))^2/(2*9.81)+B6+0.5*(((DATOS!$B$27*C6/(DATOS!$B$14*E6))^2/((DATOS!$B$14*E6)/(DATOS!$B$14+2*E6))^(4/3))+((DATOS!$B$27*C7/(DATOS!$B$14*((T7+U7)/2)))^2/((DATOS!$B$14*((T7+U7)/2))/(DATOS!$B$14+2*((T7+U7)/2)))^(4/3)))*(A6-A7)))<0,U7,((T7+U7)/2)) | X7: =IF((((V7+W7)/2)+(C7/(DATOS!$B$14*((V7+W7)/2)))^2/(2*9.81)+B7-(E6+(C6/(DATOS!$B$14*E6))^2/(2*9.81)+B6+0.5*(((DATOS!$B$27*C6/(DATOS!$B$14*E6))^2/((DATOS!$B$14*E6)/(DATOS!$B$14+2*E6))^(4/3))+((DATOS!$B$27*C7/(DATOS!$B$14*((V7+W7)/2)))^2/((DATOS!$B$14*((V7+W7)/2))/(DATOS!$B$14+2*((V7+W7)/2)))^(4/3)))*(A6-A7)))<0,((V7+W7)/2),V7) | Y7: =IF((((V7+W7)/2)+(C7/(DATOS!$B$14*((V7+W7)/2)))^2/(2*9.81)+B7-(E6+(C6/(DATOS!$B$14*E6))^2/(2*9.81)+B6+0.5*(((DATOS!$B$27*C6/(DATOS!$B$14*E6))^2/((DATOS!$B$14*E6)/(DATOS!$B$14+2*E6))^(4/3))+((DATOS!$B$27*C7/(DATOS!$B$14*((V7+W7)/2)))^2/((DATOS!$B$14*((V7+W7)/2))/(DATOS!$B$14+2*((V7+W7)/2)))^(4/3)))*(A6-A7)))<0,W7,((V7+W7)/2)) | Z7: =IF((((X7+Y7)/2)+(C7/(DATOS!$B$14*((X7+Y7)/2)))^2/(2*9.81)+B7-(E6+(C6/(DATOS!$B$14*E6))^2/(2*9.81)+B6+0.5*(((DATOS!$B$27*C6/(DATOS!$B$14*E6))^2/((DATOS!$B$14*E6)/(DATOS!$B$14+2*E6))^(4/3))+((DATOS!$B$27*C7/(DATOS!$B$14*((X7+Y7)/2)))^2/((DATOS!$B$14*((X7+Y7)/2))/(DATOS!$B$14+2*((X7+Y7)/2)))^(4/3)))*(A6-A7)))<0,((X7+Y7)/2),X7) | AA7: =IF((((X7+Y7)/2)+(C7/(DATOS!$B$14*((X7+Y7)/2)))^2/(2*9.81)+B7-(E6+(C6/(DATOS!$B$14*E6))^2/(2*9.81)+B6+0.5*(((DATOS!$B$27*C6/(DATOS!$B$14*E6))^2/((DATOS!$B$14*E6)/(DATOS!$B$14+2*E6))^(4/3))+((DATOS!$B$27*C7/(DATOS!$B$14*((X7+Y7)/2)))^2/((DATOS!$B$14*((X7+Y7)/2))/(DATOS!$B$14+2*((X7+Y7)/2)))^(4/3)))*(A6-A7)))<0,Y7,((X7+Y7)/2)) | AB7: =IF((((Z7+AA7)/2)+(C7/(DATOS!$B$14*((Z7+AA7)/2)))^2/(2*9.81)+B7-(E6+(C6/(DATOS!$B$14*E6))^2/(2*9.81)+B6+0.5*(((DATOS!$B$27*C6/(DATOS!$B$14*E6))^2/((DATOS!$B$14*E6)/(DATOS!$B$14+2*E6))^(4/3))+((DATOS!$B$27*C7/(DATOS!$B$14*((Z7+AA7)/2)))^2/((DATOS!$B$14*((Z7+AA7)/2))/(DATOS!$B$14+2*((Z7+AA7)/2)))^(4/3)))*(A6-A7)))<0,((Z7+AA7)/2),Z7) | AC7: =IF((((Z7+AA7)/2)+(C7/(DATOS!$B$14*((Z7+AA7)/2)))^2/(2*9.81)+B7-(E6+(C6/(DATOS!$B$14*E6))^2/(2*9.81)+B6+0.5*(((DATOS!$B$27*C6/(DATOS!$B$14*E6))^2/((DATOS!$B$14*E6)/(DATOS!$B$14+2*E6))^(4/3))+((DATOS!$B$27*C7/(DATOS!$B$14*((Z7+AA7)/2)))^2/((DATOS!$B$14*((Z7+AA7)/2))/(DATOS!$B$14+2*((Z7+AA7)/2)))^(4/3)))*(A6-A7)))<0,AA7,((Z7+AA7)/2)) | AD7: =IF((((AB7+AC7)/2)+(C7/(DATOS!$B$14*((AB7+AC7)/2)))^2/(2*9.81)+B7-(E6+(C6/(DATOS!$B$14*E6))^2/(2*9.81)+B6+0.5*(((DATOS!$B$27*C6/(DATOS!$B$14*E6))^2/((DATOS!$B$14*E6)/(DATOS!$B$14+2*E6))^(4/3))+((DATOS!$B$27*C7/(DATOS!$B$14*((AB7+AC7)/2)))^2/((DATOS!$B$14*((AB7+AC7)/2))/(DATOS!$B$14+2*((AB7+AC7)/2)))^(4/3)))*(A6-A7)))<0,((AB7+AC7)/2),AB7) | AE7: =IF((((AB7+AC7)/2)+(C7/(DATOS!$B$14*((AB7+AC7)/2)))^2/(2*9.81)+B7-(E6+(C6/(DATOS!$B$14*E6))^2/(2*9.81)+B6+0.5*(((DATOS!$B$27*C6/(DATOS!$B$14*E6))^2/((DATOS!$B$14*E6)/(DATOS!$B$14+2*E6))^(4/3))+((DATOS!$B$27*C7/(DATOS!$B$14*((AB7+AC7)/2)))^2/((DATOS!$B$14*((AB7+AC7)/2))/(DATOS!$B$14+2*((AB7+AC7)/2)))^(4/3)))*(A6-A7)))<0,AC7,((AB7+AC7)/2)) | AF7: =IF((((AD7+AE7)/2)+(C7/(DATOS!$B$14*((AD7+AE7)/2)))^2/(2*9.81)+B7-(E6+(C6/(DATOS!$B$14*E6))^2/(2*9.81)+B6+0.5*(((DATOS!$B$27*C6/(DATOS!$B$14*E6))^2/((DATOS!$B$14*E6)/(DATOS!$B$14+2*E6))^(4/3))+((DATOS!$B$27*C7/(DATOS!$B$14*((AD7+AE7)/2)))^2/((DATOS!$B$14*((AD7+AE7)/2))/(DATOS!$B$14+2*((AD7+AE7)/2)))^(4/3)))*(A6-A7)))<0,((AD7+AE7)/2),AD7) | AG7: =IF((((AD7+AE7)/2)+(C7/(DATOS!$B$14*((AD7+AE7)/2)))^2/(2*9.81)+B7-(E6+(C6/(DATOS!$B$14*E6))^2/(2*9.81)+B6+0.5*(((DATOS!$B$27*C6/(DATOS!$B$14*E6))^2/((DATOS!$B$14*E6)/(DATOS!$B$14+2*E6))^(4/3))+((DATOS!$B$27*C7/(DATOS!$B$14*((AD7+AE7)/2)))^2/((DATOS!$B$14*((AD7+AE7)/2))/(DATOS!$B$14+2*((AD7+AE7)/2)))^(4/3)))*(A6-A7)))<0,AE7,((AD7+AE7)/2)) | AH7: =IF((((AF7+AG7)/2)+(C7/(DATOS!$B$14*((AF7+AG7)/2)))^2/(2*9.81)+B7-(E6+(C6/(DATOS!$B$14*E6))^2/(2*9.81)+B6+0.5*(((DATOS!$B$27*C6/(DATOS!$B$14*E6))^2/((DATOS!$B$14*E6)/(DATOS!$B$14+2*E6))^(4/3))+((DATOS!$B$27*C7/(DATOS!$B$14*((AF7+AG7)/2)))^2/((DATOS!$B$14*((AF7+AG7)/2))/(DATOS!$B$14+2*((AF7+AG7)/2)))^(4/3)))*(A6-A7)))<0,((AF7+AG7)/2),AF7) | AI7: =IF((((AF7+AG7)/2)+(C7/(DATOS!$B$14*((AF7+AG7)/2)))^2/(2*9.81)+B7-(E6+(C6/(DATOS!$B$14*E6))^2/(2*9.81)+B6+0.5*(((DATOS!$B$27*C6/(DATOS!$B$14*E6))^2/((DATOS!$B$14*E6)/(DATOS!$B$14+2*E6))^(4/3))+((DATOS!$B$27*C7/(DATOS!$B$14*((AF7+AG7)/2)))^2/((DATOS!$B$14*((AF7+AG7)/2))/(DATOS!$B$14+2*((AF7+AG7)/2)))^(4/3)))*(A6-A7)))<0,AG7,((AF7+AG7)/2)) | AJ7: =IF((((AH7+AI7)/2)+(C7/(DATOS!$B$14*((AH7+AI7)/2)))^2/(2*9.81)+B7-(E6+(C6/(DATOS!$B$14*E6))^2/(2*9.81)+B6+0.5*(((DATOS!$B$27*C6/(DATOS!$B$14*E6))^2/((DATOS!$B$14*E6)/(DATOS!$B$14+2*E6))^(4/3))+((DATOS!$B$27*C7/(DATOS!$B$14*((AH7+AI7)/2)))^2/((DATOS!$B$14*((AH7+AI7)/2))/(DATOS!$B$14+2*((AH7+AI7)/2)))^(4/3)))*(A6-A7)))<0,((AH7+AI7)/2),AH7) | AK7: =IF((((AH7+AI7)/2)+(C7/(DATOS!$B$14*((AH7+AI7)/2)))^2/(2*9.81)+B7-(E6+(C6/(DATOS!$B$14*E6))^2/(2*9.81)+B6+0.5*(((DATOS!$B$27*C6/(DATOS!$B$14*E6))^2/((DATOS!$B$14*E6)/(DATOS!$B$14+2*E6))^(4/3))+((DATOS!$B$27*C7/(DATOS!$B$14*((AH7+AI7)/2)))^2/((DATOS!$B$14*((AH7+AI7)/2))/(DATOS!$B$14+2*((AH7+AI7)/2)))^(4/3)))*(A6-A7)))<0,AI7,((AH7+AI7)/2)) | AL7: =IF((((AJ7+AK7)/2)+(C7/(DATOS!$B$14*((AJ7+AK7)/2)))^2/(2*9.81)+B7-(E6+(C6/(DATOS!$B$14*E6))^2/(2*9.81)+B6+0.5*(((DATOS!$B$27*C6/(DATOS!$B$14*E6))^2/((DATOS!$B$14*E6)/(DATOS!$B$14+2*E6))^(4/3))+((DATOS!$B$27*C7/(DATOS!$B$14*((AJ7+AK7)/2)))^2/((DATOS!$B$14*((AJ7+AK7)/2))/(DATOS!$B$14+2*((AJ7+AK7)/2)))^(4/3)))*(A6-A7)))<0,((AJ7+AK7)/2),AJ7) | AM7: =IF((((AJ7+AK7)/2)+(C7/(DATOS!$B$14*((AJ7+AK7)/2)))^2/(2*9.81)+B7-(E6+(C6/(DATOS!$B$14*E6))^2/(2*9.81)+B6+0.5*(((DATOS!$B$27*C6/(DATOS!$B$14*E6))^2/((DATOS!$B$14*E6)/(DATOS!$B$14+2*E6))^(4/3))+((DATOS!$B$27*C7/(DATOS!$B$14*((AJ7+AK7)/2)))^2/((DATOS!$B$14*((AJ7+AK7)/2))/(DATOS!$B$14+2*((AJ7+AK7)/2)))^(4/3)))*(A6-A7)))<0,AK7,((AJ7+AK7)/2)) | AN7: =IF((((AL7+AM7)/2)+(C7/(DATOS!$B$14*((AL7+AM7)/2)))^2/(2*9.81)+B7-(E6+(C6/(DATOS!$B$14*E6))^2/(2*9.81)+B6+0.5*(((DATOS!$B$27*C6/(DATOS!$B$14*E6))^2/((DATOS!$B$14*E6)/(DATOS!$B$14+2*E6))^(4/3))+((DATOS!$B$27*C7/(DATOS!$B$14*((AL7+AM7)/2)))^2/((DATOS!$B$14*((AL7+AM7)/2))/(DATOS!$B$14+2*((AL7+AM7)/2)))^(4/3)))*(A6-A7)))<0,((AL7+AM7)/2),AL7) | AO7: =IF((((AL7+AM7)/2)+(C7/(DATOS!$B$14*((AL7+AM7)/2)))^2/(2*9.81)+B7-(E6+(C6/(DATOS!$B$14*E6))^2/(2*9.81)+B6+0.5*(((DATOS!$B$27*C6/(DATOS!$B$14*E6))^2/((DATOS!$B$14*E6)/(DATOS!$B$14+2*E6))^(4/3))+((DATOS!$B$27*C7/(DATOS!$B$14*((AL7+AM7)/2)))^2/((DATOS!$B$14*((AL7+AM7)/2))/(DATOS!$B$14+2*((AL7+AM7)/2)))^(4/3)))*(A6-A7)))<0,AM7,((AL7+AM7)/2)) | AP7: =IF((((AN7+AO7)/2)+(C7/(DATOS!$B$14*((AN7+AO7)/2)))^2/(2*9.81)+B7-(E6+(C6/(DATOS!$B$14*E6))^2/(2*9.81)+B6+0.5*(((DATOS!$B$27*C6/(DATOS!$B$14*E6))^2/((DATOS!$B$14*E6)/(DATOS!$B$14+2*E6))^(4/3))+((DATOS!$B$27*C7/(DATOS!$B$14*((AN7+AO7)/2)))^2/((DATOS!$B$14*((AN7+AO7)/2))/(DATOS!$B$14+2*((AN7+AO7)/2)))^(4/3)))*(A6-A7)))<0,((AN7+AO7)/2),AN7) | AQ7: =IF((((AN7+AO7)/2)+(C7/(DATOS!$B$14*((AN7+AO7)/2)))^2/(2*9.81)+B7-(E6+(C6/(DATOS!$B$14*E6))^2/(2*9.81)+B6+0.5*(((DATOS!$B$27*C6/(DATOS!$B$14*E6))^2/((DATOS!$B$14*E6)/(DATOS!$B$14+2*E6))^(4/3))+((DATOS!$B$27*C7/(DATOS!$B$14*((AN7+AO7)/2)))^2/((DATOS!$B$14*((AN7+AO7)/2))/(DATOS!$B$14+2*((AN7+AO7)/2)))^(4/3)))*(A6-A7)))<0,AO7,((AN7+AO7)/2)) | AR7: =IF((((AP7+AQ7)/2)+(C7/(DATOS!$B$14*((AP7+AQ7)/2)))^2/(2*9.81)+B7-(E6+(C6/(DATOS!$B$14*E6))^2/(2*9.81)+B6+0.5*(((DATOS!$B$27*C6/(DATOS!$B$14*E6))^2/((DATOS!$B$14*E6)/(DATOS!$B$14+2*E6))^(4/3))+((DATOS!$B$27*C7/(DATOS!$B$14*((AP7+AQ7)/2)))^2/((DATOS!$B$14*((AP7+AQ7)/2))/(DATOS!$B$14+2*((AP7+AQ7)/2)))^(4/3)))*(A6-A7)))<0,((AP7+AQ7)/2),AP7) | AS7: =IF((((AP7+AQ7)/2)+(C7/(DATOS!$B$14*((AP7+AQ7)/2)))^2/(2*9.81)+B7-(E6+(C6/(DATOS!$B$14*E6))^2/(2*9.81)+B6+0.5*(((DATOS!$B$27*C6/(DATOS!$B$14*E6))^2/((DATOS!$B$14*E6)/(DATOS!$B$14+2*E6))^(4/3))+((DATOS!$B$27*C7/(DATOS!$B$14*((AP7+AQ7)/2)))^2/((DATOS!$B$14*((AP7+AQ7)/2))/(DATOS!$B$14+2*((AP7+AQ7)/2)))^(4/3)))*(A6-A7)))<0,AQ7,((AP7+AQ7)/2)) | AT7: =IF((((AR7+AS7)/2)+(C7/(DATOS!$B$14*((AR7+AS7)/2)))^2/(2*9.81)+B7-(E6+(C6/(DATOS!$B$14*E6))^2/(2*9.81)+B6+0.5*(((DATOS!$B$27*C6/(DATOS!$B$14*E6))^2/((DATOS!$B$14*E6)/(DATOS!$B$14+2*E6))^(4/3))+((DATOS!$B$27*C7/(DATOS!$B$14*((AR7+AS7)/2)))^2/((DATOS!$B$14*((AR7+AS7)/2))/(DATOS!$B$14+2*((AR7+AS7)/2)))^(4/3)))*(A6-A7)))<0,((AR7+AS7)/2),AR7) | AU7: =IF((((AR7+AS7)/2)+(C7/(DATOS!$B$14*((AR7+AS7)/2)))^2/(2*9.81)+B7-(E6+(C6/(DATOS!$B$14*E6))^2/(2*9.81)+B6+0.5*(((DATOS!$B$27*C6/(DATOS!$B$14*E6))^2/((DATOS!$B$14*E6)/(DATOS!$B$14+2*E6))^(4/3))+((DATOS!$B$27*C7/(DATOS!$B$14*((AR7+AS7)/2)))^2/((DATOS!$B$14*((AR7+AS7)/2))/(DATOS!$B$14+2*((AR7+AS7)/2)))^(4/3)))*(A6-A7)))<0,AS7,((AR7+AS7)/2)) | AV7: =IF((((AT7+AU7)/2)+(C7/(DATOS!$B$14*((AT7+AU7)/2)))^2/(2*9.81)+B7-(E6+(C6/(DATOS!$B$14*E6))^2/(2*9.81)+B6+0.5*(((DATOS!$B$27*C6/(DATOS!$B$14*E6))^2/((DATOS!$B$14*E6)/(DATOS!$B$14+2*E6))^(4/3))+((DATOS!$B$27*C7/(DATOS!$B$14*((AT7+AU7)/2)))^2/((DATOS!$B$14*((AT7+AU7)/2))/(DATOS!$B$14+2*((AT7+AU7)/2)))^(4/3)))*(A6-A7)))<0,((AT7+AU7)/2),AT7) | AW7: =IF((((AT7+AU7)/2)+(C7/(DATOS!$B$14*((AT7+AU7)/2)))^2/(2*9.81)+B7-(E6+(C6/(DATOS!$B$14*E6))^2/(2*9.81)+B6+0.5*(((DATOS!$B$27*C6/(DATOS!$B$14*E6))^2/((DATOS!$B$14*E6)/(DATOS!$B$14+2*E6))^(4/3))+((DATOS!$B$27*C7/(DATOS!$B$14*((AT7+AU7)/2)))^2/((DATOS!$B$14*((AT7+AU7)/2))/(DATOS!$B$14+2*((AT7+AU7)/2)))^(4/3)))*(A6-A7)))<0,AU7,((AT7+AU7)/2)) | AX7: =IF((((AV7+AW7)/2)+(C7/(DATOS!$B$14*((AV7+AW7)/2)))^2/(2*9.81)+B7-(E6+(C6/(DATOS!$B$14*E6))^2/(2*9.81)+B6+0.5*(((DATOS!$B$27*C6/(DATOS!$B$14*E6))^2/((DATOS!$B$14*E6)/(DATOS!$B$14+2*E6))^(4/3))+((DATOS!$B$27*C7/(DATOS!$B$14*((AV7+AW7)/2)))^2/((DATOS!$B$14*((AV7+AW7)/2))/(DATOS!$B$14+2*((AV7+AW7)/2)))^(4/3)))*(A6-A7)))<0,((AV7+AW7)/2),AV7) | AY7: =IF((((AV7+AW7)/2)+(C7/(DATOS!$B$14*((AV7+AW7)/2)))^2/(2*9.81)+B7-(E6+(C6/(DATOS!$B$14*E6))^2/(2*9.81)+B6+0.5*(((DATOS!$B$27*C6/(DATOS!$B$14*E6))^2/((DATOS!$B$14*E6)/(DATOS!$B$14+2*E6))^(4/3))+((DATOS!$B$27*C7/(DATOS!$B$14*((AV7+AW7)/2)))^2/((DATOS!$B$14*((AV7+AW7)/2))/(DATOS!$B$14+2*((AV7+AW7)/2)))^(4/3)))*(A6-A7)))<0,AW7,((AV7+AW7)/2)) | AZ7: =IF((((AX7+AY7)/2)+(C7/(DATOS!$B$14*((AX7+AY7)/2)))^2/(2*9.81)+B7-(E6+(C6/(DATOS!$B$14*E6))^2/(2*9.81)+B6+0.5*(((DATOS!$B$27*C6/(DATOS!$B$14*E6))^2/((DATOS!$B$14*E6)/(DATOS!$B$14+2*E6))^(4/3))+((DATOS!$B$27*C7/(DATOS!$B$14*((AX7+AY7)/2)))^2/((DATOS!$B$14*((AX7+AY7)/2))/(DATOS!$B$14+2*((AX7+AY7)/2)))^(4/3)))*(A6-A7)))<0,((AX7+AY7)/2),AX7) | BA7: =IF((((AX7+AY7)/2)+(C7/(DATOS!$B$14*((AX7+AY7)/2)))^2/(2*9.81)+B7-(E6+(C6/(DATOS!$B$14*E6))^2/(2*9.81)+B6+0.5*(((DATOS!$B$27*C6/(DATOS!$B$14*E6))^2/((DATOS!$B$14*E6)/(DATOS!$B$14+2*E6))^(4/3))+((DATOS!$B$27*C7/(DATOS!$B$14*((AX7+AY7)/2)))^2/((DATOS!$B$14*((AX7+AY7)/2))/(DATOS!$B$14+2*((AX7+AY7)/2)))^(4/3)))*(A6-A7)))<0,AY7,((AX7+AY7)/2)) | BB7: =IF((((AZ7+BA7)/2)+(C7/(DATOS!$B$14*((AZ7+BA7)/2)))^2/(2*9.81)+B7-(E6+(C6/(DATOS!$B$14*E6))^2/(2*9.81)+B6+0.5*(((DATOS!$B$27*C6/(DATOS!$B$14*E6))^2/((DATOS!$B$14*E6)/(DATOS!$B$14+2*E6))^(4/3))+((DATOS!$B$27*C7/(DATOS!$B$14*((AZ7+BA7)/2)))^2/((DATOS!$B$14*((AZ7+BA7)/2))/(DATOS!$B$14+2*((AZ7+BA7)/2)))^(4/3)))*(A6-A7)))<0,((AZ7+BA7)/2),AZ7) | BC7: =IF((((AZ7+BA7)/2)+(C7/(DATOS!$B$14*((AZ7+BA7)/2)))^2/(2*9.81)+B7-(E6+(C6/(DATOS!$B$14*E6))^2/(2*9.81)+B6+0.5*(((DATOS!$B$27*C6/(DATOS!$B$14*E6))^2/((DATOS!$B$14*E6)/(DATOS!$B$14+2*E6))^(4/3))+((DATOS!$B$27*C7/(DATOS!$B$14*((AZ7+BA7)/2)))^2/((DATOS!$B$14*((AZ7+BA7)/2))/(DATOS!$B$14+2*((AZ7+BA7)/2)))^(4/3)))*(A6-A7)))<0,BA7,((AZ7+BA7)/2)) | BD7: =IF((((BB7+BC7)/2)+(C7/(DATOS!$B$14*((BB7+BC7)/2)))^2/(2*9.81)+B7-(E6+(C6/(DATOS!$B$14*E6))^2/(2*9.81)+B6+0.5*(((DATOS!$B$27*C6/(DATOS!$B$14*E6))^2/((DATOS!$B$14*E6)/(DATOS!$B$14+2*E6))^(4/3))+((DATOS!$B$27*C7/(DATOS!$B$14*((BB7+BC7)/2)))^2/((DATOS!$B$14*((BB7+BC7)/2))/(DATOS!$B$14+2*((BB7+BC7)/2)))^(4/3)))*(A6-A7)))<0,((BB7+BC7)/2),BB7) | BE7: =IF((((BB7+BC7)/2)+(C7/(DATOS!$B$14*((BB7+BC7)/2)))^2/(2*9.81)+B7-(E6+(C6/(DATOS!$B$14*E6))^2/(2*9.81)+B6+0.5*(((DATOS!$B$27*C6/(DATOS!$B$14*E6))^2/((DATOS!$B$14*E6)/(DATOS!$B$14+2*E6))^(4/3))+((DATOS!$B$27*C7/(DATOS!$B$14*((BB7+BC7)/2)))^2/((DATOS!$B$14*((BB7+BC7)/2))/(DATOS!$B$14+2*((BB7+BC7)/2)))^(4/3)))*(A6-A7)))<0,BC7,((BB7+BC7)/2)) | BF7: =IF((((BD7+BE7)/2)+(C7/(DATOS!$B$14*((BD7+BE7)/2)))^2/(2*9.81)+B7-(E6+(C6/(DATOS!$B$14*E6))^2/(2*9.81)+B6+0.5*(((DATOS!$B$27*C6/(DATOS!$B$14*E6))^2/((DATOS!$B$14*E6)/(DATOS!$B$14+2*E6))^(4/3))+((DATOS!$B$27*C7/(DATOS!$B$14*((BD7+BE7)/2)))^2/((DATOS!$B$14*((BD7+BE7)/2))/(DATOS!$B$14+2*((BD7+BE7)/2)))^(4/3)))*(A6-A7)))<0,((BD7+BE7)/2),BD7) | BG7: =IF((((BD7+BE7)/2)+(C7/(DATOS!$B$14*((BD7+BE7)/2)))^2/(2*9.81)+B7-(E6+(C6/(DATOS!$B$14*E6))^2/(2*9.81)+B6+0.5*(((DATOS!$B$27*C6/(DATOS!$B$14*E6))^2/((DATOS!$B$14*E6)/(DATOS!$B$14+2*E6))^(4/3))+((DATOS!$B$27*C7/(DATOS!$B$14*((BD7+BE7)/2)))^2/((DATOS!$B$14*((BD7+BE7)/2))/(DATOS!$B$14+2*((BD7+BE7)/2)))^(4/3)))*(A6-A7)))<0,BE7,((BD7+BE7)/2)) | BH7: =IF((((BF7+BG7)/2)+(C7/(DATOS!$B$14*((BF7+BG7)/2)))^2/(2*9.81)+B7-(E6+(C6/(DATOS!$B$14*E6))^2/(2*9.81)+B6+0.5*(((DATOS!$B$27*C6/(DATOS!$B$14*E6))^2/((DATOS!$B$14*E6)/(DATOS!$B$14+2*E6))^(4/3))+((DATOS!$B$27*C7/(DATOS!$B$14*((BF7+BG7)/2)))^2/((DATOS!$B$14*((BF7+BG7)/2))/(DATOS!$B$14+2*((BF7+BG7)/2)))^(4/3)))*(A6-A7)))<0,((BF7+BG7)/2),BF7) | BI7: =IF((((BF7+BG7)/2)+(C7/(DATOS!$B$14*((BF7+BG7)/2)))^2/(2*9.81)+B7-(E6+(C6/(DATOS!$B$14*E6))^2/(2*9.81)+B6+0.5*(((DATOS!$B$27*C6/(DATOS!$B$14*E6))^2/((DATOS!$B$14*E6)/(DATOS!$B$14+2*E6))^(4/3))+((DATOS!$B$27*C7/(DATOS!$B$14*((BF7+BG7)/2)))^2/((DATOS!$B$14*((BF7+BG7)/2))/(DATOS!$B$14+2*((BF7+BG7)/2)))^(4/3)))*(A6-A7)))<0,BG7,((BF7+BG7)/2)) | BJ7: =IF((((BH7+BI7)/2)+(C7/(DATOS!$B$14*((BH7+BI7)/2)))^2/(2*9.81)+B7-(E6+(C6/(DATOS!$B$14*E6))^2/(2*9.81)+B6+0.5*(((DATOS!$B$27*C6/(DATOS!$B$14*E6))^2/((DATOS!$B$14*E6)/(DATOS!$B$14+2*E6))^(4/3))+((DATOS!$B$27*C7/(DATOS!$B$14*((BH7+BI7)/2)))^2/((DATOS!$B$14*((BH7+BI7)/2))/(DATOS!$B$14+2*((BH7+BI7)/2)))^(4/3)))*(A6-A7)))<0,((BH7+BI7)/2),BH7) | BK7: =IF((((BH7+BI7)/2)+(C7/(DATOS!$B$14*((BH7+BI7)/2)))^2/(2*9.81)+B7-(E6+(C6/(DATOS!$B$14*E6))^2/(2*9.81)+B6+0.5*(((DATOS!$B$27*C6/(DATOS!$B$14*E6))^2/((DATOS!$B$14*E6)/(DATOS!$B$14+2*E6))^(4/3))+((DATOS!$B$27*C7/(DATOS!$B$14*((BH7+BI7)/2)))^2/((DATOS!$B$14*((BH7+BI7)/2))/(DATOS!$B$14+2*((BH7+BI7)/2)))^(4/3)))*(A6-A7)))<0,BI7,((BH7+BI7)/2)) | BL7: =IF((((BJ7+BK7)/2)+(C7/(DATOS!$B$14*((BJ7+BK7)/2)))^2/(2*9.81)+B7-(E6+(C6/(DATOS!$B$14*E6))^2/(2*9.81)+B6+0.5*(((DATOS!$B$27*C6/(DATOS!$B$14*E6))^2/((DATOS!$B$14*E6)/(DATOS!$B$14+2*E6))^(4/3))+((DATOS!$B$27*C7/(DATOS!$B$14*((BJ7+BK7)/2)))^2/((DATOS!$B$14*((BJ7+BK7)/2))/(DATOS!$B$14+2*((BJ7+BK7)/2)))^(4/3)))*(A6-A7)))<0,((BJ7+BK7)/2),BJ7) | BM7: =IF((((BJ7+BK7)/2)+(C7/(DATOS!$B$14*((BJ7+BK7)/2)))^2/(2*9.81)+B7-(E6+(C6/(DATOS!$B$14*E6))^2/(2*9.81)+B6+0.5*(((DATOS!$B$27*C6/(DATOS!$B$14*E6))^2/((DATOS!$B$14*E6)/(DATOS!$B$14+2*E6))^(4/3))+((DATOS!$B$27*C7/(DATOS!$B$14*((BJ7+BK7)/2)))^2/((DATOS!$B$14*((BJ7+BK7)/2))/(DATOS!$B$14+2*((BJ7+BK7)/2)))^(4/3)))*(A6-A7)))<0,BK7,((BJ7+BK7)/2)) | BN7: =IF((((BL7+BM7)/2)+(C7/(DATOS!$B$14*((BL7+BM7)/2)))^2/(2*9.81)+B7-(E6+(C6/(DATOS!$B$14*E6))^2/(2*9.81)+B6+0.5*(((DATOS!$B$27*C6/(DATOS!$B$14*E6))^2/((DATOS!$B$14*E6)/(DATOS!$B$14+2*E6))^(4/3))+((DATOS!$B$27*C7/(DATOS!$B$14*((BL7+BM7)/2)))^2/((DATOS!$B$14*((BL7+BM7)/2))/(DATOS!$B$14+2*((BL7+BM7)/2)))^(4/3)))*(A6-A7)))<0,((BL7+BM7)/2),BL7) | BO7: =IF((((BL7+BM7)/2)+(C7/(DATOS!$B$14*((BL7+BM7)/2)))^2/(2*9.81)+B7-(E6+(C6/(DATOS!$B$14*E6))^2/(2*9.81)+B6+0.5*(((DATOS!$B$27*C6/(DATOS!$B$14*E6))^2/((DATOS!$B$14*E6)/(DATOS!$B$14+2*E6))^(4/3))+((DATOS!$B$27*C7/(DATOS!$B$14*((BL7+BM7)/2)))^2/((DATOS!$B$14*((BL7+BM7)/2))/(DATOS!$B$14+2*((BL7+BM7)/2)))^(4/3)))*(A6-A7)))<0,BM7,((BL7+BM7)/2)) | BP7: =IF((((BN7+BO7)/2)+(C7/(DATOS!$B$14*((BN7+BO7)/2)))^2/(2*9.81)+B7-(E6+(C6/(DATOS!$B$14*E6))^2/(2*9.81)+B6+0.5*(((DATOS!$B$27*C6/(DATOS!$B$14*E6))^2/((DATOS!$B$14*E6)/(DATOS!$B$14+2*E6))^(4/3))+((DATOS!$B$27*C7/(DATOS!$B$14*((BN7+BO7)/2)))^2/((DATOS!$B$14*((BN7+BO7)/2))/(DATOS!$B$14+2*((BN7+BO7)/2)))^(4/3)))*(A6-A7)))<0,((BN7+BO7)/2),BN7) | BQ7: =IF((((BN7+BO7)/2)+(C7/(DATOS!$B$14*((BN7+BO7)/2)))^2/(2*9.81)+B7-(E6+(C6/(DATOS!$B$14*E6))^2/(2*9.81)+B6+0.5*(((DATOS!$B$27*C6/(DATOS!$B$14*E6))^2/((DATOS!$B$14*E6)/(DATOS!$B$14+2*E6))^(4/3))+((DATOS!$B$27*C7/(DATOS!$B$14*((BN7+BO7)/2)))^2/((DATOS!$B$14*((BN7+BO7)/2))/(DATOS!$B$14+2*((BN7+BO7)/2)))^(4/3)))*(A6-A7)))<0,BO7,((BN7+BO7)/2)) | BR7: =IF((((BP7+BQ7)/2)+(C7/(DATOS!$B$14*((BP7+BQ7)/2)))^2/(2*9.81)+B7-(E6+(C6/(DATOS!$B$14*E6))^2/(2*9.81)+B6+0.5*(((DATOS!$B$27*C6/(DATOS!$B$14*E6))^2/((DATOS!$B$14*E6)/(DATOS!$B$14+2*E6))^(4/3))+((DATOS!$B$27*C7/(DATOS!$B$14*((BP7+BQ7)/2)))^2/((DATOS!$B$14*((BP7+BQ7)/2))/(DATOS!$B$14+2*((BP7+BQ7)/2)))^(4/3)))*(A6-A7)))<0,((BP7+BQ7)/2),BP7) | BS7: =IF((((BP7+BQ7)/2)+(C7/(DATOS!$B$14*((BP7+BQ7)/2)))^2/(2*9.81)+B7-(E6+(C6/(DATOS!$B$14*E6))^2/(2*9.81)+B6+0.5*(((DATOS!$B$27*C6/(DATOS!$B$14*E6))^2/((DATOS!$B$14*E6)/(DATOS!$B$14+2*E6))^(4/3))+((DATOS!$B$27*C7/(DATOS!$B$14*((BP7+BQ7)/2)))^2/((DATOS!$B$14*((BP7+BQ7)/2))/(DATOS!$B$14+2*((BP7+BQ7)/2)))^(4/3)))*(A6-A7)))<0,BQ7,((BP7+BQ7)/2)) | BT7: =IF((((BR7+BS7)/2)+(C7/(DATOS!$B$14*((BR7+BS7)/2)))^2/(2*9.81)+B7-(E6+(C6/(DATOS!$B$14*E6))^2/(2*9.81)+B6+0.5*(((DATOS!$B$27*C6/(DATOS!$B$14*E6))^2/((DATOS!$B$14*E6)/(DATOS!$B$14+2*E6))^(4/3))+((DATOS!$B$27*C7/(DATOS!$B$14*((BR7+BS7)/2)))^2/((DATOS!$B$14*((BR7+BS7)/2))/(DATOS!$B$14+2*((BR7+BS7)/2)))^(4/3)))*(A6-A7)))<0,((BR7+BS7)/2),BR7) | BU7: =IF((((BR7+BS7)/2)+(C7/(DATOS!$B$14*((BR7+BS7)/2)))^2/(2*9.81)+B7-(E6+(C6/(DATOS!$B$14*E6))^2/(2*9.81)+B6+0.5*(((DATOS!$B$27*C6/(DATOS!$B$14*E6))^2/((DATOS!$B$14*E6)/(DATOS!$B$14+2*E6))^(4/3))+((DATOS!$B$27*C7/(DATOS!$B$14*((BR7+BS7)/2)))^2/((DATOS!$B$14*((BR7+BS7)/2))/(DATOS!$B$14+2*((BR7+BS7)/2)))^(4/3)))*(A6-A7)))<0,BS7,((BR7+BS7)/2))
