Workbook

Sheet RESUMEN
A1: RESUMEN DE METRADOS - COLECTOR PLUVIAL CAR MUJERES
A2: CAR Mujeres (CUI 2717013) - Colector pluvial frontal b=1.50 m, preparado para CAR Varones y Hogar de Refugio - Morales, San Martin
A4: ITEM | B4: DESCRIPCION | C4: UND | D4: METRADO | E4: HOJA DE SUSTENTO
A5: 01 | B5: OBRAS PRELIMINARES
A6: 01.01 | B6: Trazo, nivelacion y replanteo | C6: m2 | D6: ='01 PRELIMINARES'!$I$84 | E6: 01 PRELIMINARES
A7: 02 | B7: MOVIMIENTO DE TIERRAS
A8: 02.01 | B8: Excavacion de zanja | C8: m3 | D8: ='02 MOV. TIERRAS'!$I$84 | E8: 02 MOV. TIERRAS
A9: 02.02 | B9: Refine, nivelacion y compactacion de fondo | C9: m2 | D9: ='02 MOV. TIERRAS'!$I$166 | E9: 02 MOV. TIERRAS
A10: 02.03 | B10: Relleno compactado con material propio | C10: m3 | D10: ='02 MOV. TIERRAS'!$I$247 | E10: 02 MOV. TIERRAS
A11: 02.04 | B11: Eliminacion de material excedente D=5 km | C11: m3 | D11: ='02 MOV. TIERRAS'!$I$251 | E11: 02 MOV. TIERRAS
A12: 03 | B12: CONCRETO SIMPLE
A13: 03.01 | B13: Solado f'c=100 kg/cm2 e=0.05 m | C13: m2 | D13: ='03 CONCRETO SIMPLE'!$I$84 | E13: 03 CONCRETO SIMPLE
A14: 03.02 | B14: Afirmado compactado e=0.10 m bajo emboquillado | C14: m2 | D14: ='03 CONCRETO SIMPLE'!$I$88 | E14: 03 CONCRETO SIMPLE
A15: 03.03 | B15: Una de concreto ciclopeo f'c=140 + 30% P.M. | C15: m3 | D15: ='03 CONCRETO SIMPLE'!$I$92 | E15: 03 CONCRETO SIMPLE
A16: 04 | B16: CONCRETO ARMADO - COLECTOR
A17: 04.01 | B17: Concreto f'c=210 - losa de fondo | C17: m3 | D17: ='04 CONCRETO ARMADO'!$I$82 | E17: 04 CONCRETO ARMADO
A18: 04.02 | B18: Concreto f'c=210 - muros | C18: m3 | D18: ='04 CONCRETO ARMADO'!$I$163 | E18: 04 CONCRETO ARMADO
A19: 04.03 | B19: Concreto f'c=210 - losa superior (incluye borde engrosado de registros) | C19: m3 | D19: ='04 CONCRETO ARMADO'!$I$246 | E19: 04 CONCRETO ARMADO
A20: 04.04 | B20: Encofrado y desencofrado normal | C20: m2 | D20: ='04 CONCRETO ARMADO'!$I$327 | E20: 04 CONCRETO ARMADO
A21: 04.05 | B21: Acero de refuerzo fy=4200 - colector | C21: kg | D21: ='04 CONCRETO ARMADO'!$I$482 | E21: 04 CONCRETO ARMADO
A22: 04.06 | B22: Acabado frotachado y brunado de losa superior | C22: m2 | D22: ='04 CONCRETO ARMADO'!$I$487 | E22: 04 CONCRETO ARMADO
A23: 05 | B23: REGISTROS DE LIMPIEZA
A24: 05.01 | B24: Contramarco metalico L 2"x2"x3/16" con anclajes | C24: und | D24: ='05 REGISTROS'!$I$7 | E24: 05 REGISTROS
A25: 05.02 | B25: Marco metalico de tapa L 1 1/2"x1 1/2"x1/8" | C25: und | D25: ='05 REGISTROS'!$I$11 | E25: 05 REGISTROS
A26: 05.03 | B26: Angulos metalicos para marco y contramarco (peso) | C26: kg | D26: ='05 REGISTROS'!$I$16 | E26: 05 REGISTROS
A27: 05.04 | B27: Tapa de concreto armado 0.68x0.68x0.08 | C27: und | D27: ='05 REGISTROS'!$I$20 | E27: 05 REGISTROS
A28: 05.05 | B28: Concreto f'c=210 en tapas | C28: m3 | D28: ='05 REGISTROS'!$I$24 | E28: 05 REGISTROS
A29: 05.06 | B29: Acero de refuerzo en bordes, tapas y anclajes | C29: kg | D29: ='05 REGISTROS'!$I$31 | E29: 05 REGISTROS
A30: 05.07 | B30: Pintura anticorrosiva y esmalte en angulos | C30: m2 | D30: ='05 REGISTROS'!$I$36 | E30: 05 REGISTROS
A31: 06 | B31: ESTRUCTURA DE SALIDA CON DOS ALEROS
A32: 06.01 | B32: Concreto f'c=210 - aleros | C32: m3 | D32: ='06 SALIDA'!$I$8 | E32: 06 SALIDA
A33: 06.02 | B33: Encofrado y desencofrado - aleros | C33: m2 | D33: ='06 SALIDA'!$I$14 | E33: 06 SALIDA
A34: 06.03 | B34: Acero de refuerzo fy=4200 - aleros | C34: kg | D34: ='06 SALIDA'!$I$20 | E34: 06 SALIDA
A35: 06.04 | B35: Emboquillado de piedra e=0.20 con concreto f'c=140 | C35: m2 | D35: ='06 SALIDA'!$I$24 | E35: 06 SALIDA
A36: 07 | B36: JUNTAS
A37: 07.01 | B37: Junta de dilatacion e=1" con sello elastomerico | C37: m | D37: ='07 JUNTAS Y EMPALMES'!$I$8 | E37: 07 JUNTAS Y EMPALMES
A38: 07.02 | B38: Junta e=1" con tecnopor entre colector y piso adyacente | C38: m | D38: ='07 JUNTAS Y EMPALMES'!$I$12 | E38: 07 JUNTAS Y EMPALMES
A39: 08 | B39: EMPALMES
A40: 08.01 | B40: Empalme de cuneta al colector | C40: und | D40: ='07 JUNTAS Y EMPALMES'!$I$16 | E40: 07 JUNTAS Y EMPALMES
B42: ACERO TOTAL (colector + registros + aleros) | C42: kg | D42: ='04 CONCRETO ARMADO'!$I$482+'05 REGISTROS'!$I$31+'06 SALIDA'!$I$20
...

Sheet DATOS
A1: DATOS DEL METRADO
A2: CAR Mujeres (CUI 2717013) - Colector pluvial frontal b=1.50 m, preparado para CAR Varones y Hogar de Refugio - Morales, San Martin
A4: PARAMETRO | B4: VALOR | C4: UND | D4: FUENTE
A5: Ancho interior b | B5: 1.5 | C5: m | D5: Memoria de calculo
A6: Cota de fondo inicial | B6: 258.72 | C6: msnm | D6: Eje 02
A7: Cota de fondo en la salida | B7: 258.3 | C7: msnm
A8: Longitud del colector | B8: 139.08 | C8: m | D8: Plano DP-01
A9: Pendiente | B9: =(B6-B7)/B8 | C9: m/m
A10: NPT de vereda (losa superior) | B10: 259.25 | C10: msnm | D10: Arquitectura
A11: Progresiva fin de tramo en vereda | B11: 78.42 | C11: m
A12: Altura interior tramo final | B12: 0.6 | C12: m
A13: Cruce de camiones: inicio | B13: 54 | C13: m
A14: Cruce de camiones: fin | B14: 60 | C14: m
A15: Cruce de autos 1: inicio | B15: 2.74 | C15: m | D15: Rampa estacionamiento 01
A16: Cruce de autos 1: fin | B16: 18.45 | C16: m
A17: Cruce de autos 2: inicio | B17: 35.04 | C17: m | D17: Rampa estacionamiento 02
A18: Cruce de autos 2: fin | B18: 51.86 | C18: m
A19: Numero de registros de limpieza | B19: 15 | C19: und | D19: Plano DP-01 (R-01 a R-15)
A20: Numero de juntas de dilatacion | B20: 33 | C20: und | D20: Cada 4.00 m + 2 en el cruce de camiones
A21: Factor de esponjamiento | B21: 1.25 | C21: - | D21: Suelo comun
A22: Peso acero 3/8" | B22: 0.56 | C22: kg/m
A23: Peso acero 1/2" | B23: 0.994 | C23: kg/m
A24: Peso angulo 2"x2"x3/16" (contramarco) | B24: 3.63 | C24: kg/m | D24: Tabla comercial
A25: Peso angulo 1 1/2"x1 1/2"x1/8" (marco de tapa) | B25: 1.83 | C25: kg/m | D25: Tabla comercial
A26: Salida: longitud de alero (inclinado) | B26: 1 | C26: m | D26: Plano DP-07
A27: Salida: espesor de alero | B27: 0.15 | C27: m
A28: Salida: altura de alero en el cabezal (sobre el piso) | B28: 0.7 | C28: m
A29: Salida: altura de alero en el extremo | B29: 0.45 | C29: m
A30: Salida: zapata de alero (ancho x alto) | B30: 0.45 | C30: m | D30: alto 0.20
A31: Salida: avance de aleros en planta (L x cos45) | B31: 0.707 | C31: m
A32: Salida: ancho interior al final de aleros | B32: 2.914 | C32: m
A33: Registro: hueco superior (rebaje) | B33: 0.7 | C33: m | D33: DP-06B
A34: Registro: luz libre | B34: 0.6 | C34: m | D34: DP-06B
A35: Tapa: lado | B35: 0.68 | C35: m | D35: DP-06B
A36: Tapa: espesor | B36: 0.08 | C36: m
A37: Empalmes de cuneta (Ejes 02, 07, 10, 12) | B37: 4 | C37: und | D37: DP-06B

Sheet TRAMOS
A1: CALCULO POR TRAMOS (secciones medias)
A2: CAR Mujeres (CUI 2717013) - Colector pluvial frontal b=1.50 m, preparado para CAR Varones y Hogar de Refugio - Morales, San Martin
A4: PROG. INICIO | B4: PROG. FIN | C4: LONGITUD (m) | D4: PROG. MEDIA | E4: ZONA | F4: e MURO | G4: e LOSA FONDO | H4: e LOSA SUP. | I4: ALTURA INT. h | J4: TERRENO NATURAL (TIN) | K4: ANCHO EXTERIOR | L4: CONCRETO LOSA FONDO (m3) | M4: CONCRETO MUROS (m3) | N4: CONCRETO LOSA SUP. (m3) | O4: EXCAVACION (m3) | P4: RELLENO (m3) | Q4: SOLADO (m2) | R4: ENCOFRADO (m2) | S4: ACERO MARCOS (kg) | T4: ACERO LONGIT. (kg) | U4: TRAZO (m2) | V4: N. MARCOS | W4: LONG. MARCO (m) | X4: N. BARRAS LONG. | Y4: DIAM. MARCO
A5: 0 | B5: 2 | C5: =B5-A5 | D5: =(A5+B5)/2 | E5: =IF(AND(D5>=DATOS!$B$13,D5<DATOS!$B$14),"CAMION",IF(OR(AND(D5>=DATOS!$B$15,D5<=DATOS!$B$16),AND(D5>=DATOS!$B$17,D5<=DATOS!$B$18)),"AUTOS","NORMAL")) | F5: =IF(E5="CAMION",0.15,0.10) | G5: =IF(E5="CAMION",0.20,0.10) | H5: =IF(D5>9999,0,IF(E5="CAMION",0.20,0.10)) | I5: =IF(D5<=DATOS!$B$11,DATOS!$B$10-H5-(DATOS!$B$6-DATOS!$B$9*D5),DATOS!$B$12) | J5: 259.654 | K5: =DATOS!$B$5+2*F5 | L5: =K5*G5*C5 | M5: =2*F5*I5*C5 | N5: =K5*H5*C5 | O5: =(K5+0.10)*(IF(D5<=DATOS!$B$11,DATOS!$B$10,J5)-((DATOS!$B$6-DATOS!$B$9*D5)-G5-0.05))*C5 | P5: =(0.10*(IF(D5<=DATOS!$B$11,DATOS!$B$10,J5)-((DATOS!$B$6-DATOS!$B$9*D5)-G5-0.05))+IF(D5>9999,MAX(0,((DATOS!$B$6-DATOS!$B$9*D5)+I5+H5)-J5)*(0.20+0.75*MAX(0,((DATOS!$B$6-DATOS!$B$9*D5)+I5+H5)-J5)),0))*C5 | Q5: =K5*C5 | R5: =(2*I5+IF(D5>9999,0,DATOS!$B$5)+(I5+G5+H5)+IF(D5>9999,MAX(0,((DATOS!$B$6-DATOS!$B$9*D5)+I5+H5)-J5),0))*C5 | S5: =IF(E5="CAMION",C5/0.15*((2*(K5-0.09)+2*(I5+G5+H5-0.09)+0.5)+(2*(DATOS!$B$5+0.09)+2*(I5+0.09)+0.5))*DATOS!$B$23,C5/IF(E5="AUTOS",0.15,0.20)*IF(D5>9999,(DATOS!$B$5+F5)+2*(I5+G5/2)+0.20,2*(DATOS!$B$5+F5)+2*(I5+(G5+H5)/2)+0.40)*DATOS!$B$22) | T5: =IF(E5="CAMION",((ROUNDUP((K5-0.09)/0.2,0)+1)*2+2*MAX(ROUNDUP((I5+0.31)/0.2,0)-1,0)+(ROUNDUP((DATOS!$B$5+0.09)/0.2,0)+1)*2+2*MAX(ROUNDUP((I5+0.09)/0.2,0)-1,0)),IF(D5>9999,8+2*MAX(ROUNDUP((I5+0.05)/0.25,0),1),16+2*MAX(ROUNDUP((I5+0.10)/0.25,0)-1,0)))*C5*(1+0.40/9)*DATOS!$B$22 | U5: =(K5+0.10)*C5 | V5: =IF(E5="CAMION",2*C5/0.15,C5/IF(E5="AUTOS",0.15,0.20)) | W5: =IF(E5="CAMION",((2*(K5-0.09)+2*(I5+G5+H5-0.09)+0.5)+(2*(DATOS!$B$5+0.09)+2*(I5+0.09)+0.5))/2,IF(D5>9999,(DATOS!$B$5+F5)+2*(I5+G5/2)+0.20,2*(DATOS!$B$5+F5)+2*(I5+(G5+H5)/2)+0.40)) | X5: =IF(E5="CAMION",((ROUNDUP((K5-0.09)/0.2,0)+1)*2+2*MAX(ROUNDUP((I5+0.31)/0.2,0)-1,0)+(ROUNDUP((DATOS!$B$5+0.09)/0.2,0)+1)*2+2*MAX(ROUNDUP((I5+0.09)/0.2,0)-1,0)),IF(D5>9999,8+2*MAX(ROUNDUP((I5+0.05)/0.25,0),1),16+2*MAX(ROUNDUP((I5+0.10)/0.25,0)-1,0))) | Y5: =IF(E5="CAMION","1/2","3/8")
A6: 2 | B6: 2.74 | C6: =B6-A6 | D6: =(A6+B6)/2 | E6: =IF(AND(D6>=DATOS!$B$13,D6<DATOS!$B$14),"CAMION",IF(OR(AND(D6>=DATOS!$B$15,D6<=DATOS!$B$16),AND(D6>=DATOS!$B$17,D6<=DATOS!$B$18)),"AUTOS","NORMAL")) | F6: =IF(E6="CAMION",0.15,0.10) | G6: =IF(E6="CAMION",0.20,0.10) | H6: =IF(D6>9999,0,IF(E6="CAMION",0.20,0.10)) | I6: =IF(D6<=DATOS!$B$11,DATOS!$B$10-H6-(DATOS!$B$6-DATOS!$B$9*D6),DATOS!$B$12) | J6: 259.611 | K6: =DATOS!$B$5+2*F6 | L6: =K6*G6*C6 | M6: =2*F6*I6*C6 | N6: =K6*H6*C6 | O6: =(K6+0.10)*(IF(D6<=DATOS!$B$11,DATOS!$B$10,J6)-((DATOS!$B$6-DATOS!$B$9*D6)-G6-0.05))*C6 | P6: =(0.10*(IF(D6<=DATOS!$B$11,DATOS!$B$10,J6)-((DATOS!$B$6-DATOS!$B$9*D6)-G6-0.05))+IF(D6>9999,MAX(0,((DATOS!$B$6-DATOS!$B$9*D6)+I6+H6)-J6)*(0.20+0.75*MAX(0,((DATOS!$B$6-DATOS!$B$9*D6)+I6+H6)-J6)),0))*C6 | Q6: =K6*C6 | R6: =(2*I6+IF(D6>9999,0,DATOS!$B$5)+(I6+G6+H6)+IF(D6>9999,MAX(0,((DATOS!$B$6-DATOS!$B$9*D6)+I6+H6)-J6),0))*C6 | S6: =IF(E6="CAMION",C6/0.15*((2*(K6-0.09)+2*(I6+G6+H6-0.09)+0.5)+(2*(DATOS!$B$5+0.09)+2*(I6+0.09)+0.5))*DATOS!$B$23,C6/IF(E6="AUTOS",0.15,0.20)*IF(D6>9999,(DATOS!$B$5+F6)+2*(I6+G6/2)+0.20,2*(DATOS!$B$5+F6)+2*(I6+(G6+H6)/2)+0.40)*DATOS!$B$22) | T6: =IF(E6="CAMION",((ROUNDUP((K6-0.09)/0.2,0)+1)*2+2*MAX(ROUNDUP((I6+0.31)/0.2,0)-1,0)+(ROUNDUP((DATOS!$B$5+0.09)/0.2,0)+1)*2+2*MAX(ROUNDUP((I6+0.09)/0.2,0)-1,0)),IF(D6>9999,8+2*MAX(ROUNDUP((I6+0.05)/0.25,0),1),16+2*MAX(ROUNDUP((I6+0.10)/0.25,0)-1,0)))*C6*(1+0.40/9)*DATOS!$B$22 | U6: =(K6+0.10)*C6 | V6: =IF(E6="CAMION",2*C6/0.15,C6/IF(E6="AUTOS",0.15,0.20)) | W6: =IF(E6="CAMION",((2*(K6-0.09)+2*(I6+G6+H6-0.09)+0.5)+(2*(DATOS!$B$5+0.09)+2*(I6+0.09)+0.5))/2,IF(D6>9999,(DATOS!$B$5+F6)+2*(I6+G6/2)+0.20,2*(DATOS!$B$5+F6)+2*(I6+(G6+H6)/2)+0.40)) | X6: =IF(E6="CAMION",((ROUNDUP((K6-0.09)/0.2,0)+1)*2+2*MAX(ROUNDUP((I6+0.31)/0.2,0)-1,0)+(ROUNDUP((DATOS!$B$5+0.09)/0.2,0)+1)*2+2*MAX(ROUNDUP((I6+0.09)/0.2,0)-1,0)),IF(D6>9999,8+2*MAX(ROUNDUP((I6+0.05)/0.25,0),1),16+2*MAX(ROUNDUP((I6+0.10)/0.25,0)-1,0))) | Y6: =IF(E6="CAMION","1/2","3/8")
A7: 2.74 | B7: 4 | C7: =B7-A7 | D7: =(A7+B7)/2 | E7: =IF(AND(D7>=DATOS!$B$13,D7<DATOS!$B$14),"CAMION",IF(OR(AND(D7>=DATOS!$B$15,D7<=DATOS!$B$16),AND(D7>=DATOS!$B$17,D7<=DATOS!$B$18)),"AUTOS","NORMAL")) | F7: =IF(E7="CAMION",0.15,0.10) | G7: =IF(E7="CAMION",0.20,0.10) | H7: =IF(D7>9999,0,IF(E7="CAMION",0.20,0.10)) | I7: =IF(D7<=DATOS!$B$11,DATOS!$B$10-H7-(DATOS!$B$6-DATOS!$B$9*D7),DATOS!$B$12) | J7: 259.596 | K7: =DATOS!$B$5+2*F7 | L7: =K7*G7*C7 | M7: =2*F7*I7*C7 | N7: =K7*H7*C7 | O7: =(K7+0.10)*(IF(D7<=DATOS!$B$11,DATOS!$B$10,J7)-((DATOS!$B$6-DATOS!$B$9*D7)-G7-0.05))*C7 | P7: =(0.10*(IF(D7<=DATOS!$B$11,DATOS!$B$10,J7)-((DATOS!$B$6-DATOS!$B$9*D7)-G7-0.05))+IF(D7>9999,MAX(0,((DATOS!$B$6-DATOS!$B$9*D7)+I7+H7)-J7)*(0.20+0.75*MAX(0,((DATOS!$B$6-DATOS!$B$9*D7)+I7+H7)-J7)),0))*C7 | Q7: =K7*C7 | R7: =(2*I7+IF(D7>9999,0,DATOS!$B$5)+(I7+G7+H7)+IF(D7>9999,MAX(0,((DATOS!$B$6-DATOS!$B$9*D7)+I7+H7)-J7),0))*C7 | S7: =IF(E7="CAMION",C7/0.15*((2*(K7-0.09)+2*(I7+G7+H7-0.09)+0.5)+(2*(DATOS!$B$5+0.09)+2*(I7+0.09)+0.5))*DATOS!$B$23,C7/IF(E7="AUTOS",0.15,0.20)*IF(D7>9999,(DATOS!$B$5+F7)+2*(I7+G7/2)+0.20,2*(DATOS!$B$5+F7)+2*(I7+(G7+H7)/2)+0.40)*DATOS!$B$22) | T7: =IF(E7="CAMION",((ROUNDUP((K7-0.09)/0.2,0)+1)*2+2*MAX(ROUNDUP((I7+0.31)/0.2,0)-1,0)+(ROUNDUP((DATOS!$B$5+0.09)/0.2,0)+1)*2+2*MAX(ROUNDUP((I7+0.09)/0.2,0)-1,0)),IF(D7>9999,8+2*MAX(ROUNDUP((I7+0.05)/0.25,0),1),16+2*MAX(ROUNDUP((I7+0.10)/0.25,0)-1,0)))*C7*(1+0.40/9)*DATOS!$B$22 | U7: =(K7+0.10)*C7 | V7: =IF(E7="CAMION",2*C7/0.15,C7/IF(E7="AUTOS",0.15,0.20)) | W7: =IF(E7="CAMION",((2*(K7-0.09)+2*(I7+G7+H7-0.09)+0.5)+(2*(DATOS!$B$5+0.09)+2*(I7+0.09)+0.5))/2,IF(D7>9999,(DATOS!$B$5+F7)+2*(I7+G7/2)+0.20,2*(DATOS!$B$5+F7)+2*(I7+(G7+H7)/2)+0.40)) | X7: =IF(E7="CAMION",((ROUNDUP((K7-0.09)/0.2,0)+1)*2+2*MAX(ROUNDUP((I7+0.31)/0.2,0)-1,0)+(ROUNDUP((DATOS!$B$5+0.09)/0.2,0)+1)*2+2*MAX(ROUNDUP((I7+0.09)/0.2,0)-1,0)),IF(D7>9999,8+2*MAX(ROUNDUP((I7+0.05)/0.25,0),1),16+2*MAX(ROUNDUP((I7+0.10)/0.25,0)-1,0))) | Y7: =IF(E7="CAMION","1/2","3/8")
A8: 4 | B8: 6 | C8: =B8-A8 | D8: =(A8+B8)/2 | E8: =IF(AND(D8>=DATOS!$B$13,D8<DATOS!$B$14),"CAMION",IF(OR(AND(D8>=DATOS!$B$15,D8<=DATOS!$B$16),AND(D8>=DATOS!$B$17,D8<=DATOS!$B$18)),"AUTOS","NORMAL")) | F8: =IF(E8="CAMION",0.15,0.10) | G8: =IF(E8="CAMION",0.20,0.10) | H8: =IF(D8>9999,0,IF(E8="CAMION",0.20,0.10)) | I8: =IF(D8<=DATOS!$B$11,DATOS!$B$10-H8-(DATOS!$B$6-DATOS!$B$9*D8),DATOS!$B$12) | J8: 259.594 | K8: =DATOS!$B$5+2*F8 | L8: =K8*G8*C8 | M8: =2*F8*I8*C8 | N8: =K8*H8*C8 | O8: =(K8+0.10)*(IF(D8<=DATOS!$B$11,DATOS!$B$10,J8)-((DATOS!$B$6-DATOS!$B$9*D8)-G8-0.05))*C8 | P8: =(0.10*(IF(D8<=DATOS!$B$11,DATOS!$B$10,J8)-((DATOS!$B$6-DATOS!$B$9*D8)-G8-0.05))+IF(D8>9999,MAX(0,((DATOS!$B$6-DATOS!$B$9*D8)+I8+H8)-J8)*(0.20+0.75*MAX(0,((DATOS!$B$6-DATOS!$B$9*D8)+I8+H8)-J8)),0))*C8 | Q8: =K8*C8 | R8: =(2*I8+IF(D8>9999,0,DATOS!$B$5)+(I8+G8+H8)+IF(D8>9999,MAX(0,((DATOS!$B$6-DATOS!$B$9*D8)+I8+H8)-J8),0))*C8 | S8: =IF(E8="CAMION",C8/0.15*((2*(K8-0.09)+2*(I8+G8+H8-0.09)+0.5)+(2*(DATOS!$B$5+0.09)+2*(I8+0.09)+0.5))*DATOS!$B$23,C8/IF(E8="AUTOS",0.15,0.20)*IF(D8>9999,(DATOS!$B$5+F8)+2*(I8+G8/2)+0.20,2*(DATOS!$B$5+F8)+2*(I8+(G8+H8)/2)+0.40)*DATOS!$B$22) | T8: =IF(E8="CAMION",((ROUNDUP((K8-0.09)/0.2,0)+1)*2+2*MAX(ROUNDUP((I8+0.31)/0.2,0)-1,0)+(ROUNDUP((DATOS!$B$5+0.09)/0.2,0)+1)*2+2*MAX(ROUNDUP((I8+0.09)/0.2,0)-1,0)),IF(D8>9999,8+2*MAX(ROUNDUP((I8+0.05)/0.25,0),1),16+2*MAX(ROUNDUP((I8+0.10)/0.25,0)-1,0)))*C8*(1+0.40/9)*DATOS!$B$22 | U8: =(K8+0.10)*C8 | V8: =IF(E8="CAMION",2*C8/0.15,C8/IF(E8="AUTOS",0.15,0.20)) | W8: =IF(E8="CAMION",((2*(K8-0.09)+2*(I8+G8+H8-0.09)+0.5)+(2*(DATOS!$B$5+0.09)+2*(I8+0.09)+0.5))/2,IF(D8>9999,(DATOS!$B$5+F8)+2*(I8+G8/2)+0.20,2*(DATOS!$B$5+F8)+2*(I8+(G8+H8)/2)+0.40)) | X8: =IF(E8="CAMION",((ROUNDUP((K8-0.09)/0.2,0)+1)*2+2*MAX(ROUNDUP((I8+0.31)/0.2,0)-1,0)+(ROUNDUP((DATOS!$B$5+0.09)/0.2,0)+1)*2+2*MAX(ROUNDUP((I8+0.09)/0.2,0)-1,0)),IF(D8>9999,8+2*MAX(ROUNDUP((I8+0.05)/0.25,0),1),16+2*MAX(ROUNDUP((I8+0.10)/0.25,0)-1,0))) | Y8: =IF(E8="CAMION","1/2","3/8")
A9: 6 | B9: 8 | C9: =B9-A9 | D9: =(A9+B9)/2 | E9: =IF(AND(D9>=DATOS!$B$13,D9<DATOS!$B$14),"CAMION",IF(OR(AND(D9>=DATOS!$B$15,D9<=DATOS!$B$16),AND(D9>=DATOS!$B$17,D9<=DATOS!$B$18)),"AUTOS","NORMAL")) | F9: =IF(E9="CAMION",0.15,0.10) | G9: =IF(E9="CAMION",0.20,0.10) | H9: =IF(D9>9999,0,IF(E9="CAMION",0.20,0.10)) | I9: =IF(D9<=DATOS!$B$11,DATOS!$B$10-H9-(DATOS!$B$6-DATOS!$B$9*D9),DATOS!$B$12) | J9: 259.612 | K9: =DATOS!$B$5+2*F9 | L9: =K9*G9*C9 | M9: =2*F9*I9*C9 | N9: =K9*H9*C9 | O9: =(K9+0.10)*(IF(D9<=DATOS!$B$11,DATOS!$B$10,J9)-((DATOS!$B$6-DATOS!$B$9*D9)-G9-0.05))*C9 | P9: =(0.10*(IF(D9<=DATOS!$B$11,DATOS!$B$10,J9)-((DATOS!$B$6-DATOS!$B$9*D9)-G9-0.05))+IF(D9>9999,MAX(0,((DATOS!$B$6-DATOS!$B$9*D9)+I9+H9)-J9)*(0.20+0.75*MAX(0,((DATOS!$B$6-DATOS!$B$9*D9)+I9+H9)-J9)),0))*C9 | Q9: =K9*C9 | R9: =(2*I9+IF(D9>9999,0,DATOS!$B$5)+(I9+G9+H9)+IF(D9>9999,MAX(0,((DATOS!$B$6-DATOS!$B$9*D9)+I9+H9)-J9),0))*C9 | S9: =IF(E9="CAMION",C9/0.15*((2*(K9-0.09)+2*(I9+G9+H9-0.09)+0.5)+(2*(DATOS!$B$5+0.09)+2*(I9+0.09)+0.5))*DATOS!$B$23,C9/IF(E9="AUTOS",0.15,0.20)*IF(D9>9999,(DATOS!$B$5+F9)+2*(I9+G9/2)+0.20,2*(DATOS!$B$5+F9)+2*(I9+(G9+H9)/2)+0.40)*DATOS!$B$22) | T9: =IF(E9="CAMION",((ROUNDUP((K9-0.09)/0.2,0)+1)*2+2*MAX(ROUNDUP((I9+0.31)/0.2,0)-1,0)+(ROUNDUP((DATOS!$B$5+0.09)/0.2,0)+1)*2+2*MAX(ROUNDUP((I9+0.09)/0.2,0)-1,0)),IF(D9>9999,8+2*MAX(ROUNDUP((I9+0.05)/0.25,0),1),16+2*MAX(ROUNDUP((I9+0.10)/0.25,0)-1,0)))*C9*(1+0.40/9)*DATOS!$B$22 | U9: =(K9+0.10)*C9 | V9: =IF(E9="CAMION",2*C9/0.15,C9/IF(E9="AUTOS",0.15,0.20)) | W9: =IF(E9="CAMION",((2*(K9-0.09)+2*(I9+G9+H9-0.09)+0.5)+(2*(DATOS!$B$5+0.09)+2*(I9+0.09)+0.5))/2,IF(D9>9999,(DATOS!$B$5+F9)+2*(I9+G9/2)+0.20,2*(DATOS!$B$5+F9)+2*(I9+(G9+H9)/2)+0.40)) | X9: =IF(E9="CAMION",((ROUNDUP((K9-0.09)/0.2,0)+1)*2+2*MAX(ROUNDUP((I9+0.31)/0.2,0)-1,0)+(ROUNDUP((DATOS!$B$5+0.09)/0.2,0)+1)*2+2*MAX(ROUNDUP((I9+0.09)/0.2,0)-1,0)),IF(D9>9999,8+2*MAX(ROUNDUP((I9+0.05)/0.25,0),1),16+2*MAX(ROUNDUP((I9+0.10)/0.25,0)-1,0))) | Y9: =IF(E9="CAMION","1/2","3/8")
A10: 8 | B10: 10 | C10: =B10-A10 | D10: =(A10+B10)/2 | E10: =IF(AND(D10>=DATOS!$B$13,D10<DATOS!$B$14),"CAMION",IF(OR(AND(D10>=DATOS!$B$15,D10<=DATOS!$B$16),AND(D10>=DATOS!$B$17,D10<=DATOS!$B$18)),"AUTOS","NORMAL")) | F10: =IF(E10="CAMION",0.15,0.10) | G10: =IF(E10="CAMION",0.20,0.10) | H10: =IF(D10>9999,0,IF(E10="CAMION",0.20,0.10)) | I10: =IF(D10<=DATOS!$B$11,DATOS!$B$10-H10-(DATOS!$B$6-DATOS!$B$9*D10),DATOS!$B$12) | J10: 259.671 | K10: =DATOS!$B$5+2*F10 | L10: =K10*G10*C10 | M10: =2*F10*I10*C10 | N10: =K10*H10*C10 | O10: =(K10+0.10)*(IF(D10<=DATOS!$B$11,DATOS!$B$10,J10)-((DATOS!$B$6-DATOS!$B$9*D10)-G10-0.05))*C10 | P10: =(0.10*(IF(D10<=DATOS!$B$11,DATOS!$B$10,J10)-((DATOS!$B$6-DATOS!$B$9*D10)-G10-0.05))+IF(D10>9999,MAX(0,((DATOS!$B$6-DATOS!$B$9*D10)+I10+H10)-J10)*(0.20+0.75*MAX(0,((DATOS!$B$6-DATOS!$B$9*D10)+I10+H10)-J10)),0))*C10 | Q10: =K10*C10 | R10: =(2*I10+IF(D10>9999,0,DATOS!$B$5)+(I10+G10+H10)+IF(D10>9999,MAX(0,((DATOS!$B$6-DATOS!$B$9*D10)+I10+H10)-J10),0))*C10 | S10: =IF(E10="CAMION",C10/0.15*((2*(K10-0.09)+2*(I10+G10+H10-0.09)+0.5)+(2*(DATOS!$B$5+0.09)+2*(I10+0.09)+0.5))*DATOS!$B$23,C10/IF(E10="AUTOS",0.15,0.20)*IF(D10>9999,(DATOS!$B$5+F10)+2*(I10+G10/2)+0.20,2*(DATOS!$B$5+F10)+2*(I10+(G10+H10)/2)+0.40)*DATOS!$B$22) | T10: =IF(E10="CAMION",((ROUNDUP((K10-0.09)/0.2,0)+1)*2+2*MAX(ROUNDUP((I10+0.31)/0.2,0)-1,0)+(ROUNDUP((DATOS!$B$5+0.09)/0.2,0)+1)*2+2*MAX(ROUNDUP((I10+0.09)/0.2,0)-1,0)),IF(D10>9999,8+2*MAX(ROUNDUP((I10+0.05)/0.25,0),1),16+2*MAX(ROUNDUP((I10+0.10)/0.25,0)-1,0)))*C10*(1+0.40/9)*DATOS!$B$22 | U10: =(K10+0.10)*C10 | V10: =IF(E10="CAMION",2*C10/0.15,C10/IF(E10="AUTOS",0.15,0.20)) | W10: =IF(E10="CAMION",((2*(K10-0.09)+2*(I10+G10+H10-0.09)+0.5)+(2*(DATOS!$B$5+0.09)+2*(I10+0.09)+0.5))/2,IF(D10>9999,(DATOS!$B$5+F10)+2*(I10+G10/2)+0.20,2*(DATOS!$B$5+F10)+2*(I10+(G10+H10)/2)+0.40)) | X10: =IF(E10="CAMION",((ROUNDUP((K10-0.09)/0.2,0)+1)*2+2*MAX(ROUNDUP((I10+0.31)/0.2,0)-1,0)+(ROUNDUP((DATOS!$B$5+0.09)/0.2,0)+1)*2+2*MAX(ROUNDUP((I10+0.09)/0.2,0)-1,0)),IF(D10>9999,8+2*MAX(ROUNDUP((I10+0.05)/0.25,0),1),16+2*MAX(ROUNDUP((I10+0.10)/0.25,0)-1,0))) | Y10: =IF(E10="CAMION","1/2","3/8")
A11: 10 | B11: 12 | C11: =B11-A11 | D11: =(A11+B11)/2 | E11: =IF(AND(D11>=DATOS!$B$13,D11<DATOS!$B$14),"CAMION",IF(OR(AND(D11>=DATOS!$B$15,D11<=DATOS!$B$16),AND(D11>=DATOS!$B$17,D11<=DATOS!$B$18)),"AUTOS","NORMAL")) | F11: =IF(E11="CAMION",0.15,0.10) | G11: =IF(E11="CAMION",0.20,0.10) | H11: =IF(D11>9999,0,IF(E11="CAMION",0.20,0.10)) | I11: =IF(D11<=DATOS!$B$11,DATOS!$B$10-H11-(DATOS!$B$6-DATOS!$B$9*D11),DATOS!$B$12) | J11: 259.708 | K11: =DATOS!$B$5+2*F11 | L11: =K11*G11*C11 | M11: =2*F11*I11*C11 | N11: =K11*H11*C11 | O11: =(K11+0.10)*(IF(D11<=DATOS!$B$11,DATOS!$B$10,J11)-((DATOS!$B$6-DATOS!$B$9*D11)-G11-0.05))*C11 | P11: =(0.10*(IF(D11<=DATOS!$B$11,DATOS!$B$10,J11)-((DATOS!$B$6-DATOS!$B$9*D11)-G11-0.05))+IF(D11>9999,MAX(0,((DATOS!$B$6-DATOS!$B$9*D11)+I11+H11)-J11)*(0.20+0.75*MAX(0,((DATOS!$B$6-DATOS!$B$9*D11)+I11+H11)-J11)),0))*C11 | Q11: =K11*C11 | R11: =(2*I11+IF(D11>9999,0,DATOS!$B$5)+(I11+G11+H11)+IF(D11>9999,MAX(0,((DATOS!$B$6-DATOS!$B$9*D11)+I11+H11)-J11),0))*C11 | S11: =IF(E11="CAMION",C11/0.15*((2*(K11-0.09)+2*(I11+G11+H11-0.09)+0.5)+(2*(DATOS!$B$5+0.09)+2*(I11+0.09)+0.5))*DATOS!$B$23,C11/IF(E11="AUTOS",0.15,0.20)*IF(D11>9999,(DATOS!$B$5+F11)+2*(I11+G11/2)+0.20,2*(DATOS!$B$5+F11)+2*(I11+(G11+H11)/2)+0.40)*DATOS!$B$22) | T11: =IF(E11="CAMION",((ROUNDUP((K11-0.09)/0.2,0)+1)*2+2*MAX(ROUNDUP((I11+0.31)/0.2,0)-1,0)+(ROUNDUP((DATOS!$B$5+0.09)/0.2,0)+1)*2+2*MAX(ROUNDUP((I11+0.09)/0.2,0)-1,0)),IF(D11>9999,8+2*MAX(ROUNDUP((I11+0.05)/0.25,0),1),16+2*MAX(ROUNDUP((I11+0.10)/0.25,0)-1,0)))*C11*(1+0.40/9)*DATOS!$B$22 | U11: =(K11+0.10)*C11 | V11: =IF(E11="CAMION",2*C11/0.15,C11/IF(E11="AUTOS",0.15,0.20)) | W11: =IF(E11="CAMION",((2*(K11-0.09)+2*(I11+G11+H11-0.09)+0.5)+(2*(DATOS!$B$5+0.09)+2*(I11+0.09)+0.5))/2,IF(D11>9999,(DATOS!$B$5+F11)+2*(I11+G11/2)+0.20,2*(DATOS!$B$5+F11)+2*(I11+(G11+H11)/2)+0.40)) | X11: =IF(E11="CAMION",((ROUNDUP((K11-0.09)/0.2,0)+1)*2+2*MAX(ROUNDUP((I11+0.31)/0.2,0)-1,0)+(ROUNDUP((DATOS!$B$5+0.09)/0.2,0)+1)*2+2*MAX(ROUNDUP((I11+0.09)/0.2,0)-1,0)),IF(D11>9999,8+2*MAX(ROUNDUP((I11+0.05)/0.25,0),1),16+2*MAX(ROUNDUP((I11+0.10)/0.25,0)-1,0))) | Y11: =IF(E11="CAMION","1/2","3/8")
A12: 12 | B12: 14 | C12: =B12-A12 | D12: =(A12+B12)/2 | E12: =IF(AND(D12>=DATOS!$B$13,D12<DATOS!$B$14),"CAMION",IF(OR(AND(D12>=DATOS!$B$15,D12<=DATOS!$B$16),AND(D12>=DATOS!$B$17,D12<=DATOS!$B$18)),"AUTOS","NORMAL")) | F12: =IF(E12="CAMION",0.15,0.10) | G12: =IF(E12="CAMION",0.20,0.10) | H12: =IF(D12>9999,0,IF(E12="CAMION",0.20,0.10)) | I12: =IF(D12<=DATOS!$B$11,DATOS!$B$10-H12-(DATOS!$B$6-DATOS!$B$9*D12),DATOS!$B$12) | J12: 259.69 | K12: =DATOS!$B$5+2*F12 | L12: =K12*G12*C12 | M12: =2*F12*I12*C12 | N12: =K12*H12*C12 | O12: =(K12+0.10)*(IF(D12<=DATOS!$B$11,DATOS!$B$10,J12)-((DATOS!$B$6-DATOS!$B$9*D12)-G12-0.05))*C12 | P12: =(0.10*(IF(D12<=DATOS!$B$11,DATOS!$B$10,J12)-((DATOS!$B$6-DATOS!$B$9*D12)-G12-0.05))+IF(D12>9999,MAX(0,((DATOS!$B$6-DATOS!$B$9*D12)+I12+H12)-J12)*(0.20+0.75*MAX(0,((DATOS!$B$6-DATOS!$B$9*D12)+I12+H12)-J12)),0))*C12 | Q12: =K12*C12 | R12: =(2*I12+IF(D12>9999,0,DATOS!$B$5)+(I12+G12+H12)+IF(D12>9999,MAX(0,((DATOS!$B$6-DATOS!$B$9*D12)+I12+H12)-J12),0))*C12 | S12: =IF(E12="CAMION",C12/0.15*((2*(K12-0.09)+2*(I12+G12+H12-0.09)+0.5)+(2*(DATOS!$B$5+0.09)+2*(I12+0.09)+0.5))*DATOS!$B$23,C12/IF(E12="AUTOS",0.15,0.20)*IF(D12>9999,(DATOS!$B$5+F12)+2*(I12+G12/2)+0.20,2*(DATOS!$B$5+F12)+2*(I12+(G12+H12)/2)+0.40)*DATOS!$B$22) | T12: =IF(E12="CAMION",((ROUNDUP((K12-0.09)/0.2,0)+1)*2+2*MAX(ROUNDUP((I12+0.31)/0.2,0)-1,0)+(ROUNDUP((DATOS!$B$5+0.09)/0.2,0)+1)*2+2*MAX(ROUNDUP((I12+0.09)/0.2,0)-1,0)),IF(D12>9999,8+2*MAX(ROUNDUP((I12+0.05)/0.25,0),1),16+2*MAX(ROUNDUP((I12+0.10)/0.25,0)-1,0)))*C12*(1+0.40/9)*DATOS!$B$22 | U12: =(K12+0.10)*C12 | V12: =IF(E12="CAMION",2*C12/0.15,C12/IF(E12="AUTOS",0.15,0.20)) | W12: =IF(E12="CAMION",((2*(K12-0.09)+2*(I12+G12+H12-0.09)+0.5)+(2*(DATOS!$B$5+0.09)+2*(I12+0.09)+0.5))/2,IF(D12>9999,(DATOS!$B$5+F12)+2*(I12+G12/2)+0.20,2*(DATOS!$B$5+F12)+2*(I12+(G12+H12)/2)+0.40)) | X12: =IF(E12="CAMION",((ROUNDUP((K12-0.09)/0.2,0)+1)*2+2*MAX(ROUNDUP((I12+0.31)/0.2,0)-1,0)+(ROUNDUP((DATOS!$B$5+0.09)/0.2,0)+1)*2+2*MAX(ROUNDUP((I12+0.09)/0.2,0)-1,0)),IF(D12>9999,8+2*MAX(ROUNDUP((I12+0.05)/0.25,0),1),16+2*MAX(ROUNDUP((I12+0.10)/0.25,0)-1,0))) | Y12: =IF(E12="CAMION","1/2","3/8")
A13: 14 | B13: 16 | C13: =B13-A13 | D13: =(A13+B13)/2 | E13: =IF(AND(D13>=DATOS!$B$13,D13<DATOS!$B$14),"CAMION",IF(OR(AND(D13>=DATOS!$B$15,D13<=DATOS!$B$16),AND(D13>=DATOS!$B$17,D13<=DATOS!$B$18)),"AUTOS","NORMAL")) | F13: =IF(E13="CAMION",0.15,0.10) | G13: =IF(E13="CAMION",0.20,0.10) | H13: =IF(D13>9999,0,IF(E13="CAMION",0.20,0.10)) | I13: =IF(D13<=DATOS!$B$11,DATOS!$B$10-H13-(DATOS!$B$6-DATOS!$B$9*D13),DATOS!$B$12) | J13: 259.703 | K13: =DATOS!$B$5+2*F13 | L13: =K13*G13*C13 | M13: =2*F13*I13*C13 | N13: =K13*H13*C13 | O13: =(K13+0.10)*(IF(D13<=DATOS!$B$11,DATOS!$B$10,J13)-((DATOS!$B$6-DATOS!$B$9*D13)-G13-0.05))*C13 | P13: =(0.10*(IF(D13<=DATOS!$B$11,DATOS!$B$10,J13)-((DATOS!$B$6-DATOS!$B$9*D13)-G13-0.05))+IF(D13>9999,MAX(0,((DATOS!$B$6-DATOS!$B$9*D13)+I13+H13)-J13)*(0.20+0.75*MAX(0,((DATOS!$B$6-DATOS!$B$9*D13)+I13+H13)-J13)),0))*C13 | Q13: =K13*C13 | R13: =(2*I13+IF(D13>9999,0,DATOS!$B$5)+(I13+G13+H13)+IF(D13>9999,MAX(0,((DATOS!$B$6-DATOS!$B$9*D13)+I13+H13)-J13),0))*C13 | S13: =IF(E13="CAMION",C13/0.15*((2*(K13-0.09)+2*(I13+G13+H13-0.09)+0.5)+(2*(DATOS!$B$5+0.09)+2*(I13+0.09)+0.5))*DATOS!$B$23,C13/IF(E13="AUTOS",0.15,0.20)*IF(D13>9999,(DATOS!$B$5+F13)+2*(I13+G13/2)+0.20,2*(DATOS!$B$5+F13)+2*(I13+(G13+H13)/2)+0.40)*DATOS!$B$22) | T13: =IF(E13="CAMION",((ROUNDUP((K13-0.09)/0.2,0)+1)*2+2*MAX(ROUNDUP((I13+0.31)/0.2,0)-1,0)+(ROUNDUP((DATOS!$B$5+0.09)/0.2,0)+1)*2+2*MAX(ROUNDUP((I13+0.09)/0.2,0)-1,0)),IF(D13>9999,8+2*MAX(ROUNDUP((I13+0.05)/0.25,0),1),16+2*MAX(ROUNDUP((I13+0.10)/0.25,0)-1,0)))*C13*(1+0.40/9)*DATOS!$B$22 | U13: =(K13+0.10)*C13 | V13: =IF(E13="CAMION",2*C13/0.15,C13/IF(E13="AUTOS",0.15,0.20)) | W13: =IF(E13="CAMION",((2*(K13-0.09)+2*(I13+G13+H13-0.09)+0.5)+(2*(DATOS!$B$5+0.09)+2*(I13+0.09)+0.5))/2,IF(D13>9999,(DATOS!$B$5+F13)+2*(I13+G13/2)+0.20,2*(DATOS!$B$5+F13)+2*(I13+(G13+H13)/2)+0.40)) | X13: =IF(E13="CAMION",((ROUNDUP((K13-0.09)/0.2,0)+1)*2+2*MAX(ROUNDUP((I13+0.31)/0.2,0)-1,0)+(ROUNDUP((DATOS!$B$5+0.09)/0.2,0)+1)*2+2*MAX(ROUNDUP((I13+0.09)/0.2,0)-1,0)),IF(D13>9999,8+2*MAX(ROUNDUP((I13+0.05)/0.25,0),1),16+2*MAX(ROUNDUP((I13+0.10)/0.25,0)-1,0))) | Y13: =IF(E13="CAMION","1/2","3/8")
A14: 16 | B14: 18 | C14: =B14-A14 | D14: =(A14+B14)/2 | E14: =IF(AND(D14>=DATOS!$B$13,D14<DATOS!$B$14),"CAMION",IF(OR(AND(D14>=DATOS!$B$15,D14<=DATOS!$B$16),AND(D14>=DATOS!$B$17,D14<=DATOS!$B$18)),"AUTOS","NORMAL")) | F14: =IF(E14="CAMION",0.15,0.10) | G14: =IF(E14="CAMION",0.20,0.10) | H14: =IF(D14>9999,0,IF(E14="CAMION",0.20,0.10)) | I14: =IF(D14<=DATOS!$B$11,DATOS!$B$10-H14-(DATOS!$B$6-DATOS!$B$9*D14),DATOS!$B$12) | J14: 259.719 | K14: =DATOS!$B$5+2*F14 | L14: =K14*G14*C14 | M14: =2*F14*I14*C14 | N14: =K14*H14*C14 | O14: =(K14+0.10)*(IF(D14<=DATOS!$B$11,DATOS!$B$10,J14)-((DATOS!$B$6-DATOS!$B$9*D14)-G14-0.05))*C14 | P14: =(0.10*(IF(D14<=DATOS!$B$11,DATOS!$B$10,J14)-((DATOS!$B$6-DATOS!$B$9*D14)-G14-0.05))+IF(D14>9999,MAX(0,((DATOS!$B$6-DATOS!$B$9*D14)+I14+H14)-J14)*(0.20+0.75*MAX(0,((DATOS!$B$6-DATOS!$B$9*D14)+I14+H14)-J14)),0))*C14 | Q14: =K14*C14 | R14: =(2*I14+IF(D14>9999,0,DATOS!$B$5)+(I14+G14+H14)+IF(D14>9999,MAX(0,((DATOS!$B$6-DATOS!$B$9*D14)+I14+H14)-J14),0))*C14 | S14: =IF(E14="CAMION",C14/0.15*((2*(K14-0.09)+2*(I14+G14+H14-0.09)+0.5)+(2*(DATOS!$B$5+0.09)+2*(I14+0.09)+0.5))*DATOS!$B$23,C14/IF(E14="AUTOS",0.15,0.20)*IF(D14>9999,(DATOS!$B$5+F14)+2*(I14+G14/2)+0.20,2*(DATOS!$B$5+F14)+2*(I14+(G14+H14)/2)+0.40)*DATOS!$B$22) | T14: =IF(E14="CAMION",((ROUNDUP((K14-0.09)/0.2,0)+1)*2+2*MAX(ROUNDUP((I14+0.31)/0.2,0)-1,0)+(ROUNDUP((DATOS!$B$5+0.09)/0.2,0)+1)*2+2*MAX(ROUNDUP((I14+0.09)/0.2,0)-1,0)),IF(D14>9999,8+2*MAX(ROUNDUP((I14+0.05)/0.25,0),1),16+2*MAX(ROUNDUP((I14+0.10)/0.25,0)-1,0)))*C14*(1+0.40/9)*DATOS!$B$22 | U14: =(K14+0.10)*C14 | V14: =IF(E14="CAMION",2*C14/0.15,C14/IF(E14="AUTOS",0.15,0.20)) | W14: =IF(E14="CAMION",((2*(K14-0.09)+2*(I14+G14+H14-0.09)+0.5)+(2*(DATOS!$B$5+0.09)+2*(I14+0.09)+0.5))/2,IF(D14>9999,(DATOS!$B$5+F14)+2*(I14+G14/2)+0.20,2*(DATOS!$B$5+F14)+2*(I14+(G14+H14)/2)+0.40)) | X14: =IF(E14="CAMION",((ROUNDUP((K14-0.09)/0.2,0)+1)*2+2*MAX(ROUNDUP((I14+0.31)/0.2,0)-1,0)+(ROUNDUP((DATOS!$B$5+0.09)/0.2,0)+1)*2+2*MAX(ROUNDUP((I14+0.09)/0.2,0)-1,0)),IF(D14>9999,8+2*MAX(ROUNDUP((I14+0.05)/0.25,0),1),16+2*MAX(ROUNDUP((I14+0.10)/0.25,0)-1,0))) | Y14: =IF(E14="CAMION","1/2","3/8")
A15: 18 | B15: 18.45 | C15: =B15-A15 | D15: =(A15+B15)/2 | E15: =IF(AND(D15>=DATOS!$B$13,D15<DATOS!$B$14),"CAMION",IF(OR(AND(D15>=DATOS!$B$15,D15<=DATOS!$B$16),AND(D15>=DATOS!$B$17,D15<=DATOS!$B$18)),"AUTOS","NORMAL")) | F15: =IF(E15="CAMION",0.15,0.10) | G15: =IF(E15="CAMION",0.20,0.10) | H15: =IF(D15>9999,0,IF(E15="CAMION",0.20,0.10)) | I15: =IF(D15<=DATOS!$B$11,DATOS!$B$10-H15-(DATOS!$B$6-DATOS!$B$9*D15),DATOS!$B$12) | J15: 259.696 | K15: =DATOS!$B$5+2*F15 | L15: =K15*G15*C15 | M15: =2*F15*I15*C15 | N15: =K15*H15*C15 | O15: =(K15+0.10)*(IF(D15<=DATOS!$B$11,DATOS!$B$10,J15)-((DATOS!$B$6-DATOS!$B$9*D15)-G15-0.05))*C15 | P15: =(0.10*(IF(D15<=DATOS!$B$11,DATOS!$B$10,J15)-((DATOS!$B$6-DATOS!$B$9*D15)-G15-0.05))+IF(D15>9999,MAX(0,((DATOS!$B$6-DATOS!$B$9*D15)+I15+H15)-J15)*(0.20+0.75*MAX(0,((DATOS!$B$6-DATOS!$B$9*D15)+I15+H15)-J15)),0))*C15 | Q15: =K15*C15 | R15: =(2*I15+IF(D15>9999,0,DATOS!$B$5)+(I15+G15+H15)+IF(D15>9999,MAX(0,((DATOS!$B$6-DATOS!$B$9*D15)+I15+H15)-J15),0))*C15 | S15: =IF(E15="CAMION",C15/0.15*((2*(K15-0.09)+2*(I15+G15+H15-0.09)+0.5)+(2*(DATOS!$B$5+0.09)+2*(I15+0.09)+0.5))*DATOS!$B$23,C15/IF(E15="AUTOS",0.15,0.20)*IF(D15>9999,(DATOS!$B$5+F15)+2*(I15+G15/2)+0.20,2*(DATOS!$B$5+F15)+2*(I15+(G15+H15)/2)+0.40)*DATOS!$B$22) | T15: =IF(E15="CAMION",((ROUNDUP((K15-0.09)/0.2,0)+1)*2+2*MAX(ROUNDUP((I15+0.31)/0.2,0)-1,0)+(ROUNDUP((DATOS!$B$5+0.09)/0.2,0)+1)*2+2*MAX(ROUNDUP((I15+0.09)/0.2,0)-1,0)),IF(D15>9999,8+2*MAX(ROUNDUP((I15+0.05)/0.25,0),1),16+2*MAX(ROUNDUP((I15+0.10)/0.25,0)-1,0)))*C15*(1+0.40/9)*DATOS!$B$22 | U15: =(K15+0.10)*C15 | V15: =IF(E15="CAMION",2*C15/0.15,C15/IF(E15="AUTOS",0.15,0.20)) | W15: =IF(E15="CAMION",((2*(K15-0.09)+2*(I15+G15+H15-0.09)+0.5)+(2*(DATOS!$B$5+0.09)+2*(I15+0.09)+0.5))/2,IF(D15>9999,(DATOS!$B$5+F15)+2*(I15+G15/2)+0.20,2*(DATOS!$B$5+F15)+2*(I15+(G15+H15)/2)+0.40)) | X15: =IF(E15="CAMION",((ROUNDUP((K15-0.09)/0.2,0)+1)*2+2*MAX(ROUNDUP((I15+0.31)/0.2,0)-1,0)+(ROUNDUP((DATOS!$B$5+0.09)/0.2,0)+1)*2+2*MAX(ROUNDUP((I15+0.09)/0.2,0)-1,0)),IF(D15>9999,8+2*MAX(ROUNDUP((I15+0.05)/0.25,0),1),16+2*MAX(ROUNDUP((I15+0.10)/0.25,0)-1,0))) | Y15: =IF(E15="CAMION","1/2","3/8")
A16: 18.45 | B16: 20 | C16: =B16-A16 | D16: =(A16+B16)/2 | E16: =IF(AND(D16>=DATOS!$B$13,D16<DATOS!$B$14),"CAMION",IF(OR(AND(D16>=DATOS!$B$15,D16<=DATOS!$B$16),AND(D16>=DATOS!$B$17,D16<=DATOS!$B$18)),"AUTOS","NORMAL")) | F16: =IF(E16="CAMION",0.15,0.10) | G16: =IF(E16="CAMION",0.20,0.10) | H16: =IF(D16>9999,0,IF(E16="CAMION",0.20,0.10)) | I16: =IF(D16<=DATOS!$B$11,DATOS!$B$10-H16-(DATOS!$B$6-DATOS!$B$9*D16),DATOS!$B$12) | J16: 259.651 | K16: =DATOS!$B$5+2*F16 | L16: =K16*G16*C16 | M16: =2*F16*I16*C16 | N16: =K16*H16*C16 | O16: =(K16+0.10)*(IF(D16<=DATOS!$B$11,DATOS!$B$10,J16)-((DATOS!$B$6-DATOS!$B$9*D16)-G16-0.05))*C16 | P16: =(0.10*(IF(D16<=DATOS!$B$11,DATOS!$B$10,J16)-((DATOS!$B$6-DATOS!$B$9*D16)-G16-0.05))+IF(D16>9999,MAX(0,((DATOS!$B$6-DATOS!$B$9*D16)+I16+H16)-J16)*(0.20+0.75*MAX(0,((DATOS!$B$6-DATOS!$B$9*D16)+I16+H16)-J16)),0))*C16 | Q16: =K16*C16 | R16: =(2*I16+IF(D16>9999,0,DATOS!$B$5)+(I16+G16+H16)+IF(D16>9999,MAX(0,((DATOS!$B$6-DATOS!$B$9*D16)+I16+H16)-J16),0))*C16 | S16: =IF(E16="CAMION",C16/0.15*((2*(K16-0.09)+2*(I16+G16+H16-0.09)+0.5)+(2*(DATOS!$B$5+0.09)+2*(I16+0.09)+0.5))*DATOS!$B$23,C16/IF(E16="AUTOS",0.15,0.20)*IF(D16>9999,(DATOS!$B$5+F16)+2*(I16+G16/2)+0.20,2*(DATOS!$B$5+F16)+2*(I16+(G16+H16)/2)+0.40)*DATOS!$B$22) | T16: =IF(E16="CAMION",((ROUNDUP((K16-0.09)/0.2,0)+1)*2+2*MAX(ROUNDUP((I16+0.31)/0.2,0)-1,0)+(ROUNDUP((DATOS!$B$5+0.09)/0.2,0)+1)*2+2*MAX(ROUNDUP((I16+0.09)/0.2,0)-1,0)),IF(D16>9999,8+2*MAX(ROUNDUP((I16+0.05)/0.25,0),1),16+2*MAX(ROUNDUP((I16+0.10)/0.25,0)-1,0)))*C16*(1+0.40/9)*DATOS!$B$22 | U16: =(K16+0.10)*C16 | V16: =IF(E16="CAMION",2*C16/0.15,C16/IF(E16="AUTOS",0.15,0.20)) | W16: =IF(E16="CAMION",((2*(K16-0.09)+2*(I16+G16+H16-0.09)+0.5)+(2*(DATOS!$B$5+0.09)+2*(I16+0.09)+0.5))/2,IF(D16>9999,(DATOS!$B$5+F16)+2*(I16+G16/2)+0.20,2*(DATOS!$B$5+F16)+2*(I16+(G16+H16)/2)+0.40)) | X16: =IF(E16="CAMION",((ROUNDUP((K16-0.09)/0.2,0)+1)*2+2*MAX(ROUNDUP((I16+0.31)/0.2,0)-1,0)+(ROUNDUP((DATOS!$B$5+0.09)/0.2,0)+1)*2+2*MAX(ROUNDUP((I16+0.09)/0.2,0)-1,0)),IF(D16>9999,8+2*MAX(ROUNDUP((I16+0.05)/0.25,0),1),16+2*MAX(ROUNDUP((I16+0.10)/0.25,0)-1,0))) | Y16: =IF(E16="CAMION","1/2","3/8")
... A79: 138 | B79: 139.08 | C79: =B79-A79 | D79: =(A79+B79)/2 | E79: =IF(AND(D79>=DATOS!$B$13,D79<DATOS!$B$14),"CAMION",IF(OR(AND(D79>=DATOS!$B$15,D79<=DATOS!$B$16),AND(D79>=DATOS!$B$17,D79<=DATOS!$B$18)),"AUTOS","NORMAL")) | F79: =IF(E79="CAMION",0.15,0.10) | G79: =IF(E79="CAMION",0.20,0.10) | H79: =IF(D79>9999,0,IF(E79="CAMION",0.20,0.10)) | I79: =IF(D79<=DATOS!$B$11,DATOS!$B$10-H79-(DATOS!$B$6-DATOS!$B$9*D79),DATOS!$B$12) | J79: 258.417 | K79: =DATOS!$B$5+2*F79 | L79: =K79*G79*C79 | M79: =2*F79*I79*C79 | N79: =K79*H79*C79 | O79: =(K79+0.10)*(IF(D79<=DATOS!$B$11,DATOS!$B$10,J79)-((DATOS!$B$6-DATOS!$B$9*D79)-G79-0.05))*C79 | P79: =(0.10*(IF(D79<=DATOS!$B$11,DATOS!$B$10,J79)-((DATOS!$B$6-DATOS!$B$9*D79)-G79-0.05))+IF(D79>9999,MAX(0,((DATOS!$B$6-DATOS!$B$9*D79)+I79+H79)-J79)*(0.20+0.75*MAX(0,((DATOS!$B$6-DATOS!$B$9*D79)+I79+H79)-J79)),0))*C79 | Q79: =K79*C79 | R79: =(2*I79+IF(D79>9999,0,DATOS!$B$5)+(I79+G79+H79)+IF(D79>9999,MAX(0,((DATOS!$B$6-DATOS!$B$9*D79)+I79+H79)-J79),0))*C79 | S79: =IF(E79="CAMION",C79/0.15*((2*(K79-0.09)+2*(I79+G79+H79-0.09)+0.5)+(2*(DATOS!$B$5+0.09)+2*(I79+0.09)+0.5))*DATOS!$B$23,C79/IF(E79="AUTOS",0.15,0.20)*IF(D79>9999,(DATOS!$B$5+F79)+2*(I79+G79/2)+0.20,2*(DATOS!$B$5+F79)+2*(I79+(G79+H79)/2)+0.40)*DATOS!$B$22) | T79: =IF(E79="CAMION",((ROUNDUP((K79-0.09)/0.2,0)+1)*2+2*MAX(ROUNDUP((I79+0.31)/0.2,0)-1,0)+(ROUNDUP((DATOS!$B$5+0.09)/0.2,0)+1)*2+2*MAX(ROUNDUP((I79+0.09)/0.2,0)-1,0)),IF(D79>9999,8+2*MAX(ROUNDUP((I79+0.05)/0.25,0),1),16+2*MAX(ROUNDUP((I79+0.10)/0.25,0)-1,0)))*C79*(1+0.40/9)*DATOS!$B$22 | U79: =(K79+0.10)*C79 | V79: =IF(E79="CAMION",2*C79/0.15,C79/IF(E79="AUTOS",0.15,0.20)) | W79: =IF(E79="CAMION",((2*(K79-0.09)+2*(I79+G79+H79-0.09)+0.5)+(2*(DATOS!$B$5+0.09)+2*(I79+0.09)+0.5))/2,IF(D79>9999,(DATOS!$B$5+F79)+2*(I79+G79/2)+0.20,2*(DATOS!$B$5+F79)+2*(I79+(G79+H79)/2)+0.40)) | X79: =IF(E79="CAMION",((ROUNDUP((K79-0.09)/0.2,0)+1)*2+2*MAX(ROUNDUP((I79+0.31)/0.2,0)-1,0)+(ROUNDUP((DATOS!$B$5+0.09)/0.2,0)+1)*2+2*MAX(ROUNDUP((I79+0.09)/0.2,0)-1,0)),IF(D79>9999,8+2*MAX(ROUNDUP((I79+0.05)/0.25,0),1),16+2*MAX(ROUNDUP((I79+0.10)/0.25,0)-1,0))) | Y79: =IF(E79="CAMION","1/2","3/8")
A80: TOTALES | C80: =SUM(C5:C79) | L80: =SUM(L5:L79) | M80: =SUM(M5:M79) | N80: =SUM(N5:N79) | O80: =SUM(O5:O79) | P80: =SUM(P5:P79) | Q80: =SUM(Q5:Q79) | R80: =SUM(R5:R79) | S80: =SUM(S5:S79) | ... V80: =SUM(V5:V79)

Sheet 01 PRELIMINARES
A1: 01 OBRAS PRELIMINARES
A2: CAR Mujeres (CUI 2717013) - Colector pluvial frontal b=1.50 m, preparado para CAR Varones y Hogar de Refugio - Morales, San Martin
A4: ITEM | B4: DESCRIPCION | C4: UND | D4: N. VECES | E4: LARGO (m) | F4: ANCHO (m) | G4: ALTO (m) | H4: PARCIAL | I4: TOTAL | J4: OBSERVACION
A5: 01.01 | B5: TRAZO, NIVELACION Y REPLANTEO | C5: m2
B6: Colector: franja = ancho exterior + 0.10 m (hoja TRAMOS, col. U)
B7: Tramo 0+000.00 - 0+002.00 (normal) | H7: =TRAMOS!U5
B8: Tramo 0+002.00 - 0+002.74 (normal) | H8: =TRAMOS!U6
B9: Tramo 0+002.74 - 0+004.00 (cruce de autos) | H9: =TRAMOS!U7
B10: Tramo 0+004.00 - 0+006.00 (cruce de autos) | H10: =TRAMOS!U8
B11: Tramo 0+006.00 - 0+008.00 (cruce de autos) | H11: =TRAMOS!U9
B12: Tramo 0+008.00 - 0+010.00 (cruce de autos) | H12: =TRAMOS!U10
B13: Tramo 0+010.00 - 0+012.00 (cruce de autos) | H13: =TRAMOS!U11
B14: Tramo 0+012.00 - 0+014.00 (cruce de autos) | H14: =TRAMOS!U12
B15: Tramo 0+014.00 - 0+016.00 (cruce de autos) | H15: =TRAMOS!U13
B16: Tramo 0+016.00 - 0+018.00 (cruce de autos) | H16: =TRAMOS!U14
B17: Tramo 0+018.00 - 0+018.45 (cruce de autos) | H17: =TRAMOS!U15
B18: Tramo 0+018.45 - 0+020.00 (normal) | H18: =TRAMOS!U16
... B81: Tramo 0+138.00 - 0+139.08 (normal) | H81: =TRAMOS!U79
B82: Estructura de salida
B83: Planta de aleros, emboquillado y una | D83: 1 | E83: =DATOS!$B$31+0.15+0.40 | F83: =DATOS!$B$32+0.60 | H83: =D83*E83*F83
G84: TOTAL | I84: =SUM(H6:H83)

Sheet 02 MOV. TIERRAS
A1: 02 MOVIMIENTO DE TIERRAS
A2: CAR Mujeres (CUI 2717013) - Colector pluvial frontal b=1.50 m, preparado para CAR Varones y Hogar de Refugio - Morales, San Martin
A4: ITEM | B4: DESCRIPCION | C4: UND | D4: N. VECES | E4: LARGO (m) | F4: ANCHO (m) | G4: ALTO (m) | H4: PARCIAL | I4: TOTAL | J4: OBSERVACION
A5: 02.01 | B5: EXCAVACION DE ZANJA (manual / con equipo liviano) | C5: m3
B6: Colector: (ancho ext. + 0.10) x profundidad desde NPT o terreno hasta fondo de solado
B7: Tramo 0+000.00 - 0+002.00 (normal) | H7: =TRAMOS!O5
B8: Tramo 0+002.00 - 0+002.74 (normal) | H8: =TRAMOS!O6
B9: Tramo 0+002.74 - 0+004.00 (cruce de autos) | H9: =TRAMOS!O7
B10: Tramo 0+004.00 - 0+006.00 (cruce de autos) | H10: =TRAMOS!O8
B11: Tramo 0+006.00 - 0+008.00 (cruce de autos) | H11: =TRAMOS!O9
B12: Tramo 0+008.00 - 0+010.00 (cruce de autos) | H12: =TRAMOS!O10
B13: Tramo 0+010.00 - 0+012.00 (cruce de autos) | H13: =TRAMOS!O11
B14: Tramo 0+012.00 - 0+014.00 (cruce de autos) | H14: =TRAMOS!O12
B15: Tramo 0+014.00 - 0+016.00 (cruce de autos) | H15: =TRAMOS!O13
B16: Tramo 0+016.00 - 0+018.00 (cruce de autos) | H16: =TRAMOS!O14
B17: Tramo 0+018.00 - 0+018.45 (cruce de autos) | H17: =TRAMOS!O15
B18: Tramo 0+018.45 - 0+020.00 (normal) | H18: =TRAMOS!O16
... B81: Tramo 0+138.00 - 0+139.08 (normal) | H81: =TRAMOS!O79
B82: Estructura de salida
B83: Aleros, emboquillado y una (fondo a CF - 0.65 en la una, CF - 0.45 en zapatas) | D83: 1 | E83: =DATOS!$B$31+0.15+0.40 | F83: =DATOS!$B$32+0.60 | G83: 0.85 | H83: =D83*E83*F83*G83
G84: TOTAL | I84: =SUM(H6:H83)
A86: 02.02 | B86: REFINE, NIVELACION Y COMPACTACION DE FONDO | C86: m2
B87: Colector: ancho exterior x longitud
B88: Tramo 0+000.00 - 0+002.00 (normal) | H88: =TRAMOS!Q5
B89: Tramo 0+002.00 - 0+002.74 (normal) | H89: =TRAMOS!Q6
B90: Tramo 0+002.74 - 0+004.00 (cruce de autos) | H90: =TRAMOS!Q7
B91: Tramo 0+004.00 - 0+006.00 (cruce de autos) | H91: =TRAMOS!Q8
B92: Tramo 0+006.00 - 0+008.00 (cruce de autos) | H92: =TRAMOS!Q9
B93: Tramo 0+008.00 - 0+010.00 (cruce de autos) | H93: =TRAMOS!Q10
B94: Tramo 0+010.00 - 0+012.00 (cruce de autos) | H94: =TRAMOS!Q11
B95: Tramo 0+012.00 - 0+014.00 (cruce de autos) | H95: =TRAMOS!Q12
B96: Tramo 0+014.00 - 0+016.00 (cruce de autos) | H96: =TRAMOS!Q13
B97: Tramo 0+016.00 - 0+018.00 (cruce de autos) | H97: =TRAMOS!Q14
B98: Tramo 0+018.00 - 0+018.45 (cruce de autos) | H98: =TRAMOS!Q15
B99: Tramo 0+018.45 - 0+020.00 (normal) | H99: =TRAMOS!Q16
... B162: Tramo 0+138.00 - 0+139.08 (normal) | H162: =TRAMOS!Q79
B163: Estructura de salida
B164: Zapatas de aleros | D164: 2 | E164: =DATOS!$B$26 | F164: =DATOS!$B$30 | H164: =D164*E164*F164
B165: Piso del emboquillado (trapecio) | D165: 1 | H165: =(DATOS!$B$5+DATOS!$B$32)/2*DATOS!$B$31
G166: TOTAL | I166: =SUM(H87:H165)
...

Sheet 03 CONCRETO SIMPLE
A1: 03 CONCRETO SIMPLE
A2: CAR Mujeres (CUI 2717013) - Colector pluvial frontal b=1.50 m, preparado para CAR Varones y Hogar de Refugio - Morales, San Martin
A4: ITEM | B4: DESCRIPCION | C4: UND | D4: N. VECES | E4: LARGO (m) | F4: ANCHO (m) | G4: ALTO (m) | H4: PARCIAL | I4: TOTAL | J4: OBSERVACION
A5: 03.01 | B5: SOLADO DE CONCRETO f'c=100 kg/cm2 e=0.05 m | C5: m2
B6: Colector
B7: Tramo 0+000.00 - 0+002.00 (normal) | H7: =TRAMOS!Q5
B8: Tramo 0+002.00 - 0+002.74 (normal) | H8: =TRAMOS!Q6
B9: Tramo 0+002.74 - 0+004.00 (cruce de autos) | H9: =TRAMOS!Q7
B10: Tramo 0+004.00 - 0+006.00 (cruce de autos) | H10: =TRAMOS!Q8
B11: Tramo 0+006.00 - 0+008.00 (cruce de autos) | H11: =TRAMOS!Q9
B12: Tramo 0+008.00 - 0+010.00 (cruce de autos) | H12: =TRAMOS!Q10
B13: Tramo 0+010.00 - 0+012.00 (cruce de autos) | H13: =TRAMOS!Q11
B14: Tramo 0+012.00 - 0+014.00 (cruce de autos) | H14: =TRAMOS!Q12
B15: Tramo 0+014.00 - 0+016.00 (cruce de autos) | H15: =TRAMOS!Q13
B16: Tramo 0+016.00 - 0+018.00 (cruce de autos) | H16: =TRAMOS!Q14
B17: Tramo 0+018.00 - 0+018.45 (cruce de autos) | H17: =TRAMOS!Q15
B18: Tramo 0+018.45 - 0+020.00 (normal) | H18: =TRAMOS!Q16
... B81: Tramo 0+138.00 - 0+139.08 (normal) | H81: =TRAMOS!Q79
B82: Estructura de salida
B83: Bajo zapatas de aleros | D83: 2 | E83: =DATOS!$B$26 | F83: =DATOS!$B$30 | H83: =D83*E83*F83
G84: TOTAL | I84: =SUM(H6:H83)
A86: 03.02 | B86: AFIRMADO COMPACTADO e=0.10 m BAJO EMBOQUILLADO | C86: m2
B87: Piso del emboquillado (trapecio) | D87: 1 | H87: =(DATOS!$B$5+DATOS!$B$32)/2*DATOS!$B$31
G88: TOTAL | I88: =SUM(H87:H87)
A90: 03.03 | B90: UNA DE CONCRETO CICLOPEO f'c=140 kg/cm2 + 30% P.M. | C90: m3
B91: Seccion trapecial (0.35+0.15)/2 x 0.65 x longitud | D91: 1 | E91: =DATOS!$B$32+0.30 | F91: 0.25 | G91: 0.65 | H91: =D91*E91*F91*G91 | J91: DP-07 corte A-A
G92: TOTAL | I92: =SUM(H91:H91)

Sheet 04 CONCRETO ARMADO
A1: 04 CONCRETO ARMADO - COLECTOR
A2: CAR Mujeres (CUI 2717013) - Colector pluvial frontal b=1.50 m, preparado para CAR Varones y Hogar de Refugio - Morales, San Martin
A4: ITEM | B4: DESCRIPCION | C4: UND | D4: N. VECES | E4: LARGO (m) | F4: ANCHO (m) | G4: ALTO (m) | H4: PARCIAL | I4: TOTAL | J4: OBSERVACION
A5: 04.01 | B5: CONCRETO f'c=210 kg/cm2 - LOSA DE FONDO | C5: m3
B6: ancho exterior x e losa x longitud
B7: Tramo 0+000.00 - 0+002.00 (normal) | H7: =TRAMOS!L5
B8: Tramo 0+002.00 - 0+002.74 (normal) | H8: =TRAMOS!L6
B9: Tramo 0+002.74 - 0+004.00 (cruce de autos) | H9: =TRAMOS!L7
B10: Tramo 0+004.00 - 0+006.00 (cruce de autos) | H10: =TRAMOS!L8
B11: Tramo 0+006.00 - 0+008.00 (cruce de autos) | H11: =TRAMOS!L9
B12: Tramo 0+008.00 - 0+010.00 (cruce de autos) | H12: =TRAMOS!L10
B13: Tramo 0+010.00 - 0+012.00 (cruce de autos) | H13: =TRAMOS!L11
B14: Tramo 0+012.00 - 0+014.00 (cruce de autos) | H14: =TRAMOS!L12
B15: Tramo 0+014.00 - 0+016.00 (cruce de autos) | H15: =TRAMOS!L13
B16: Tramo 0+016.00 - 0+018.00 (cruce de autos) | H16: =TRAMOS!L14
B17: Tramo 0+018.00 - 0+018.45 (cruce de autos) | H17: =TRAMOS!L15
B18: Tramo 0+018.45 - 0+020.00 (normal) | H18: =TRAMOS!L16
... B81: Tramo 0+138.00 - 0+139.08 (normal) | H81: =TRAMOS!L79
G82: TOTAL | I82: =SUM(H6:H81)
A84: 04.02 | B84: CONCRETO f'c=210 kg/cm2 - MUROS | C84: m3
B85: 2 muros x e x h x longitud
B86: Tramo 0+000.00 - 0+002.00 (normal) | H86: =TRAMOS!M5
B87: Tramo 0+002.00 - 0+002.74 (normal) | H87: =TRAMOS!M6
B88: Tramo 0+002.74 - 0+004.00 (cruce de autos) | H88: =TRAMOS!M7
B89: Tramo 0+004.00 - 0+006.00 (cruce de autos) | H89: =TRAMOS!M8
B90: Tramo 0+006.00 - 0+008.00 (cruce de autos) | H90: =TRAMOS!M9
B91: Tramo 0+008.00 - 0+010.00 (cruce de autos) | H91: =TRAMOS!M10
B92: Tramo 0+010.00 - 0+012.00 (cruce de autos) | H92: =TRAMOS!M11
B93: Tramo 0+012.00 - 0+014.00 (cruce de autos) | H93: =TRAMOS!M12
B94: Tramo 0+014.00 - 0+016.00 (cruce de autos) | H94: =TRAMOS!M13
B95: Tramo 0+016.00 - 0+018.00 (cruce de autos) | H95: =TRAMOS!M14
B96: Tramo 0+018.00 - 0+018.45 (cruce de autos) | H96: =TRAMOS!M15
B97: Tramo 0+018.45 - 0+020.00 (normal) | H97: =TRAMOS!M16
... B160: Tramo 0+138.00 - 0+139.08 (normal) | H160: =TRAMOS!M79
B161: Descuentos
B162: (-) Ventanas de empalme de cunetas 0.40 x 0.30 | D162: =-DATOS!$B$37 | E162: 0.4 | F162: 0.1 | G162: 0.3 | H162: =D162*E162*F162*G162
G163: TOTAL | I163: =SUM(H85:H162)
A165: 04.03 | B165: CONCRETO f'c=210 kg/cm2 - LOSA SUPERIOR (vaciada con los muros) | C165: m3
B166: ancho exterior x e losa x longitud
B167: Tramo 0+000.00 - 0+002.00 (normal) | H167: =TRAMOS!N5
...

Sheet 05 REGISTROS
A1: 05 REGISTROS DE LIMPIEZA (R-01 a R-15)
A2: CAR Mujeres (CUI 2717013) - Colector pluvial frontal b=1.50 m, preparado para CAR Varones y Hogar de Refugio - Morales, San Martin
A4: ITEM | B4: DESCRIPCION | C4: UND | D4: N. VECES | E4: LARGO (m) | F4: ANCHO (m) | G4: ALTO (m) | H4: PARCIAL | I4: TOTAL | J4: OBSERVACION
A5: 05.01 | B5: CONTRAMARCO METALICO DE ANGULO L 2"x2"x3/16" CON ANCLAJES (suministro y colocacion) | C5: und
B6: Un contramarco por registro | D6: =DATOS!$B$19 | H6: =D6 | J6: perimetro 4 x 0.70 = 2.80 m ; 10.2 kg ; 8 anclajes 3/8" L=0.20 soldados
G7: TOTAL | I7: =SUM(H6:H6)
A9: 05.02 | B9: MARCO METALICO DE TAPA, ANGULO L 1 1/2"x1 1/2"x1/8" (suministro y colocacion) | C9: und
B10: Un marco por tapa | D10: =DATOS!$B$19 | H10: =D10 | J10: perimetro 4 x 0.68 = 2.72 m ; 5.0 kg
G11: TOTAL | I11: =SUM(H10:H10)
A13: 05.03 | B13: ANGULOS METALICOS PARA MARCO Y CONTRAMARCO (peso) | C13: kg
B14: Contramarco L 2"x2"x3/16" | D14: =DATOS!$B$19 | E14: 2.8 | H14: =D14*E14*DATOS!$B$24
B15: Marco de tapa L 1 1/2"x1 1/2"x1/8" | D15: =DATOS!$B$19 | E15: 2.72 | H15: =D15*E15*DATOS!$B$25
G16: TOTAL | I16: =SUM(H14:H15)
A18: 05.04 | B18: TAPA DE CONCRETO ARMADO 0.68x0.68x0.08 f'c=210 (incluye acero y asas) | C18: und
B19: Una tapa por registro | D19: =DATOS!$B$19 | H19: =D19 | J19: volumen por tapa 0.68 x 0.68 x 0.08 = 0.037 m3 ; peso aprox. 95 kg
G20: TOTAL | I20: =SUM(H19:H19)
A22: 05.05 | B22: CONCRETO f'c=210 kg/cm2 EN TAPAS | C22: m3
B23: Tapas | D23: =DATOS!$B$19 | E23: =DATOS!$B$35 | F23: =DATOS!$B$35 | G23: =DATOS!$B$36 | H23: =D23*E23*F23*G23
G24: TOTAL | I24: =SUM(H23:H23)
A26: 05.06 | B26: ACERO DE REFUERZO fy=4200 EN BORDES, TAPAS Y ANCLAJES | C26: kg
B27: Refuerzo de borde 1/2": 8 barras x 1.40 m | D27: =DATOS!$B$19*8 | E27: 1.4 | H27: =D27*E27*DATOS!$B$23
B28: Tapa 3/8" @0.10: 14 barras x 0.62 m | D28: =DATOS!$B$19*14 | E28: 0.62 | H28: =D28*E28*DATOS!$B$22
B29: Asas 3/8" liso: 2 x 0.40 m | D29: =DATOS!$B$19*2 | E29: 0.4 | H29: =D29*E29*DATOS!$B$22
B30: Anclajes de contramarco 3/8": 8 x 0.20 m | D30: =DATOS!$B$19*8 | E30: 0.2 | H30: =D30*E30*DATOS!$B$22
G31: TOTAL | I31: =SUM(H27:H30)
A33: 05.07 | B33: PINTURA ANTICORROSIVA Y ESMALTE EN ANGULOS | C33: m2
B34: Contramarco: desarrollo 0.203 m2/m x 2.80 m | D34: =DATOS!$B$19 | E34: 2.8 | F34: 0.203 | H34: =D34*E34*F34
B35: Marco de tapa: desarrollo 0.152 m2/m x 2.72 m | D35: =DATOS!$B$19 | E35: 2.72 | F35: 0.152 | H35: =D35*E35*F35
G36: TOTAL | I36: =SUM(H34:H35)

Sheet 06 SALIDA
A1: 06 ESTRUCTURA DE SALIDA CON DOS ALEROS
A2: CAR Mujeres (CUI 2717013) - Colector pluvial frontal b=1.50 m, preparado para CAR Varones y Hogar de Refugio - Morales, San Martin
A4: ITEM | B4: DESCRIPCION | C4: UND | D4: N. VECES | E4: LARGO (m) | F4: ANCHO (m) | G4: ALTO (m) | H4: PARCIAL | I4: TOTAL | J4: OBSERVACION
A5: 06.01 | B5: CONCRETO f'c=210 kg/cm2 - ALEROS | C5: m3
B6: Muro de alero (altura media sobre la zapata) | D6: 2 | E6: =DATOS!$B$26 | F6: =DATOS!$B$27 | H6: =D6*E6*F6*((DATOS!$B$28+DATOS!$B$29)/2+0.20)
B7: Zapata de alero | D7: 2 | E7: =DATOS!$B$26 | F7: =DATOS!$B$30 | G7: 0.2 | H7: =D7*E7*F7*G7
G8: TOTAL | I8: =SUM(H6:H7)
A10: 06.02 | B10: ENCOFRADO Y DESENCOFRADO - ALEROS | C10: m2
B11: Muro: 2 caras | D11: 4 | E11: =DATOS!$B$26 | H11: =D11*E11*((DATOS!$B$28+DATOS!$B$29)/2+0.20)
B12: Muro: cabeza | D12: 2 | E12: =DATOS!$B$27 | H12: =D12*E12*(DATOS!$B$29+0.20)
B13: Zapata: 2 costados | D13: 4 | E13: =DATOS!$B$26 | G13: 0.2 | H13: =D13*E13*G13
G14: TOTAL | I14: =SUM(H11:H13)
A16: 06.03 | B16: ACERO DE REFUERZO fy=4200 - ALEROS | C16: kg
B17: Barras en L 3/8" @0.20 (vertical + zapata) | D17: 12 | E17: 1.38 | H17: =D17*E17*DATOS!$B$22
B18: Horizontales 3/8" @0.20 en el muro | D18: 10 | E18: =DATOS!$B$26 | H18: =D18*E18*DATOS!$B$22
B19: Longitudinales 3/8" en zapata | D19: 6 | E19: =DATOS!$B$26 | H19: =D19*E19*DATOS!$B$22
G20: TOTAL | I20: =SUM(H17:H19)
A22: 06.04 | B22: EMBOQUILLADO DE PIEDRA e=0.20 CON CONCRETO f'c=140 | C22: m2
B23: Piso entre aleros (trapecio) | D23: 1 | H23: =(DATOS!$B$5+DATOS!$B$32)/2*DATOS!$B$31
G24: TOTAL | I24: =SUM(H23:H23)

Sheet 07 JUNTAS Y EMPALMES
A1: 07 JUNTAS Y 08 EMPALMES
A2: CAR Mujeres (CUI 2717013) - Colector pluvial frontal b=1.50 m, preparado para CAR Varones y Hogar de Refugio - Morales, San Martin
A4: ITEM | B4: DESCRIPCION | C4: UND | D4: N. VECES | E4: LARGO (m) | F4: ANCHO (m) | G4: ALTO (m) | H4: PARCIAL | I4: TOTAL | J4: OBSERVACION
A5: 07.01 | B5: JUNTA DE DILATACION e=1" (poliestireno + sello elastomerico) EN EL COLECTOR | C5: m
B6: Tramo cubierto: perimetro de la seccion cerrada | D6: 33 | H6: =D6*(2*1.70+2*(AVERAGEIF(TRAMOS!D5:D79,"<="&9999,TRAMOS!I5:I79)+0.20))
B7: Tramo abierto: perimetro de la seccion en U | D7: 0 | H7: =D7*(1.70+2*(DATOS!$B$12+0.10))
G8: TOTAL | I8: =SUM(H6:H7)
A10: 07.02 | B10: JUNTA e=1" CON TECNOPOR ENTRE COLECTOR Y PISO ADYACENTE (lado predio, tramo en vereda) | C10: m
B11: Borde lado predio de la losa superior | D11: 1 | E11: =DATOS!$B$11 | H11: =D11*E11
G12: TOTAL | I12: =SUM(H11:H11)
A14: 08.01 | B14: EMPALME DE CUNETA AL COLECTOR (ventana en muro, caida y junta) | C14: und
B15: Ejes 02, 07, 10 y 12 | D15: =DATOS!$B$37 | H15: =D15 | J15: ventana 0.40 x 0.30 dejada al vaciar el muro, bajo un registro; junta 1" entre cuneta y colector (DP-06B)
G16: TOTAL | I16: =SUM(H15:H15)

Sheet 08 PLANILLA ACERO
A1: PLANILLA DE ACERO (despiece)
A2: CAR Mujeres (CUI 2717013) - Colector pluvial frontal b=1.50 m, preparado para CAR Varones y Hogar de Refugio - Morales, San Martin
A4: ELEMENTO | B4: DIAM. | C4: FORMA | D4: N. PIEZAS | E4: LONG. POR PIEZA (m) | F4: LONG. TOTAL (m) | G4: PESO (kg/m) | H4: PESO (kg) | I4: OBSERVACION
A5: Marcos en vereda y tramo final @0.20 | B5: 3/8" | C5: cerrado | D5: =SUMIF(TRAMOS!$E$5:$E$79,"NORMAL",TRAMOS!$V$5:$V$79) | E5: =IFERROR(SUMPRODUCT((TRAMOS!$E$5:$E$79="NORMAL")*TRAMOS!$V$5:$V$79*TRAMOS!$W$5:$W$79)/D5,0) | F5: =D5*E5 | G5: =DATOS!$B$22 | H5: =F5*G5 | I5: longitud media ponderada (incluye ganchos)
A6: Marcos en cruce de autos @0.15 | B6: 3/8" | C6: cerrado | D6: =SUMIF(TRAMOS!$E$5:$E$79,"AUTOS",TRAMOS!$V$5:$V$79) | E6: =IFERROR(SUMPRODUCT((TRAMOS!$E$5:$E$79="AUTOS")*TRAMOS!$V$5:$V$79*TRAMOS!$W$5:$W$79)/D6,0) | F6: =D6*E6 | G6: =DATOS!$B$22 | H6: =F6*G6 | I6: longitud media ponderada (incluye ganchos)
A7: Marcos dobles en cruce de camiones @0.15 | B7: 1/2" | C7: cerrado | D7: =SUMIF(TRAMOS!$E$5:$E$79,"CAMION",TRAMOS!$V$5:$V$79) | E7: =IFERROR(SUMPRODUCT((TRAMOS!$E$5:$E$79="CAMION")*TRAMOS!$V$5:$V$79*TRAMOS!$W$5:$W$79)/D7,0) | F7: =D7*E7 | G7: =DATOS!$B$23 | H7: =F7*G7 | I7: longitud media ponderada (incluye ganchos)
A8: Barras longitudinales (vereda, autos y final) @0.25 | B8: 3/8" | C8: recta | D8: =SUMPRODUCT((TRAMOS!$E$5:$E$79<>"CAMION")*TRAMOS!$X$5:$X$79*TRAMOS!$C$5:$C$79)/9 | E8: 9.4 | F8: =D8*E8 | G8: =DATOS!$B$22 | H8: =F8*G8 | I8: barras de 9 m con traslape 0.40 m
A9: Barras longitudinales (cruce de camiones) @0.20 | B9: 3/8" | C9: recta | D9: =SUMPRODUCT((TRAMOS!$E$5:$E$79="CAMION")*TRAMOS!$X$5:$X$79*TRAMOS!$C$5:$C$79)/9 | E9: 9.4 | F9: =D9*E9 | G9: =DATOS!$B$22 | H9: =F9*G9
A10: Registros: refuerzo de borde de abertura | B10: 1/2" | C10: recta | D10: =DATOS!$B$19*8 | E10: 1.4 | F10: =D10*E10 | G10: =DATOS!$B$23 | H10: =F10*G10
A11: Tapas de registro @0.10 (dos sentidos) | B11: 3/8" | C11: recta | D11: =DATOS!$B$19*14 | E11: 0.62 | F11: =D11*E11 | G11: =DATOS!$B$22 | H11: =F11*G11
A12: Asas de tapa (liso) | B12: 3/8" | C12: U | D12: =DATOS!$B$19*2 | E12: 0.4 | F12: =D12*E12 | G12: =DATOS!$B$22 | H12: =F12*G12
A13: Anclajes de contramarco | B13: 3/8" | C13: L | D13: =DATOS!$B$19*8 | E13: 0.2 | F13: =D13*E13 | G13: =DATOS!$B$22 | H13: =F13*G13
A14: Aleros: barras en L (vertical + zapata) @0.20 | B14: 3/8" | C14: L | D14: 12 | E14: 1.38 | F14: =D14*E14 | G14: =DATOS!$B$22 | H14: =F14*G14
A15: Aleros: horizontales en muro @0.20 | B15: 3/8" | C15: recta | D15: 10 | E15: 1 | F15: =D15*E15 | G15: =DATOS!$B$22 | H15: =F15*G15
A16: Aleros: longitudinales en zapata | B16: 3/8" | C16: recta | D16: 6 | E16: 1 | F16: =D16*E16 | G16: =DATOS!$B$22 | H16: =F16*G16
A18: TOTAL ACERO 3/8" | H18: =SUMIF(B5:B16,"3/8""",H5:H16)
A19: TOTAL ACERO 1/2" | H19: =SUMIF(B5:B16,"1/2""",H5:H16)
A20: TOTAL ACERO | H20: =H18+H19
