Workbook

Sheet RESUMEN
A1: ANÁLISIS DE COSTOS UNITARIOS - PARTIDAS GLOBALES (glb) DE INSTALACIONES SANITARIAS
A2: CREACIÓN DEL SERVICIO DE PROTECCIÓN INTEGRAL A NIÑAS, NIÑOS Y ADOLESCENTES SIN CUIDADOS PARENTALES O EN RIESGO DE PERDERLOS EN CENTRO DE ACOGIDA RESIDENCIAL - MUJERES, DISTRITO DE MORALES, PROVINCIA Y DEPARTAMENTO DE SAN MARTÍN (CAR Mujeres, CUI 2717013)
A3: Lugar: San Martín - San Martín - Morales. Fecha: Octubre 2026. Metrado: hoja PLANILLA del metrado de IISS (sin cambios).
A5: ÍTEM | B5: DESCRIPCIÓN | C5: UND | D5: METRADO | E5: PRECIO UNIT. (S/) | F5: PARCIAL (S/)
A6: 4.2.3.1.1 | B6: SUM. E INST. DE LINEA DE INGRESO A LA CISTERNA DE PVC SP D=1 1/4" | C6: glb | D6: 1 | E6: ='4.2.3.1.1'!$G$24 -> 475.52 | F6: =ROUND(D6*E6,2) -> 475.52
A7: 4.2.3.1.2 | B7: SUM. E INST. DE LINEA DE SUCCIÓN SISTEMA DE BOMBEO DE PVC SP D=1 1/2" | C7: glb | D7: 1 | E7: ='4.2.3.1.2'!$G$27 -> 1131.11 | F7: =ROUND(D7*E7,2) -> 1131.11
A8: 4.2.3.1.3 | B8: SUM. E INST. DE LINEA DE IMPULSIÓN SISTEMA DE BOMBEO DE PVC SP D=1" | C8: glb | D8: 1 | E8: ='4.2.3.1.3'!$G$39 -> 2304.67 | F8: =ROUND(D8*E8,2) -> 2304.67
A9: 4.2.3.1.4 | B9: SUM. E INST. DE LINEA DE DISTRIBUCION SISTEMA DE BOMBEO DE PVC SP D=2" | C9: glb | D9: 1 | E9: ='4.2.3.1.4'!$G$32 -> 1418.12 | F9: =ROUND(D9*E9,2) -> 1418.12
A10: 4.2.3.1.5 | B10: SUM. E INST. DE LINEA DE REBOSE TANQUE ELEVADO DE PVC SP D=2" | C10: glb | D10: 1 | E10: ='4.2.3.1.5'!$G$36 -> 2561.98 | F10: =ROUND(D10*E10,2) -> 2561.98
A11: 4.2.3.1.6 | B11: SUM. E INST. DE LINEA DE LIMPIA Y VENTILACION CISTERNA DE PVC SP D=2" | C11: glb | D11: 1 | E11: ='4.2.3.1.6'!$G$24 -> 443.11 | F11: =ROUND(D11*E11,2) -> 443.11
A12: 4.2.3.1.7 | B12: PRUEBA HIDRÁULICA DE ESTANQUEIDAD Y DESINFECCIÓN DE CISTERNA Y TANQUE ELEVADO | C12: glb | D12: 1 | E12: ='4.2.3.1.7'!$G$20 -> 1387.45 | F12: =ROUND(D12*E12,2) -> 1387.45
A13: 4.3.6.3.3 | B13: TECLE DE PALANCA P/CABALLETE | C13: glb | D13: 1 | E13: ='4.3.6.3.3'!$G$27 -> 2274.97 | F13: =ROUND(D13*E13,2) -> 2274.97
A14: COSTO DIRECTO DE LAS PARTIDAS GLOBALES (S/, sin IGV) | F14: =SUM(F6:F13) -> 11996.93
A16: NOTAS
A17: • Mano de obra: costo hora-hombre 2026 de la tabla oficial CAPECO - FTCCP (operario S/ 28.95, oficial S/ 22.68, peón S/ 20.54); ver hoja MANO DE OBRA 2026.
A18: • Materiales: precios de venta publicados (con IGV) en tiendas de alcance nacional, pasados a precio sin IGV; cada precio tiene su tienda y enlace en la hoja PRECIOS DE INSUMOS.
A19: • Las cantidades de materiales son las del desagregado de la planilla (más 5 % de desperdicio en tuberías). Las filas con unidad o parcial irregular se explican en las observaciones de cada ACU; el metrado no se ha modificado.
A20: • Rendimientos: se calculan por componente (días-cuadrilla) en cada ACU; son referenciales y editables (celdas amarillas).
A21: • Los precios unitarios son costo directo sin IGV; gastos generales, utilidad e IGV se agregan en el presupuesto.

Sheet MANO DE OBRA 2026
A1: COSTO DE LA HORA-HOMBRE 2026 - RÉGIMEN DE CONSTRUCCIÓN CIVIL
A2: CREACIÓN DEL SERVICIO DE PROTECCIÓN INTEGRAL A NIÑAS, NIÑOS Y ADOLESCENTES SIN CUIDADOS PARENTALES O EN RIESGO DE PERDERLOS EN CENTRO DE ACOGIDA RESIDENCIAL - MUJERES, DISTRITO DE MORALES, PROVINCIA Y DEPARTAMENTO DE SAN MARTÍN (CAR Mujeres, CUI 2717013)
A3: Tabla oficial CAPECO - FTCCP «Remuneración y condiciones de trabajo en construcción civil 2026» (Acta final de negociación colectiva, Exp. N.° 339-2025-MTPE/2.14-NC), costo hora-hombre en edificación del 01.01.2026 al 31.12.2026.
A5: DESGLOSE DEL COSTO DIARIO EN EDIFICACIÓN (S/ por día de 8 horas)
A6: N.° | B6: CONCEPTO | C6: OPERARIO | D6: OFICIAL | E6: PEÓN | F6: SUSTENTO
A7: 1 | B7: Remuneración básica (jornal diario) | C7: 89.3 | D7: 69.75 | E7: 62.8 | F7: R.M. 197-2025-TR; tabla oficial
A8: 2 | B8: Leyes y beneficios sociales sobre el jornal básico (112.20 %) | C8: =ROUND(C7*112.2/100,2) -> 100.19 | D8: =ROUND(D7*112.2/100,2) -> 78.26 | E8: =ROUND(E7*112.2/100,2) -> 70.46 | F8: tabla oficial
A9: 3 | B9: Bonificación unificada de construcción BUC (32 % / 30 % / 30 %) | C9: =ROUND(C7*0.32,2) -> 28.58 | D9: =ROUND(D7*0.3,2) -> 20.93 | E9: =ROUND(E7*0.3,2) -> 18.84 | F9: tabla oficial
A10: 4 | B10: Leyes y beneficios sociales sobre el BUC (12.25 %) | C10: =ROUND(C9*12.25/100,2) -> 3.5 | D10: =ROUND(D9*12.25/100,2) -> 2.56 | E10: =ROUND(E9*12.25/100,2) -> 2.31 | F10: tabla oficial
A11: 5 | B11: Seguro de vida ESSALUD + Vida | C11: 0.16 | D11: 0.16 | E11: 0.16 | F11: tabla oficial
A12: 6 | B12: Fondo de capacitación | C12: 0.4 | D12: 0.31 | E12: 0.28 | F12: tabla oficial
A13: 7 | B13: Bonificación por movilidad (R.M. N.° 139-2024-TR) | C13: 8.6 | D13: 8.6 | E13: 8.6 | F13: S/ 8.60 por día laborado
A14: 8 | B14: Overol (R.D. N.° 777-87-DR-LIM): (2 x S/ 132.80) / 300 | C14: =ROUND(2*132.8/300,2) -> 0.89 | D14: =ROUND(2*132.8/300,2) -> 0.89 | E14: =ROUND(2*132.8/300,2) -> 0.89 | F14: tabla oficial
B15: Total por día de 8 horas (S/) | C15: =SUM(C7:C14) -> 231.62 | D15: =SUM(D7:D14) -> 181.46 | E15: =SUM(E7:E14) -> 164.34
B16: COSTO DE LA HORA-HOMBRE (S/ hh) = total / 8 | C16: =ROUND(C15/8,2) -> 28.95 | D16: =ROUND(D15/8,2) -> 22.68 | E16: =ROUND(E15/8,2) -> 20.54 | F16: tabla oficial: 231.62 / 181.46 / 164.34 y 28.95 / 22.68 / 20.54

Sheet PRECIOS DE INSUMOS
A1: PRECIOS DE INSUMOS (materiales y equipos) - SUSTENTO
A2: CREACIÓN DEL SERVICIO DE PROTECCIÓN INTEGRAL A NIÑAS, NIÑOS Y ADOLESCENTES SIN CUIDADOS PARENTALES O EN RIESGO DE PERDERLOS EN CENTRO DE ACOGIDA RESIDENCIAL - MUJERES, DISTRITO DE MORALES, PROVINCIA Y DEPARTAMENTO DE SAN MARTÍN (CAR Mujeres, CUI 2717013)
A3: Precio publicado con IGV en la tienda indicada (venta nacional; Sodimac y Promart tienen tienda en Tarapoto) y precio unitario sin IGV = precio publicado / contenido / 1.18. Las ACU leen la columna H. Celda amarilla = dato editable (el ingeniero de costos puede reemplazarlo por su cotización y todo se recalcula); verde = fórmula.
A5: CÓDIGO | B5: INSUMO (como figura en la ACU) | C5: UND | D5: PRODUCTO PUBLICADO | E5: PRESENTACIÓN | F5: PRECIO CON IGV (S/) | G5: CONTENIDO (und ACU) | H5: PRECIO UNIT. SIN IGV (S/) | I5: TIENDA / FUENTE | J5: ENLACE | K5: ESTADO
A6: 1. INSUMOS COMERCIALES
A7: TB1 | B7: Tubería PVC SP C-10 Ø1" | C7: m | D7: Tubo agua PVC 1" x 5 m Pavco SP fría | E7: barra 5 m | F7: 26.9 | G7: 5 | H7: =ROUND(F7/G7/1.18,2) -> 4.56 | I7: Sodimac Perú | J7: https://www.sodimac.com.pe/sodimac-pe/b/tubo-pvc-1-pulgada | K7: EXACTO
A8: TB15 | B8: Tubería PVC SP C-10 Ø1 1/2" | C8: m | D8: Tubo x 5 m 1 1/2" simple presión agua fría Pavco (C-10) | E8: barra 5 m | F8: 51.9 | G8: 5 | H8: =ROUND(F8/G8/1.18,2) -> 8.8 | I8: Promart / Sodimac | J8: https://www.promart.pe/tubo-presion-c-10-ec-1-1-2-go/p | K8: EXACTO (mismo precio en ambas)
A9: TB2 | B9: Tubería PVC SP C-10 Ø2" | C9: m | D9: Tubo x 5 m 2" simple presión agua fría Pavco (C-10) | E9: barra 5 m | F9: 65.9 | G9: 5 | H9: =ROUND(F9/G9/1.18,2) -> 11.17 | I9: Promart | J9: https://www.promart.pe/tubo-presion-c-10-ec-2-go/p | K9: EXACTO (Sodimac S/ 85.90)
A10: CD1 | B10: Codo PVC SP Ø1" x 90° | C10: und | D10: Codo 90° 1" simple presión agua fría Pavco | E10: und | F10: 5.7 | G10: 1 | H10: =ROUND(F10/G10/1.18,2) -> 4.83 | I10: Promart / Sodimac | J10: https://www.promart.pe/codo-pvc-90--sp-1-go/p | K10: EXACTO
A11: CD15 | B11: Codo PVC SP Ø1 1/2" x 90° | C11: und | D11: Codo PVC 1 1/2" 90° Pavco SP agua fría | E11: und | F11: 10.9 | G11: 1 | H11: =ROUND(F11/G11/1.18,2) -> 9.24 | I11: Sodimac / Promart | J11: https://www.sodimac.com.pe/sodimac-pe/b/codo-1-1-2 | K11: EXACTO
A12: CD2 | B12: Codo PVC SP Ø2" x 90° | C12: und | D12: Codo 2" 90° SP agua fría Matusita | E12: und | F12: 15.9 | G12: 1 | H12: =ROUND(F12/G12/1.18,2) -> 13.47 | I12: Sodimac Perú | J12: https://www.sodimac.com.pe/sodimac-pe/b/codo-2-x-90 | K12: EXACTO (otra marca)
A13: CD245 | B13: Codo PVC SP Ø2" x 45° | C13: und | D13: Codo 45° 2" simple presión agua fría Pavco | E13: und | F13: 10.8 | G13: 1 | H13: =ROUND(F13/G13/1.18,2) -> 9.15 | I13: Promart | J13: https://www.promart.pe/codo-45-sp-2/p | K13: EXACTO (sin stock en línea)
A14: TE15 | B14: Tee PVC SP Ø1 1/2" | C14: und | D14: Tee 1 1/2" simple presión agua fría Pavco | E14: und | F14: 15.5 | G14: 1 | H14: =ROUND(F14/G14/1.18,2) -> 13.14 | I14: Promart | J14: https://www.promart.pe/tee-pvc-sp-1-1-2-go/p | K14: EXACTO (venta en tienda)
A15: TE2 | B15: Tee PVC SP Ø2" | C15: und | D15: Tee 2" PVC SP agua fría Pavco | E15: und | F15: 22.9 | G15: 1 | H15: =ROUND(F15/G15/1.18,2) -> 19.41 | I15: Sodimac Perú | J15: https://www.sodimac.com.pe/sodimac-pe/seleccion/conexiones | K15: EXACTO
A16: UU15 | B16: Unión universal PVC roscada Ø1 1/2" | C16: und | D16: Unión universal 1 1/2" PVC Sanking (agua fría, 150 psi) | E16: und | F16: 20 | G16: 1 | H16: =ROUND(F16/G16/1.18,2) -> 16.95 | I16: Sodimac Perú | J16: https://www.sodimac.com.pe/sodimac-pe/product/217298/union-universal-1-1-2/217298/ | K16: EXACTO
A17: UU2 | B17: Unión universal PVC roscada Ø2" | C17: und | D17: Sanking unión universal 2" PVC C/R | E17: und | F17: 49.9 | G17: 1 | H17: =ROUND(F17/G17/1.18,2) -> 42.29 | I17: Falabella (vende Sodimac) | J17: https://www.falabella.com.pe/falabella-pe/brand/SANKING | K17: EXACTO
A18: UPR2 | B18: Adaptador UPR PVC Ø2" | C18: und | D18: Adaptador PVC enroscado Pavco 2" (PR) | E18: und | F18: 10.9 | G18: 1 | H18: =ROUND(F18/G18/1.18,2) -> 9.24 | I18: Promart / Sodimac | J18: https://www.promart.pe/adaptador-pr-2/p | K18: EST. (adaptador PR equivalente al UPR)
... A22: NP15 | B22: Niple roscado PVC Ø1 1/2" x 2" | C22: und | D22: Niple 1 1/2" x 2" roscado agua fría Nicoll | E22: und | F22: 4.4 | G22: 1 | H22: =ROUND(F22/G22/1.18,2) -> 3.73 | I22: Promart | J22: https://www.promart.pe/niple-1-1-2--x-2--c-r---term/p | K22: EXACTO
A23: NP2 | B23: Niple roscado PVC Ø2" (x 4" y x 6") | C23: und | D23: Tubo PVC C-10 roscado 2" x 5 m, cortado en niples de 6" (33 por tubo) | E23: barra 5 m | F23: 94.9 | G23: =5/0.15 -> 33.333333 | H23: =ROUND(F23/G23/1.18,2) -> 2.41 | I23: Promart | J23: https://www.promart.pe/tubo-presion-c-10-ec-2-go/p | K23: EST. (no se publica el niple PVC 2"; roscado con tarraja incluido en la mano de obra)
A24: RD15 | B24: Reducción PVC SP Ø1 1/2" x 3/4" | C24: und | D24: Reducción simple presión 2" x 3/4" Nicoll (referencia) | E24: und | F24: 10 | G24: 1 | H24: =ROUND(F24/G24/1.18,2) -> 8.47 | I24: Promart | J24: https://www.promart.pe/reduccion-simple-presion-2--x-3-4/p | K24: EST. (la de 1 1/2" x 3/4" figura sin precio)
A25: RD2 | B25: Reducción PVC SP Ø2" x 1" | C25: und | D25: Reducción SP 2" a 1" agua fría Pavco | E25: und | F25: 9.9 | G25: 1 | H25: =ROUND(F25/G25/1.18,2) -> 8.39 | I25: Promart | J25: https://www.promart.pe/reduccion-sp-2-1/p | K25: EXACTO
A26: VCH15 | B26: Válvula check Ø1 1/2" | C26: und | D26: Válvula check swing 1 1/2" bronce ITAP (NPT) | E26: und | F26: 109.9 | G26: 1 | H26: =ROUND(F26/G26/1.18,2) -> 93.14 | I26: Sodimac Perú | J26: https://www.sodimac.com.pe/sodimac-pe/articulo/113306910/Valvula-Check-Swing-1-1-2-/113306914 | K26: EST. (no se vende check de PVC 1 1/2"; se toma la de bronce)
A27: VEP15 | B27: Válvula esférica PVC Ø1 1/2" | C27: und | D27: Válvula bola PVC con rosca 1 1/2" Sanking (145 psi) | E27: und | F27: 24.9 | G27: 1 | H27: =ROUND(F27/G27/1.18,2) -> 21.1 | I27: Promart | J27: https://www.promart.pe/valvula-bola-pvc-1-1-2--con-rosca/p | K27: EXACTO
A28: VEB15 | B28: Válvula esférica bronce pesado Ø1 1/2" | C28: und | D28: Válvula esférica bronce NPT 1 1/2" CIM 400 psi | E28: und | F28: 179.9 | G28: 1 | H28: =ROUND(F28/G28/1.18,2) -> 152.46 | I28: Promart | J28: https://www.promart.pe/valvula-esferica-p-total-400-lbs-1-1-2-/p | K28: EXACTO (agotada en línea)
A29: VCB2 | B29: Válvula compuerta bronce pesado Ø2" | C29: und | D29: Válvula compuerta bronce 2" CIM, rosca NPT | E29: und | F29: 80 | G29: 1 | H29: =ROUND(F29/G29/1.18,2) -> 67.8 | I29: Icofesa | J29: https://icofesa.com/producto.php?id=15544 | K29: EXACTO (confirmar que sea pesada)
A30: VF1 | B30: Válvula flotadora bronce Ø1" | C30: und | D30: Galusa válvula para cisterna con boya 1" | E30: und | F30: 169.9 | G30: 1 | H30: =ROUND(F30/G30/1.18,2) -> 143.98 | I30: Sodimac Perú | J30: https://www.sodimac.com.pe/sodimac-pe/b/boya-para-tanque-de-agua | K30: EST. (la ficha no indica el material)
A31: VF15 | B31: Válvula flotadora bronce Ø1 1/2" | C31: und | D31: Válvula flotadora 1 1/2" bronce con boya de cobre Helbert | E31: und | F31: 370 | G31: 1 | H31: =ROUND(F31/G31/1.18,2) -> 313.56 | I31: Maveri | J31: https://maveri.com/producto/valvula-flotadora-de-1-1-2-bronce-c-boya-de-cobre-helbert/ | K31: EXACTO
A32: CAN15 | B32: Canastilla de succión Ø1 1/2" | C32: und | D32: ITAP válvula check de pie 1 1/2" con canastilla | E32: und | F32: 95.9 | G32: 1 | H32: =ROUND(F32/G32/1.18,2) -> 81.27 | I32: Sodimac Perú | J32: https://www.sodimac.com.pe/sodimac-pe/marca/ITAP | K32: EST. (no se vende canastilla PVC 1 1/2"; válvula de pie con canastilla)
A33: ELN | B33: Electronivel (interruptor de nivel tipo pera) | C33: und | D33: Electronivel 3 m Rotoplas (hasta 1 HP a 220 V) | E33: und | F33: 89.9 | G33: 1 | H33: =ROUND(F33/G33/1.18,2) -> 76.19 | I33: Promart | J33: https://www.promart.pe/electronivel-de-3-metros-23057/p | K33: EXACTO (se toma el mayor de S/ 68.00 a 89.90)
A34: UFG1 | B34: Unión F°G° roscada Ø1" | C34: und | D34: Unión simple galvanizada 1" Magnum Mech | E34: und | F34: 6.9 | G34: 1 | H34: =ROUND(F34/G34/1.18,2) -> 5.85 | I34: Sodimac Perú | J34: https://www.sodimac.com.pe/sodimac-pe/b/union-universal-1-pulgada | K34: EXACTO
A35: UFG15 | B35: Unión F°G° roscada Ø1 1/2" | C35: und | D35: Unión simple galvanizada 1 1/2" Magnum Mech | E35: und | F35: 14.9 | G35: 1 | H35: =ROUND(F35/G35/1.18,2) -> 12.63 | I35: Sodimac Perú | J35: https://www.sodimac.com.pe/sodimac-pe/articulo/113328852/Union-Simple-Galvanizado-1-1-2-/113328853 | K35: EXACTO
... A43: TAR | B43: Perno de anclaje 3/8" para fijar abrazaderas | C43: und | D43: Perno de anclaje 3/8" x 3 3/4" FIXSER (paquete x 4) | E43: paquete x 4 | F43: 37.9 | G43: 4 | H43: =ROUND(F43/G43/1.18,2) -> 8.03 | I43: Falabella (vende Sodimac) | J43: https://www.falabella.com.pe/falabella-pe/product/113091980/Perno-de-Anclaje-3-8x3-3-4-Pulgadas-x-4-unid/113092005 | K43: EXACTO (conservador; con tarugo y tornillo sale más barato)
A44: PLA | B44: Plancha LAC 1/8" (24.91 kg/m²) | C44: kg | D44: Plancha LAC 1/8" x 4' x 8' (1.20 x 2.40 m) | E44: plancha | F44: 189.93 | G44: =1.2*2.4*24.91 -> 71.7408 | H44: =ROUND(F44/G44/1.18,2) -> 2.24 | I44: Huval | J44: https://www.huvalnegocios.com/product/plancha-lac-316x4x8-44 | K44: COTIZAR (precio tomado de productos relacionados)
A45: SOMB2 | B45: Sombrero de ventilación PVC Ø2" | C45: und | D45: Sombrero de ventilación PVC 2" Pavco | E45: und | F45: 6.2 | G45: 1 | H45: =ROUND(F45/G45/1.18,2) -> 5.25 | I45: Sodimac Perú | J45: https://sodimac.falabella.com.pe/sodimac-pe/product/113328544/Sombrero-de-Ventilacion-PVC-2-Desague/113328546 | K45: EXACTO
A46: MALLA | B46: Malla mosquitero metálica | C46: m2 | D46: Malla mosquitero metálica Prodac 0.90 x 30 m | E46: rollo 27 m² | F46: 129.9 | G46: 27 | H46: =ROUND(F46/G46/1.18,2) -> 4.08 | I46: Sodimac Perú | J46: https://www.sodimac.com.pe/sodimac-pe/lista/CATG15054/Mallas | K46: EXACTO
A47: PEG | B47: Pegamento para PVC | C47: gal | D47: Pegamento PVC Oatey dorado 946 ml (1/4 gal) | E47: 1/4 gal | F47: 61.9 | G47: 0.25 | H47: =ROUND(F47/G47/1.18,2) -> 209.83 | I47: Sodimac Perú | J47: https://www.sodimac.com.pe/sodimac-pe/b/pegamento-para-pvc-1-4 | K47: EXACTO
A48: TEF | B48: Cinta teflón 3/4" x 10 m | C48: und | D48: Cinta teflón Topex 3/4" x 10 m | E48: rollo | F48: 2.9 | G48: 1 | H48: =ROUND(F48/G48/1.18,2) -> 2.46 | I48: Sodimac Perú | J48: https://www.sodimac.com.pe/sodimac-pe/lista/CATG14985/Teflones-y-sellos | K48: EXACTO
A49: SOLD | B49: Soldadura cellocord E6011 1/8" | C49: kg | D49: Soldadura Cellocord 1/8" (E-6011) Oerlikon | E49: caja 5 kg | F49: 109.9 | G49: 5 | H49: =ROUND(F49/G49/1.18,2) -> 18.63 | I49: Sodimac Perú | J49: https://www.sodimac.com.pe/sodimac-pe/articulo/113780372/Soldadura-Cellocord-1-8-Oerlikon-5KG/113780373 | K49: EXACTO
A50: SOLM | B50: Máquina de soldar eléctrica 250 A | C50: hm | D50: Alquiler de máquina de soldar (por día de 8 h) | E50: día | F50: 55 | G50: 8 | H50: =ROUND(F50/G50/1.18,2) -> 5.83 | I50: ST América | J50: https://stamerica.com.pe/alquiler_maquina_soldar | K50: REFERENCIA (tarifa de Lima; compra Truper 200 A S/ 469.90)
A51: AGUA | B51: Agua | C51: m3 | D51: EMAPA San Martín, categoría comercial y otros, tramo de 30 m³ a más: agua 6.80 + alcantarillado 1.53 | E51: m3 | F51: 8.33 | G51: 1 | H51: =ROUND(F51/G51/1,2) -> 8.33 | I51: Res. 00077-2024-SUNASS-CD (tarifa sin IGV) | J51: https://www.emapasanmartin.com/uploads/Gobernanza%20Gobernabilidad/Gobernabilidad/transparencia-informacion/indicador-8/2025/Publicacion%20Oficial%20-%20Diario%20Oficial%20El%20Peruano%20ESTRUCTURA%20TARIFARIA.pdf | K51: COMPROBADO (mismo valor que la planilla del Hogar de Refugio)
...

Sheet 4.2.3.1.1
A1: ANÁLISIS DE COSTOS UNITARIOS
A2: CREACIÓN DEL SERVICIO DE PROTECCIÓN INTEGRAL A NIÑAS, NIÑOS Y ADOLESCENTES SIN CUIDADOS PARENTALES O EN RIESGO DE PERDERLOS EN CENTRO DE ACOGIDA RESIDENCIAL - MUJERES, DISTRITO DE MORALES, PROVINCIA Y DEPARTAMENTO DE SAN MARTÍN (CAR Mujeres, CUI 2717013)
A3: Partida | B3: 4.2.3.1.1 SUM. E INST. DE LINEA DE INGRESO A LA CISTERNA DE PVC SP D=1 1/4"
A4: Rend. | B4: =G33 -> 1.1289 | C4: MO | D4: =SUM(E9:E10) -> 10.6298 | E4: EQ | F4: =SUMIF(C21:C22,"hm",E21:E22) -> 0.5 | G4: Costo unit. directo por glb (S/) | H4: =G24 -> 475.52
A5: Metrado | B5: 1 glb (planilla, hoja RESUMEN) | C5: Lugar | D5: San Martín - San Martín - Morales | G5: Fecha | H5: Octubre 2026
A7: CÓDIGO | B7: DESCRIPCIÓN DEL RECURSO | C7: UND | D7: CUADRILLA | E7: CANTIDAD | F7: PRECIO S/ | G7: PARCIAL S/ | H7: SUSTENTO
A8: MANO DE OBRA
A9: 47-0001 | B9: Operario | C9: hh | D9: 1 | E9: =ROUND(D9*8/$B$4,4) -> 7.0865 | F9: ='MANO DE OBRA 2026'!$C$16 -> 28.95 | G9: =ROUND(E9*F9,2) -> 205.15 | H9: cantidad = cuadrilla x 8 h / rendimiento; costo HH CAPECO - FTCCP 2026
A10: 47-0003 | B10: Peón | C10: hh | D10: 0.5 | E10: =ROUND(D10*8/$B$4,4) -> 3.5433 | F10: ='MANO DE OBRA 2026'!$E$16 -> 20.54 | G10: =ROUND(E10*F10,2) -> 72.78 | H10: cantidad = cuadrilla x 8 h / rendimiento; costo HH CAPECO - FTCCP 2026
B11: Subtotal mano de obra | G11: =SUM(G9:G10) -> 277.93
A12: MATERIALES
A13: TB1 | B13: Tubería PVC SP C-10 de Ø=1" - NTP 399.002:2015 | C13: m | E13: =(6)*1.05 -> 6.3 | F13: ='PRECIOS DE INSUMOS'!$H$7 -> 4.56 | G13: =ROUND(E13*F13,2) -> 28.73 | H13: planilla fila 438: 6 m; + 5 % de desperdicio
A14: VF1 | B14: Válvula Flotadora de Bronce de Ø=1" | C14: und | E14: 1 | F14: ='PRECIOS DE INSUMOS'!$H$30 -> 143.98 | G14: =ROUND(E14*F14,2) -> 143.98 | H14: planilla fila 439: 1 und
A15: UFG1 | B15: Unión roscado de F°G°de Ø=1" | C15: und | E15: 1 | F15: ='PRECIOS DE INSUMOS'!$H$34 -> 5.85 | G15: =ROUND(E15*F15,2) -> 5.85 | H15: planilla fila 440: sin parcial (se toma 1, ver obs.)
A16: BR01 | B16: Brida rompe agua Ø1" PL 0.15x0.15 e=1/8" (niple F°G° 3/4" L=0.35) | C16: und | E16: 1 | F16: ='PRECIOS DE INSUMOS'!$H$64 -> 5.48 | G16: =ROUND(E16*F16,2) -> 5.48 | H16: planilla fila 441: 1 und
A17: PEG | B17: Pegamento para PVC | C17: gal | E17: 0.0036 | F17: ='PRECIOS DE INSUMOS'!$H$47 -> 209.83 | G17: =ROUND(E17*F17,2) -> 0.76 | H17: 1 uniones pegadas (≈0.003 / 0.005 / 0.007 gal por unión de Ø1" / 1 1/2" / 2")
A18: TEF | B18: Cinta teflón 3/4" x 10 m | C18: und | E18: 0.62 | F18: ='PRECIOS DE INSUMOS'!$H$48 -> 2.46 | G18: =ROUND(E18*F18,2) -> 1.53 | H18: 5 extremos roscados ≈ 2 roscas macho; 1 rollo cada 4 roscas
B19: Subtotal materiales | G19: =SUM(G13:G18) -> 186.33
A20: EQUIPOS Y HERRAMIENTAS
A21: 37-0001 | B21: Herramientas manuales | C21: %MO | E21: 3 | F21: =G11 -> 277.93 | G21: =ROUND(E21/100*F21,2) -> 8.34 | H21: 3 % de la mano de obra (tarraja, llaves, sierra, taladro)
A22: SOLM | B22: Máquina de soldar eléctrica 250 A | C22: hm | E22: 0.5 | F22: ='PRECIOS DE INSUMOS'!$H$50 -> 5.83 | G22: =ROUND(E22*F22,2) -> 2.92 | H22: 0.5 h por brida rompe agua (1 bridas)
B23: Subtotal equipos y herramientas | G23: =SUM(G21:G22) -> 11.26
A24: COSTO UNITARIO DIRECTO POR glb (S/) | G24: =G11+G19+G23 -> 475.52
A26: CÁLCULO DEL RENDIMIENTO (días-cuadrilla por componente)
A27: TIPO | B27: COMPONENTE | C27: UND | E27: CANTIDAD | F27: REND. (und/día) | G27: DÍAS | H27: CRITERIO
A28: tubo1 | B28: Tubería PVC SP Ø1" (tendido, corte, unión y fijación) | C28: m | E28: 6 | F28: 25 | G28: =E28/F28 -> 0.24 | H28: rendimiento adoptado (referencial, editable)
A29: flot | B29: Válvula flotadora con boya (instalación y regulación) | C29: und | E29: 1 | F29: 4 | G29: =E29/F29 -> 0.25 | H29: rendimiento adoptado (referencial, editable)
A30: fg | B30: Accesorio F°G° roscado (unión, codo, niple) | C30: und | E30: 1 | F30: 16 | G30: =E30/F30 -> 0.0625 | H30: rendimiento adoptado (referencial, editable)
A31: brida | B31: Brida rompe agua (corte, soldadura, roscado y fijación al encofrado) | C31: und | E31: 1 | F31: 3 | G31: =E31/F31 -> 0.33333333 | H31: rendimiento adoptado (referencial, editable)
B32: Total días-cuadrilla para 1 glb | G32: =SUM(G28:G31) -> 0.88583333
B33: Rendimiento = 1 / total días (glb/día) | G33: =ROUND(1/G32,4) -> 1.1289
A35: OBSERVACIONES
A36: • Ingreso a cisterna. El título dice D=1 1/4" pero el desagregado de la planilla es de Ø1"; se analiza lo desagregado.
A37: • fila 440: la planilla no lleva el parcial (columna I vacía); se toma N.° veces 1 x cantidad 1 = 1 und

Sheet 4.2.3.1.2
A1: ANÁLISIS DE COSTOS UNITARIOS
A2: CREACIÓN DEL SERVICIO DE PROTECCIÓN INTEGRAL A NIÑAS, NIÑOS Y ADOLESCENTES SIN CUIDADOS PARENTALES O EN RIESGO DE PERDERLOS EN CENTRO DE ACOGIDA RESIDENCIAL - MUJERES, DISTRITO DE MORALES, PROVINCIA Y DEPARTAMENTO DE SAN MARTÍN (CAR Mujeres, CUI 2717013)
A3: Partida | B3: 4.2.3.1.2 SUM. E INST. DE LINEA DE SUCCIÓN SISTEMA DE BOMBEO DE PVC SP D=1 1/2"
A4: Rend. | B4: =G37 -> 0.4727 | C4: MO | D4: =SUM(E9:E10) -> 25.3861 | E4: EQ | F4: =SUMIF(C24:C25,"hm",E24:E25) -> 1 | G4: Costo unit. directo por glb (S/) | H4: =G27 -> 1131.11
A5: Metrado | B5: 1 glb (planilla, hoja RESUMEN) | C5: Lugar | D5: San Martín - San Martín - Morales | G5: Fecha | H5: Octubre 2026
A7: CÓDIGO | B7: DESCRIPCIÓN DEL RECURSO | C7: UND | D7: CUADRILLA | E7: CANTIDAD | F7: PRECIO S/ | G7: PARCIAL S/ | H7: SUSTENTO
A8: MANO DE OBRA
A9: 47-0001 | B9: Operario | C9: hh | D9: 1 | E9: =ROUND(D9*8/$B$4,4) -> 16.9241 | F9: ='MANO DE OBRA 2026'!$C$16 -> 28.95 | G9: =ROUND(E9*F9,2) -> 489.95 | H9: cantidad = cuadrilla x 8 h / rendimiento; costo HH CAPECO - FTCCP 2026
A10: 47-0003 | B10: Peón | C10: hh | D10: 0.5 | E10: =ROUND(D10*8/$B$4,4) -> 8.462 | F10: ='MANO DE OBRA 2026'!$E$16 -> 20.54 | G10: =ROUND(E10*F10,2) -> 173.81 | H10: cantidad = cuadrilla x 8 h / rendimiento; costo HH CAPECO - FTCCP 2026
B11: Subtotal mano de obra | G11: =SUM(G9:G10) -> 663.76
A12: MATERIALES
A13: BR02 | B13: Brida rompe agua Ø1 1/2" PL 0.15x0.15 e=1/8" (niple F°G° 1 1/2" L=0.25) | C13: und | E13: 2 | F13: ='PRECIOS DE INSUMOS'!$H$65 -> 7.29 | G13: =ROUND(E13*F13,2) -> 14.58 | H13: planilla fila 444: 2 und
A14: TB15 | B14: Tubería PVC SP C-10 Ø1 1/2" del tramo de succión (planilla: «Canastilla de PVC-U Ø1 1/2"» 4.64 m) | C14: m | E14: =(4.64)*1.05 -> 4.872 | F14: ='PRECIOS DE INSUMOS'!$H$8 -> 8.8 | G14: =ROUND(E14*F14,2) -> 42.87 | H14: planilla fila 445: 4.64 m; + 5 % de desperdicio
A15: CAN15 | B15: Canastilla de succión PVC Ø1 1/2" | C15: und | E15: 2 | F15: ='PRECIOS DE INSUMOS'!$H$32 -> 81.27 | G15: =ROUND(E15*F15,2) -> 162.54 | H15: ver observación
A16: SK15 | B16: Unión Socket PVC C-10 de ∅=1 1/2" (Rosca Hembra) | C16: und | E16: 2 | F16: ='PRECIOS DE INSUMOS'!$H$19 -> 7.12 | G16: =ROUND(E16*F16,2) -> 14.24 | H16: planilla fila 446: 2 und
A17: TE15 | B17: Tee PVC SP C-10 de Ø=1 1/2" | C17: und | E17: 2 | F17: ='PRECIOS DE INSUMOS'!$H$14 -> 13.14 | G17: =ROUND(E17*F17,2) -> 26.28 | H17: planilla fila 447: 2 und
A18: TP15 | B18: Tapón hembra de PVC SP C-10 de Ø=1 1/2" | C18: und | E18: 2 | F18: ='PRECIOS DE INSUMOS'!$H$21 -> 8.14 | G18: =ROUND(E18*F18,2) -> 16.28 | H18: planilla fila 448: 2 und
A19: ELN | B19: Electronivel conectado a bombas | C19: und | E19: 2 | F19: ='PRECIOS DE INSUMOS'!$H$33 -> 76.19 | G19: =ROUND(E19*F19,2) -> 152.38 | H19: planilla fila 449: 2 und
A20: PEG | B20: Pegamento para PVC | C20: gal | E20: 0.0446 | F20: ='PRECIOS DE INSUMOS'!$H$47 -> 209.83 | G20: =ROUND(E20*F20,2) -> 9.36 | H20: 9 uniones pegadas (≈0.003 / 0.005 / 0.007 gal por unión de Ø1" / 1 1/2" / 2")
A21: TEF | B21: Cinta teflón 3/4" x 10 m | C21: und | E21: 1.25 | F21: ='PRECIOS DE INSUMOS'!$H$48 -> 2.46 | G21: =ROUND(E21*F21,2) -> 3.08 | H21: 10 extremos roscados ≈ 5 roscas macho; 1 rollo cada 4 roscas
B22: Subtotal materiales | G22: =SUM(G13:G21) -> 441.61
A23: EQUIPOS Y HERRAMIENTAS
A24: 37-0001 | B24: Herramientas manuales | C24: %MO | E24: 3 | F24: =G11 -> 663.76 | G24: =ROUND(E24/100*F24,2) -> 19.91 | H24: 3 % de la mano de obra (tarraja, llaves, sierra, taladro)
A25: SOLM | B25: Máquina de soldar eléctrica 250 A | C25: hm | E25: 1 | F25: ='PRECIOS DE INSUMOS'!$H$50 -> 5.83 | G25: =ROUND(E25*F25,2) -> 5.83 | H25: 0.5 h por brida rompe agua (2 bridas)
B26: Subtotal equipos y herramientas | G26: =SUM(G24:G25) -> 25.74
A27: COSTO UNITARIO DIRECTO POR glb (S/) | G27: =G11+G22+G26 -> 1131.11
A29: CÁLCULO DEL RENDIMIENTO (días-cuadrilla por componente)
A30: TIPO | B30: COMPONENTE | C30: UND | E30: CANTIDAD | F30: REND. (und/día) | G30: DÍAS | H30: CRITERIO
A31: brida | B31: Brida rompe agua (corte, soldadura, roscado y fijación al encofrado) | C31: und | E31: 2 | F31: 3 | G31: =E31/F31 -> 0.66666667 | H31: rendimiento adoptado (referencial, editable)
A32: tubo15 | B32: Tubería PVC SP Ø1 1/2" | C32: m | E32: 4.64 | F32: 20 | G32: =E32/F32 -> 0.232 | H32: rendimiento adoptado (referencial, editable)
A33: canast | B33: Canastilla de succión | C33: und | E33: 2 | F33: 8 | G33: =E33/F33 -> 0.25 | H33: rendimiento adoptado (referencial, editable)
A34: acc15 | B34: Accesorio PVC hasta Ø1 1/2" (codo, tee, unión, niple, reducción, tapón) | C34: und | E34: 6 | F34: 20 | G34: =E34/F34 -> 0.3 | H34: rendimiento adoptado (referencial, editable)
A35: elec | B35: Electronivel (montaje, regulación y conexión al tablero de bombas) | C35: und | E35: 2 | F35: 3 | G35: =E35/F35 -> 0.66666667 | H35: rendimiento adoptado (referencial, editable)
B36: Total días-cuadrilla para 1 glb | G36: =SUM(G31:G35) -> 2.1153333
B37: Rendimiento = 1 / total días (glb/día) | G37: =ROUND(1/G36,4) -> 0.4727
A39: OBSERVACIONES
A40: • fila 445: «Canastilla de PVC-U Ø1 1/2"» figura con 4.64 m; se analiza como 4.64 m de tubería Ø1 1/2" del tramo de succión + 2 canastillas (una por bomba, igual que las 2 tees, 2 tapones y 2 electroniveles)

Sheet 4.2.3.1.3
A1: ANÁLISIS DE COSTOS UNITARIOS
A2: CREACIÓN DEL SERVICIO DE PROTECCIÓN INTEGRAL A NIÑAS, NIÑOS Y ADOLESCENTES SIN CUIDADOS PARENTALES O EN RIESGO DE PERDERLOS EN CENTRO DE ACOGIDA RESIDENCIAL - MUJERES, DISTRITO DE MORALES, PROVINCIA Y DEPARTAMENTO DE SAN MARTÍN (CAR Mujeres, CUI 2717013)
A3: Partida | B3: 4.2.3.1.3 SUM. E INST. DE LINEA DE IMPULSIÓN SISTEMA DE BOMBEO DE PVC SP D=1"
A4: Rend. | B4: =G52 -> 0.2794 | C4: MO | D4: =SUM(E9:E10) -> 42.9492 | E4: EQ | F4: =SUMIF(C36:C37,"hm",E36:E37) -> 0.5 | G4: Costo unit. directo por glb (S/) | H4: =G39 -> 2304.67
A5: Metrado | B5: 1 glb (planilla, hoja RESUMEN) | C5: Lugar | D5: San Martín - San Martín - Morales | G5: Fecha | H5: Octubre 2026
A7: CÓDIGO | B7: DESCRIPCIÓN DEL RECURSO | C7: UND | D7: CUADRILLA | E7: CANTIDAD | F7: PRECIO S/ | G7: PARCIAL S/ | H7: SUSTENTO
A8: MANO DE OBRA
A9: 47-0001 | B9: Operario | C9: hh | D9: 1 | E9: =ROUND(D9*8/$B$4,4) -> 28.6328 | F9: ='MANO DE OBRA 2026'!$C$16 -> 28.95 | G9: =ROUND(E9*F9,2) -> 828.92 | H9: cantidad = cuadrilla x 8 h / rendimiento; costo HH CAPECO - FTCCP 2026
A10: 47-0003 | B10: Peón | C10: hh | D10: 0.5 | E10: =ROUND(D10*8/$B$4,4) -> 14.3164 | F10: ='MANO DE OBRA 2026'!$E$16 -> 20.54 | G10: =ROUND(E10*F10,2) -> 294.06 | H10: cantidad = cuadrilla x 8 h / rendimiento; costo HH CAPECO - FTCCP 2026
B11: Subtotal mano de obra | G11: =SUM(G9:G10) -> 1122.98
A12: MATERIALES
A13: CD15 | B13: Codo PVC SP C-10 de Ø=1 1/2" x 90° | C13: und | E13: 3 | F13: ='PRECIOS DE INSUMOS'!$H$11 -> 9.24 | G13: =ROUND(E13*F13,2) -> 27.72 | H13: planilla fila 453: 3 und
A14: VCH15 | B14: Válvula Check de PVC Ø=1 1/2" | C14: und | E14: 1 | F14: ='PRECIOS DE INSUMOS'!$H$26 -> 93.14 | G14: =ROUND(E14*F14,2) -> 93.14 | H14: planilla fila 454: 1 und
A15: UU15 | B15: Unión universal roscado de PVC C-10 de Ø=1 1/2" | C15: und | E15: =2+1 -> 3 | F15: ='PRECIOS DE INSUMOS'!$H$16 -> 16.95 | G15: =ROUND(E15*F15,2) -> 50.85 | H15: planilla fila 455: 2 und + planilla fila 461: 1 und
A16: VEP15 | B16: Válvula Esferica de PVC Ø=1 1/2" | C16: und | E16: 1 | F16: ='PRECIOS DE INSUMOS'!$H$27 -> 21.1 | G16: =ROUND(E16*F16,2) -> 21.1 | H16: planilla fila 456: 1 und
A17: TE15 | B17: Tee PVC SP C-10 de Ø=1 1/2" | C17: und | E17: 1 | F17: ='PRECIOS DE INSUMOS'!$H$14 -> 13.14 | G17: =ROUND(E17*F17,2) -> 13.14 | H17: planilla fila 457: 1 und
A18: TB15 | B18: Tubería PVC SP C-10 de Ø=1 1/2" - NTP 399.002:2015 | C18: m | E18: =(15)*1.05 -> 15.75 | F18: ='PRECIOS DE INSUMOS'!$H$8 -> 8.8 | G18: =ROUND(E18*F18,2) -> 138.6 | H18: planilla fila 458: 15 m; + 5 % de desperdicio
A19: NP15 | B19: Niple roscado de PVC C-10 de Ø=1 1/2" x 2" | C19: und | E19: =1+6 -> 7 | F19: ='PRECIOS DE INSUMOS'!$H$22 -> 3.73 | G19: =ROUND(E19*F19,2) -> 26.11 | H19: planilla fila 459: 1 und + planilla fila 464: 6 und
A20: RD15 | B20: Reducción PVC SP C-10 de Ø=1 1/2" x 3/4" | C20: und | E20: 1 | F20: ='PRECIOS DE INSUMOS'!$H$24 -> 8.47 | G20: =ROUND(E20*F20,2) -> 8.47 | H20: planilla fila 460: 1 und
A21: VEB15 | B21: Válvula esférica roscado de Bronce Pesado de Ø=1 1/2" | C21: und | E21: 1 | F21: ='PRECIOS DE INSUMOS'!$H$28 -> 152.46 | G21: =ROUND(E21*F21,2) -> 152.46 | H21: planilla fila 462: 1 und
A22: TP15 | B22: Tapón Hembra PVC Ø=1 1/2" | C22: und | E22: 1 | F22: ='PRECIOS DE INSUMOS'!$H$21 -> 8.14 | G22: =ROUND(E22*F22,2) -> 8.14 | H22: planilla fila 463: 1 und
A23: AB15 | B23: Abrazadera de F°G° e= 1/8" P/Tubería de Ø 1 1/2" | C23: und | E23: 8 | F23: ='PRECIOS DE INSUMOS'!$H$41 -> 1.19 | G23: =ROUND(E23*F23,2) -> 9.52 | H23: planilla fila 465: 8 und
A24: SK15 | B24: Unión Socket PVC C-10 de ∅=1 1/2" (Rosca Hembra) | C24: und | E24: 1 | F24: ='PRECIOS DE INSUMOS'!$H$19 -> 7.12 | G24: =ROUND(E24*F24,2) -> 7.12 | H24: planilla fila 466: 1 und
A25: CFG15 | B25: Codo roscado de F°G° de Ø=1 1/2" x 90° | C25: und | E25: 1 | F25: ='PRECIOS DE INSUMOS'!$H$36 -> 14.32 | G25: =ROUND(E25*F25,2) -> 14.32 | H25: planilla fila 467: 1 und
A26: BR02 | B26: Brida rompe agua Ø1 1/2" PL 0.15x0.15 e=1/8" (niple F°G° 1 1/2" L=0.25) | C26: und | E26: 1 | F26: ='PRECIOS DE INSUMOS'!$H$65 -> 7.29 | G26: =ROUND(E26*F26,2) -> 7.29 | H26: planilla fila 468: 1 und
A27: NFG15 | B27: Niple Roscado de F°G° de Ø=1 1/2", L=0.60 m - Rosca Ambos Lados - Norma ISO 65 - Serie I (Estándar) | C27: m | E27: =(1)*0.6 -> 0.6 | F27: ='PRECIOS DE INSUMOS'!$H$38 -> 15.21 | G27: =ROUND(E27*F27,2) -> 9.13 | H27: planilla fila 469: 1 und (niple L = 0.60 m)
A28: UFG15 | B28: Unión roscado de F°G°de Ø=1 1/2" | C28: und | E28: 1 | F28: ='PRECIOS DE INSUMOS'!$H$35 -> 12.63 | G28: =ROUND(E28*F28,2) -> 12.63 | H28: planilla fila 470: 1 und
A29: VF15 | B29: Válvula Flotadora de Bronce de Ø=1 1/2" | C29: und | E29: 1 | F29: ='PRECIOS DE INSUMOS'!$H$31 -> 313.56 | G29: =ROUND(E29*F29,2) -> 313.56 | H29: planilla fila 471: 1 und
A30: ELN | B30: Electronivel conectado a bombas | C30: und | E30: 1 | F30: ='PRECIOS DE INSUMOS'!$H$33 -> 76.19 | G30: =ROUND(E30*F30,2) -> 76.19 | H30: planilla fila 472: 1 und
A31: PEG | B31: Pegamento para PVC | C31: gal | E31: 0.075 | F31: ='PRECIOS DE INSUMOS'!$H$47 -> 209.83 | G31: =ROUND(E31*F31,2) -> 15.74 | H31: 15 uniones pegadas (≈0.003 / 0.005 / 0.007 gal por unión de Ø1" / 1 1/2" / 2")
A32: TEF | B32: Cinta teflón 3/4" x 10 m | C32: und | E32: 4.62 | F32: ='PRECIOS DE INSUMOS'!$H$48 -> 2.46 | G32: =ROUND(E32*F32,2) -> 11.37 | H32: 37 extremos roscados ≈ 18 roscas macho; 1 rollo cada 4 roscas
A33: TAR | B33: Perno de anclaje 3/8" para fijar abrazaderas | C33: und | E33: 16 | F33: ='PRECIOS DE INSUMOS'!$H$43 -> 8.03 | G33: =ROUND(E33*F33,2) -> 128.48 | H33: 2 por abrazadera (una por oreja)
B34: Subtotal materiales | G34: =SUM(G13:G33) -> 1145.08
A35: EQUIPOS Y HERRAMIENTAS
A36: 37-0001 | B36: Herramientas manuales | C36: %MO | E36: 3 | F36: =G11 -> 1122.98 | G36: =ROUND(E36/100*F36,2) -> 33.69 | H36: 3 % de la mano de obra (tarraja, llaves, sierra, taladro)
A37: SOLM | B37: Máquina de soldar eléctrica 250 A | C37: hm | E37: 0.5 | F37: ='PRECIOS DE INSUMOS'!$H$50 -> 5.83 | G37: =ROUND(E37*F37,2) -> 2.92 | H37: 0.5 h por brida rompe agua (1 bridas)
B38: Subtotal equipos y herramientas | G38: =SUM(G36:G37) -> 36.61
A39: COSTO UNITARIO DIRECTO POR glb (S/) | G39: =G11+G34+G38 -> 2304.67
A41: CÁLCULO DEL RENDIMIENTO (días-cuadrilla por componente)
A42: TIPO | B42: COMPONENTE | C42: UND | E42: CANTIDAD | F42: REND. (und/día) | G42: DÍAS | H42: CRITERIO
...

Sheet 4.2.3.1.4
A1: ANÁLISIS DE COSTOS UNITARIOS
A2: CREACIÓN DEL SERVICIO DE PROTECCIÓN INTEGRAL A NIÑAS, NIÑOS Y ADOLESCENTES SIN CUIDADOS PARENTALES O EN RIESGO DE PERDERLOS EN CENTRO DE ACOGIDA RESIDENCIAL - MUJERES, DISTRITO DE MORALES, PROVINCIA Y DEPARTAMENTO DE SAN MARTÍN (CAR Mujeres, CUI 2717013)
A3: Partida | B3: 4.2.3.1.4 SUM. E INST. DE LINEA DE DISTRIBUCION SISTEMA DE BOMBEO DE PVC SP D=2"
A4: Rend. | B4: =G42 -> 0.3956 | C4: MO | D4: =SUM(E9:E10) -> 30.3336 | E4: EQ | F4: =SUMIF(C29:C30,"hm",E29:E30) -> 0.5 | G4: Costo unit. directo por glb (S/) | H4: =G32 -> 1418.12
A5: Metrado | B5: 1 glb (planilla, hoja RESUMEN) | C5: Lugar | D5: San Martín - San Martín - Morales | G5: Fecha | H5: Octubre 2026
A7: CÓDIGO | B7: DESCRIPCIÓN DEL RECURSO | C7: UND | D7: CUADRILLA | E7: CANTIDAD | F7: PRECIO S/ | G7: PARCIAL S/ | H7: SUSTENTO
A8: MANO DE OBRA
A9: 47-0001 | B9: Operario | C9: hh | D9: 1 | E9: =ROUND(D9*8/$B$4,4) -> 20.2224 | F9: ='MANO DE OBRA 2026'!$C$16 -> 28.95 | G9: =ROUND(E9*F9,2) -> 585.44 | H9: cantidad = cuadrilla x 8 h / rendimiento; costo HH CAPECO - FTCCP 2026
A10: 47-0003 | B10: Peón | C10: hh | D10: 0.5 | E10: =ROUND(D10*8/$B$4,4) -> 10.1112 | F10: ='MANO DE OBRA 2026'!$E$16 -> 20.54 | G10: =ROUND(E10*F10,2) -> 207.68 | H10: cantidad = cuadrilla x 8 h / rendimiento; costo HH CAPECO - FTCCP 2026
B11: Subtotal mano de obra | G11: =SUM(G9:G10) -> 793.12
A12: MATERIALES
A13: BR03 | B13: Brida rompe agua Ø2" PL 0.25x0.25 e=1/8" (niple F°G° 2" L=0.40) | C13: und | E13: 1 | F13: ='PRECIOS DE INSUMOS'!$H$66 -> 14.23 | G13: =ROUND(E13*F13,2) -> 14.23 | H13: planilla fila 475: 1 und
A14: SK2 | B14: Unión Socket PVC C-10 de ∅=2" (Rosca Hembra) | C14: und | E14: 1 | F14: ='PRECIOS DE INSUMOS'!$H$20 -> 8.64 | G14: =ROUND(E14*F14,2) -> 8.64 | H14: planilla fila 476: 1 und
A15: CD2 | B15: Codo PVC SP C-10 de Ø=2" x 90° | C15: und | E15: 1 | F15: ='PRECIOS DE INSUMOS'!$H$12 -> 13.47 | G15: =ROUND(E15*F15,2) -> 13.47 | H15: planilla fila 477: 17 m (se toma 1, ver obs.)
A16: TB2 | B16: Tubería PVC SP C-10 de Ø=2" - NTP 399.002:2015 | C16: m | E16: =(17)*1.05 -> 17.85 | F16: ='PRECIOS DE INSUMOS'!$H$9 -> 11.17 | G16: =ROUND(E16*F16,2) -> 199.38 | H16: planilla fila 478: 1 und (se toma 17, ver obs.); + 5 % de desperdicio
A17: UPR2 | B17: Adaptador UPR PVC C-10 de Ø=2" | C17: und | E17: 2 | F17: ='PRECIOS DE INSUMOS'!$H$18 -> 9.24 | G17: =ROUND(E17*F17,2) -> 18.48 | H17: planilla fila 479: 2 und
A18: UU2 | B18: Unión universal roscado de PVC C-10 de Ø=2" | C18: und | E18: 2 | F18: ='PRECIOS DE INSUMOS'!$H$17 -> 42.29 | G18: =ROUND(E18*F18,2) -> 84.58 | H18: planilla fila 480: 2 und
A19: NP2 | B19: Niple roscado de PVC C-10 de Ø=2" x 6" | C19: und | E19: 2 | F19: ='PRECIOS DE INSUMOS'!$H$23 -> 2.41 | G19: =ROUND(E19*F19,2) -> 4.82 | H19: planilla fila 481: 2 und
A20: VCB2 | B20: Válvula compuerta roscado de Bronce Pesado de Ø=2" | C20: und | E20: 1 | F20: ='PRECIOS DE INSUMOS'!$H$29 -> 67.8 | G20: =ROUND(E20*F20,2) -> 67.8 | H20: planilla fila 482: 1 und
A21: AB2 | B21: Abrazadera de F°G e= 1/8" P/Tubería de Ø 2" | C21: und | E21: 7 | F21: ='PRECIOS DE INSUMOS'!$H$42 -> 1.36 | G21: =ROUND(E21*F21,2) -> 9.52 | H21: planilla fila 483: 7 und
A22: TE2 | B22: Tee PVC SP C-10 de Ø=2" | C22: und | E22: 1 | F22: ='PRECIOS DE INSUMOS'!$H$15 -> 19.41 | G22: =ROUND(E22*F22,2) -> 19.41 | H22: planilla fila 484: 1 und
A23: CD245 | B23: Codo PVC SP C-10 de Ø=2" x 45° | C23: und | E23: 2 | F23: ='PRECIOS DE INSUMOS'!$H$13 -> 9.15 | G23: =ROUND(E23*F23,2) -> 18.3 | H23: planilla fila 485: 2 und
A24: PEG | B24: Pegamento para PVC | C24: gal | E24: 0.1078 | F24: ='PRECIOS DE INSUMOS'!$H$47 -> 209.83 | G24: =ROUND(E24*F24,2) -> 22.62 | H24: 15 uniones pegadas (≈0.003 / 0.005 / 0.007 gal por unión de Ø1" / 1 1/2" / 2")
A25: TEF | B25: Cinta teflón 3/4" x 10 m | C25: und | E25: 1.88 | F25: ='PRECIOS DE INSUMOS'!$H$48 -> 2.46 | G25: =ROUND(E25*F25,2) -> 4.62 | H25: 15 extremos roscados ≈ 8 roscas macho; 1 rollo cada 4 roscas
A26: TAR | B26: Perno de anclaje 3/8" para fijar abrazaderas | C26: und | E26: 14 | F26: ='PRECIOS DE INSUMOS'!$H$43 -> 8.03 | G26: =ROUND(E26*F26,2) -> 112.42 | H26: 2 por abrazadera (una por oreja)
B27: Subtotal materiales | G27: =SUM(G13:G26) -> 598.29
A28: EQUIPOS Y HERRAMIENTAS
A29: 37-0001 | B29: Herramientas manuales | C29: %MO | E29: 3 | F29: =G11 -> 793.12 | G29: =ROUND(E29/100*F29,2) -> 23.79 | H29: 3 % de la mano de obra (tarraja, llaves, sierra, taladro)
A30: SOLM | B30: Máquina de soldar eléctrica 250 A | C30: hm | E30: 0.5 | F30: ='PRECIOS DE INSUMOS'!$H$50 -> 5.83 | G30: =ROUND(E30*F30,2) -> 2.92 | H30: 0.5 h por brida rompe agua (1 bridas)
B31: Subtotal equipos y herramientas | G31: =SUM(G29:G30) -> 26.71
A32: COSTO UNITARIO DIRECTO POR glb (S/) | G32: =G11+G27+G31 -> 1418.12
A34: CÁLCULO DEL RENDIMIENTO (días-cuadrilla por componente)
A35: TIPO | B35: COMPONENTE | C35: UND | E35: CANTIDAD | F35: REND. (und/día) | G35: DÍAS | H35: CRITERIO
A36: brida | B36: Brida rompe agua (corte, soldadura, roscado y fijación al encofrado) | C36: und | E36: 1 | F36: 3 | G36: =E36/F36 -> 0.33333333 | H36: rendimiento adoptado (referencial, editable)
A37: acc2 | B37: Accesorio PVC Ø2" (codo, tee, unión, adaptador, niple) | C37: und | E37: 11 | F37: 16 | G37: =E37/F37 -> 0.6875 | H37: rendimiento adoptado (referencial, editable)
A38: tubo2 | B38: Tubería PVC SP Ø2" | C38: m | E38: 17 | F38: 18 | G38: =E38/F38 -> 0.94444444 | H38: rendimiento adoptado (referencial, editable)
A39: valv | B39: Válvula roscada (compuerta, esférica, check) | C39: und | E39: 1 | F39: 8 | G39: =E39/F39 -> 0.125 | H39: rendimiento adoptado (referencial, editable)
A40: abr | B40: Abrazadera F°G° (perforación, tarugo y fijación) | C40: und | E40: 7 | F40: 16 | G40: =E40/F40 -> 0.4375 | H40: rendimiento adoptado (referencial, editable)
B41: Total días-cuadrilla para 1 glb | G41: =SUM(G36:G40) -> 2.5277778
B42: Rendimiento = 1 / total días (glb/día) | G42: =ROUND(1/G41,4) -> 0.3956
...

Sheet 4.2.3.1.5
A1: ANÁLISIS DE COSTOS UNITARIOS
A2: CREACIÓN DEL SERVICIO DE PROTECCIÓN INTEGRAL A NIÑAS, NIÑOS Y ADOLESCENTES SIN CUIDADOS PARENTALES O EN RIESGO DE PERDERLOS EN CENTRO DE ACOGIDA RESIDENCIAL - MUJERES, DISTRITO DE MORALES, PROVINCIA Y DEPARTAMENTO DE SAN MARTÍN (CAR Mujeres, CUI 2717013)
A3: Partida | B3: 4.2.3.1.5 SUM. E INST. DE LINEA DE REBOSE TANQUE ELEVADO DE PVC SP D=2"
A4: Rend. | B4: =G49 -> 0.2042 | C4: MO | D4: =SUM(E9:E10) -> 58.7659 | E4: EQ | F4: =SUMIF(C33:C34,"hm",E33:E34) -> 1 | G4: Costo unit. directo por glb (S/) | H4: =G36 -> 2561.98
A5: Metrado | B5: 1 glb (planilla, hoja RESUMEN) | C5: Lugar | D5: San Martín - San Martín - Morales | G5: Fecha | H5: Octubre 2026
A7: CÓDIGO | B7: DESCRIPCIÓN DEL RECURSO | C7: UND | D7: CUADRILLA | E7: CANTIDAD | F7: PRECIO S/ | G7: PARCIAL S/ | H7: SUSTENTO
A8: MANO DE OBRA
A9: 47-0001 | B9: Operario | C9: hh | D9: 1 | E9: =ROUND(D9*8/$B$4,4) -> 39.1773 | F9: ='MANO DE OBRA 2026'!$C$16 -> 28.95 | G9: =ROUND(E9*F9,2) -> 1134.18 | H9: cantidad = cuadrilla x 8 h / rendimiento; costo HH CAPECO - FTCCP 2026
A10: 47-0003 | B10: Peón | C10: hh | D10: 0.5 | E10: =ROUND(D10*8/$B$4,4) -> 19.5886 | F10: ='MANO DE OBRA 2026'!$E$16 -> 20.54 | G10: =ROUND(E10*F10,2) -> 402.35 | H10: cantidad = cuadrilla x 8 h / rendimiento; costo HH CAPECO - FTCCP 2026
B11: Subtotal mano de obra | G11: =SUM(G9:G10) -> 1536.53
A12: MATERIALES
A13: RD2 | B13: Reducción PVC SP C-10 de Ø=2" x 1" | C13: und | E13: 1 | F13: ='PRECIOS DE INSUMOS'!$H$25 -> 8.39 | G13: =ROUND(E13*F13,2) -> 8.39 | H13: planilla fila 488: 1 und
A14: TB1 | B14: Tubería PVC SP C-10 de Ø=1" - NTP 399.002:2015 | C14: m | E14: =(17)*1.05 -> 17.85 | F14: ='PRECIOS DE INSUMOS'!$H$7 -> 4.56 | G14: =ROUND(E14*F14,2) -> 81.4 | H14: planilla fila 489: 17 m; + 5 % de desperdicio
A15: AB1 | B15: Abrazadera de F°G° e= 1/8" P/Tubería de Ø 1" | C15: und | E15: 4 | F15: ='PRECIOS DE INSUMOS'!$H$40 -> 1.19 | G15: =ROUND(E15*F15,2) -> 4.76 | H15: planilla fila 490: 4 und
A16: CD1 | B16: Codo PVC SP C-10 de Ø=1" x 90° | C16: und | E16: 4 | F16: ='PRECIOS DE INSUMOS'!$H$10 -> 4.83 | G16: =ROUND(E16*F16,2) -> 19.32 | H16: planilla fila 491: 4 und
A17: BR04 | B17: Brida rompe agua Ø2" PL 0.15x0.15 e=1/8" (niple F°G° 2" L=0.25) | C17: und | E17: 2 | F17: ='PRECIOS DE INSUMOS'!$H$67 -> 9.01 | G17: =ROUND(E17*F17,2) -> 18.02 | H17: planilla fila 492: 2 und
A18: TE2 | B18: Tee PVC Roscada C-10 de Ø=2" | C18: und | E18: =1+1 -> 2 | F18: ='PRECIOS DE INSUMOS'!$H$15 -> 19.41 | G18: =ROUND(E18*F18,2) -> 38.82 | H18: planilla fila 493: 1 und + planilla fila 499: 1 und
A19: NP2 | B19: Niple roscado de PVC C-10 de Ø=2" x 4" | C19: und | E19: =2+2 -> 4 | F19: ='PRECIOS DE INSUMOS'!$H$23 -> 2.41 | G19: =ROUND(E19*F19,2) -> 9.64 | H19: planilla fila 494: 2 und + planilla fila 502: 2 und
A20: SK2 | B20: Unión Socket PVC C-10 de ∅=2" (Rosca Hembra) | C20: und | E20: 3 | F20: ='PRECIOS DE INSUMOS'!$H$20 -> 8.64 | G20: =ROUND(E20*F20,2) -> 25.92 | H20: planilla fila 495: 3 und
A21: AB2 | B21: Abrazadera de F°G° e= 1/8" P/Tubería de Ø 2" | C21: und | E21: 13 | F21: ='PRECIOS DE INSUMOS'!$H$42 -> 1.36 | G21: =ROUND(E21*F21,2) -> 17.68 | H21: planilla fila 496: 13 und
A22: TB2 | B22: Tubería PVC SP C-10 de Ø=2" - NTP 399.002:2015 | C22: m | E22: =(18)*1.05 -> 18.9 | F22: ='PRECIOS DE INSUMOS'!$H$9 -> 11.17 | G22: =ROUND(E22*F22,2) -> 211.11 | H22: planilla fila 497: 18 m; + 5 % de desperdicio
A23: SOMB2 | B23: Sombrero de Ventilación PVC-SAP Ø2" | C23: und | E23: 1 | F23: ='PRECIOS DE INSUMOS'!$H$45 -> 5.25 | G23: =ROUND(E23*F23,2) -> 5.25 | H23: planilla fila 498: 1 und
A24: UPR2 | B24: Adaptador UPR PVC C-10 de Ø=2" | C24: und | E24: 2 | F24: ='PRECIOS DE INSUMOS'!$H$18 -> 9.24 | G24: =ROUND(E24*F24,2) -> 18.48 | H24: planilla fila 500: 2 und
A25: UU2 | B25: Unión universal roscado de PVC C-10 de Ø=2" | C25: und | E25: 2 | F25: ='PRECIOS DE INSUMOS'!$H$17 -> 42.29 | G25: =ROUND(E25*F25,2) -> 84.58 | H25: planilla fila 501: 2 und
A26: VCB2 | B26: Válvula compuerta roscado de Bronce Pesado de Ø=2" | C26: und | E26: 1 | F26: ='PRECIOS DE INSUMOS'!$H$29 -> 67.8 | G26: =ROUND(E26*F26,2) -> 67.8 | H26: planilla fila 503: 1 und
A27: CD2 | B27: Codo PVC SP C-10 de Ø=2" x 90° | C27: und | E27: 3 | F27: ='PRECIOS DE INSUMOS'!$H$12 -> 13.47 | G27: =ROUND(E27*F27,2) -> 40.41 | H27: planilla fila 504: 3 und
A28: PEG | B28: Pegamento para PVC | C28: gal | E28: 0.1994 | F28: ='PRECIOS DE INSUMOS'!$H$47 -> 209.83 | G28: =ROUND(E28*F28,2) -> 41.84 | H28: 35 uniones pegadas (≈0.003 / 0.005 / 0.007 gal por unión de Ø1" / 1 1/2" / 2")
A29: TEF | B29: Cinta teflón 3/4" x 10 m | C29: und | E29: 2.88 | F29: ='PRECIOS DE INSUMOS'!$H$48 -> 2.46 | G29: =ROUND(E29*F29,2) -> 7.08 | H29: 23 extremos roscados ≈ 12 roscas macho; 1 rollo cada 4 roscas
A30: TAR | B30: Perno de anclaje 3/8" para fijar abrazaderas | C30: und | E30: 34 | F30: ='PRECIOS DE INSUMOS'!$H$43 -> 8.03 | G30: =ROUND(E30*F30,2) -> 273.02 | H30: 2 por abrazadera (una por oreja)
B31: Subtotal materiales | G31: =SUM(G13:G30) -> 973.52
A32: EQUIPOS Y HERRAMIENTAS
A33: 37-0001 | B33: Herramientas manuales | C33: %MO | E33: 3 | F33: =G11 -> 1536.53 | G33: =ROUND(E33/100*F33,2) -> 46.1 | H33: 3 % de la mano de obra (tarraja, llaves, sierra, taladro)
A34: SOLM | B34: Máquina de soldar eléctrica 250 A | C34: hm | E34: 1 | F34: ='PRECIOS DE INSUMOS'!$H$50 -> 5.83 | G34: =ROUND(E34*F34,2) -> 5.83 | H34: 0.5 h por brida rompe agua (2 bridas)
B35: Subtotal equipos y herramientas | G35: =SUM(G33:G34) -> 51.93
A36: COSTO UNITARIO DIRECTO POR glb (S/) | G36: =G11+G31+G35 -> 2561.98
A38: CÁLCULO DEL RENDIMIENTO (días-cuadrilla por componente)
A39: TIPO | B39: COMPONENTE | C39: UND | E39: CANTIDAD | F39: REND. (und/día) | G39: DÍAS | H39: CRITERIO
A40: acc2 | B40: Accesorio PVC Ø2" (codo, tee, unión, adaptador, niple) | C40: und | E40: 17 | F40: 16 | G40: =E40/F40 -> 1.0625 | H40: rendimiento adoptado (referencial, editable)
A41: tubo1 | B41: Tubería PVC SP Ø1" (tendido, corte, unión y fijación) | C41: m | E41: 17 | F41: 25 | G41: =E41/F41 -> 0.68 | H41: rendimiento adoptado (referencial, editable)
A42: abr | B42: Abrazadera F°G° (perforación, tarugo y fijación) | C42: und | E42: 17 | F42: 16 | G42: =E42/F42 -> 1.0625 | H42: rendimiento adoptado (referencial, editable)
...

Sheet 4.2.3.1.6
A1: ANÁLISIS DE COSTOS UNITARIOS
A2: CREACIÓN DEL SERVICIO DE PROTECCIÓN INTEGRAL A NIÑAS, NIÑOS Y ADOLESCENTES SIN CUIDADOS PARENTALES O EN RIESGO DE PERDERLOS EN CENTRO DE ACOGIDA RESIDENCIAL - MUJERES, DISTRITO DE MORALES, PROVINCIA Y DEPARTAMENTO DE SAN MARTÍN (CAR Mujeres, CUI 2717013)
A3: Partida | B3: 4.2.3.1.6 SUM. E INST. DE LINEA DE LIMPIA Y VENTILACION CISTERNA DE PVC SP D=2"
A4: Rend. | B4: =G31 -> 0.96 | C4: MO | D4: =SUM(E9:E10) -> 12.5 | E4: EQ | F4: =SUMIF(C21:C22,"hm",E21:E22) -> 1 | G4: Costo unit. directo por glb (S/) | H4: =G24 -> 443.11
A5: Metrado | B5: 1 glb (planilla, hoja RESUMEN) | C5: Lugar | D5: San Martín - San Martín - Morales | G5: Fecha | H5: Octubre 2026
A7: CÓDIGO | B7: DESCRIPCIÓN DEL RECURSO | C7: UND | D7: CUADRILLA | E7: CANTIDAD | F7: PRECIO S/ | G7: PARCIAL S/ | H7: SUSTENTO
A8: MANO DE OBRA
A9: 47-0001 | B9: Operario | C9: hh | D9: 1 | E9: =ROUND(D9*8/$B$4,4) -> 8.3333 | F9: ='MANO DE OBRA 2026'!$C$16 -> 28.95 | G9: =ROUND(E9*F9,2) -> 241.25 | H9: cantidad = cuadrilla x 8 h / rendimiento; costo HH CAPECO - FTCCP 2026
A10: 47-0003 | B10: Peón | C10: hh | D10: 0.5 | E10: =ROUND(D10*8/$B$4,4) -> 4.1667 | F10: ='MANO DE OBRA 2026'!$E$16 -> 20.54 | G10: =ROUND(E10*F10,2) -> 85.58 | H10: cantidad = cuadrilla x 8 h / rendimiento; costo HH CAPECO - FTCCP 2026
B11: Subtotal mano de obra | G11: =SUM(G9:G10) -> 326.83
A12: MATERIALES
A13: BR05 | B13: Brida rompe agua Ø2" PL 0.20x0.20 e=1/8" (niple F°G° 2" L=0.45) | C13: und | E13: 2 | F13: ='PRECIOS DE INSUMOS'!$H$68 -> 13.97 | G13: =ROUND(E13*F13,2) -> 27.94 | H13: planilla fila 507: sin parcial (se toma 2, ver obs.)
A14: CD2 | B14: Codo de PVC de Ø=2" x 90° | C14: und | E14: =2+2 -> 4 | F14: ='PRECIOS DE INSUMOS'!$H$12 -> 13.47 | G14: =ROUND(E14*F14,2) -> 53.88 | H14: planilla fila 508: 2 und + planilla fila 510: sin parcial (se toma 2, ver obs.)
A15: NP2 | B15: Niple roscado de PVC de Ø=2" x 6" | C15: und | E15: 2 | F15: ='PRECIOS DE INSUMOS'!$H$23 -> 2.41 | G15: =ROUND(E15*F15,2) -> 4.82 | H15: planilla fila 509: 2 und
A16: MALLA | B16: Malla galvanizada para codos de ventilación (2 x 0.05 m²) | C16: m2 | E16: 0.1 | F16: ='PRECIOS DE INSUMOS'!$H$46 -> 4.08 | G16: =ROUND(E16*F16,2) -> 0.41 | H16: ver observación
A17: PEG | B17: Pegamento para PVC | C17: gal | E17: 0.056 | F17: ='PRECIOS DE INSUMOS'!$H$47 -> 209.83 | G17: =ROUND(E17*F17,2) -> 11.75 | H17: 8 uniones pegadas (≈0.003 / 0.005 / 0.007 gal por unión de Ø1" / 1 1/2" / 2")
A18: TEF | B18: Cinta teflón 3/4" x 10 m | C18: und | E18: 0.75 | F18: ='PRECIOS DE INSUMOS'!$H$48 -> 2.46 | G18: =ROUND(E18*F18,2) -> 1.85 | H18: 6 extremos roscados ≈ 3 roscas macho; 1 rollo cada 4 roscas
B19: Subtotal materiales | G19: =SUM(G13:G18) -> 100.65
A20: EQUIPOS Y HERRAMIENTAS
A21: 37-0001 | B21: Herramientas manuales | C21: %MO | E21: 3 | F21: =G11 -> 326.83 | G21: =ROUND(E21/100*F21,2) -> 9.8 | H21: 3 % de la mano de obra (tarraja, llaves, sierra, taladro)
A22: SOLM | B22: Máquina de soldar eléctrica 250 A | C22: hm | E22: 1 | F22: ='PRECIOS DE INSUMOS'!$H$50 -> 5.83 | G22: =ROUND(E22*F22,2) -> 5.83 | H22: 0.5 h por brida rompe agua (2 bridas)
B23: Subtotal equipos y herramientas | G23: =SUM(G21:G22) -> 15.63
A24: COSTO UNITARIO DIRECTO POR glb (S/) | G24: =G11+G19+G23 -> 443.11
A26: CÁLCULO DEL RENDIMIENTO (días-cuadrilla por componente)
A27: TIPO | B27: COMPONENTE | C27: UND | E27: CANTIDAD | F27: REND. (und/día) | G27: DÍAS | H27: CRITERIO
A28: brida | B28: Brida rompe agua (corte, soldadura, roscado y fijación al encofrado) | C28: und | E28: 2 | F28: 3 | G28: =E28/F28 -> 0.66666667 | H28: rendimiento adoptado (referencial, editable)
A29: acc2 | B29: Accesorio PVC Ø2" (codo, tee, unión, adaptador, niple) | C29: und | E29: 6 | F29: 16 | G29: =E29/F29 -> 0.375 | H29: rendimiento adoptado (referencial, editable)
B30: Total días-cuadrilla para 1 glb | G30: =SUM(G28:G29) -> 1.0416667
B31: Rendimiento = 1 / total días (glb/día) | G31: =ROUND(1/G30,4) -> 0.96
A33: OBSERVACIONES
A34: • fila 507: la planilla no lleva el parcial; se toma N.° veces 1 x cantidad 2 = 2 und
A35: • fila 510: la planilla no lleva el parcial; se toma 2 und (codo Ø2" + malla galvanizada soldada)

Sheet 4.2.3.1.7
A1: ANÁLISIS DE COSTOS UNITARIOS
A2: CREACIÓN DEL SERVICIO DE PROTECCIÓN INTEGRAL A NIÑAS, NIÑOS Y ADOLESCENTES SIN CUIDADOS PARENTALES O EN RIESGO DE PERDERLOS EN CENTRO DE ACOGIDA RESIDENCIAL - MUJERES, DISTRITO DE MORALES, PROVINCIA Y DEPARTAMENTO DE SAN MARTÍN (CAR Mujeres, CUI 2717013)
A3: Partida | B3: 4.2.3.1.7 PRUEBA HIDRÁULICA DE ESTANQUEIDAD Y DESINFECCIÓN DE CISTERNA Y TANQUE ELEVADO
A4: Rend. | B4: =G29 -> 0.5 | C4: MO | D4: =SUM(E9:E10) -> 32 | E4: EQ | F4: =SUMIF(C18:C18,"hm",E18:E18) -> 0 | G4: Costo unit. directo por glb (S/) | H4: =G20 -> 1387.45
A5: Metrado | B5: 1 glb (planilla, hoja RESUMEN) | C5: Lugar | D5: San Martín - San Martín - Morales | G5: Fecha | H5: Octubre 2026
A7: CÓDIGO | B7: DESCRIPCIÓN DEL RECURSO | C7: UND | D7: CUADRILLA | E7: CANTIDAD | F7: PRECIO S/ | G7: PARCIAL S/ | H7: SUSTENTO
A8: MANO DE OBRA
A9: 47-0001 | B9: Operario | C9: hh | D9: 1 | E9: =ROUND(D9*8/$B$4,4) -> 16 | F9: ='MANO DE OBRA 2026'!$C$16 -> 28.95 | G9: =ROUND(E9*F9,2) -> 463.2 | H9: cantidad = cuadrilla x 8 h / rendimiento; costo HH CAPECO - FTCCP 2026
A10: 47-0003 | B10: Peón | C10: hh | D10: 1 | E10: =ROUND(D10*8/$B$4,4) -> 16 | F10: ='MANO DE OBRA 2026'!$E$16 -> 20.54 | G10: =ROUND(E10*F10,2) -> 328.64 | H10: cantidad = cuadrilla x 8 h / rendimiento; costo HH CAPECO - FTCCP 2026
B11: Subtotal mano de obra | G11: =SUM(G9:G10) -> 791.84
A12: MATERIALES
A13: AGUA | B13: Agua para llenado de cisterna (32 m³) y tanque elevado (15 m³) + 10 % de enjuague | C13: m3 | E13: =(32+15)*1.1 -> 51.7 | F13: ='PRECIOS DE INSUMOS'!$H$51 -> 8.33 | G13: =ROUND(E13*F13,2) -> 430.66 | H13: volúmenes del programa arquitectónico del perfil (cisterna 32 m³, tanque elevado 15 m³)
A14: HIPO | B14: Hipoclorito de calcio al 70 % | C14: kg | E14: =ROUND((32+15)*50/1000/0.7,2) -> 3.36 | F14: ='PRECIOS DE INSUMOS'!$H$52 -> 29.66 | G14: =ROUND(E14*F14,2) -> 99.66 | H14: 50 mg/l de cloro libre durante 24 h (RNE IS.010); 47 m³ x 50 g/m³ / 0.70
A15: KIT | B15: Comparador de cloro residual y pH (con reactivos) | C15: und | E15: 1 | F15: ='PRECIOS DE INSUMOS'!$H$53 -> 41.53 | G15: =ROUND(E15*F15,2) -> 41.53 | H15: lectura de cloro residual al final de la desinfección
B16: Subtotal materiales | G16: =SUM(G13:G15) -> 571.85
A17: EQUIPOS Y HERRAMIENTAS
A18: 37-0001 | B18: Herramientas manuales | C18: %MO | E18: 3 | F18: =G11 -> 791.84 | G18: =ROUND(E18/100*F18,2) -> 23.76 | H18: 3 % de la mano de obra
B19: Subtotal equipos y herramientas | G19: =SUM(G18:G18) -> 23.76
A20: COSTO UNITARIO DIRECTO POR glb (S/) | G20: =G11+G16+G19 -> 1387.45
A22: CÁLCULO DEL RENDIMIENTO (días-cuadrilla por componente)
A23: TIPO | B23: COMPONENTE | C23: UND | E23: CANTIDAD | F23: REND. (und/día) | G23: DÍAS | H23: CRITERIO
A24: prep | B24: Preparación, taponeo de salidas y llenado de cisterna y tanque | C24: und | E24: 1 | F24: 2 | G24: =E24/F24 -> 0.5 | H24: 2 estructuras por día
A25: lect | B25: Prueba de estanqueidad: marcado de nivel y lectura a las 24 h, revisión de filtraciones | C25: und | E25: 1 | F25: 4 | G25: =E25/F25 -> 0.25 | H25: control del nivel; 1/4 de día
A26: desi | B26: Desinfección: preparación de la solución, aplicación, 24 h de contacto y medición | C26: und | E26: 1 | F26: 2 | G26: =E26/F26 -> 0.5 | H26: 1/2 día
A27: vac | B27: Vaciado, enjuague y limpieza final (2 estructuras) | C27: und | E27: 1 | F27: 1.333 | G27: =E27/F27 -> 0.75018755 | H27: 3/4 de día
B28: Total días-cuadrilla para 1 glb | G28: =SUM(G24:G27) -> 2.0001875
B29: Rendimiento = 1 / total días (glb/día) | G29: =ROUND(1/G28,4) -> 0.5
A31: OBSERVACIONES
A32: • La planilla no desagrega esta partida; el análisis se arma con los volúmenes del programa arquitectónico (cisterna 32 m³ y tanque elevado 15 m³). Si el diseño de IISS tiene otros volúmenes, cambiar las fórmulas de agua e hipoclorito.
A33: • Se llena una sola vez: la desinfección se hace con el agua de la prueba de estanqueidad, agregando el cloro; el vaciado se hace con las electrobombas de la partida 4.2.3.2.1 (sin costo de equipo adicional).
A34: • El agua se valoriza con la tarifa oficial de EMAPA San Martín (categoría comercial y otros, tramo de 30 m³ a más), que es sin IGV.

Sheet 4.3.6.3.3
A1: ANÁLISIS DE COSTOS UNITARIOS
A2: CREACIÓN DEL SERVICIO DE PROTECCIÓN INTEGRAL A NIÑAS, NIÑOS Y ADOLESCENTES SIN CUIDADOS PARENTALES O EN RIESGO DE PERDERLOS EN CENTRO DE ACOGIDA RESIDENCIAL - MUJERES, DISTRITO DE MORALES, PROVINCIA Y DEPARTAMENTO DE SAN MARTÍN (CAR Mujeres, CUI 2717013)
A3: Partida | B3: 4.3.6.3.3 TECLE DE PALANCA P/CABALLETE
A4: Rend. | B4: =G36 -> 0.3437 | C4: MO | D4: =SUM(E9:E10) -> 46.5522 | E4: EQ | F4: =SUMIF(C24:C25,"hm",E24:E25) -> 13.77 | G4: Costo unit. directo por glb (S/) | H4: =G27 -> 2274.97
A5: Metrado | B5: 1 glb (planilla, hoja RESUMEN) | C5: Lugar | D5: San Martín - San Martín - Morales | G5: Fecha | H5: Octubre 2026
A7: CÓDIGO | B7: DESCRIPCIÓN DEL RECURSO | C7: UND | D7: CUADRILLA | E7: CANTIDAD | F7: PRECIO S/ | G7: PARCIAL S/ | H7: SUSTENTO
A8: MANO DE OBRA
A9: 47-0001 | B9: Operario | C9: hh | D9: 1 | E9: =ROUND(D9*8/$B$4,4) -> 23.2761 | F9: ='MANO DE OBRA 2026'!$C$16 -> 28.95 | G9: =ROUND(E9*F9,2) -> 673.84 | H9: cantidad = cuadrilla x 8 h / rendimiento; costo HH CAPECO - FTCCP 2026
A10: 47-0003 | B10: Peón | C10: hh | D10: 1 | E10: =ROUND(D10*8/$B$4,4) -> 23.2761 | F10: ='MANO DE OBRA 2026'!$E$16 -> 20.54 | G10: =ROUND(E10*F10,2) -> 478.09 | H10: cantidad = cuadrilla x 8 h / rendimiento; costo HH CAPECO - FTCCP 2026
B11: Subtotal mano de obra | G11: =SUM(G9:G10) -> 1151.93
A12: MATERIALES
A13: IPN | B13: Perfil IPN 100 (8.34 kg/m) | C13: m | E13: =11.8*1.05 -> 12.39 | F13: ='PRECIOS DE INSUMOS'!$H$54 -> 25.68 | G13: =ROUND(E13*F13,2) -> 318.18 | H13: planilla filas 1022-1026: 11.80 m; + 5 % de desperdicio
A14: TECLE | B14: Tecle de palanca | C14: und | E14: 1 | F14: ='PRECIOS DE INSUMOS'!$H$55 -> 398.22 | G14: =ROUND(E14*F14,2) -> 398.22 | H14: planilla fila 1027
A15: PLA | B15: Tapa: plancha LAC 1/8" 0.40 x 0.40 m (24.91 kg/m²) | C15: kg | E15: =ROUND(0.4*0.4*24.91,2) -> 3.99 | F15: ='PRECIOS DE INSUMOS'!$H$44 -> 2.24 | G15: =ROUND(E15*F15,2) -> 8.94 | H15: planilla fila 1028: «Tapa» 1 und; medida adoptada, confirmar con el plano
A16: RUEDA | B16: Rueda giratoria 360° con freno | C16: und | E16: 4 | F16: ='PRECIOS DE INSUMOS'!$H$56 -> 42.29 | G16: =ROUND(E16*F16,2) -> 169.16 | H16: planilla fila 1029
A17: SOLD | B17: Soldadura cellocord E6011 1/8" | C17: kg | E17: 2.5 | F17: ='PRECIOS DE INSUMOS'!$H$49 -> 18.63 | G17: =ROUND(E17*F17,2) -> 46.58 | H17: ≈2.5 % del peso del caballete (≈100 kg); incluye la soldadura de las placas de las ruedas
A18: ANTI | B18: Pintura anticorrosiva | C18: gal | E18: 0.3 | F18: ='PRECIOS DE INSUMOS'!$H$57 -> 52.54 | G18: =ROUND(E18*F18,2) -> 15.76 | H18: ≈4.7 m² (0.40 m²/m de IPN 100) a 2 manos, 32 m²/gal
A19: ESM | B19: Esmalte sintético | C19: gal | E19: 0.3 | F19: ='PRECIOS DE INSUMOS'!$H$58 -> 48.31 | G19: =ROUND(E19*F19,2) -> 14.49 | H19: ≈4.7 m² a 2 manos, 32 m²/gal
A20: THIN | B20: Thinner | C20: gal | E20: 0.15 | F20: ='PRECIOS DE INSUMOS'!$H$59 -> 35.65 | G20: =ROUND(E20*F20,2) -> 5.35 | H20: dilución y limpieza
A21: LIJA | B21: Lija para fierro N.° 80 | C21: und | E21: 4 | F21: ='PRECIOS DE INSUMOS'!$H$60 -> 2.12 | G21: =ROUND(E21*F21,2) -> 8.48 | H21: preparación de superficie
B22: Subtotal materiales | G22: =SUM(G13:G21) -> 985.16
A23: EQUIPOS Y HERRAMIENTAS
A24: 37-0001 | B24: Herramientas manuales | C24: %MO | E24: 5 | F24: =G11 -> 1151.93 | G24: =ROUND(E24/100*F24,2) -> 57.6 | H24: 5 % de la mano de obra (amoladora, discos de corte, escuadras, prensas)
A25: SOLM | B25: Máquina de soldar eléctrica 250 A | C25: hm | E25: =ROUND(ROUND(11.8*1.05*8.34,1)/60*8,2) -> 13.77 | F25: ='PRECIOS DE INSUMOS'!$H$50 -> 5.83 | G25: =ROUND(E25*F25,2) -> 80.28 | H25: horas de fabricación del caballete
B26: Subtotal equipos y herramientas | G26: =SUM(G24:G25) -> 137.88
A27: COSTO UNITARIO DIRECTO POR glb (S/) | G27: =G11+G22+G26 -> 2274.97
A29: CÁLCULO DEL RENDIMIENTO (días-cuadrilla por componente)
A30: TIPO | B30: COMPONENTE | C30: UND | E30: CANTIDAD | F30: REND. (und/día) | G30: DÍAS | H30: CRITERIO
A31: fab | B31: Habilitado, corte y soldadura del caballete de IPN 100 | C31: kg | E31: =ROUND(11.8*1.05*8.34,1) -> 103.3 | F31: 60 | G31: =E31/F31 -> 1.7216667 | H31: 60 kg/día de estructura liviana
A32: pin | B32: Limpieza, lijado y pintura (anticorrosivo + esmalte) | C32: m2 | E32: 4.7 | F32: 25 | G32: =E32/F32 -> 0.188 | H32: 25 m²/día
A33: rue | B33: Montaje de ruedas con freno | C33: und | E33: 4 | F33: 8 | G33: =E33/F33 -> 0.5 | H33: 8 und/día
A34: tec | B34: Montaje y prueba del tecle de palanca y de la tapa | C34: und | E34: 1 | F34: 2 | G34: =E34/F34 -> 0.5 | H34: 1/2 día
B35: Total días-cuadrilla para 1 glb | G35: =SUM(G31:G34) -> 2.9096667
B36: Rendimiento = 1 / total días (glb/día) | G36: =ROUND(1/G35,4) -> 0.3437
A38: OBSERVACIONES
A39: • Caballete móvil de perfil IPN 100 con 4 ruedas giratorias con freno y tecle de palanca, para levantar las tapas de inspección del tanque séptico (1.00 x 1.00 x 0.20 m ≈ 480 kg): el tecle debe ser de 1.5 t o más.
A40: • La planilla pone «Tapa» 1 und sin medida; se analiza como plancha LAC 1/8" de 0.40 x 0.40 m (cabezal del caballete). Confirmar con el plano.
