Workbook

Sheet RESUMEN
A2: RESUMEN METRADOS DE DRENAJE PLUVIAL
A4: ENTIDAD | B4: GERENCIA TERRITORIAL BAJO MAYO - TARAPOTO
A5: PROYECTO | B5: “CREACIÓN DEL SERVICIO DE PROTECCIÓN INTEGRAL A NIÑAS, NIÑOS Y ADOLESCENTES SIN CUIDADOS PARENTALES O EN RIESGO DE PERDERLOS EN CENTRO DE ACOGIDA RESIDENCIAL - MUJERES DISTRITO DE MORALES DE LA PROVINCIA DE SAN MARTÍN DEL DEPARTAMENTO DE SAN MARTÍN”, con CUI N.° 2717013.
A6: UBICACIÓN | B6: SAN MARTIN - SAN MARTIN - MORALES
A7: FECHA | B7: 46266
A8: Item | B8: Descripción | C8: Unid. | D8: Total.
A9: 1.4.4 | B9: SISTEMA DE DRENAJE PLUVIAL
A10: 1.4.4.1 | B10: TRABAJOS PRELIMINARES
A11: 1.4.4.1.1 | B11: LIMPIEZA MANUAL DE TERRENO | C11: m² | D11: =+'PLANILLA GENERAL DE METRADOS'!K11 -> 1011.514
A12: 1.4.4.1.2 | B12: TRAZO, NIVELES Y REPLANTEO PRELIMINAR | C12: m² | D12: =+'PLANILLA GENERAL DE METRADOS'!K24 -> 1011.514
A13: 1.4.4.2 | B13: MOVIMIENTO DE TIERRAS
A14: 1.4.4.2.1 | B14: EXCAVACIÓN MANUAL DE ZANJAS P/CUNETAS | C14: m³ | D14: =+'PLANILLA GENERAL DE METRADOS'!K38 -> 647.31408
A15: 1.4.4.2.2 | B15: EXCAVACIÓN MANUAL DE ZANJAS P/DADOS DE CONCRETO | C15: m³ | D15: =+'PLANILLA GENERAL DE METRADOS'!K51 -> 3.024
A16: 1.4.4.2.3 | B16: REFINE, NIVELACIÓN Y COMPACTACIÓN EN TERRENO NORMAL | C16: m² | D16: =+'PLANILLA GENERAL DE METRADOS'!K54 -> 433.506
A17: 1.4.4.2.4 | B17: RELLENO COMPACTADO C/MATERIAL PROPIO SELECCIONADO | C17: m³ | D17: =+'PLANILLA GENERAL DE METRADOS'!K67 -> 369.89376
A18: 1.4.4.2.5 | B18: ELIMINACIÓN DE MATERIAL EXCEDENTE D<1Km | C18: m³ | D18: =+'PLANILLA GENERAL DE METRADOS'!K80 -> 332.90438
A19: 1.4.4.3 | B19: OBRAS DE CONCRETO SIMPLE
A20: 1.4.4.3.1 | B20: CONCRETO f'c=100 kg/cm2 PARA SOLADO E=4'' | C20: m² | D20: =+'PLANILLA GENERAL DE METRADOS'!K84 -> 433.506
A21: 1.4.4.3.2 | B21: CONCRETO f'c=140 Kg/cm2 PARA DADOS DE CONCRETO | C21: m³ | D21: =+'PLANILLA GENERAL DE METRADOS'!K97 -> 3.024
A22: 1.4.4.4 | B22: OBRAS DE CONCRETO ARMADO
A23: 1.4.4.4.1 | B23: CUNETAS
A24: 1.4.4.4.1.1 | B24: CONCRETO f'c=175 kg/cm2 PARA CUNETAS | C24: m³ | D24: =+'PLANILLA GENERAL DE METRADOS'!K101 -> 116.7356
A25: 1.4.4.4.1.2 | B25: ENCOFRADO Y DESENCOFRADO DE CUNETAS | C25: m² | D25: =+'PLANILLA GENERAL DE METRADOS'!K114 -> 1603.955
A26: 1.4.4.4.1.3 | B26: ACERO f'y=4200 kg/cm2 PARA CUNETA | C26: kg | D26: =+'PLANILLA GENERAL DE METRADOS'!K127 -> 3983.5486
A27: 1.4.4.4.1.4 | B27: CURADO DE CONCRETO EN CUNETA | C27: m² | D27: =+'METRADO DE CURADO'!M28 -> 1004.3559
A28: 1.4.4.4.2 | B28: VARIOS
A29: 1.4.4.4.2.1 | B29: REJILLA METALICA P/CUNETA C/PL 1''x 3/16'' Y ANGULO 1'' x 1'' x 3/16'', S/DETALLE | C29: m | D29: =+'PLANILLA GENERAL DE METRADOS'!K132 -> 627.93
A30: 1.4.4.4.2.2 | B30: TAPA DE INSPECCION 0.60m x 0.60m | C30: und | D30: =+'PLANILLA GENERAL DE METRADOS'!K133 -> 10
A31: 1.4.4.4.2.3 | B31: JUNTA DE DILATACION E=1" CON SELLADOR ASFALTO | C31: m | D31: =+'PLANILLA GENERAL DE METRADOS'!K134 -> 230.46386
A32: 1.4.4.5 | B32: RED DE COLECCIÓN
A33: 1.4.4.5.1 | B33: RED DE RECOLECCION TECHO
A34: 1.4.4.5.1.1 | B34: MONTANTE TUBERÍA PVC DE 4" | C34: m | D34: =+'PLANILLA GENERAL DE METRADOS'!K138 -> 522.96
A35: 1.4.4.5.1.2 | B35: FALSA COLUMNA P/MONTANTE DE 0.20m x 0.15m x 1.30m | C35: und | D35: =+'PLANILLA GENERAL DE METRADOS'!K139 -> 70
A36: 1.4.4.5.1.2.1 | B36: CONCRETO F´C=175 KG/CM2 EN FALSA COLUMNA | C36: m³ | D36: =+'PLANILLA GENERAL DE METRADOS'!K140 -> 2.73
A37: 1.4.4.5.1.2.2 | B37: ENCOFRADO Y DESENCOFRADO EN FALSA COLUMNA - MONTANTE PLUVIAL | C37: m² | D37: =+'PLANILLA GENERAL DE METRADOS'!K142 -> 45.5
A38: 1.4.4.5.1.2.3 | B38: ACERO FY=4200 KG/CM2 EN FALSA COLUMNA (MONTANTE PLUVIAL) | C38: kg | D38: =+'PLANILLA GENERAL DE METRADOS'!K145 -> 392.784
A39: 1.4.4.5.1.3 | B39: CANALETA DE PLANCHA DE ACERO GALVANIZADO e=0.9mm, SECCIÓN 0.25m x 0.20m | C39: m | D39: =+'PLANILLA GENERAL DE METRADOS'!K148 -> 446.22
A40: 1.4.4.5.1.4 | B40: SOPORTE DE PLATINA F°G° 1" x 1/8" P/CANALETA | C40: und | D40: =+'PLANILLA GENERAL DE METRADOS'!K149 -> 776
A41: 1.4.4.5.1.5 | B41: TAPA LATERAL DE PLANCHA GALVANIZADA P/CANALETA | C41: und | D41: =+'PLANILLA GENERAL DE METRADOS'!K150 -> 40
A42: 1.4.4.5.1.6 | B42: BOQUILLA DE PLANCHA GALVANIZADA P/CONEXIÓN DE CANALETA A MONTANTE Ø4" | C42: und | D42: =+'PLANILLA GENERAL DE METRADOS'!K151 -> 44
...

Sheet PLANILLA GENERAL DE METRADOS
A2: RESUMEN METRADOS DE DRENAJE PLUVIAL
A3: ENTIDAD | B3: =+RESUMEN!B4 -> GERENCIA TERRITORIAL BAJO MAYO - TARAPOTO
A4: PROYECTO | B4: =+RESUMEN!B5 -> “CREACIÓN DEL SERVICIO DE PROTECCIÓN INTEGRAL A NIÑAS, NIÑOS Y ADOLESCENTES SIN CUIDADOS PARENTALES O EN RIESGO DE PERDERLOS EN CENTRO DE ACOGIDA RESIDENCIAL - MUJERES DISTRITO DE MORALES DE LA PROVINCIA DE SAN MARTÍN DEL DEPARTAMENTO DE SAN MARTÍN”, con CUI N.° 2717013.
A5: UBICACIÓN | B5: =+RESUMEN!B6 -> SAN MARTIN - SAN MARTIN - MORALES
A6: FECHA | B6: =+RESUMEN!B7 -> 46266
A8: ITEM | B8: DESCRIPCION | C8: Nº DE VECES | D8: LARGO | E8: ANCHO | F8: ALTURA | G8: FACT. | H8: AREA | I8: VOLUMEN | J8: PARCIAL | K8: TOTAL | L8: UND
A9: 1.4.4 | B9: SISTEMA DE DRENAJE PLUVIAL
A10: 1.4.4.1 | B10: TRABAJOS PRELIMINARES
A11: 1.4.4.1.1 | B11: LIMPIEZA MANUAL DE TERRENO | K11: =SUM(J12:J23) -> 1011.514 | L11: m²
B12: EJE 1 | C12: 1 | D12: 23.6 | E12: 1.4 | J12: =C12*D12*E12 -> 33.04
B13: EJE 2 | C13: 1 | D13: 143.5 | E13: 1.4 | J13: =C13*D13*E13 -> 200.9
B14: EJE 3 | C14: 1 | D14: 26.35 | E14: 1.4 | J14: =C14*D14*E14 -> 36.89
B15: EJE 4 | C15: 1 | D15: 9.65 | E15: 1.4 | J15: =C15*D15*E15 -> 13.51
B16: EJE 5 | C16: 1 | D16: 25.66 | E16: 1.4 | J16: =C16*D16*E16 -> 35.924
B17: EJE 6 | C17: 1 | D17: 106.95 | E17: 1.4 | J17: =C17*D17*E17 -> 149.73
B18: EJE 7 | C18: 1 | D18: 141.2 | E18: 1.4 | J18: =C18*D18*E18 -> 197.68
B19: EJE 8 | C19: 1 | D19: 23.3 | E19: 1.4 | J19: =C19*D19*E19 -> 32.62
B20: EJE 9 | C20: 1 | D20: 60.7 | E20: 1.4 | J20: =C20*D20*E20 -> 84.98
B21: EJE 10 | C21: 1 | D21: 51.25 | E21: 1.4 | J21: =C21*D21*E21 -> 71.75
B22: EJE 11 | C22: 1 | D22: 15.5 | E22: 1.4 | J22: =C22*D22*E22 -> 21.7
B23: EJE 12 | C23: 1 | D23: 94.85 | E23: 1.4 | J23: =C23*D23*E23 -> 132.79
A24: 1.4.4.1.2 | B24: TRAZO, NIVELES Y REPLANTEO PRELIMINAR | K24: =SUM(J25:J36) -> 1011.514 | L24: m²
B25: EJE 1 | C25: 1 | D25: 23.6 | E25: 1.4 | J25: =C25*D25*E25 -> 33.04
B26: EJE 2 | C26: 1 | D26: 143.5 | E26: 1.4 | J26: =C26*D26*E26 -> 200.9
B27: EJE 3 | C27: 1 | D27: 26.35 | E27: 1.4 | J27: =C27*D27*E27 -> 36.89
B28: EJE 4 | C28: 1 | D28: 9.65 | E28: 1.4 | J28: =C28*D28*E28 -> 13.51
B29: EJE 5 | C29: 1 | D29: 25.66 | E29: 1.4 | J29: =C29*D29*E29 -> 35.924
B30: EJE 6 | C30: 1 | D30: 106.95 | E30: 1.4 | J30: =C30*D30*E30 -> 149.73
B31: EJE 7 | C31: 1 | D31: 141.2 | E31: 1.4 | J31: =C31*D31*E31 -> 197.68
B32: EJE 8 | C32: 1 | D32: 23.3 | E32: 1.4 | J32: =C32*D32*E32 -> 32.62
B33: EJE 9 | C33: 1 | D33: 60.7 | E33: 1.4 | J33: =C33*D33*E33 -> 84.98
B34: EJE 10 | C34: 1 | D34: 51.25 | E34: 1.4 | J34: =C34*D34*E34 -> 71.75
B35: EJE 11 | C35: 1 | D35: 15.5 | E35: 1.4 | J35: =C35*D35*E35 -> 21.7
B36: EJE 12 | C36: 1 | D36: 94.85 | E36: 1.4 | J36: =C36*D36*E36 -> 132.79
A37: 1.4.4.2 | B37: MOVIMIENTO DE TIERRAS
A38: 1.4.4.2.1 | B38: EXCAVACIÓN MANUAL DE ZANJAS P/CUNETAS | K38: =SUM(J39:J50) -> 647.31408 | L38: m³
B39: EJE 1 | C39: 1 | D39: 23.6 | E39: 1.4 | F39: 0.41 | J39: =C39*D39*E39*(F39+PARAMETROS!$B$15) -> 16.8504
B40: EJE 2 | C40: 1 | D40: 143.5 | E40: 1.4 | F40: 0.65 | J40: =C40*D40*E40*(F40+PARAMETROS!$B$15) -> 150.675
B41: EJE 3 | C41: 1 | D41: 26.35 | E41: 1.4 | F41: 0.37 | J41: =C41*D41*E41*(F41+PARAMETROS!$B$15) -> 17.3383
B42: EJE 4 | C42: 1 | D42: 9.65 | E42: 1.4 | F42: 0.33 | J42: =C42*D42*E42*(F42+PARAMETROS!$B$15) -> 5.8093
...

Sheet METRADO MONTANTES
B2: CALCULO DE MONTANTES POR EDIFICACION - DRENAJE PLUVIAL
B3: ENTIDAD | C3: =+RESUMEN!B4 -> GERENCIA TERRITORIAL BAJO MAYO - TARAPOTO
B4: PROYECTO | C4: =+RESUMEN!B5 -> “CREACIÓN DEL SERVICIO DE PROTECCIÓN INTEGRAL A NIÑAS, NIÑOS Y ADOLESCENTES SIN CUIDADOS PARENTALES O EN RIESGO DE PERDERLOS EN CENTRO DE ACOGIDA RESIDENCIAL - MUJERES DISTRITO DE MORALES DE LA PROVINCIA DE SAN MARTÍN DEL DEPARTAMENTO DE SAN MARTÍN”, con CUI N.° 2717013.
B5: UBICACIÓN | C5: =+RESUMEN!B6 -> SAN MARTIN - SAN MARTIN - MORALES
B6: FECHA | C6: =+RESUMEN!B7 -> 46266
C9: MONTANTES | D9: LONG. TUBERIA PVC 4" | G9: CODO PVC 90° 4" | J9: CODO PVC 45° 4" | M9: ABRAZADERA 4" | P9: COLGADOR 4"
D10: VECES | E10: LONGITUD | F10: TOTAL (m) | G10: CANTIDAD | H10: VECES | I10: TOTAL (und) | J10: CANTIDAD | K10: VECES | L10: TOTAL (und) | M10: CANTIDAD | N10: VECES | O10: TOTAL (und) | P10: CANTIDAD | Q10: VECES | R10: TOTAL (und)
B11: BLOQUE 01
B12: Lado A | C12: 2 | D12: 2 | E12: 6.25 | F12: =E12*D12 -> 12.5 | G12: 3 | H12: 2 | I12: =H12*G12 -> 6 | J12: 0 | K12: 0 | L12: =K12*J12 -> 0 | M12: 1 | N12: 2 | O12: =N12*M12 -> 2 | P12: 2 | Q12: 2 | R12: =Q12*P12 -> 4
B13: Lado B | C13: 2 | D13: 2 | E13: 6.2 | F13: =E13*D13 -> 12.4 | G13: 3 | H13: 2 | I13: =H13*G13 -> 6 | L13: =K13*J13 -> 0 | M13: 1 | N13: 2 | O13: =N13*M13 -> 2 | P13: 2 | Q13: 2 | R13: =Q13*P13 -> 4
B14: BLOQUE 02
B15: Lado A | C15: 2 | D15: 2 | E15: 6.2 | F15: =E15*D15 -> 12.4 | G15: 3 | H15: 2 | I15: =H15*G15 -> 6 | L15: =K15*J15 -> 0 | M15: 1 | N15: 2 | O15: =N15*M15 -> 2 | P15: 2 | Q15: 2 | R15: =Q15*P15 -> 4
B16: Lado B | C16: 2 | D16: 2 | E16: 6.25 | F16: =E16*D16 -> 12.5 | G16: 3 | H16: 2 | I16: =H16*G16 -> 6 | L16: =K16*J16 -> 0 | M16: 1 | N16: 2 | O16: =N16*M16 -> 2 | P16: 2 | Q16: 2 | R16: =Q16*P16 -> 4
B17: BLOQUE 03
B18: Lado A | C18: 2 | D18: 2 | E18: 6.18 | F18: =E18*D18 -> 12.36 | G18: 3 | H18: 2 | I18: =H18*G18 -> 6 | L18: =K18*J18 -> 0 | M18: 1 | N18: 2 | O18: =N18*M18 -> 2 | P18: 2 | Q18: 2 | R18: =Q18*P18 -> 4
B19: Lado B | C19: 2 | D19: 2 | E19: 6.18 | F19: =E19*D19 -> 12.36 | G19: 3 | H19: 2 | I19: =H19*G19 -> 6 | L19: =K19*J19 -> 0 | M19: 1 | N19: 2 | O19: =N19*M19 -> 2 | P19: 2 | Q19: 2 | R19: =Q19*P19 -> 4
B20: BLOQUE 04
B21: Lado A | C21: 2 | D21: 2 | E21: 6.18 | F21: =E21*D21 -> 12.36 | G21: 3 | H21: 2 | I21: =H21*G21 -> 6 | L21: =K21*J21 -> 0 | M21: 1 | N21: 2 | O21: =N21*M21 -> 2 | P21: 2 | Q21: 2 | R21: =Q21*P21 -> 4
B22: Lado B | C22: 2 | D22: 2 | E22: 6.18 | F22: =E22*D22 -> 12.36 | G22: 3 | H22: 2 | I22: =H22*G22 -> 6 | L22: =K22*J22 -> 0 | M22: 1 | N22: 2 | O22: =N22*M22 -> 2 | P22: 2 | Q22: 2 | R22: =Q22*P22 -> 4
B23: BLOQUE 05
B24: Lado A | C24: 2 | D24: 2 | E24: 6.23 | F24: =E24*D24 -> 12.46 | G24: 3 | H24: 2 | I24: =H24*G24 -> 6 | L24: =K24*J24 -> 0 | M24: 1 | N24: 2 | O24: =N24*M24 -> 2 | P24: 2 | Q24: 2 | R24: =Q24*P24 -> 4
B25: Lado B | C25: 2 | D25: 2 | E25: 6.23 | F25: =E25*D25 -> 12.46 | G25: 3 | H25: 2 | I25: =H25*G25 -> 6 | L25: =K25*J25 -> 0 | M25: 1 | N25: 2 | O25: =N25*M25 -> 2 | P25: 2 | Q25: 2 | R25: =Q25*P25 -> 4
B26: BLOQUE 06
B27: Lado A | C27: 2 | D27: 2 | E27: 6.1 | F27: =E27*D27 -> 12.2 | G27: 3 | H27: 2 | I27: =H27*G27 -> 6 | L27: =K27*J27 -> 0 | M27: 1 | N27: 2 | O27: =N27*M27 -> 2 | P27: 2 | Q27: 2 | R27: =Q27*P27 -> 4
B28: Lado B | C28: 2 | D28: 2 | E28: 6.1 | F28: =E28*D28 -> 12.2 | G28: 3 | H28: 2 | I28: =H28*G28 -> 6 | L28: =K28*J28 -> 0 | M28: 1 | N28: 2 | O28: =N28*M28 -> 2 | P28: 2 | Q28: 2 | R28: =Q28*P28 -> 4
B29: BLOQUE 07
B30: Lado A | C30: 2 | D30: 2 | E30: 6.18 | F30: =E30*D30 -> 12.36 | G30: 3 | H30: 2 | I30: =H30*G30 -> 6 | L30: =K30*J30 -> 0 | M30: 1 | N30: 2 | O30: =N30*M30 -> 2 | P30: 2 | Q30: 2 | R30: =Q30*P30 -> 4
B31: Lado B | C31: 2 | D31: 2 | E31: 6.18 | F31: =E31*D31 -> 12.36 | G31: 3 | H31: 2 | I31: =H31*G31 -> 6 | L31: =K31*J31 -> 0 | M31: 1 | N31: 2 | O31: =N31*M31 -> 2 | P31: 2 | Q31: 2 | R31: =Q31*P31 -> 4
B32: BLOQUE 08
B33: Lado A | C33: 2 | D33: 2 | E33: 6.18 | F33: =E33*D33 -> 12.36 | G33: 3 | H33: 2 | I33: =H33*G33 -> 6 | L33: =K33*J33 -> 0 | M33: 1 | N33: 2 | O33: =N33*M33 -> 2 | P33: 2 | Q33: 2 | R33: =Q33*P33 -> 4
B34: Lado B | C34: 2 | D34: 2 | E34: 6.18 | F34: =E34*D34 -> 12.36 | G34: 3 | H34: 2 | I34: =H34*G34 -> 6 | L34: =K34*J34 -> 0 | M34: 1 | N34: 2 | O34: =N34*M34 -> 2 | P34: 2 | Q34: 2 | R34: =Q34*P34 -> 4
B35: BLOQUE 09
B36: Lado A | C36: 2 | D36: 2 | E36: 8.2 | F36: =E36*D36 -> 16.4 | G36: 3 | H36: 2 | I36: =H36*G36 -> 6 | L36: =K36*J36 -> 0 | M36: 2 | N36: 2 | O36: =N36*M36 -> 4 | P36: 2 | Q36: 2 | R36: =Q36*P36 -> 4
B37: Lado B | C37: 2 | D37: 2 | E37: 8.2 | F37: =E37*D37 -> 16.4 | G37: 3 | H37: 2 | I37: =H37*G37 -> 6 | L37: =K37*J37 -> 0 | M37: 2 | N37: 2 | O37: =N37*M37 -> 4 | P37: 2 | Q37: 2 | R37: =Q37*P37 -> 4
B38: Lado A" | C38: 2 | D38: 2 | E38: 6.2 | F38: =E38*D38 -> 12.4 | G38: 3 | H38: 2 | I38: =H38*G38 -> 6 | L38: =K38*J38 -> 0 | M38: 1 | N38: 2 | O38: =N38*M38 -> 2 | P38: 2 | Q38: 2 | R38: =Q38*P38 -> 4
B39: Lado B" | C39: 2 | D39: 2 | E39: 6.2 | F39: =E39*D39 -> 12.4 | G39: 3 | H39: 2 | I39: =H39*G39 -> 6 | L39: =K39*J39 -> 0 | M39: 1 | N39: 2 | O39: =N39*M39 -> 2 | P39: 2 | Q39: 2 | R39: =Q39*P39 -> 4
B40: BLOQUE 10
B41: Lado A | C41: 2 | D41: 2 | E41: 6.22 | F41: =E41*D41 -> 12.44 | G41: 3 | H41: 2 | I41: =H41*G41 -> 6 | L41: =K41*J41 -> 0 | M41: 1 | N41: 2 | O41: =N41*M41 -> 2 | P41: 2 | Q41: 2 | R41: =Q41*P41 -> 4
B42: Lado B | C42: 2 | D42: 2 | E42: 6.22 | F42: =E42*D42 -> 12.44 | G42: 3 | H42: 2 | I42: =H42*G42 -> 6 | L42: =K42*J42 -> 0 | M42: 1 | N42: 2 | O42: =N42*M42 -> 2 | P42: 2 | Q42: 2 | R42: =Q42*P42 -> 4
B43: LOSA DEPORTIVA
...

Sheet CONCRETO EN CUNETAS
B2: CONCRETO F´C=175 KG/CM2 PARA CUNETAS - DRENAJE PLUVIAL
B3: ENTIDAD | C3: =+RESUMEN!B4 -> GERENCIA TERRITORIAL BAJO MAYO - TARAPOTO
B4: PROYECTO | C4: =+RESUMEN!B5 -> “CREACIÓN DEL SERVICIO DE PROTECCIÓN INTEGRAL A NIÑAS, NIÑOS Y ADOLESCENTES SIN CUIDADOS PARENTALES O EN RIESGO DE PERDERLOS EN CENTRO DE ACOGIDA RESIDENCIAL - MUJERES DISTRITO DE MORALES DE LA PROVINCIA DE SAN MARTÍN DEL DEPARTAMENTO DE SAN MARTÍN”, con CUI N.° 2717013.
B5: UBICACIÓN | C5: =+RESUMEN!B6 -> SAN MARTIN - SAN MARTIN - MORALES
B6: FECHA | C6: =+RESUMEN!B7 -> 46266
B7: OBRAS DE CONCRETO ARMADO
B9: LONGITUDES Y AREAS | E9: m3 | F9: Sub.TOTAL | G9: TOTAL (m3) | J9: LONGITUDES Y AREAS | M9: m3 | N9: Sub.TOTAL | O9: TOTAL (m3)
B10: CUNETA EJE 01 | C10: MUROS | D10: AREA | E10: 7.29 | F10: =E10*E11*E12 -> 1.458 | G10: =SUM(F10:F18) -> 2.874 | J10: CUNETA EJE 07 | K10: MUROS | L10: AREA | M10: 79.34 | N10: =M10*M11*M12 -> 15.868 | O10: =SUM(N10:N18) -> 25.645
D11: ESPESOR | E11: 0.1 | L11: ESPESOR | M11: 0.1
D12: CANT. | E12: 2 | L12: CANT. | M12: 2
C13: LOSA | D13: ESPESOR | E13: 0.1 | F13: =E13*E14*E15 -> 1.416 | K13: LOSA | L13: ESPESOR | M13: 0.1 | N13: =M13*M14*M15 -> 8.472
D14: LONGITUD | E14: 23.6 | L14: LONGITUD | M14: 141.2
D15: ANCHO | E15: 0.6 | L15: ANCHO | M15: 0.6
C16: TAPA | D16: LONGITUD | E16: 0 | F16: =E16*E17*E18 -> 0 | K16: TAPA | L16: LONGITUD | M16: 21.75 | N16: =M16*M17*M18 -> 1.305
D17: ESPESOR | E17: 0.1 | L17: ESPESOR | M17: 0.1
D18: ANCHO | E18: 0.6 | L18: ANCHO | M18: 0.6
B21: LONGITUDES Y AREAS | E21: m3 | F21: Sub.TOTAL | G21: TOTAL (m3) | J21: LONGITUDES Y AREAS | M21: m3 | N21: Sub.TOTAL | O21: TOTAL (m3)
B22: CUNETA EJE 02 | C22: MUROS | D22: AREA | E22: 82.33 | F22: =E22*E23*E24 -> 16.466 | G22: =SUM(F22:F30) -> 26.018 | J22: CUNETA EJE 08 | K22: MUROS | L22: AREA | M22: 7.18 | N22: =M22*M23*M24 -> 1.436 | O22: =SUM(N22:N30) -> 2.834
D23: ESPESOR | E23: 0.1 | L23: ESPESOR | M23: 0.1
D24: CANT. | E24: 2 | L24: CANT. | M24: 2
C25: LOSA | D25: ESPESOR | E25: 0.1 | F25: =E25*E26*E27 -> 8.61 | K25: LOSA | L25: ESPESOR | M25: 0.1 | N25: =M25*M26*M27 -> 1.398
D26: LONGITUD | E26: 143.5 | L26: LONGITUD | M26: 23.3
D27: ANCHO | E27: 0.6 | L27: ANCHO | M27: 0.6
C28: TAPA | D28: LONGITUD | E28: 15.7 | F28: =E28*E29*E30 -> 0.942 | K28: TAPA | L28: LONGITUD | N28: =M28*M29*M30 -> 0
D29: ESPESOR | E29: 0.1 | L29: ESPESOR | M29: 0.1
D30: ANCHO | E30: 0.6 | L30: ANCHO | M30: 0.6
B33: LONGITUDES Y AREAS | E33: m3 | F33: Sub.TOTAL | G33: TOTAL (m3) | J33: LONGITUDES Y AREAS | M33: m3 | N33: Sub.TOTAL | O33: TOTAL (m3)
B34: CUNETA EJE 03 | C34: MUROS | D34: AREA | E34: 8.32 | F34: =E34*E35*E36 -> 1.664 | G34: =SUM(F34:F42) -> 3.245 | J34: CUNETA EJE 09 | K34: MUROS | L34: AREA | M34: 24.38 | N34: =M34*M35*M36 -> 4.876 | O34: =SUM(N34:N42) -> 8.518
D35: ESPESOR | E35: 0.1 | L35: ESPESOR | M35: 0.1
D36: CANT. | E36: 2 | L36: CANT. | M36: 2
C37: LOSA | D37: ESPESOR | E37: 0.1 | F37: =E37*E38*E39 -> 1.581 | K37: LOSA | L37: ESPESOR | M37: 0.1 | N37: =M37*M38*M39 -> 3.642
D38: LONGITUD | E38: 26.35 | L38: LONGITUD | M38: 60.7
D39: ANCHO | E39: 0.6 | L39: ANCHO | M39: 0.6
C40: TAPA | D40: LONGITUD | E40: 0 | F40: =E40*E41*E42 -> 0 | K40: TAPA | L40: LONGITUD | N40: =M40*M41*M42 -> 0
D41: ESPESOR | E41: 0.1 | L41: ESPESOR | M41: 0.1
D42: ANCHO | E42: 0.6 | L42: ANCHO | M42: 0.6
B45: LONGITUDES Y AREAS | E45: m3 | F45: Sub.TOTAL | G45: TOTAL (m3) | J45: LONGITUDES Y AREAS | M45: m3 | N45: Sub.TOTAL | O45: TOTAL (m3)
B46: CUNETA EJE 04 | C46: MUROS | D46: AREA | E46: 2.64 | F46: =E46*E47*E48 -> 0.528 | G46: =SUM(F46:F54) -> 1.107 | J46: CUNETA EJE 10 | K46: MUROS | L46: AREA | M46: 18.33 | N46: =M46*M47*M48 -> 3.666 | O46: =SUM(N46:N54) -> 7.623
D47: ESPESOR | E47: 0.1 | L47: ESPESOR | M47: 0.1
D48: CANT. | E48: 2 | L48: CANT. | M48: 2
...

Sheet ENCOFRADO Y DESENCOFRADO
B2: ENCOFRADO Y DESENCOFRADO CUNETAS - DRENAJE PLUVIAL
B3: ENTIDAD | C3: =+RESUMEN!B4 -> GERENCIA TERRITORIAL BAJO MAYO - TARAPOTO
B4: PROYECTO | C4: =+RESUMEN!B5 -> “CREACIÓN DEL SERVICIO DE PROTECCIÓN INTEGRAL A NIÑAS, NIÑOS Y ADOLESCENTES SIN CUIDADOS PARENTALES O EN RIESGO DE PERDERLOS EN CENTRO DE ACOGIDA RESIDENCIAL - MUJERES DISTRITO DE MORALES DE LA PROVINCIA DE SAN MARTÍN DEL DEPARTAMENTO DE SAN MARTÍN”, con CUI N.° 2717013.
B5: UBICACIÓN | C5: =+RESUMEN!B6 -> SAN MARTIN - SAN MARTIN - MORALES
B6: FECHA | C6: =+RESUMEN!B7 -> 46266
B8: OBRAS DE CONCRETO ARMADO - ENCOFRADO Y DESENCOFRADO CUNETAS
B11: LONGITUDES Y AREAS | G11: Sub.TOTAL | H11: TOTAL (m2) | J11: LONGITUDES Y AREAS | O11: Sub.TOTAL | P11: TOTAL (m2)
B12: EJE1 | C12: ABIERTA | D12: MUROS EXTERNO | E12: AREA | F12: 9.6525 | G12: =F12*F13 -> 19.305 | H12: =SUM(G12:G20) -> 33.885 | J12: EJE 2 | K12: NORMAL | L12: MUROS EXTERNO | M12: AREA | N12: 85.56 | O12: =N12*N13 -> 171.12 | P12: =SUM(O12:O20) -> 368.38
E13: CANT. | F13: 2 | M13: CANT. | N13: 2
D14: MURO INTERNO | E14: AREA | F14: 7.29 | G14: =F14*F15 -> 14.58 | L14: MURO INTERNO | M14: AREA | N14: 72.78 | O14: =N14*N15 -> 145.56
E15: CANTIDAD | F15: 2 | M15: CANTIDAD | N15: 2
C16: TAPADO | D16: MURO EXTERNO | E16: AREA | F16: 0 | G16: =F16*F17 -> 0 | K16: TAPADO | L16: MURO EXTERNO | M16: AREA | N16: 12.76 | O16: =N16*N17 -> 25.52
E17: CANT. | F17: 2 | M17: CANT. | N17: 2
D18: MURO INTERNO | E18: AREA | F18: 0 | G18: =(F18*F19)+F20 -> 0 | L18: MURO INTERNO | M18: AREA | N18: 9.55 | O18: =N18*N19+N20 -> 26.18
E19: CANTIDAD | F19: 2 | M19: CANTIDAD | N19: 2
E20: TAPA | F20: 0 | M20: TAPA | N20: =17.7*0.4 -> 7.08
B22: LONGITUDES Y AREAS | G22: Sub.TOTAL | H22: TOTAL (m2) | J22: LONGITUDES Y AREAS | O22: Sub.TOTAL | P22: TOTAL (m2)
B23: EJE 3 | C23: ABIERTA | D23: MUROS EXTERNO | E23: AREA | F23: 10.95 | G23: =F23*F24 -> 21.9 | H23: =SUM(G23:G31) -> 38.54 | J23: EJE 4 | K23: NORMAL | L23: MUROS EXTERNO | M23: AREA | N23: 3.61 | O23: =N23*N24 -> 7.22 | P23: =SUM(O23:O31) -> 12.5
E24: CANT. | F24: 2 | M24: CANT. | N24: 2
D25: MURO INTERNO | E25: AREA | F25: 8.32 | G25: =F25*F26 -> 16.64 | L25: MURO INTERNO | M25: AREA | N25: 2.64 | O25: =N25*N26 -> 5.28
E26: CANTIDAD | F26: 2 | M26: CANTIDAD | N26: 2
C27: TAPADO | D27: MURO EXTERNO | E27: AREA | F27: 0 | G27: =F27*F28 -> 0 | K27: TAPADO | L27: MURO EXTERNO | M27: AREA | N27: 0 | O27: =N27*N28 -> 0
E28: CANT. | F28: 2 | M28: CANT. | N28: 2
D29: MURO INTERNO | E29: AREA | F29: 0 | G29: =F29*F30+F31 -> 0 | L29: MURO INTERNO | M29: AREA | N29: 0 | O29: =N29*N30+N31 -> 0
E30: CANTIDAD | F30: 2 | M30: CANTIDAD | N30: 2
E31: TAPA | F31: 0 | M31: TAPA | N31: 0
B33: LONGITUDES Y AREAS | G33: Sub.TOTAL | H33: TOTAL (m2) | J33: LONGITUDES Y AREAS | O33: Sub.TOTAL | P33: TOTAL (m2)
B34: EJE 5 | C34: NORMAL | D34: MUROS EXTERNO | E34: AREA | F34: 10.62 | G34: =F34*F35 -> 21.24 | H34: =SUM(G34:G42) -> 37.36 | J34: EJE 6 | K34: NORMAL | L34: MUROS EXTERNO | M34: AREA | N34: 66.02 | O34: =N34*N35 -> 132.04 | P34: =SUM(O34:O42) -> 242.68
E35: CANT. | F35: 2 | M35: CANT. | N35: 2
D36: MURO INTERNO | E36: AREA | F36: 8.06 | G36: =F36*F37 -> 16.12 | L36: MURO INTERNO | M36: AREA | N36: 55.32 | O36: =N36*N37 -> 110.64
E37: CANTIDAD | F37: 2 | M37: CANTIDAD | N37: 2
C38: TAPADO | D38: MURO EXTERNO | E38: AREA | F38: 0 | G38: =F38*F39 -> 0 | K38: TAPADO | L38: MURO EXTERNO | M38: AREA | N38: 0 | O38: =N38*N39 -> 0
E39: CANT. | F39: 2 | M39: CANT. | N39: 2
D40: MURO INTERNO | E40: AREA | F40: 0 | G40: =F40*F41+F42 -> 0 | L40: MURO INTERNO | M40: AREA | N40: 0 | O40: =N40*N41+N42 -> 0
E41: CANTIDAD | F41: 2 | M41: CANTIDAD | N41: 2
E42: TAPA | F42: 0 | M42: TAPA | N42: 0
B44: LONGITUDES Y AREAS | G44: Sub.TOTAL | H44: TOTAL (m2) | J44: LONGITUDES Y AREAS | O44: Sub.TOTAL | P44: TOTAL (m2)
B45: EJE 7 | C45: NORMAL | D45: MUROS EXTERNO | E45: AREA | F45: 80.52 | G45: =F45*F46 -> 161.04 | H45: =SUM(G45:G53) -> 371.77 | J45: EJE 8 | K45: NORMAL | L45: MUROS EXTERNO | M45: AREA | N45: 9.51 | O45: =N45*N46 -> 19.02 | P45: =SUM(O45:O53) -> 33.38
E46: CANT. | F46: 2 | M46: CANT. | N46: 2
D47: MURO INTERNO | E47: AREA | F47: 68.57 | G47: =F47*F48 -> 137.14 | L47: MURO INTERNO | M47: AREA | N47: 7.18 | O47: =N47*N48 -> 14.36
...

Sheet METRADO CANALETAS
B2: METRADO DE CANALETAS DE TECHO - DRENAJE PLUVIAL
B3: ENTIDAD | C3: =+RESUMEN!B4 -> GERENCIA TERRITORIAL BAJO MAYO - TARAPOTO
B4: PROYECTO | C4: =+RESUMEN!B5 -> “CREACIÓN DEL SERVICIO DE PROTECCIÓN INTEGRAL A NIÑAS, NIÑOS Y ADOLESCENTES SIN CUIDADOS PARENTALES O EN RIESGO DE PERDERLOS EN CENTRO DE ACOGIDA RESIDENCIAL - MUJERES DISTRITO DE MORALES DE LA PROVINCIA DE SAN MARTÍN DEL DEPARTAMENTO DE SAN MARTÍN”, con CUI N.° 2717013.
B5: UBICACIÓN | C5: =+RESUMEN!B6 -> SAN MARTIN - SAN MARTIN - MORALES
B6: FECHA | C6: =+RESUMEN!B7 -> 46266
B8: CANALETA DE PLANCHA DE ACERO GALVANIZADO - SECCIÓN INTERIOR 0.25 m (FONDO) x 0.20 m (ALTO) - TECHOS A DOS AGUAS: UNA CANALETA POR CADA LADO
B9: EDIFICACIÓN | C9: N° DE CANALETAS | D9: CANALETA 0.25 x 0.20 m | F9: SOPORTE PLATINA F°G° 1" x 1/8" | H9: TAPA LATERAL | J9: BOQUILLA A MONTANTE Ø4"
D10: LONGITUD (m) | E10: TOTAL (m) | F10: CANTIDAD | G10: TOTAL (und) | H10: CANTIDAD | I10: TOTAL (und) | J10: CANTIDAD | K10: TOTAL (und)
B11: EDIFICACION 01
B12: Lado 01 | C12: 1 | D12: 25.78 | E12: =C12*D12 -> 25.78 | F12: =IF(D12>0,ROUNDUP(D12/$F$50,0)+1,0) -> 44 | G12: =C12*F12 -> 44 | H12: =$F$51 -> 2 | I12: =C12*H12 -> 2 | J12: ='METRADO MONTANTES'!C12 -> 2 | K12: =C12*J12 -> 2
B13: Lado 02 | C13: 1 | D13: =D12 -> 25.78 | E13: =C13*D13 -> 25.78 | F13: =IF(D13>0,ROUNDUP(D13/$F$50,0)+1,0) -> 44 | G13: =C13*F13 -> 44 | H13: =$F$51 -> 2 | I13: =C13*H13 -> 2 | J13: ='METRADO MONTANTES'!C13 -> 2 | K13: =C13*J13 -> 2
B14: EDIFICACION 02
B15: Lado 01 | C15: 1 | D15: 9.73 | E15: =C15*D15 -> 9.73 | F15: =IF(D15>0,ROUNDUP(D15/$F$50,0)+1,0) -> 18 | G15: =C15*F15 -> 18 | H15: =$F$51 -> 2 | I15: =C15*H15 -> 2 | J15: ='METRADO MONTANTES'!C15 -> 2 | K15: =C15*J15 -> 2
B16: Lado 02 | C16: 1 | D16: =D15 -> 9.73 | E16: =C16*D16 -> 9.73 | F16: =IF(D16>0,ROUNDUP(D16/$F$50,0)+1,0) -> 18 | G16: =C16*F16 -> 18 | H16: =$F$51 -> 2 | I16: =C16*H16 -> 2 | J16: ='METRADO MONTANTES'!C16 -> 2 | K16: =C16*J16 -> 2
B17: EDIFICACION 03
B18: Lado 01 | C18: 1 | D18: 26.53 | E18: =C18*D18 -> 26.53 | F18: =IF(D18>0,ROUNDUP(D18/$F$50,0)+1,0) -> 46 | G18: =C18*F18 -> 46 | H18: =$F$51 -> 2 | I18: =C18*H18 -> 2 | J18: ='METRADO MONTANTES'!C18 -> 2 | K18: =C18*J18 -> 2
B19: Lado 02 | C19: 1 | D19: =D18 -> 26.53 | E19: =C19*D19 -> 26.53 | F19: =IF(D19>0,ROUNDUP(D19/$F$50,0)+1,0) -> 46 | G19: =C19*F19 -> 46 | H19: =$F$51 -> 2 | I19: =C19*H19 -> 2 | J19: ='METRADO MONTANTES'!C19 -> 2 | K19: =C19*J19 -> 2
B20: EDIFICACION 04
B21: Lado 01 | C21: 1 | D21: 26.53 | E21: =C21*D21 -> 26.53 | F21: =IF(D21>0,ROUNDUP(D21/$F$50,0)+1,0) -> 46 | G21: =C21*F21 -> 46 | H21: =$F$51 -> 2 | I21: =C21*H21 -> 2 | J21: ='METRADO MONTANTES'!C21 -> 2 | K21: =C21*J21 -> 2
B22: Lado 02 | C22: 1 | D22: =D21 -> 26.53 | E22: =C22*D22 -> 26.53 | F22: =IF(D22>0,ROUNDUP(D22/$F$50,0)+1,0) -> 46 | G22: =C22*F22 -> 46 | H22: =$F$51 -> 2 | I22: =C22*H22 -> 2 | J22: ='METRADO MONTANTES'!C22 -> 2 | K22: =C22*J22 -> 2
B23: EDIFICACION 05
B24: Lado 01 | C24: 1 | D24: 15.16 | E24: =C24*D24 -> 15.16 | F24: =IF(D24>0,ROUNDUP(D24/$F$50,0)+1,0) -> 27 | G24: =C24*F24 -> 27 | H24: =$F$51 -> 2 | I24: =C24*H24 -> 2 | J24: ='METRADO MONTANTES'!C24 -> 2 | K24: =C24*J24 -> 2
B25: Lado 02 | C25: 1 | D25: =D24 -> 15.16 | E25: =C25*D25 -> 15.16 | F25: =IF(D25>0,ROUNDUP(D25/$F$50,0)+1,0) -> 27 | G25: =C25*F25 -> 27 | H25: =$F$51 -> 2 | I25: =C25*H25 -> 2 | J25: ='METRADO MONTANTES'!C25 -> 2 | K25: =C25*J25 -> 2
B26: EDIFICACION 06
B27: Lado 01 | C27: 1 | D27: 14.78 | E27: =C27*D27 -> 14.78 | F27: =IF(D27>0,ROUNDUP(D27/$F$50,0)+1,0) -> 26 | G27: =C27*F27 -> 26 | H27: =$F$51 -> 2 | I27: =C27*H27 -> 2 | J27: ='METRADO MONTANTES'!C27 -> 2 | K27: =C27*J27 -> 2
B28: Lado 02 | C28: 1 | D28: =D27 -> 14.78 | E28: =C28*D28 -> 14.78 | F28: =IF(D28>0,ROUNDUP(D28/$F$50,0)+1,0) -> 26 | G28: =C28*F28 -> 26 | H28: =$F$51 -> 2 | I28: =C28*H28 -> 2 | J28: ='METRADO MONTANTES'!C28 -> 2 | K28: =C28*J28 -> 2
B29: EDIFICACION 07
B30: Lado 01 | C30: 1 | D30: 26.53 | E30: =C30*D30 -> 26.53 | F30: =IF(D30>0,ROUNDUP(D30/$F$50,0)+1,0) -> 46 | G30: =C30*F30 -> 46 | H30: =$F$51 -> 2 | I30: =C30*H30 -> 2 | J30: ='METRADO MONTANTES'!C30 -> 2 | K30: =C30*J30 -> 2
B31: Lado 02 | C31: 1 | D31: =D30 -> 26.53 | E31: =C31*D31 -> 26.53 | F31: =IF(D31>0,ROUNDUP(D31/$F$50,0)+1,0) -> 46 | G31: =C31*F31 -> 46 | H31: =$F$51 -> 2 | I31: =C31*H31 -> 2 | J31: ='METRADO MONTANTES'!C31 -> 2 | K31: =C31*J31 -> 2
B32: EDIFICACION 08
B33: Lado 01 | C33: 1 | D33: 26.53 | E33: =C33*D33 -> 26.53 | F33: =IF(D33>0,ROUNDUP(D33/$F$50,0)+1,0) -> 46 | G33: =C33*F33 -> 46 | H33: =$F$51 -> 2 | I33: =C33*H33 -> 2 | J33: ='METRADO MONTANTES'!C33 -> 2 | K33: =C33*J33 -> 2
B34: Lado 02 | C34: 1 | D34: =D33 -> 26.53 | E34: =C34*D34 -> 26.53 | F34: =IF(D34>0,ROUNDUP(D34/$F$50,0)+1,0) -> 46 | G34: =C34*F34 -> 46 | H34: =$F$51 -> 2 | I34: =C34*H34 -> 2 | J34: ='METRADO MONTANTES'!C34 -> 2 | K34: =C34*J34 -> 2
B35: EDIFICACION 09
B36: Lado 01 | C36: 1 | D36: 36.96 | E36: =C36*D36 -> 36.96 | F36: =IF(D36>0,ROUNDUP(D36/$F$50,0)+1,0) -> 63 | G36: =C36*F36 -> 63 | H36: =$F$51 -> 2 | I36: =C36*H36 -> 2 | J36: ='METRADO MONTANTES'!C36+'METRADO MONTANTES'!C38 -> 4 | K36: =C36*J36 -> 4
B37: Lado 02 | C37: 1 | D37: =D36 -> 36.96 | E37: =C37*D37 -> 36.96 | F37: =IF(D37>0,ROUNDUP(D37/$F$50,0)+1,0) -> 63 | G37: =C37*F37 -> 63 | H37: =$F$51 -> 2 | I37: =C37*H37 -> 2 | J37: ='METRADO MONTANTES'!C37+'METRADO MONTANTES'!C39 -> 4 | K37: =C37*J37 -> 4
B38: EDIFICACION 10
B39: Lado 01 | C39: 1 | D39: 14.58 | E39: =C39*D39 -> 14.58 | F39: =IF(D39>0,ROUNDUP(D39/$F$50,0)+1,0) -> 26 | G39: =C39*F39 -> 26 | H39: =$F$51 -> 2 | I39: =C39*H39 -> 2 | J39: ='METRADO MONTANTES'!C41 -> 2 | K39: =C39*J39 -> 2
B40: Lado 02 | C40: 1 | D40: =D39 -> 14.58 | E40: =C40*D40 -> 14.58 | F40: =IF(D40>0,ROUNDUP(D40/$F$50,0)+1,0) -> 26 | G40: =C40*F40 -> 26 | H40: =$F$51 -> 2 | I40: =C40*H40 -> 2 | J40: ='METRADO MONTANTES'!C42 -> 2 | K40: =C40*J40 -> 2
B41: TOTAL | C41: =SUM(C11:C40) -> 20 | E41: =SUM(E11:E40) -> 446.22 | G41: =SUM(G11:G40) -> 776 | I41: =SUM(I11:I40) -> 40 | K41: =SUM(K11:K40) -> 44
B43: PARÁMETROS DE CÁLCULO - CANALETA
...

Sheet METRADO CANALETA BANCAS
B2: METRADO DE CANALETA DE TECHO - BANCAS DE JARDINERIA TIPO 01
B3: ENTIDAD | C3: =+RESUMEN!B4 -> GERENCIA TERRITORIAL BAJO MAYO - TARAPOTO
B4: PROYECTO | C4: =+RESUMEN!B5 -> “CREACIÓN DEL SERVICIO DE PROTECCIÓN INTEGRAL A NIÑAS, NIÑOS Y ADOLESCENTES SIN CUIDADOS PARENTALES O EN RIESGO DE PERDERLOS EN CENTRO DE ACOGIDA RESIDENCIAL - MUJERES DISTRITO DE MORALES DE LA PROVINCIA DE SAN MARTÍN DEL DEPARTAMENTO DE SAN MARTÍN”, con CUI N.° 2717013.
B5: UBICACIÓN | C5: =+RESUMEN!B6 -> SAN MARTIN - SAN MARTIN - MORALES
B6: FECHA | C6: =+RESUMEN!B7 -> 46266
B8: CANALETA DE PLANCHA DE ALUZINC e=0.50mm - TECHO DE BANCAS A UNA AGUA (UN TRAMO POR TECHO, SIN UNIONES)
B9: EDIFICACIÓN | C9: N° DE TECHOS | D9: CANALETA 0.18 x 0.20 m | F9: TAPA LATERAL | H9: SOPORTE PLATINA F°G° 1" x 1/8" | J9: BOQUILLA A TUBERIA PVC Ø4"
D10: LONGITUD (m) | E10: TOTAL (m) | F10: CANTIDAD | G10: TOTAL (und) | H10: CANTIDAD | I10: TOTAL (und) | J10: CANTIDAD | K10: TOTAL (und)
B11: Bancas tipo 01 | C11: 16 | D11: 2 | E11: =C11*D11 -> 32 | F11: =$F$19 -> 2 | G11: =C11*F11 -> 32 | H11: =$F$20 -> 2 | I11: =C11*H11 -> 32 | J11: =$F$21 -> 1 | K11: =C11*J11 -> 16
B12: TOTAL | C12: =SUM(C11:C11) -> 16 | E12: =SUM(E11:E11) -> 32 | G12: =SUM(G11:G11) -> 32 | I12: =SUM(I11:I11) -> 32 | K12: =SUM(K11:K11) -> 16
B14: PARÁMETROS DE CÁLCULO - CANALETA DE BANCAS
B15: DESCRIPCIÓN | F15: VALOR | G15: UNIDAD | H15: CRITERIO
B16: Ancho interior de canaleta | F16: 0.18 | G16: m | H16: Detalle de banca tipo 01
B17: Altura interior de canaleta | F17: 0.2 | G17: m | H17: Detalle de banca tipo 01
B18: Espesor de plancha de aluzinc | F18: 0.5 | G18: mm | H18: Canaleta, tapas y boquilla
B19: Tapas laterales por canaleta | F19: 2 | G19: und | H19: Una en cada extremo del tramo
B20: Soportes por canaleta | F20: 2 | G20: und | H20: A 0.40 m de cada extremo
B21: Boquillas por canaleta | F21: 1 | G21: und | H21: Una salida a la tubería PVC Ø4"

Sheet METRADO  EN PISO (SUMIDERO)
A1: PLANILLA DE METRADOS - RED DE DRENAJE EN PISO Y SUMIDEROS
A2: ENTIDAD | B2: =+RESUMEN!B4 -> GERENCIA TERRITORIAL BAJO MAYO - TARAPOTO
A3: PROYECTO | B3: =+RESUMEN!B5 -> “CREACIÓN DEL SERVICIO DE PROTECCIÓN INTEGRAL A NIÑAS, NIÑOS Y ADOLESCENTES SIN CUIDADOS PARENTALES O EN RIESGO DE PERDERLOS EN CENTRO DE ACOGIDA RESIDENCIAL - MUJERES DISTRITO DE MORALES DE LA PROVINCIA DE SAN MARTÍN DEL DEPARTAMENTO DE SAN MARTÍN”, con CUI N.° 2717013.
A4: UBICACIÓN | B4: =+RESUMEN!B6 -> SAN MARTIN - SAN MARTIN - MORALES
A5: FECHA | B5: =+RESUMEN!B7 -> 46266
A7: SECTOR | B7: TUBERÍA 4" PVC-U Desagüe Clase Pesada (m) | C7: SUMIDERO DE 4" (und) | D7: CODO 90° x 4" (und) | E7: CODO 45° x 4" (und) | F7: TEE° x 4" (und) | G7: OBSERVACIÓN
A8: SECTOR 01 | B8: 9.2 | C8: 6 | D8: 6 | E8: 0 | F8: 0 | G8: Según sector
A9: SECTOR 02 | B9: 11 | C9: 8 | D9: 8 | E9: 0 | F9: 0 | G9: Según sector
A10: SECTOR 03 | B10: 9.4 | C10: 7 | D10: 7 | E10: 0 | F10: 0 | G10: Según sector
A11: SECTOR 04 | B11: 29.6 | C11: 10 | D11: 8 | E11: 0 | F11: 2 | G11: Según sector
A12: SECTOR 05 | B12: 14 | C12: 8 | D12: 8 | E12: 0 | F12: 0 | G12: Según sector
A13: TOTAL | B13: =SUM(B8:B12) -> 73.2 | C13: =SUM(C8:C12) -> 39 | D13: =SUM(D8:D12) -> 37 | E13: =SUM(E8:E12) -> 0 | F13: =SUM(F8:F12) -> 2

Sheet METRADO ACERO
A2: METRADO DE ACERO EN CUNETAS - DRENAJE PLUVIAL
A3: ENTIDAD | B3: =+RESUMEN!B4 -> GERENCIA TERRITORIAL BAJO MAYO - TARAPOTO
A4: PROYECTO | B4: =+RESUMEN!B5 -> “CREACIÓN DEL SERVICIO DE PROTECCIÓN INTEGRAL A NIÑAS, NIÑOS Y ADOLESCENTES SIN CUIDADOS PARENTALES O EN RIESGO DE PERDERLOS EN CENTRO DE ACOGIDA RESIDENCIAL - MUJERES DISTRITO DE MORALES DE LA PROVINCIA DE SAN MARTÍN DEL DEPARTAMENTO DE SAN MARTÍN”, con CUI N.° 2717013.
A5: UBICACIÓN | B5: =+RESUMEN!B6 -> SAN MARTIN - SAN MARTIN - MORALES
A6: FECHA | B6: =+RESUMEN!B7 -> 46266
A8: METRADO DETALLADO POR EJE Y POR TRAMO
A9: IDENTIFICACIÓN Y GEOMETRÍA | H9: ACERO LONGITUDINAL DEL CUERPO U | P9: ACERO TRANSVERSAL DEL CUERPO U | X9: ACERO TRANSVERSAL DE LA TAPA (SOLO CUNETA TAPADA) | AG9: RESULTADO
A10: N° | B10: EJE | C10: TRAMO | D10: TIPO DE CUNETA | E10: SEC. INI | F10: SEC. FIN | G10: LONGITUD TRAMO (m) | H10: Ø CUERPO | I10: FACTOR CUERPO (kg/m) | J10: SEP. LONG. (m) | K10: BARRAS LONG. INI | L10: BARRAS LONG. FIN | M10: BARRAS PROM. | N10: LONG. ACERO LONG. (m) | O10: KG LONG. | P10: SEP. TRANSV. U (m) | Q10: DES. TRANSV. U INI (m) | R10: DES. TRANSV. U FIN (m) | S10: DES. PROM. U (m) | T10: CANT. TRANSV. U | U10: LONG. ACERO TRANSV. U (m) | V10: KG TRANSV. U | W10: TOTAL KG CUERPO U | X10: Ø TAPA | Y10: FACTOR TAPA (kg/m) | Z10: SEP. TRANSV. TAPA (m) | AA10: LONG. BARRA TAPA INI (m) | AB10: LONG. BARRA TAPA FIN (m) | AC10: LONG. PROM. TAPA (m) | AD10: CANT. BARRAS TAPA | AE10: LONG. ACERO TAPA (m) | AF10: KG ACERO TAPA | AG10: TOTAL KG TRAMO
A11: 1 | B11: EJE 02 | C11: TRAMO 01 | D11: ABIERTA | E11: sec 05 | F11: sec 06 | G11: 97.8 | H11: 3/8" | I11: =IF(H11="","",IFERROR(VLOOKUP(H11,Listas!$A$4:$B$11,2,FALSE()),"")) -> 0.56 | J11: 0.2 | K11: 7 | L11: 11 | M11: =IF(B11="","",(K11+L11)/2) -> 9 | N11: =IF(B11="","",G11*M11) -> 880.2 | O11: =IF(B11="","",N11*I11) -> 492.912 | P11: 0.25 | Q11: 1.42 | R11: 2.36 | S11: =IF(B11="","",(Q11+R11)/2) -> 1.89 | T11: =IF(B11="","",IFERROR(IF($X$1="ENTERO (redondeo arriba)",ROUNDUP(G11/P11,0)+1,G11/P11+1),0)) -> 392.2 | U11: =IF(B11="","",S11*T11) -> 741.258 | V11: =IF(B11="","",U11*I11) -> 415.10448 | W11: =IF(B11="","",O11+V11) -> 908.01648 | Y11: =IF(X11="","",IFERROR(VLOOKUP(X11,Listas!$A$4:$B$11,2,FALSE()),"")) | AC11: =IF(B11="","",IF(D11="TAPADA",(AA11+AB11)/2,0)) -> 0 | AD11: =IF(B11="","",IF(D11="TAPADA",IFERROR(IF($X$1="ENTERO (redondeo arriba)",ROUNDUP(G11/Z11,0)+1,G11/Z11+1),0),0)) -> 0 | AE11: =IF(B11="","",IF(D11="TAPADA",AC11*AD11,0)) -> 0 | AF11: =IF(B11="","",IF(D11="TAPADA",AE11*Y11,0)) -> 0 | AG11: =IF(B11="","",W11+AF11) -> 908.01648
A12: 2 | B12: EJE 02 | C12: TRAMO 02 | D12: TAPADA | E12: sec 06 | F12: sec 07 | G12: 5.8 | H12: 3/8" | I12: =IF(H12="","",IFERROR(VLOOKUP(H12,Listas!$A$4:$B$11,2,FALSE()),"")) -> 0.56 | J12: 0.22 | K12: 12 | L12: 12 | M12: =IF(B12="","",(K12+L12)/2) -> 12 | N12: =IF(B12="","",G12*M12) -> 69.6 | O12: =IF(B12="","",N12*I12) -> 38.976 | P12: 0.25 | Q12: 2.36 | R12: 2.46 | S12: =IF(B12="","",(Q12+R12)/2) -> 2.41 | T12: =IF(B12="","",IFERROR(IF($X$1="ENTERO (redondeo arriba)",ROUNDUP(G12/P12,0)+1,G12/P12+1),0)) -> 24.2 | U12: =IF(B12="","",S12*T12) -> 58.322 | V12: =IF(B12="","",U12*I12) -> 32.66032 | W12: =IF(B12="","",O12+V12) -> 71.63632 | X12: 3/8" | Y12: =IF(X12="","",IFERROR(VLOOKUP(X12,Listas!$A$4:$B$11,2,FALSE()),"")) -> 0.56 | Z12: 0.25 | AA12: 0.56 | AB12: 0.56 | AC12: =IF(B12="","",IF(D12="TAPADA",(AA12+AB12)/2,0)) -> 0.56 | AD12: =IF(B12="","",IF(D12="TAPADA",IFERROR(IF($X$1="ENTERO (redondeo arriba)",ROUNDUP(G12/Z12,0)+1,G12/Z12+1),0),0)) -> 24.2 | AE12: =IF(B12="","",IF(D12="TAPADA",AC12*AD12,0)) -> 13.552 | AF12: =IF(B12="","",IF(D12="TAPADA",AE12*Y12,0)) -> 7.58912 | AG12: =IF(B12="","",W12+AF12) -> 79.22544
A13: 3 | B13: EJE 02 | C13: TRAMO 03 | D13: TAPADA | E13: sec 08 | F13: sec 09 | G13: 4.9 | H13: 3/8" | I13: =IF(H13="","",IFERROR(VLOOKUP(H13,Listas!$A$4:$B$11,2,FALSE()),"")) -> 0.56 | J13: 0.2 | K13: 10 | L13: 10 | M13: =IF(B13="","",(K13+L13)/2) -> 10 | N13: =IF(B13="","",G13*M13) -> 49 | O13: =IF(B13="","",N13*I13) -> 27.44 | P13: 0.25 | Q13: 1.82 | R13: 1.9 | S13: =IF(B13="","",(Q13+R13)/2) -> 1.86 | T13: =IF(B13="","",IFERROR(IF($X$1="ENTERO (redondeo arriba)",ROUNDUP(G13/P13,0)+1,G13/P13+1),0)) -> 20.6 | U13: =IF(B13="","",S13*T13) -> 38.316 | V13: =IF(B13="","",U13*I13) -> 21.45696 | W13: =IF(B13="","",O13+V13) -> 48.89696 | X13: 3/8" | Y13: =IF(X13="","",IFERROR(VLOOKUP(X13,Listas!$A$4:$B$11,2,FALSE()),"")) -> 0.56 | Z13: 0.25 | AA13: 0.56 | AB13: 0.56 | AC13: =IF(B13="","",IF(D13="TAPADA",(AA13+AB13)/2,0)) -> 0.56 | AD13: =IF(B13="","",IF(D13="TAPADA",IFERROR(IF($X$1="ENTERO (redondeo arriba)",ROUNDUP(G13/Z13,0)+1,G13/Z13+1),0),0)) -> 20.6 | AE13: =IF(B13="","",IF(D13="TAPADA",AC13*AD13,0)) -> 11.536 | AF13: =IF(B13="","",IF(D13="TAPADA",AE13*Y13,0)) -> 6.46016 | AG13: =IF(B13="","",W13+AF13) -> 55.35712
A14: 4 | B14: EJE 02 | C14: TRAMO 04 | D14: TAPADA | E14: sec 10 | F14: sec 11 | G14: 2.95 | H14: 3/8" | I14: =IF(H14="","",IFERROR(VLOOKUP(H14,Listas!$A$4:$B$11,2,FALSE()),"")) -> 0.56 | J14: 0.25 | K14: 10 | L14: 10 | M14: =IF(B14="","",(K14+L14)/2) -> 10 | N14: =IF(B14="","",G14*M14) -> 29.5 | O14: =IF(B14="","",N14*I14) -> 16.52 | P14: 0.25 | Q14: 2.1 | R14: 2.14 | S14: =IF(B14="","",(Q14+R14)/2) -> 2.12 | T14: =IF(B14="","",IFERROR(IF($X$1="ENTERO (redondeo arriba)",ROUNDUP(G14/P14,0)+1,G14/P14+1),0)) -> 12.8 | U14: =IF(B14="","",S14*T14) -> 27.136 | V14: =IF(B14="","",U14*I14) -> 15.19616 | W14: =IF(B14="","",O14+V14) -> 31.71616 | X14: 3/8" | Y14: =IF(X14="","",IFERROR(VLOOKUP(X14,Listas!$A$4:$B$11,2,FALSE()),"")) -> 0.56 | Z14: 0.25 | AA14: 0.56 | AB14: 0.56 | AC14: =IF(B14="","",IF(D14="TAPADA",(AA14+AB14)/2,0)) -> 0.56 | AD14: =IF(B14="","",IF(D14="TAPADA",IFERROR(IF($X$1="ENTERO (redondeo arriba)",ROUNDUP(G14/Z14,0)+1,G14/Z14+1),0),0)) -> 12.8 | AE14: =IF(B14="","",IF(D14="TAPADA",AC14*AD14,0)) -> 7.168 | AF14: =IF(B14="","",IF(D14="TAPADA",AE14*Y14,0)) -> 4.01408 | AG14: =IF(B14="","",W14+AF14) -> 35.73024
A15: 5 | B15: EJE 02 | C15: TRAMO 05 | D15: TAPADA | E15: sec 12 | F15: sec 13 | G15: 1.75 | H15: 3/8" | I15: =IF(H15="","",IFERROR(VLOOKUP(H15,Listas!$A$4:$B$11,2,FALSE()),"")) -> 0.56 | J15: 0.17 | K15: 10 | L15: 10 | M15: =IF(B15="","",(K15+L15)/2) -> 10 | N15: =IF(B15="","",G15*M15) -> 17.5 | O15: =IF(B15="","",N15*I15) -> 9.8 | P15: 0.25 | Q15: 1.62 | R15: 1.66 | S15: =IF(B15="","",(Q15+R15)/2) -> 1.64 | T15: =IF(B15="","",IFERROR(IF($X$1="ENTERO (redondeo arriba)",ROUNDUP(G15/P15,0)+1,G15/P15+1),0)) -> 8 | U15: =IF(B15="","",S15*T15) -> 13.12 | V15: =IF(B15="","",U15*I15) -> 7.3472 | W15: =IF(B15="","",O15+V15) -> 17.1472 | X15: 3/8" | Y15: =IF(X15="","",IFERROR(VLOOKUP(X15,Listas!$A$4:$B$11,2,FALSE()),"")) -> 0.56 | Z15: 0.25 | AA15: 0.56 | AB15: 0.56 | AC15: =IF(B15="","",IF(D15="TAPADA",(AA15+AB15)/2,0)) -> 0.56 | AD15: =IF(B15="","",IF(D15="TAPADA",IFERROR(IF($X$1="ENTERO (redondeo arriba)",ROUNDUP(G15/Z15,0)+1,G15/Z15+1),0),0)) -> 8 | AE15: =IF(B15="","",IF(D15="TAPADA",AC15*AD15,0)) -> 4.48 | AF15: =IF(B15="","",IF(D15="TAPADA",AE15*Y15,0)) -> 2.5088 | AG15: =IF(B15="","",W15+AF15) -> 19.656
A16: 6 | B16: EJE 06 | C16: TRAMO 01 | D16: ABIERTA | E16: sec 23 | F16: sec 24 | G16: 76.95 | H16: 3/8" | I16: =IF(H16="","",IFERROR(VLOOKUP(H16,Listas!$A$4:$B$11,2,FALSE()),"")) -> 0.56 | J16: 0.2 | K16: 7 | L16: 9 | M16: =IF(B16="","",(K16+L16)/2) -> 8 | N16: =IF(B16="","",G16*M16) -> 615.6 | O16: =IF(B16="","",N16*I16) -> 344.736 | P16: 0.25 | Q16: 1.42 | R16: 2.18 | S16: =IF(B16="","",(Q16+R16)/2) -> 1.8 | T16: =IF(B16="","",IFERROR(IF($X$1="ENTERO (redondeo arriba)",ROUNDUP(G16/P16,0)+1,G16/P16+1),0)) -> 308.8 | U16: =IF(B16="","",S16*T16) -> 555.84 | V16: =IF(B16="","",U16*I16) -> 311.2704 | W16: =IF(B16="","",O16+V16) -> 656.0064 | Y16: =IF(X16="","",IFERROR(VLOOKUP(X16,Listas!$A$4:$B$11,2,FALSE()),"")) | AC16: =IF(B16="","",IF(D16="TAPADA",(AA16+AB16)/2,0)) -> 0 | AD16: =IF(B16="","",IF(D16="TAPADA",IFERROR(IF($X$1="ENTERO (redondeo arriba)",ROUNDUP(G16/Z16,0)+1,G16/Z16+1),0),0)) -> 0 | AE16: =IF(B16="","",IF(D16="TAPADA",AC16*AD16,0)) -> 0 | AF16: =IF(B16="","",IF(D16="TAPADA",AE16*Y16,0)) -> 0 | AG16: =IF(B16="","",W16+AF16) -> 656.0064
A17: 7 | B17: EJE 07 | C17: TRAMO 01 | D17: ABIERTA | E17: sec 26 | F17: sec 27 | G17: 6 | H17: 3/8" | I17: =IF(H17="","",IFERROR(VLOOKUP(H17,Listas!$A$4:$B$11,2,FALSE()),"")) -> 0.56 | J17: 0.2 | K17: 7 | L17: 7 | M17: =IF(B17="","",(K17+L17)/2) -> 7 | N17: =IF(B17="","",G17*M17) -> 42 | O17: =IF(B17="","",N17*I17) -> 23.52 | P17: 0.25 | Q17: 1.42 | R17: 1.48 | S17: =IF(B17="","",(Q17+R17)/2) -> 1.45 | T17: =IF(B17="","",IFERROR(IF($X$1="ENTERO (redondeo arriba)",ROUNDUP(G17/P17,0)+1,G17/P17+1),0)) -> 25 | U17: =IF(B17="","",S17*T17) -> 36.25 | V17: =IF(B17="","",U17*I17) -> 20.3 | W17: =IF(B17="","",O17+V17) -> 43.82 | Y17: =IF(X17="","",IFERROR(VLOOKUP(X17,Listas!$A$4:$B$11,2,FALSE()),"")) | AC17: =IF(B17="","",IF(D17="TAPADA",(AA17+AB17)/2,0)) -> 0 | AD17: =IF(B17="","",IF(D17="TAPADA",IFERROR(IF($X$1="ENTERO (redondeo arriba)",ROUNDUP(G17/Z17,0)+1,G17/Z17+1),0),0)) -> 0 | AE17: =IF(B17="","",IF(D17="TAPADA",AC17*AD17,0)) -> 0 | AF17: =IF(B17="","",IF(D17="TAPADA",AE17*Y17,0)) -> 0 | AG17: =IF(B17="","",W17+AF17) -> 43.82
A18: 8 | B18: EJE 07 | C18: TRAMO 02 | D18: TAPADA | E18: sec 27 | F18: sec 28 | G18: 7.3 | H18: 3/8" | I18: =IF(H18="","",IFERROR(VLOOKUP(H18,Listas!$A$4:$B$11,2,FALSE()),"")) -> 0.56 | J18: 0.21 | K18: 8 | L18: 8 | M18: =IF(B18="","",(K18+L18)/2) -> 8 | N18: =IF(B18="","",G18*M18) -> 58.4 | O18: =IF(B18="","",N18*I18) -> 32.704 | P18: 0.25 | Q18: 1.48 | R18: 1.56 | S18: =IF(B18="","",(Q18+R18)/2) -> 1.52 | T18: =IF(B18="","",IFERROR(IF($X$1="ENTERO (redondeo arriba)",ROUNDUP(G18/P18,0)+1,G18/P18+1),0)) -> 30.2 | U18: =IF(B18="","",S18*T18) -> 45.904 | V18: =IF(B18="","",U18*I18) -> 25.70624 | W18: =IF(B18="","",O18+V18) -> 58.41024 | X18: 3/8" | Y18: =IF(X18="","",IFERROR(VLOOKUP(X18,Listas!$A$4:$B$11,2,FALSE()),"")) -> 0.56 | Z18: 0.25 | AA18: 0.56 | AB18: 0.56 | AC18: =IF(B18="","",IF(D18="TAPADA",(AA18+AB18)/2,0)) -> 0.56 | AD18: =IF(B18="","",IF(D18="TAPADA",IFERROR(IF($X$1="ENTERO (redondeo arriba)",ROUNDUP(G18/Z18,0)+1,G18/Z18+1),0),0)) -> 30.2 | AE18: =IF(B18="","",IF(D18="TAPADA",AC18*AD18,0)) -> 16.912 | AF18: =IF(B18="","",IF(D18="TAPADA",AE18*Y18,0)) -> 9.47072 | AG18: =IF(B18="","",W18+AF18) -> 67.88096
A19: 9 | B19: EJE 07 | C19: TRAMO 03 | D19: ABIERTA | E19: sec 28 | F19: sec 29 | G19: 83.45 | H19: 3/8" | I19: =IF(H19="","",IFERROR(VLOOKUP(H19,Listas!$A$4:$B$11,2,FALSE()),"")) -> 0.56 | J19: 0.24 | K19: 7 | L19: 11 | M19: =IF(B19="","",(K19+L19)/2) -> 9 | N19: =IF(B19="","",G19*M19) -> 751.05 | O19: =IF(B19="","",N19*I19) -> 420.588 | P19: 0.25 | Q19: 1.56 | R19: 2.36 | S19: =IF(B19="","",(Q19+R19)/2) -> 1.96 | T19: =IF(B19="","",IFERROR(IF($X$1="ENTERO (redondeo arriba)",ROUNDUP(G19/P19,0)+1,G19/P19+1),0)) -> 334.8 | U19: =IF(B19="","",S19*T19) -> 656.208 | V19: =IF(B19="","",U19*I19) -> 367.47648 | W19: =IF(B19="","",O19+V19) -> 788.06448 | Y19: =IF(X19="","",IFERROR(VLOOKUP(X19,Listas!$A$4:$B$11,2,FALSE()),"")) | AC19: =IF(B19="","",IF(D19="TAPADA",(AA19+AB19)/2,0)) -> 0 | AD19: =IF(B19="","",IF(D19="TAPADA",IFERROR(IF($X$1="ENTERO (redondeo arriba)",ROUNDUP(G19/Z19,0)+1,G19/Z19+1),0),0)) -> 0 | AE19: =IF(B19="","",IF(D19="TAPADA",AC19*AD19,0)) -> 0 | AF19: =IF(B19="","",IF(D19="TAPADA",AE19*Y19,0)) -> 0 | AG19: =IF(B19="","",W19+AF19) -> 788.06448
A20: 10 | B20: EJE 07 | C20: TRAMO 04 | D20: TAPADA | E20: sec 29 | F20: sec 30 | G20: 3.72 | H20: 3/8" | I20: =IF(H20="","",IFERROR(VLOOKUP(H20,Listas!$A$4:$B$11,2,FALSE()),"")) -> 0.56 | J20: 0.22 | K20: 12 | L20: 12 | M20: =IF(B20="","",(K20+L20)/2) -> 12 | N20: =IF(B20="","",G20*M20) -> 44.64 | O20: =IF(B20="","",N20*I20) -> 24.9984 | P20: 0.25 | Q20: 2.36 | R20: 2.42 | S20: =IF(B20="","",(Q20+R20)/2) -> 2.39 | T20: =IF(B20="","",IFERROR(IF($X$1="ENTERO (redondeo arriba)",ROUNDUP(G20/P20,0)+1,G20/P20+1),0)) -> 15.88 | U20: =IF(B20="","",S20*T20) -> 37.9532 | V20: =IF(B20="","",U20*I20) -> 21.253792 | W20: =IF(B20="","",O20+V20) -> 46.252192 | X20: 3/8" | Y20: =IF(X20="","",IFERROR(VLOOKUP(X20,Listas!$A$4:$B$11,2,FALSE()),"")) -> 0.56 | Z20: 0.25 | AA20: 0.56 | AB20: 0.56 | AC20: =IF(B20="","",IF(D20="TAPADA",(AA20+AB20)/2,0)) -> 0.56 | AD20: =IF(B20="","",IF(D20="TAPADA",IFERROR(IF($X$1="ENTERO (redondeo arriba)",ROUNDUP(G20/Z20,0)+1,G20/Z20+1),0),0)) -> 15.88 | AE20: =IF(B20="","",IF(D20="TAPADA",AC20*AD20,0)) -> 8.8928 | AF20: =IF(B20="","",IF(D20="TAPADA",AE20*Y20,0)) -> 4.979968 | AG20: =IF(B20="","",W20+AF20) -> 51.23216
A21: 11 | B21: EJE 07 | C21: TRAMO 05 | D21: TAPADA | E21: sec 31 | F21: sec 32 | G21: 5 | H21: 3/8" | I21: =IF(H21="","",IFERROR(VLOOKUP(H21,Listas!$A$4:$B$11,2,FALSE()),"")) -> 0.56 | J21: 0.23 | K21: 10 | L21: 10 | M21: =IF(B21="","",(K21+L21)/2) -> 10 | N21: =IF(B21="","",G21*M21) -> 50 | O21: =IF(B21="","",N21*I21) -> 28 | P21: 0.25 | Q21: 2 | R21: 2.08 | S21: =IF(B21="","",(Q21+R21)/2) -> 2.04 | T21: =IF(B21="","",IFERROR(IF($X$1="ENTERO (redondeo arriba)",ROUNDUP(G21/P21,0)+1,G21/P21+1),0)) -> 21 | U21: =IF(B21="","",S21*T21) -> 42.84 | V21: =IF(B21="","",U21*I21) -> 23.9904 | W21: =IF(B21="","",O21+V21) -> 51.9904 | X21: 3/8" | Y21: =IF(X21="","",IFERROR(VLOOKUP(X21,Listas!$A$4:$B$11,2,FALSE()),"")) -> 0.56 | Z21: 0.25 | AA21: 0.56 | AB21: 0.56 | AC21: =IF(B21="","",IF(D21="TAPADA",(AA21+AB21)/2,0)) -> 0.56 | AD21: =IF(B21="","",IF(D21="TAPADA",IFERROR(IF($X$1="ENTERO (redondeo arriba)",ROUNDUP(G21/Z21,0)+1,G21/Z21+1),0),0)) -> 21 | AE21: =IF(B21="","",IF(D21="TAPADA",AC21*AD21,0)) -> 11.76 | AF21: =IF(B21="","",IF(D21="TAPADA",AE21*Y21,0)) -> 6.5856 | AG21: =IF(B21="","",W21+AF21) -> 58.576
A22: 12 | B22: EJE 07 | C22: TRAMO 06 | D22: TAPADA | E22: sec 32 | F22: sec 33 | G22: 3.84 | H22: 3/8" | I22: =IF(H22="","",IFERROR(VLOOKUP(H22,Listas!$A$4:$B$11,2,FALSE()),"")) -> 0.56 | J22: 0.21 | K22: 10 | L22: 10 | M22: =IF(B22="","",(K22+L22)/2) -> 10 | N22: =IF(B22="","",G22*M22) -> 38.4 | O22: =IF(B22="","",N22*I22) -> 21.504 | P22: 0.25 | Q22: 2.08 | R22: 1.62 | S22: =IF(B22="","",(Q22+R22)/2) -> 1.85 | T22: =IF(B22="","",IFERROR(IF($X$1="ENTERO (redondeo arriba)",ROUNDUP(G22/P22,0)+1,G22/P22+1),0)) -> 16.36 | U22: =IF(B22="","",S22*T22) -> 30.266 | V22: =IF(B22="","",U22*I22) -> 16.94896 | W22: =IF(B22="","",O22+V22) -> 38.45296 | X22: 3/8" | Y22: =IF(X22="","",IFERROR(VLOOKUP(X22,Listas!$A$4:$B$11,2,FALSE()),"")) -> 0.56 | Z22: 0.25 | AA22: 0.56 | AB22: 0.56 | AC22: =IF(B22="","",IF(D22="TAPADA",(AA22+AB22)/2,0)) -> 0.56 | AD22: =IF(B22="","",IF(D22="TAPADA",IFERROR(IF($X$1="ENTERO (redondeo arriba)",ROUNDUP(G22/Z22,0)+1,G22/Z22+1),0),0)) -> 16.36 | AE22: =IF(B22="","",IF(D22="TAPADA",AC22*AD22,0)) -> 9.1616 | AF22: =IF(B22="","",IF(D22="TAPADA",AE22*Y22,0)) -> 5.130496 | AG22: =IF(B22="","",W22+AF22) -> 43.583456
A23: 13 | B23: EJE 07 | C23: TRAMO 07 | D23: TAPADA | E23: sec 33 | F23: sec 34 | G23: 1.79 | H23: 3/8" | I23: =IF(H23="","",IFERROR(VLOOKUP(H23,Listas!$A$4:$B$11,2,FALSE()),"")) -> 0.56 | J23: 0.17 | K23: 10 | L23: 10 | M23: =IF(B23="","",(K23+L23)/2) -> 10 | N23: =IF(B23="","",G23*M23) -> 17.9 | O23: =IF(B23="","",N23*I23) -> 10.024 | P23: 0.25 | Q23: 1.62 | R23: 1.64 | S23: =IF(B23="","",(Q23+R23)/2) -> 1.63 | T23: =IF(B23="","",IFERROR(IF($X$1="ENTERO (redondeo arriba)",ROUNDUP(G23/P23,0)+1,G23/P23+1),0)) -> 8.16 | U23: =IF(B23="","",S23*T23) -> 13.3008 | V23: =IF(B23="","",U23*I23) -> 7.448448 | W23: =IF(B23="","",O23+V23) -> 17.472448 | X23: 3/8" | Y23: =IF(X23="","",IFERROR(VLOOKUP(X23,Listas!$A$4:$B$11,2,FALSE()),"")) -> 0.56 | Z23: 0.25 | AA23: 0.56 | AB23: 0.56 | AC23: =IF(B23="","",IF(D23="TAPADA",(AA23+AB23)/2,0)) -> 0.56 | AD23: =IF(B23="","",IF(D23="TAPADA",IFERROR(IF($X$1="ENTERO (redondeo arriba)",ROUNDUP(G23/Z23,0)+1,G23/Z23+1),0),0)) -> 8.16 | AE23: =IF(B23="","",IF(D23="TAPADA",AC23*AD23,0)) -> 4.5696 | AF23: =IF(B23="","",IF(D23="TAPADA",AE23*Y23,0)) -> 2.558976 | AG23: =IF(B23="","",W23+AF23) -> 20.031424
A24: 14 | B24: EJE 09 | C24: TRAMO 01 | D24: ABIERTA | E24: sec 39 | F24: sec 40 | G24: 3.84 | H24: 3/8" | I24: =IF(H24="","",IFERROR(VLOOKUP(H24,Listas!$A$4:$B$11,2,FALSE()),"")) -> 0.56 | J24: 0.2 | K24: 7 | L24: 9 | M24: =IF(B24="","",(K24+L24)/2) -> 8 | N24: =IF(B24="","",G24*M24) -> 30.72 | O24: =IF(B24="","",N24*I24) -> 17.2032 | P24: 0.25 | Q24: 1.42 | R24: 1.86 | S24: =IF(B24="","",(Q24+R24)/2) -> 1.64 | T24: =IF(B24="","",IFERROR(IF($X$1="ENTERO (redondeo arriba)",ROUNDUP(G24/P24,0)+1,G24/P24+1),0)) -> 16.36 | U24: =IF(B24="","",S24*T24) -> 26.8304 | V24: =IF(B24="","",U24*I24) -> 15.025024 | W24: =IF(B24="","",O24+V24) -> 32.228224 | Y24: =IF(X24="","",IFERROR(VLOOKUP(X24,Listas!$A$4:$B$11,2,FALSE()),"")) | AC24: =IF(B24="","",IF(D24="TAPADA",(AA24+AB24)/2,0)) -> 0 | AD24: =IF(B24="","",IF(D24="TAPADA",IFERROR(IF($X$1="ENTERO (redondeo arriba)",ROUNDUP(G24/Z24,0)+1,G24/Z24+1),0),0)) -> 0 | AE24: =IF(B24="","",IF(D24="TAPADA",AC24*AD24,0)) -> 0 | AF24: =IF(B24="","",IF(D24="TAPADA",AE24*Y24,0)) -> 0 | AG24: =IF(B24="","",W24+AF24) -> 32.228224
A25: 15 | B25: EJE 09 | C25: TRAMO 02 | D25: ABIERTA | E25: sec 40 | F25: sec 41 | G25: 26.86 | H25: 3/8" | I25: =IF(H25="","",IFERROR(VLOOKUP(H25,Listas!$A$4:$B$11,2,FALSE()),"")) -> 0.56 | J25: 0.2 | K25: 9 | L25: 9 | M25: =IF(B25="","",(K25+L25)/2) -> 9 | N25: =IF(B25="","",G25*M25) -> 241.74 | O25: =IF(B25="","",N25*I25) -> 135.3744 | P25: 0.25 | Q25: 1.86 | R25: 2.12 | S25: =IF(B25="","",(Q25+R25)/2) -> 1.99 | T25: =IF(B25="","",IFERROR(IF($X$1="ENTERO (redondeo arriba)",ROUNDUP(G25/P25,0)+1,G25/P25+1),0)) -> 108.44 | U25: =IF(B25="","",S25*T25) -> 215.7956 | V25: =IF(B25="","",U25*I25) -> 120.84554 | W25: =IF(B25="","",O25+V25) -> 256.21994 | Y25: =IF(X25="","",IFERROR(VLOOKUP(X25,Listas!$A$4:$B$11,2,FALSE()),"")) | AC25: =IF(B25="","",IF(D25="TAPADA",(AA25+AB25)/2,0)) -> 0 | AD25: =IF(B25="","",IF(D25="TAPADA",IFERROR(IF($X$1="ENTERO (redondeo arriba)",ROUNDUP(G25/Z25,0)+1,G25/Z25+1),0),0)) -> 0 | AE25: =IF(B25="","",IF(D25="TAPADA",AC25*AD25,0)) -> 0 | AF25: =IF(B25="","",IF(D25="TAPADA",AE25*Y25,0)) -> 0 | AG25: =IF(B25="","",W25+AF25) -> 256.21994
A26: 16 | B26: EJE 10 | C26: TRAMO 01 | D26: ABIERTA | E26: sec 43 | F26: sec 44 | G26: 6.55 | H26: 3/8" | I26: =IF(H26="","",IFERROR(VLOOKUP(H26,Listas!$A$4:$B$11,2,FALSE()),"")) -> 0.56 | J26: 0.21 | K26: 7 | L26: 7 | M26: =IF(B26="","",(K26+L26)/2) -> 7 | N26: =IF(B26="","",G26*M26) -> 45.85 | O26: =IF(B26="","",N26*I26) -> 25.676 | P26: 0.25 | Q26: 1.42 | R26: 1.48 | S26: =IF(B26="","",(Q26+R26)/2) -> 1.45 | T26: =IF(B26="","",IFERROR(IF($X$1="ENTERO (redondeo arriba)",ROUNDUP(G26/P26,0)+1,G26/P26+1),0)) -> 27.2 | U26: =IF(B26="","",S26*T26) -> 39.44 | V26: =IF(B26="","",U26*I26) -> 22.0864 | W26: =IF(B26="","",O26+V26) -> 47.7624 | Y26: =IF(X26="","",IFERROR(VLOOKUP(X26,Listas!$A$4:$B$11,2,FALSE()),"")) | AC26: =IF(B26="","",IF(D26="TAPADA",(AA26+AB26)/2,0)) -> 0 | AD26: =IF(B26="","",IF(D26="TAPADA",IFERROR(IF($X$1="ENTERO (redondeo arriba)",ROUNDUP(G26/Z26,0)+1,G26/Z26+1),0),0)) -> 0 | AE26: =IF(B26="","",IF(D26="TAPADA",AC26*AD26,0)) -> 0 | AF26: =IF(B26="","",IF(D26="TAPADA",AE26*Y26,0)) -> 0 | AG26: =IF(B26="","",W26+AF26) -> 47.7624
A27: 17 | B27: EJE 10 | C27: TRAMO 02 | D27: TAPADA | E27: sec 44 | F27: sec 46 | G27: 8.83 | H27: 3/8" | I27: =IF(H27="","",IFERROR(VLOOKUP(H27,Listas!$A$4:$B$11,2,FALSE()),"")) -> 0.56 | J27: 0.23 | K27: 8 | L27: 8 | M27: =IF(B27="","",(K27+L27)/2) -> 8 | N27: =IF(B27="","",G27*M27) -> 70.64 | O27: =IF(B27="","",N27*I27) -> 39.5584 | P27: 0.25 | Q27: 1.48 | R27: 1.58 | S27: =IF(B27="","",(Q27+R27)/2) -> 1.53 | T27: =IF(B27="","",IFERROR(IF($X$1="ENTERO (redondeo arriba)",ROUNDUP(G27/P27,0)+1,G27/P27+1),0)) -> 36.32 | U27: =IF(B27="","",S27*T27) -> 55.5696 | V27: =IF(B27="","",U27*I27) -> 31.118976 | W27: =IF(B27="","",O27+V27) -> 70.677376 | X27: 3/8" | Y27: =IF(X27="","",IFERROR(VLOOKUP(X27,Listas!$A$4:$B$11,2,FALSE()),"")) -> 0.56 | Z27: 0.25 | AA27: 0.56 | AB27: 0.56 | AC27: =IF(B27="","",IF(D27="TAPADA",(AA27+AB27)/2,0)) -> 0.56 | AD27: =IF(B27="","",IF(D27="TAPADA",IFERROR(IF($X$1="ENTERO (redondeo arriba)",ROUNDUP(G27/Z27,0)+1,G27/Z27+1),0),0)) -> 36.32 | AE27: =IF(B27="","",IF(D27="TAPADA",AC27*AD27,0)) -> 20.3392 | AF27: =IF(B27="","",IF(D27="TAPADA",AE27*Y27,0)) -> 11.389952 | AG27: =IF(B27="","",W27+AF27) -> 82.067328
A28: 18 | B28: EJE 10 | C28: TRAMO 03 | D28: TAPADA | E28: sec 46 | F28: sec 47 | G28: 3.85 | H28: 3/8" | I28: =IF(H28="","",IFERROR(VLOOKUP(H28,Listas!$A$4:$B$11,2,FALSE()),"")) -> 0.56 | J28: 0.23 | K28: 8 | L28: 10 | M28: =IF(B28="","",(K28+L28)/2) -> 9 | N28: =IF(B28="","",G28*M28) -> 34.65 | O28: =IF(B28="","",N28*I28) -> 19.404 | P28: 0.25 | Q28: 1.58 | R28: 1.62 | S28: =IF(B28="","",(Q28+R28)/2) -> 1.6 | T28: =IF(B28="","",IFERROR(IF($X$1="ENTERO (redondeo arriba)",ROUNDUP(G28/P28,0)+1,G28/P28+1),0)) -> 16.4 | U28: =IF(B28="","",S28*T28) -> 26.24 | V28: =IF(B28="","",U28*I28) -> 14.6944 | W28: =IF(B28="","",O28+V28) -> 34.0984 | X28: 3/8" | Y28: =IF(X28="","",IFERROR(VLOOKUP(X28,Listas!$A$4:$B$11,2,FALSE()),"")) -> 0.56 | Z28: 0.25 | AA28: 0.56 | AB28: 0.56 | AC28: =IF(B28="","",IF(D28="TAPADA",(AA28+AB28)/2,0)) -> 0.56 | AD28: =IF(B28="","",IF(D28="TAPADA",IFERROR(IF($X$1="ENTERO (redondeo arriba)",ROUNDUP(G28/Z28,0)+1,G28/Z28+1),0),0)) -> 16.4 | AE28: =IF(B28="","",IF(D28="TAPADA",AC28*AD28,0)) -> 9.184 | AF28: =IF(B28="","",IF(D28="TAPADA",AE28*Y28,0)) -> 5.14304 | AG28: =IF(B28="","",W28+AF28) -> 39.24144
A29: 19 | B29: EJE 10 | C29: TRAMO 04 | D29: TAPADA | E29: sec 47 | F29: sec 48 | G29: 2.03 | H29: 3/8" | I29: =IF(H29="","",IFERROR(VLOOKUP(H29,Listas!$A$4:$B$11,2,FALSE()),"")) -> 0.56 | J29: 0.17 | K29: 10 | L29: 10 | M29: =IF(B29="","",(K29+L29)/2) -> 10 | N29: =IF(B29="","",G29*M29) -> 20.3 | O29: =IF(B29="","",N29*I29) -> 11.368 | P29: 0.25 | Q29: 1.62 | R29: 1.63 | S29: =IF(B29="","",(Q29+R29)/2) -> 1.625 | T29: =IF(B29="","",IFERROR(IF($X$1="ENTERO (redondeo arriba)",ROUNDUP(G29/P29,0)+1,G29/P29+1),0)) -> 9.12 | U29: =IF(B29="","",S29*T29) -> 14.82 | V29: =IF(B29="","",U29*I29) -> 8.2992 | W29: =IF(B29="","",O29+V29) -> 19.6672 | X29: 3/8" | Y29: =IF(X29="","",IFERROR(VLOOKUP(X29,Listas!$A$4:$B$11,2,FALSE()),"")) -> 0.56 | Z29: 0.25 | AA29: 0.56 | AB29: 0.56 | AC29: =IF(B29="","",IF(D29="TAPADA",(AA29+AB29)/2,0)) -> 0.56 | AD29: =IF(B29="","",IF(D29="TAPADA",IFERROR(IF($X$1="ENTERO (redondeo arriba)",ROUNDUP(G29/Z29,0)+1,G29/Z29+1),0),0)) -> 9.12 | AE29: =IF(B29="","",IF(D29="TAPADA",AC29*AD29,0)) -> 5.1072 | AF29: =IF(B29="","",IF(D29="TAPADA",AE29*Y29,0)) -> 2.860032 | AG29: =IF(B29="","",W29+AF29) -> 22.527232
A30: 20 | B30: EJE 12 | C30: TRAMO 01 | D30: ABIERTA | E30: sec 52 | F30: sec 53 | G30: 3.55 | H30: 3/8" | I30: =IF(H30="","",IFERROR(VLOOKUP(H30,Listas!$A$4:$B$11,2,FALSE()),"")) -> 0.56 | J30: 0.2 | K30: 7 | L30: 7 | M30: =IF(B30="","",(K30+L30)/2) -> 7 | N30: =IF(B30="","",G30*M30) -> 24.85 | O30: =IF(B30="","",N30*I30) -> 13.916 | P30: 0.25 | Q30: 1.42 | R30: 1.48 | S30: =IF(B30="","",(Q30+R30)/2) -> 1.45 | T30: =IF(B30="","",IFERROR(IF($X$1="ENTERO (redondeo arriba)",ROUNDUP(G30/P30,0)+1,G30/P30+1),0)) -> 15.2 | U30: =IF(B30="","",S30*T30) -> 22.04 | V30: =IF(B30="","",U30*I30) -> 12.3424 | W30: =IF(B30="","",O30+V30) -> 26.2584 | Y30: =IF(X30="","",IFERROR(VLOOKUP(X30,Listas!$A$4:$B$11,2,FALSE()),"")) | AC30: =IF(B30="","",IF(D30="TAPADA",(AA30+AB30)/2,0)) -> 0 | AD30: =IF(B30="","",IF(D30="TAPADA",IFERROR(IF($X$1="ENTERO (redondeo arriba)",ROUNDUP(G30/Z30,0)+1,G30/Z30+1),0),0)) -> 0 | AE30: =IF(B30="","",IF(D30="TAPADA",AC30*AD30,0)) -> 0 | AF30: =IF(B30="","",IF(D30="TAPADA",AE30*Y30,0)) -> 0 | AG30: =IF(B30="","",W30+AF30) -> 26.2584
A31: 21 | B31: EJE 12 | C31: TRAMO 02 | D31: TAPADA | E31: sec 53 | F31: sec 54 | G31: 12.05 | H31: 3/8" | I31: =IF(H31="","",IFERROR(VLOOKUP(H31,Listas!$A$4:$B$11,2,FALSE()),"")) -> 0.56 | J31: 0.23 | K31: 8 | L31: 8 | M31: =IF(B31="","",(K31+L31)/2) -> 8 | N31: =IF(B31="","",G31*M31) -> 96.4 | O31: =IF(B31="","",N31*I31) -> 53.984 | P31: 0.25 | Q31: 1.48 | R31: 1.58 | S31: =IF(B31="","",(Q31+R31)/2) -> 1.53 | T31: =IF(B31="","",IFERROR(IF($X$1="ENTERO (redondeo arriba)",ROUNDUP(G31/P31,0)+1,G31/P31+1),0)) -> 49.2 | U31: =IF(B31="","",S31*T31) -> 75.276 | V31: =IF(B31="","",U31*I31) -> 42.15456 | W31: =IF(B31="","",O31+V31) -> 96.13856 | X31: 3/8" | Y31: =IF(X31="","",IFERROR(VLOOKUP(X31,Listas!$A$4:$B$11,2,FALSE()),"")) -> 0.56 | Z31: 0.25 | AA31: 0.56 | AB31: 0.56 | AC31: =IF(B31="","",IF(D31="TAPADA",(AA31+AB31)/2,0)) -> 0.56 | AD31: =IF(B31="","",IF(D31="TAPADA",IFERROR(IF($X$1="ENTERO (redondeo arriba)",ROUNDUP(G31/Z31,0)+1,G31/Z31+1),0),0)) -> 49.2 | AE31: =IF(B31="","",IF(D31="TAPADA",AC31*AD31,0)) -> 27.552 | AF31: =IF(B31="","",IF(D31="TAPADA",AE31*Y31,0)) -> 15.42912 | AG31: =IF(B31="","",W31+AF31) -> 111.56768
A32: 22 | B32: EJE 12 | C32: TRAMO 03 | D32: TAPADA | E32: sec 55 | F32: sec 56 | G32: 3.4 | H32: 3/8" | I32: =IF(H32="","",IFERROR(VLOOKUP(H32,Listas!$A$4:$B$11,2,FALSE()),"")) -> 0.56 | J32: 0.23 | K32: 10 | L32: 10 | M32: =IF(B32="","",(K32+L32)/2) -> 10 | N32: =IF(B32="","",G32*M32) -> 34 | O32: =IF(B32="","",N32*I32) -> 19.04 | P32: 0.25 | Q32: 1.98 | R32: 2 | S32: =IF(B32="","",(Q32+R32)/2) -> 1.99 | T32: =IF(B32="","",IFERROR(IF($X$1="ENTERO (redondeo arriba)",ROUNDUP(G32/P32,0)+1,G32/P32+1),0)) -> 14.6 | U32: =IF(B32="","",S32*T32) -> 29.054 | V32: =IF(B32="","",U32*I32) -> 16.27024 | W32: =IF(B32="","",O32+V32) -> 35.31024 | X32: 3/8" | Y32: =IF(X32="","",IFERROR(VLOOKUP(X32,Listas!$A$4:$B$11,2,FALSE()),"")) -> 0.56 | Z32: 0.25 | AA32: 0.56 | AB32: 0.56 | AC32: =IF(B32="","",IF(D32="TAPADA",(AA32+AB32)/2,0)) -> 0.56 | AD32: =IF(B32="","",IF(D32="TAPADA",IFERROR(IF($X$1="ENTERO (redondeo arriba)",ROUNDUP(G32/Z32,0)+1,G32/Z32+1),0),0)) -> 14.6 | AE32: =IF(B32="","",IF(D32="TAPADA",AC32*AD32,0)) -> 8.176 | AF32: =IF(B32="","",IF(D32="TAPADA",AE32*Y32,0)) -> 4.57856 | AG32: =IF(B32="","",W32+AF32) -> 39.8888
A33: 23 | B33: EJE 12 | C33: TRAMO 04 | D33: ABIERTA | E33: sec 56 | F33: sec 57 | G33: 18.9 | H33: 3/8" | I33: =IF(H33="","",IFERROR(VLOOKUP(H33,Listas!$A$4:$B$11,2,FALSE()),"")) -> 0.56 | J33: 0.21 | K33: 9 | L33: 11 | M33: =IF(B33="","",(K33+L33)/2) -> 10 | N33: =IF(B33="","",G33*M33) -> 189 | O33: =IF(B33="","",N33*I33) -> 105.84 | P33: 0.25 | Q33: 2 | R33: 2.22 | S33: =IF(B33="","",(Q33+R33)/2) -> 2.11 | T33: =IF(B33="","",IFERROR(IF($X$1="ENTERO (redondeo arriba)",ROUNDUP(G33/P33,0)+1,G33/P33+1),0)) -> 76.6 | U33: =IF(B33="","",S33*T33) -> 161.626 | V33: =IF(B33="","",U33*I33) -> 90.51056 | W33: =IF(B33="","",O33+V33) -> 196.35056 | Y33: =IF(X33="","",IFERROR(VLOOKUP(X33,Listas!$A$4:$B$11,2,FALSE()),"")) | AC33: =IF(B33="","",IF(D33="TAPADA",(AA33+AB33)/2,0)) -> 0 | AD33: =IF(B33="","",IF(D33="TAPADA",IFERROR(IF($X$1="ENTERO (redondeo arriba)",ROUNDUP(G33/Z33,0)+1,G33/Z33+1),0),0)) -> 0 | AE33: =IF(B33="","",IF(D33="TAPADA",AC33*AD33,0)) -> 0 | AF33: =IF(B33="","",IF(D33="TAPADA",AE33*Y33,0)) -> 0 | AG33: =IF(B33="","",W33+AF33) -> 196.35056
A34: 24 | B34: EJE 12 | C34: TRAMO 05 | D34: TAPADA | E34: sec 57 | F34: sec 58 | G34: 2.52 | H34: 3/8" | I34: =IF(H34="","",IFERROR(VLOOKUP(H34,Listas!$A$4:$B$11,2,FALSE()),"")) -> 0.56 | J34: 0.2 | K34: 12 | L34: 12 | M34: =IF(B34="","",(K34+L34)/2) -> 12 | N34: =IF(B34="","",G34*M34) -> 30.24 | O34: =IF(B34="","",N34*I34) -> 16.9344 | P34: 0.25 | Q34: 2.22 | R34: 2.23 | S34: =IF(B34="","",(Q34+R34)/2) -> 2.225 | T34: =IF(B34="","",IFERROR(IF($X$1="ENTERO (redondeo arriba)",ROUNDUP(G34/P34,0)+1,G34/P34+1),0)) -> 11.08 | U34: =IF(B34="","",S34*T34) -> 24.653 | V34: =IF(B34="","",U34*I34) -> 13.80568 | W34: =IF(B34="","",O34+V34) -> 30.74008 | X34: 3/8" | Y34: =IF(X34="","",IFERROR(VLOOKUP(X34,Listas!$A$4:$B$11,2,FALSE()),"")) -> 0.56 | Z34: 0.25 | AA34: 0.56 | AB34: 0.56 | AC34: =IF(B34="","",IF(D34="TAPADA",(AA34+AB34)/2,0)) -> 0.56 | AD34: =IF(B34="","",IF(D34="TAPADA",IFERROR(IF($X$1="ENTERO (redondeo arriba)",ROUNDUP(G34/Z34,0)+1,G34/Z34+1),0),0)) -> 11.08 | AE34: =IF(B34="","",IF(D34="TAPADA",AC34*AD34,0)) -> 6.2048 | AF34: =IF(B34="","",IF(D34="TAPADA",AE34*Y34,0)) -> 3.474688 | AG34: =IF(B34="","",W34+AF34) -> 34.214768
A35: 25 | B35: EJE 12 | C35: TRAMO 06 | D35: TAPADA | E35: sec 59 | F35: sec 60 | G35: 15.48 | H35: 3/8" | I35: =IF(H35="","",IFERROR(VLOOKUP(H35,Listas!$A$4:$B$11,2,FALSE()),"")) -> 0.56 | J35: 0.21 | K35: 10 | L35: 10 | M35: =IF(B35="","",(K35+L35)/2) -> 10 | N35: =IF(B35="","",G35*M35) -> 154.8 | O35: =IF(B35="","",N35*I35) -> 86.688 | P35: 0.25 | Q35: 1.82 | R35: 2.02 | S35: =IF(B35="","",(Q35+R35)/2) -> 1.92 | T35: =IF(B35="","",IFERROR(IF($X$1="ENTERO (redondeo arriba)",ROUNDUP(G35/P35,0)+1,G35/P35+1),0)) -> 62.92 | U35: =IF(B35="","",S35*T35) -> 120.8064 | V35: =IF(B35="","",U35*I35) -> 67.651584 | W35: =IF(B35="","",O35+V35) -> 154.33958 | X35: 3/8" | Y35: =IF(X35="","",IFERROR(VLOOKUP(X35,Listas!$A$4:$B$11,2,FALSE()),"")) -> 0.56 | Z35: 0.25 | AA35: 0.56 | AB35: 0.56 | AC35: =IF(B35="","",IF(D35="TAPADA",(AA35+AB35)/2,0)) -> 0.56 | AD35: =IF(B35="","",IF(D35="TAPADA",IFERROR(IF($X$1="ENTERO (redondeo arriba)",ROUNDUP(G35/Z35,0)+1,G35/Z35+1),0),0)) -> 62.92 | AE35: =IF(B35="","",IF(D35="TAPADA",AC35*AD35,0)) -> 35.2352 | AF35: =IF(B35="","",IF(D35="TAPADA",AE35*Y35,0)) -> 19.731712 | AG35: =IF(B35="","",W35+AF35) -> 174.0713
